File: OriginPro/XRD from Panalytical X'Pert PRO/Nova Cu foil/Cufoil_START_30°C.csv
[Measurement conditions]
Sample identification,
Comment - 1,"finito"
Comment - 2,"Configuration=MRI TC-Basic Stage, Owner=User-1, Creation date=26-10-2009 9:18:44"
Comment - 3,"Goniometer=PW3050/60 (Theta/Theta); Minimum step size 2Theta:0.001; Minimum step size Omega:0.001"
Comment - 4,"Sample stage=MRI TC-Basic (PtRh heat strip)"
Comment - 5,"Diffractometer system=XPERT-PRO"
Comment - 6,"Measurement program=FlatStage, Owner=joana, Creation date=03-08-2011 15:43:53"
Anode material,Cu
K-Alpha1 wavelength,1.5405980
K-Alpha2 wavelength,1.5444260
Ratio K-Alpha2/K-Alpha1,0.500
Divergence slit,Fixed,0.76mm
Monochromator used,NO
Generator voltage, 45
Tube current, 40
File date and time,06/Dec/2012 18:55
Unit cell,
h k l, 0 0 0
Temperature [K],302
Scan axis,Gonio
Scan range,24.999999996,100.000175174
Scan step size,0.0167113
No. of points, 4488
Scan type,CONTINUOUS
Time per step,53.340
[Scan points]
Angle,Intensity
25.008355630,4623.0
25.058489437,4646.0
25.108623244,4631.0
25.158757051,4670.0
25.208890858,4532.0
25.259024665,4712.0
25.309158472,4538.0
25.359292279,4497.0
25.409426086,4560.0
25.459559892,4370.0
25.509693699,4603.0
25.559827506,4551.0
25.609961313,4650.0
25.660095120,4589.0
25.710228927,4493.0
25.760362734,4614.0
25.810496541,4549.0
25.860630348,4630.0
25.910764155,4586.0
25.960897962,4558.0
26.011031769,4385.0
26.061165576,4583.0
26.111299383,4606.0
26.161433190,4599.0
26.211566997,4620.0
26.261700803,4633.0
26.311834610,4644.0
26.361968417,4522.0
26.412102224,4596.0
26.462236031,4553.0
26.512369838,4517.0
26.562503645,4581.0
26.612637452,4608.0
26.662771259,4571.0
26.712905066,4487.0
26.763038873,4612.0
26.813172680,4617.0
26.863306487,4447.0
26.913440294,4587.0
26.963574101,4573.0
27.013707908,4696.0
27.063841714,4434.0
27.113975521,4502.0
27.164109328,4606.0
27.214243135,4591.0
27.264376942,4571.0
27.314510749,4508.0
27.364644556,4493.0
27.414778363,4548.0
27.464912170,4393.0
27.515045977,4555.0
27.565179784,4403.0
27.615313591,4540.0
27.665447398,4495.0
27.715581205,4418.0
27.765715012,4627.0
27.815848819,4429.0
27.865982625,4504.0
27.916116432,4489.0
27.966250239,4619.0
28.016384046,4676.0
28.066517853,4569.0
28.116651660,4583.0
28.166785467,4586.0
28.216919274,4499.0
28.267053081,4601.0
28.317186888,4513.0
28.367320695,4597.0
28.417454502,4494.0
28.467588309,4413.0
28.517722116,4602.0
28.567855923,4478.0
28.617989730,4530.0
28.668123536,4475.0
28.718257343,4419.0
28.768391150,4501.0
28.818524957,4591.0
28.868658764,4419.0
28.918792571,4457.0
28.968926378,4476.0
29.019060185,4495.0
29.069193992,4613.0
29.119327799,4459.0
29.169461606,4510.0
29.219595413,4447.0
29.269729220,4571.0
29.319863027,4402.0
29.369996834,4619.0
29.420130641,4609.0
29.470264447,4536.0
29.520398254,4468.0
29.570532061,4498.0
29.620665868,4518.0
29.670799675,4464.0
29.720933482,4521.0
29.771067289,4483.0
29.821201096,4357.0
29.871334903,4529.0
29.921468710,4594.0
29.971602517,4470.0
30.021736324,4495.0
30.071870131,4509.0
30.122003938,4477.0
30.172137745,4493.0
30.222271552,4473.0
30.272405358,4487.0
30.322539165,4549.0
30.372672972,4503.0
30.422806779,4532.0
30.472940586,4480.0
30.523074393,4511.0
30.573208200,4546.0
30.623342007,4436.0
30.673475814,4615.0
30.723609621,4508.0
30.773743428,4532.0
30.823877235,4415.0
30.874011042,4371.0
30.924144849,4499.0
30.974278656,4617.0
31.024412463,4493.0
31.074546269,4498.0
31.124680076,4528.0
31.174813883,4606.0
31.224947690,4369.0
31.275081497,4537.0
31.325215304,4535.0
31.375349111,4418.0
31.425482918,4434.0
31.475616725,4482.0
31.525750532,4478.0
31.575884339,4568.0
31.626018146,4389.0
31.676151953,4563.0
31.726285760,4513.0
31.776419567,4312.0
31.826553374,4418.0
31.876687180,4410.0
31.926820987,4511.0
31.976954794,4459.0
32.027088601,4481.0
32.077222408,4363.0
32.127356215,4458.0
32.177490022,4424.0
32.227623829,4381.0
32.277757636,4403.0
32.327891443,4557.0
32.378025250,4647.0
32.428159057,4374.0
32.478292864,4343.0
32.528426671,4487.0
32.578560478,4377.0
32.628694285,4475.0
32.678828091,4348.0
32.728961898,4540.0
32.779095705,4479.0
32.829229512,4423.0
32.879363319,4408.0
32.929497126,4326.0
32.979630933,4519.0
33.029764740,4438.0
33.079898547,4482.0
33.130032354,4387.0
33.180166161,4521.0
33.230299968,4556.0
33.280433775,4622.0
33.330567582,4459.0
33.380701389,4376.0
33.430835196,4521.0
33.480969002,4427.0
33.531102809,4501.0
33.581236616,4424.0
33.631370423,4554.0
33.681504230,4395.0
33.731638037,4429.0
33.781771844,4357.0
33.831905651,4404.0
33.882039458,4446.0
33.932173265,4478.0
33.982307072,4487.0
34.032440879,4506.0
34.082574686,4428.0
34.132708493,4459.0
34.182842300,4559.0
34.232976107,4517.0
34.283109913,4463.0
34.333243720,4485.0
34.383377527,4430.0
34.433511334,4517.0
34.483645141,4476.0
34.533778948,4515.0
34.583912755,4519.0
34.634046562,4392.0
34.684180369,4468.0
34.734314176,4504.0
34.784447983,4456.0
34.834581790,4381.0
34.884715597,4446.0
34.934849404,4498.0
34.984983211,4470.0
35.035117018,4476.0
35.085250825,4397.0
35.135384631,4579.0
35.185518438,4582.0
35.235652245,4381.0
35.285786052,4444.0
35.335919859,4488.0
35.386053666,4516.0
35.436187473,4586.0
35.486321280,4542.0
35.536455087,4461.0
35.586588894,4366.0
35.636722701,4462.0
35.686856508,4514.0
35.736990315,4436.0
35.787124122,4403.0
35.837257929,4435.0
35.887391736,4458.0
35.937525542,4536.0
35.987659349,4459.0
36.037793156,4453.0
36.087926963,4409.0
36.138060770,4398.0
36.188194577,4488.0
36.238328384,4480.0
36.288462191,4523.0
36.338595998,4465.0
36.388729805,4429.0
36.438863612,4357.0
36.488997419,4468.0
36.539131226,4361.0
36.589265033,4541.0
36.639398840,4494.0
36.689532647,4406.0
36.739666453,4429.0
36.789800260,4411.0
36.839934067,4492.0
36.890067874,4556.0
36.940201681,4396.0
36.990335488,4451.0
37.040469295,4411.0
37.090603102,4465.0
37.140736909,4324.0
37.190870716,4457.0
37.241004523,4528.0
37.291138330,4414.0
37.341272137,4489.0
37.391405944,4515.0
37.441539751,4465.0
37.491673558,4657.0
37.541807364,4550.0
37.591941171,4452.0
37.642074978,4598.0
37.692208785,4573.0
37.742342592,4474.0
37.792476399,4457.0
37.842610206,4616.0
37.892744013,4443.0
37.942877820,4420.0
37.993011627,4496.0
38.043145434,4501.0
38.093279241,4628.0
38.143413048,4566.0
38.193546855,4524.0
38.243680662,4533.0
38.293814469,4557.0
38.343948275,4432.0
38.394082082,4480.0
38.444215889,4563.0
38.494349696,4530.0
38.544483503,4548.0
38.594617310,4571.0
38.644751117,4570.0
38.694884924,4708.0
38.745018731,4929.0
38.795152538,5677.0
38.845286345,4898.0
38.895420152,4571.0
38.945553959,4585.0
38.995687766,4610.0
39.045821573,4545.0
39.095955380,4488.0
39.146089186,4619.0
39.196222993,4580.0
39.246356800,4610.0
39.296490607,4634.0
39.346624414,4534.0
39.396758221,4542.0
39.446892028,4504.0
39.497025835,4494.0
39.547159642,4494.0
39.597293449,4484.0
39.647427256,4501.0
39.697561063,4571.0
39.747694870,4575.0
39.797828677,4482.0
39.847962484,4528.0
39.898096291,4632.0
39.948230097,4589.0
39.998363904,4587.0
40.048497711,4594.0
40.098631518,4500.0
40.148765325,4571.0
40.198899132,4476.0
40.249032939,4481.0
40.299166746,4593.0
40.349300553,4639.0
40.399434360,4598.0
40.449568167,4577.0
40.499701974,4620.0
40.549835781,4534.0
40.599969588,4463.0
40.650103395,4659.0
40.700237202,4495.0
40.750371008,4504.0
40.800504815,4506.0
40.850638622,4588.0
40.900772429,4606.0
40.950906236,4520.0
41.001040043,4646.0
41.051173850,4598.0
41.101307657,4559.0
41.151441464,4540.0
41.201575271,4766.0
41.251709078,4652.0
41.301842885,4617.0
41.351976692,4587.0
41.402110499,4524.0
41.452244306,4615.0
41.502378113,4772.0
41.552511919,4721.0
41.602645726,5215.0
41.652779533,5529.0
41.702913340,5418.0
41.753047147,5526.0
41.803180954,5519.0
41.853314761,5345.0
41.903448568,5495.0
41.953582375,5546.0
42.003716182,5472.0
42.053849989,5595.0
42.103983796,5464.0
42.154117603,5638.0
42.204251410,5817.0
42.254385217,5722.0
42.304519024,5551.0
42.354652830,5661.0
42.404786637,5677.0
42.454920444,5750.0
42.505054251,5841.0
42.555188058,5836.0
42.605321865,6005.0
42.655455672,5936.0
42.705589479,6167.0
42.755723286,6806.0
42.805857093,7876.0
42.855990900,10389.0
42.906124707,13592.0
42.956258514,18084.0
43.006392321,23767.0
43.056526128,49111.0
43.106659935,166591.0
43.156793741,479440.0
43.206927548,128735.0
43.257061355,234699.0
43.307195162,84218.0
43.357328969,22860.0
43.407462776,13778.0
43.457596583,10656.0
43.507730390,8331.0
43.557864197,7387.0
43.607998004,6840.0
43.658131811,6260.0
43.708265618,6278.0
43.758399425,6078.0
43.808533232,5940.0
43.858667039,6078.0
43.908800846,5726.0
43.958934652,5641.0
44.009068459,5500.0
44.059202266,5539.0
44.109336073,5467.0
44.159469880,5398.0
44.209603687,5433.0
44.259737494,5382.0
44.309871301,5449.0
44.360005108,5279.0
44.410138915,5268.0
44.460272722,5227.0
44.510406529,5226.0
44.560540336,5286.0
44.610674143,5143.0
44.660807950,5158.0
44.710941757,5229.0
44.761075564,5261.0
44.811209370,5266.0
44.861343177,5070.0
44.911476984,5139.0
44.961610791,5165.0
45.011744598,5163.0
45.061878405,5247.0
45.112012212,5717.0
45.162146019,5754.0
45.212279826,5077.0
45.262413633,5135.0
45.312547440,5128.0
45.362681247,5090.0
45.412815054,4931.0
45.462948861,5116.0
45.513082668,4904.0
45.563216475,4923.0
45.613350281,5015.0
45.663484088,5077.0
45.713617895,4961.0
45.763751702,4916.0
45.813885509,4980.0
45.864019316,4876.0
45.914153123,4916.0
45.964286930,4916.0
46.014420737,4984.0
46.064554544,4874.0
46.114688351,4986.0
46.164822158,4868.0
46.214955965,4970.0
46.265089772,5011.0
46.315223579,4811.0
46.365357386,5005.0
46.415491192,5014.0
46.465624999,5104.0
46.515758806,5131.0
46.565892613,5063.0
46.616026420,5024.0
46.666160227,5139.0
46.716294034,4910.0
46.766427841,5030.0
46.816561648,4970.0
46.866695455,5507.0
46.916829262,5337.0
46.966963069,5203.0
47.017096876,5237.0
47.067230683,4853.0
47.117364490,4849.0
47.167498297,4781.0
47.217632103,4785.0
47.267765910,4883.0
47.317899717,4897.0
47.368033524,4899.0
47.418167331,4754.0
47.468301138,4749.0
47.518434945,4840.0
47.568568752,4830.0
47.618702559,4918.0
47.668836366,4831.0
47.718970173,4692.0
47.769103980,4686.0
47.819237787,4846.0
47.869371594,4702.0
47.919505401,4697.0
47.969639208,4581.0
48.019773014,4680.0
48.069906821,4795.0
48.120040628,4878.0
48.170174435,4821.0
48.220308242,4624.0
48.270442049,4815.0
48.320575856,4962.0
48.370709663,4768.0
48.420843470,5009.0
48.470977277,5325.0
48.521111084,5302.0
48.571244891,5380.0
48.621378698,5529.0
48.671512505,5316.0
48.721646312,5399.0
48.771780119,5306.0
48.821913925,5230.0
48.872047732,5458.0
48.922181539,5417.0
48.972315346,5429.0
49.022449153,5412.0
49.072582960,5554.0
49.122716767,5659.0
49.172850574,5680.0
49.222984381,5352.0
49.273118188,5351.0
49.323251995,5538.0
49.373385802,5513.0
49.423519609,5573.0
49.473653416,5443.0
49.523787223,5679.0
49.573921030,5702.0
49.624054836,5704.0
49.674188643,5763.0
49.724322450,6023.0
49.774456257,6138.0
49.824590064,6372.0
49.874723871,6761.0
49.924857678,7581.0
49.974991485,9699.0
50.025125292,13070.0
50.075259099,15711.0
50.125392906,19679.0
50.175526713,34420.0
50.225660520,99524.0
50.275794327,330588.0
50.325928134,189058.0
50.376061941,105221.0
50.426195747,189841.0
50.476329554,59892.0
50.526463361,20406.0
50.576597168,13148.0
50.626730975,9823.0
50.676864782,7990.0
50.726998589,7115.0
50.777132396,6566.0
50.827266203,6336.0
50.877400010,5957.0
50.927533817,5909.0
50.977667624,5588.0
51.027801431,5490.0
51.077935238,5408.0
51.128069045,5483.0
51.178202852,5302.0
51.228336658,5420.0
51.278470465,5289.0
51.328604272,5200.0
51.378738079,5141.0
51.428871886,5009.0
51.479005693,5156.0
51.529139500,4996.0
51.579273307,5150.0
51.629407114,5061.0
51.679540921,5005.0
51.729674728,5059.0
51.779808535,4913.0
51.829942342,5019.0
51.880076149,4932.0
51.930209956,4927.0
51.980343763,5014.0
52.030477569,4831.0
52.080611376,4949.0
52.130745183,4809.0
52.180878990,4875.0
52.231012797,4842.0
52.281146604,4907.0
52.331280411,4914.0
52.381414218,4795.0
52.431548025,4810.0
52.481681832,4709.0
52.531815639,4862.0
52.581949446,4889.0
52.632083253,4741.0
52.682217060,4885.0
52.732350867,4828.0
52.782484674,4764.0
52.832618480,4961.0
52.882752287,4918.0
52.932886094,4866.0
52.983019901,4695.0
53.033153708,4795.0
53.083287515,4884.0
53.133421322,4840.0
53.183555129,4762.0
53.233688936,4816.0
53.283822743,4742.0
53.333956550,4822.0
53.384090357,4795.0
53.434224164,4638.0
53.484357971,4745.0
53.534491778,4672.0
53.584625585,4714.0
53.634759391,4698.0
53.684893198,4650.0
53.735027005,4688.0
53.785160812,4747.0
53.835294619,4620.0
53.885428426,4588.0
53.935562233,4652.0
53.985696040,4762.0
54.035829847,4700.0
54.085963654,4711.0
54.136097461,4657.0
54.186231268,4606.0
54.236365075,4670.0
54.286498882,4653.0
54.336632689,4808.0
54.386766496,4748.0
54.436900303,4786.0
54.487034109,4796.0
54.537167916,4707.0
54.587301723,4816.0
54.637435530,4901.0
54.687569337,5295.0
54.737703144,5100.0
54.787836951,4949.0
54.837970758,5075.0
54.888104565,4610.0
54.938238372,4642.0
54.988372179,4640.0
55.038505986,4615.0
55.088639793,4597.0
55.138773600,4662.0
55.188907407,4728.0
55.239041214,4659.0
55.289175020,4634.0
55.339308827,4738.0
55.389442634,4407.0
55.439576441,4532.0
55.489710248,4486.0
55.539844055,4578.0
55.589977862,4636.0
55.640111669,4670.0
55.690245476,4677.0
55.740379283,4607.0
55.790513090,4469.0
55.840646897,4532.0
55.890780704,4458.0
55.940914511,4515.0
55.991048318,4573.0
56.041182125,4519.0
56.091315931,4671.0
56.141449738,4470.0
56.191583545,4504.0
56.241717352,4524.0
56.291851159,4440.0
56.341984966,4506.0
56.392118773,4384.0
56.442252580,4547.0
56.492386387,4520.0
56.542520194,4496.0
56.592654001,4470.0
56.642787808,4643.0
56.692921615,4524.0
56.743055422,4471.0
56.793189229,4503.0
56.843323036,4430.0
56.893456842,4630.0
56.943590649,4328.0
56.993724456,4502.0
57.043858263,4502.0
57.093992070,4579.0
57.144125877,4543.0
57.194259684,4441.0
57.244393491,4495.0
57.294527298,4639.0
57.344661105,4510.0
57.394794912,4531.0
57.444928719,4533.0
57.495062526,4527.0
57.545196333,4507.0
57.595330140,4433.0
57.645463947,4485.0
57.695597753,4514.0
57.745731560,4371.0
57.795865367,4397.0
57.845999174,4392.0
57.896132981,4469.0
57.946266788,4397.0
57.996400595,4320.0
58.046534402,4488.0
58.096668209,4581.0
58.146802016,4408.0
58.196935823,4518.0
58.247069630,4522.0
58.297203437,4437.0
58.347337244,4498.0
58.397471051,4354.0
58.447604858,4459.0
58.497738664,4483.0
58.547872471,4377.0
58.598006278,4490.0
58.648140085,4459.0
58.698273892,4437.0
58.748407699,4423.0
58.798541506,4465.0
58.848675313,4433.0
58.898809120,4454.0
58.948942927,4498.0
58.999076734,4388.0
59.049210541,4372.0
59.099344348,4513.0
59.149478155,4419.0
59.199611962,4398.0
59.249745769,4385.0
59.299879575,4252.0
59.350013382,4530.0
59.400147189,4505.0
59.450280996,4329.0
59.500414803,4586.0
59.550548610,4449.0
59.600682417,4474.0
59.650816224,4340.0
59.700950031,4400.0
59.751083838,4436.0
59.801217645,4534.0
59.851351452,4358.0
59.901485259,4437.0
59.951619066,4524.0
60.001752873,4534.0
60.051886680,4478.0
60.102020486,4372.0
60.152154293,4240.0
60.202288100,4488.0
60.252421907,4373.0
60.302555714,4396.0
60.352689521,4500.0
60.402823328,4499.0
60.452957135,4428.0
60.503090942,4351.0
60.553224749,4360.0
60.603358556,4345.0
60.653492363,4401.0
60.703626170,4352.0
60.753759977,4394.0
60.803893784,4503.0
60.854027591,4460.0
60.904161397,4515.0
60.954295204,4470.0
61.004429011,4367.0
61.054562818,4585.0
61.104696625,4291.0
61.154830432,4437.0
61.204964239,4423.0
61.255098046,4592.0
61.305231853,4477.0
61.355365660,4425.0
61.405499467,4387.0
61.455633274,4435.0
61.505767081,4415.0
61.555900888,4375.0
61.606034695,4417.0
61.656168502,4343.0
61.706302308,4303.0
61.756436115,4457.0
61.806569922,4374.0
61.856703729,4304.0
61.906837536,4363.0
61.956971343,4471.0
62.007105150,4173.0
62.057238957,4382.0
62.107372764,4531.0
62.157506571,4412.0
62.207640378,4302.0
62.257774185,4467.0
62.307907992,4366.0
62.358041799,4390.0
62.408175606,4404.0
62.458309413,4414.0
62.508443219,4357.0
62.558577026,4369.0
62.608710833,4517.0
62.658844640,4306.0
62.708978447,4431.0
62.759112254,4330.0
62.809246061,4469.0
62.859379868,4400.0
62.909513675,4408.0
62.959647482,4455.0
63.009781289,4481.0
63.059915096,4443.0
63.110048903,4459.0
63.160182710,4336.0
63.210316517,4363.0
63.260450324,4433.0
63.310584130,4467.0
63.360717937,4484.0
63.410851744,4247.0
63.460985551,4316.0
63.511119358,4383.0
63.561253165,4412.0
63.611386972,4390.0
63.661520779,4463.0
63.711654586,4420.0
63.761788393,4423.0
63.811922200,4459.0
63.862056007,4456.0
63.912189814,4491.0
63.962323621,4345.0
64.012457428,4313.0
64.062591235,4415.0
64.112725041,4434.0
64.162858848,4431.0
64.212992655,4353.0
64.263126462,4379.0
64.313260269,4356.0
64.363394076,4400.0
64.413527883,4286.0
64.463661690,4385.0
64.513795497,4331.0
64.563929304,4375.0
64.614063111,4439.0
64.664196918,4478.0
64.714330725,4389.0
64.764464532,4362.0
64.814598339,4374.0
64.864732146,4389.0
64.914865953,4362.0
64.964999759,4387.0
65.015133566,4488.0
65.065267373,4551.0
65.115401180,4393.0
65.165534987,4367.0
65.215668794,4403.0
65.265802601,4295.0
65.315936408,4289.0
65.366070215,4392.0
65.416204022,4367.0
65.466337829,4404.0
65.516471636,4277.0
65.566605443,4315.0
65.616739250,4348.0
65.666873057,4403.0
65.717006864,4533.0
65.767140670,4506.0
65.817274477,4538.0
65.867408284,4496.0
65.917542091,4308.0
65.967675898,4440.0
66.017809705,4462.0
66.067943512,4349.0
66.118077319,4488.0
66.168211126,4392.0
66.218344933,4383.0
66.268478740,4336.0
66.318612547,4428.0
66.368746354,4475.0
66.418880161,4292.0
66.469013968,4222.0
66.519147775,4398.0
66.569281581,4320.0
66.619415388,4437.0
66.669549195,4364.0
66.719683002,4252.0
66.769816809,4349.0
66.819950616,4274.0
66.870084423,4391.0
66.920218230,4407.0
66.970352037,4427.0
67.020485844,4296.0
67.070619651,4375.0
67.120753458,4314.0
67.170887265,4335.0
67.221021072,4359.0
67.271154879,4459.0
67.321288686,4336.0
67.371422492,4359.0
67.421556299,4534.0
67.471690106,4249.0
67.521823913,4348.0
67.571957720,4393.0
67.622091527,4402.0
67.672225334,4429.0
67.722359141,4458.0
67.772492948,4216.0
67.822626755,4426.0
67.872760562,4394.0
67.922894369,4561.0
67.973028176,4690.0
68.023161983,4777.0
68.073295790,4563.0
68.123429597,4338.0
68.173563403,4390.0
68.223697210,4424.0
68.273831017,4324.0
68.323964824,4305.0
68.374098631,4346.0
68.424232438,4296.0
68.474366245,4514.0
68.524500052,4396.0
68.574633859,4392.0
68.624767666,4364.0
68.674901473,4310.0
68.725035280,4262.0
68.775169087,4313.0
68.825302894,4346.0
68.875436701,4398.0
68.925570508,4294.0
68.975704314,4330.0
69.025838121,4356.0
69.075971928,4277.0
69.126105735,4371.0
69.176239542,4392.0
69.226373349,4303.0
69.276507156,4463.0
69.326640963,4277.0
69.376774770,4347.0
69.426908577,4339.0
69.477042384,4352.0
69.527176191,4386.0
69.577309998,4365.0
69.627443805,4233.0
69.677577612,4420.0
69.727711419,4265.0
69.777845225,4324.0
69.827979032,4306.0
69.878112839,4300.0
69.928246646,4296.0
69.978380453,4272.0
70.028514260,4446.0
70.078648067,4285.0
70.128781874,4358.0
70.178915681,4310.0
70.229049488,4414.0
70.279183295,4368.0
70.329317102,4275.0
70.379450909,4350.0
70.429584716,4480.0
70.479718523,4347.0
70.529852330,4375.0
70.579986136,4400.0
70.630119943,4315.0
70.680253750,4524.0
70.730387557,4332.0
70.780521364,4190.0
70.830655171,4436.0
70.880788978,4304.0
70.930922785,4329.0
70.981056592,4363.0
71.031190399,4409.0
71.081324206,4463.0
71.131458013,4422.0
71.181591820,4423.0
71.231725627,4448.0
71.281859434,4422.0
71.331993241,4509.0
71.382127047,4465.0
71.432260854,4394.0
71.482394661,4392.0
71.532528468,4466.0
71.582662275,4411.0
71.632796082,4380.0
71.682929889,4475.0
71.733063696,4324.0
71.783197503,4463.0
71.833331310,4444.0
71.883465117,4490.0
71.933598924,4417.0
71.983732731,4514.0
72.033866538,4534.0
72.084000345,4529.0
72.134134152,4456.0
72.184267958,4495.0
72.234401765,4531.0
72.284535572,4413.0
72.334669379,4454.0
72.384803186,4536.0
72.434936993,4522.0
72.485070800,4390.0
72.535204607,4518.0
72.585338414,4509.0
72.635472221,4561.0
72.685606028,4541.0
72.735739835,4461.0
72.785873642,4391.0
72.836007449,4403.0
72.886141256,4465.0
72.936275063,4506.0
72.986408869,4521.0
73.036542676,4296.0
73.086676483,4618.0
73.136810290,4555.0
73.186944097,4503.0
73.237077904,4605.0
73.287211711,4646.0
73.337345518,4495.0
73.387479325,4585.0
73.437613132,4592.0
73.487746939,4738.0
73.537880746,4916.0
73.588014553,5207.0
73.638148360,5473.0
73.688282167,5572.0
73.738415974,6050.0
73.788549780,6683.0
73.838683587,7852.0
73.888817394,12440.0
73.938951201,33796.0
73.989085008,68030.0
74.039218815,25945.0
74.089352622,12747.0
74.139486429,16691.0
74.189620236,35114.0
74.239754043,21606.0
74.289887850,9087.0
74.340021657,6577.0
74.390155464,5871.0
74.440289271,5272.0
74.490423078,4990.0
74.540556885,4930.0
74.590690692,4845.0
74.640824498,4698.0
74.690958305,4569.0
74.741092112,4678.0
74.791225919,4631.0
74.841359726,4610.0
74.891493533,4660.0
74.941627340,4549.0
74.991761147,4594.0
75.041894954,4614.0
75.092028761,4563.0
75.142162568,4401.0
75.192296375,4535.0
75.242430182,4563.0
75.292563989,4440.0
75.342697796,4543.0
75.392831603,4626.0
75.442965409,4345.0
75.493099216,4525.0
75.543233023,4580.0
75.593366830,4399.0
75.643500637,4545.0
75.693634444,4512.0
75.743768251,4418.0
75.793902058,4375.0
75.844035865,4561.0
75.894169672,4452.0
75.944303479,4353.0
75.994437286,4528.0
76.044571093,4525.0
76.094704900,4550.0
76.144838707,4485.0
76.194972514,4480.0
76.245106320,4451.0
76.295240127,4445.0
76.345373934,4368.0
76.395507741,4365.0
76.445641548,4482.0
76.495775355,4592.0
76.545909162,4494.0
76.596042969,4435.0
76.646176776,4332.0
76.696310583,4511.0
76.746444390,4462.0
76.796578197,4419.0
76.846712004,4363.0
76.896845811,4393.0
76.946979618,4560.0
76.997113425,4476.0
77.047247231,4520.0
77.097381038,4493.0
77.147514845,4406.0
77.197648652,4298.0
77.247782459,4417.0
77.297916266,4354.0
77.348050073,4320.0
77.398183880,4345.0
77.448317687,4408.0
77.498451494,4421.0
77.548585301,4413.0
77.598719108,4464.0
77.648852915,4419.0
77.698986722,4325.0
77.749120529,4352.0
77.799254336,4442.0
77.849388142,4262.0
77.899521949,4484.0
77.949655756,4441.0
77.999789563,4459.0
78.049923370,4318.0
78.100057177,4495.0
78.150190984,4265.0
78.200324791,4438.0
78.250458598,4437.0
78.300592405,4453.0
78.350726212,4355.0
78.400860019,4368.0
78.450993826,4356.0
78.501127633,4430.0
78.551261440,4355.0
78.601395247,4392.0
78.651529053,4433.0
78.701662860,4489.0
78.751796667,4384.0
78.801930474,4320.0
78.852064281,4373.0
78.902198088,4395.0
78.952331895,4359.0
79.002465702,4378.0
79.052599509,4471.0
79.102733316,4353.0
79.152867123,4413.0
79.203000930,4510.0
79.253134737,4375.0
79.303268544,4341.0
79.353402351,4403.0
79.403536158,4424.0
79.453669964,4367.0
79.503803771,4466.0
79.553937578,4408.0
79.604071385,4334.0
79.654205192,4419.0
79.704338999,4292.0
79.754472806,4346.0
79.804606613,4299.0
79.854740420,4418.0
79.904874227,4388.0
79.955008034,4360.0
80.005141841,4254.0
80.055275648,4282.0
80.105409455,4370.0
80.155543262,4441.0
80.205677069,4305.0
80.255810875,4348.0
80.305944682,4308.0
80.356078489,4394.0
80.406212296,4406.0
80.456346103,4368.0
80.506479910,4340.0
80.556613717,4260.0
80.606747524,4388.0
80.656881331,4314.0
80.707015138,4375.0
80.757148945,4379.0
80.807282752,4451.0
80.857416559,4460.0
80.907550366,4489.0
80.957684173,4341.0
81.007817980,4537.0
81.057951786,4377.0
81.108085593,4427.0
81.158219400,4457.0
81.208353207,4321.0
81.258487014,4412.0
81.308620821,4360.0
81.358754628,4224.0
81.408888435,4454.0
81.459022242,4442.0
81.509156049,4419.0
81.559289856,4346.0
81.609423663,4376.0
81.659557470,4277.0
81.709691277,4456.0
81.759825084,4363.0
81.809958891,4449.0
81.860092697,4504.0
81.910226504,4432.0
81.960360311,4467.0
82.010494118,4426.0
82.060627925,4518.0
82.110761732,4598.0
82.160895539,4428.0
82.211029346,4350.0
82.261163153,4540.0
82.311296960,4509.0
82.361430767,4370.0
82.411564574,4393.0
82.461698381,4622.0
82.511832188,4384.0
82.561965995,4309.0
82.612099802,4378.0
82.662233608,4267.0
82.712367415,4371.0
82.762501222,4344.0
82.812635029,4377.0
82.862768836,4540.0
82.912902643,4344.0
82.963036450,4399.0
83.013170257,4198.0
83.063304064,4383.0
83.113437871,4207.0
83.163571678,4322.0
83.213705485,4369.0
83.263839292,4462.0
83.313973099,4393.0
83.364106906,4407.0
83.414240713,4389.0
83.464374519,4350.0
83.514508326,4292.0
83.564642133,4391.0
83.614775940,4366.0
83.664909747,4413.0
83.715043554,4428.0
83.765177361,4435.0
83.815311168,4423.0
83.865444975,4272.0
83.915578782,4405.0
83.965712589,4260.0
84.015846396,4450.0
84.065980203,4265.0
84.116114010,4299.0
84.166247817,4342.0
84.216381624,4361.0
84.266515431,4316.0
84.316649237,4289.0
84.366783044,4339.0
84.416916851,4187.0
84.467050658,4268.0
84.517184465,4211.0
84.567318272,4240.0
84.617452079,4346.0
84.667585886,4306.0
84.717719693,4366.0
84.767853500,4412.0
84.817987307,4410.0
84.868121114,4330.0
84.918254921,4330.0
84.968388728,4359.0
85.018522535,4313.0
85.068656342,4261.0
85.118790148,4315.0
85.168923955,4409.0
85.219057762,4345.0
85.269191569,4257.0
85.319325376,4431.0
85.369459183,4415.0
85.419592990,4426.0
85.469726797,4319.0
85.519860604,4391.0
85.569994411,4281.0
85.620128218,4300.0
85.670262025,4389.0
85.720395832,4391.0
85.770529639,4318.0
85.820663446,4468.0
85.870797253,4327.0
85.920931059,4362.0
85.971064866,4444.0
86.021198673,4382.0
86.071332480,4393.0
86.121466287,4482.0
86.171600094,4401.0
86.221733901,4426.0
86.271867708,4227.0
86.322001515,4358.0
86.372135322,4411.0
86.422269129,4439.0
86.472402936,4397.0
86.522536743,4306.0
86.572670550,4399.0
86.622804357,4366.0
86.672938164,4399.0
86.723071970,4456.0
86.773205777,4456.0
86.823339584,4417.0
86.873473391,4348.0
86.923607198,4450.0
86.973741005,4351.0
87.023874812,4558.0
87.074008619,4542.0
87.124142426,4334.0
87.174276233,4394.0
87.224410040,4459.0
87.274543847,4304.0
87.324677654,4429.0
87.374811461,4525.0
87.424945268,4362.0
87.475079075,4417.0
87.525212881,4425.0
87.575346688,4336.0
87.625480495,4449.0
87.675614302,4395.0
87.725748109,4350.0
87.775881916,4337.0
87.826015723,4255.0
87.876149530,4421.0
87.926283337,4334.0
87.976417144,4342.0
88.026550951,4405.0
88.076684758,4347.0
88.126818565,4268.0
88.176952372,4379.0
88.227086179,4441.0
88.277219986,4489.0
88.327353792,4390.0
88.377487599,4409.0
88.427621406,4393.0
88.477755213,4325.0
88.527889020,4367.0
88.578022827,4368.0
88.628156634,4360.0
88.678290441,4412.0
88.728424248,4435.0
88.778558055,4438.0
88.828691862,4298.0
88.878825669,4357.0
88.928959476,4461.0
88.979093283,4486.0
89.029227090,4350.0
89.079360897,4540.0
89.129494703,4591.0
89.179628510,4493.0
89.229762317,4483.0
89.279896124,4726.0
89.330029931,4566.0
89.380163738,4646.0
89.430297545,4820.0
89.480431352,4934.0
89.530565159,5023.0
89.580698966,5073.0
89.630832773,5614.0
89.680966580,6722.0
89.731100387,9926.0
89.781234194,18802.0
89.831368001,21986.0
89.881501808,12117.0
89.931635614,7925.0
89.981769421,7388.0
90.031903228,8692.0
90.082037035,13317.0
90.132170842,11747.0
90.182304649,7478.0
90.232438456,5661.0
90.282572263,5093.0
90.332706070,4950.0
90.382839877,4727.0
90.432973684,4700.0
90.483107491,4684.0
90.533241298,4644.0
90.583375105,4411.0
90.633508912,4433.0
90.683642719,4423.0
90.733776525,4394.0
90.783910332,4545.0
90.834044139,4489.0
90.884177946,4511.0
90.934311753,4514.0
90.984445560,4357.0
91.034579367,4398.0
91.084713174,4408.0
91.134846981,4420.0
91.184980788,4407.0
91.235114595,4388.0
91.285248402,4480.0
91.335382209,4386.0
91.385516016,4442.0
91.435649823,4490.0
91.485783630,4378.0
91.535917436,4371.0
91.586051243,4482.0
91.636185050,4351.0
91.686318857,4355.0
91.736452664,4397.0
91.786586471,4331.0
91.836720278,4387.0
91.886854085,4340.0
91.936987892,4357.0
91.987121699,4482.0
92.037255506,4426.0
92.087389313,4447.0
92.137523120,4260.0
92.187656927,4361.0
92.237790734,4389.0
92.287924541,4374.0
92.338058347,4399.0
92.388192154,4294.0
92.438325961,4398.0
92.488459768,4276.0
92.538593575,4257.0
92.588727382,4382.0
92.638861189,4338.0
92.688994996,4425.0
92.739128803,4438.0
92.789262610,4349.0
92.839396417,4376.0
92.889530224,4353.0
92.939664031,4445.0
92.989797838,4365.0
93.039931645,4492.0
93.090065452,4350.0
93.140199258,4242.0
93.190333065,4331.0
93.240466872,4301.0
93.290600679,4414.0
93.340734486,4244.0
93.390868293,4464.0
93.441002100,4451.0
93.491135907,4353.0
93.541269714,4287.0
93.591403521,4441.0
93.641537328,4392.0
93.691671135,4324.0
93.741804942,4546.0
93.791938749,4446.0
93.842072556,4431.0
93.892206363,4407.0
93.942340170,4412.0
93.992473976,4454.0
94.042607783,4375.0
94.092741590,4496.0
94.142875397,4423.0
94.193009204,4421.0
94.243143011,4366.0
94.293276818,4431.0
94.343410625,4482.0
94.393544432,4488.0
94.443678239,4593.0
94.493812046,4567.0
94.543945853,4542.0
94.594079660,4563.0
94.644213467,4749.0
94.694347274,4902.0
94.744481081,4878.0
94.794614887,5246.0
94.844748694,5549.0
94.894882501,6060.0
94.945016308,8569.0
94.995150115,18129.0
95.045283922,25040.0
95.095417729,12404.0
95.145551536,7555.0
95.195685343,6398.0
95.245819150,6948.0
95.295952957,9964.0
95.346086764,15006.0
95.396220571,9723.0
95.446354378,6277.0
95.496488185,5334.0
95.546621992,5009.0
95.596755798,4644.0
95.646889605,4674.0
95.697023412,4620.0
95.747157219,4559.0
95.797291026,4442.0
95.847424833,4518.0
95.897558640,4508.0
95.947692447,4458.0
95.997826254,4301.0
96.047960061,4242.0
96.098093868,4366.0
96.148227675,4414.0
96.198361482,4468.0
96.248495289,4402.0
96.298629096,4343.0
96.348762903,4415.0
96.398896709,4354.0
96.449030516,4369.0
96.499164323,4568.0
96.549298130,4453.0
96.599431937,4383.0
96.649565744,4450.0
96.699699551,4371.0
96.749833358,4401.0
96.799967165,4340.0
96.850100972,4408.0
96.900234779,4354.0
96.950368586,4515.0
97.000502393,4417.0
97.050636200,4375.0
97.100770007,4529.0
97.150903814,4356.0
97.201037620,4310.0
97.251171427,4284.0
97.301305234,4291.0
97.351439041,4405.0
97.401572848,4317.0
97.451706655,4340.0
97.501840462,4494.0
97.551974269,4382.0
97.602108076,4337.0
97.652241883,4403.0
97.702375690,4225.0
97.752509497,4363.0
97.802643304,4138.0
97.852777111,4382.0
97.902910918,4293.0
97.953044725,4359.0
98.003178531,4411.0
98.053312338,4395.0
98.103446145,4355.0
98.153579952,4417.0
98.203713759,4313.0
98.253847566,4261.0
98.303981373,4312.0
98.354115180,4235.0
98.404248987,4375.0
98.454382794,4461.0
98.504516601,4397.0
98.554650408,4319.0
98.604784215,4405.0
98.654918022,4305.0
98.705051829,4261.0
98.755185636,4430.0
98.805319442,4228.0
98.855453249,4284.0
98.905587056,4280.0
98.955720863,4386.0
99.005854670,4299.0
99.055988477,4275.0
99.106122284,4163.0
99.156256091,4379.0
99.206389898,4325.0
99.256523705,4349.0
99.306657512,4271.0
99.356791319,4375.0
99.406925126,4213.0
99.457058933,4403.0
99.507192740,4277.0
99.557326547,4305.0
99.607460353,4483.0
99.657594160,4293.0
99.707727967,4321.0
99.757861774,4430.0
99.807995581,4359.0
99.858129388,4353.0
99.908263195,4288.0
99.958397002,4287.0
99.991819540,4286.0