File: OriginPro/XRD from Panalytical X'Pert PRO/Nova Cu foil/Cufoil_END_30°C.csv
[Measurement conditions]
Sample identification,
Comment - 1,"finito"
Comment - 2,"Configuration=MRI TC-Basic Stage, Owner=User-1, Creation date=26-10-2009 9:18:44"
Comment - 3,"Goniometer=PW3050/60 (Theta/Theta); Minimum step size 2Theta:0.001; Minimum step size Omega:0.001"
Comment - 4,"Sample stage=MRI TC-Basic (PtRh heat strip)"
Comment - 5,"Diffractometer system=XPERT-PRO"
Comment - 6,"Measurement program=FlatStage, Owner=joana, Creation date=03-08-2011 15:43:53"
Anode material,Cu
K-Alpha1 wavelength,1.5405980
K-Alpha2 wavelength,1.5444260
Ratio K-Alpha2/K-Alpha1,0.500
Divergence slit,Fixed,0.76mm
Monochromator used,NO
Generator voltage, 45
Tube current, 40
File date and time,07/Dec/2012 01:31
Unit cell,
h k l, 0 0 0
Temperature [K],304
Scan axis,Gonio
Scan range,24.999999996,100.000175174
Scan step size,0.0167113
No. of points, 4488
Scan type,CONTINUOUS
Time per step,53.340
[Scan points]
Angle,Intensity
25.008355630,3349.0
25.058489437,3324.0
25.108623244,3434.0
25.158757051,3375.0
25.208890858,3427.0
25.259024665,3327.0
25.309158472,3350.0
25.359292279,3435.0
25.409426086,3278.0
25.459559892,3414.0
25.509693699,3285.0
25.559827506,3352.0
25.609961313,3361.0
25.660095120,3440.0
25.710228927,3323.0
25.760362734,3325.0
25.810496541,3338.0
25.860630348,3429.0
25.910764155,3379.0
25.960897962,3371.0
26.011031769,3330.0
26.061165576,3454.0
26.111299383,3398.0
26.161433190,3339.0
26.211566997,3347.0
26.261700803,3396.0
26.311834610,3412.0
26.361968417,3429.0
26.412102224,3347.0
26.462236031,3453.0
26.512369838,3337.0
26.562503645,3464.0
26.612637452,3287.0
26.662771259,3368.0
26.712905066,3509.0
26.763038873,3544.0
26.813172680,3436.0
26.863306487,3468.0
26.913440294,3446.0
26.963574101,3463.0
27.013707908,3508.0
27.063841714,3482.0
27.113975521,3425.0
27.164109328,3456.0
27.214243135,3503.0
27.264376942,3361.0
27.314510749,3576.0
27.364644556,3468.0
27.414778363,3402.0
27.464912170,3517.0
27.515045977,3433.0
27.565179784,3465.0
27.615313591,3491.0
27.665447398,3595.0
27.715581205,3394.0
27.765715012,3508.0
27.815848819,3539.0
27.865982625,3522.0
27.916116432,3494.0
27.966250239,3529.0
28.016384046,3442.0
28.066517853,3641.0
28.116651660,3569.0
28.166785467,3474.0
28.216919274,3366.0
28.267053081,3452.0
28.317186888,3542.0
28.367320695,3454.0
28.417454502,3532.0
28.467588309,3575.0
28.517722116,3548.0
28.567855923,3591.0
28.617989730,3505.0
28.668123536,3445.0
28.718257343,3533.0
28.768391150,3521.0
28.818524957,3365.0
28.868658764,3651.0
28.918792571,3588.0
28.968926378,3666.0
29.019060185,3611.0
29.069193992,3615.0
29.119327799,3645.0
29.169461606,3768.0
29.219595413,3939.0
29.269729220,4265.0
29.319863027,4455.0
29.369996834,4702.0
29.420130641,5122.0
29.470264447,5402.0
29.520398254,5705.0
29.570532061,5760.0
29.620665868,5928.0
29.670799675,5648.0
29.720933482,5265.0
29.771067289,4587.0
29.821201096,4032.0
29.871334903,3838.0
29.921468710,3751.0
29.971602517,3609.0
30.021736324,3549.0
30.071870131,3620.0
30.122003938,3674.0
30.172137745,3615.0
30.222271552,3540.0
30.272405358,3564.0
30.322539165,3606.0
30.372672972,3513.0
30.422806779,3574.0
30.472940586,3550.0
30.523074393,3611.0
30.573208200,3629.0
30.623342007,3627.0
30.673475814,3598.0
30.723609621,3632.0
30.773743428,3535.0
30.823877235,3591.0
30.874011042,3522.0
30.924144849,3692.0
30.974278656,3590.0
31.024412463,3635.0
31.074546269,3654.0
31.124680076,3537.0
31.174813883,3579.0
31.224947690,3595.0
31.275081497,3594.0
31.325215304,3671.0
31.375349111,3646.0
31.425482918,3685.0
31.475616725,3712.0
31.525750532,3610.0
31.575884339,3747.0
31.626018146,3561.0
31.676151953,3624.0
31.726285760,3578.0
31.776419567,3694.0
31.826553374,3643.0
31.876687180,3715.0
31.926820987,3633.0
31.976954794,3714.0
32.027088601,3656.0
32.077222408,3672.0
32.127356215,3680.0
32.177490022,3739.0
32.227623829,3734.0
32.277757636,3810.0
32.327891443,3734.0
32.378025250,3717.0
32.428159057,3762.0
32.478292864,3715.0
32.528426671,3803.0
32.578560478,3809.0
32.628694285,3828.0
32.678828091,3843.0
32.728961898,3824.0
32.779095705,3835.0
32.829229512,3810.0
32.879363319,3714.0
32.929497126,3814.0
32.979630933,3768.0
33.029764740,3878.0
33.079898547,3656.0
33.130032354,3742.0
33.180166161,3798.0
33.230299968,3715.0
33.280433775,3688.0
33.330567582,3685.0
33.380701389,3622.0
33.430835196,3713.0
33.480969002,3780.0
33.531102809,3695.0
33.581236616,3765.0
33.631370423,3706.0
33.681504230,3688.0
33.731638037,3759.0
33.781771844,3734.0
33.831905651,3747.0
33.882039458,3786.0
33.932173265,3808.0
33.982307072,3866.0
34.032440879,3875.0
34.082574686,3750.0
34.132708493,3789.0
34.182842300,3682.0
34.232976107,3819.0
34.283109913,3732.0
34.333243720,3841.0
34.383377527,3829.0
34.433511334,3749.0
34.483645141,3775.0
34.533778948,3827.0
34.583912755,3768.0
34.634046562,3937.0
34.684180369,3857.0
34.734314176,3852.0
34.784447983,3891.0
34.834581790,3915.0
34.884715597,3902.0
34.934849404,3968.0
34.984983211,4007.0
35.035117018,4004.0
35.085250825,4102.0
35.135384631,4156.0
35.185518438,4204.0
35.235652245,4197.0
35.285786052,4440.0
35.335919859,4522.0
35.386053666,4557.0
35.436187473,4794.0
35.486321280,4989.0
35.536455087,4959.0
35.586588894,5228.0
35.636722701,5223.0
35.686856508,5336.0
35.736990315,5578.0
35.787124122,5891.0
35.837257929,6419.0
35.887391736,6746.0
35.937525542,7497.0
35.987659349,8700.0
36.037793156,10173.0
36.087926963,13063.0
36.138060770,16736.0
36.188194577,21026.0
36.238328384,25689.0
36.288462191,30747.0
36.338595998,35993.0
36.388729805,39742.0
36.438863612,41907.0
36.488997419,40381.0
36.539131226,34811.0
36.589265033,25781.0
36.639398840,17220.0
36.689532647,11056.0
36.739666453,7319.0
36.789800260,5847.0
36.839934067,5285.0
36.890067874,4766.0
36.940201681,4507.0
36.990335488,4454.0
37.040469295,4260.0
37.090603102,4278.0
37.140736909,4230.0
37.190870716,4283.0
37.241004523,4208.0
37.291138330,4183.0
37.341272137,4236.0
37.391405944,4064.0
37.441539751,4079.0
37.491673558,4135.0
37.541807364,4124.0
37.591941171,4108.0
37.642074978,3988.0
37.692208785,4205.0
37.742342592,4219.0
37.792476399,4169.0
37.842610206,4129.0
37.892744013,4081.0
37.942877820,4091.0
37.993011627,4109.0
38.043145434,4072.0
38.093279241,4162.0
38.143413048,4073.0
38.193546855,4114.0
38.243680662,4298.0
38.293814469,4155.0
38.343948275,4165.0
38.394082082,4172.0
38.444215889,4231.0
38.494349696,4264.0
38.544483503,4338.0
38.594617310,4376.0
38.644751117,4347.0
38.694884924,4479.0
38.745018731,4478.0
38.795152538,4531.0
38.845286345,4708.0
38.895420152,4591.0
38.945553959,4516.0
38.995687766,4565.0
39.045821573,4552.0
39.095955380,4463.0
39.146089186,4363.0
39.196222993,4453.0
39.246356800,4334.0
39.296490607,4318.0
39.346624414,4195.0
39.396758221,4130.0
39.446892028,4127.0
39.497025835,4018.0
39.547159642,4122.0
39.597293449,4045.0
39.647427256,4042.0
39.697561063,4132.0
39.747694870,4034.0
39.797828677,4159.0
39.847962484,4100.0
39.898096291,4144.0
39.948230097,4097.0
39.998363904,4073.0
40.048497711,4053.0
40.098631518,3932.0
40.148765325,4034.0
40.198899132,3978.0
40.249032939,4104.0
40.299166746,3949.0
40.349300553,4065.0
40.399434360,4013.0
40.449568167,4017.0
40.499701974,3889.0
40.549835781,3952.0
40.599969588,4066.0
40.650103395,4082.0
40.700237202,4103.0
40.750371008,4066.0
40.800504815,4040.0
40.850638622,4155.0
40.900772429,4000.0
40.950906236,4000.0
41.001040043,4108.0
41.051173850,4066.0
41.101307657,4047.0
41.151441464,4173.0
41.201575271,4149.0
41.251709078,4072.0
41.301842885,4207.0
41.351976692,4321.0
41.402110499,4147.0
41.452244306,4331.0
41.502378113,4355.0
41.552511919,4460.0
41.602645726,4626.0
41.652779533,4771.0
41.702913340,4970.0
41.753047147,5552.0
41.803180954,6127.0
41.853314761,6825.0
41.903448568,7963.0
41.953582375,8838.0
42.003716182,10591.0
42.053849989,11921.0
42.103983796,13273.0
42.154117603,14567.0
42.204251410,15215.0
42.254385217,14826.0
42.304519024,14095.0
42.354652830,12368.0
42.404786637,10362.0
42.454920444,8833.0
42.505054251,7375.0
42.555188058,6219.0
42.605321865,5528.0
42.655455672,5010.0
42.705589479,4862.0
42.755723286,4641.0
42.805857093,4738.0
42.855990900,4967.0
42.906124707,5376.0
42.956258514,5678.0
43.006392321,5875.0
43.056526128,6363.0
43.106659935,7075.0
43.156793741,9559.0
43.206927548,13122.0
43.257061355,13364.0
43.307195162,14457.0
43.357328969,16304.0
43.407462776,19086.0
43.457596583,28393.0
43.507730390,33874.0
43.557864197,34788.0
43.607998004,28736.0
43.658131811,17879.0
43.708265618,12771.0
43.758399425,6412.0
43.808533232,5122.0
43.858667039,4790.0
43.908800846,4518.0
43.958934652,4222.0
44.009068459,4341.0
44.059202266,4255.0
44.109336073,4283.0
44.159469880,4271.0
44.209603687,4219.0
44.259737494,4164.0
44.309871301,4140.0
44.360005108,4075.0
44.410138915,4127.0
44.460272722,4154.0
44.510406529,4023.0
44.560540336,4095.0
44.610674143,4114.0
44.660807950,4189.0
44.710941757,4187.0
44.761075564,4189.0
44.811209370,4226.0
44.861343177,4037.0
44.911476984,4172.0
44.961610791,4167.0
45.011744598,4105.0
45.061878405,4048.0
45.112012212,4123.0
45.162146019,4072.0
45.212279826,4101.0
45.262413633,4198.0
45.312547440,4122.0
45.362681247,4058.0
45.412815054,4153.0
45.462948861,4202.0
45.513082668,4134.0
45.563216475,4039.0
45.613350281,4107.0
45.663484088,4003.0
45.713617895,4109.0
45.763751702,4192.0
45.813885509,4160.0
45.864019316,4028.0
45.914153123,3979.0
45.964286930,4055.0
46.014420737,4043.0
46.064554544,4040.0
46.114688351,4147.0
46.164822158,4107.0
46.214955965,4144.0
46.265089772,4122.0
46.315223579,4197.0
46.365357386,4121.0
46.415491192,4266.0
46.465624999,5309.0
46.515758806,6900.0
46.565892613,4745.0
46.616026420,5179.0
46.666160227,4780.0
46.716294034,4064.0
46.766427841,4141.0
46.816561648,4029.0
46.866695455,4029.0
46.916829262,3997.0
46.966963069,4212.0
47.017096876,4014.0
47.067230683,4046.0
47.117364490,4047.0
47.167498297,3899.0
47.217632103,3978.0
47.267765910,4104.0
47.317899717,4074.0
47.368033524,4171.0
47.418167331,4100.0
47.468301138,4011.0
47.518434945,4037.0
47.568568752,4081.0
47.618702559,3877.0
47.668836366,3971.0
47.718970173,4066.0
47.769103980,3951.0
47.819237787,4020.0
47.869371594,4118.0
47.919505401,4116.0
47.969639208,4057.0
48.019773014,3919.0
48.069906821,3937.0
48.120040628,4078.0
48.170174435,3954.0
48.220308242,4062.0
48.270442049,3998.0
48.320575856,4102.0
48.370709663,3984.0
48.420843470,4131.0
48.470977277,4055.0
48.521111084,4173.0
48.571244891,4112.0
48.621378698,4205.0
48.671512505,4207.0
48.721646312,4346.0
48.771780119,4413.0
48.821913925,4532.0
48.872047732,4521.0
48.922181539,4496.0
48.972315346,4467.0
49.022449153,4370.0
49.072582960,4382.0
49.122716767,4323.0
49.172850574,4337.0
49.222984381,4163.0
49.273118188,4143.0
49.323251995,4181.0
49.373385802,4147.0
49.423519609,4263.0
49.473653416,4180.0
49.523787223,4171.0
49.573921030,4210.0
49.624054836,4207.0
49.674188643,4068.0
49.724322450,4161.0
49.774456257,4190.0
49.824590064,4224.0
49.874723871,4196.0
49.924857678,4165.0
49.974991485,4452.0
50.025125292,4727.0
50.075259099,4522.0
50.125392906,4587.0
50.175526713,4668.0
50.225660520,4857.0
50.275794327,5795.0
50.325928134,8489.0
50.376061941,10315.0
50.426195747,9816.0
50.476329554,10504.0
50.526463361,11453.0
50.576597168,14912.0
50.626730975,25981.0
50.676864782,35196.0
50.726998589,31628.0
50.777132396,24072.0
50.827266203,19934.0
50.877400010,13915.0
50.927533817,7544.0
50.977667624,5308.0
51.027801431,4720.0
51.077935238,4593.0
51.128069045,4348.0
51.178202852,4275.0
51.228336658,4193.0
51.278470465,4260.0
51.328604272,4188.0
51.378738079,4216.0
51.428871886,4239.0
51.479005693,4175.0
51.529139500,4334.0
51.579273307,4000.0
51.629407114,4139.0
51.679540921,4090.0
51.729674728,4182.0
51.779808535,4096.0
51.829942342,4108.0
51.880076149,4158.0
51.930209956,4183.0
51.980343763,4171.0
52.030477569,4245.0
52.080611376,4219.0
52.130745183,4312.0
52.180878990,4376.0
52.231012797,4398.0
52.281146604,4353.0
52.331280411,4545.0
52.381414218,4527.0
52.431548025,4532.0
52.481681832,4315.0
52.531815639,4484.0
52.581949446,4400.0
52.632083253,4255.0
52.682217060,4191.0
52.732350867,4117.0
52.782484674,4156.0
52.832618480,4051.0
52.882752287,4170.0
52.932886094,4062.0
52.983019901,3918.0
53.033153708,4138.0
53.083287515,4029.0
53.133421322,4003.0
53.183555129,4067.0
53.233688936,4042.0
53.283822743,4011.0
53.333956550,4070.0
53.384090357,4149.0
53.434224164,4031.0
53.484357971,4036.0
53.534491778,4125.0
53.584625585,3996.0
53.634759391,3991.0
53.684893198,4055.0
53.735027005,4031.0
53.785160812,4085.0
53.835294619,4030.0
53.885428426,4028.0
53.935562233,4019.0
53.985696040,4097.0
54.035829847,4034.0
54.085963654,4029.0
54.136097461,4150.0
54.186231268,4155.0
54.236365075,4040.0
54.286498882,4150.0
54.336632689,4076.0
54.386766496,4135.0
54.436900303,4065.0
54.487034109,4026.0
54.537167916,4063.0
54.587301723,4019.0
54.637435530,4068.0
54.687569337,4085.0
54.737703144,3910.0
54.787836951,4127.0
54.837970758,4084.0
54.888104565,4082.0
54.938238372,4084.0
54.988372179,4132.0
55.038505986,3961.0
55.088639793,4034.0
55.138773600,4070.0
55.188907407,4196.0
55.239041214,4086.0
55.289175020,4057.0
55.339308827,4038.0
55.389442634,4013.0
55.439576441,4060.0
55.489710248,4018.0
55.539844055,4082.0
55.589977862,4084.0
55.640111669,3968.0
55.690245476,4003.0
55.740379283,4026.0
55.790513090,3998.0
55.840646897,3944.0
55.890780704,4088.0
55.940914511,4039.0
55.991048318,4041.0
56.041182125,3961.0
56.091315931,3934.0
56.141449738,3972.0
56.191583545,4156.0
56.241717352,4132.0
56.291851159,4088.0
56.341984966,4005.0
56.392118773,4097.0
56.442252580,4154.0
56.492386387,4149.0
56.542520194,4025.0
56.592654001,4100.0
56.642787808,4158.0
56.692921615,4152.0
56.743055422,4004.0
56.793189229,4020.0
56.843323036,4119.0
56.893456842,4154.0
56.943590649,4067.0
56.993724456,4095.0
57.043858263,4025.0
57.093992070,4019.0
57.144125877,4091.0
57.194259684,4047.0
57.244393491,4133.0
57.294527298,4104.0
57.344661105,4059.0
57.394794912,4024.0
57.444928719,4117.0
57.495062526,4074.0
57.545196333,4101.0
57.595330140,4055.0
57.645463947,4037.0
57.695597753,4005.0
57.745731560,4043.0
57.795865367,4019.0
57.845999174,4119.0
57.896132981,4035.0
57.946266788,4126.0
57.996400595,4039.0
58.046534402,4028.0
58.096668209,3990.0
58.146802016,4101.0
58.196935823,4095.0
58.247069630,4123.0
58.297203437,4127.0
58.347337244,4213.0
58.397471051,4102.0
58.447604858,4091.0
58.497738664,4253.0
58.547872471,4150.0
58.598006278,4084.0
58.648140085,4068.0
58.698273892,4157.0
58.748407699,4045.0
58.798541506,4237.0
58.848675313,4109.0
58.898809120,4164.0
58.948942927,4161.0
58.999076734,4068.0
59.049210541,4091.0
59.099344348,4157.0
59.149478155,4204.0
59.199611962,4113.0
59.249745769,4174.0
59.299879575,4094.0
59.350013382,4142.0
59.400147189,4088.0
59.450280996,4090.0
59.500414803,4199.0
59.550548610,4178.0
59.600682417,4174.0
59.650816224,4182.0
59.700950031,4275.0
59.751083838,4152.0
59.801217645,4163.0
59.851351452,4168.0
59.901485259,4238.0
59.951619066,4136.0
60.001752873,4221.0
60.051886680,4114.0
60.102020486,4136.0
60.152154293,4278.0
60.202288100,4267.0
60.252421907,4246.0
60.302555714,4181.0
60.352689521,4311.0
60.402823328,4382.0
60.452957135,4255.0
60.503090942,4281.0
60.553224749,4410.0
60.603358556,4460.0
60.653492363,4703.0
60.703626170,4871.0
60.753759977,5008.0
60.803893784,5439.0
60.854027591,5995.0
60.904161397,6645.0
60.954295204,7194.0
61.004429011,8014.0
61.054562818,9183.0
61.104696625,10242.0
61.154830432,11269.0
61.204964239,11856.0
61.255098046,12079.0
61.305231853,12021.0
61.355365660,11293.0
61.405499467,10508.0
61.455633274,9291.0
61.505767081,8051.0
61.555900888,6893.0
61.606034695,6180.0
61.656168502,5605.0
61.706302308,5074.0
61.756436115,4743.0
61.806569922,4571.0
61.856703729,4430.0
61.906837536,4399.0
61.956971343,4319.0
62.007105150,4413.0
62.057238957,4332.0
62.107372764,4231.0
62.157506571,4127.0
62.207640378,4150.0
62.257774185,4168.0
62.307907992,4215.0
62.358041799,4179.0
62.408175606,4198.0
62.458309413,4210.0
62.508443219,4168.0
62.558577026,4193.0
62.608710833,4167.0
62.658844640,4265.0
62.708978447,4039.0
62.759112254,4227.0
62.809246061,4133.0
62.859379868,4175.0
62.909513675,4081.0
62.959647482,4059.0
63.009781289,4135.0
63.059915096,4225.0
63.110048903,4205.0
63.160182710,4094.0
63.210316517,4302.0
63.260450324,4076.0
63.310584130,4111.0
63.360717937,4174.0
63.410851744,4200.0
63.460985551,4078.0
63.511119358,4174.0
63.561253165,4186.0
63.611386972,4130.0
63.661520779,4134.0
63.711654586,4105.0
63.761788393,4105.0
63.811922200,4240.0
63.862056007,4081.0
63.912189814,4150.0
63.962323621,4231.0
64.012457428,4130.0
64.062591235,4151.0
64.112725041,4135.0
64.162858848,4227.0
64.212992655,4197.0
64.263126462,4181.0
64.313260269,4119.0
64.363394076,4187.0
64.413527883,4051.0
64.463661690,4099.0
64.513795497,4108.0
64.563929304,4138.0
64.614063111,4047.0
64.664196918,4168.0
64.714330725,4293.0
64.764464532,4210.0
64.814598339,4092.0
64.864732146,4124.0
64.914865953,4039.0
64.964999759,4181.0
65.015133566,4130.0
65.065267373,4134.0
65.115401180,4120.0
65.165534987,4050.0
65.215668794,4133.0
65.265802601,4285.0
65.315936408,4146.0
65.366070215,4042.0
65.416204022,4150.0
65.466337829,4144.0
65.516471636,4164.0
65.566605443,4190.0
65.616739250,4208.0
65.666873057,4233.0
65.717006864,4196.0
65.767140670,4239.0
65.817274477,4123.0
65.867408284,4152.0
65.917542091,4253.0
65.967675898,4240.0
66.017809705,4289.0
66.067943512,4211.0
66.118077319,4302.0
66.168211126,4271.0
66.218344933,4408.0
66.268478740,4343.0
66.318612547,4437.0
66.368746354,4489.0
66.418880161,4301.0
66.469013968,4293.0
66.519147775,4354.0
66.569281581,4371.0
66.619415388,4468.0
66.669549195,4365.0
66.719683002,4220.0
66.769816809,4292.0
66.819950616,4275.0
66.870084423,4253.0
66.920218230,4189.0
66.970352037,4241.0
67.020485844,4174.0
67.070619651,4098.0
67.120753458,4326.0
67.170887265,4112.0
67.221021072,4210.0
67.271154879,4228.0
67.321288686,4217.0
67.371422492,4133.0
67.421556299,4105.0
67.471690106,4161.0
67.521823913,4201.0
67.571957720,4215.0
67.622091527,4285.0
67.672225334,4356.0
67.722359141,4059.0
67.772492948,4120.0
67.822626755,4145.0
67.872760562,4163.0
67.922894369,4262.0
67.973028176,4323.0
68.023161983,4645.0
68.073295790,4281.0
68.123429597,4229.0
68.173563403,4310.0
68.223697210,4379.0
68.273831017,4304.0
68.323964824,4244.0
68.374098631,4226.0
68.424232438,4234.0
68.474366245,4058.0
68.524500052,4211.0
68.574633859,4253.0
68.624767666,4201.0
68.674901473,4238.0
68.725035280,4168.0
68.775169087,4193.0
68.825302894,4242.0
68.875436701,4112.0
68.925570508,4129.0
68.975704314,4137.0
69.025838121,3982.0
69.075971928,4175.0
69.126105735,4150.0
69.176239542,4198.0
69.226373349,4172.0
69.276507156,4257.0
69.326640963,4275.0
69.376774770,4212.0
69.426908577,4233.0
69.477042384,4173.0
69.527176191,4174.0
69.577309998,4146.0
69.627443805,4154.0
69.677577612,4217.0
69.727711419,4158.0
69.777845225,4152.0
69.827979032,4273.0
69.878112839,4046.0
69.928246646,4140.0
69.978380453,4219.0
70.028514260,4227.0
70.078648067,4187.0
70.128781874,4223.0
70.178915681,4131.0
70.229049488,4205.0
70.279183295,4125.0
70.329317102,4331.0
70.379450909,4243.0
70.429584716,4176.0
70.479718523,4171.0
70.529852330,4176.0
70.579986136,4274.0
70.630119943,4137.0
70.680253750,4222.0
70.730387557,4289.0
70.780521364,4218.0
70.830655171,4189.0
70.880788978,4116.0
70.930922785,4177.0
70.981056592,4211.0
71.031190399,4268.0
71.081324206,4154.0
71.131458013,4140.0
71.181591820,4114.0
71.231725627,4248.0
71.281859434,4269.0
71.331993241,4170.0
71.382127047,4162.0
71.432260854,4284.0
71.482394661,4332.0
71.532528468,4239.0
71.582662275,4218.0
71.632796082,4153.0
71.682929889,4160.0
71.733063696,4273.0
71.783197503,4235.0
71.833331310,4325.0
71.883465117,4266.0
71.933598924,4303.0
71.983732731,4304.0
72.033866538,4287.0
72.084000345,4209.0
72.134134152,4282.0
72.184267958,4302.0
72.234401765,4410.0
72.284535572,4394.0
72.334669379,4310.0
72.384803186,4320.0
72.434936993,4372.0
72.485070800,4454.0
72.535204607,4509.0
72.585338414,4500.0
72.635472221,4560.0
72.685606028,4768.0
72.735739835,4953.0
72.785873642,5216.0
72.836007449,5389.0
72.886141256,5639.0
72.936275063,5923.0
72.986408869,6193.0
73.036542676,6865.0
73.086676483,7263.0
73.136810290,7665.0
73.186944097,7973.0
73.237077904,8279.0
73.287211711,8530.0
73.337345518,8538.0
73.387479325,8447.0
73.437613132,7988.0
73.487746939,7520.0
73.537880746,7316.0
73.588014553,6707.0
73.638148360,6272.0
73.688282167,5931.0
73.738415974,5521.0
73.788549780,5395.0
73.838683587,5289.0
73.888817394,5391.0
73.938951201,5445.0
73.989085008,6097.0
74.039218815,7150.0
74.089352622,7432.0
74.139486429,7400.0
74.189620236,7819.0
74.239754043,9749.0
74.289887850,12626.0
74.340021657,14102.0
74.390155464,10772.0
74.440289271,7738.0
74.490423078,7953.0
74.540556885,8898.0
74.590690692,7556.0
74.640824498,5507.0
74.690958305,4935.0
74.741092112,4480.0
74.791225919,4345.0
74.841359726,4397.0
74.891493533,4290.0
74.941627340,4307.0
74.991761147,4308.0
75.041894954,4284.0
75.092028761,4435.0
75.142162568,4301.0
75.192296375,4392.0
75.242430182,4317.0
75.292563989,4232.0
75.342697796,4232.0
75.392831603,4248.0
75.442965409,4258.0
75.493099216,4288.0
75.543233023,4287.0
75.593366830,4426.0
75.643500637,4216.0
75.693634444,4182.0
75.743768251,4304.0
75.793902058,4256.0
75.844035865,4296.0
75.894169672,4183.0
75.944303479,4230.0
75.994437286,4289.0
76.044571093,4140.0
76.094704900,4074.0
76.144838707,4270.0
76.194972514,4097.0
76.245106320,4256.0
76.295240127,4186.0
76.345373934,4208.0
76.395507741,4158.0
76.445641548,4220.0
76.495775355,4199.0
76.545909162,4142.0
76.596042969,4227.0
76.646176776,4368.0
76.696310583,4413.0
76.746444390,4482.0
76.796578197,4371.0
76.846712004,4689.0
76.896845811,4618.0
76.946979618,4766.0
76.997113425,4929.0
77.047247231,4856.0
77.097381038,5013.0
77.147514845,5146.0
77.197648652,5178.0
77.247782459,5136.0
77.297916266,5033.0
77.348050073,4980.0
77.398183880,4878.0
77.448317687,4842.0
77.498451494,4639.0
77.548585301,4627.0
77.598719108,4568.0
77.648852915,4364.0
77.698986722,4325.0
77.749120529,4281.0
77.799254336,4339.0
77.849388142,4252.0
77.899521949,4120.0
77.949655756,4231.0
77.999789563,4147.0
78.049923370,4226.0
78.100057177,4158.0
78.150190984,4101.0
78.200324791,4265.0
78.250458598,4092.0
78.300592405,4237.0
78.350726212,4194.0
78.400860019,4078.0
78.450993826,4260.0
78.501127633,4369.0
78.551261440,4185.0
78.601395247,4115.0
78.651529053,4206.0
78.701662860,4124.0
78.751796667,4003.0
78.801930474,4117.0
78.852064281,4153.0
78.902198088,4146.0
78.952331895,4216.0
79.002465702,4275.0
79.052599509,4179.0
79.102733316,4214.0
79.152867123,4254.0
79.203000930,4124.0
79.253134737,4148.0
79.303268544,4169.0
79.353402351,4140.0
79.403536158,4143.0
79.453669964,4156.0
79.503803771,4226.0
79.553937578,4180.0
79.604071385,4298.0
79.654205192,4085.0
79.704338999,4116.0
79.754472806,4279.0
79.804606613,4067.0
79.854740420,3985.0
79.904874227,4150.0
79.955008034,4161.0
80.005141841,4233.0
80.055275648,4213.0
80.105409455,4117.0
80.155543262,4113.0
80.205677069,4181.0
80.255810875,4230.0
80.305944682,4146.0
80.356078489,4024.0
80.406212296,4240.0
80.456346103,4358.0
80.506479910,4098.0
80.556613717,4241.0
80.606747524,4041.0
80.656881331,4223.0
80.707015138,4215.0
80.757148945,4160.0
80.807282752,4202.0
80.857416559,4175.0
80.907550366,4221.0
80.957684173,4128.0
81.007817980,4216.0
81.057951786,4136.0
81.108085593,4215.0
81.158219400,4318.0
81.208353207,4207.0
81.258487014,4113.0
81.308620821,4133.0
81.358754628,4056.0
81.408888435,4168.0
81.459022242,4124.0
81.509156049,4274.0
81.559289856,4141.0
81.609423663,4308.0
81.659557470,4232.0
81.709691277,4105.0
81.759825084,4278.0
81.809958891,4283.0
81.860092697,4259.0
81.910226504,4178.0
81.960360311,4283.0
82.010494118,4537.0
82.060627925,4491.0
82.110761732,4195.0
82.160895539,4331.0
82.211029346,4190.0
82.261163153,4293.0
82.311296960,4404.0
82.361430767,4232.0
82.411564574,4147.0
82.461698381,4178.0
82.511832188,4126.0
82.561965995,4152.0
82.612099802,4094.0
82.662233608,4199.0
82.712367415,4160.0
82.762501222,4131.0
82.812635029,4098.0
82.862768836,4129.0
82.912902643,4275.0
82.963036450,4104.0
83.013170257,4315.0
83.063304064,4135.0
83.113437871,4118.0
83.163571678,4053.0
83.213705485,4145.0
83.263839292,4096.0
83.313973099,4148.0
83.364106906,4146.0
83.414240713,4179.0
83.464374519,4167.0
83.514508326,4178.0
83.564642133,4075.0
83.614775940,4213.0
83.664909747,4143.0
83.715043554,4126.0
83.765177361,4294.0
83.815311168,4192.0
83.865444975,4272.0
83.915578782,4127.0
83.965712589,4157.0
84.015846396,4031.0
84.065980203,4073.0
84.116114010,4149.0
84.166247817,4011.0
84.216381624,4219.0
84.266515431,4229.0
84.316649237,4289.0
84.366783044,4185.0
84.416916851,4195.0
84.467050658,4138.0
84.517184465,4127.0
84.567318272,4109.0
84.617452079,4208.0
84.667585886,4078.0
84.717719693,4163.0
84.767853500,4120.0
84.817987307,4197.0
84.868121114,4164.0
84.918254921,4241.0
84.968388728,4105.0
85.018522535,4278.0
85.068656342,4140.0
85.118790148,4045.0
85.168923955,4147.0
85.219057762,4072.0
85.269191569,4108.0
85.319325376,4174.0
85.369459183,4130.0
85.419592990,4030.0
85.469726797,3970.0
85.519860604,4142.0
85.569994411,4221.0
85.620128218,4252.0
85.670262025,4097.0
85.720395832,4325.0
85.770529639,4153.0
85.820663446,4128.0
85.870797253,4133.0
85.920931059,4178.0
85.971064866,4068.0
86.021198673,4084.0
86.071332480,4258.0
86.121466287,4208.0
86.171600094,4158.0
86.221733901,4181.0
86.271867708,4230.0
86.322001515,4112.0
86.372135322,4109.0
86.422269129,4210.0
86.472402936,4278.0
86.522536743,4222.0
86.572670550,4254.0
86.622804357,4213.0
86.672938164,4206.0
86.723071970,4118.0
86.773205777,4114.0
86.823339584,4120.0
86.873473391,4365.0
86.923607198,4153.0
86.973741005,4203.0
87.023874812,3990.0
87.074008619,4246.0
87.124142426,4205.0
87.174276233,4300.0
87.224410040,4106.0
87.274543847,4181.0
87.324677654,4325.0
87.374811461,4186.0
87.424945268,4243.0
87.475079075,4150.0
87.525212881,4243.0
87.575346688,4057.0
87.625480495,4199.0
87.675614302,4104.0
87.725748109,4032.0
87.775881916,4122.0
87.826015723,4218.0
87.876149530,4126.0
87.926283337,4223.0
87.976417144,4159.0
88.026550951,4150.0
88.076684758,4065.0
88.126818565,4212.0
88.176952372,4227.0
88.227086179,4162.0
88.277219986,4188.0
88.327353792,4288.0
88.377487599,4037.0
88.427621406,4129.0
88.477755213,4121.0
88.527889020,4117.0
88.578022827,4116.0
88.628156634,4139.0
88.678290441,4169.0
88.728424248,4004.0
88.778558055,4213.0
88.828691862,4147.0
88.878825669,4100.0
88.928959476,4150.0
88.979093283,4265.0
89.029227090,4129.0
89.079360897,4188.0
89.129494703,4231.0
89.179628510,3971.0
89.229762317,4230.0
89.279896124,4229.0
89.330029931,4284.0
89.380163738,4105.0
89.430297545,4388.0
89.480431352,4145.0
89.530565159,4319.0
89.580698966,4385.0
89.630832773,4644.0
89.680966580,4787.0
89.731100387,5178.0
89.781234194,5516.0
89.831368001,6114.0
89.881501808,6960.0
89.931635614,7793.0
89.981769421,8150.0
90.031903228,8263.0
90.082037035,8484.0
90.132170842,8774.0
90.182304649,7925.0
90.232438456,6978.0
90.282572263,6362.0
90.332706070,6383.0
90.382839877,6098.0
90.432973684,5779.0
90.483107491,5267.0
90.533241298,4739.0
90.583375105,4450.0
90.633508912,4336.0
90.683642719,4320.0
90.733776525,4248.0
90.783910332,4157.0
90.834044139,4150.0
90.884177946,4199.0
90.934311753,4234.0
90.984445560,4246.0
91.034579367,4150.0
91.084713174,4084.0
91.134846981,4230.0
91.184980788,4361.0
91.235114595,4114.0
91.285248402,4203.0
91.335382209,4369.0
91.385516016,4396.0
91.435649823,4410.0
91.485783630,4395.0
91.535917436,4427.0
91.586051243,4429.0
91.636185050,4331.0
91.686318857,4356.0
91.736452664,4488.0
91.786586471,4502.0
91.836720278,4555.0
91.886854085,4573.0
91.936987892,4576.0
91.987121699,4453.0
92.037255506,4570.0
92.087389313,4501.0
92.137523120,4473.0
92.187656927,4575.0
92.237790734,4637.0
92.287924541,4272.0
92.338058347,4405.0
92.388192154,4349.0
92.438325961,4444.0
92.488459768,4298.0
92.538593575,4266.0
92.588727382,4301.0
92.638861189,4213.0
92.688994996,4219.0
92.739128803,4223.0
92.789262610,4248.0
92.839396417,4225.0
92.889530224,4224.0
92.939664031,4303.0
92.989797838,4209.0
93.039931645,4235.0
93.090065452,4101.0
93.140199258,4136.0
93.190333065,4139.0
93.240466872,4207.0
93.290600679,4070.0
93.340734486,4185.0
93.390868293,4216.0
93.441002100,4136.0
93.491135907,4203.0
93.541269714,4103.0
93.591403521,4318.0
93.641537328,4215.0
93.691671135,4126.0
93.741804942,4238.0
93.791938749,4150.0
93.842072556,4230.0
93.892206363,4212.0
93.942340170,4312.0
93.992473976,4107.0
94.042607783,4297.0
94.092741590,4144.0
94.142875397,4229.0
94.193009204,4208.0
94.243143011,4166.0
94.293276818,4009.0
94.343410625,4267.0
94.393544432,4177.0
94.443678239,4098.0
94.493812046,4217.0
94.543945853,4155.0
94.594079660,4144.0
94.644213467,4188.0
94.694347274,4148.0
94.744481081,4222.0
94.794614887,4471.0
94.844748694,4343.0
94.894882501,4343.0
94.945016308,4476.0
94.995150115,4641.0
95.045283922,5183.0
95.095417729,6007.0
95.145551536,5926.0
95.195685343,6120.0
95.245819150,6894.0
95.295952957,7756.0
95.346086764,8319.0
95.396220571,7019.0
95.446354378,5879.0
95.496488185,5352.0
95.546621992,5425.0
95.596755798,5728.0
95.646889605,6080.0
95.697023412,5278.0
95.747157219,4663.0
95.797291026,4439.0
95.847424833,4308.0
95.897558640,4230.0
95.947692447,4208.0
95.997826254,4259.0
96.047960061,4007.0
96.098093868,4218.0
96.148227675,4239.0
96.198361482,4123.0
96.248495289,4188.0
96.298629096,4072.0
96.348762903,4125.0
96.398896709,4173.0
96.449030516,4368.0
96.499164323,4346.0
96.549298130,4084.0
96.599431937,4204.0
96.649565744,4231.0
96.699699551,4192.0
96.749833358,4092.0
96.799967165,4114.0
96.850100972,4188.0
96.900234779,4070.0
96.950368586,4182.0
97.000502393,4177.0
97.050636200,4128.0
97.100770007,4271.0
97.150903814,4283.0
97.201037620,4004.0
97.251171427,4158.0
97.301305234,4174.0
97.351439041,4205.0
97.401572848,4215.0
97.451706655,4235.0
97.501840462,4185.0
97.551974269,4197.0
97.602108076,4269.0
97.652241883,4119.0
97.702375690,4185.0
97.752509497,4231.0
97.802643304,4289.0
97.852777111,4144.0
97.902910918,4077.0
97.953044725,4137.0
98.003178531,4209.0
98.053312338,4027.0
98.103446145,4060.0
98.153579952,4186.0
98.203713759,4202.0
98.253847566,4187.0
98.303981373,4225.0
98.354115180,4197.0
98.404248987,4208.0
98.454382794,4225.0
98.504516601,4189.0
98.554650408,4273.0
98.604784215,4268.0
98.654918022,4148.0
98.705051829,4258.0
98.755185636,4073.0
98.805319442,4064.0
98.855453249,4239.0
98.905587056,4113.0
98.955720863,4305.0
99.005854670,4267.0
99.055988477,4259.0
99.106122284,4184.0
99.156256091,4227.0
99.206389898,4286.0
99.256523705,4140.0
99.306657512,4200.0
99.356791319,4193.0
99.406925126,4142.0
99.457058933,4068.0
99.507192740,4186.0
99.557326547,4254.0
99.607460353,4149.0
99.657594160,4216.0
99.707727967,4059.0
99.757861774,4214.0
99.807995581,4113.0
99.858129388,4194.0
99.908263195,4189.0
99.958397002,4215.0
99.991819540,4181.0