File: OriginPro/XRD from Panalytical X'Pert PRO/Nova Cu foil/Cufoil_200°C.csv
[Measurement conditions]
Sample identification,
Comment - 1,"finito"
Comment - 2,"Configuration=MRI TC-Basic Stage, Owner=User-1, Creation date=26-10-2009 9:18:44"
Comment - 3,"Goniometer=PW3050/60 (Theta/Theta); Minimum step size 2Theta:0.001; Minimum step size Omega:0.001"
Comment - 4,"Sample stage=MRI TC-Basic (PtRh heat strip)"
Comment - 5,"Diffractometer system=XPERT-PRO"
Comment - 6,"Measurement program=FlatStage, Owner=joana, Creation date=03-08-2011 15:43:53"
Anode material,Cu
K-Alpha1 wavelength,1.5405980
K-Alpha2 wavelength,1.5444260
Ratio K-Alpha2/K-Alpha1,0.500
Divergence slit,Fixed,0.76mm
Monochromator used,NO
Generator voltage, 45
Tube current, 40
File date and time,06/Dec/2012 21:18
Unit cell,
h k l, 0 0 0
Temperature [K],473
Scan axis,Gonio
Scan range,24.999999996,100.000175174
Scan step size,0.0167113
No. of points, 4488
Scan type,CONTINUOUS
Time per step,53.340
[Scan points]
Angle,Intensity
25.008355630,4553.0
25.058489437,4503.0
25.108623244,4650.0
25.158757051,4515.0
25.208890858,4502.0
25.259024665,4412.0
25.309158472,4524.0
25.359292279,4623.0
25.409426086,4532.0
25.459559892,4391.0
25.509693699,4403.0
25.559827506,4475.0
25.609961313,4515.0
25.660095120,4445.0
25.710228927,4658.0
25.760362734,4501.0
25.810496541,4441.0
25.860630348,4467.0
25.910764155,4500.0
25.960897962,4502.0
26.011031769,4491.0
26.061165576,4531.0
26.111299383,4406.0
26.161433190,4498.0
26.211566997,4392.0
26.261700803,4488.0
26.311834610,4527.0
26.361968417,4463.0
26.412102224,4404.0
26.462236031,4516.0
26.512369838,4601.0
26.562503645,4488.0
26.612637452,4403.0
26.662771259,4533.0
26.712905066,4400.0
26.763038873,4520.0
26.813172680,4497.0
26.863306487,4523.0
26.913440294,4458.0
26.963574101,4572.0
27.013707908,4561.0
27.063841714,4488.0
27.113975521,4500.0
27.164109328,4403.0
27.214243135,4367.0
27.264376942,4405.0
27.314510749,4417.0
27.364644556,4360.0
27.414778363,4412.0
27.464912170,4452.0
27.515045977,4432.0
27.565179784,4548.0
27.615313591,4405.0
27.665447398,4487.0
27.715581205,4335.0
27.765715012,4529.0
27.815848819,4379.0
27.865982625,4546.0
27.916116432,4494.0
27.966250239,4407.0
28.016384046,4517.0
28.066517853,4428.0
28.116651660,4489.0
28.166785467,4464.0
28.216919274,4449.0
28.267053081,4533.0
28.317186888,4522.0
28.367320695,4503.0
28.417454502,4583.0
28.467588309,4458.0
28.517722116,4390.0
28.567855923,4287.0
28.617989730,4465.0
28.668123536,4348.0
28.718257343,4414.0
28.768391150,4512.0
28.818524957,4396.0
28.868658764,4491.0
28.918792571,4437.0
28.968926378,4435.0
29.019060185,4430.0
29.069193992,4386.0
29.119327799,4296.0
29.169461606,4471.0
29.219595413,4423.0
29.269729220,4490.0
29.319863027,4407.0
29.369996834,4320.0
29.420130641,4449.0
29.470264447,4348.0
29.520398254,4574.0
29.570532061,4461.0
29.620665868,4456.0
29.670799675,4548.0
29.720933482,4323.0
29.771067289,4367.0
29.821201096,4459.0
29.871334903,4407.0
29.921468710,4346.0
29.971602517,4467.0
30.021736324,4171.0
30.071870131,4305.0
30.122003938,4454.0
30.172137745,4479.0
30.222271552,4403.0
30.272405358,4495.0
30.322539165,4495.0
30.372672972,4476.0
30.422806779,4328.0
30.472940586,4499.0
30.523074393,4364.0
30.573208200,4328.0
30.623342007,4519.0
30.673475814,4372.0
30.723609621,4360.0
30.773743428,4357.0
30.823877235,4460.0
30.874011042,4330.0
30.924144849,4457.0
30.974278656,4372.0
31.024412463,4348.0
31.074546269,4387.0
31.124680076,4355.0
31.174813883,4397.0
31.224947690,4398.0
31.275081497,4459.0
31.325215304,4342.0
31.375349111,4420.0
31.425482918,4354.0
31.475616725,4533.0
31.525750532,4431.0
31.575884339,4504.0
31.626018146,4377.0
31.676151953,4348.0
31.726285760,4359.0
31.776419567,4422.0
31.826553374,4438.0
31.876687180,4302.0
31.926820987,4465.0
31.976954794,4288.0
32.027088601,4413.0
32.077222408,4382.0
32.127356215,4340.0
32.177490022,4431.0
32.227623829,4319.0
32.277757636,4374.0
32.327891443,4291.0
32.378025250,4418.0
32.428159057,4372.0
32.478292864,4421.0
32.528426671,4421.0
32.578560478,4365.0
32.628694285,4358.0
32.678828091,4252.0
32.728961898,4345.0
32.779095705,4467.0
32.829229512,4331.0
32.879363319,4402.0
32.929497126,4438.0
32.979630933,4393.0
33.029764740,4410.0
33.079898547,4491.0
33.130032354,4426.0
33.180166161,4534.0
33.230299968,4367.0
33.280433775,4363.0
33.330567582,4240.0
33.380701389,4357.0
33.430835196,4500.0
33.480969002,4405.0
33.531102809,4288.0
33.581236616,4469.0
33.631370423,4404.0
33.681504230,4204.0
33.731638037,4410.0
33.781771844,4359.0
33.831905651,4355.0
33.882039458,4466.0
33.932173265,4342.0
33.982307072,4401.0
34.032440879,4323.0
34.082574686,4399.0
34.132708493,4454.0
34.182842300,4413.0
34.232976107,4414.0
34.283109913,4389.0
34.333243720,4392.0
34.383377527,4328.0
34.433511334,4361.0
34.483645141,4326.0
34.533778948,4425.0
34.583912755,4267.0
34.634046562,4419.0
34.684180369,4480.0
34.734314176,4272.0
34.784447983,4428.0
34.834581790,4394.0
34.884715597,4374.0
34.934849404,4473.0
34.984983211,4557.0
35.035117018,4369.0
35.085250825,4436.0
35.135384631,4350.0
35.185518438,4549.0
35.235652245,4339.0
35.285786052,4431.0
35.335919859,4401.0
35.386053666,4306.0
35.436187473,4381.0
35.486321280,4453.0
35.536455087,4429.0
35.586588894,4445.0
35.636722701,4393.0
35.686856508,4374.0
35.736990315,4292.0
35.787124122,4404.0
35.837257929,4432.0
35.887391736,4518.0
35.937525542,4558.0
35.987659349,4330.0
36.037793156,4406.0
36.087926963,4276.0
36.138060770,4388.0
36.188194577,4412.0
36.238328384,4292.0
36.288462191,4415.0
36.338595998,4495.0
36.388729805,4368.0
36.438863612,4419.0
36.488997419,4384.0
36.539131226,4419.0
36.589265033,4437.0
36.639398840,4424.0
36.689532647,4456.0
36.739666453,4405.0
36.789800260,4409.0
36.839934067,4352.0
36.890067874,4431.0
36.940201681,4297.0
36.990335488,4361.0
37.040469295,4428.0
37.090603102,4483.0
37.140736909,4516.0
37.190870716,4427.0
37.241004523,4371.0
37.291138330,4443.0
37.341272137,4451.0
37.391405944,4397.0
37.441539751,4526.0
37.491673558,4475.0
37.541807364,4474.0
37.591941171,4409.0
37.642074978,4520.0
37.692208785,4409.0
37.742342592,4477.0
37.792476399,4439.0
37.842610206,4577.0
37.892744013,4472.0
37.942877820,4477.0
37.993011627,4457.0
38.043145434,4563.0
38.093279241,4458.0
38.143413048,4554.0
38.193546855,4631.0
38.243680662,4512.0
38.293814469,4569.0
38.343948275,4428.0
38.394082082,4561.0
38.444215889,4555.0
38.494349696,4508.0
38.544483503,4525.0
38.594617310,4599.0
38.644751117,4717.0
38.694884924,4836.0
38.745018731,5324.0
38.795152538,4899.0
38.845286345,4620.0
38.895420152,4530.0
38.945553959,4655.0
38.995687766,4646.0
39.045821573,4608.0
39.095955380,4609.0
39.146089186,4394.0
39.196222993,4520.0
39.246356800,4621.0
39.296490607,4697.0
39.346624414,4530.0
39.396758221,4533.0
39.446892028,4730.0
39.497025835,4593.0
39.547159642,4470.0
39.597293449,4556.0
39.647427256,4636.0
39.697561063,4528.0
39.747694870,4569.0
39.797828677,4573.0
39.847962484,4616.0
39.898096291,4591.0
39.948230097,4555.0
39.998363904,4422.0
40.048497711,4579.0
40.098631518,4523.0
40.148765325,4465.0
40.198899132,4448.0
40.249032939,4601.0
40.299166746,4625.0
40.349300553,4509.0
40.399434360,4658.0
40.449568167,4449.0
40.499701974,4605.0
40.549835781,4470.0
40.599969588,4474.0
40.650103395,4556.0
40.700237202,4509.0
40.750371008,4615.0
40.800504815,4498.0
40.850638622,4572.0
40.900772429,4441.0
40.950906236,4680.0
41.001040043,4578.0
41.051173850,4564.0
41.101307657,4568.0
41.151441464,4655.0
41.201575271,4702.0
41.251709078,4659.0
41.301842885,4723.0
41.351976692,4738.0
41.402110499,4706.0
41.452244306,4746.0
41.502378113,4970.0
41.552511919,5261.0
41.602645726,5674.0
41.652779533,5491.0
41.702913340,5536.0
41.753047147,5364.0
41.803180954,5537.0
41.853314761,5686.0
41.903448568,5651.0
41.953582375,5516.0
42.003716182,5536.0
42.053849989,5725.0
42.103983796,5642.0
42.154117603,5843.0
42.204251410,5823.0
42.254385217,5763.0
42.304519024,5841.0
42.354652830,5772.0
42.404786637,5902.0
42.454920444,5918.0
42.505054251,6159.0
42.555188058,6285.0
42.605321865,6432.0
42.655455672,6842.0
42.705589479,8002.0
42.755723286,9550.0
42.805857093,11782.0
42.855990900,14963.0
42.906124707,19905.0
42.956258514,34695.0
43.006392321,95187.0
43.056526128,264123.0
43.106659935,293319.0
43.156793741,197597.0
43.206927548,163875.0
43.257061355,79543.0
43.307195162,23338.0
43.357328969,13433.0
43.407462776,10050.0
43.457596583,8316.0
43.507730390,7310.0
43.557864197,6844.0
43.607998004,6598.0
43.658131811,6300.0
43.708265618,6131.0
43.758399425,6005.0
43.808533232,5895.0
43.858667039,5932.0
43.908800846,5690.0
43.958934652,5709.0
44.009068459,5491.0
44.059202266,5458.0
44.109336073,5562.0
44.159469880,5564.0
44.209603687,5455.0
44.259737494,5338.0
44.309871301,5190.0
44.360005108,5401.0
44.410138915,5405.0
44.460272722,5446.0
44.510406529,5265.0
44.560540336,5257.0
44.610674143,5223.0
44.660807950,5252.0
44.710941757,5273.0
44.761075564,5164.0
44.811209370,5306.0
44.861343177,5310.0
44.911476984,5355.0
44.961610791,5344.0
45.011744598,5486.0
45.061878405,5996.0
45.112012212,5430.0
45.162146019,5317.0
45.212279826,5203.0
45.262413633,5179.0
45.312547440,5135.0
45.362681247,5072.0
45.412815054,5080.0
45.462948861,5100.0
45.513082668,5014.0
45.563216475,5068.0
45.613350281,4993.0
45.663484088,5123.0
45.713617895,5006.0
45.763751702,4996.0
45.813885509,5085.0
45.864019316,5054.0
45.914153123,5024.0
45.964286930,4945.0
46.014420737,5068.0
46.064554544,5040.0
46.114688351,4932.0
46.164822158,4867.0
46.214955965,4966.0
46.265089772,4901.0
46.315223579,4983.0
46.365357386,5061.0
46.415491192,5303.0
46.465624999,5157.0
46.515758806,5187.0
46.565892613,5267.0
46.616026420,5047.0
46.666160227,5041.0
46.716294034,5167.0
46.766427841,5251.0
46.816561648,5567.0
46.866695455,5318.0
46.916829262,5258.0
46.966963069,5183.0
47.017096876,4915.0
47.067230683,4977.0
47.117364490,4870.0
47.167498297,4930.0
47.217632103,4858.0
47.267765910,4860.0
47.317899717,4832.0
47.368033524,4945.0
47.418167331,4800.0
47.468301138,4926.0
47.518434945,4668.0
47.568568752,4871.0
47.618702559,4855.0
47.668836366,4885.0
47.718970173,4860.0
47.769103980,4899.0
47.819237787,4851.0
47.869371594,4829.0
47.919505401,4908.0
47.969639208,4892.0
48.019773014,4764.0
48.069906821,4833.0
48.120040628,4850.0
48.170174435,4828.0
48.220308242,4887.0
48.270442049,4889.0
48.320575856,4968.0
48.370709663,5233.0
48.420843470,5366.0
48.470977277,5434.0
48.521111084,5346.0
48.571244891,5363.0
48.621378698,5397.0
48.671512505,5515.0
48.721646312,5447.0
48.771780119,5381.0
48.821913925,5580.0
48.872047732,5338.0
48.922181539,5342.0
48.972315346,5507.0
49.022449153,5582.0
49.072582960,5669.0
49.122716767,5614.0
49.172850574,5354.0
49.222984381,5503.0
49.273118188,5407.0
49.323251995,5565.0
49.373385802,5546.0
49.423519609,5580.0
49.473653416,5727.0
49.523787223,5706.0
49.573921030,5829.0
49.624054836,5846.0
49.674188643,6010.0
49.724322450,6206.0
49.774456257,6640.0
49.824590064,7614.0
49.874723871,9338.0
49.924857678,11795.0
49.974991485,14265.0
50.025125292,18079.0
50.075259099,31718.0
50.125392906,87356.0
50.175526713,219935.0
50.225660520,219679.0
50.275794327,132654.0
50.325928134,136968.0
50.376061941,90623.0
50.426195747,31949.0
50.476329554,14855.0
50.526463361,10500.0
50.576597168,8333.0
50.626730975,7090.0
50.676864782,6709.0
50.726998589,6367.0
50.777132396,6120.0
50.827266203,5974.0
50.877400010,5915.0
50.927533817,5772.0
50.977667624,5560.0
51.027801431,5528.0
51.077935238,5418.0
51.128069045,5299.0
51.178202852,5334.0
51.228336658,5305.0
51.278470465,5339.0
51.328604272,5115.0
51.378738079,5181.0
51.428871886,5244.0
51.479005693,5193.0
51.529139500,5145.0
51.579273307,5044.0
51.629407114,5025.0
51.679540921,5101.0
51.729674728,5081.0
51.779808535,5104.0
51.829942342,5137.0
51.880076149,4956.0
51.930209956,5090.0
51.980343763,5090.0
52.030477569,4856.0
52.080611376,4947.0
52.130745183,4990.0
52.180878990,5080.0
52.231012797,4942.0
52.281146604,4975.0
52.331280411,5058.0
52.381414218,4949.0
52.431548025,4815.0
52.481681832,4845.0
52.531815639,4842.0
52.581949446,4943.0
52.632083253,4866.0
52.682217060,4940.0
52.732350867,4780.0
52.782484674,4818.0
52.832618480,4837.0
52.882752287,4712.0
52.932886094,4899.0
52.983019901,4835.0
53.033153708,4708.0
53.083287515,4772.0
53.133421322,4761.0
53.183555129,4612.0
53.233688936,4729.0
53.283822743,4704.0
53.333956550,4709.0
53.384090357,4781.0
53.434224164,4704.0
53.484357971,4859.0
53.534491778,4779.0
53.584625585,4684.0
53.634759391,4698.0
53.684893198,4667.0
53.735027005,4747.0
53.785160812,4713.0
53.835294619,4640.0
53.885428426,4808.0
53.935562233,4730.0
53.985696040,4628.0
54.035829847,4769.0
54.085963654,4714.0
54.136097461,4689.0
54.186231268,4849.0
54.236365075,4738.0
54.286498882,4837.0
54.336632689,4687.0
54.386766496,4896.0
54.436900303,4644.0
54.487034109,5002.0
54.537167916,4804.0
54.587301723,4957.0
54.637435530,5184.0
54.687569337,4915.0
54.737703144,4932.0
54.787836951,4839.0
54.837970758,4726.0
54.888104565,4708.0
54.938238372,4623.0
54.988372179,4683.0
55.038505986,4634.0
55.088639793,4751.0
55.138773600,4611.0
55.188907407,4560.0
55.239041214,4489.0
55.289175020,4541.0
55.339308827,4623.0
55.389442634,4515.0
55.439576441,4552.0
55.489710248,4732.0
55.539844055,4534.0
55.589977862,4573.0
55.640111669,4597.0
55.690245476,4548.0
55.740379283,4587.0
55.790513090,4562.0
55.840646897,4533.0
55.890780704,4569.0
55.940914511,4592.0
55.991048318,4562.0
56.041182125,4639.0
56.091315931,4438.0
56.141449738,4626.0
56.191583545,4521.0
56.241717352,4686.0
56.291851159,4401.0
56.341984966,4571.0
56.392118773,4557.0
56.442252580,4634.0
56.492386387,4557.0
56.542520194,4516.0
56.592654001,4559.0
56.642787808,4520.0
56.692921615,4487.0
56.743055422,4456.0
56.793189229,4409.0
56.843323036,4467.0
56.893456842,4422.0
56.943590649,4470.0
56.993724456,4485.0
57.043858263,4507.0
57.093992070,4623.0
57.144125877,4369.0
57.194259684,4543.0
57.244393491,4405.0
57.294527298,4484.0
57.344661105,4505.0
57.394794912,4519.0
57.444928719,4437.0
57.495062526,4467.0
57.545196333,4470.0
57.595330140,4501.0
57.645463947,4493.0
57.695597753,4463.0
57.745731560,4382.0
57.795865367,4474.0
57.845999174,4548.0
57.896132981,4484.0
57.946266788,4426.0
57.996400595,4562.0
58.046534402,4470.0
58.096668209,4407.0
58.146802016,4382.0
58.196935823,4355.0
58.247069630,4580.0
58.297203437,4349.0
58.347337244,4429.0
58.397471051,4497.0
58.447604858,4412.0
58.497738664,4597.0
58.547872471,4476.0
58.598006278,4409.0
58.648140085,4593.0
58.698273892,4366.0
58.748407699,4377.0
58.798541506,4481.0
58.848675313,4497.0
58.898809120,4577.0
58.948942927,4512.0
58.999076734,4331.0
59.049210541,4469.0
59.099344348,4373.0
59.149478155,4518.0
59.199611962,4448.0
59.249745769,4406.0
59.299879575,4446.0
59.350013382,4500.0
59.400147189,4477.0
59.450280996,4348.0
59.500414803,4396.0
59.550548610,4443.0
59.600682417,4392.0
59.650816224,4371.0
59.700950031,4351.0
59.751083838,4584.0
59.801217645,4291.0
59.851351452,4455.0
59.901485259,4334.0
59.951619066,4321.0
60.001752873,4375.0
60.051886680,4381.0
60.102020486,4437.0
60.152154293,4476.0
60.202288100,4444.0
60.252421907,4520.0
60.302555714,4471.0
60.352689521,4428.0
60.402823328,4626.0
60.452957135,4571.0
60.503090942,4289.0
60.553224749,4341.0
60.603358556,4496.0
60.653492363,4418.0
60.703626170,4291.0
60.753759977,4497.0
60.803893784,4386.0
60.854027591,4424.0
60.904161397,4235.0
60.954295204,4522.0
61.004429011,4459.0
61.054562818,4438.0
61.104696625,4456.0
61.154830432,4343.0
61.204964239,4543.0
61.255098046,4477.0
61.305231853,4406.0
61.355365660,4347.0
61.405499467,4340.0
61.455633274,4370.0
61.505767081,4397.0
61.555900888,4395.0
61.606034695,4458.0
61.656168502,4452.0
61.706302308,4302.0
61.756436115,4353.0
61.806569922,4394.0
61.856703729,4375.0
61.906837536,4497.0
61.956971343,4357.0
62.007105150,4440.0
62.057238957,4402.0
62.107372764,4323.0
62.157506571,4355.0
62.207640378,4380.0
62.257774185,4370.0
62.307907992,4516.0
62.358041799,4364.0
62.408175606,4263.0
62.458309413,4310.0
62.508443219,4492.0
62.558577026,4366.0
62.608710833,4301.0
62.658844640,4286.0
62.708978447,4408.0
62.759112254,4433.0
62.809246061,4392.0
62.859379868,4486.0
62.909513675,4454.0
62.959647482,4442.0
63.009781289,4327.0
63.059915096,4488.0
63.110048903,4469.0
63.160182710,4549.0
63.210316517,4317.0
63.260450324,4367.0
63.310584130,4346.0
63.360717937,4389.0
63.410851744,4330.0
63.460985551,4434.0
63.511119358,4508.0
63.561253165,4508.0
63.611386972,4453.0
63.661520779,4376.0
63.711654586,4396.0
63.761788393,4449.0
63.811922200,4429.0
63.862056007,4318.0
63.912189814,4460.0
63.962323621,4480.0
64.012457428,4459.0
64.062591235,4366.0
64.112725041,4293.0
64.162858848,4404.0
64.212992655,4372.0
64.263126462,4429.0
64.313260269,4328.0
64.363394076,4356.0
64.413527883,4365.0
64.463661690,4396.0
64.513795497,4314.0
64.563929304,4447.0
64.614063111,4331.0
64.664196918,4436.0
64.714330725,4310.0
64.764464532,4416.0
64.814598339,4265.0
64.864732146,4334.0
64.914865953,4371.0
64.964999759,4495.0
65.015133566,4346.0
65.065267373,4462.0
65.115401180,4442.0
65.165534987,4289.0
65.215668794,4328.0
65.265802601,4390.0
65.315936408,4321.0
65.366070215,4296.0
65.416204022,4455.0
65.466337829,4426.0
65.516471636,4352.0
65.566605443,4263.0
65.616739250,4422.0
65.666873057,4450.0
65.717006864,4625.0
65.767140670,4508.0
65.817274477,4433.0
65.867408284,4490.0
65.917542091,4348.0
65.967675898,4323.0
66.017809705,4323.0
66.067943512,4362.0
66.118077319,4439.0
66.168211126,4511.0
66.218344933,4454.0
66.268478740,4377.0
66.318612547,4355.0
66.368746354,4437.0
66.418880161,4387.0
66.469013968,4428.0
66.519147775,4337.0
66.569281581,4333.0
66.619415388,4457.0
66.669549195,4498.0
66.719683002,4402.0
66.769816809,4364.0
66.819950616,4290.0
66.870084423,4291.0
66.920218230,4251.0
66.970352037,4368.0
67.020485844,4416.0
67.070619651,4310.0
67.120753458,4502.0
67.170887265,4410.0
67.221021072,4445.0
67.271154879,4326.0
67.321288686,4420.0
67.371422492,4459.0
67.421556299,4424.0
67.471690106,4395.0
67.521823913,4408.0
67.571957720,4430.0
67.622091527,4321.0
67.672225334,4432.0
67.722359141,4351.0
67.772492948,4586.0
67.822626755,4580.0
67.872760562,4701.0
67.922894369,4815.0
67.973028176,4369.0
68.023161983,4485.0
68.073295790,4495.0
68.123429597,4355.0
68.173563403,4430.0
68.223697210,4290.0
68.273831017,4410.0
68.323964824,4323.0
68.374098631,4411.0
68.424232438,4475.0
68.474366245,4386.0
68.524500052,4406.0
68.574633859,4337.0
68.624767666,4354.0
68.674901473,4400.0
68.725035280,4475.0
68.775169087,4305.0
68.825302894,4369.0
68.875436701,4420.0
68.925570508,4365.0
68.975704314,4518.0
69.025838121,4491.0
69.075971928,4324.0
69.126105735,4517.0
69.176239542,4409.0
69.226373349,4321.0
69.276507156,4326.0
69.326640963,4414.0
69.376774770,4377.0
69.426908577,4334.0
69.477042384,4462.0
69.527176191,4459.0
69.577309998,4365.0
69.627443805,4358.0
69.677577612,4416.0
69.727711419,4435.0
69.777845225,4308.0
69.827979032,4338.0
69.878112839,4460.0
69.928246646,4354.0
69.978380453,4350.0
70.028514260,4347.0
70.078648067,4397.0
70.128781874,4276.0
70.178915681,4493.0
70.229049488,4419.0
70.279183295,4409.0
70.329317102,4303.0
70.379450909,4348.0
70.429584716,4470.0
70.479718523,4567.0
70.529852330,4307.0
70.579986136,4465.0
70.630119943,4451.0
70.680253750,4366.0
70.730387557,4265.0
70.780521364,4416.0
70.830655171,4493.0
70.880788978,4450.0
70.930922785,4445.0
70.981056592,4668.0
71.031190399,4488.0
71.081324206,4561.0
71.131458013,4467.0
71.181591820,4450.0
71.231725627,4413.0
71.281859434,4544.0
71.331993241,4397.0
71.382127047,4603.0
71.432260854,4428.0
71.482394661,4565.0
71.532528468,4468.0
71.582662275,4366.0
71.632796082,4656.0
71.682929889,4507.0
71.733063696,4600.0
71.783197503,4445.0
71.833331310,4436.0
71.883465117,4431.0
71.933598924,4430.0
71.983732731,4530.0
72.033866538,4568.0
72.084000345,4469.0
72.134134152,4567.0
72.184267958,4535.0
72.234401765,4518.0
72.284535572,4548.0
72.334669379,4530.0
72.384803186,4320.0
72.434936993,4535.0
72.485070800,4450.0
72.535204607,4438.0
72.585338414,4598.0
72.635472221,4620.0
72.685606028,4534.0
72.735739835,4597.0
72.785873642,4659.0
72.836007449,4548.0
72.886141256,4518.0
72.936275063,4677.0
72.986408869,4564.0
73.036542676,4712.0
73.086676483,4675.0
73.136810290,4639.0
73.186944097,4703.0
73.237077904,4758.0
73.287211711,4918.0
73.337345518,4743.0
73.387479325,5237.0
73.437613132,5396.0
73.487746939,5531.0
73.537880746,5920.0
73.588014553,6286.0
73.638148360,7234.0
73.688282167,10605.0
73.738415974,24244.0
73.788549780,49536.0
73.838683587,40037.0
73.888817394,17562.0
73.938951201,14817.0
73.989085008,25236.0
74.039218815,25823.0
74.089352622,13357.0
74.139486429,7334.0
74.189620236,5897.0
74.239754043,5418.0
74.289887850,4945.0
74.340021657,5013.0
74.390155464,4744.0
74.440289271,4789.0
74.490423078,4650.0
74.540556885,4674.0
74.590690692,4597.0
74.640824498,4692.0
74.690958305,4603.0
74.741092112,4536.0
74.791225919,4578.0
74.841359726,4551.0
74.891493533,4618.0
74.941627340,4634.0
74.991761147,4430.0
75.041894954,4539.0
75.092028761,4566.0
75.142162568,4515.0
75.192296375,4520.0
75.242430182,4651.0
75.292563989,4474.0
75.342697796,4449.0
75.392831603,4472.0
75.442965409,4487.0
75.493099216,4468.0
75.543233023,4477.0
75.593366830,4478.0
75.643500637,4369.0
75.693634444,4545.0
75.743768251,4509.0
75.793902058,4435.0
75.844035865,4410.0
75.894169672,4516.0
75.944303479,4512.0
75.994437286,4509.0
76.044571093,4391.0
76.094704900,4449.0
76.144838707,4356.0
76.194972514,4403.0
76.245106320,4398.0
76.295240127,4470.0
76.345373934,4541.0
76.395507741,4401.0
76.445641548,4465.0
76.495775355,4504.0
76.545909162,4450.0
76.596042969,4415.0
76.646176776,4464.0
76.696310583,4446.0
76.746444390,4412.0
76.796578197,4501.0
76.846712004,4319.0
76.896845811,4447.0
76.946979618,4475.0
76.997113425,4445.0
77.047247231,4426.0
77.097381038,4415.0
77.147514845,4608.0
77.197648652,4417.0
77.247782459,4522.0
77.297916266,4446.0
77.348050073,4422.0
77.398183880,4435.0
77.448317687,4419.0
77.498451494,4359.0
77.548585301,4257.0
77.598719108,4538.0
77.648852915,4474.0
77.698986722,4402.0
77.749120529,4491.0
77.799254336,4359.0
77.849388142,4398.0
77.899521949,4348.0
77.949655756,4575.0
77.999789563,4324.0
78.049923370,4351.0
78.100057177,4259.0
78.150190984,4376.0
78.200324791,4368.0
78.250458598,4440.0
78.300592405,4452.0
78.350726212,4368.0
78.400860019,4438.0
78.450993826,4437.0
78.501127633,4322.0
78.551261440,4517.0
78.601395247,4325.0
78.651529053,4380.0
78.701662860,4434.0
78.751796667,4534.0
78.801930474,4361.0
78.852064281,4372.0
78.902198088,4371.0
78.952331895,4430.0
79.002465702,4426.0
79.052599509,4453.0
79.102733316,4472.0
79.152867123,4422.0
79.203000930,4542.0
79.253134737,4443.0
79.303268544,4454.0
79.353402351,4279.0
79.403536158,4440.0
79.453669964,4522.0
79.503803771,4440.0
79.553937578,4430.0
79.604071385,4344.0
79.654205192,4276.0
79.704338999,4446.0
79.754472806,4359.0
79.804606613,4434.0
79.854740420,4505.0
79.904874227,4446.0
79.955008034,4429.0
80.005141841,4444.0
80.055275648,4439.0
80.105409455,4390.0
80.155543262,4354.0
80.205677069,4440.0
80.255810875,4346.0
80.305944682,4406.0
80.356078489,4395.0
80.406212296,4410.0
80.456346103,4375.0
80.506479910,4454.0
80.556613717,4493.0
80.606747524,4358.0
80.656881331,4351.0
80.707015138,4437.0
80.757148945,4574.0
80.807282752,4508.0
80.857416559,4456.0
80.907550366,4489.0
80.957684173,4376.0
81.007817980,4389.0
81.057951786,4402.0
81.108085593,4491.0
81.158219400,4391.0
81.208353207,4391.0
81.258487014,4435.0
81.308620821,4360.0
81.358754628,4441.0
81.408888435,4400.0
81.459022242,4439.0
81.509156049,4413.0
81.559289856,4416.0
81.609423663,4383.0
81.659557470,4503.0
81.709691277,4385.0
81.759825084,4558.0
81.809958891,4500.0
81.860092697,4571.0
81.910226504,4562.0
81.960360311,4456.0
82.010494118,4467.0
82.060627925,4450.0
82.110761732,4593.0
82.160895539,4471.0
82.211029346,4326.0
82.261163153,4424.0
82.311296960,4489.0
82.361430767,4492.0
82.411564574,4338.0
82.461698381,4321.0
82.511832188,4482.0
82.561965995,4405.0
82.612099802,4369.0
82.662233608,4289.0
82.712367415,4500.0
82.762501222,4534.0
82.812635029,4280.0
82.862768836,4385.0
82.912902643,4321.0
82.963036450,4308.0
83.013170257,4408.0
83.063304064,4328.0
83.113437871,4375.0
83.163571678,4399.0
83.213705485,4328.0
83.263839292,4419.0
83.313973099,4402.0
83.364106906,4590.0
83.414240713,4446.0
83.464374519,4394.0
83.514508326,4411.0
83.564642133,4499.0
83.614775940,4492.0
83.664909747,4454.0
83.715043554,4402.0
83.765177361,4411.0
83.815311168,4362.0
83.865444975,4364.0
83.915578782,4453.0
83.965712589,4424.0
84.015846396,4450.0
84.065980203,4330.0
84.116114010,4394.0
84.166247817,4430.0
84.216381624,4289.0
84.266515431,4500.0
84.316649237,4515.0
84.366783044,4365.0
84.416916851,4350.0
84.467050658,4481.0
84.517184465,4430.0
84.567318272,4411.0
84.617452079,4446.0
84.667585886,4347.0
84.717719693,4548.0
84.767853500,4392.0
84.817987307,4304.0
84.868121114,4489.0
84.918254921,4289.0
84.968388728,4387.0
85.018522535,4447.0
85.068656342,4485.0
85.118790148,4258.0
85.168923955,4442.0
85.219057762,4363.0
85.269191569,4398.0
85.319325376,4351.0
85.369459183,4335.0
85.419592990,4443.0
85.469726797,4256.0
85.519860604,4350.0
85.569994411,4415.0
85.620128218,4360.0
85.670262025,4441.0
85.720395832,4439.0
85.770529639,4341.0
85.820663446,4404.0
85.870797253,4502.0
85.920931059,4509.0
85.971064866,4473.0
86.021198673,4336.0
86.071332480,4406.0
86.121466287,4376.0
86.171600094,4449.0
86.221733901,4463.0
86.271867708,4529.0
86.322001515,4408.0
86.372135322,4437.0
86.422269129,4451.0
86.472402936,4409.0
86.522536743,4342.0
86.572670550,4431.0
86.622804357,4389.0
86.672938164,4379.0
86.723071970,4445.0
86.773205777,4490.0
86.823339584,4416.0
86.873473391,4421.0
86.923607198,4405.0
86.973741005,4390.0
87.023874812,4427.0
87.074008619,4389.0
87.124142426,4467.0
87.174276233,4388.0
87.224410040,4401.0
87.274543847,4440.0
87.324677654,4420.0
87.374811461,4491.0
87.424945268,4485.0
87.475079075,4528.0
87.525212881,4504.0
87.575346688,4428.0
87.625480495,4431.0
87.675614302,4578.0
87.725748109,4557.0
87.775881916,4473.0
87.826015723,4390.0
87.876149530,4474.0
87.926283337,4400.0
87.976417144,4475.0
88.026550951,4433.0
88.076684758,4532.0
88.126818565,4443.0
88.176952372,4453.0
88.227086179,4365.0
88.277219986,4359.0
88.327353792,4372.0
88.377487599,4439.0
88.427621406,4497.0
88.477755213,4491.0
88.527889020,4485.0
88.578022827,4393.0
88.628156634,4589.0
88.678290441,4487.0
88.728424248,4346.0
88.778558055,4457.0
88.828691862,4506.0
88.878825669,4450.0
88.928959476,4552.0
88.979093283,4527.0
89.029227090,4699.0
89.079360897,4693.0
89.129494703,4612.0
89.179628510,4794.0
89.229762317,4927.0
89.279896124,5012.0
89.330029931,5397.0
89.380163738,5764.0
89.430297545,7019.0
89.480431352,11784.0
89.530565159,18504.0
89.580698966,16677.0
89.630832773,10042.0
89.680966580,7097.0
89.731100387,7310.0
89.781234194,9676.0
89.831368001,11703.0
89.881501808,9624.0
89.931635614,6434.0
89.981769421,5390.0
90.031903228,5033.0
90.082037035,5005.0
90.132170842,4628.0
90.182304649,4580.0
90.232438456,4558.0
90.282572263,4588.0
90.332706070,4473.0
90.382839877,4508.0
90.432973684,4487.0
90.483107491,4514.0
90.533241298,4530.0
90.583375105,4481.0
90.633508912,4412.0
90.683642719,4539.0
90.733776525,4389.0
90.783910332,4421.0
90.834044139,4399.0
90.884177946,4442.0
90.934311753,4492.0
90.984445560,4472.0
91.034579367,4490.0
91.084713174,4385.0
91.134846981,4473.0
91.184980788,4351.0
91.235114595,4391.0
91.285248402,4532.0
91.335382209,4417.0
91.385516016,4393.0
91.435649823,4539.0
91.485783630,4484.0
91.535917436,4272.0
91.586051243,4387.0
91.636185050,4418.0
91.686318857,4412.0
91.736452664,4488.0
91.786586471,4400.0
91.836720278,4483.0
91.886854085,4450.0
91.936987892,4481.0
91.987121699,4301.0
92.037255506,4554.0
92.087389313,4361.0
92.137523120,4541.0
92.187656927,4448.0
92.237790734,4591.0
92.287924541,4425.0
92.338058347,4551.0
92.388192154,4356.0
92.438325961,4413.0
92.488459768,4409.0
92.538593575,4437.0
92.588727382,4444.0
92.638861189,4421.0
92.688994996,4393.0
92.739128803,4318.0
92.789262610,4414.0
92.839396417,4551.0
92.889530224,4408.0
92.939664031,4460.0
92.989797838,4456.0
93.039931645,4380.0
93.090065452,4450.0
93.140199258,4419.0
93.190333065,4554.0
93.240466872,4436.0
93.290600679,4492.0
93.340734486,4523.0
93.390868293,4457.0
93.441002100,4568.0
93.491135907,4420.0
93.541269714,4470.0
93.591403521,4493.0
93.641537328,4523.0
93.691671135,4419.0
93.741804942,4406.0
93.791938749,4450.0
93.842072556,4418.0
93.892206363,4375.0
93.942340170,4542.0
93.992473976,4487.0
94.042607783,4485.0
94.092741590,4614.0
94.142875397,4590.0
94.193009204,4664.0
94.243143011,4678.0
94.293276818,4677.0
94.343410625,4782.0
94.393544432,4818.0
94.443678239,4761.0
94.493812046,5100.0
94.543945853,5382.0
94.594079660,6255.0
94.644213467,8826.0
94.694347274,16622.0
94.744481081,21312.0
94.794614887,13282.0
94.844748694,7782.0
94.894882501,6414.0
94.945016308,6958.0
94.995150115,9985.0
95.045283922,13012.0
95.095417729,9921.0
95.145551536,6537.0
95.195685343,5427.0
95.245819150,4983.0
95.295952957,4721.0
95.346086764,4670.0
95.396220571,4600.0
95.446354378,4537.0
95.496488185,4574.0
95.546621992,4475.0
95.596755798,4499.0
95.646889605,4555.0
95.697023412,4569.0
95.747157219,4568.0
95.797291026,4509.0
95.847424833,4354.0
95.897558640,4431.0
95.947692447,4440.0
95.997826254,4462.0
96.047960061,4536.0
96.098093868,4243.0
96.148227675,4530.0
96.198361482,4523.0
96.248495289,4362.0
96.298629096,4354.0
96.348762903,4496.0
96.398896709,4432.0
96.449030516,4451.0
96.499164323,4395.0
96.549298130,4546.0
96.599431937,4489.0
96.649565744,4477.0
96.699699551,4511.0
96.749833358,4458.0
96.799967165,4372.0
96.850100972,4485.0
96.900234779,4383.0
96.950368586,4399.0
97.000502393,4385.0
97.050636200,4369.0
97.100770007,4378.0
97.150903814,4464.0
97.201037620,4446.0
97.251171427,4357.0
97.301305234,4413.0
97.351439041,4419.0
97.401572848,4278.0
97.451706655,4365.0
97.501840462,4339.0
97.551974269,4384.0
97.602108076,4382.0
97.652241883,4336.0
97.702375690,4328.0
97.752509497,4391.0
97.802643304,4316.0
97.852777111,4488.0
97.902910918,4426.0
97.953044725,4453.0
98.003178531,4422.0
98.053312338,4286.0
98.103446145,4275.0
98.153579952,4336.0
98.203713759,4393.0
98.253847566,4304.0
98.303981373,4355.0
98.354115180,4420.0
98.404248987,4465.0
98.454382794,4377.0
98.504516601,4408.0
98.554650408,4351.0
98.604784215,4338.0
98.654918022,4343.0
98.705051829,4369.0
98.755185636,4427.0
98.805319442,4327.0
98.855453249,4395.0
98.905587056,4301.0
98.955720863,4493.0
99.005854670,4322.0
99.055988477,4520.0
99.106122284,4471.0
99.156256091,4315.0
99.206389898,4373.0
99.256523705,4487.0
99.306657512,4430.0
99.356791319,4386.0
99.406925126,4361.0
99.457058933,4322.0
99.507192740,4249.0
99.557326547,4431.0
99.607460353,4364.0
99.657594160,4590.0
99.707727967,4417.0
99.757861774,4378.0
99.807995581,4498.0
99.858129388,4397.0
99.908263195,4422.0
99.958397002,4429.0
99.991819540,4409.0