File: OriginPro/XRD from Panalytical X'Pert PRO/Nova Cu foil/Cufoil_350°C.csv
[Measurement conditions]
Sample identification,
Comment - 1,"finito"
Comment - 2,"Configuration=MRI TC-Basic Stage, Owner=User-1, Creation date=26-10-2009 9:18:44"
Comment - 3,"Goniometer=PW3050/60 (Theta/Theta); Minimum step size 2Theta:0.001; Minimum step size Omega:0.001"
Comment - 4,"Sample stage=MRI TC-Basic (PtRh heat strip)"
Comment - 5,"Diffractometer system=XPERT-PRO"
Comment - 6,"Measurement program=FlatStage, Owner=joana, Creation date=03-08-2011 15:43:53"
Anode material,Cu
K-Alpha1 wavelength,1.5405980
K-Alpha2 wavelength,1.5444260
Ratio K-Alpha2/K-Alpha1,0.500
Divergence slit,Fixed,0.76mm
Monochromator used,NO
Generator voltage, 45
Tube current, 40
File date and time,06/Dec/2012 23:04
Unit cell,
h k l, 0 0 0
Temperature [K],623
Scan axis,Gonio
Scan range,24.999999996,100.000175174
Scan step size,0.0167113
No. of points, 4488
Scan type,CONTINUOUS
Time per step,53.340
[Scan points]
Angle,Intensity
25.008355630,3677.0
25.058489437,3652.0
25.108623244,3742.0
25.158757051,3688.0
25.208890858,3836.0
25.259024665,3781.0
25.309158472,3868.0
25.359292279,3853.0
25.409426086,3801.0
25.459559892,3859.0
25.509693699,3803.0
25.559827506,3750.0
25.609961313,3765.0
25.660095120,3759.0
25.710228927,3872.0
25.760362734,3894.0
25.810496541,3782.0
25.860630348,3753.0
25.910764155,3740.0
25.960897962,3746.0
26.011031769,3820.0
26.061165576,3849.0
26.111299383,3778.0
26.161433190,3890.0
26.211566997,3809.0
26.261700803,3718.0
26.311834610,3855.0
26.361968417,3748.0
26.412102224,3754.0
26.462236031,3745.0
26.512369838,3810.0
26.562503645,3921.0
26.612637452,3816.0
26.662771259,3888.0
26.712905066,3732.0
26.763038873,3905.0
26.813172680,3829.0
26.863306487,3848.0
26.913440294,3807.0
26.963574101,3796.0
27.013707908,3808.0
27.063841714,3906.0
27.113975521,3948.0
27.164109328,3828.0
27.214243135,3864.0
27.264376942,3888.0
27.314510749,3658.0
27.364644556,3830.0
27.414778363,3915.0
27.464912170,3797.0
27.515045977,3851.0
27.565179784,3857.0
27.615313591,3909.0
27.665447398,3966.0
27.715581205,3811.0
27.765715012,3899.0
27.815848819,3895.0
27.865982625,3740.0
27.916116432,3755.0
27.966250239,3858.0
28.016384046,3856.0
28.066517853,3900.0
28.116651660,3941.0
28.166785467,3846.0
28.216919274,3967.0
28.267053081,3920.0
28.317186888,4001.0
28.367320695,3959.0
28.417454502,3846.0
28.467588309,3904.0
28.517722116,3981.0
28.567855923,3833.0
28.617989730,3838.0
28.668123536,3885.0
28.718257343,3906.0
28.768391150,4007.0
28.818524957,3852.0
28.868658764,3818.0
28.918792571,3931.0
28.968926378,3817.0
29.019060185,3962.0
29.069193992,3911.0
29.119327799,3995.0
29.169461606,4036.0
29.219595413,3920.0
29.269729220,4006.0
29.319863027,3998.0
29.369996834,3990.0
29.420130641,3957.0
29.470264447,3943.0
29.520398254,4035.0
29.570532061,4078.0
29.620665868,4080.0
29.670799675,3872.0
29.720933482,4065.0
29.771067289,4084.0
29.821201096,3985.0
29.871334903,3971.0
29.921468710,3899.0
29.971602517,4032.0
30.021736324,3811.0
30.071870131,4038.0
30.122003938,4061.0
30.172137745,4138.0
30.222271552,4098.0
30.272405358,3939.0
30.322539165,3974.0
30.372672972,3999.0
30.422806779,3929.0
30.472940586,3848.0
30.523074393,4003.0
30.573208200,3925.0
30.623342007,4009.0
30.673475814,4029.0
30.723609621,4010.0
30.773743428,4014.0
30.823877235,3992.0
30.874011042,3925.0
30.924144849,4036.0
30.974278656,4073.0
31.024412463,4099.0
31.074546269,3981.0
31.124680076,4049.0
31.174813883,4079.0
31.224947690,4020.0
31.275081497,4042.0
31.325215304,4089.0
31.375349111,3921.0
31.425482918,4148.0
31.475616725,4096.0
31.525750532,3951.0
31.575884339,3981.0
31.626018146,4018.0
31.676151953,4097.0
31.726285760,4072.0
31.776419567,4104.0
31.826553374,4110.0
31.876687180,3972.0
31.926820987,3986.0
31.976954794,4078.0
32.027088601,4023.0
32.077222408,4195.0
32.127356215,4210.0
32.177490022,4017.0
32.227623829,4058.0
32.277757636,3990.0
32.327891443,4053.0
32.378025250,4002.0
32.428159057,3967.0
32.478292864,4024.0
32.528426671,4063.0
32.578560478,4103.0
32.628694285,4060.0
32.678828091,4048.0
32.728961898,4168.0
32.779095705,4147.0
32.829229512,4052.0
32.879363319,4145.0
32.929497126,4001.0
32.979630933,4025.0
33.029764740,4175.0
33.079898547,4068.0
33.130032354,4169.0
33.180166161,4151.0
33.230299968,4089.0
33.280433775,4166.0
33.330567582,4088.0
33.380701389,4147.0
33.430835196,4160.0
33.480969002,4091.0
33.531102809,4093.0
33.581236616,4182.0
33.631370423,4001.0
33.681504230,4204.0
33.731638037,4280.0
33.781771844,4192.0
33.831905651,3987.0
33.882039458,4077.0
33.932173265,4107.0
33.982307072,4102.0
34.032440879,4298.0
34.082574686,4079.0
34.132708493,4150.0
34.182842300,4157.0
34.232976107,4151.0
34.283109913,4171.0
34.333243720,4259.0
34.383377527,4087.0
34.433511334,4087.0
34.483645141,4199.0
34.533778948,4200.0
34.583912755,4103.0
34.634046562,4183.0
34.684180369,4084.0
34.734314176,3997.0
34.784447983,4187.0
34.834581790,4137.0
34.884715597,4226.0
34.934849404,4119.0
34.984983211,4126.0
35.035117018,4259.0
35.085250825,4320.0
35.135384631,4330.0
35.185518438,4328.0
35.235652245,4189.0
35.285786052,4173.0
35.335919859,4315.0
35.386053666,4263.0
35.436187473,4273.0
35.486321280,4374.0
35.536455087,4251.0
35.586588894,4383.0
35.636722701,4249.0
35.686856508,4277.0
35.736990315,4359.0
35.787124122,4274.0
35.837257929,4269.0
35.887391736,4382.0
35.937525542,4484.0
35.987659349,4343.0
36.037793156,4389.0
36.087926963,4419.0
36.138060770,4348.0
36.188194577,4481.0
36.238328384,4639.0
36.288462191,4730.0
36.338595998,4559.0
36.388729805,4549.0
36.438863612,4343.0
36.488997419,4444.0
36.539131226,4351.0
36.589265033,4424.0
36.639398840,4347.0
36.689532647,4449.0
36.739666453,4428.0
36.789800260,4456.0
36.839934067,4274.0
36.890067874,4359.0
36.940201681,4285.0
36.990335488,4263.0
37.040469295,4459.0
37.090603102,4244.0
37.140736909,4225.0
37.190870716,4335.0
37.241004523,4234.0
37.291138330,4386.0
37.341272137,4265.0
37.391405944,4300.0
37.441539751,4361.0
37.491673558,4389.0
37.541807364,4278.0
37.591941171,4389.0
37.642074978,4316.0
37.692208785,4202.0
37.742342592,4388.0
37.792476399,4358.0
37.842610206,4249.0
37.892744013,4303.0
37.942877820,4353.0
37.993011627,4472.0
38.043145434,4337.0
38.093279241,4371.0
38.143413048,4390.0
38.193546855,4491.0
38.243680662,4345.0
38.293814469,4503.0
38.343948275,4409.0
38.394082082,4427.0
38.444215889,4384.0
38.494349696,4444.0
38.544483503,4657.0
38.594617310,4605.0
38.644751117,4861.0
38.694884924,4988.0
38.745018731,4807.0
38.795152538,4560.0
38.845286345,4545.0
38.895420152,4546.0
38.945553959,4562.0
38.995687766,4501.0
39.045821573,4489.0
39.095955380,4396.0
39.146089186,4487.0
39.196222993,4567.0
39.246356800,4463.0
39.296490607,4395.0
39.346624414,4420.0
39.396758221,4439.0
39.446892028,4334.0
39.497025835,4404.0
39.547159642,4409.0
39.597293449,4347.0
39.647427256,4518.0
39.697561063,4500.0
39.747694870,4678.0
39.797828677,4544.0
39.847962484,4557.0
39.898096291,4531.0
39.948230097,4476.0
39.998363904,4558.0
40.048497711,4474.0
40.098631518,4399.0
40.148765325,4430.0
40.198899132,4542.0
40.249032939,4613.0
40.299166746,4428.0
40.349300553,4464.0
40.399434360,4415.0
40.449568167,4626.0
40.499701974,4510.0
40.549835781,4600.0
40.599969588,4643.0
40.650103395,4490.0
40.700237202,4418.0
40.750371008,4540.0
40.800504815,4540.0
40.850638622,4589.0
40.900772429,4425.0
40.950906236,4502.0
41.001040043,4577.0
41.051173850,4470.0
41.101307657,4489.0
41.151441464,4575.0
41.201575271,4512.0
41.251709078,4660.0
41.301842885,4660.0
41.351976692,4669.0
41.402110499,4829.0
41.452244306,4900.0
41.502378113,5258.0
41.552511919,5244.0
41.602645726,5247.0
41.652779533,5517.0
41.702913340,5279.0
41.753047147,5457.0
41.803180954,5454.0
41.853314761,5406.0
41.903448568,5523.0
41.953582375,5751.0
42.003716182,5563.0
42.053849989,5420.0
42.103983796,5567.0
42.154117603,5606.0
42.204251410,5594.0
42.254385217,5742.0
42.304519024,5636.0
42.354652830,5741.0
42.404786637,5623.0
42.454920444,5998.0
42.505054251,5880.0
42.555188058,6300.0
42.605321865,6992.0
42.655455672,7715.0
42.705589479,9428.0
42.755723286,11712.0
42.805857093,15322.0
42.855990900,27248.0
42.906124707,87486.0
42.956258514,161218.0
43.006392321,169031.0
43.056526128,223483.0
43.106659935,104205.0
43.156793741,100383.0
43.206927548,41240.0
43.257061355,20251.0
43.307195162,14968.0
43.357328969,11272.0
43.407462776,9505.0
43.457596583,8527.0
43.507730390,7798.0
43.557864197,7075.0
43.607998004,6971.0
43.658131811,6562.0
43.708265618,6152.0
43.758399425,6258.0
43.808533232,6159.0
43.858667039,6100.0
43.908800846,5873.0
43.958934652,5702.0
44.009068459,5665.0
44.059202266,5527.0
44.109336073,5454.0
44.159469880,5408.0
44.209603687,5325.0
44.259737494,5259.0
44.309871301,5317.0
44.360005108,5395.0
44.410138915,5198.0
44.460272722,5367.0
44.510406529,5269.0
44.560540336,5187.0
44.610674143,5069.0
44.660807950,5239.0
44.710941757,5186.0
44.761075564,5049.0
44.811209370,5136.0
44.861343177,5243.0
44.911476984,5384.0
44.961610791,5390.0
45.011744598,5556.0
45.061878405,5105.0
45.112012212,5112.0
45.162146019,4929.0
45.212279826,5027.0
45.262413633,4989.0
45.312547440,5042.0
45.362681247,5011.0
45.412815054,4977.0
45.462948861,5013.0
45.513082668,5102.0
45.563216475,5013.0
45.613350281,5009.0
45.663484088,4951.0
45.713617895,5042.0
45.763751702,5060.0
45.813885509,4904.0
45.864019316,5178.0
45.914153123,5030.0
45.964286930,5017.0
46.014420737,4857.0
46.064554544,5015.0
46.114688351,4967.0
46.164822158,5154.0
46.214955965,5153.0
46.265089772,5284.0
46.315223579,5802.0
46.365357386,5581.0
46.415491192,5505.0
46.465624999,5246.0
46.515758806,5264.0
46.565892613,4940.0
46.616026420,5047.0
46.666160227,5193.0
46.716294034,5199.0
46.766427841,5229.0
46.816561648,5071.0
46.866695455,5099.0
46.916829262,5030.0
46.966963069,4930.0
47.017096876,4955.0
47.067230683,4862.0
47.117364490,4883.0
47.167498297,4969.0
47.217632103,4915.0
47.267765910,4876.0
47.317899717,4927.0
47.368033524,4831.0
47.418167331,4779.0
47.468301138,5015.0
47.518434945,4943.0
47.568568752,4861.0
47.618702559,4763.0
47.668836366,4939.0
47.718970173,4856.0
47.769103980,4767.0
47.819237787,4768.0
47.869371594,4800.0
47.919505401,4829.0
47.969639208,4889.0
48.019773014,4899.0
48.069906821,4857.0
48.120040628,4936.0
48.170174435,4921.0
48.220308242,4959.0
48.270442049,5196.0
48.320575856,5234.0
48.370709663,5450.0
48.420843470,5277.0
48.470977277,5222.0
48.521111084,5347.0
48.571244891,5341.0
48.621378698,5442.0
48.671512505,5335.0
48.721646312,5356.0
48.771780119,5316.0
48.821913925,5347.0
48.872047732,5619.0
48.922181539,5474.0
48.972315346,5523.0
49.022449153,5539.0
49.072582960,5374.0
49.122716767,5428.0
49.172850574,5509.0
49.222984381,5629.0
49.273118188,5596.0
49.323251995,5444.0
49.373385802,5651.0
49.423519609,5486.0
49.473653416,5613.0
49.523787223,5805.0
49.573921030,5969.0
49.624054836,6091.0
49.674188643,6335.0
49.724322450,7328.0
49.774456257,8614.0
49.824590064,10197.0
49.874723871,12551.0
49.924857678,18206.0
49.974991485,44089.0
50.025125292,109545.0
50.075259099,143078.0
50.125392906,171906.0
50.175526713,111327.0
50.225660520,87472.0
50.275794327,70353.0
50.325928134,24207.0
50.376061941,13384.0
50.426195747,9990.0
50.476329554,8115.0
50.526463361,7228.0
50.576597168,6676.0
50.626730975,6187.0
50.676864782,6144.0
50.726998589,5806.0
50.777132396,5833.0
50.827266203,5687.0
50.877400010,5604.0
50.927533817,5544.0
50.977667624,5469.0
51.027801431,5507.0
51.077935238,5452.0
51.128069045,5357.0
51.178202852,5286.0
51.228336658,5241.0
51.278470465,5147.0
51.328604272,5058.0
51.378738079,5168.0
51.428871886,5069.0
51.479005693,5185.0
51.529139500,4940.0
51.579273307,5038.0
51.629407114,5012.0
51.679540921,5039.0
51.729674728,4931.0
51.779808535,5020.0
51.829942342,4962.0
51.880076149,5012.0
51.930209956,4799.0
51.980343763,5015.0
52.030477569,4819.0
52.080611376,4824.0
52.130745183,4915.0
52.180878990,4847.0
52.231012797,4922.0
52.281146604,4846.0
52.331280411,4953.0
52.381414218,4802.0
52.431548025,4880.0
52.481681832,4872.0
52.531815639,5043.0
52.581949446,4747.0
52.632083253,4789.0
52.682217060,4789.0
52.732350867,4869.0
52.782484674,4727.0
52.832618480,4827.0
52.882752287,4896.0
52.932886094,4785.0
52.983019901,4703.0
53.033153708,4769.0
53.083287515,4716.0
53.133421322,4767.0
53.183555129,4795.0
53.233688936,4854.0
53.283822743,4647.0
53.333956550,4676.0
53.384090357,4686.0
53.434224164,4770.0
53.484357971,4787.0
53.534491778,4704.0
53.584625585,4716.0
53.634759391,4659.0
53.684893198,4721.0
53.735027005,4666.0
53.785160812,4757.0
53.835294619,4686.0
53.885428426,4726.0
53.935562233,4640.0
53.985696040,4729.0
54.035829847,4864.0
54.085963654,4690.0
54.136097461,4845.0
54.186231268,4541.0
54.236365075,4913.0
54.286498882,4686.0
54.336632689,4604.0
54.386766496,4727.0
54.436900303,4911.0
54.487034109,4959.0
54.537167916,4847.0
54.587301723,4698.0
54.637435530,4694.0
54.687569337,4772.0
54.737703144,4563.0
54.787836951,4758.0
54.837970758,4728.0
54.888104565,4626.0
54.938238372,4622.0
54.988372179,4708.0
55.038505986,4618.0
55.088639793,4730.0
55.138773600,4618.0
55.188907407,4642.0
55.239041214,4599.0
55.289175020,4647.0
55.339308827,4685.0
55.389442634,4562.0
55.439576441,4667.0
55.489710248,4641.0
55.539844055,4543.0
55.589977862,4512.0
55.640111669,4415.0
55.690245476,4560.0
55.740379283,4622.0
55.790513090,4596.0
55.840646897,4648.0
55.890780704,4547.0
55.940914511,4574.0
55.991048318,4588.0
56.041182125,4634.0
56.091315931,4474.0
56.141449738,4567.0
56.191583545,4489.0
56.241717352,4541.0
56.291851159,4648.0
56.341984966,4527.0
56.392118773,4634.0
56.442252580,4536.0
56.492386387,4503.0
56.542520194,4642.0
56.592654001,4530.0
56.642787808,4740.0
56.692921615,4518.0
56.743055422,4620.0
56.793189229,4558.0
56.843323036,4568.0
56.893456842,4566.0
56.943590649,4546.0
56.993724456,4630.0
57.043858263,4562.0
57.093992070,4522.0
57.144125877,4557.0
57.194259684,4502.0
57.244393491,4516.0
57.294527298,4538.0
57.344661105,4596.0
57.394794912,4633.0
57.444928719,4538.0
57.495062526,4619.0
57.545196333,4606.0
57.595330140,4591.0
57.645463947,4471.0
57.695597753,4639.0
57.745731560,4519.0
57.795865367,4591.0
57.845999174,4606.0
57.896132981,4452.0
57.946266788,4490.0
57.996400595,4553.0
58.046534402,4468.0
58.096668209,4409.0
58.146802016,4614.0
58.196935823,4459.0
58.247069630,4439.0
58.297203437,4402.0
58.347337244,4440.0
58.397471051,4611.0
58.447604858,4555.0
58.497738664,4471.0
58.547872471,4435.0
58.598006278,4463.0
58.648140085,4579.0
58.698273892,4479.0
58.748407699,4517.0
58.798541506,4440.0
58.848675313,4585.0
58.898809120,4478.0
58.948942927,4611.0
58.999076734,4392.0
59.049210541,4557.0
59.099344348,4522.0
59.149478155,4527.0
59.199611962,4563.0
59.249745769,4610.0
59.299879575,4426.0
59.350013382,4479.0
59.400147189,4499.0
59.450280996,4482.0
59.500414803,4369.0
59.550548610,4423.0
59.600682417,4534.0
59.650816224,4476.0
59.700950031,4575.0
59.751083838,4496.0
59.801217645,4451.0
59.851351452,4542.0
59.901485259,4555.0
59.951619066,4483.0
60.001752873,4452.0
60.051886680,4476.0
60.102020486,4538.0
60.152154293,4516.0
60.202288100,4404.0
60.252421907,4473.0
60.302555714,4595.0
60.352689521,4479.0
60.402823328,4467.0
60.452957135,4517.0
60.503090942,4428.0
60.553224749,4580.0
60.603358556,4541.0
60.653492363,4451.0
60.703626170,4453.0
60.753759977,4421.0
60.803893784,4642.0
60.854027591,4575.0
60.904161397,4419.0
60.954295204,4602.0
61.004429011,4445.0
61.054562818,4629.0
61.104696625,4509.0
61.154830432,4524.0
61.204964239,4453.0
61.255098046,4333.0
61.305231853,4579.0
61.355365660,4545.0
61.405499467,4505.0
61.455633274,4420.0
61.505767081,4578.0
61.555900888,4523.0
61.606034695,4530.0
61.656168502,4533.0
61.706302308,4407.0
61.756436115,4462.0
61.806569922,4528.0
61.856703729,4453.0
61.906837536,4381.0
61.956971343,4456.0
62.007105150,4462.0
62.057238957,4636.0
62.107372764,4421.0
62.157506571,4571.0
62.207640378,4494.0
62.257774185,4419.0
62.307907992,4440.0
62.358041799,4436.0
62.408175606,4552.0
62.458309413,4410.0
62.508443219,4478.0
62.558577026,4458.0
62.608710833,4397.0
62.658844640,4281.0
62.708978447,4449.0
62.759112254,4531.0
62.809246061,4334.0
62.859379868,4444.0
62.909513675,4497.0
62.959647482,4523.0
63.009781289,4471.0
63.059915096,4548.0
63.110048903,4472.0
63.160182710,4351.0
63.210316517,4437.0
63.260450324,4436.0
63.310584130,4498.0
63.360717937,4529.0
63.410851744,4402.0
63.460985551,4567.0
63.511119358,4460.0
63.561253165,4384.0
63.611386972,4396.0
63.661520779,4535.0
63.711654586,4540.0
63.761788393,4511.0
63.811922200,4499.0
63.862056007,4339.0
63.912189814,4539.0
63.962323621,4510.0
64.012457428,4445.0
64.062591235,4440.0
64.112725041,4346.0
64.162858848,4378.0
64.212992655,4391.0
64.263126462,4468.0
64.313260269,4523.0
64.363394076,4540.0
64.413527883,4515.0
64.463661690,4533.0
64.513795497,4428.0
64.563929304,4426.0
64.614063111,4510.0
64.664196918,4481.0
64.714330725,4467.0
64.764464532,4386.0
64.814598339,4495.0
64.864732146,4352.0
64.914865953,4476.0
64.964999759,4380.0
65.015133566,4556.0
65.065267373,4374.0
65.115401180,4411.0
65.165534987,4421.0
65.215668794,4464.0
65.265802601,4254.0
65.315936408,4428.0
65.366070215,4386.0
65.416204022,4458.0
65.466337829,4517.0
65.516471636,4475.0
65.566605443,4454.0
65.616739250,4426.0
65.666873057,4438.0
65.717006864,4484.0
65.767140670,4569.0
65.817274477,4513.0
65.867408284,4528.0
65.917542091,4400.0
65.967675898,4496.0
66.017809705,4487.0
66.067943512,4507.0
66.118077319,4535.0
66.168211126,4494.0
66.218344933,4414.0
66.268478740,4424.0
66.318612547,4377.0
66.368746354,4473.0
66.418880161,4477.0
66.469013968,4567.0
66.519147775,4402.0
66.569281581,4266.0
66.619415388,4544.0
66.669549195,4379.0
66.719683002,4553.0
66.769816809,4473.0
66.819950616,4414.0
66.870084423,4454.0
66.920218230,4404.0
66.970352037,4336.0
67.020485844,4457.0
67.070619651,4611.0
67.120753458,4417.0
67.170887265,4393.0
67.221021072,4488.0
67.271154879,4543.0
67.321288686,4513.0
67.371422492,4540.0
67.421556299,4553.0
67.471690106,4481.0
67.521823913,4327.0
67.571957720,4444.0
67.622091527,4470.0
67.672225334,4537.0
67.722359141,4594.0
67.772492948,4618.0
67.822626755,4841.0
67.872760562,4609.0
67.922894369,4420.0
67.973028176,4641.0
68.023161983,4536.0
68.073295790,4568.0
68.123429597,4640.0
68.173563403,4548.0
68.223697210,4572.0
68.273831017,4416.0
68.323964824,4395.0
68.374098631,4348.0
68.424232438,4401.0
68.474366245,4575.0
68.524500052,4572.0
68.574633859,4433.0
68.624767666,4499.0
68.674901473,4477.0
68.725035280,4432.0
68.775169087,4441.0
68.825302894,4508.0
68.875436701,4575.0
68.925570508,4526.0
68.975704314,4550.0
69.025838121,4420.0
69.075971928,4625.0
69.126105735,4419.0
69.176239542,4410.0
69.226373349,4458.0
69.276507156,4511.0
69.326640963,4526.0
69.376774770,4572.0
69.426908577,4601.0
69.477042384,4518.0
69.527176191,4548.0
69.577309998,4517.0
69.627443805,4415.0
69.677577612,4390.0
69.727711419,4428.0
69.777845225,4487.0
69.827979032,4590.0
69.878112839,4481.0
69.928246646,4584.0
69.978380453,4611.0
70.028514260,4479.0
70.078648067,4401.0
70.128781874,4453.0
70.178915681,4532.0
70.229049488,4561.0
70.279183295,4627.0
70.329317102,4289.0
70.379450909,4521.0
70.429584716,4495.0
70.479718523,4542.0
70.529852330,4570.0
70.579986136,4573.0
70.630119943,4572.0
70.680253750,4533.0
70.730387557,4518.0
70.780521364,4567.0
70.830655171,4565.0
70.880788978,4546.0
70.930922785,4551.0
70.981056592,4462.0
71.031190399,4632.0
71.081324206,4620.0
71.131458013,4659.0
71.181591820,4652.0
71.231725627,4470.0
71.281859434,4648.0
71.331993241,4470.0
71.382127047,4445.0
71.432260854,4664.0
71.482394661,4577.0
71.532528468,4731.0
71.582662275,4541.0
71.632796082,4609.0
71.682929889,4553.0
71.733063696,4577.0
71.783197503,4475.0
71.833331310,4586.0
71.883465117,4570.0
71.933598924,4727.0
71.983732731,4657.0
72.033866538,4616.0
72.084000345,4576.0
72.134134152,4730.0
72.184267958,4667.0
72.234401765,4658.0
72.284535572,4668.0
72.334669379,4621.0
72.384803186,4652.0
72.434936993,4587.0
72.485070800,4641.0
72.535204607,4689.0
72.585338414,4658.0
72.635472221,4725.0
72.685606028,4709.0
72.735739835,4697.0
72.785873642,4757.0
72.836007449,4792.0
72.886141256,4635.0
72.936275063,4857.0
72.986408869,4851.0
73.036542676,4824.0
73.086676483,4986.0
73.136810290,5048.0
73.186944097,5273.0
73.237077904,5274.0
73.287211711,5352.0
73.337345518,6036.0
73.387479325,6821.0
73.437613132,10733.0
73.487746939,21148.0
73.537880746,30249.0
73.588014553,24458.0
73.638148360,18803.0
73.688282167,18419.0
73.738415974,20619.0
73.788549780,17908.0
73.838683587,12909.0
73.888817394,10055.0
73.938951201,8055.0
73.989085008,6856.0
74.039218815,6332.0
74.089352622,5935.0
74.139486429,5485.0
74.189620236,5495.0
74.239754043,5258.0
74.289887850,5142.0
74.340021657,5059.0
74.390155464,4978.0
74.440289271,5059.0
74.490423078,4875.0
74.540556885,4833.0
74.590690692,4811.0
74.640824498,4717.0
74.690958305,4820.0
74.741092112,4670.0
74.791225919,4498.0
74.841359726,4713.0
74.891493533,4678.0
74.941627340,4679.0
74.991761147,4822.0
75.041894954,4669.0
75.092028761,4638.0
75.142162568,4558.0
75.192296375,4609.0
75.242430182,4725.0
75.292563989,4724.0
75.342697796,4614.0
75.392831603,4702.0
75.442965409,4706.0
75.493099216,4582.0
75.543233023,4649.0
75.593366830,4540.0
75.643500637,4734.0
75.693634444,4705.0
75.743768251,4718.0
75.793902058,4655.0
75.844035865,4562.0
75.894169672,4635.0
75.944303479,4603.0
75.994437286,4535.0
76.044571093,4502.0
76.094704900,4732.0
76.144838707,4481.0
76.194972514,4628.0
76.245106320,4505.0
76.295240127,4671.0
76.345373934,4585.0
76.395507741,4551.0
76.445641548,4540.0
76.495775355,4493.0
76.545909162,4715.0
76.596042969,4552.0
76.646176776,4601.0
76.696310583,4582.0
76.746444390,4746.0
76.796578197,4655.0
76.846712004,4564.0
76.896845811,4584.0
76.946979618,4600.0
76.997113425,4557.0
77.047247231,4722.0
77.097381038,4544.0
77.147514845,4519.0
77.197648652,4581.0
77.247782459,4711.0
77.297916266,4575.0
77.348050073,4656.0
77.398183880,4689.0
77.448317687,4403.0
77.498451494,4663.0
77.548585301,4552.0
77.598719108,4647.0
77.648852915,4625.0
77.698986722,4549.0
77.749120529,4633.0
77.799254336,4719.0
77.849388142,4492.0
77.899521949,4667.0
77.949655756,4529.0
77.999789563,4556.0
78.049923370,4596.0
78.100057177,4591.0
78.150190984,4447.0
78.200324791,4638.0
78.250458598,4462.0
78.300592405,4626.0
78.350726212,4509.0
78.400860019,4503.0
78.450993826,4478.0
78.501127633,4523.0
78.551261440,4532.0
78.601395247,4496.0
78.651529053,4564.0
78.701662860,4673.0
78.751796667,4576.0
78.801930474,4570.0
78.852064281,4498.0
78.902198088,4477.0
78.952331895,4667.0
79.002465702,4508.0
79.052599509,4506.0
79.102733316,4472.0
79.152867123,4468.0
79.203000930,4423.0
79.253134737,4479.0
79.303268544,4459.0
79.353402351,4456.0
79.403536158,4469.0
79.453669964,4458.0
79.503803771,4497.0
79.553937578,4491.0
79.604071385,4494.0
79.654205192,4578.0
79.704338999,4617.0
79.754472806,4631.0
79.804606613,4587.0
79.854740420,4409.0
79.904874227,4537.0
79.955008034,4581.0
80.005141841,4520.0
80.055275648,4617.0
80.105409455,4573.0
80.155543262,4621.0
80.205677069,4670.0
80.255810875,4546.0
80.305944682,4537.0
80.356078489,4663.0
80.406212296,4486.0
80.456346103,4514.0
80.506479910,4542.0
80.556613717,4522.0
80.606747524,4580.0
80.656881331,4532.0
80.707015138,4448.0
80.757148945,4663.0
80.807282752,4614.0
80.857416559,4541.0
80.907550366,4644.0
80.957684173,4576.0
81.007817980,4502.0
81.057951786,4523.0
81.108085593,4462.0
81.158219400,4653.0
81.208353207,4483.0
81.258487014,4625.0
81.308620821,4437.0
81.358754628,4418.0
81.408888435,4405.0
81.459022242,4575.0
81.509156049,4715.0
81.559289856,4461.0
81.609423663,4669.0
81.659557470,4708.0
81.709691277,4721.0
81.759825084,4758.0
81.809958891,4587.0
81.860092697,4587.0
81.910226504,4482.0
81.960360311,4627.0
82.010494118,4676.0
82.060627925,4593.0
82.110761732,4553.0
82.160895539,4595.0
82.211029346,4617.0
82.261163153,4529.0
82.311296960,4674.0
82.361430767,4590.0
82.411564574,4523.0
82.461698381,4559.0
82.511832188,4584.0
82.561965995,4361.0
82.612099802,4623.0
82.662233608,4615.0
82.712367415,4496.0
82.762501222,4587.0
82.812635029,4594.0
82.862768836,4529.0
82.912902643,4599.0
82.963036450,4528.0
83.013170257,4529.0
83.063304064,4513.0
83.113437871,4567.0
83.163571678,4559.0
83.213705485,4574.0
83.263839292,4624.0
83.313973099,4620.0
83.364106906,4510.0
83.414240713,4488.0
83.464374519,4529.0
83.514508326,4560.0
83.564642133,4492.0
83.614775940,4564.0
83.664909747,4552.0
83.715043554,4443.0
83.765177361,4605.0
83.815311168,4574.0
83.865444975,4518.0
83.915578782,4463.0
83.965712589,4696.0
84.015846396,4728.0
84.065980203,4576.0
84.116114010,4562.0
84.166247817,4465.0
84.216381624,4424.0
84.266515431,4524.0
84.316649237,4568.0
84.366783044,4431.0
84.416916851,4580.0
84.467050658,4502.0
84.517184465,4546.0
84.567318272,4567.0
84.617452079,4657.0
84.667585886,4705.0
84.717719693,4526.0
84.767853500,4628.0
84.817987307,4556.0
84.868121114,4498.0
84.918254921,4575.0
84.968388728,4655.0
85.018522535,4671.0
85.068656342,4629.0
85.118790148,4662.0
85.168923955,4633.0
85.219057762,4660.0
85.269191569,4645.0
85.319325376,4505.0
85.369459183,4416.0
85.419592990,4498.0
85.469726797,4501.0
85.519860604,4657.0
85.569994411,4614.0
85.620128218,4518.0
85.670262025,4548.0
85.720395832,4607.0
85.770529639,4530.0
85.820663446,4635.0
85.870797253,4560.0
85.920931059,4621.0
85.971064866,4664.0
86.021198673,4489.0
86.071332480,4450.0
86.121466287,4563.0
86.171600094,4542.0
86.221733901,4477.0
86.271867708,4572.0
86.322001515,4605.0
86.372135322,4590.0
86.422269129,4602.0
86.472402936,4669.0
86.522536743,4462.0
86.572670550,4502.0
86.622804357,4573.0
86.672938164,4686.0
86.723071970,4608.0
86.773205777,4631.0
86.823339584,4712.0
86.873473391,4477.0
86.923607198,4612.0
86.973741005,4574.0
87.023874812,4499.0
87.074008619,4605.0
87.124142426,4623.0
87.174276233,4677.0
87.224410040,4608.0
87.274543847,4570.0
87.324677654,4572.0
87.374811461,4565.0
87.424945268,4657.0
87.475079075,4512.0
87.525212881,4588.0
87.575346688,4603.0
87.625480495,4620.0
87.675614302,4632.0
87.725748109,4542.0
87.775881916,4587.0
87.826015723,4629.0
87.876149530,4700.0
87.926283337,4787.0
87.976417144,4466.0
88.026550951,4660.0
88.076684758,4568.0
88.126818565,4590.0
88.176952372,4606.0
88.227086179,4648.0
88.277219986,4581.0
88.327353792,4598.0
88.377487599,4716.0
88.427621406,4576.0
88.477755213,4637.0
88.527889020,4516.0
88.578022827,4577.0
88.628156634,4724.0
88.678290441,4713.0
88.728424248,4780.0
88.778558055,4832.0
88.828691862,4651.0
88.878825669,4826.0
88.928959476,4921.0
88.979093283,5024.0
89.029227090,5231.0
89.079360897,5697.0
89.129494703,7321.0
89.179628510,9902.0
89.229762317,10904.0
89.279896124,10453.0
89.330029931,10150.0
89.380163738,9613.0
89.430297545,10093.0
89.480431352,10819.0
89.530565159,10282.0
89.580698966,9197.0
89.630832773,8459.0
89.680966580,7538.0
89.731100387,6901.0
89.781234194,6397.0
89.831368001,6085.0
89.881501808,5688.0
89.931635614,5342.0
89.981769421,5140.0
90.031903228,4829.0
90.082037035,4832.0
90.132170842,4629.0
90.182304649,4636.0
90.232438456,4642.0
90.282572263,4505.0
90.332706070,4554.0
90.382839877,4583.0
90.432973684,4559.0
90.483107491,4542.0
90.533241298,4479.0
90.583375105,4576.0
90.633508912,4412.0
90.683642719,4502.0
90.733776525,4573.0
90.783910332,4502.0
90.834044139,4440.0
90.884177946,4515.0
90.934311753,4371.0
90.984445560,4624.0
91.034579367,4482.0
91.084713174,4495.0
91.134846981,4536.0
91.184980788,4608.0
91.235114595,4522.0
91.285248402,4584.0
91.335382209,4448.0
91.385516016,4491.0
91.435649823,4343.0
91.485783630,4453.0
91.535917436,4430.0
91.586051243,4544.0
91.636185050,4537.0
91.686318857,4549.0
91.736452664,4571.0
91.786586471,4567.0
91.836720278,4523.0
91.886854085,4431.0
91.936987892,4497.0
91.987121699,4513.0
92.037255506,4509.0
92.087389313,4482.0
92.137523120,4442.0
92.187656927,4517.0
92.237790734,4523.0
92.287924541,4482.0
92.338058347,4507.0
92.388192154,4559.0
92.438325961,4544.0
92.488459768,4621.0
92.538593575,4503.0
92.588727382,4497.0
92.638861189,4675.0
92.688994996,4445.0
92.739128803,4499.0
92.789262610,4530.0
92.839396417,4536.0
92.889530224,4473.0
92.939664031,4586.0
92.989797838,4572.0
93.039931645,4559.0
93.090065452,4488.0
93.140199258,4519.0
93.190333065,4369.0
93.240466872,4640.0
93.290600679,4577.0
93.340734486,4520.0
93.390868293,4570.0
93.441002100,4537.0
93.491135907,4461.0
93.541269714,4397.0
93.591403521,4630.0
93.641537328,4505.0
93.691671135,4547.0
93.741804942,4532.0
93.791938749,4573.0
93.842072556,4688.0
93.892206363,4749.0
93.942340170,4609.0
93.992473976,4656.0
94.042607783,4669.0
94.092741590,4801.0
94.142875397,4813.0
94.193009204,5035.0
94.243143011,5799.0
94.293276818,8514.0
94.343410625,13052.0
94.393544432,12479.0
94.443678239,9104.0
94.493812046,7254.0
94.543945853,6472.0
94.594079660,7087.0
94.644213467,9098.0
94.694347274,9050.0
94.744481081,7345.0
94.794614887,6302.0
94.844748694,5427.0
94.894882501,5100.0
94.945016308,5051.0
94.995150115,4854.0
95.045283922,4684.0
95.095417729,4743.0
95.145551536,4620.0
95.195685343,4538.0
95.245819150,4655.0
95.295952957,4582.0
95.346086764,4495.0
95.396220571,4543.0
95.446354378,4525.0
95.496488185,4432.0
95.546621992,4535.0
95.596755798,4542.0
95.646889605,4446.0
95.697023412,4471.0
95.747157219,4658.0
95.797291026,4476.0
95.847424833,4489.0
95.897558640,4531.0
95.947692447,4453.0
95.997826254,4540.0
96.047960061,4499.0
96.098093868,4587.0
96.148227675,4348.0
96.198361482,4399.0
96.248495289,4527.0
96.298629096,4539.0
96.348762903,4464.0
96.398896709,4445.0
96.449030516,4545.0
96.499164323,4558.0
96.549298130,4509.0
96.599431937,4441.0
96.649565744,4536.0
96.699699551,4363.0
96.749833358,4421.0
96.799967165,4551.0
96.850100972,4462.0
96.900234779,4439.0
96.950368586,4413.0
97.000502393,4512.0
97.050636200,4565.0
97.100770007,4492.0
97.150903814,4464.0
97.201037620,4488.0
97.251171427,4313.0
97.301305234,4490.0
97.351439041,4422.0
97.401572848,4482.0
97.451706655,4461.0
97.501840462,4480.0
97.551974269,4623.0
97.602108076,4389.0
97.652241883,4419.0
97.702375690,4468.0
97.752509497,4378.0
97.802643304,4411.0
97.852777111,4439.0
97.902910918,4369.0
97.953044725,4376.0
98.003178531,4392.0
98.053312338,4573.0
98.103446145,4604.0
98.153579952,4429.0
98.203713759,4446.0
98.253847566,4439.0
98.303981373,4419.0
98.354115180,4409.0
98.404248987,4456.0
98.454382794,4555.0
98.504516601,4377.0
98.554650408,4504.0
98.604784215,4485.0
98.654918022,4483.0
98.705051829,4477.0
98.755185636,4536.0
98.805319442,4412.0
98.855453249,4516.0
98.905587056,4556.0
98.955720863,4434.0
99.005854670,4483.0
99.055988477,4451.0
99.106122284,4534.0
99.156256091,4380.0
99.206389898,4359.0
99.256523705,4394.0
99.306657512,4555.0
99.356791319,4592.0
99.406925126,4376.0
99.457058933,4481.0
99.507192740,4441.0
99.557326547,4417.0
99.607460353,4458.0
99.657594160,4475.0
99.707727967,4300.0
99.757861774,4512.0
99.807995581,4364.0
99.858129388,4443.0
99.908263195,4510.0
99.958397002,4341.0
99.991819540,4434.0