File: OriginPro/XRD from Panalytical X'Pert PRO/Nova Cu foil/Cufoil_300°C.csv
[Measurement conditions]
Sample identification,
Comment - 1,"finito"
Comment - 2,"Configuration=MRI TC-Basic Stage, Owner=User-1, Creation date=26-10-2009 9:18:44"
Comment - 3,"Goniometer=PW3050/60 (Theta/Theta); Minimum step size 2Theta:0.001; Minimum step size Omega:0.001"
Comment - 4,"Sample stage=MRI TC-Basic (PtRh heat strip)"
Comment - 5,"Diffractometer system=XPERT-PRO"
Comment - 6,"Measurement program=FlatStage, Owner=joana, Creation date=03-08-2011 15:43:53"
Anode material,Cu
K-Alpha1 wavelength,1.5405980
K-Alpha2 wavelength,1.5444260
Ratio K-Alpha2/K-Alpha1,0.500
Divergence slit,Fixed,0.76mm
Monochromator used,NO
Generator voltage, 45
Tube current, 40
File date and time,06/Dec/2012 22:29
Unit cell,
h k l, 0 0 0
Temperature [K],573
Scan axis,Gonio
Scan range,24.999999996,100.000175174
Scan step size,0.0167113
No. of points, 4488
Scan type,CONTINUOUS
Time per step,53.340
[Scan points]
Angle,Intensity
25.008355630,4691.0
25.058489437,4831.0
25.108623244,4735.0
25.158757051,4718.0
25.208890858,4879.0
25.259024665,4652.0
25.309158472,4658.0
25.359292279,4776.0
25.409426086,4750.0
25.459559892,4752.0
25.509693699,4739.0
25.559827506,4854.0
25.609961313,4707.0
25.660095120,4771.0
25.710228927,4806.0
25.760362734,4687.0
25.810496541,4746.0
25.860630348,4614.0
25.910764155,4698.0
25.960897962,4677.0
26.011031769,4834.0
26.061165576,4623.0
26.111299383,4650.0
26.161433190,4789.0
26.211566997,4827.0
26.261700803,4675.0
26.311834610,4838.0
26.361968417,4769.0
26.412102224,4742.0
26.462236031,4521.0
26.512369838,4749.0
26.562503645,4675.0
26.612637452,4559.0
26.662771259,4637.0
26.712905066,4778.0
26.763038873,4853.0
26.813172680,4675.0
26.863306487,4725.0
26.913440294,4686.0
26.963574101,4655.0
27.013707908,4619.0
27.063841714,4713.0
27.113975521,4702.0
27.164109328,4651.0
27.214243135,4700.0
27.264376942,4679.0
27.314510749,4568.0
27.364644556,4654.0
27.414778363,4562.0
27.464912170,4640.0
27.515045977,4640.0
27.565179784,4733.0
27.615313591,4691.0
27.665447398,4730.0
27.715581205,4679.0
27.765715012,4719.0
27.815848819,4683.0
27.865982625,4673.0
27.916116432,4744.0
27.966250239,4595.0
28.016384046,4699.0
28.066517853,4594.0
28.116651660,4623.0
28.166785467,4737.0
28.216919274,4778.0
28.267053081,4712.0
28.317186888,4638.0
28.367320695,4742.0
28.417454502,4660.0
28.467588309,4620.0
28.517722116,4732.0
28.567855923,4669.0
28.617989730,4611.0
28.668123536,4640.0
28.718257343,4693.0
28.768391150,4682.0
28.818524957,4610.0
28.868658764,4721.0
28.918792571,4613.0
28.968926378,4723.0
29.019060185,4721.0
29.069193992,4549.0
29.119327799,4723.0
29.169461606,4585.0
29.219595413,4665.0
29.269729220,4627.0
29.319863027,4523.0
29.369996834,4530.0
29.420130641,4584.0
29.470264447,4683.0
29.520398254,4640.0
29.570532061,4682.0
29.620665868,4701.0
29.670799675,4642.0
29.720933482,4712.0
29.771067289,4699.0
29.821201096,4591.0
29.871334903,4597.0
29.921468710,4625.0
29.971602517,4717.0
30.021736324,4656.0
30.071870131,4710.0
30.122003938,4648.0
30.172137745,4568.0
30.222271552,4733.0
30.272405358,4676.0
30.322539165,4779.0
30.372672972,4657.0
30.422806779,4537.0
30.472940586,4586.0
30.523074393,4671.0
30.573208200,4670.0
30.623342007,4668.0
30.673475814,4578.0
30.723609621,4671.0
30.773743428,4768.0
30.823877235,4607.0
30.874011042,4608.0
30.924144849,4724.0
30.974278656,4732.0
31.024412463,4557.0
31.074546269,4753.0
31.124680076,4686.0
31.174813883,4804.0
31.224947690,4455.0
31.275081497,4684.0
31.325215304,4593.0
31.375349111,4641.0
31.425482918,4750.0
31.475616725,4616.0
31.525750532,4521.0
31.575884339,4596.0
31.626018146,4615.0
31.676151953,4550.0
31.726285760,4652.0
31.776419567,4610.0
31.826553374,4621.0
31.876687180,4660.0
31.926820987,4515.0
31.976954794,4698.0
32.027088601,4649.0
32.077222408,4592.0
32.127356215,4580.0
32.177490022,4522.0
32.227623829,4638.0
32.277757636,4693.0
32.327891443,4598.0
32.378025250,4616.0
32.428159057,4662.0
32.478292864,4612.0
32.528426671,4679.0
32.578560478,4626.0
32.628694285,4645.0
32.678828091,4669.0
32.728961898,4661.0
32.779095705,4624.0
32.829229512,4611.0
32.879363319,4719.0
32.929497126,4730.0
32.979630933,4616.0
33.029764740,4708.0
33.079898547,4595.0
33.130032354,4739.0
33.180166161,4721.0
33.230299968,4719.0
33.280433775,4692.0
33.330567582,4738.0
33.380701389,4648.0
33.430835196,4642.0
33.480969002,4644.0
33.531102809,4594.0
33.581236616,4497.0
33.631370423,4662.0
33.681504230,4634.0
33.731638037,4552.0
33.781771844,4734.0
33.831905651,4711.0
33.882039458,4650.0
33.932173265,4663.0
33.982307072,4692.0
34.032440879,4598.0
34.082574686,4622.0
34.132708493,4690.0
34.182842300,4667.0
34.232976107,4508.0
34.283109913,4670.0
34.333243720,4545.0
34.383377527,4733.0
34.433511334,4692.0
34.483645141,4720.0
34.533778948,4638.0
34.583912755,4747.0
34.634046562,4662.0
34.684180369,4721.0
34.734314176,4586.0
34.784447983,4654.0
34.834581790,4736.0
34.884715597,4633.0
34.934849404,4653.0
34.984983211,4695.0
35.035117018,4597.0
35.085250825,4703.0
35.135384631,4762.0
35.185518438,4705.0
35.235652245,4569.0
35.285786052,4597.0
35.335919859,4655.0
35.386053666,4597.0
35.436187473,4627.0
35.486321280,4678.0
35.536455087,4716.0
35.586588894,4740.0
35.636722701,4744.0
35.686856508,4562.0
35.736990315,4750.0
35.787124122,4696.0
35.837257929,4822.0
35.887391736,4675.0
35.937525542,4592.0
35.987659349,4849.0
36.037793156,4651.0
36.087926963,4644.0
36.138060770,4722.0
36.188194577,4654.0
36.238328384,4754.0
36.288462191,4531.0
36.338595998,4620.0
36.388729805,4679.0
36.438863612,4611.0
36.488997419,4699.0
36.539131226,4658.0
36.589265033,4669.0
36.639398840,4606.0
36.689532647,4722.0
36.739666453,4622.0
36.789800260,4679.0
36.839934067,4700.0
36.890067874,4732.0
36.940201681,4562.0
36.990335488,4650.0
37.040469295,4605.0
37.090603102,4597.0
37.140736909,4647.0
37.190870716,4793.0
37.241004523,4641.0
37.291138330,4697.0
37.341272137,4559.0
37.391405944,4734.0
37.441539751,4656.0
37.491673558,4864.0
37.541807364,4787.0
37.591941171,4616.0
37.642074978,4677.0
37.692208785,4710.0
37.742342592,4758.0
37.792476399,4745.0
37.842610206,4748.0
37.892744013,4622.0
37.942877820,4716.0
37.993011627,4767.0
38.043145434,4677.0
38.093279241,4929.0
38.143413048,4846.0
38.193546855,4816.0
38.243680662,4762.0
38.293814469,4790.0
38.343948275,4741.0
38.394082082,4785.0
38.444215889,4839.0
38.494349696,4963.0
38.544483503,4788.0
38.594617310,4833.0
38.644751117,4928.0
38.694884924,5168.0
38.745018731,5225.0
38.795152538,5701.0
38.845286345,5153.0
38.895420152,4889.0
38.945553959,4962.0
38.995687766,4901.0
39.045821573,4819.0
39.095955380,4634.0
39.146089186,4770.0
39.196222993,4807.0
39.246356800,4881.0
39.296490607,4720.0
39.346624414,4877.0
39.396758221,4701.0
39.446892028,4781.0
39.497025835,4649.0
39.547159642,4748.0
39.597293449,4960.0
39.647427256,4715.0
39.697561063,4902.0
39.747694870,4876.0
39.797828677,4838.0
39.847962484,4732.0
39.898096291,4827.0
39.948230097,4860.0
39.998363904,4863.0
40.048497711,4784.0
40.098631518,4771.0
40.148765325,4764.0
40.198899132,4830.0
40.249032939,4828.0
40.299166746,4892.0
40.349300553,4798.0
40.399434360,4882.0
40.449568167,4929.0
40.499701974,4810.0
40.549835781,4889.0
40.599969588,4910.0
40.650103395,4990.0
40.700237202,4857.0
40.750371008,4825.0
40.800504815,4869.0
40.850638622,4866.0
40.900772429,4877.0
40.950906236,4878.0
41.001040043,4784.0
41.051173850,4758.0
41.101307657,4857.0
41.151441464,4894.0
41.201575271,4927.0
41.251709078,4831.0
41.301842885,5040.0
41.351976692,5052.0
41.402110499,4901.0
41.452244306,4990.0
41.502378113,5128.0
41.552511919,5324.0
41.602645726,5732.0
41.652779533,5707.0
41.702913340,5812.0
41.753047147,5899.0
41.803180954,5744.0
41.853314761,5831.0
41.903448568,5903.0
41.953582375,5929.0
42.003716182,5953.0
42.053849989,5969.0
42.103983796,6049.0
42.154117603,6095.0
42.204251410,6242.0
42.254385217,6125.0
42.304519024,6125.0
42.354652830,6053.0
42.404786637,6205.0
42.454920444,6354.0
42.505054251,6203.0
42.555188058,6640.0
42.605321865,6667.0
42.655455672,6938.0
42.705589479,7336.0
42.755723286,8300.0
42.805857093,9980.0
42.855990900,12764.0
42.906124707,17248.0
42.956258514,25598.0
43.006392321,50897.0
43.056526128,140329.0
43.106659935,330968.0
43.156793741,270527.0
43.206927548,169630.0
43.257061355,158711.0
43.307195162,40074.0
43.357328969,16091.0
43.407462776,11761.0
43.457596583,9216.0
43.507730390,7696.0
43.557864197,7220.0
43.607998004,6821.0
43.658131811,6703.0
43.708265618,6484.0
43.758399425,6544.0
43.808533232,6166.0
43.858667039,6098.0
43.908800846,6099.0
43.958934652,5844.0
44.009068459,5998.0
44.059202266,5959.0
44.109336073,5828.0
44.159469880,5811.0
44.209603687,5889.0
44.259737494,5760.0
44.309871301,5736.0
44.360005108,5625.0
44.410138915,5596.0
44.460272722,5679.0
44.510406529,5742.0
44.560540336,5686.0
44.610674143,5621.0
44.660807950,5446.0
44.710941757,5538.0
44.761075564,5585.0
44.811209370,5669.0
44.861343177,5463.0
44.911476984,5540.0
44.961610791,5539.0
45.011744598,5649.0
45.061878405,6031.0
45.112012212,5967.0
45.162146019,5545.0
45.212279826,5349.0
45.262413633,5419.0
45.312547440,5425.0
45.362681247,5541.0
45.412815054,5444.0
45.462948861,5460.0
45.513082668,5276.0
45.563216475,5203.0
45.613350281,5367.0
45.663484088,5455.0
45.713617895,5346.0
45.763751702,5352.0
45.813885509,5184.0
45.864019316,5248.0
45.914153123,5387.0
45.964286930,5240.0
46.014420737,5319.0
46.064554544,5363.0
46.114688351,5223.0
46.164822158,5207.0
46.214955965,5167.0
46.265089772,5245.0
46.315223579,5473.0
46.365357386,5386.0
46.415491192,5518.0
46.465624999,5446.0
46.515758806,5581.0
46.565892613,5377.0
46.616026420,5241.0
46.666160227,5243.0
46.716294034,5250.0
46.766427841,5594.0
46.816561648,5635.0
46.866695455,5732.0
46.916829262,5406.0
46.966963069,5610.0
47.017096876,5280.0
47.067230683,5194.0
47.117364490,5212.0
47.167498297,5293.0
47.217632103,5232.0
47.267765910,5159.0
47.317899717,5206.0
47.368033524,5105.0
47.418167331,5226.0
47.468301138,5094.0
47.518434945,5149.0
47.568568752,5160.0
47.618702559,5153.0
47.668836366,5034.0
47.718970173,5133.0
47.769103980,5180.0
47.819237787,5174.0
47.869371594,5192.0
47.919505401,5148.0
47.969639208,5148.0
48.019773014,5130.0
48.069906821,4999.0
48.120040628,5221.0
48.170174435,5112.0
48.220308242,5156.0
48.270442049,5304.0
48.320575856,5279.0
48.370709663,5380.0
48.420843470,5901.0
48.470977277,5824.0
48.521111084,5812.0
48.571244891,5717.0
48.621378698,5949.0
48.671512505,5946.0
48.721646312,5825.0
48.771780119,5888.0
48.821913925,5816.0
48.872047732,5968.0
48.922181539,5838.0
48.972315346,6030.0
49.022449153,6061.0
49.072582960,6159.0
49.122716767,6061.0
49.172850574,6026.0
49.222984381,6167.0
49.273118188,5873.0
49.323251995,5907.0
49.373385802,5920.0
49.423519609,6042.0
49.473653416,6112.0
49.523787223,6139.0
49.573921030,6237.0
49.624054836,6412.0
49.674188643,6520.0
49.724322450,6549.0
49.774456257,7011.0
49.824590064,7616.0
49.874723871,8641.0
49.924857678,11337.0
49.974991485,14523.0
50.025125292,18128.0
50.075259099,28711.0
50.125392906,68236.0
50.175526713,193607.0
50.225660520,310095.0
50.275794327,153911.0
50.325928134,145673.0
50.376061941,137579.0
50.426195747,41248.0
50.476329554,16776.0
50.526463361,11760.0
50.576597168,9485.0
50.626730975,7895.0
50.676864782,7210.0
50.726998589,6650.0
50.777132396,6445.0
50.827266203,6416.0
50.877400010,6199.0
50.927533817,6009.0
50.977667624,5994.0
51.027801431,5955.0
51.077935238,5854.0
51.128069045,5853.0
51.178202852,5765.0
51.228336658,5827.0
51.278470465,5507.0
51.328604272,5533.0
51.378738079,5548.0
51.428871886,5575.0
51.479005693,5619.0
51.529139500,5410.0
51.579273307,5437.0
51.629407114,5386.0
51.679540921,5450.0
51.729674728,5288.0
51.779808535,5296.0
51.829942342,5261.0
51.880076149,5273.0
51.930209956,5319.0
51.980343763,5186.0
52.030477569,5188.0
52.080611376,5313.0
52.130745183,5325.0
52.180878990,5135.0
52.231012797,5229.0
52.281146604,5189.0
52.331280411,5164.0
52.381414218,5227.0
52.431548025,5183.0
52.481681832,5301.0
52.531815639,5149.0
52.581949446,5122.0
52.632083253,5228.0
52.682217060,5075.0
52.732350867,5134.0
52.782484674,5108.0
52.832618480,5048.0
52.882752287,5161.0
52.932886094,5148.0
52.983019901,5047.0
53.033153708,4878.0
53.083287515,5033.0
53.133421322,4932.0
53.183555129,4972.0
53.233688936,5131.0
53.283822743,4950.0
53.333956550,5133.0
53.384090357,4922.0
53.434224164,4911.0
53.484357971,5138.0
53.534491778,5038.0
53.584625585,5037.0
53.634759391,4923.0
53.684893198,5005.0
53.735027005,5004.0
53.785160812,4961.0
53.835294619,4828.0
53.885428426,4881.0
53.935562233,4799.0
53.985696040,4969.0
54.035829847,4987.0
54.085963654,5106.0
54.136097461,4801.0
54.186231268,4961.0
54.236365075,5070.0
54.286498882,4975.0
54.336632689,4986.0
54.386766496,5140.0
54.436900303,5086.0
54.487034109,5046.0
54.537167916,5184.0
54.587301723,5290.0
54.637435530,5272.0
54.687569337,5062.0
54.737703144,5183.0
54.787836951,5035.0
54.837970758,4904.0
54.888104565,5065.0
54.938238372,4819.0
54.988372179,4858.0
55.038505986,4789.0
55.088639793,4818.0
55.138773600,4914.0
55.188907407,4980.0
55.239041214,4868.0
55.289175020,4879.0
55.339308827,4737.0
55.389442634,4828.0
55.439576441,4905.0
55.489710248,4774.0
55.539844055,4753.0
55.589977862,4821.0
55.640111669,4759.0
55.690245476,4747.0
55.740379283,4684.0
55.790513090,4800.0
55.840646897,4747.0
55.890780704,4638.0
55.940914511,4693.0
55.991048318,4837.0
56.041182125,4768.0
56.091315931,4761.0
56.141449738,4764.0
56.191583545,4872.0
56.241717352,4707.0
56.291851159,4810.0
56.341984966,4716.0
56.392118773,4718.0
56.442252580,4683.0
56.492386387,4665.0
56.542520194,4788.0
56.592654001,4848.0
56.642787808,4697.0
56.692921615,4683.0
56.743055422,4762.0
56.793189229,4777.0
56.843323036,4679.0
56.893456842,4764.0
56.943590649,4645.0
56.993724456,4774.0
57.043858263,4690.0
57.093992070,4686.0
57.144125877,4678.0
57.194259684,4651.0
57.244393491,4705.0
57.294527298,4585.0
57.344661105,4695.0
57.394794912,4743.0
57.444928719,4768.0
57.495062526,4749.0
57.545196333,4729.0
57.595330140,4553.0
57.645463947,4663.0
57.695597753,4664.0
57.745731560,4848.0
57.795865367,4621.0
57.845999174,4643.0
57.896132981,4695.0
57.946266788,4685.0
57.996400595,4581.0
58.046534402,4728.0
58.096668209,4519.0
58.146802016,4689.0
58.196935823,4762.0
58.247069630,4539.0
58.297203437,4663.0
58.347337244,4640.0
58.397471051,4737.0
58.447604858,4540.0
58.497738664,4667.0
58.547872471,4589.0
58.598006278,4667.0
58.648140085,4558.0
58.698273892,4541.0
58.748407699,4650.0
58.798541506,4712.0
58.848675313,4755.0
58.898809120,4740.0
58.948942927,4630.0
58.999076734,4676.0
59.049210541,4657.0
59.099344348,4560.0
59.149478155,4544.0
59.199611962,4537.0
59.249745769,4690.0
59.299879575,4740.0
59.350013382,4700.0
59.400147189,4597.0
59.450280996,4583.0
59.500414803,4544.0
59.550548610,4601.0
59.600682417,4642.0
59.650816224,4611.0
59.700950031,4598.0
59.751083838,4607.0
59.801217645,4661.0
59.851351452,4604.0
59.901485259,4681.0
59.951619066,4545.0
60.001752873,4496.0
60.051886680,4483.0
60.102020486,4763.0
60.152154293,4679.0
60.202288100,4713.0
60.252421907,4624.0
60.302555714,4685.0
60.352689521,4610.0
60.402823328,4576.0
60.452957135,4548.0
60.503090942,4689.0
60.553224749,4694.0
60.603358556,4589.0
60.653492363,4565.0
60.703626170,4628.0
60.753759977,4647.0
60.803893784,4505.0
60.854027591,4586.0
60.904161397,4709.0
60.954295204,4542.0
61.004429011,4536.0
61.054562818,4502.0
61.104696625,4563.0
61.154830432,4619.0
61.204964239,4574.0
61.255098046,4530.0
61.305231853,4681.0
61.355365660,4576.0
61.405499467,4746.0
61.455633274,4497.0
61.505767081,4575.0
61.555900888,4551.0
61.606034695,4670.0
61.656168502,4513.0
61.706302308,4543.0
61.756436115,4579.0
61.806569922,4599.0
61.856703729,4622.0
61.906837536,4668.0
61.956971343,4652.0
62.007105150,4524.0
62.057238957,4459.0
62.107372764,4648.0
62.157506571,4598.0
62.207640378,4584.0
62.257774185,4584.0
62.307907992,4623.0
62.358041799,4519.0
62.408175606,4646.0
62.458309413,4629.0
62.508443219,4579.0
62.558577026,4392.0
62.608710833,4721.0
62.658844640,4507.0
62.708978447,4371.0
62.759112254,4604.0
62.809246061,4556.0
62.859379868,4538.0
62.909513675,4433.0
62.959647482,4505.0
63.009781289,4629.0
63.059915096,4510.0
63.110048903,4622.0
63.160182710,4715.0
63.210316517,4509.0
63.260450324,4494.0
63.310584130,4557.0
63.360717937,4581.0
63.410851744,4514.0
63.460985551,4559.0
63.511119358,4541.0
63.561253165,4570.0
63.611386972,4516.0
63.661520779,4631.0
63.711654586,4562.0
63.761788393,4618.0
63.811922200,4559.0
63.862056007,4518.0
63.912189814,4559.0
63.962323621,4495.0
64.012457428,4585.0
64.062591235,4459.0
64.112725041,4468.0
64.162858848,4664.0
64.212992655,4476.0
64.263126462,4473.0
64.313260269,4530.0
64.363394076,4563.0
64.413527883,4561.0
64.463661690,4674.0
64.513795497,4493.0
64.563929304,4467.0
64.614063111,4580.0
64.664196918,4449.0
64.714330725,4577.0
64.764464532,4471.0
64.814598339,4599.0
64.864732146,4521.0
64.914865953,4514.0
64.964999759,4497.0
65.015133566,4661.0
65.065267373,4571.0
65.115401180,4525.0
65.165534987,4468.0
65.215668794,4588.0
65.265802601,4591.0
65.315936408,4562.0
65.366070215,4607.0
65.416204022,4582.0
65.466337829,4617.0
65.516471636,4535.0
65.566605443,4553.0
65.616739250,4641.0
65.666873057,4575.0
65.717006864,4498.0
65.767140670,4646.0
65.817274477,4544.0
65.867408284,4566.0
65.917542091,4584.0
65.967675898,4587.0
66.017809705,4607.0
66.067943512,4513.0
66.118077319,4584.0
66.168211126,4538.0
66.218344933,4605.0
66.268478740,4503.0
66.318612547,4472.0
66.368746354,4533.0
66.418880161,4421.0
66.469013968,4391.0
66.519147775,4574.0
66.569281581,4479.0
66.619415388,4593.0
66.669549195,4515.0
66.719683002,4501.0
66.769816809,4609.0
66.819950616,4453.0
66.870084423,4626.0
66.920218230,4689.0
66.970352037,4528.0
67.020485844,4543.0
67.070619651,4559.0
67.120753458,4542.0
67.170887265,4634.0
67.221021072,4479.0
67.271154879,4543.0
67.321288686,4510.0
67.371422492,4530.0
67.421556299,4563.0
67.471690106,4456.0
67.521823913,4647.0
67.571957720,4601.0
67.622091527,4715.0
67.672225334,4542.0
67.722359141,4515.0
67.772492948,4743.0
67.822626755,4889.0
67.872760562,4746.0
67.922894369,4695.0
67.973028176,4680.0
68.023161983,4601.0
68.073295790,4651.0
68.123429597,4516.0
68.173563403,4462.0
68.223697210,4763.0
68.273831017,4456.0
68.323964824,4485.0
68.374098631,4490.0
68.424232438,4541.0
68.474366245,4479.0
68.524500052,4472.0
68.574633859,4466.0
68.624767666,4423.0
68.674901473,4598.0
68.725035280,4605.0
68.775169087,4516.0
68.825302894,4536.0
68.875436701,4434.0
68.925570508,4544.0
68.975704314,4478.0
69.025838121,4764.0
69.075971928,4624.0
69.126105735,4541.0
69.176239542,4546.0
69.226373349,4478.0
69.276507156,4548.0
69.326640963,4566.0
69.376774770,4504.0
69.426908577,4567.0
69.477042384,4422.0
69.527176191,4554.0
69.577309998,4600.0
69.627443805,4498.0
69.677577612,4457.0
69.727711419,4470.0
69.777845225,4584.0
69.827979032,4632.0
69.878112839,4466.0
69.928246646,4547.0
69.978380453,4577.0
70.028514260,4505.0
70.078648067,4620.0
70.128781874,4625.0
70.178915681,4713.0
70.229049488,4580.0
70.279183295,4611.0
70.329317102,4501.0
70.379450909,4652.0
70.429584716,4621.0
70.479718523,4634.0
70.529852330,4422.0
70.579986136,4544.0
70.630119943,4506.0
70.680253750,4589.0
70.730387557,4597.0
70.780521364,4672.0
70.830655171,4594.0
70.880788978,4528.0
70.930922785,4590.0
70.981056592,4759.0
71.031190399,4516.0
71.081324206,4551.0
71.131458013,4727.0
71.181591820,4622.0
71.231725627,4690.0
71.281859434,4592.0
71.331993241,4554.0
71.382127047,4581.0
71.432260854,4817.0
71.482394661,4641.0
71.532528468,4600.0
71.582662275,4815.0
71.632796082,4736.0
71.682929889,4706.0
71.733063696,4548.0
71.783197503,4648.0
71.833331310,4672.0
71.883465117,4749.0
71.933598924,4584.0
71.983732731,4750.0
72.033866538,4624.0
72.084000345,4719.0
72.134134152,4532.0
72.184267958,4746.0
72.234401765,4723.0
72.284535572,4710.0
72.334669379,4703.0
72.384803186,4709.0
72.434936993,4723.0
72.485070800,4815.0
72.535204607,4783.0
72.585338414,4626.0
72.635472221,4867.0
72.685606028,4764.0
72.735739835,4840.0
72.785873642,4610.0
72.836007449,4873.0
72.886141256,4711.0
72.936275063,4859.0
72.986408869,4791.0
73.036542676,4819.0
73.086676483,4858.0
73.136810290,4742.0
73.186944097,4894.0
73.237077904,4861.0
73.287211711,5050.0
73.337345518,5352.0
73.387479325,5492.0
73.437613132,5818.0
73.487746939,5951.0
73.537880746,6305.0
73.588014553,7522.0
73.638148360,11314.0
73.688282167,25163.0
73.738415974,52944.0
73.788549780,40488.0
73.838683587,15588.0
73.888817394,14947.0
73.938951201,26323.0
73.989085008,27960.0
74.039218815,12059.0
74.089352622,7152.0
74.139486429,5998.0
74.189620236,5549.0
74.239754043,5310.0
74.289887850,5055.0
74.340021657,5025.0
74.390155464,5087.0
74.440289271,4852.0
74.490423078,4938.0
74.540556885,4830.0
74.590690692,4967.0
74.640824498,4933.0
74.690958305,4872.0
74.741092112,4941.0
74.791225919,4580.0
74.841359726,4776.0
74.891493533,4760.0
74.941627340,4764.0
74.991761147,4723.0
75.041894954,4619.0
75.092028761,4762.0
75.142162568,4653.0
75.192296375,4858.0
75.242430182,4712.0
75.292563989,4696.0
75.342697796,4637.0
75.392831603,4743.0
75.442965409,4631.0
75.493099216,4552.0
75.543233023,4622.0
75.593366830,4593.0
75.643500637,4707.0
75.693634444,4653.0
75.743768251,4615.0
75.793902058,4709.0
75.844035865,4681.0
75.894169672,4618.0
75.944303479,4678.0
75.994437286,4721.0
76.044571093,4689.0
76.094704900,4662.0
76.144838707,4536.0
76.194972514,4594.0
76.245106320,4673.0
76.295240127,4586.0
76.345373934,4616.0
76.395507741,4655.0
76.445641548,4542.0
76.495775355,4648.0
76.545909162,4568.0
76.596042969,4551.0
76.646176776,4584.0
76.696310583,4637.0
76.746444390,4501.0
76.796578197,4545.0
76.846712004,4580.0
76.896845811,4573.0
76.946979618,4604.0
76.997113425,4543.0
77.047247231,4688.0
77.097381038,4616.0
77.147514845,4623.0
77.197648652,4544.0
77.247782459,4502.0
77.297916266,4488.0
77.348050073,4641.0
77.398183880,4571.0
77.448317687,4536.0
77.498451494,4613.0
77.548585301,4594.0
77.598719108,4607.0
77.648852915,4684.0
77.698986722,4523.0
77.749120529,4495.0
77.799254336,4519.0
77.849388142,4592.0
77.899521949,4622.0
77.949655756,4573.0
77.999789563,4523.0
78.049923370,4714.0
78.100057177,4652.0
78.150190984,4544.0
78.200324791,4681.0
78.250458598,4497.0
78.300592405,4636.0
78.350726212,4676.0
78.400860019,4607.0
78.450993826,4624.0
78.501127633,4645.0
78.551261440,4613.0
78.601395247,4537.0
78.651529053,4630.0
78.701662860,4495.0
78.751796667,4659.0
78.801930474,4600.0
78.852064281,4525.0
78.902198088,4537.0
78.952331895,4506.0
79.002465702,4702.0
79.052599509,4529.0
79.102733316,4653.0
79.152867123,4605.0
79.203000930,4636.0
79.253134737,4431.0
79.303268544,4608.0
79.353402351,4536.0
79.403536158,4644.0
79.453669964,4445.0
79.503803771,4385.0
79.553937578,4538.0
79.604071385,4430.0
79.654205192,4599.0
79.704338999,4608.0
79.754472806,4583.0
79.804606613,4574.0
79.854740420,4513.0
79.904874227,4607.0
79.955008034,4618.0
80.005141841,4472.0
80.055275648,4506.0
80.105409455,4510.0
80.155543262,4554.0
80.205677069,4408.0
80.255810875,4463.0
80.305944682,4555.0
80.356078489,4686.0
80.406212296,4556.0
80.456346103,4569.0
80.506479910,4482.0
80.556613717,4600.0
80.606747524,4542.0
80.656881331,4735.0
80.707015138,4686.0
80.757148945,4659.0
80.807282752,4553.0
80.857416559,4731.0
80.907550366,4568.0
80.957684173,4555.0
81.007817980,4576.0
81.057951786,4554.0
81.108085593,4615.0
81.158219400,4548.0
81.208353207,4523.0
81.258487014,4557.0
81.308620821,4613.0
81.358754628,4589.0
81.408888435,4586.0
81.459022242,4582.0
81.509156049,4476.0
81.559289856,4526.0
81.609423663,4521.0
81.659557470,4626.0
81.709691277,4764.0
81.759825084,4866.0
81.809958891,4784.0
81.860092697,4771.0
81.910226504,4553.0
81.960360311,4511.0
82.010494118,4601.0
82.060627925,4702.0
82.110761732,4640.0
82.160895539,4528.0
82.211029346,4542.0
82.261163153,4594.0
82.311296960,4570.0
82.361430767,4471.0
82.411564574,4546.0
82.461698381,4526.0
82.511832188,4569.0
82.561965995,4582.0
82.612099802,4488.0
82.662233608,4577.0
82.712367415,4549.0
82.762501222,4570.0
82.812635029,4509.0
82.862768836,4519.0
82.912902643,4495.0
82.963036450,4521.0
83.013170257,4516.0
83.063304064,4503.0
83.113437871,4597.0
83.163571678,4567.0
83.213705485,4549.0
83.263839292,4477.0
83.313973099,4615.0
83.364106906,4612.0
83.414240713,4450.0
83.464374519,4581.0
83.514508326,4501.0
83.564642133,4490.0
83.614775940,4610.0
83.664909747,4482.0
83.715043554,4550.0
83.765177361,4503.0
83.815311168,4535.0
83.865444975,4329.0
83.915578782,4554.0
83.965712589,4529.0
84.015846396,4466.0
84.065980203,4463.0
84.116114010,4591.0
84.166247817,4562.0
84.216381624,4566.0
84.266515431,4352.0
84.316649237,4628.0
84.366783044,4549.0
84.416916851,4617.0
84.467050658,4538.0
84.517184465,4516.0
84.567318272,4517.0
84.617452079,4526.0
84.667585886,4520.0
84.717719693,4526.0
84.767853500,4517.0
84.817987307,4595.0
84.868121114,4509.0
84.918254921,4598.0
84.968388728,4523.0
85.018522535,4386.0
85.068656342,4465.0
85.118790148,4519.0
85.168923955,4493.0
85.219057762,4704.0
85.269191569,4515.0
85.319325376,4617.0
85.369459183,4546.0
85.419592990,4527.0
85.469726797,4564.0
85.519860604,4597.0
85.569994411,4601.0
85.620128218,4519.0
85.670262025,4549.0
85.720395832,4507.0
85.770529639,4544.0
85.820663446,4626.0
85.870797253,4543.0
85.920931059,4504.0
85.971064866,4454.0
86.021198673,4439.0
86.071332480,4546.0
86.121466287,4638.0
86.171600094,4593.0
86.221733901,4633.0
86.271867708,4581.0
86.322001515,4502.0
86.372135322,4541.0
86.422269129,4544.0
86.472402936,4577.0
86.522536743,4677.0
86.572670550,4573.0
86.622804357,4528.0
86.672938164,4522.0
86.723071970,4514.0
86.773205777,4593.0
86.823339584,4497.0
86.873473391,4652.0
86.923607198,4574.0
86.973741005,4563.0
87.023874812,4591.0
87.074008619,4539.0
87.124142426,4553.0
87.174276233,4634.0
87.224410040,4597.0
87.274543847,4594.0
87.324677654,4552.0
87.374811461,4629.0
87.424945268,4644.0
87.475079075,4637.0
87.525212881,4517.0
87.575346688,4599.0
87.625480495,4582.0
87.675614302,4545.0
87.725748109,4490.0
87.775881916,4702.0
87.826015723,4543.0
87.876149530,4632.0
87.926283337,4631.0
87.976417144,4465.0
88.026550951,4681.0
88.076684758,4563.0
88.126818565,4368.0
88.176952372,4673.0
88.227086179,4629.0
88.277219986,4599.0
88.327353792,4741.0
88.377487599,4583.0
88.427621406,4576.0
88.477755213,4533.0
88.527889020,4579.0
88.578022827,4634.0
88.628156634,4561.0
88.678290441,4610.0
88.728424248,4670.0
88.778558055,4635.0
88.828691862,4643.0
88.878825669,4727.0
88.928959476,4717.0
88.979093283,4747.0
89.029227090,4786.0
89.079360897,4849.0
89.129494703,4933.0
89.179628510,5030.0
89.229762317,5188.0
89.279896124,5677.0
89.330029931,6998.0
89.380163738,11064.0
89.430297545,17786.0
89.480431352,15003.0
89.530565159,8411.0
89.580698966,6430.0
89.630832773,7019.0
89.680966580,9269.0
89.731100387,11307.0
89.781234194,8266.0
89.831368001,5924.0
89.881501808,5195.0
89.931635614,5027.0
89.981769421,4795.0
90.031903228,4738.0
90.082037035,4666.0
90.132170842,4580.0
90.182304649,4553.0
90.232438456,4604.0
90.282572263,4550.0
90.332706070,4586.0
90.382839877,4710.0
90.432973684,4593.0
90.483107491,4633.0
90.533241298,4589.0
90.583375105,4577.0
90.633508912,4601.0
90.683642719,4501.0
90.733776525,4661.0
90.783910332,4510.0
90.834044139,4657.0
90.884177946,4587.0
90.934311753,4570.0
90.984445560,4580.0
91.034579367,4587.0
91.084713174,4507.0
91.134846981,4514.0
91.184980788,4664.0
91.235114595,4531.0
91.285248402,4554.0
91.335382209,4623.0
91.385516016,4543.0
91.435649823,4591.0
91.485783630,4651.0
91.535917436,4619.0
91.586051243,4571.0
91.636185050,4677.0
91.686318857,4538.0
91.736452664,4595.0
91.786586471,4540.0
91.836720278,4472.0
91.886854085,4549.0
91.936987892,4540.0
91.987121699,4682.0
92.037255506,4538.0
92.087389313,4493.0
92.137523120,4578.0
92.187656927,4514.0
92.237790734,4574.0
92.287924541,4564.0
92.338058347,4559.0
92.388192154,4464.0
92.438325961,4568.0
92.488459768,4602.0
92.538593575,4624.0
92.588727382,4472.0
92.638861189,4596.0
92.688994996,4582.0
92.739128803,4550.0
92.789262610,4518.0
92.839396417,4587.0
92.889530224,4574.0
92.939664031,4504.0
92.989797838,4541.0
93.039931645,4642.0
93.090065452,4636.0
93.140199258,4486.0
93.190333065,4550.0
93.240466872,4549.0
93.290600679,4626.0
93.340734486,4717.0
93.390868293,4685.0
93.441002100,4635.0
93.491135907,4500.0
93.541269714,4725.0
93.591403521,4590.0
93.641537328,4606.0
93.691671135,4555.0
93.741804942,4635.0
93.791938749,4654.0
93.842072556,4568.0
93.892206363,4564.0
93.942340170,4647.0
93.992473976,4718.0
94.042607783,4703.0
94.092741590,4696.0
94.142875397,4818.0
94.193009204,4855.0
94.243143011,4767.0
94.293276818,4949.0
94.343410625,5032.0
94.393544432,5325.0
94.443678239,5724.0
94.493812046,6824.0
94.543945853,11339.0
94.594079660,20670.0
94.644213467,17005.0
94.694347274,8822.0
94.744481081,6431.0
94.794614887,6473.0
94.844748694,7788.0
94.894882501,11755.0
94.945016308,11714.0
94.995150115,7152.0
95.045283922,5574.0
95.095417729,5136.0
95.145551536,4889.0
95.195685343,4810.0
95.245819150,4788.0
95.295952957,4746.0
95.346086764,4678.0
95.396220571,4571.0
95.446354378,4587.0
95.496488185,4642.0
95.546621992,4618.0
95.596755798,4479.0
95.646889605,4602.0
95.697023412,4604.0
95.747157219,4540.0
95.797291026,4529.0
95.847424833,4558.0
95.897558640,4553.0
95.947692447,4625.0
95.997826254,4631.0
96.047960061,4489.0
96.098093868,4517.0
96.148227675,4587.0
96.198361482,4616.0
96.248495289,4574.0
96.298629096,4633.0
96.348762903,4585.0
96.398896709,4620.0
96.449030516,4629.0
96.499164323,4521.0
96.549298130,4639.0
96.599431937,4470.0
96.649565744,4512.0
96.699699551,4504.0
96.749833358,4665.0
96.799967165,4471.0
96.850100972,4583.0
96.900234779,4549.0
96.950368586,4526.0
97.000502393,4580.0
97.050636200,4551.0
97.100770007,4533.0
97.150903814,4511.0
97.201037620,4543.0
97.251171427,4378.0
97.301305234,4574.0
97.351439041,4439.0
97.401572848,4516.0
97.451706655,4489.0
97.501840462,4466.0
97.551974269,4563.0
97.602108076,4511.0
97.652241883,4502.0
97.702375690,4589.0
97.752509497,4584.0
97.802643304,4439.0
97.852777111,4492.0
97.902910918,4499.0
97.953044725,4540.0
98.003178531,4479.0
98.053312338,4471.0
98.103446145,4449.0
98.153579952,4537.0
98.203713759,4490.0
98.253847566,4633.0
98.303981373,4514.0
98.354115180,4420.0
98.404248987,4448.0
98.454382794,4546.0
98.504516601,4460.0
98.554650408,4497.0
98.604784215,4459.0
98.654918022,4576.0
98.705051829,4503.0
98.755185636,4592.0
98.805319442,4621.0
98.855453249,4468.0
98.905587056,4392.0
98.955720863,4522.0
99.005854670,4530.0
99.055988477,4481.0
99.106122284,4504.0
99.156256091,4570.0
99.206389898,4574.0
99.256523705,4466.0
99.306657512,4519.0
99.356791319,4488.0
99.406925126,4543.0
99.457058933,4582.0
99.507192740,4684.0
99.557326547,4450.0
99.607460353,4438.0
99.657594160,4592.0
99.707727967,4569.0
99.757861774,4474.0
99.807995581,4510.0
99.858129388,4543.0
99.908263195,4504.0
99.958397002,4471.0
99.991819540,4469.0