File: OriginPro/XRD from Panalytical X'Pert PRO/Nova Cu foil/Cufoil_450°C.csv
[Measurement conditions]
Sample identification,
Comment - 1,"finito"
Comment - 2,"Configuration=MRI TC-Basic Stage, Owner=User-1, Creation date=26-10-2009 9:18:44"
Comment - 3,"Goniometer=PW3050/60 (Theta/Theta); Minimum step size 2Theta:0.001; Minimum step size Omega:0.001"
Comment - 4,"Sample stage=MRI TC-Basic (PtRh heat strip)"
Comment - 5,"Diffractometer system=XPERT-PRO"
Comment - 6,"Measurement program=FlatStage, Owner=joana, Creation date=03-08-2011 15:43:53"
Anode material,Cu
K-Alpha1 wavelength,1.5405980
K-Alpha2 wavelength,1.5444260
Ratio K-Alpha2/K-Alpha1,0.500
Divergence slit,Fixed,0.76mm
Monochromator used,NO
Generator voltage, 45
Tube current, 40
File date and time,07/Dec/2012 00:14
Unit cell,
h k l, 0 0 0
Temperature [K],723
Scan axis,Gonio
Scan range,24.999999996,100.000175174
Scan step size,0.0167113
No. of points, 4488
Scan type,CONTINUOUS
Time per step,53.340
[Scan points]
Angle,Intensity
25.008355630,2098.0
25.058489437,2188.0
25.108623244,2158.0
25.158757051,2179.0
25.208890858,2102.0
25.259024665,2236.0
25.309158472,2175.0
25.359292279,2146.0
25.409426086,2253.0
25.459559892,2208.0
25.509693699,2168.0
25.559827506,2196.0
25.609961313,2241.0
25.660095120,2225.0
25.710228927,2272.0
25.760362734,2254.0
25.810496541,2155.0
25.860630348,2204.0
25.910764155,2242.0
25.960897962,2147.0
26.011031769,2314.0
26.061165576,2300.0
26.111299383,2251.0
26.161433190,2216.0
26.211566997,2256.0
26.261700803,2295.0
26.311834610,2210.0
26.361968417,2262.0
26.412102224,2283.0
26.462236031,2267.0
26.512369838,2311.0
26.562503645,2329.0
26.612637452,2274.0
26.662771259,2183.0
26.712905066,2255.0
26.763038873,2250.0
26.813172680,2299.0
26.863306487,2270.0
26.913440294,2219.0
26.963574101,2297.0
27.013707908,2269.0
27.063841714,2327.0
27.113975521,2360.0
27.164109328,2278.0
27.214243135,2335.0
27.264376942,2361.0
27.314510749,2279.0
27.364644556,2325.0
27.414778363,2409.0
27.464912170,2367.0
27.515045977,2305.0
27.565179784,2445.0
27.615313591,2369.0
27.665447398,2411.0
27.715581205,2278.0
27.765715012,2444.0
27.815848819,2480.0
27.865982625,2385.0
27.916116432,2394.0
27.966250239,2394.0
28.016384046,2341.0
28.066517853,2348.0
28.116651660,2459.0
28.166785467,2422.0
28.216919274,2403.0
28.267053081,2392.0
28.317186888,2476.0
28.367320695,2322.0
28.417454502,2511.0
28.467588309,2414.0
28.517722116,2378.0
28.567855923,2452.0
28.617989730,2377.0
28.668123536,2435.0
28.718257343,2371.0
28.768391150,2446.0
28.818524957,2577.0
28.868658764,2410.0
28.918792571,2357.0
28.968926378,2412.0
29.019060185,2592.0
29.069193992,2501.0
29.119327799,2488.0
29.169461606,2771.0
29.219595413,2881.0
29.269729220,3302.0
29.319863027,3604.0
29.369996834,3750.0
29.420130641,3486.0
29.470264447,3480.0
29.520398254,3168.0
29.570532061,2743.0
29.620665868,2724.0
29.670799675,2584.0
29.720933482,2634.0
29.771067289,2655.0
29.821201096,2547.0
29.871334903,2503.0
29.921468710,2567.0
29.971602517,2537.0
30.021736324,2581.0
30.071870131,2500.0
30.122003938,2469.0
30.172137745,2602.0
30.222271552,2583.0
30.272405358,2598.0
30.322539165,2413.0
30.372672972,2520.0
30.422806779,2601.0
30.472940586,2540.0
30.523074393,2567.0
30.573208200,2578.0
30.623342007,2591.0
30.673475814,2422.0
30.723609621,2678.0
30.773743428,2586.0
30.823877235,2554.0
30.874011042,2577.0
30.924144849,2498.0
30.974278656,2587.0
31.024412463,2546.0
31.074546269,2646.0
31.124680076,2686.0
31.174813883,2511.0
31.224947690,2609.0
31.275081497,2509.0
31.325215304,2658.0
31.375349111,2742.0
31.425482918,2592.0
31.475616725,2628.0
31.525750532,2605.0
31.575884339,2570.0
31.626018146,2672.0
31.676151953,2668.0
31.726285760,2735.0
31.776419567,2638.0
31.826553374,2724.0
31.876687180,2576.0
31.926820987,2719.0
31.976954794,2699.0
32.027088601,2648.0
32.077222408,2724.0
32.127356215,2634.0
32.177490022,2758.0
32.227623829,2714.0
32.277757636,2718.0
32.327891443,2741.0
32.378025250,2680.0
32.428159057,2741.0
32.478292864,2753.0
32.528426671,2747.0
32.578560478,2815.0
32.628694285,2708.0
32.678828091,2722.0
32.728961898,2764.0
32.779095705,2620.0
32.829229512,2798.0
32.879363319,2789.0
32.929497126,2830.0
32.979630933,2768.0
33.029764740,2678.0
33.079898547,2820.0
33.130032354,2803.0
33.180166161,2758.0
33.230299968,2763.0
33.280433775,2703.0
33.330567582,2809.0
33.380701389,2763.0
33.430835196,2751.0
33.480969002,2722.0
33.531102809,2971.0
33.581236616,2809.0
33.631370423,2849.0
33.681504230,2741.0
33.731638037,2744.0
33.781771844,2794.0
33.831905651,2890.0
33.882039458,2898.0
33.932173265,2898.0
33.982307072,2809.0
34.032440879,2876.0
34.082574686,2907.0
34.132708493,2881.0
34.182842300,2817.0
34.232976107,2861.0
34.283109913,2924.0
34.333243720,2965.0
34.383377527,2941.0
34.433511334,2833.0
34.483645141,2884.0
34.533778948,2934.0
34.583912755,2906.0
34.634046562,2951.0
34.684180369,2902.0
34.734314176,2887.0
34.784447983,2907.0
34.834581790,3110.0
34.884715597,2901.0
34.934849404,3033.0
34.984983211,3113.0
35.035117018,3057.0
35.085250825,3144.0
35.135384631,3200.0
35.185518438,3303.0
35.235652245,3459.0
35.285786052,3448.0
35.335919859,3587.0
35.386053666,3590.0
35.436187473,3516.0
35.486321280,3479.0
35.536455087,3433.0
35.586588894,3483.0
35.636722701,3365.0
35.686856508,3350.0
35.736990315,3512.0
35.787124122,3511.0
35.837257929,3749.0
35.887391736,4000.0
35.937525542,4765.0
35.987659349,5774.0
36.037793156,7826.0
36.087926963,11171.0
36.138060770,16188.0
36.188194577,21008.0
36.238328384,23187.0
36.288462191,22704.0
36.338595998,18822.0
36.388729805,14031.0
36.438863612,10395.0
36.488997419,7412.0
36.539131226,5656.0
36.589265033,4773.0
36.639398840,4119.0
36.689532647,3898.0
36.739666453,3692.0
36.789800260,3563.0
36.839934067,3515.0
36.890067874,3487.0
36.940201681,3313.0
36.990335488,3378.0
37.040469295,3327.0
37.090603102,3384.0
37.140736909,3307.0
37.190870716,3289.0
37.241004523,3454.0
37.291138330,3304.0
37.341272137,3294.0
37.391405944,3351.0
37.441539751,3321.0
37.491673558,3332.0
37.541807364,3282.0
37.591941171,3225.0
37.642074978,3283.0
37.692208785,3239.0
37.742342592,3396.0
37.792476399,3268.0
37.842610206,3328.0
37.892744013,3316.0
37.942877820,3241.0
37.993011627,3280.0
38.043145434,3331.0
38.093279241,3508.0
38.143413048,3454.0
38.193546855,3511.0
38.243680662,3433.0
38.293814469,3533.0
38.343948275,3439.0
38.394082082,3474.0
38.444215889,3600.0
38.494349696,3683.0
38.544483503,3812.0
38.594617310,3634.0
38.644751117,3615.0
38.694884924,3686.0
38.745018731,3521.0
38.795152538,3496.0
38.845286345,3412.0
38.895420152,3466.0
38.945553959,3456.0
38.995687766,3385.0
39.045821573,3319.0
39.095955380,3321.0
39.146089186,3362.0
39.196222993,3303.0
39.246356800,3399.0
39.296490607,3421.0
39.346624414,3432.0
39.396758221,3454.0
39.446892028,3336.0
39.497025835,3347.0
39.547159642,3327.0
39.597293449,3342.0
39.647427256,3337.0
39.697561063,3670.0
39.747694870,3592.0
39.797828677,3699.0
39.847962484,3526.0
39.898096291,3516.0
39.948230097,3325.0
39.998363904,3409.0
40.048497711,3406.0
40.098631518,3395.0
40.148765325,3390.0
40.198899132,3301.0
40.249032939,3388.0
40.299166746,3381.0
40.349300553,3397.0
40.399434360,3452.0
40.449568167,3451.0
40.499701974,3431.0
40.549835781,3319.0
40.599969588,3441.0
40.650103395,3426.0
40.700237202,3426.0
40.750371008,3459.0
40.800504815,3471.0
40.850638622,3458.0
40.900772429,3380.0
40.950906236,3452.0
41.001040043,3433.0
41.051173850,3526.0
41.101307657,3574.0
41.151441464,3530.0
41.201575271,3607.0
41.251709078,3561.0
41.301842885,3659.0
41.351976692,3846.0
41.402110499,3883.0
41.452244306,4025.0
41.502378113,4204.0
41.552511919,4369.0
41.602645726,4411.0
41.652779533,4664.0
41.702913340,4981.0
41.753047147,5336.0
41.803180954,5765.0
41.853314761,6544.0
41.903448568,7374.0
41.953582375,7850.0
42.003716182,8352.0
42.053849989,8383.0
42.103983796,8100.0
42.154117603,7492.0
42.204251410,7089.0
42.254385217,6347.0
42.304519024,5825.0
42.354652830,5348.0
42.404786637,5129.0
42.454920444,4930.0
42.505054251,4895.0
42.555188058,5038.0
42.605321865,5554.0
42.655455672,6462.0
42.705589479,7776.0
42.755723286,11173.0
42.805857093,27684.0
42.855990900,98981.0
42.906124707,85332.0
42.956258514,84472.0
43.006392321,74726.0
43.056526128,37690.0
43.106659935,22981.0
43.156793741,11619.0
43.206927548,7192.0
43.257061355,5511.0
43.307195162,5047.0
43.357328969,4713.0
43.407462776,4594.0
43.457596583,4436.0
43.507730390,4221.0
43.557864197,4284.0
43.607998004,4325.0
43.658131811,4328.0
43.708265618,4012.0
43.758399425,4032.0
43.808533232,3887.0
43.858667039,3896.0
43.908800846,3974.0
43.958934652,3754.0
44.009068459,3962.0
44.059202266,3950.0
44.109336073,3857.0
44.159469880,3910.0
44.209603687,3803.0
44.259737494,3850.0
44.309871301,3787.0
44.360005108,3866.0
44.410138915,3878.0
44.460272722,3767.0
44.510406529,3871.0
44.560540336,3816.0
44.610674143,3872.0
44.660807950,3897.0
44.710941757,3918.0
44.761075564,3783.0
44.811209370,3999.0
44.861343177,3994.0
44.911476984,4027.0
44.961610791,3906.0
45.011744598,3894.0
45.061878405,3763.0
45.112012212,3688.0
45.162146019,3711.0
45.212279826,3785.0
45.262413633,3707.0
45.312547440,3768.0
45.362681247,3744.0
45.412815054,3738.0
45.462948861,3783.0
45.513082668,3777.0
45.563216475,3760.0
45.613350281,3774.0
45.663484088,3680.0
45.713617895,3784.0
45.763751702,3745.0
45.813885509,3837.0
45.864019316,3649.0
45.914153123,3850.0
45.964286930,3739.0
46.014420737,3758.0
46.064554544,3894.0
46.114688351,3842.0
46.164822158,4109.0
46.214955965,4395.0
46.265089772,5779.0
46.315223579,6150.0
46.365357386,5304.0
46.415491192,4894.0
46.465624999,4530.0
46.515758806,4049.0
46.565892613,3935.0
46.616026420,3931.0
46.666160227,3853.0
46.716294034,3863.0
46.766427841,3835.0
46.816561648,3764.0
46.866695455,3728.0
46.916829262,3664.0
46.966963069,3678.0
47.017096876,3778.0
47.067230683,3682.0
47.117364490,3828.0
47.167498297,3760.0
47.217632103,3787.0
47.267765910,3711.0
47.317899717,3590.0
47.368033524,3682.0
47.418167331,3667.0
47.468301138,3669.0
47.518434945,3597.0
47.568568752,3730.0
47.618702559,3580.0
47.668836366,3691.0
47.718970173,3798.0
47.769103980,3731.0
47.819237787,3733.0
47.869371594,3792.0
47.919505401,3721.0
47.969639208,3786.0
48.019773014,3773.0
48.069906821,3713.0
48.120040628,3863.0
48.170174435,3920.0
48.220308242,4002.0
48.270442049,3959.0
48.320575856,4116.0
48.370709663,4139.0
48.420843470,4152.0
48.470977277,4149.0
48.521111084,4301.0
48.571244891,4324.0
48.621378698,4392.0
48.671512505,4214.0
48.721646312,4249.0
48.771780119,4190.0
48.821913925,4250.0
48.872047732,4115.0
48.922181539,4113.0
48.972315346,4090.0
49.022449153,4062.0
49.072582960,4329.0
49.122716767,4138.0
49.172850574,4176.0
49.222984381,4122.0
49.273118188,4166.0
49.323251995,4098.0
49.373385802,4149.0
49.423519609,4233.0
49.473653416,4269.0
49.523787223,4255.0
49.573921030,4533.0
49.624054836,4829.0
49.674188643,5496.0
49.724322450,6525.0
49.774456257,7385.0
49.824590064,9645.0
49.874723871,19600.0
49.924857678,70091.0
49.974991485,99834.0
50.025125292,70708.0
50.075259099,86992.0
50.125392906,62268.0
50.175526713,34191.0
50.225660520,23012.0
50.275794327,11983.0
50.325928134,7017.0
50.376061941,5748.0
50.426195747,5279.0
50.476329554,4744.0
50.526463361,4733.0
50.576597168,4582.0
50.626730975,4300.0
50.676864782,4201.0
50.726998589,4254.0
50.777132396,4177.0
50.827266203,4051.0
50.877400010,4069.0
50.927533817,4104.0
50.977667624,4023.0
51.027801431,4049.0
51.077935238,4036.0
51.128069045,3963.0
51.178202852,4035.0
51.228336658,4010.0
51.278470465,3831.0
51.328604272,3881.0
51.378738079,3943.0
51.428871886,3904.0
51.479005693,3881.0
51.529139500,3961.0
51.579273307,4068.0
51.629407114,3944.0
51.679540921,3917.0
51.729674728,3771.0
51.779808535,4011.0
51.829942342,3916.0
51.880076149,3877.0
51.930209956,3910.0
51.980343763,3958.0
52.030477569,3917.0
52.080611376,3913.0
52.130745183,3890.0
52.180878990,3953.0
52.231012797,4086.0
52.281146604,4029.0
52.331280411,3971.0
52.381414218,3904.0
52.431548025,3791.0
52.481681832,3919.0
52.531815639,3876.0
52.581949446,3839.0
52.632083253,3944.0
52.682217060,3707.0
52.732350867,3908.0
52.782484674,3910.0
52.832618480,3777.0
52.882752287,3728.0
52.932886094,3674.0
52.983019901,3811.0
53.033153708,3886.0
53.083287515,3818.0
53.133421322,3851.0
53.183555129,3816.0
53.233688936,3834.0
53.283822743,3842.0
53.333956550,3712.0
53.384090357,3729.0
53.434224164,3742.0
53.484357971,3838.0
53.534491778,3846.0
53.584625585,3809.0
53.634759391,3813.0
53.684893198,3734.0
53.735027005,3767.0
53.785160812,3776.0
53.835294619,3880.0
53.885428426,3879.0
53.935562233,3809.0
53.985696040,3861.0
54.035829847,3848.0
54.085963654,3802.0
54.136097461,3668.0
54.186231268,3835.0
54.236365075,3907.0
54.286498882,3822.0
54.336632689,3942.0
54.386766496,3931.0
54.436900303,3786.0
54.487034109,3991.0
54.537167916,3885.0
54.587301723,3769.0
54.637435530,3788.0
54.687569337,3801.0
54.737703144,3762.0
54.787836951,3883.0
54.837970758,3743.0
54.888104565,3852.0
54.938238372,3812.0
54.988372179,3763.0
55.038505986,3851.0
55.088639793,3919.0
55.138773600,3755.0
55.188907407,3880.0
55.239041214,3673.0
55.289175020,3737.0
55.339308827,3730.0
55.389442634,3923.0
55.439576441,3816.0
55.489710248,3697.0
55.539844055,3803.0
55.589977862,3890.0
55.640111669,3798.0
55.690245476,3675.0
55.740379283,3748.0
55.790513090,3910.0
55.840646897,3852.0
55.890780704,3797.0
55.940914511,3706.0
55.991048318,3736.0
56.041182125,3735.0
56.091315931,3781.0
56.141449738,3758.0
56.191583545,3799.0
56.241717352,3910.0
56.291851159,3799.0
56.341984966,3722.0
56.392118773,3766.0
56.442252580,3798.0
56.492386387,3755.0
56.542520194,3748.0
56.592654001,3773.0
56.642787808,3749.0
56.692921615,3743.0
56.743055422,3810.0
56.793189229,3792.0
56.843323036,3736.0
56.893456842,3802.0
56.943590649,3803.0
56.993724456,3795.0
57.043858263,3838.0
57.093992070,3857.0
57.144125877,3812.0
57.194259684,3907.0
57.244393491,3825.0
57.294527298,3834.0
57.344661105,3839.0
57.394794912,3834.0
57.444928719,3805.0
57.495062526,3838.0
57.545196333,3792.0
57.595330140,3793.0
57.645463947,3919.0
57.695597753,3776.0
57.745731560,3715.0
57.795865367,3874.0
57.845999174,3894.0
57.896132981,3719.0
57.946266788,3851.0
57.996400595,3803.0
58.046534402,3803.0
58.096668209,3786.0
58.146802016,3833.0
58.196935823,3902.0
58.247069630,3757.0
58.297203437,3801.0
58.347337244,3745.0
58.397471051,3718.0
58.447604858,3770.0
58.497738664,3809.0
58.547872471,3729.0
58.598006278,3845.0
58.648140085,3735.0
58.698273892,3882.0
58.748407699,3845.0
58.798541506,3911.0
58.848675313,3777.0
58.898809120,3819.0
58.948942927,3840.0
58.999076734,3757.0
59.049210541,3788.0
59.099344348,3840.0
59.149478155,3823.0
59.199611962,3899.0
59.249745769,3909.0
59.299879575,3812.0
59.350013382,3881.0
59.400147189,3910.0
59.450280996,3992.0
59.500414803,3751.0
59.550548610,3840.0
59.600682417,3925.0
59.650816224,3911.0
59.700950031,3852.0
59.751083838,3814.0
59.801217645,3937.0
59.851351452,3808.0
59.901485259,3933.0
59.951619066,3766.0
60.001752873,3942.0
60.051886680,3926.0
60.102020486,3990.0
60.152154293,4048.0
60.202288100,3920.0
60.252421907,3912.0
60.302555714,3869.0
60.352689521,4021.0
60.402823328,3991.0
60.452957135,3948.0
60.503090942,3991.0
60.553224749,4091.0
60.603358556,4011.0
60.653492363,4185.0
60.703626170,4249.0
60.753759977,4425.0
60.803893784,4720.0
60.854027591,4996.0
60.904161397,5350.0
60.954295204,5563.0
61.004429011,6042.0
61.054562818,6309.0
61.104696625,6331.0
61.154830432,6429.0
61.204964239,6524.0
61.255098046,6281.0
61.305231853,6051.0
61.355365660,5509.0
61.405499467,5296.0
61.455633274,4894.0
61.505767081,4804.0
61.555900888,4467.0
61.606034695,4451.0
61.656168502,4246.0
61.706302308,4186.0
61.756436115,4110.0
61.806569922,4137.0
61.856703729,4037.0
61.906837536,4102.0
61.956971343,3989.0
62.007105150,4013.0
62.057238957,3912.0
62.107372764,4065.0
62.157506571,3864.0
62.207640378,3903.0
62.257774185,3949.0
62.307907992,4025.0
62.358041799,3968.0
62.408175606,3869.0
62.458309413,3929.0
62.508443219,3830.0
62.558577026,3973.0
62.608710833,4011.0
62.658844640,4058.0
62.708978447,3911.0
62.759112254,3938.0
62.809246061,3868.0
62.859379868,3904.0
62.909513675,3923.0
62.959647482,3965.0
63.009781289,3819.0
63.059915096,3892.0
63.110048903,3952.0
63.160182710,3969.0
63.210316517,3865.0
63.260450324,3827.0
63.310584130,3976.0
63.360717937,3913.0
63.410851744,3852.0
63.460985551,3849.0
63.511119358,3897.0
63.561253165,3831.0
63.611386972,3859.0
63.661520779,3891.0
63.711654586,3884.0
63.761788393,3958.0
63.811922200,3976.0
63.862056007,3903.0
63.912189814,3814.0
63.962323621,3849.0
64.012457428,3905.0
64.062591235,3882.0
64.112725041,4023.0
64.162858848,3959.0
64.212992655,3904.0
64.263126462,3986.0
64.313260269,3974.0
64.363394076,3814.0
64.413527883,3874.0
64.463661690,3946.0
64.513795497,3886.0
64.563929304,3903.0
64.614063111,3908.0
64.664196918,3843.0
64.714330725,3994.0
64.764464532,3778.0
64.814598339,3993.0
64.864732146,3859.0
64.914865953,3853.0
64.964999759,3907.0
65.015133566,3998.0
65.065267373,3932.0
65.115401180,3870.0
65.165534987,3981.0
65.215668794,3918.0
65.265802601,4004.0
65.315936408,3903.0
65.366070215,3825.0
65.416204022,3908.0
65.466337829,3932.0
65.516471636,4103.0
65.566605443,3946.0
65.616739250,3999.0
65.666873057,3955.0
65.717006864,3856.0
65.767140670,4030.0
65.817274477,4068.0
65.867408284,3957.0
65.917542091,3992.0
65.967675898,3969.0
66.017809705,3962.0
66.067943512,3899.0
66.118077319,3949.0
66.168211126,4022.0
66.218344933,4018.0
66.268478740,4036.0
66.318612547,3844.0
66.368746354,4021.0
66.418880161,3940.0
66.469013968,3962.0
66.519147775,3944.0
66.569281581,3933.0
66.619415388,4007.0
66.669549195,3903.0
66.719683002,3913.0
66.769816809,3822.0
66.819950616,3880.0
66.870084423,4039.0
66.920218230,3927.0
66.970352037,3966.0
67.020485844,3848.0
67.070619651,3906.0
67.120753458,3998.0
67.170887265,3914.0
67.221021072,3935.0
67.271154879,4106.0
67.321288686,4093.0
67.371422492,3851.0
67.421556299,3916.0
67.471690106,4075.0
67.521823913,3978.0
67.571957720,4039.0
67.622091527,4142.0
67.672225334,4154.0
67.722359141,4129.0
67.772492948,4169.0
67.822626755,4172.0
67.872760562,4134.0
67.922894369,4179.0
67.973028176,4010.0
68.023161983,3967.0
68.073295790,4025.0
68.123429597,3979.0
68.173563403,3898.0
68.223697210,3958.0
68.273831017,3963.0
68.323964824,3852.0
68.374098631,3894.0
68.424232438,3779.0
68.474366245,3895.0
68.524500052,4074.0
68.574633859,4024.0
68.624767666,3832.0
68.674901473,3975.0
68.725035280,3899.0
68.775169087,3956.0
68.825302894,3992.0
68.875436701,4074.0
68.925570508,3849.0
68.975704314,3808.0
69.025838121,3963.0
69.075971928,4046.0
69.126105735,3867.0
69.176239542,3939.0
69.226373349,4063.0
69.276507156,4042.0
69.326640963,3949.0
69.376774770,4023.0
69.426908577,3973.0
69.477042384,3962.0
69.527176191,3995.0
69.577309998,3925.0
69.627443805,4018.0
69.677577612,3921.0
69.727711419,3878.0
69.777845225,3947.0
69.827979032,3915.0
69.878112839,4054.0
69.928246646,3982.0
69.978380453,4072.0
70.028514260,3929.0
70.078648067,3984.0
70.128781874,3999.0
70.178915681,3980.0
70.229049488,4086.0
70.279183295,3986.0
70.329317102,4007.0
70.379450909,4078.0
70.429584716,3964.0
70.479718523,4051.0
70.529852330,4003.0
70.579986136,4099.0
70.630119943,4096.0
70.680253750,4107.0
70.730387557,4121.0
70.780521364,4024.0
70.830655171,4015.0
70.880788978,4046.0
70.930922785,4129.0
70.981056592,4006.0
71.031190399,4134.0
71.081324206,3987.0
71.131458013,4092.0
71.181591820,4153.0
71.231725627,4151.0
71.281859434,4145.0
71.331993241,4004.0
71.382127047,4065.0
71.432260854,4019.0
71.482394661,4040.0
71.532528468,4036.0
71.582662275,4131.0
71.632796082,4060.0
71.682929889,4265.0
71.733063696,4098.0
71.783197503,4026.0
71.833331310,4102.0
71.883465117,4016.0
71.933598924,4193.0
71.983732731,4005.0
72.033866538,4155.0
72.084000345,4242.0
72.134134152,4177.0
72.184267958,4280.0
72.234401765,4133.0
72.284535572,4244.0
72.334669379,4238.0
72.384803186,4287.0
72.434936993,4230.0
72.485070800,4293.0
72.535204607,4246.0
72.585338414,4366.0
72.635472221,4376.0
72.685606028,4422.0
72.735739835,4614.0
72.785873642,4589.0
72.836007449,4751.0
72.886141256,4882.0
72.936275063,5032.0
72.986408869,5103.0
73.036542676,5422.0
73.086676483,5530.0
73.136810290,5836.0
73.186944097,6067.0
73.237077904,6157.0
73.287211711,6626.0
73.337345518,9130.0
73.387479325,19989.0
73.437613132,20618.0
73.487746939,15572.0
73.537880746,15325.0
73.588014553,16150.0
73.638148360,15047.0
73.688282167,10996.0
73.738415974,10002.0
73.788549780,8438.0
73.838683587,6419.0
73.888817394,5211.0
73.938951201,5072.0
73.989085008,4834.0
74.039218815,4883.0
74.089352622,4554.0
74.139486429,4711.0
74.189620236,4423.0
74.239754043,4456.0
74.289887850,4612.0
74.340021657,4350.0
74.390155464,4215.0
74.440289271,4357.0
74.490423078,4339.0
74.540556885,4356.0
74.590690692,4331.0
74.640824498,4330.0
74.690958305,4352.0
74.741092112,4388.0
74.791225919,4221.0
74.841359726,4338.0
74.891493533,4257.0
74.941627340,4237.0
74.991761147,4309.0
75.041894954,4320.0
75.092028761,4329.0
75.142162568,4270.0
75.192296375,4307.0
75.242430182,4335.0
75.292563989,4364.0
75.342697796,4272.0
75.392831603,4101.0
75.442965409,4263.0
75.493099216,4134.0
75.543233023,4288.0
75.593366830,4185.0
75.643500637,4228.0
75.693634444,4260.0
75.743768251,4216.0
75.793902058,4368.0
75.844035865,4326.0
75.894169672,4200.0
75.944303479,4292.0
75.994437286,4324.0
76.044571093,4164.0
76.094704900,4455.0
76.144838707,4299.0
76.194972514,4314.0
76.245106320,4234.0
76.295240127,4240.0
76.345373934,4315.0
76.395507741,4265.0
76.445641548,4435.0
76.495775355,4139.0
76.545909162,4288.0
76.596042969,4396.0
76.646176776,4344.0
76.696310583,4293.0
76.746444390,4359.0
76.796578197,4420.0
76.846712004,4483.0
76.896845811,4498.0
76.946979618,4430.0
76.997113425,4379.0
77.047247231,4573.0
77.097381038,4555.0
77.147514845,4528.0
77.197648652,4534.0
77.247782459,4543.0
77.297916266,4505.0
77.348050073,4478.0
77.398183880,4426.0
77.448317687,4249.0
77.498451494,4491.0
77.548585301,4376.0
77.598719108,4445.0
77.648852915,4353.0
77.698986722,4479.0
77.749120529,4379.0
77.799254336,4224.0
77.849388142,4242.0
77.899521949,4231.0
77.949655756,4315.0
77.999789563,4410.0
78.049923370,4187.0
78.100057177,4256.0
78.150190984,4264.0
78.200324791,4264.0
78.250458598,4273.0
78.300592405,4295.0
78.350726212,4286.0
78.400860019,4344.0
78.450993826,4374.0
78.501127633,4154.0
78.551261440,4315.0
78.601395247,4225.0
78.651529053,4387.0
78.701662860,4338.0
78.751796667,4351.0
78.801930474,4392.0
78.852064281,4354.0
78.902198088,4305.0
78.952331895,4335.0
79.002465702,4293.0
79.052599509,4298.0
79.102733316,4211.0
79.152867123,4369.0
79.203000930,4131.0
79.253134737,4199.0
79.303268544,4336.0
79.353402351,4292.0
79.403536158,4333.0
79.453669964,4361.0
79.503803771,4246.0
79.553937578,4384.0
79.604071385,4308.0
79.654205192,4352.0
79.704338999,4154.0
79.754472806,4343.0
79.804606613,4250.0
79.854740420,4291.0
79.904874227,4208.0
79.955008034,4311.0
80.005141841,4361.0
80.055275648,4362.0
80.105409455,4329.0
80.155543262,4409.0
80.205677069,4343.0
80.255810875,4375.0
80.305944682,4264.0
80.356078489,4398.0
80.406212296,4274.0
80.456346103,4432.0
80.506479910,4405.0
80.556613717,4317.0
80.606747524,4485.0
80.656881331,4373.0
80.707015138,4344.0
80.757148945,4337.0
80.807282752,4413.0
80.857416559,4315.0
80.907550366,4466.0
80.957684173,4199.0
81.007817980,4394.0
81.057951786,4345.0
81.108085593,4321.0
81.158219400,4296.0
81.208353207,4351.0
81.258487014,4439.0
81.308620821,4297.0
81.358754628,4445.0
81.408888435,4390.0
81.459022242,4273.0
81.509156049,4520.0
81.559289856,4439.0
81.609423663,4557.0
81.659557470,4523.0
81.709691277,4401.0
81.759825084,4601.0
81.809958891,4418.0
81.860092697,4274.0
81.910226504,4404.0
81.960360311,4481.0
82.010494118,4385.0
82.060627925,4466.0
82.110761732,4343.0
82.160895539,4412.0
82.211029346,4413.0
82.261163153,4412.0
82.311296960,4356.0
82.361430767,4396.0
82.411564574,4343.0
82.461698381,4479.0
82.511832188,4408.0
82.561965995,4440.0
82.612099802,4363.0
82.662233608,4415.0
82.712367415,4557.0
82.762501222,4326.0
82.812635029,4343.0
82.862768836,4464.0
82.912902643,4430.0
82.963036450,4324.0
83.013170257,4562.0
83.063304064,4409.0
83.113437871,4414.0
83.163571678,4427.0
83.213705485,4554.0
83.263839292,4464.0
83.313973099,4410.0
83.364106906,4558.0
83.414240713,4534.0
83.464374519,4361.0
83.514508326,4547.0
83.564642133,4443.0
83.614775940,4405.0
83.664909747,4457.0
83.715043554,4421.0
83.765177361,4400.0
83.815311168,4417.0
83.865444975,4442.0
83.915578782,4435.0
83.965712589,4495.0
84.015846396,4472.0
84.065980203,4506.0
84.116114010,4315.0
84.166247817,4673.0
84.216381624,4481.0
84.266515431,4345.0
84.316649237,4529.0
84.366783044,4417.0
84.416916851,4490.0
84.467050658,4519.0
84.517184465,4464.0
84.567318272,4368.0
84.617452079,4495.0
84.667585886,4384.0
84.717719693,4609.0
84.767853500,4459.0
84.817987307,4482.0
84.868121114,4569.0
84.918254921,4438.0
84.968388728,4472.0
85.018522535,4530.0
85.068656342,4628.0
85.118790148,4558.0
85.168923955,4508.0
85.219057762,4472.0
85.269191569,4420.0
85.319325376,4659.0
85.369459183,4524.0
85.419592990,4337.0
85.469726797,4443.0
85.519860604,4565.0
85.569994411,4524.0
85.620128218,4481.0
85.670262025,4627.0
85.720395832,4519.0
85.770529639,4510.0
85.820663446,4563.0
85.870797253,4283.0
85.920931059,4474.0
85.971064866,4543.0
86.021198673,4565.0
86.071332480,4685.0
86.121466287,4414.0
86.171600094,4426.0
86.221733901,4525.0
86.271867708,4502.0
86.322001515,4496.0
86.372135322,4581.0
86.422269129,4697.0
86.472402936,4426.0
86.522536743,4491.0
86.572670550,4455.0
86.622804357,4560.0
86.672938164,4455.0
86.723071970,4556.0
86.773205777,4441.0
86.823339584,4515.0
86.873473391,4588.0
86.923607198,4483.0
86.973741005,4573.0
87.023874812,4478.0
87.074008619,4538.0
87.124142426,4662.0
87.174276233,4631.0
87.224410040,4584.0
87.274543847,4648.0
87.324677654,4388.0
87.374811461,4563.0
87.424945268,4435.0
87.475079075,4537.0
87.525212881,4544.0
87.575346688,4648.0
87.625480495,4537.0
87.675614302,4550.0
87.725748109,4499.0
87.775881916,4431.0
87.826015723,4608.0
87.876149530,4486.0
87.926283337,4664.0
87.976417144,4476.0
88.026550951,4689.0
88.076684758,4564.0
88.126818565,4602.0
88.176952372,4535.0
88.227086179,4519.0
88.277219986,4490.0
88.327353792,4521.0
88.377487599,4507.0
88.427621406,4589.0
88.477755213,4590.0
88.527889020,4660.0
88.578022827,4701.0
88.628156634,4664.0
88.678290441,4634.0
88.728424248,4564.0
88.778558055,4713.0
88.828691862,4706.0
88.878825669,4809.0
88.928959476,5023.0
88.979093283,5978.0
89.029227090,7566.0
89.079360897,7796.0
89.129494703,7974.0
89.179628510,8397.0
89.229762317,7949.0
89.279896124,7434.0
89.330029931,7428.0
89.380163738,6864.0
89.430297545,6825.0
89.480431352,6696.0
89.530565159,6017.0
89.580698966,5686.0
89.630832773,5183.0
89.680966580,5040.0
89.731100387,4820.0
89.781234194,4717.0
89.831368001,4697.0
89.881501808,4691.0
89.931635614,4741.0
89.981769421,4572.0
90.031903228,4705.0
90.082037035,4617.0
90.132170842,4643.0
90.182304649,4625.0
90.232438456,4711.0
90.282572263,4566.0
90.332706070,4480.0
90.382839877,4522.0
90.432973684,4535.0
90.483107491,4596.0
90.533241298,4493.0
90.583375105,4705.0
90.633508912,4565.0
90.683642719,4506.0
90.733776525,4611.0
90.783910332,4593.0
90.834044139,4491.0
90.884177946,4687.0
90.934311753,4540.0
90.984445560,4552.0
91.034579367,4832.0
91.084713174,4563.0
91.134846981,4577.0
91.184980788,4594.0
91.235114595,4565.0
91.285248402,4675.0
91.335382209,4641.0
91.385516016,4654.0
91.435649823,4544.0
91.485783630,4617.0
91.535917436,4524.0
91.586051243,4575.0
91.636185050,4648.0
91.686318857,4666.0
91.736452664,4562.0
91.786586471,4645.0
91.836720278,4692.0
91.886854085,4625.0
91.936987892,4669.0
91.987121699,4650.0
92.037255506,4737.0
92.087389313,4718.0
92.137523120,4604.0
92.187656927,4545.0
92.237790734,4727.0
92.287924541,4553.0
92.338058347,4552.0
92.388192154,4628.0
92.438325961,4610.0
92.488459768,4665.0
92.538593575,4714.0
92.588727382,4395.0
92.638861189,4620.0
92.688994996,4582.0
92.739128803,4607.0
92.789262610,4588.0
92.839396417,4403.0
92.889530224,4659.0
92.939664031,4719.0
92.989797838,4592.0
93.039931645,4540.0
93.090065452,4489.0
93.140199258,4613.0
93.190333065,4596.0
93.240466872,4496.0
93.290600679,4573.0
93.340734486,4723.0
93.390868293,4650.0
93.441002100,4653.0
93.491135907,4709.0
93.541269714,4635.0
93.591403521,4673.0
93.641537328,4593.0
93.691671135,4685.0
93.741804942,4810.0
93.791938749,4706.0
93.842072556,4723.0
93.892206363,4736.0
93.942340170,4773.0
93.992473976,4938.0
94.042607783,5277.0
94.092741590,5920.0
94.142875397,8860.0
94.193009204,11053.0
94.243143011,9431.0
94.293276818,8669.0
94.343410625,8140.0
94.393544432,6818.0
94.443678239,7092.0
94.493812046,8190.0
94.543945853,7371.0
94.594079660,6917.0
94.644213467,6348.0
94.694347274,5656.0
94.744481081,5195.0
94.794614887,4942.0
94.844748694,4711.0
94.894882501,4709.0
94.945016308,4693.0
94.995150115,4629.0
95.045283922,4682.0
95.095417729,4555.0
95.145551536,4622.0
95.195685343,4662.0
95.245819150,4638.0
95.295952957,4718.0
95.346086764,4568.0
95.396220571,4591.0
95.446354378,4606.0
95.496488185,4519.0
95.546621992,4624.0
95.596755798,4666.0
95.646889605,4602.0
95.697023412,4603.0
95.747157219,4695.0
95.797291026,4697.0
95.847424833,4654.0
95.897558640,4499.0
95.947692447,4728.0
95.997826254,4562.0
96.047960061,4617.0
96.098093868,4595.0
96.148227675,4554.0
96.198361482,4487.0
96.248495289,4490.0
96.298629096,4629.0
96.348762903,4474.0
96.398896709,4668.0
96.449030516,4611.0
96.499164323,4561.0
96.549298130,4571.0
96.599431937,4509.0
96.649565744,4717.0
96.699699551,4613.0
96.749833358,4523.0
96.799967165,4488.0
96.850100972,4632.0
96.900234779,4615.0
96.950368586,4476.0
97.000502393,4647.0
97.050636200,4520.0
97.100770007,4603.0
97.150903814,4588.0
97.201037620,4493.0
97.251171427,4562.0
97.301305234,4438.0
97.351439041,4575.0
97.401572848,4524.0
97.451706655,4642.0
97.501840462,4704.0
97.551974269,4622.0
97.602108076,4594.0
97.652241883,4546.0
97.702375690,4567.0
97.752509497,4547.0
97.802643304,4408.0
97.852777111,4520.0
97.902910918,4620.0
97.953044725,4653.0
98.003178531,4515.0
98.053312338,4690.0
98.103446145,4525.0
98.153579952,4579.0
98.203713759,4531.0
98.253847566,4610.0
98.303981373,4521.0
98.354115180,4490.0
98.404248987,4568.0
98.454382794,4374.0
98.504516601,4574.0
98.554650408,4579.0
98.604784215,4544.0
98.654918022,4546.0
98.705051829,4570.0
98.755185636,4625.0
98.805319442,4624.0
98.855453249,4577.0
98.905587056,4570.0
98.955720863,4427.0
99.005854670,4642.0
99.055988477,4576.0
99.106122284,4527.0
99.156256091,4537.0
99.206389898,4539.0
99.256523705,4509.0
99.306657512,4565.0
99.356791319,4592.0
99.406925126,4532.0
99.457058933,4646.0
99.507192740,4566.0
99.557326547,4540.0
99.607460353,4388.0
99.657594160,4555.0
99.707727967,4497.0
99.757861774,4506.0
99.807995581,4516.0
99.858129388,4561.0
99.908263195,4607.0
99.958397002,4649.0
99.991819540,4608.0