File: OriginPro/XRD from Panalytical X'Pert PRO/Nova Cu foil/Cufoil_HTC.csv
[Measurement conditions]
Sample identification,
Comment - 1,"Configuration=MRI TC-Basic Stage, Owner=User-1, Creation date=26-10-2009 9:18:44"
Comment - 2,"Goniometer=PW3050/60 (Theta/Theta); Minimum step size 2Theta:0.001; Minimum step size Omega:0.001"
Comment - 3,"Sample stage=MRI TC-Basic (PtRh heat strip)"
Comment - 4,"Diffractometer system=XPERT-PRO"
Comment - 5,"Measurement program=FlatStage, Owner=joana, Creation date=03-08-2011 15:43:53"
Anode material,Cu
K-Alpha1 wavelength,1.5405980
K-Alpha2 wavelength,1.5444260
Ratio K-Alpha2/K-Alpha1,0.500
Divergence slit,Fixed,0.76mm
Monochromator used,NO
Generator voltage, 45
Tube current, 40
File date and time,06/Dec/2012 18:40
Unit cell,
h k l, 0 0 0
Temperature [K],302
Scan axis,Gonio
Scan range,29.999999996,95.023547594
Scan step size,0.0167113
No. of points, 3891
Scan type,CONTINUOUS
Time per step,19.685
[Scan points]
Angle,Intensity
30.008355630,1656.0
30.058489437,1711.0
30.108623244,1673.0
30.158757051,1633.0
30.208890858,1689.0
30.259024665,1622.0
30.309158472,1650.0
30.359292279,1689.0
30.409426086,1672.0
30.459559892,1670.0
30.509693699,1686.0
30.559827506,1607.0
30.609961313,1671.0
30.660095120,1645.0
30.710228927,1625.0
30.760362734,1681.0
30.810496541,1633.0
30.860630348,1688.0
30.910764155,1653.0
30.960897962,1631.0
31.011031769,1679.0
31.061165576,1635.0
31.111299383,1690.0
31.161433190,1571.0
31.211566997,1704.0
31.261700803,1633.0
31.311834610,1700.0
31.361968417,1607.0
31.412102224,1653.0
31.462236031,1584.0
31.512369838,1613.0
31.562503645,1734.0
31.612637452,1644.0
31.662771259,1676.0
31.712905066,1644.0
31.763038873,1618.0
31.813172680,1620.0
31.863306487,1685.0
31.913440294,1638.0
31.963574101,1670.0
32.013707908,1659.0
32.063841714,1665.0
32.113975521,1659.0
32.164109328,1628.0
32.214243135,1765.0
32.264376942,1678.0
32.314510749,1678.0
32.364644556,1645.0
32.414778363,1670.0
32.464912170,1669.0
32.515045977,1571.0
32.565179784,1684.0
32.615313591,1675.0
32.665447398,1641.0
32.715581205,1677.0
32.765715012,1658.0
32.815848819,1650.0
32.865982625,1646.0
32.916116432,1663.0
32.966250239,1643.0
33.016384046,1628.0
33.066517853,1594.0
33.116651660,1663.0
33.166785467,1621.0
33.216919274,1697.0
33.267053081,1635.0
33.317186888,1627.0
33.367320695,1624.0
33.417454502,1674.0
33.467588309,1661.0
33.517722116,1705.0
33.567855923,1634.0
33.617989730,1701.0
33.668123536,1636.0
33.718257343,1671.0
33.768391150,1637.0
33.818524957,1669.0
33.868658764,1656.0
33.918792571,1633.0
33.968926378,1673.0
34.019060185,1622.0
34.069193992,1659.0
34.119327799,1638.0
34.169461606,1637.0
34.219595413,1681.0
34.269729220,1626.0
34.319863027,1648.0
34.369996834,1656.0
34.420130641,1645.0
34.470264448,1644.0
34.520398254,1640.0
34.570532061,1601.0
34.620665868,1663.0
34.670799675,1662.0
34.720933482,1633.0
34.771067289,1635.0
34.821201096,1582.0
34.871334903,1638.0
34.921468710,1613.0
34.971602517,1657.0
35.021736324,1643.0
35.071870131,1622.0
35.122003938,1576.0
35.172137745,1677.0
35.222271552,1730.0
35.272405359,1652.0
35.322539165,1652.0
35.372672972,1683.0
35.422806779,1610.0
35.472940586,1687.0
35.523074393,1527.0
35.573208200,1673.0
35.623342007,1678.0
35.673475814,1614.0
35.723609621,1641.0
35.773743428,1734.0
35.823877235,1651.0
35.874011042,1619.0
35.924144849,1669.0
35.974278656,1686.0
36.024412463,1649.0
36.074546270,1618.0
36.124680076,1656.0
36.174813883,1663.0
36.224947690,1478.0
36.275081497,1586.0
36.325215304,1678.0
36.375349111,1652.0
36.425482918,1612.0
36.475616725,1636.0
36.525750532,1585.0
36.575884339,1669.0
36.626018146,1704.0
36.676151953,1612.0
36.726285760,1601.0
36.776419567,1647.0
36.826553374,1662.0
36.876687181,1662.0
36.926820987,1608.0
36.976954794,1742.0
37.027088601,1631.0
37.077222408,1662.0
37.127356215,1653.0
37.177490022,1613.0
37.227623829,1632.0
37.277757636,1711.0
37.327891443,1688.0
37.378025250,1594.0
37.428159057,1626.0
37.478292864,1613.0
37.528426671,1798.0
37.578560478,1647.0
37.628694285,1681.0
37.678828092,1749.0
37.728961898,1671.0
37.779095705,1736.0
37.829229512,1674.0
37.879363319,1626.0
37.929497126,1696.0
37.979630933,1661.0
38.029764740,1640.0
38.079898547,1641.0
38.130032354,1660.0
38.180166161,1694.0
38.230299968,1563.0
38.280433775,1733.0
38.330567582,1729.0
38.380701389,1643.0
38.430835196,1650.0
38.480969003,1652.0
38.531102810,1743.0
38.581236616,1664.0
38.631370423,1692.0
38.681504230,1742.0
38.731638037,1841.0
38.781771844,1992.0
38.831905651,1944.0
38.882039458,1748.0
38.932173265,1714.0
38.982307072,1694.0
39.032440879,1657.0
39.082574686,1734.0
39.132708493,1681.0
39.182842300,1670.0
39.232976107,1702.0
39.283109914,1698.0
39.333243721,1712.0
39.383377527,1759.0
39.433511334,1691.0
39.483645141,1646.0
39.533778948,1659.0
39.583912755,1764.0
39.634046562,1721.0
39.684180369,1776.0
39.734314176,1651.0
39.784447983,1672.0
39.834581790,1649.0
39.884715597,1592.0
39.934849404,1704.0
39.984983211,1622.0
40.035117018,1644.0
40.085250825,1679.0
40.135384632,1651.0
40.185518438,1639.0
40.235652245,1683.0
40.285786052,1596.0
40.335919859,1760.0
40.386053666,1653.0
40.436187473,1714.0
40.486321280,1624.0
40.536455087,1641.0
40.586588894,1677.0
40.636722701,1648.0
40.686856508,1684.0
40.736990315,1666.0
40.787124122,1568.0
40.837257929,1643.0
40.887391736,1761.0
40.937525543,1705.0
40.987659349,1771.0
41.037793156,1672.0
41.087926963,1696.0
41.138060770,1684.0
41.188194577,1684.0
41.238328384,1718.0
41.288462191,1705.0
41.338595998,1736.0
41.388729805,1729.0
41.438863612,1652.0
41.488997419,1718.0
41.539131226,1608.0
41.589265033,1870.0
41.639398840,2021.0
41.689532647,2005.0
41.739666454,2040.0
41.789800261,2071.0
41.839934067,2080.0
41.890067874,2104.0
41.940201681,1967.0
41.990335488,2007.0
42.040469295,2006.0
42.090603102,2040.0
42.140736909,1976.0
42.190870716,2093.0
42.241004523,2205.0
42.291138330,2175.0
42.341272137,2063.0
42.391405944,2074.0
42.441539751,2161.0
42.491673558,2046.0
42.541807365,2117.0
42.591941172,2181.0
42.642074978,2325.0
42.692208785,2257.0
42.742342592,2439.0
42.792476399,2700.0
42.842610206,3409.0
42.892744013,4317.0
42.942877820,5815.0
42.993011627,7485.0
43.043145434,12195.0
43.093279241,34166.0
43.143413048,137945.0
43.193546855,89378.0
43.243680662,57769.0
43.293814469,69059.0
43.343948276,12299.0
43.394082083,6005.0
43.444215889,4343.0
43.494349696,3440.0
43.544483503,2859.0
43.594617310,2567.0
43.644751117,2490.0
43.694884924,2346.0
43.745018731,2229.0
43.795152538,2185.0
43.845286345,2078.0
43.895420152,2172.0
43.945553959,2089.0
43.995687766,2032.0
44.045821573,2039.0
44.095955380,2000.0
44.146089187,2003.0
44.196222994,1924.0
44.246356800,1963.0
44.296490607,2072.0
44.346624414,1893.0
44.396758221,1891.0
44.446892028,1977.0
44.497025835,1899.0
44.547159642,1984.0
44.597293449,1860.0
44.647427256,1966.0
44.697561063,1900.0
44.747694870,1941.0
44.797828677,1958.0
44.847962484,1858.0
44.898096291,1898.0
44.948230098,1889.0
44.998363905,1847.0
45.048497711,2012.0
45.098631518,2026.0
45.148765325,2162.0
45.198899132,2012.0
45.249032939,1862.0
45.299166746,1907.0
45.349300553,1930.0
45.399434360,1941.0
45.449568167,1824.0
45.499701974,1845.0
45.549835781,1877.0
45.599969588,1810.0
45.650103395,1758.0
45.700237202,1877.0
45.750371009,1854.0
45.800504816,1797.0
45.850638623,1823.0
45.900772429,1792.0
45.950906236,1888.0
46.001040043,1787.0
46.051173850,1768.0
46.101307657,1790.0
46.151441464,1774.0
46.201575271,1787.0
46.251709078,1834.0
46.301842885,1834.0
46.351976692,1836.0
46.402110499,1852.0
46.452244306,1847.0
46.502378113,1862.0
46.552511920,1981.0
46.602645727,1772.0
46.652779534,1882.0
46.702913340,1873.0
46.753047147,1783.0
46.803180954,1828.0
46.853314761,1961.0
46.903448568,2023.0
46.953582375,1963.0
47.003716182,1965.0
47.053849989,1781.0
47.103983796,1803.0
47.154117603,1787.0
47.204251410,1829.0
47.254385217,1805.0
47.304519024,1764.0
47.354652831,1827.0
47.404786638,1770.0
47.454920445,1789.0
47.505054251,1737.0
47.555188058,1814.0
47.605321865,1784.0
47.655455672,1878.0
47.705589479,1749.0
47.755723286,1725.0
47.805857093,1745.0
47.855990900,1767.0
47.906124707,1742.0
47.956258514,1765.0
48.006392321,1728.0
48.056526128,1796.0
48.106659935,1739.0
48.156793742,1847.0
48.206927549,1777.0
48.257061356,1722.0
48.307195162,1831.0
48.357328969,1829.0
48.407462776,1836.0
48.457596583,1916.0
48.507730390,1969.0
48.557864197,1950.0
48.607998004,1993.0
48.658131811,1939.0
48.708265618,1970.0
48.758399425,1921.0
48.808533232,1963.0
48.858667039,1914.0
48.908800846,1996.0
48.958934653,1994.0
49.009068460,1981.0
49.059202267,2059.0
49.109336073,2078.0
49.159469880,2032.0
49.209603687,2051.0
49.259737494,1963.0
49.309871301,2010.0
49.360005108,2079.0
49.410138915,2085.0
49.460272722,2092.0
49.510406529,2012.0
49.560540336,2095.0
49.610674143,2118.0
49.660807950,2125.0
49.710941757,2182.0
49.761075564,2276.0
49.811209371,2268.0
49.861343178,2519.0
49.911476985,2598.0
49.961610791,3156.0
50.011744598,4266.0
50.061878405,5457.0
50.112012212,6460.0
50.162146019,9527.0
50.212279826,22007.0
50.262413633,76826.0
50.312547440,117648.0
50.362681247,37238.0
50.412815054,61205.0
50.462948861,42294.0
50.513082668,10732.0
50.563216475,5722.0
50.613350282,3984.0
50.663484089,3265.0
50.713617896,2787.0
50.763751702,2563.0
50.813885509,2430.0
50.864019316,2212.0
50.914153123,2224.0
50.964286930,2115.0
51.014420737,2079.0
51.064554544,2063.0
51.114688351,2021.0
51.164822158,1977.0
51.214955965,1923.0
51.265089772,1970.0
51.315223579,1964.0
51.365357386,1908.0
51.415491193,1900.0
51.465625000,1929.0
51.515758807,1927.0
51.565892613,1854.0
51.616026420,1908.0
51.666160227,1883.0
51.716294034,1872.0
51.766427841,1864.0
51.816561648,1855.0
51.866695455,1856.0
51.916829262,1832.0
51.966963069,1830.0
52.017096876,1848.0
52.067230683,1765.0
52.117364490,1847.0
52.167498297,1825.0
52.217632104,1742.0
52.267765911,1847.0
52.317899718,1852.0
52.368033524,1771.0
52.418167331,1850.0
52.468301138,1783.0
52.518434945,1807.0
52.568568752,1837.0
52.618702559,1790.0
52.668836366,1805.0
52.718970173,1816.0
52.769103980,1771.0
52.819237787,1842.0
52.869371594,1806.0
52.919505401,1787.0
52.969639208,1805.0
53.019773015,1750.0
53.069906822,1834.0
53.120040629,1794.0
53.170174435,1825.0
53.220308242,1727.0
53.270442049,1799.0
53.320575856,1783.0
53.370709663,1678.0
53.420843470,1715.0
53.470977277,1624.0
53.521111084,1703.0
53.571244891,1766.0
53.621378698,1742.0
53.671512505,1775.0
53.721646312,1717.0
53.771780119,1759.0
53.821913926,1746.0
53.872047733,1776.0
53.922181540,1738.0
53.972315347,1689.0
54.022449153,1738.0
54.072582960,1721.0
54.122716767,1732.0
54.172850574,1778.0
54.222984381,1681.0
54.273118188,1718.0
54.323251995,1714.0
54.373385802,1778.0
54.423519609,1721.0
54.473653416,1750.0
54.523787223,1834.0
54.573921030,1770.0
54.624054837,1759.0
54.674188644,1881.0
54.724322451,1799.0
54.774456258,1708.0
54.824590064,1832.0
54.874723871,1777.0
54.924857678,1632.0
54.974991485,1735.0
55.025125292,1701.0
55.075259099,1685.0
55.125392906,1720.0
55.175526713,1743.0
55.225660520,1678.0
55.275794327,1671.0
55.325928134,1656.0
55.376061941,1625.0
55.426195748,1644.0
55.476329555,1742.0
55.526463362,1669.0
55.576597169,1718.0
55.626730975,1638.0
55.676864782,1720.0
55.726998589,1665.0
55.777132396,1732.0
55.827266203,1677.0
55.877400010,1631.0
55.927533817,1660.0
55.977667624,1558.0
56.027801431,1694.0
56.077935238,1689.0
56.128069045,1692.0
56.178202852,1667.0
56.228336659,1599.0
56.278470466,1676.0
56.328604273,1624.0
56.378738080,1729.0
56.428871886,1605.0
56.479005693,1691.0
56.529139500,1594.0
56.579273307,1712.0
56.629407114,1751.0
56.679540921,1765.0
56.729674728,1741.0
56.779808535,1678.0
56.829942342,1695.0
56.880076149,1685.0
56.930209956,1713.0
56.980343763,1628.0
57.030477570,1699.0
57.080611377,1703.0
57.130745184,1592.0
57.180878991,1726.0
57.231012797,1570.0
57.281146604,1699.0
57.331280411,1705.0
57.381414218,1625.0
57.431548025,1677.0
57.481681832,1615.0
57.531815639,1599.0
57.581949446,1648.0
57.632083253,1659.0
57.682217060,1628.0
57.732350867,1641.0
57.782484674,1590.0
57.832618481,1646.0
57.882752288,1613.0
57.932886095,1692.0
57.983019902,1662.0
58.033153709,1670.0
58.083287515,1692.0
58.133421322,1640.0
58.183555129,1663.0
58.233688936,1648.0
58.283822743,1721.0
58.333956550,1658.0
58.384090357,1613.0
58.434224164,1630.0
58.484357971,1637.0
58.534491778,1712.0
58.584625585,1678.0
58.634759392,1681.0
58.684893199,1600.0
58.735027006,1623.0
58.785160813,1707.0
58.835294620,1609.0
58.885428426,1633.0
58.935562233,1659.0
58.985696040,1718.0
59.035829847,1616.0
59.085963654,1681.0
59.136097461,1669.0
59.186231268,1639.0
59.236365075,1682.0
59.286498882,1633.0
59.336632689,1634.0
59.386766496,1669.0
59.436900303,1660.0
59.487034110,1641.0
59.537167917,1621.0
59.587301724,1702.0
59.637435531,1612.0
59.687569337,1663.0
59.737703144,1603.0
59.787836951,1644.0
59.837970758,1726.0
59.888104565,1712.0
59.938238372,1600.0
59.988372179,1652.0
60.038505986,1677.0
60.088639793,1567.0
60.138773600,1664.0
60.188907407,1643.0
60.239041214,1627.0
60.289175021,1673.0
60.339308828,1695.0
60.389442635,1594.0
60.439576442,1696.0
60.489710248,1645.0
60.539844055,1624.0
60.589977862,1653.0
60.640111669,1577.0
60.690245476,1628.0
60.740379283,1641.0
60.790513090,1647.0
60.840646897,1632.0
60.890780704,1635.0
60.940914511,1623.0
60.991048318,1592.0
61.041182125,1600.0
61.091315932,1603.0
61.141449739,1623.0
61.191583546,1592.0
61.241717353,1664.0
61.291851160,1527.0
61.341984966,1575.0
61.392118773,1582.0
61.442252580,1543.0
61.492386387,1733.0
61.542520194,1639.0
61.592654001,1610.0
61.642787808,1667.0
61.692921615,1556.0
61.743055422,1598.0
61.793189229,1530.0
61.843323036,1640.0
61.893456843,1651.0
61.943590650,1602.0
61.993724457,1586.0
62.043858264,1634.0
62.093992071,1623.0
62.144125877,1638.0
62.194259684,1586.0
62.244393491,1702.0
62.294527298,1599.0
62.344661105,1555.0
62.394794912,1639.0
62.444928719,1613.0
62.495062526,1576.0
62.545196333,1550.0
62.595330140,1524.0
62.645463947,1583.0
62.695597754,1659.0
62.745731561,1631.0
62.795865368,1659.0
62.845999175,1634.0
62.896132982,1650.0
62.946266788,1684.0
62.996400595,1577.0
63.046534402,1606.0
63.096668209,1593.0
63.146802016,1565.0
63.196935823,1615.0
63.247069630,1650.0
63.297203437,1640.0
63.347337244,1551.0
63.397471051,1691.0
63.447604858,1499.0
63.497738665,1559.0
63.547872472,1582.0
63.598006279,1649.0
63.648140086,1665.0
63.698273893,1596.0
63.748407699,1663.0
63.798541506,1610.0
63.848675313,1576.0
63.898809120,1621.0
63.948942927,1709.0
63.999076734,1632.0
64.049210541,1653.0
64.099344348,1659.0
64.149478155,1544.0
64.199611962,1582.0
64.249745769,1587.0
64.299879576,1712.0
64.350013383,1696.0
64.400147190,1610.0
64.450280997,1626.0
64.500414804,1582.0
64.550548610,1627.0
64.600682417,1609.0
64.650816224,1618.0
64.700950031,1657.0
64.751083838,1552.0
64.801217645,1626.0
64.851351452,1623.0
64.901485259,1640.0
64.951619066,1631.0
65.001752873,1589.0
65.051886680,1652.0
65.102020487,1610.0
65.152154294,1630.0
65.202288101,1529.0
65.252421908,1664.0
65.302555715,1595.0
65.352689522,1573.0
65.402823328,1608.0
65.452957135,1589.0
65.503090942,1570.0
65.553224749,1621.0
65.603358556,1575.0
65.653492363,1633.0
65.703626170,1659.0
65.753759977,1547.0
65.803893784,1679.0
65.854027591,1651.0
65.904161398,1702.0
65.954295205,1594.0
66.004429012,1569.0
66.054562819,1634.0
66.104696626,1640.0
66.154830433,1675.0
66.204964239,1547.0
66.255098046,1611.0
66.305231853,1671.0
66.355365660,1687.0
66.405499467,1618.0
66.455633274,1562.0
66.505767081,1505.0
66.555900888,1606.0
66.606034695,1624.0
66.656168502,1595.0
66.706302309,1622.0
66.756436116,1653.0
66.806569923,1551.0
66.856703730,1609.0
66.906837537,1682.0
66.956971344,1585.0
67.007105150,1618.0
67.057238957,1650.0
67.107372764,1622.0
67.157506571,1562.0
67.207640378,1577.0
67.257774185,1538.0
67.307907992,1565.0
67.358041799,1662.0
67.408175606,1592.0
67.458309413,1605.0
67.508443220,1649.0
67.558577027,1633.0
67.608710834,1657.0
67.658844641,1647.0
67.708978448,1661.0
67.759112255,1512.0
67.809246061,1584.0
67.859379868,1639.0
67.909513675,1606.0
67.959647482,1723.0
68.009781289,1748.0
68.059915096,1729.0
68.110048903,1643.0
68.160182710,1657.0
68.210316517,1690.0
68.260450324,1692.0
68.310584131,1627.0
68.360717938,1656.0
68.410851745,1583.0
68.460985552,1561.0
68.511119359,1597.0
68.561253166,1599.0
68.611386972,1598.0
68.661520779,1580.0
68.711654586,1590.0
68.761788393,1673.0
68.811922200,1640.0
68.862056007,1643.0
68.912189814,1624.0
68.962323621,1620.0
69.012457428,1632.0
69.062591235,1599.0
69.112725042,1618.0
69.162858849,1666.0
69.212992656,1576.0
69.263126463,1590.0
69.313260270,1602.0
69.363394077,1627.0
69.413527884,1581.0
69.463661690,1597.0
69.513795497,1670.0
69.563929304,1664.0
69.614063111,1606.0
69.664196918,1630.0
69.714330725,1639.0
69.764464532,1666.0
69.814598339,1565.0
69.864732146,1692.0
69.914865953,1713.0
69.964999760,1619.0
70.015133567,1621.0
70.065267374,1659.0
70.115401181,1606.0
70.165534988,1606.0
70.215668795,1644.0
70.265802601,1636.0
70.315936408,1552.0
70.366070215,1592.0
70.416204022,1634.0
70.466337829,1667.0
70.516471636,1607.0
70.566605443,1624.0
70.616739250,1579.0
70.666873057,1568.0
70.717006864,1662.0
70.767140671,1567.0
70.817274478,1571.0
70.867408285,1661.0
70.917542092,1577.0
70.967675899,1606.0
71.017809706,1692.0
71.067943512,1656.0
71.118077319,1626.0
71.168211126,1671.0
71.218344933,1709.0
71.268478740,1659.0
71.318612547,1646.0
71.368746354,1555.0
71.418880161,1692.0
71.469013968,1647.0
71.519147775,1710.0
71.569281582,1635.0
71.619415389,1669.0
71.669549196,1597.0
71.719683003,1626.0
71.769816810,1637.0
71.819950617,1598.0
71.870084423,1597.0
71.920218230,1593.0
71.970352037,1663.0
72.020485844,1661.0
72.070619651,1638.0
72.120753458,1670.0
72.170887265,1698.0
72.221021072,1718.0
72.271154879,1563.0
72.321288686,1694.0
72.371422493,1627.0
72.421556300,1574.0
72.471690107,1626.0
72.521823914,1603.0
72.571957721,1659.0
72.622091528,1727.0
72.672225334,1602.0
72.722359141,1713.0
72.772492948,1682.0
72.822626755,1659.0
72.872760562,1635.0
72.922894369,1611.0
72.973028176,1587.0
73.023161983,1596.0
73.073295790,1699.0
73.123429597,1688.0
73.173563404,1724.0
73.223697211,1721.0
73.273831018,1716.0
73.323964825,1622.0
73.374098632,1715.0
73.424232439,1738.0
73.474366246,1737.0
73.524500052,1816.0
73.574633859,1855.0
73.624767666,2003.0
73.674901473,2079.0
73.725035280,2192.0
73.775169087,2306.0
73.825302894,2651.0
73.875436701,3644.0
73.925570508,7470.0
73.975704315,21970.0
74.025838122,16432.0
74.075971929,5923.0
74.126105736,4835.0
74.176239543,9714.0
74.226373350,11812.0
74.276507157,4665.0
74.326640963,2672.0
74.376774770,2243.0
74.426908577,2017.0
74.477042384,1985.0
74.527176191,1825.0
74.577309998,1817.0
74.627443805,1728.0
74.677577612,1670.0
74.727711419,1778.0
74.777845226,1674.0
74.827979033,1733.0
74.878112840,1716.0
74.928246647,1674.0
74.978380454,1774.0
75.028514261,1691.0
75.078648068,1746.0
75.128781874,1696.0
75.178915681,1676.0
75.229049488,1657.0
75.279183295,1657.0
75.329317102,1633.0
75.379450909,1729.0
75.429584716,1634.0
75.479718523,1634.0
75.529852330,1652.0
75.579986137,1660.0
75.630119944,1627.0
75.680253751,1618.0
75.730387558,1679.0
75.780521365,1675.0
75.830655172,1623.0
75.880788979,1646.0
75.930922785,1644.0
75.981056592,1699.0
76.031190399,1646.0
76.081324206,1633.0
76.131458013,1697.0
76.181591820,1613.0
76.231725627,1685.0
76.281859434,1562.0
76.331993241,1686.0
76.382127048,1586.0
76.432260855,1627.0
76.482394662,1664.0
76.532528469,1674.0
76.582662276,1579.0
76.632796083,1597.0
76.682929890,1605.0
76.733063696,1705.0
76.783197503,1653.0
76.833331310,1720.0
76.883465117,1634.0
76.933598924,1614.0
76.983732731,1674.0
77.033866538,1624.0
77.084000345,1534.0
77.134134152,1613.0
77.184267959,1533.0
77.234401766,1686.0
77.284535573,1641.0
77.334669380,1571.0
77.384803187,1656.0
77.434936994,1663.0
77.485070801,1644.0
77.535204608,1745.0
77.585338414,1652.0
77.635472221,1626.0
77.685606028,1624.0
77.735739835,1652.0
77.785873642,1619.0
77.836007449,1561.0
77.886141256,1664.0
77.936275063,1609.0
77.986408870,1623.0
78.036542677,1643.0
78.086676484,1625.0
78.136810291,1609.0
78.186944098,1623.0
78.237077905,1653.0
78.287211712,1623.0
78.337345519,1592.0
78.387479325,1610.0
78.437613132,1705.0
78.487746939,1618.0
78.537880746,1678.0
78.588014553,1683.0
78.638148360,1625.0
78.688282167,1662.0
78.738415974,1632.0
78.788549781,1633.0
78.838683588,1618.0
78.888817395,1584.0
78.938951202,1673.0
78.989085009,1656.0
79.039218816,1608.0
79.089352623,1638.0
79.139486430,1638.0
79.189620236,1609.0
79.239754043,1614.0
79.289887850,1616.0
79.340021657,1576.0
79.390155464,1607.0
79.440289271,1635.0
79.490423078,1624.0
79.540556885,1574.0
79.590690692,1561.0
79.640824499,1626.0
79.690958306,1605.0
79.741092113,1587.0
79.791225920,1666.0
79.841359727,1582.0
79.891493534,1587.0
79.941627341,1580.0
79.991761147,1633.0
80.041894954,1622.0
80.092028761,1572.0
80.142162568,1662.0
80.192296375,1570.0
80.242430182,1573.0
80.292563989,1675.0
80.342697796,1665.0
80.392831603,1622.0
80.442965410,1616.0
80.493099217,1542.0
80.543233024,1567.0
80.593366831,1561.0
80.643500638,1572.0
80.693634445,1635.0
80.743768252,1663.0
80.793902059,1664.0
80.844035865,1607.0
80.894169672,1654.0
80.944303479,1643.0
80.994437286,1639.0
81.044571093,1650.0
81.094704900,1660.0
81.144838707,1624.0
81.194972514,1667.0
81.245106321,1675.0
81.295240128,1610.0
81.345373935,1616.0
81.395507742,1620.0
81.445641549,1716.0
81.495775356,1610.0
81.545909163,1640.0
81.596042970,1573.0
81.646176776,1619.0
81.696310583,1631.0
81.746444390,1592.0
81.796578197,1608.0
81.846712004,1558.0
81.896845811,1587.0
81.946979618,1593.0
81.997113425,1645.0
82.047247232,1624.0
82.097381039,1652.0
82.147514846,1636.0
82.197648653,1607.0
82.247782460,1672.0
82.297916267,1650.0
82.348050074,1685.0
82.398183881,1610.0
82.448317687,1725.0
82.498451494,1569.0
82.548585301,1627.0
82.598719108,1588.0
82.648852915,1467.0
82.698986722,1533.0
82.749120529,1585.0
82.799254336,1596.0
82.849388143,1594.0
82.899521950,1615.0
82.949655757,1640.0
82.999789564,1608.0
83.049923371,1572.0
83.100057178,1603.0
83.150190985,1569.0
83.200324792,1607.0
83.250458598,1644.0
83.300592405,1554.0
83.350726212,1622.0
83.400860019,1580.0
83.450993826,1636.0
83.501127633,1625.0
83.551261440,1661.0
83.601395247,1606.0
83.651529054,1571.0
83.701662861,1605.0
83.751796668,1559.0
83.801930475,1630.0
83.852064282,1548.0
83.902198089,1648.0
83.952331896,1664.0
84.002465703,1644.0
84.052599509,1637.0
84.102733316,1598.0
84.152867123,1557.0
84.203000930,1575.0
84.253134737,1619.0
84.303268544,1611.0
84.353402351,1702.0
84.403536158,1594.0
84.453669965,1624.0
84.503803772,1603.0
84.553937579,1523.0
84.604071386,1579.0
84.654205193,1627.0
84.704339000,1603.0
84.754472807,1597.0
84.804606614,1661.0
84.854740421,1574.0
84.904874227,1581.0
84.955008034,1570.0
85.005141841,1610.0
85.055275648,1630.0
85.105409455,1670.0
85.155543262,1621.0
85.205677069,1676.0
85.255810876,1632.0
85.305944683,1638.0
85.356078490,1638.0
85.406212297,1669.0
85.456346104,1704.0
85.506479911,1607.0
85.556613718,1621.0
85.606747525,1580.0
85.656881332,1622.0
85.707015138,1652.0
85.757148945,1542.0
85.807282752,1537.0
85.857416559,1545.0
85.907550366,1639.0
85.957684173,1596.0
86.007817980,1657.0
86.057951787,1586.0
86.108085594,1584.0
86.158219401,1576.0
86.208353208,1683.0
86.258487015,1621.0
86.308620822,1669.0
86.358754629,1635.0
86.408888436,1567.0
86.459022243,1672.0
86.509156049,1689.0
86.559289856,1644.0
86.609423663,1605.0
86.659557470,1619.0
86.709691277,1667.0
86.759825084,1571.0
86.809958891,1587.0
86.860092698,1582.0
86.910226505,1672.0
86.960360312,1590.0
87.010494119,1648.0
87.060627926,1675.0
87.110761733,1623.0
87.160895540,1584.0
87.211029347,1635.0
87.261163154,1582.0
87.311296960,1581.0
87.361430767,1683.0
87.411564574,1541.0
87.461698381,1613.0
87.511832188,1616.0
87.561965995,1645.0
87.612099802,1603.0
87.662233609,1670.0
87.712367416,1626.0
87.762501223,1606.0
87.812635030,1601.0
87.862768837,1610.0
87.912902644,1635.0
87.963036451,1545.0
88.013170258,1623.0
88.063304065,1665.0
88.113437871,1647.0
88.163571678,1639.0
88.213705485,1586.0
88.263839292,1569.0
88.313973099,1607.0
88.364106906,1678.0
88.414240713,1682.0
88.464374520,1674.0
88.514508327,1557.0
88.564642134,1700.0
88.614775941,1614.0
88.664909748,1664.0
88.715043555,1722.0
88.765177362,1700.0
88.815311169,1607.0
88.865444976,1623.0
88.915578783,1632.0
88.965712589,1653.0
89.015846396,1709.0
89.065980203,1621.0
89.116114010,1676.0
89.166247817,1701.0
89.216381624,1727.0
89.266515431,1695.0
89.316649238,1687.0
89.366783045,1771.0
89.416916852,1685.0
89.467050659,1812.0
89.517184466,1805.0
89.567318273,1942.0
89.617452080,2016.0
89.667585887,2269.0
89.717719694,3174.0
89.767853500,5494.0
89.817987307,8685.0
89.868121114,5655.0
89.918254921,3251.0
89.968388728,2651.0
90.018522535,2949.0
90.068656342,4210.0
90.118790149,5018.0
90.168923956,3197.0
90.219057763,2267.0
90.269191570,2007.0
90.319325377,1831.0
90.369459184,1786.0
90.419592991,1800.0
90.469726798,1607.0
90.519860605,1687.0
90.569994411,1707.0
90.620128218,1643.0
90.670262025,1605.0
90.720395832,1691.0
90.770529639,1661.0
90.820663446,1647.0
90.870797253,1663.0
90.920931060,1685.0
90.971064867,1730.0
91.021198674,1615.0
91.071332481,1615.0
91.121466288,1587.0
91.171600095,1619.0
91.221733902,1723.0
91.271867709,1656.0
91.322001516,1644.0
91.372135322,1674.0
91.422269129,1643.0
91.472402936,1643.0
91.522536743,1622.0
91.572670550,1644.0
91.622804357,1647.0
91.672938164,1639.0
91.723071971,1677.0
91.773205778,1507.0
91.823339585,1688.0
91.873473392,1596.0
91.923607199,1708.0
91.973741006,1704.0
92.023874813,1690.0
92.074008620,1600.0
92.124142427,1692.0
92.174276233,1638.0
92.224410040,1692.0
92.274543847,1641.0
92.324677654,1671.0
92.374811461,1671.0
92.424945268,1648.0
92.475079075,1695.0
92.525212882,1654.0
92.575346689,1577.0
92.625480496,1627.0
92.675614303,1601.0
92.725748110,1679.0
92.775881917,1671.0
92.826015724,1732.0
92.876149531,1626.0
92.926283338,1670.0
92.976417145,1686.0
93.026550951,1565.0
93.076684758,1671.0
93.126818565,1626.0
93.176952372,1650.0
93.227086179,1614.0
93.277219986,1622.0
93.327353793,1607.0
93.377487600,1571.0
93.427621407,1635.0
93.477755214,1643.0
93.527889021,1677.0
93.578022828,1575.0
93.628156635,1580.0
93.678290442,1633.0
93.728424249,1585.0
93.778558056,1748.0
93.828691862,1571.0
93.878825669,1597.0
93.928959476,1600.0
93.979093283,1639.0
94.029227090,1650.0
94.079360897,1603.0
94.129494704,1711.0
94.179628511,1648.0
94.229762318,1720.0
94.279896125,1708.0
94.330029932,1748.0
94.380163739,1625.0
94.430297546,1679.0
94.480431353,1749.0
94.530565160,1696.0
94.580698967,1671.0
94.630832773,1767.0
94.680966580,1802.0
94.731100387,1818.0
94.781234194,1893.0
94.831368001,2030.0
94.881501808,2132.0
94.931635615,2673.0
94.981769422,4882.0
95.015191960,8367.0