File: OriginPro/XRD from Panalytical X'Pert PRO/Nova Cu foil/Cufoil_100°C.csv
[Measurement conditions]
Sample identification,
Comment - 1,"finito"
Comment - 2,"Configuration=MRI TC-Basic Stage, Owner=User-1, Creation date=26-10-2009 9:18:44"
Comment - 3,"Goniometer=PW3050/60 (Theta/Theta); Minimum step size 2Theta:0.001; Minimum step size Omega:0.001"
Comment - 4,"Sample stage=MRI TC-Basic (PtRh heat strip)"
Comment - 5,"Diffractometer system=XPERT-PRO"
Comment - 6,"Measurement program=FlatStage, Owner=joana, Creation date=03-08-2011 15:43:53"
Anode material,Cu
K-Alpha1 wavelength,1.5405980
K-Alpha2 wavelength,1.5444260
Ratio K-Alpha2/K-Alpha1,0.500
Divergence slit,Fixed,0.76mm
Monochromator used,NO
Generator voltage, 45
Tube current, 40
File date and time,06/Dec/2012 20:08
Unit cell,
h k l, 0 0 0
Temperature [K],373
Scan axis,Gonio
Scan range,24.999999996,100.000175174
Scan step size,0.0167113
No. of points, 4488
Scan type,CONTINUOUS
Time per step,53.340
[Scan points]
Angle,Intensity
25.008355630,4565.0
25.058489437,4563.0
25.108623244,4440.0
25.158757051,4670.0
25.208890858,4537.0
25.259024665,4653.0
25.309158472,4658.0
25.359292279,4617.0
25.409426086,4671.0
25.459559892,4550.0
25.509693699,4673.0
25.559827506,4567.0
25.609961313,4681.0
25.660095120,4609.0
25.710228927,4604.0
25.760362734,4629.0
25.810496541,4571.0
25.860630348,4525.0
25.910764155,4495.0
25.960897962,4674.0
26.011031769,4539.0
26.061165576,4480.0
26.111299383,4468.0
26.161433190,4511.0
26.211566997,4560.0
26.261700803,4645.0
26.311834610,4590.0
26.361968417,4563.0
26.412102224,4514.0
26.462236031,4411.0
26.512369838,4545.0
26.562503645,4640.0
26.612637452,4592.0
26.662771259,4595.0
26.712905066,4672.0
26.763038873,4493.0
26.813172680,4544.0
26.863306487,4465.0
26.913440294,4545.0
26.963574101,4521.0
27.013707908,4507.0
27.063841714,4609.0
27.113975521,4473.0
27.164109328,4517.0
27.214243135,4651.0
27.264376942,4576.0
27.314510749,4500.0
27.364644556,4397.0
27.414778363,4565.0
27.464912170,4452.0
27.515045977,4543.0
27.565179784,4478.0
27.615313591,4479.0
27.665447398,4411.0
27.715581205,4462.0
27.765715012,4582.0
27.815848819,4513.0
27.865982625,4496.0
27.916116432,4563.0
27.966250239,4497.0
28.016384046,4592.0
28.066517853,4472.0
28.116651660,4577.0
28.166785467,4529.0
28.216919274,4638.0
28.267053081,4654.0
28.317186888,4403.0
28.367320695,4535.0
28.417454502,4486.0
28.467588309,4460.0
28.517722116,4528.0
28.567855923,4404.0
28.617989730,4578.0
28.668123536,4438.0
28.718257343,4537.0
28.768391150,4427.0
28.818524957,4569.0
28.868658764,4553.0
28.918792571,4687.0
28.968926378,4510.0
29.019060185,4497.0
29.069193992,4454.0
29.119327799,4530.0
29.169461606,4545.0
29.219595413,4535.0
29.269729220,4506.0
29.319863027,4495.0
29.369996834,4556.0
29.420130641,4572.0
29.470264447,4493.0
29.520398254,4539.0
29.570532061,4459.0
29.620665868,4500.0
29.670799675,4529.0
29.720933482,4437.0
29.771067289,4458.0
29.821201096,4414.0
29.871334903,4391.0
29.921468710,4479.0
29.971602517,4487.0
30.021736324,4474.0
30.071870131,4499.0
30.122003938,4535.0
30.172137745,4462.0
30.222271552,4472.0
30.272405358,4490.0
30.322539165,4479.0
30.372672972,4379.0
30.422806779,4483.0
30.472940586,4465.0
30.523074393,4517.0
30.573208200,4503.0
30.623342007,4395.0
30.673475814,4630.0
30.723609621,4397.0
30.773743428,4449.0
30.823877235,4436.0
30.874011042,4638.0
30.924144849,4387.0
30.974278656,4536.0
31.024412463,4470.0
31.074546269,4483.0
31.124680076,4634.0
31.174813883,4438.0
31.224947690,4427.0
31.275081497,4466.0
31.325215304,4397.0
31.375349111,4523.0
31.425482918,4476.0
31.475616725,4480.0
31.525750532,4460.0
31.575884339,4423.0
31.626018146,4388.0
31.676151953,4530.0
31.726285760,4389.0
31.776419567,4456.0
31.826553374,4494.0
31.876687180,4354.0
31.926820987,4468.0
31.976954794,4386.0
32.027088601,4506.0
32.077222408,4411.0
32.127356215,4459.0
32.177490022,4504.0
32.227623829,4579.0
32.277757636,4441.0
32.327891443,4411.0
32.378025250,4416.0
32.428159057,4436.0
32.478292864,4384.0
32.528426671,4436.0
32.578560478,4537.0
32.628694285,4451.0
32.678828091,4446.0
32.728961898,4443.0
32.779095705,4481.0
32.829229512,4405.0
32.879363319,4444.0
32.929497126,4613.0
32.979630933,4425.0
33.029764740,4546.0
33.079898547,4390.0
33.130032354,4379.0
33.180166161,4555.0
33.230299968,4306.0
33.280433775,4409.0
33.330567582,4428.0
33.380701389,4489.0
33.430835196,4360.0
33.480969002,4207.0
33.531102809,4417.0
33.581236616,4442.0
33.631370423,4522.0
33.681504230,4462.0
33.731638037,4470.0
33.781771844,4291.0
33.831905651,4415.0
33.882039458,4471.0
33.932173265,4520.0
33.982307072,4320.0
34.032440879,4516.0
34.082574686,4569.0
34.132708493,4440.0
34.182842300,4420.0
34.232976107,4551.0
34.283109913,4374.0
34.333243720,4514.0
34.383377527,4388.0
34.433511334,4439.0
34.483645141,4616.0
34.533778948,4352.0
34.583912755,4472.0
34.634046562,4507.0
34.684180369,4507.0
34.734314176,4388.0
34.784447983,4568.0
34.834581790,4404.0
34.884715597,4486.0
34.934849404,4512.0
34.984983211,4545.0
35.035117018,4460.0
35.085250825,4504.0
35.135384631,4530.0
35.185518438,4500.0
35.235652245,4483.0
35.285786052,4468.0
35.335919859,4344.0
35.386053666,4460.0
35.436187473,4384.0
35.486321280,4434.0
35.536455087,4598.0
35.586588894,4397.0
35.636722701,4430.0
35.686856508,4413.0
35.736990315,4372.0
35.787124122,4403.0
35.837257929,4475.0
35.887391736,4638.0
35.937525542,4433.0
35.987659349,4527.0
36.037793156,4327.0
36.087926963,4464.0
36.138060770,4321.0
36.188194577,4418.0
36.238328384,4360.0
36.288462191,4366.0
36.338595998,4423.0
36.388729805,4520.0
36.438863612,4407.0
36.488997419,4547.0
36.539131226,4485.0
36.589265033,4245.0
36.639398840,4371.0
36.689532647,4514.0
36.739666453,4418.0
36.789800260,4459.0
36.839934067,4493.0
36.890067874,4518.0
36.940201681,4502.0
36.990335488,4531.0
37.040469295,4593.0
37.090603102,4539.0
37.140736909,4574.0
37.190870716,4485.0
37.241004523,4543.0
37.291138330,4568.0
37.341272137,4597.0
37.391405944,4488.0
37.441539751,4510.0
37.491673558,4561.0
37.541807364,4514.0
37.591941171,4498.0
37.642074978,4533.0
37.692208785,4452.0
37.742342592,4471.0
37.792476399,4547.0
37.842610206,4448.0
37.892744013,4466.0
37.942877820,4640.0
37.993011627,4494.0
38.043145434,4523.0
38.093279241,4467.0
38.143413048,4488.0
38.193546855,4624.0
38.243680662,4461.0
38.293814469,4618.0
38.343948275,4712.0
38.394082082,4655.0
38.444215889,4710.0
38.494349696,4697.0
38.544483503,4745.0
38.594617310,4795.0
38.644751117,4708.0
38.694884924,5075.0
38.745018731,5762.0
38.795152538,4823.0
38.845286345,4675.0
38.895420152,4574.0
38.945553959,4633.0
38.995687766,4693.0
39.045821573,4619.0
39.095955380,4731.0
39.146089186,4590.0
39.196222993,4614.0
39.246356800,4657.0
39.296490607,4640.0
39.346624414,4653.0
39.396758221,4629.0
39.446892028,4559.0
39.497025835,4665.0
39.547159642,4496.0
39.597293449,4458.0
39.647427256,4540.0
39.697561063,4551.0
39.747694870,4714.0
39.797828677,4579.0
39.847962484,4563.0
39.898096291,4542.0
39.948230097,4504.0
39.998363904,4550.0
40.048497711,4488.0
40.098631518,4668.0
40.148765325,4559.0
40.198899132,4572.0
40.249032939,4604.0
40.299166746,4516.0
40.349300553,4637.0
40.399434360,4578.0
40.449568167,4574.0
40.499701974,4545.0
40.549835781,4532.0
40.599969588,4546.0
40.650103395,4615.0
40.700237202,4679.0
40.750371008,4567.0
40.800504815,4372.0
40.850638622,4634.0
40.900772429,4645.0
40.950906236,4513.0
41.001040043,4771.0
41.051173850,4674.0
41.101307657,4613.0
41.151441464,4622.0
41.201575271,4634.0
41.251709078,4604.0
41.301842885,4673.0
41.351976692,4567.0
41.402110499,4849.0
41.452244306,4732.0
41.502378113,4968.0
41.552511919,5236.0
41.602645726,5458.0
41.652779533,5483.0
41.702913340,5372.0
41.753047147,5461.0
41.803180954,5614.0
41.853314761,5541.0
41.903448568,5575.0
41.953582375,5534.0
42.003716182,5657.0
42.053849989,5490.0
42.103983796,5725.0
42.154117603,5873.0
42.204251410,5816.0
42.254385217,5717.0
42.304519024,5783.0
42.354652830,5821.0
42.404786637,5794.0
42.454920444,5851.0
42.505054251,6033.0
42.555188058,6025.0
42.605321865,6238.0
42.655455672,6404.0
42.705589479,7053.0
42.755723286,8156.0
42.805857093,10987.0
42.855990900,14057.0
42.906124707,18762.0
42.956258514,26258.0
43.006392321,59268.0
43.056526128,223280.0
43.106659935,404003.0
43.156793741,124449.0
43.206927548,241107.0
43.257061355,58852.0
43.307195162,20238.0
43.357328969,13152.0
43.407462776,10329.0
43.457596583,8367.0
43.507730390,7315.0
43.557864197,6823.0
43.607998004,6618.0
43.658131811,6189.0
43.708265618,5995.0
43.758399425,5784.0
43.808533232,5962.0
43.858667039,5686.0
43.908800846,5740.0
43.958934652,5618.0
44.009068459,5592.0
44.059202266,5518.0
44.109336073,5482.0
44.159469880,5488.0
44.209603687,5485.0
44.259737494,5222.0
44.309871301,5409.0
44.360005108,5473.0
44.410138915,5449.0
44.460272722,5440.0
44.510406529,5285.0
44.560540336,5280.0
44.610674143,5320.0
44.660807950,5285.0
44.710941757,5299.0
44.761075564,5275.0
44.811209370,5186.0
44.861343177,5305.0
44.911476984,5188.0
44.961610791,5235.0
45.011744598,5230.0
45.061878405,5886.0
45.112012212,5504.0
45.162146019,5306.0
45.212279826,5095.0
45.262413633,5094.0
45.312547440,5204.0
45.362681247,5002.0
45.412815054,4976.0
45.462948861,5074.0
45.513082668,5060.0
45.563216475,5061.0
45.613350281,5080.0
45.663484088,4916.0
45.713617895,5025.0
45.763751702,5068.0
45.813885509,4913.0
45.864019316,5072.0
45.914153123,4888.0
45.964286930,4861.0
46.014420737,5017.0
46.064554544,4928.0
46.114688351,4911.0
46.164822158,4912.0
46.214955965,4938.0
46.265089772,4970.0
46.315223579,5082.0
46.365357386,4925.0
46.415491192,5105.0
46.465624999,5146.0
46.515758806,5053.0
46.565892613,5276.0
46.616026420,5073.0
46.666160227,4939.0
46.716294034,4993.0
46.766427841,5197.0
46.816561648,5546.0
46.866695455,5434.0
46.916829262,5194.0
46.966963069,5142.0
47.017096876,5053.0
47.067230683,4780.0
47.117364490,4866.0
47.167498297,4890.0
47.217632103,4745.0
47.267765910,4996.0
47.317899717,4890.0
47.368033524,4965.0
47.418167331,4774.0
47.468301138,4900.0
47.518434945,4781.0
47.568568752,4857.0
47.618702559,4924.0
47.668836366,4709.0
47.718970173,4904.0
47.769103980,4979.0
47.819237787,4789.0
47.869371594,4865.0
47.919505401,4816.0
47.969639208,4777.0
48.019773014,4897.0
48.069906821,4801.0
48.120040628,4791.0
48.170174435,4841.0
48.220308242,4805.0
48.270442049,4908.0
48.320575856,4842.0
48.370709663,5103.0
48.420843470,5481.0
48.470977277,5406.0
48.521111084,5463.0
48.571244891,5368.0
48.621378698,5304.0
48.671512505,5274.0
48.721646312,5367.0
48.771780119,5364.0
48.821913925,5529.0
48.872047732,5536.0
48.922181539,5510.0
48.972315346,5465.0
49.022449153,5585.0
49.072582960,5670.0
49.122716767,5566.0
49.172850574,5594.0
49.222984381,5561.0
49.273118188,5716.0
49.323251995,5608.0
49.373385802,5459.0
49.423519609,5729.0
49.473653416,5699.0
49.523787223,5799.0
49.573921030,5669.0
49.624054836,5864.0
49.674188643,5964.0
49.724322450,6346.0
49.774456257,6398.0
49.824590064,7078.0
49.874723871,8153.0
49.924857678,11055.0
49.974991485,14165.0
50.025125292,16746.0
50.075259099,22794.0
50.125392906,48664.0
50.175526713,164733.0
50.225660520,349259.0
50.275794327,114817.0
50.325928134,142352.0
50.376061941,139814.0
50.426195747,35006.0
50.476329554,16131.0
50.526463361,11558.0
50.576597168,9045.0
50.626730975,7539.0
50.676864782,6820.0
50.726998589,6415.0
50.777132396,6112.0
50.827266203,5843.0
50.877400010,5837.0
50.927533817,5780.0
50.977667624,5712.0
51.027801431,5506.0
51.077935238,5582.0
51.128069045,5457.0
51.178202852,5392.0
51.228336658,5314.0
51.278470465,5301.0
51.328604272,5285.0
51.378738079,5253.0
51.428871886,5263.0
51.479005693,5252.0
51.529139500,5166.0
51.579273307,5167.0
51.629407114,5083.0
51.679540921,5121.0
51.729674728,5143.0
51.779808535,5104.0
51.829942342,5130.0
51.880076149,5079.0
51.930209956,4944.0
51.980343763,4947.0
52.030477569,5074.0
52.080611376,4901.0
52.130745183,4728.0
52.180878990,4948.0
52.231012797,5148.0
52.281146604,5000.0
52.331280411,4893.0
52.381414218,4718.0
52.431548025,4800.0
52.481681832,4898.0
52.531815639,4997.0
52.581949446,4897.0
52.632083253,4776.0
52.682217060,4824.0
52.732350867,4769.0
52.782484674,4791.0
52.832618480,4881.0
52.882752287,4975.0
52.932886094,4758.0
52.983019901,4869.0
53.033153708,4871.0
53.083287515,4776.0
53.133421322,4731.0
53.183555129,4711.0
53.233688936,4792.0
53.283822743,4655.0
53.333956550,4795.0
53.384090357,4732.0
53.434224164,4806.0
53.484357971,4825.0
53.534491778,4716.0
53.584625585,4767.0
53.634759391,4670.0
53.684893198,4663.0
53.735027005,4686.0
53.785160812,4784.0
53.835294619,4830.0
53.885428426,4691.0
53.935562233,4618.0
53.985696040,4746.0
54.035829847,4676.0
54.085963654,4815.0
54.136097461,4722.0
54.186231268,4759.0
54.236365075,4723.0
54.286498882,4626.0
54.336632689,4916.0
54.386766496,4738.0
54.436900303,4716.0
54.487034109,4924.0
54.537167916,4829.0
54.587301723,5005.0
54.637435530,5050.0
54.687569337,5035.0
54.737703144,4866.0
54.787836951,4820.0
54.837970758,4742.0
54.888104565,4731.0
54.938238372,4682.0
54.988372179,4615.0
55.038505986,4659.0
55.088639793,4794.0
55.138773600,4738.0
55.188907407,4710.0
55.239041214,4694.0
55.289175020,4545.0
55.339308827,4654.0
55.389442634,4533.0
55.439576441,4721.0
55.489710248,4536.0
55.539844055,4571.0
55.589977862,4649.0
55.640111669,4604.0
55.690245476,4654.0
55.740379283,4600.0
55.790513090,4594.0
55.840646897,4646.0
55.890780704,4540.0
55.940914511,4758.0
55.991048318,4549.0
56.041182125,4601.0
56.091315931,4597.0
56.141449738,4452.0
56.191583545,4490.0
56.241717352,4562.0
56.291851159,4592.0
56.341984966,4577.0
56.392118773,4603.0
56.442252580,4600.0
56.492386387,4522.0
56.542520194,4442.0
56.592654001,4487.0
56.642787808,4469.0
56.692921615,4444.0
56.743055422,4566.0
56.793189229,4588.0
56.843323036,4656.0
56.893456842,4638.0
56.943590649,4596.0
56.993724456,4503.0
57.043858263,4431.0
57.093992070,4564.0
57.144125877,4523.0
57.194259684,4484.0
57.244393491,4409.0
57.294527298,4545.0
57.344661105,4535.0
57.394794912,4463.0
57.444928719,4559.0
57.495062526,4405.0
57.545196333,4540.0
57.595330140,4548.0
57.645463947,4446.0
57.695597753,4501.0
57.745731560,4612.0
57.795865367,4400.0
57.845999174,4544.0
57.896132981,4639.0
57.946266788,4579.0
57.996400595,4477.0
58.046534402,4511.0
58.096668209,4458.0
58.146802016,4421.0
58.196935823,4393.0
58.247069630,4547.0
58.297203437,4446.0
58.347337244,4464.0
58.397471051,4374.0
58.447604858,4459.0
58.497738664,4466.0
58.547872471,4482.0
58.598006278,4489.0
58.648140085,4564.0
58.698273892,4531.0
58.748407699,4445.0
58.798541506,4507.0
58.848675313,4412.0
58.898809120,4391.0
58.948942927,4502.0
58.999076734,4352.0
59.049210541,4533.0
59.099344348,4420.0
59.149478155,4487.0
59.199611962,4372.0
59.249745769,4394.0
59.299879575,4464.0
59.350013382,4362.0
59.400147189,4475.0
59.450280996,4590.0
59.500414803,4430.0
59.550548610,4459.0
59.600682417,4482.0
59.650816224,4492.0
59.700950031,4455.0
59.751083838,4441.0
59.801217645,4328.0
59.851351452,4395.0
59.901485259,4501.0
59.951619066,4423.0
60.001752873,4390.0
60.051886680,4407.0
60.102020486,4454.0
60.152154293,4486.0
60.202288100,4485.0
60.252421907,4444.0
60.302555714,4353.0
60.352689521,4533.0
60.402823328,4526.0
60.452957135,4463.0
60.503090942,4457.0
60.553224749,4381.0
60.603358556,4383.0
60.653492363,4444.0
60.703626170,4388.0
60.753759977,4450.0
60.803893784,4499.0
60.854027591,4315.0
60.904161397,4572.0
60.954295204,4491.0
61.004429011,4437.0
61.054562818,4409.0
61.104696625,4298.0
61.154830432,4459.0
61.204964239,4434.0
61.255098046,4339.0
61.305231853,4258.0
61.355365660,4397.0
61.405499467,4325.0
61.455633274,4448.0
61.505767081,4410.0
61.555900888,4504.0
61.606034695,4440.0
61.656168502,4433.0
61.706302308,4428.0
61.756436115,4361.0
61.806569922,4490.0
61.856703729,4459.0
61.906837536,4343.0
61.956971343,4347.0
62.007105150,4383.0
62.057238957,4387.0
62.107372764,4393.0
62.157506571,4447.0
62.207640378,4390.0
62.257774185,4555.0
62.307907992,4427.0
62.358041799,4366.0
62.408175606,4328.0
62.458309413,4453.0
62.508443219,4413.0
62.558577026,4501.0
62.608710833,4528.0
62.658844640,4361.0
62.708978447,4335.0
62.759112254,4381.0
62.809246061,4386.0
62.859379868,4325.0
62.909513675,4434.0
62.959647482,4385.0
63.009781289,4479.0
63.059915096,4390.0
63.110048903,4338.0
63.160182710,4300.0
63.210316517,4302.0
63.260450324,4312.0
63.310584130,4383.0
63.360717937,4378.0
63.410851744,4452.0
63.460985551,4432.0
63.511119358,4273.0
63.561253165,4467.0
63.611386972,4495.0
63.661520779,4363.0
63.711654586,4428.0
63.761788393,4355.0
63.811922200,4418.0
63.862056007,4426.0
63.912189814,4315.0
63.962323621,4403.0
64.012457428,4484.0
64.062591235,4283.0
64.112725041,4446.0
64.162858848,4369.0
64.212992655,4378.0
64.263126462,4456.0
64.313260269,4419.0
64.363394076,4365.0
64.413527883,4352.0
64.463661690,4453.0
64.513795497,4400.0
64.563929304,4477.0
64.614063111,4393.0
64.664196918,4517.0
64.714330725,4330.0
64.764464532,4498.0
64.814598339,4317.0
64.864732146,4413.0
64.914865953,4585.0
64.964999759,4324.0
65.015133566,4323.0
65.065267373,4379.0
65.115401180,4389.0
65.165534987,4300.0
65.215668794,4451.0
65.265802601,4449.0
65.315936408,4588.0
65.366070215,4416.0
65.416204022,4412.0
65.466337829,4319.0
65.516471636,4438.0
65.566605443,4310.0
65.616739250,4364.0
65.666873057,4413.0
65.717006864,4409.0
65.767140670,4522.0
65.817274477,4465.0
65.867408284,4284.0
65.917542091,4390.0
65.967675898,4364.0
66.017809705,4350.0
66.067943512,4425.0
66.118077319,4311.0
66.168211126,4274.0
66.218344933,4375.0
66.268478740,4492.0
66.318612547,4423.0
66.368746354,4355.0
66.418880161,4348.0
66.469013968,4438.0
66.519147775,4468.0
66.569281581,4329.0
66.619415388,4347.0
66.669549195,4258.0
66.719683002,4390.0
66.769816809,4390.0
66.819950616,4467.0
66.870084423,4516.0
66.920218230,4306.0
66.970352037,4532.0
67.020485844,4361.0
67.070619651,4301.0
67.120753458,4420.0
67.170887265,4459.0
67.221021072,4366.0
67.271154879,4305.0
67.321288686,4290.0
67.371422492,4482.0
67.421556299,4407.0
67.471690106,4490.0
67.521823913,4416.0
67.571957720,4351.0
67.622091527,4434.0
67.672225334,4433.0
67.722359141,4374.0
67.772492948,4491.0
67.822626755,4448.0
67.872760562,4428.0
67.922894369,4582.0
67.973028176,4737.0
68.023161983,4579.0
68.073295790,4330.0
68.123429597,4613.0
68.173563403,4547.0
68.223697210,4418.0
68.273831017,4246.0
68.323964824,4455.0
68.374098631,4289.0
68.424232438,4411.0
68.474366245,4387.0
68.524500052,4263.0
68.574633859,4313.0
68.624767666,4317.0
68.674901473,4372.0
68.725035280,4406.0
68.775169087,4351.0
68.825302894,4353.0
68.875436701,4417.0
68.925570508,4316.0
68.975704314,4335.0
69.025838121,4360.0
69.075971928,4431.0
69.126105735,4342.0
69.176239542,4366.0
69.226373349,4449.0
69.276507156,4443.0
69.326640963,4358.0
69.376774770,4292.0
69.426908577,4338.0
69.477042384,4458.0
69.527176191,4421.0
69.577309998,4422.0
69.627443805,4418.0
69.677577612,4223.0
69.727711419,4392.0
69.777845225,4309.0
69.827979032,4273.0
69.878112839,4326.0
69.928246646,4427.0
69.978380453,4347.0
70.028514260,4329.0
70.078648067,4400.0
70.128781874,4494.0
70.178915681,4418.0
70.229049488,4358.0
70.279183295,4394.0
70.329317102,4387.0
70.379450909,4346.0
70.429584716,4381.0
70.479718523,4375.0
70.529852330,4280.0
70.579986136,4377.0
70.630119943,4294.0
70.680253750,4487.0
70.730387557,4446.0
70.780521364,4408.0
70.830655171,4467.0
70.880788978,4541.0
70.930922785,4440.0
70.981056592,4425.0
71.031190399,4482.0
71.081324206,4519.0
71.131458013,4522.0
71.181591820,4456.0
71.231725627,4461.0
71.281859434,4512.0
71.331993241,4578.0
71.382127047,4496.0
71.432260854,4536.0
71.482394661,4460.0
71.532528468,4405.0
71.582662275,4412.0
71.632796082,4503.0
71.682929889,4549.0
71.733063696,4493.0
71.783197503,4549.0
71.833331310,4498.0
71.883465117,4531.0
71.933598924,4540.0
71.983732731,4410.0
72.033866538,4625.0
72.084000345,4485.0
72.134134152,4541.0
72.184267958,4496.0
72.234401765,4471.0
72.284535572,4504.0
72.334669379,4513.0
72.384803186,4569.0
72.434936993,4473.0
72.485070800,4444.0
72.535204607,4548.0
72.585338414,4530.0
72.635472221,4504.0
72.685606028,4592.0
72.735739835,4591.0
72.785873642,4674.0
72.836007449,4429.0
72.886141256,4586.0
72.936275063,4640.0
72.986408869,4637.0
73.036542676,4551.0
73.086676483,4640.0
73.136810290,4605.0
73.186944097,4630.0
73.237077904,4704.0
73.287211711,4727.0
73.337345518,4805.0
73.387479325,4891.0
73.437613132,5087.0
73.487746939,5337.0
73.537880746,5383.0
73.588014553,5594.0
73.638148360,6155.0
73.688282167,6731.0
73.738415974,8295.0
73.788549780,13999.0
73.838683587,40284.0
73.888817394,60663.0
73.938951201,21330.0
73.989085008,12283.0
74.039218815,18548.0
74.089352622,35003.0
74.139486429,17731.0
74.189620236,8365.0
74.239754043,6396.0
74.289887850,5724.0
74.340021657,5189.0
74.390155464,5168.0
74.440289271,4884.0
74.490423078,4785.0
74.540556885,4721.0
74.590690692,4679.0
74.640824498,4695.0
74.690958305,4620.0
74.741092112,4567.0
74.791225919,4611.0
74.841359726,4711.0
74.891493533,4481.0
74.941627340,4623.0
74.991761147,4651.0
75.041894954,4521.0
75.092028761,4481.0
75.142162568,4482.0
75.192296375,4439.0
75.242430182,4528.0
75.292563989,4410.0
75.342697796,4497.0
75.392831603,4531.0
75.442965409,4503.0
75.493099216,4401.0
75.543233023,4496.0
75.593366830,4481.0
75.643500637,4415.0
75.693634444,4396.0
75.743768251,4429.0
75.793902058,4562.0
75.844035865,4455.0
75.894169672,4508.0
75.944303479,4580.0
75.994437286,4429.0
76.044571093,4239.0
76.094704900,4359.0
76.144838707,4309.0
76.194972514,4370.0
76.245106320,4436.0
76.295240127,4310.0
76.345373934,4504.0
76.395507741,4387.0
76.445641548,4359.0
76.495775355,4403.0
76.545909162,4522.0
76.596042969,4469.0
76.646176776,4449.0
76.696310583,4414.0
76.746444390,4473.0
76.796578197,4365.0
76.846712004,4429.0
76.896845811,4503.0
76.946979618,4431.0
76.997113425,4428.0
77.047247231,4487.0
77.097381038,4399.0
77.147514845,4457.0
77.197648652,4442.0
77.247782459,4378.0
77.297916266,4451.0
77.348050073,4343.0
77.398183880,4487.0
77.448317687,4383.0
77.498451494,4471.0
77.548585301,4428.0
77.598719108,4527.0
77.648852915,4545.0
77.698986722,4426.0
77.749120529,4400.0
77.799254336,4420.0
77.849388142,4439.0
77.899521949,4366.0
77.949655756,4530.0
77.999789563,4348.0
78.049923370,4388.0
78.100057177,4446.0
78.150190984,4463.0
78.200324791,4407.0
78.250458598,4429.0
78.300592405,4413.0
78.350726212,4406.0
78.400860019,4353.0
78.450993826,4364.0
78.501127633,4449.0
78.551261440,4398.0
78.601395247,4464.0
78.651529053,4469.0
78.701662860,4310.0
78.751796667,4344.0
78.801930474,4392.0
78.852064281,4393.0
78.902198088,4448.0
78.952331895,4437.0
79.002465702,4455.0
79.052599509,4395.0
79.102733316,4601.0
79.152867123,4450.0
79.203000930,4424.0
79.253134737,4356.0
79.303268544,4387.0
79.353402351,4384.0
79.403536158,4346.0
79.453669964,4358.0
79.503803771,4512.0
79.553937578,4395.0
79.604071385,4560.0
79.654205192,4268.0
79.704338999,4428.0
79.754472806,4426.0
79.804606613,4507.0
79.854740420,4378.0
79.904874227,4307.0
79.955008034,4364.0
80.005141841,4322.0
80.055275648,4494.0
80.105409455,4451.0
80.155543262,4643.0
80.205677069,4360.0
80.255810875,4332.0
80.305944682,4432.0
80.356078489,4377.0
80.406212296,4428.0
80.456346103,4293.0
80.506479910,4409.0
80.556613717,4445.0
80.606747524,4387.0
80.656881331,4390.0
80.707015138,4361.0
80.757148945,4380.0
80.807282752,4503.0
80.857416559,4383.0
80.907550366,4461.0
80.957684173,4376.0
81.007817980,4502.0
81.057951786,4479.0
81.108085593,4382.0
81.158219400,4411.0
81.208353207,4426.0
81.258487014,4284.0
81.308620821,4342.0
81.358754628,4344.0
81.408888435,4424.0
81.459022242,4515.0
81.509156049,4449.0
81.559289856,4364.0
81.609423663,4462.0
81.659557470,4363.0
81.709691277,4343.0
81.759825084,4290.0
81.809958891,4423.0
81.860092697,4398.0
81.910226504,4544.0
81.960360311,4718.0
82.010494118,4645.0
82.060627925,4498.0
82.110761732,4517.0
82.160895539,4492.0
82.211029346,4465.0
82.261163153,4592.0
82.311296960,4508.0
82.361430767,4450.0
82.411564574,4462.0
82.461698381,4374.0
82.511832188,4414.0
82.561965995,4412.0
82.612099802,4511.0
82.662233608,4435.0
82.712367415,4558.0
82.762501222,4303.0
82.812635029,4357.0
82.862768836,4281.0
82.912902643,4304.0
82.963036450,4386.0
83.013170257,4360.0
83.063304064,4370.0
83.113437871,4292.0
83.163571678,4410.0
83.213705485,4400.0
83.263839292,4405.0
83.313973099,4496.0
83.364106906,4381.0
83.414240713,4388.0
83.464374519,4448.0
83.514508326,4336.0
83.564642133,4347.0
83.614775940,4469.0
83.664909747,4283.0
83.715043554,4371.0
83.765177361,4336.0
83.815311168,4274.0
83.865444975,4279.0
83.915578782,4438.0
83.965712589,4385.0
84.015846396,4392.0
84.065980203,4319.0
84.116114010,4358.0
84.166247817,4348.0
84.216381624,4361.0
84.266515431,4329.0
84.316649237,4240.0
84.366783044,4399.0
84.416916851,4588.0
84.467050658,4381.0
84.517184465,4345.0
84.567318272,4441.0
84.617452079,4470.0
84.667585886,4304.0
84.717719693,4441.0
84.767853500,4358.0
84.817987307,4467.0
84.868121114,4379.0
84.918254921,4420.0
84.968388728,4194.0
85.018522535,4440.0
85.068656342,4390.0
85.118790148,4427.0
85.168923955,4441.0
85.219057762,4358.0
85.269191569,4461.0
85.319325376,4460.0
85.369459183,4178.0
85.419592990,4313.0
85.469726797,4403.0
85.519860604,4337.0
85.569994411,4223.0
85.620128218,4384.0
85.670262025,4339.0
85.720395832,4366.0
85.770529639,4282.0
85.820663446,4468.0
85.870797253,4318.0
85.920931059,4487.0
85.971064866,4502.0
86.021198673,4317.0
86.071332480,4447.0
86.121466287,4356.0
86.171600094,4531.0
86.221733901,4501.0
86.271867708,4471.0
86.322001515,4516.0
86.372135322,4388.0
86.422269129,4409.0
86.472402936,4417.0
86.522536743,4380.0
86.572670550,4443.0
86.622804357,4481.0
86.672938164,4435.0
86.723071970,4364.0
86.773205777,4453.0
86.823339584,4408.0
86.873473391,4423.0
86.923607198,4361.0
86.973741005,4469.0
87.023874812,4414.0
87.074008619,4475.0
87.124142426,4458.0
87.174276233,4461.0
87.224410040,4504.0
87.274543847,4499.0
87.324677654,4421.0
87.374811461,4393.0
87.424945268,4395.0
87.475079075,4403.0
87.525212881,4406.0
87.575346688,4328.0
87.625480495,4403.0
87.675614302,4457.0
87.725748109,4465.0
87.775881916,4602.0
87.826015723,4339.0
87.876149530,4376.0
87.926283337,4478.0
87.976417144,4496.0
88.026550951,4383.0
88.076684758,4464.0
88.126818565,4403.0
88.176952372,4370.0
88.227086179,4393.0
88.277219986,4341.0
88.327353792,4528.0
88.377487599,4443.0
88.427621406,4404.0
88.477755213,4509.0
88.527889020,4386.0
88.578022827,4493.0
88.628156634,4349.0
88.678290441,4539.0
88.728424248,4498.0
88.778558055,4538.0
88.828691862,4473.0
88.878825669,4520.0
88.928959476,4486.0
88.979093283,4562.0
89.029227090,4376.0
89.079360897,4469.0
89.129494703,4638.0
89.179628510,4727.0
89.229762317,4734.0
89.279896124,4734.0
89.330029931,4805.0
89.380163738,4947.0
89.430297545,5265.0
89.480431352,5639.0
89.530565159,6548.0
89.580698966,8748.0
89.630832773,16218.0
89.680966580,22219.0
89.731100387,12792.0
89.781234194,7973.0
89.831368001,6938.0
89.881501808,8396.0
89.931635614,12245.0
89.981769421,12035.0
90.031903228,7669.0
90.082037035,5857.0
90.132170842,5113.0
90.182304649,4861.0
90.232438456,4652.0
90.282572263,4692.0
90.332706070,4529.0
90.382839877,4571.0
90.432973684,4432.0
90.483107491,4513.0
90.533241298,4602.0
90.583375105,4472.0
90.633508912,4528.0
90.683642719,4443.0
90.733776525,4521.0
90.783910332,4503.0
90.834044139,4316.0
90.884177946,4447.0
90.934311753,4440.0
90.984445560,4475.0
91.034579367,4436.0
91.084713174,4537.0
91.134846981,4519.0
91.184980788,4222.0
91.235114595,4528.0
91.285248402,4459.0
91.335382209,4605.0
91.385516016,4485.0
91.435649823,4383.0
91.485783630,4441.0
91.535917436,4512.0
91.586051243,4467.0
91.636185050,4431.0
91.686318857,4403.0
91.736452664,4386.0
91.786586471,4505.0
91.836720278,4477.0
91.886854085,4363.0
91.936987892,4518.0
91.987121699,4432.0
92.037255506,4354.0
92.087389313,4394.0
92.137523120,4325.0
92.187656927,4469.0
92.237790734,4514.0
92.287924541,4492.0
92.338058347,4251.0
92.388192154,4384.0
92.438325961,4560.0
92.488459768,4472.0
92.538593575,4352.0
92.588727382,4542.0
92.638861189,4418.0
92.688994996,4395.0
92.739128803,4258.0
92.789262610,4360.0
92.839396417,4488.0
92.889530224,4355.0
92.939664031,4489.0
92.989797838,4484.0
93.039931645,4307.0
93.090065452,4475.0
93.140199258,4406.0
93.190333065,4461.0
93.240466872,4525.0
93.290600679,4520.0
93.340734486,4437.0
93.390868293,4393.0
93.441002100,4427.0
93.491135907,4461.0
93.541269714,4474.0
93.591403521,4447.0
93.641537328,4394.0
93.691671135,4345.0
93.741804942,4562.0
93.791938749,4502.0
93.842072556,4438.0
93.892206363,4432.0
93.942340170,4543.0
93.992473976,4485.0
94.042607783,4456.0
94.092741590,4580.0
94.142875397,4475.0
94.193009204,4534.0
94.243143011,4531.0
94.293276818,4682.0
94.343410625,4577.0
94.393544432,4623.0
94.443678239,4695.0
94.493812046,4819.0
94.543945853,4704.0
94.594079660,5052.0
94.644213467,5147.0
94.694347274,5420.0
94.744481081,6350.0
94.794614887,9009.0
94.844748694,19254.0
94.894882501,22236.0
94.945016308,11111.0
94.995150115,7013.0
95.045283922,6447.0
95.095417729,6708.0
95.145551536,10416.0
95.195685343,14373.0
95.245819150,8773.0
95.295952957,6078.0
95.346086764,5209.0
95.396220571,4858.0
95.446354378,4639.0
95.496488185,4574.0
95.546621992,4555.0
95.596755798,4663.0
95.646889605,4587.0
95.697023412,4409.0
95.747157219,4415.0
95.797291026,4495.0
95.847424833,4416.0
95.897558640,4510.0
95.947692447,4429.0
95.997826254,4591.0
96.047960061,4481.0
96.098093868,4374.0
96.148227675,4391.0
96.198361482,4393.0
96.248495289,4339.0
96.298629096,4419.0
96.348762903,4495.0
96.398896709,4467.0
96.449030516,4430.0
96.499164323,4528.0
96.549298130,4507.0
96.599431937,4428.0
96.649565744,4283.0
96.699699551,4312.0
96.749833358,4390.0
96.799967165,4415.0
96.850100972,4338.0
96.900234779,4388.0
96.950368586,4436.0
97.000502393,4346.0
97.050636200,4266.0
97.100770007,4383.0
97.150903814,4410.0
97.201037620,4303.0
97.251171427,4418.0
97.301305234,4313.0
97.351439041,4280.0
97.401572848,4313.0
97.451706655,4400.0
97.501840462,4380.0
97.551974269,4363.0
97.602108076,4363.0
97.652241883,4402.0
97.702375690,4373.0
97.752509497,4390.0
97.802643304,4394.0
97.852777111,4342.0
97.902910918,4270.0
97.953044725,4399.0
98.003178531,4414.0
98.053312338,4428.0
98.103446145,4393.0
98.153579952,4408.0
98.203713759,4385.0
98.253847566,4516.0
98.303981373,4257.0
98.354115180,4368.0
98.404248987,4338.0
98.454382794,4310.0
98.504516601,4392.0
98.554650408,4285.0
98.604784215,4254.0
98.654918022,4459.0
98.705051829,4334.0
98.755185636,4366.0
98.805319442,4487.0
98.855453249,4311.0
98.905587056,4365.0
98.955720863,4522.0
99.005854670,4350.0
99.055988477,4515.0
99.106122284,4431.0
99.156256091,4357.0
99.206389898,4309.0
99.256523705,4358.0
99.306657512,4306.0
99.356791319,4492.0
99.406925126,4382.0
99.457058933,4401.0
99.507192740,4336.0
99.557326547,4239.0
99.607460353,4462.0
99.657594160,4418.0
99.707727967,4522.0
99.757861774,4343.0
99.807995581,4329.0
99.858129388,4365.0
99.908263195,4337.0
99.958397002,4443.0
99.991819540,4415.0