File: OriginPro/XRD from Panalytical X'Pert PRO/Nova Cu foil/Cufoil_150°C.csv
[Measurement conditions]
Sample identification,
Comment - 1,"finito"
Comment - 2,"Configuration=MRI TC-Basic Stage, Owner=User-1, Creation date=26-10-2009 9:18:44"
Comment - 3,"Goniometer=PW3050/60 (Theta/Theta); Minimum step size 2Theta:0.001; Minimum step size Omega:0.001"
Comment - 4,"Sample stage=MRI TC-Basic (PtRh heat strip)"
Comment - 5,"Diffractometer system=XPERT-PRO"
Comment - 6,"Measurement program=FlatStage, Owner=joana, Creation date=03-08-2011 15:43:53"
Anode material,Cu
K-Alpha1 wavelength,1.5405980
K-Alpha2 wavelength,1.5444260
Ratio K-Alpha2/K-Alpha1,0.500
Divergence slit,Fixed,0.76mm
Monochromator used,NO
Generator voltage, 45
Tube current, 40
File date and time,06/Dec/2012 20:43
Unit cell,
h k l, 0 0 0
Temperature [K],423
Scan axis,Gonio
Scan range,24.999999996,100.000175174
Scan step size,0.0167113
No. of points, 4488
Scan type,CONTINUOUS
Time per step,53.340
[Scan points]
Angle,Intensity
25.008355630,4567.0
25.058489437,4614.0
25.108623244,4555.0
25.158757051,4555.0
25.208890858,4500.0
25.259024665,4421.0
25.309158472,4697.0
25.359292279,4593.0
25.409426086,4585.0
25.459559892,4379.0
25.509693699,4484.0
25.559827506,4538.0
25.609961313,4619.0
25.660095120,4485.0
25.710228927,4659.0
25.760362734,4502.0
25.810496541,4470.0
25.860630348,4594.0
25.910764155,4525.0
25.960897962,4532.0
26.011031769,4464.0
26.061165576,4508.0
26.111299383,4573.0
26.161433190,4527.0
26.211566997,4525.0
26.261700803,4464.0
26.311834610,4505.0
26.361968417,4559.0
26.412102224,4587.0
26.462236031,4532.0
26.512369838,4599.0
26.562503645,4526.0
26.612637452,4461.0
26.662771259,4616.0
26.712905066,4459.0
26.763038873,4544.0
26.813172680,4668.0
26.863306487,4464.0
26.913440294,4478.0
26.963574101,4503.0
27.013707908,4571.0
27.063841714,4538.0
27.113975521,4509.0
27.164109328,4488.0
27.214243135,4471.0
27.264376942,4441.0
27.314510749,4471.0
27.364644556,4405.0
27.414778363,4583.0
27.464912170,4540.0
27.515045977,4548.0
27.565179784,4536.0
27.615313591,4633.0
27.665447398,4512.0
27.715581205,4502.0
27.765715012,4478.0
27.815848819,4540.0
27.865982625,4528.0
27.916116432,4585.0
27.966250239,4471.0
28.016384046,4583.0
28.066517853,4479.0
28.116651660,4549.0
28.166785467,4555.0
28.216919274,4550.0
28.267053081,4670.0
28.317186888,4508.0
28.367320695,4582.0
28.417454502,4472.0
28.467588309,4550.0
28.517722116,4514.0
28.567855923,4427.0
28.617989730,4490.0
28.668123536,4612.0
28.718257343,4477.0
28.768391150,4544.0
28.818524957,4493.0
28.868658764,4423.0
28.918792571,4516.0
28.968926378,4510.0
29.019060185,4491.0
29.069193992,4494.0
29.119327799,4585.0
29.169461606,4506.0
29.219595413,4569.0
29.269729220,4525.0
29.319863027,4588.0
29.369996834,4490.0
29.420130641,4555.0
29.470264447,4563.0
29.520398254,4620.0
29.570532061,4438.0
29.620665868,4472.0
29.670799675,4465.0
29.720933482,4558.0
29.771067289,4371.0
29.821201096,4333.0
29.871334903,4459.0
29.921468710,4537.0
29.971602517,4487.0
30.021736324,4415.0
30.071870131,4560.0
30.122003938,4482.0
30.172137745,4395.0
30.222271552,4605.0
30.272405358,4543.0
30.322539165,4507.0
30.372672972,4422.0
30.422806779,4471.0
30.472940586,4363.0
30.523074393,4511.0
30.573208200,4368.0
30.623342007,4501.0
30.673475814,4423.0
30.723609621,4462.0
30.773743428,4572.0
30.823877235,4555.0
30.874011042,4428.0
30.924144849,4502.0
30.974278656,4279.0
31.024412463,4566.0
31.074546269,4488.0
31.124680076,4514.0
31.174813883,4546.0
31.224947690,4445.0
31.275081497,4433.0
31.325215304,4395.0
31.375349111,4487.0
31.425482918,4462.0
31.475616725,4530.0
31.525750532,4344.0
31.575884339,4499.0
31.626018146,4653.0
31.676151953,4553.0
31.726285760,4458.0
31.776419567,4651.0
31.826553374,4530.0
31.876687180,4464.0
31.926820987,4481.0
31.976954794,4574.0
32.027088601,4607.0
32.077222408,4478.0
32.127356215,4458.0
32.177490022,4571.0
32.227623829,4441.0
32.277757636,4437.0
32.327891443,4442.0
32.378025250,4394.0
32.428159057,4514.0
32.478292864,4341.0
32.528426671,4446.0
32.578560478,4522.0
32.628694285,4511.0
32.678828091,4376.0
32.728961898,4483.0
32.779095705,4398.0
32.829229512,4363.0
32.879363319,4447.0
32.929497126,4436.0
32.979630933,4552.0
33.029764740,4407.0
33.079898547,4356.0
33.130032354,4454.0
33.180166161,4430.0
33.230299968,4517.0
33.280433775,4488.0
33.330567582,4350.0
33.380701389,4359.0
33.430835196,4452.0
33.480969002,4550.0
33.531102809,4446.0
33.581236616,4437.0
33.631370423,4356.0
33.681504230,4390.0
33.731638037,4495.0
33.781771844,4419.0
33.831905651,4560.0
33.882039458,4375.0
33.932173265,4512.0
33.982307072,4576.0
34.032440879,4496.0
34.082574686,4483.0
34.132708493,4347.0
34.182842300,4390.0
34.232976107,4382.0
34.283109913,4384.0
34.333243720,4382.0
34.383377527,4388.0
34.433511334,4469.0
34.483645141,4382.0
34.533778948,4512.0
34.583912755,4561.0
34.634046562,4424.0
34.684180369,4486.0
34.734314176,4428.0
34.784447983,4474.0
34.834581790,4508.0
34.884715597,4514.0
34.934849404,4443.0
34.984983211,4333.0
35.035117018,4443.0
35.085250825,4545.0
35.135384631,4401.0
35.185518438,4371.0
35.235652245,4428.0
35.285786052,4565.0
35.335919859,4443.0
35.386053666,4479.0
35.436187473,4595.0
35.486321280,4448.0
35.536455087,4503.0
35.586588894,4407.0
35.636722701,4428.0
35.686856508,4539.0
35.736990315,4490.0
35.787124122,4337.0
35.837257929,4443.0
35.887391736,4464.0
35.937525542,4506.0
35.987659349,4392.0
36.037793156,4511.0
36.087926963,4507.0
36.138060770,4422.0
36.188194577,4444.0
36.238328384,4528.0
36.288462191,4420.0
36.338595998,4481.0
36.388729805,4308.0
36.438863612,4372.0
36.488997419,4410.0
36.539131226,4453.0
36.589265033,4491.0
36.639398840,4491.0
36.689532647,4587.0
36.739666453,4458.0
36.789800260,4405.0
36.839934067,4448.0
36.890067874,4511.0
36.940201681,4512.0
36.990335488,4421.0
37.040469295,4450.0
37.090603102,4451.0
37.140736909,4512.0
37.190870716,4382.0
37.241004523,4595.0
37.291138330,4584.0
37.341272137,4474.0
37.391405944,4494.0
37.441539751,4438.0
37.491673558,4335.0
37.541807364,4521.0
37.591941171,4689.0
37.642074978,4594.0
37.692208785,4394.0
37.742342592,4530.0
37.792476399,4532.0
37.842610206,4501.0
37.892744013,4482.0
37.942877820,4438.0
37.993011627,4587.0
38.043145434,4609.0
38.093279241,4586.0
38.143413048,4636.0
38.193546855,4545.0
38.243680662,4597.0
38.293814469,4526.0
38.343948275,4518.0
38.394082082,4635.0
38.444215889,4606.0
38.494349696,4547.0
38.544483503,4528.0
38.594617310,4817.0
38.644751117,4712.0
38.694884924,5556.0
38.745018731,5176.0
38.795152538,4658.0
38.845286345,4688.0
38.895420152,4539.0
38.945553959,4744.0
38.995687766,4646.0
39.045821573,4559.0
39.095955380,4680.0
39.146089186,4514.0
39.196222993,4559.0
39.246356800,4769.0
39.296490607,4656.0
39.346624414,4539.0
39.396758221,4618.0
39.446892028,4588.0
39.497025835,4498.0
39.547159642,4569.0
39.597293449,4652.0
39.647427256,4638.0
39.697561063,4584.0
39.747694870,4547.0
39.797828677,4500.0
39.847962484,4772.0
39.898096291,4670.0
39.948230097,4695.0
39.998363904,4555.0
40.048497711,4694.0
40.098631518,4603.0
40.148765325,4488.0
40.198899132,4837.0
40.249032939,4613.0
40.299166746,4437.0
40.349300553,4536.0
40.399434360,4525.0
40.449568167,4665.0
40.499701974,4636.0
40.549835781,4513.0
40.599969588,4542.0
40.650103395,4542.0
40.700237202,4597.0
40.750371008,4669.0
40.800504815,4520.0
40.850638622,4600.0
40.900772429,4712.0
40.950906236,4685.0
41.001040043,4754.0
41.051173850,4650.0
41.101307657,4778.0
41.151441464,4775.0
41.201575271,4639.0
41.251709078,4728.0
41.301842885,4692.0
41.351976692,4614.0
41.402110499,4734.0
41.452244306,4879.0
41.502378113,5218.0
41.552511919,5448.0
41.602645726,5541.0
41.652779533,5480.0
41.702913340,5448.0
41.753047147,5462.0
41.803180954,5478.0
41.853314761,5475.0
41.903448568,5545.0
41.953582375,5684.0
42.003716182,5546.0
42.053849989,5730.0
42.103983796,5863.0
42.154117603,5923.0
42.204251410,5787.0
42.254385217,5781.0
42.304519024,5786.0
42.354652830,5784.0
42.404786637,5721.0
42.454920444,6027.0
42.505054251,6055.0
42.555188058,6189.0
42.605321865,6529.0
42.655455672,6775.0
42.705589479,7867.0
42.755723286,10131.0
42.805857093,13244.0
42.855990900,17004.0
42.906124707,21927.0
42.956258514,42487.0
43.006392321,134766.0
43.056526128,454242.0
43.106659935,155937.0
43.156793741,207710.0
43.206927548,113463.0
43.257061355,25429.0
43.307195162,14585.0
43.357328969,11115.0
43.407462776,8817.0
43.457596583,7738.0
43.507730390,7099.0
43.557864197,6692.0
43.607998004,6441.0
43.658131811,6195.0
43.708265618,6145.0
43.758399425,5991.0
43.808533232,5896.0
43.858667039,5692.0
43.908800846,5757.0
43.958934652,5702.0
44.009068459,5565.0
44.059202266,5463.0
44.109336073,5482.0
44.159469880,5450.0
44.209603687,5353.0
44.259737494,5449.0
44.309871301,5265.0
44.360005108,5476.0
44.410138915,5286.0
44.460272722,5327.0
44.510406529,5532.0
44.560540336,5283.0
44.610674143,5348.0
44.660807950,5210.0
44.710941757,5273.0
44.761075564,5320.0
44.811209370,5422.0
44.861343177,5206.0
44.911476984,5261.0
44.961610791,5265.0
45.011744598,5743.0
45.061878405,5694.0
45.112012212,5277.0
45.162146019,5293.0
45.212279826,5198.0
45.262413633,5179.0
45.312547440,5149.0
45.362681247,5112.0
45.412815054,5157.0
45.462948861,5196.0
45.513082668,5104.0
45.563216475,5103.0
45.613350281,5091.0
45.663484088,4960.0
45.713617895,5013.0
45.763751702,5067.0
45.813885509,5036.0
45.864019316,4974.0
45.914153123,5016.0
45.964286930,5021.0
46.014420737,4827.0
46.064554544,5061.0
46.114688351,4991.0
46.164822158,4941.0
46.214955965,4997.0
46.265089772,5024.0
46.315223579,4884.0
46.365357386,5084.0
46.415491192,5216.0
46.465624999,5255.0
46.515758806,5153.0
46.565892613,5357.0
46.616026420,4947.0
46.666160227,4952.0
46.716294034,4868.0
46.766427841,5456.0
46.816561648,5453.0
46.866695455,5261.0
46.916829262,5368.0
46.966963069,4995.0
47.017096876,4866.0
47.067230683,4846.0
47.117364490,4870.0
47.167498297,4967.0
47.217632103,4994.0
47.267765910,5036.0
47.317899717,4991.0
47.368033524,4855.0
47.418167331,4833.0
47.468301138,4752.0
47.518434945,4833.0
47.568568752,4776.0
47.618702559,4926.0
47.668836366,4754.0
47.718970173,4785.0
47.769103980,4818.0
47.819237787,4824.0
47.869371594,4815.0
47.919505401,4667.0
47.969639208,4879.0
48.019773014,4913.0
48.069906821,4868.0
48.120040628,4951.0
48.170174435,4947.0
48.220308242,4907.0
48.270442049,5100.0
48.320575856,5158.0
48.370709663,5370.0
48.420843470,5541.0
48.470977277,5605.0
48.521111084,5484.0
48.571244891,5252.0
48.621378698,5364.0
48.671512505,5439.0
48.721646312,5548.0
48.771780119,5562.0
48.821913925,5480.0
48.872047732,5547.0
48.922181539,5408.0
48.972315346,5507.0
49.022449153,5786.0
49.072582960,5738.0
49.122716767,5607.0
49.172850574,5586.0
49.222984381,5682.0
49.273118188,5613.0
49.323251995,5530.0
49.373385802,5513.0
49.423519609,5542.0
49.473653416,5750.0
49.523787223,5857.0
49.573921030,5839.0
49.624054836,5953.0
49.674188643,6191.0
49.724322450,6335.0
49.774456257,6872.0
49.824590064,7931.0
49.874723871,10462.0
49.924857678,13728.0
49.974991485,15760.0
50.025125292,20691.0
50.075259099,40160.0
50.125392906,127681.0
50.175526713,352982.0
50.225660520,141502.0
50.275794327,120983.0
50.325928134,165406.0
50.376061941,44146.0
50.426195747,17766.0
50.476329554,12179.0
50.526463361,9522.0
50.576597168,7712.0
50.626730975,7012.0
50.676864782,6384.0
50.726998589,6366.0
50.777132396,6018.0
50.827266203,6080.0
50.877400010,5899.0
50.927533817,5553.0
50.977667624,5591.0
51.027801431,5549.0
51.077935238,5405.0
51.128069045,5503.0
51.178202852,5370.0
51.228336658,5359.0
51.278470465,5231.0
51.328604272,5247.0
51.378738079,5277.0
51.428871886,5204.0
51.479005693,5192.0
51.529139500,4992.0
51.579273307,5121.0
51.629407114,5100.0
51.679540921,5024.0
51.729674728,5010.0
51.779808535,4937.0
51.829942342,5000.0
51.880076149,5127.0
51.930209956,5037.0
51.980343763,4960.0
52.030477569,5084.0
52.080611376,4950.0
52.130745183,5049.0
52.180878990,4954.0
52.231012797,4892.0
52.281146604,5027.0
52.331280411,4999.0
52.381414218,4988.0
52.431548025,5021.0
52.481681832,4907.0
52.531815639,4867.0
52.581949446,4903.0
52.632083253,4980.0
52.682217060,4843.0
52.732350867,4904.0
52.782484674,4749.0
52.832618480,4793.0
52.882752287,4837.0
52.932886094,4947.0
52.983019901,4842.0
53.033153708,4775.0
53.083287515,4666.0
53.133421322,4789.0
53.183555129,4727.0
53.233688936,4748.0
53.283822743,4825.0
53.333956550,4750.0
53.384090357,4764.0
53.434224164,4808.0
53.484357971,4850.0
53.534491778,4750.0
53.584625585,4664.0
53.634759391,4770.0
53.684893198,4782.0
53.735027005,4683.0
53.785160812,4708.0
53.835294619,4718.0
53.885428426,4807.0
53.935562233,4687.0
53.985696040,4872.0
54.035829847,4649.0
54.085963654,4710.0
54.136097461,4774.0
54.186231268,4719.0
54.236365075,4719.0
54.286498882,4861.0
54.336632689,4902.0
54.386766496,4821.0
54.436900303,4690.0
54.487034109,4928.0
54.537167916,5055.0
54.587301723,5098.0
54.637435530,4864.0
54.687569337,4919.0
54.737703144,4838.0
54.787836951,4865.0
54.837970758,4661.0
54.888104565,4713.0
54.938238372,4815.0
54.988372179,4792.0
55.038505986,4691.0
55.088639793,4659.0
55.138773600,4680.0
55.188907407,4649.0
55.239041214,4693.0
55.289175020,4565.0
55.339308827,4541.0
55.389442634,4571.0
55.439576441,4633.0
55.489710248,4578.0
55.539844055,4598.0
55.589977862,4619.0
55.640111669,4534.0
55.690245476,4527.0
55.740379283,4665.0
55.790513090,4667.0
55.840646897,4516.0
55.890780704,4646.0
55.940914511,4588.0
55.991048318,4522.0
56.041182125,4573.0
56.091315931,4704.0
56.141449738,4618.0
56.191583545,4547.0
56.241717352,4557.0
56.291851159,4497.0
56.341984966,4583.0
56.392118773,4576.0
56.442252580,4503.0
56.492386387,4534.0
56.542520194,4527.0
56.592654001,4421.0
56.642787808,4432.0
56.692921615,4511.0
56.743055422,4320.0
56.793189229,4663.0
56.843323036,4487.0
56.893456842,4436.0
56.943590649,4504.0
56.993724456,4484.0
57.043858263,4596.0
57.093992070,4609.0
57.144125877,4482.0
57.194259684,4593.0
57.244393491,4406.0
57.294527298,4466.0
57.344661105,4589.0
57.394794912,4539.0
57.444928719,4509.0
57.495062526,4579.0
57.545196333,4557.0
57.595330140,4500.0
57.645463947,4518.0
57.695597753,4498.0
57.745731560,4465.0
57.795865367,4443.0
57.845999174,4518.0
57.896132981,4425.0
57.946266788,4586.0
57.996400595,4419.0
58.046534402,4446.0
58.096668209,4562.0
58.146802016,4378.0
58.196935823,4537.0
58.247069630,4443.0
58.297203437,4495.0
58.347337244,4419.0
58.397471051,4443.0
58.447604858,4416.0
58.497738664,4463.0
58.547872471,4622.0
58.598006278,4422.0
58.648140085,4565.0
58.698273892,4450.0
58.748407699,4394.0
58.798541506,4655.0
58.848675313,4419.0
58.898809120,4538.0
58.948942927,4491.0
58.999076734,4435.0
59.049210541,4477.0
59.099344348,4539.0
59.149478155,4402.0
59.199611962,4589.0
59.249745769,4433.0
59.299879575,4401.0
59.350013382,4625.0
59.400147189,4478.0
59.450280996,4450.0
59.500414803,4418.0
59.550548610,4520.0
59.600682417,4509.0
59.650816224,4470.0
59.700950031,4483.0
59.751083838,4482.0
59.801217645,4526.0
59.851351452,4540.0
59.901485259,4496.0
59.951619066,4562.0
60.001752873,4463.0
60.051886680,4426.0
60.102020486,4463.0
60.152154293,4450.0
60.202288100,4449.0
60.252421907,4633.0
60.302555714,4547.0
60.352689521,4467.0
60.402823328,4414.0
60.452957135,4557.0
60.503090942,4347.0
60.553224749,4443.0
60.603358556,4419.0
60.653492363,4466.0
60.703626170,4430.0
60.753759977,4388.0
60.803893784,4440.0
60.854027591,4550.0
60.904161397,4366.0
60.954295204,4503.0
61.004429011,4314.0
61.054562818,4383.0
61.104696625,4521.0
61.154830432,4503.0
61.204964239,4478.0
61.255098046,4421.0
61.305231853,4373.0
61.355365660,4502.0
61.405499467,4537.0
61.455633274,4549.0
61.505767081,4598.0
61.555900888,4405.0
61.606034695,4526.0
61.656168502,4472.0
61.706302308,4431.0
61.756436115,4479.0
61.806569922,4459.0
61.856703729,4304.0
61.906837536,4408.0
61.956971343,4571.0
62.007105150,4599.0
62.057238957,4362.0
62.107372764,4330.0
62.157506571,4508.0
62.207640378,4409.0
62.257774185,4439.0
62.307907992,4355.0
62.358041799,4352.0
62.408175606,4526.0
62.458309413,4276.0
62.508443219,4381.0
62.558577026,4361.0
62.608710833,4444.0
62.658844640,4426.0
62.708978447,4476.0
62.759112254,4412.0
62.809246061,4492.0
62.859379868,4356.0
62.909513675,4431.0
62.959647482,4305.0
63.009781289,4476.0
63.059915096,4593.0
63.110048903,4384.0
63.160182710,4436.0
63.210316517,4310.0
63.260450324,4456.0
63.310584130,4384.0
63.360717937,4414.0
63.410851744,4342.0
63.460985551,4401.0
63.511119358,4445.0
63.561253165,4454.0
63.611386972,4534.0
63.661520779,4364.0
63.711654586,4386.0
63.761788393,4458.0
63.811922200,4345.0
63.862056007,4290.0
63.912189814,4294.0
63.962323621,4476.0
64.012457428,4376.0
64.062591235,4483.0
64.112725041,4445.0
64.162858848,4410.0
64.212992655,4352.0
64.263126462,4521.0
64.313260269,4416.0
64.363394076,4393.0
64.413527883,4483.0
64.463661690,4362.0
64.513795497,4466.0
64.563929304,4393.0
64.614063111,4491.0
64.664196918,4193.0
64.714330725,4438.0
64.764464532,4440.0
64.814598339,4452.0
64.864732146,4342.0
64.914865953,4437.0
64.964999759,4551.0
65.015133566,4402.0
65.065267373,4378.0
65.115401180,4521.0
65.165534987,4383.0
65.215668794,4440.0
65.265802601,4428.0
65.315936408,4484.0
65.366070215,4496.0
65.416204022,4398.0
65.466337829,4392.0
65.516471636,4418.0
65.566605443,4527.0
65.616739250,4457.0
65.666873057,4475.0
65.717006864,4636.0
65.767140670,4395.0
65.817274477,4340.0
65.867408284,4508.0
65.917542091,4315.0
65.967675898,4513.0
66.017809705,4465.0
66.067943512,4512.0
66.118077319,4386.0
66.168211126,4384.0
66.218344933,4440.0
66.268478740,4392.0
66.318612547,4257.0
66.368746354,4403.0
66.418880161,4373.0
66.469013968,4266.0
66.519147775,4337.0
66.569281581,4353.0
66.619415388,4240.0
66.669549195,4449.0
66.719683002,4374.0
66.769816809,4380.0
66.819950616,4471.0
66.870084423,4366.0
66.920218230,4472.0
66.970352037,4393.0
67.020485844,4448.0
67.070619651,4493.0
67.120753458,4470.0
67.170887265,4396.0
67.221021072,4438.0
67.271154879,4261.0
67.321288686,4350.0
67.371422492,4394.0
67.421556299,4373.0
67.471690106,4405.0
67.521823913,4362.0
67.571957720,4418.0
67.622091527,4320.0
67.672225334,4326.0
67.722359141,4302.0
67.772492948,4409.0
67.822626755,4567.0
67.872760562,4568.0
67.922894369,4781.0
67.973028176,4570.0
68.023161983,4427.0
68.073295790,4518.0
68.123429597,4616.0
68.173563403,4396.0
68.223697210,4373.0
68.273831017,4345.0
68.323964824,4357.0
68.374098631,4598.0
68.424232438,4470.0
68.474366245,4387.0
68.524500052,4508.0
68.574633859,4319.0
68.624767666,4329.0
68.674901473,4365.0
68.725035280,4389.0
68.775169087,4282.0
68.825302894,4404.0
68.875436701,4365.0
68.925570508,4500.0
68.975704314,4462.0
69.025838121,4388.0
69.075971928,4373.0
69.126105735,4295.0
69.176239542,4413.0
69.226373349,4349.0
69.276507156,4358.0
69.326640963,4252.0
69.376774770,4435.0
69.426908577,4337.0
69.477042384,4480.0
69.527176191,4437.0
69.577309998,4384.0
69.627443805,4386.0
69.677577612,4385.0
69.727711419,4283.0
69.777845225,4397.0
69.827979032,4531.0
69.878112839,4580.0
69.928246646,4335.0
69.978380453,4356.0
70.028514260,4436.0
70.078648067,4340.0
70.128781874,4418.0
70.178915681,4432.0
70.229049488,4314.0
70.279183295,4441.0
70.329317102,4609.0
70.379450909,4480.0
70.429584716,4456.0
70.479718523,4348.0
70.529852330,4451.0
70.579986136,4543.0
70.630119943,4480.0
70.680253750,4492.0
70.730387557,4365.0
70.780521364,4575.0
70.830655171,4601.0
70.880788978,4433.0
70.930922785,4527.0
70.981056592,4649.0
71.031190399,4499.0
71.081324206,4537.0
71.131458013,4464.0
71.181591820,4511.0
71.231725627,4459.0
71.281859434,4519.0
71.331993241,4425.0
71.382127047,4509.0
71.432260854,4379.0
71.482394661,4495.0
71.532528468,4656.0
71.582662275,4369.0
71.632796082,4521.0
71.682929889,4614.0
71.733063696,4463.0
71.783197503,4558.0
71.833331310,4483.0
71.883465117,4548.0
71.933598924,4497.0
71.983732731,4481.0
72.033866538,4490.0
72.084000345,4468.0
72.134134152,4478.0
72.184267958,4440.0
72.234401765,4464.0
72.284535572,4573.0
72.334669379,4494.0
72.384803186,4633.0
72.434936993,4561.0
72.485070800,4491.0
72.535204607,4561.0
72.585338414,4496.0
72.635472221,4560.0
72.685606028,4552.0
72.735739835,4526.0
72.785873642,4526.0
72.836007449,4612.0
72.886141256,4559.0
72.936275063,4555.0
72.986408869,4682.0
73.036542676,4662.0
73.086676483,4556.0
73.136810290,4727.0
73.186944097,4506.0
73.237077904,4795.0
73.287211711,4836.0
73.337345518,4837.0
73.387479325,5227.0
73.437613132,5530.0
73.487746939,5631.0
73.537880746,5879.0
73.588014553,6097.0
73.638148360,7027.0
73.688282167,9424.0
73.738415974,19447.0
73.788549780,57784.0
73.838683587,42669.0
73.888817394,15174.0
73.938951201,12826.0
73.989085008,25606.0
74.039218815,30673.0
74.089352622,12147.0
74.139486429,7255.0
74.189620236,6016.0
74.239754043,5365.0
74.289887850,5178.0
74.340021657,4938.0
74.390155464,4875.0
74.440289271,4764.0
74.490423078,4719.0
74.540556885,4785.0
74.590690692,4605.0
74.640824498,4537.0
74.690958305,4715.0
74.741092112,4597.0
74.791225919,4633.0
74.841359726,4604.0
74.891493533,4612.0
74.941627340,4507.0
74.991761147,4489.0
75.041894954,4574.0
75.092028761,4581.0
75.142162568,4656.0
75.192296375,4528.0
75.242430182,4646.0
75.292563989,4486.0
75.342697796,4570.0
75.392831603,4615.0
75.442965409,4550.0
75.493099216,4488.0
75.543233023,4517.0
75.593366830,4492.0
75.643500637,4529.0
75.693634444,4478.0
75.743768251,4575.0
75.793902058,4495.0
75.844035865,4549.0
75.894169672,4442.0
75.944303479,4483.0
75.994437286,4455.0
76.044571093,4366.0
76.094704900,4427.0
76.144838707,4369.0
76.194972514,4439.0
76.245106320,4431.0
76.295240127,4444.0
76.345373934,4421.0
76.395507741,4400.0
76.445641548,4527.0
76.495775355,4426.0
76.545909162,4462.0
76.596042969,4438.0
76.646176776,4534.0
76.696310583,4405.0
76.746444390,4310.0
76.796578197,4495.0
76.846712004,4547.0
76.896845811,4351.0
76.946979618,4547.0
76.997113425,4343.0
77.047247231,4361.0
77.097381038,4349.0
77.147514845,4504.0
77.197648652,4375.0
77.247782459,4494.0
77.297916266,4380.0
77.348050073,4433.0
77.398183880,4483.0
77.448317687,4534.0
77.498451494,4513.0
77.548585301,4573.0
77.598719108,4514.0
77.648852915,4436.0
77.698986722,4385.0
77.749120529,4471.0
77.799254336,4418.0
77.849388142,4498.0
77.899521949,4410.0
77.949655756,4363.0
77.999789563,4535.0
78.049923370,4446.0
78.100057177,4307.0
78.150190984,4444.0
78.200324791,4418.0
78.250458598,4405.0
78.300592405,4266.0
78.350726212,4501.0
78.400860019,4542.0
78.450993826,4513.0
78.501127633,4418.0
78.551261440,4470.0
78.601395247,4481.0
78.651529053,4441.0
78.701662860,4501.0
78.751796667,4374.0
78.801930474,4448.0
78.852064281,4464.0
78.902198088,4481.0
78.952331895,4531.0
79.002465702,4464.0
79.052599509,4569.0
79.102733316,4384.0
79.152867123,4408.0
79.203000930,4408.0
79.253134737,4447.0
79.303268544,4346.0
79.353402351,4474.0
79.403536158,4419.0
79.453669964,4379.0
79.503803771,4323.0
79.553937578,4327.0
79.604071385,4306.0
79.654205192,4397.0
79.704338999,4429.0
79.754472806,4447.0
79.804606613,4319.0
79.854740420,4471.0
79.904874227,4447.0
79.955008034,4406.0
80.005141841,4433.0
80.055275648,4378.0
80.105409455,4368.0
80.155543262,4546.0
80.205677069,4382.0
80.255810875,4399.0
80.305944682,4390.0
80.356078489,4291.0
80.406212296,4471.0
80.456346103,4384.0
80.506479910,4319.0
80.556613717,4442.0
80.606747524,4315.0
80.656881331,4280.0
80.707015138,4514.0
80.757148945,4465.0
80.807282752,4618.0
80.857416559,4481.0
80.907550366,4487.0
80.957684173,4458.0
81.007817980,4430.0
81.057951786,4499.0
81.108085593,4416.0
81.158219400,4461.0
81.208353207,4410.0
81.258487014,4449.0
81.308620821,4332.0
81.358754628,4475.0
81.408888435,4392.0
81.459022242,4408.0
81.509156049,4442.0
81.559289856,4329.0
81.609423663,4551.0
81.659557470,4451.0
81.709691277,4415.0
81.759825084,4393.0
81.809958891,4504.0
81.860092697,4524.0
81.910226504,4578.0
81.960360311,4506.0
82.010494118,4399.0
82.060627925,4417.0
82.110761732,4390.0
82.160895539,4517.0
82.211029346,4411.0
82.261163153,4426.0
82.311296960,4442.0
82.361430767,4329.0
82.411564574,4478.0
82.461698381,4386.0
82.511832188,4258.0
82.561965995,4517.0
82.612099802,4502.0
82.662233608,4419.0
82.712367415,4486.0
82.762501222,4499.0
82.812635029,4397.0
82.862768836,4344.0
82.912902643,4419.0
82.963036450,4316.0
83.013170257,4460.0
83.063304064,4352.0
83.113437871,4425.0
83.163571678,4502.0
83.213705485,4454.0
83.263839292,4442.0
83.313973099,4550.0
83.364106906,4426.0
83.414240713,4344.0
83.464374519,4421.0
83.514508326,4318.0
83.564642133,4324.0
83.614775940,4400.0
83.664909747,4361.0
83.715043554,4362.0
83.765177361,4415.0
83.815311168,4270.0
83.865444975,4390.0
83.915578782,4435.0
83.965712589,4354.0
84.015846396,4430.0
84.065980203,4291.0
84.116114010,4452.0
84.166247817,4414.0
84.216381624,4457.0
84.266515431,4349.0
84.316649237,4415.0
84.366783044,4336.0
84.416916851,4524.0
84.467050658,4579.0
84.517184465,4436.0
84.567318272,4397.0
84.617452079,4410.0
84.667585886,4432.0
84.717719693,4322.0
84.767853500,4379.0
84.817987307,4548.0
84.868121114,4425.0
84.918254921,4337.0
84.968388728,4372.0
85.018522535,4441.0
85.068656342,4530.0
85.118790148,4391.0
85.168923955,4314.0
85.219057762,4372.0
85.269191569,4308.0
85.319325376,4319.0
85.369459183,4488.0
85.419592990,4436.0
85.469726797,4407.0
85.519860604,4525.0
85.569994411,4508.0
85.620128218,4274.0
85.670262025,4426.0
85.720395832,4358.0
85.770529639,4441.0
85.820663446,4332.0
85.870797253,4499.0
85.920931059,4316.0
85.971064866,4377.0
86.021198673,4395.0
86.071332480,4593.0
86.121466287,4532.0
86.171600094,4367.0
86.221733901,4491.0
86.271867708,4479.0
86.322001515,4403.0
86.372135322,4455.0
86.422269129,4388.0
86.472402936,4350.0
86.522536743,4465.0
86.572670550,4453.0
86.622804357,4568.0
86.672938164,4337.0
86.723071970,4387.0
86.773205777,4481.0
86.823339584,4346.0
86.873473391,4353.0
86.923607198,4448.0
86.973741005,4352.0
87.023874812,4306.0
87.074008619,4263.0
87.124142426,4412.0
87.174276233,4326.0
87.224410040,4423.0
87.274543847,4411.0
87.324677654,4510.0
87.374811461,4381.0
87.424945268,4495.0
87.475079075,4437.0
87.525212881,4342.0
87.575346688,4428.0
87.625480495,4412.0
87.675614302,4265.0
87.725748109,4544.0
87.775881916,4482.0
87.826015723,4353.0
87.876149530,4402.0
87.926283337,4425.0
87.976417144,4465.0
88.026550951,4536.0
88.076684758,4445.0
88.126818565,4428.0
88.176952372,4411.0
88.227086179,4501.0
88.277219986,4444.0
88.327353792,4282.0
88.377487599,4374.0
88.427621406,4390.0
88.477755213,4455.0
88.527889020,4464.0
88.578022827,4392.0
88.628156634,4547.0
88.678290441,4553.0
88.728424248,4549.0
88.778558055,4561.0
88.828691862,4403.0
88.878825669,4449.0
88.928959476,4464.0
88.979093283,4488.0
89.029227090,4533.0
89.079360897,4595.0
89.129494703,4728.0
89.179628510,4640.0
89.229762317,4665.0
89.279896124,4917.0
89.330029931,5152.0
89.380163738,5681.0
89.430297545,6110.0
89.480431352,8093.0
89.530565159,14519.0
89.580698966,22253.0
89.630832773,13444.0
89.680966580,7958.0
89.731100387,7049.0
89.781234194,7847.0
89.831368001,11486.0
89.881501808,12374.0
89.931635614,7862.0
89.981769421,5802.0
90.031903228,5166.0
90.082037035,5015.0
90.132170842,4776.0
90.182304649,4684.0
90.232438456,4607.0
90.282572263,4553.0
90.332706070,4572.0
90.382839877,4396.0
90.432973684,4445.0
90.483107491,4495.0
90.533241298,4515.0
90.583375105,4302.0
90.633508912,4454.0
90.683642719,4601.0
90.733776525,4472.0
90.783910332,4496.0
90.834044139,4484.0
90.884177946,4525.0
90.934311753,4439.0
90.984445560,4447.0
91.034579367,4366.0
91.084713174,4516.0
91.134846981,4453.0
91.184980788,4495.0
91.235114595,4406.0
91.285248402,4638.0
91.335382209,4496.0
91.385516016,4416.0
91.435649823,4608.0
91.485783630,4575.0
91.535917436,4495.0
91.586051243,4331.0
91.636185050,4483.0
91.686318857,4371.0
91.736452664,4367.0
91.786586471,4563.0
91.836720278,4498.0
91.886854085,4554.0
91.936987892,4565.0
91.987121699,4553.0
92.037255506,4438.0
92.087389313,4401.0
92.137523120,4441.0
92.187656927,4338.0
92.237790734,4318.0
92.287924541,4383.0
92.338058347,4431.0
92.388192154,4504.0
92.438325961,4543.0
92.488459768,4386.0
92.538593575,4475.0
92.588727382,4502.0
92.638861189,4372.0
92.688994996,4441.0
92.739128803,4352.0
92.789262610,4419.0
92.839396417,4381.0
92.889530224,4308.0
92.939664031,4408.0
92.989797838,4443.0
93.039931645,4384.0
93.090065452,4469.0
93.140199258,4509.0
93.190333065,4356.0
93.240466872,4546.0
93.290600679,4378.0
93.340734486,4479.0
93.390868293,4515.0
93.441002100,4346.0
93.491135907,4436.0
93.541269714,4388.0
93.591403521,4413.0
93.641537328,4485.0
93.691671135,4434.0
93.741804942,4526.0
93.791938749,4523.0
93.842072556,4431.0
93.892206363,4500.0
93.942340170,4480.0
93.992473976,4494.0
94.042607783,4421.0
94.092741590,4605.0
94.142875397,4573.0
94.193009204,4500.0
94.243143011,4654.0
94.293276818,4524.0
94.343410625,4626.0
94.393544432,4712.0
94.443678239,4660.0
94.493812046,5047.0
94.543945853,5139.0
94.594079660,5507.0
94.644213467,6249.0
94.694347274,9180.0
94.744481081,20115.0
94.794614887,21178.0
94.844748694,10524.0
94.894882501,6914.0
94.945016308,6210.0
94.995150115,6943.0
95.045283922,10861.0
95.095417729,13830.0
95.145551536,8473.0
95.195685343,5786.0
95.245819150,5183.0
95.295952957,4991.0
95.346086764,4832.0
95.396220571,4656.0
95.446354378,4556.0
95.496488185,4488.0
95.546621992,4574.0
95.596755798,4565.0
95.646889605,4441.0
95.697023412,4473.0
95.747157219,4421.0
95.797291026,4494.0
95.847424833,4492.0
95.897558640,4499.0
95.947692447,4496.0
95.997826254,4423.0
96.047960061,4354.0
96.098093868,4525.0
96.148227675,4432.0
96.198361482,4501.0
96.248495289,4431.0
96.298629096,4410.0
96.348762903,4530.0
96.398896709,4489.0
96.449030516,4284.0
96.499164323,4436.0
96.549298130,4442.0
96.599431937,4573.0
96.649565744,4353.0
96.699699551,4346.0
96.749833358,4335.0
96.799967165,4389.0
96.850100972,4344.0
96.900234779,4343.0
96.950368586,4335.0
97.000502393,4492.0
97.050636200,4425.0
97.100770007,4564.0
97.150903814,4345.0
97.201037620,4386.0
97.251171427,4436.0
97.301305234,4477.0
97.351439041,4329.0
97.401572848,4463.0
97.451706655,4488.0
97.501840462,4465.0
97.551974269,4317.0
97.602108076,4307.0
97.652241883,4392.0
97.702375690,4362.0
97.752509497,4344.0
97.802643304,4383.0
97.852777111,4443.0
97.902910918,4432.0
97.953044725,4468.0
98.003178531,4451.0
98.053312338,4405.0
98.103446145,4428.0
98.153579952,4599.0
98.203713759,4374.0
98.253847566,4390.0
98.303981373,4408.0
98.354115180,4353.0
98.404248987,4410.0
98.454382794,4518.0
98.504516601,4427.0
98.554650408,4362.0
98.604784215,4284.0
98.654918022,4501.0
98.705051829,4440.0
98.755185636,4352.0
98.805319442,4373.0
98.855453249,4427.0
98.905587056,4523.0
98.955720863,4362.0
99.005854670,4365.0
99.055988477,4327.0
99.106122284,4479.0
99.156256091,4238.0
99.206389898,4355.0
99.256523705,4244.0
99.306657512,4364.0
99.356791319,4486.0
99.406925126,4436.0
99.457058933,4365.0
99.507192740,4269.0
99.557326547,4364.0
99.607460353,4330.0
99.657594160,4346.0
99.707727967,4478.0
99.757861774,4374.0
99.807995581,4352.0
99.858129388,4243.0
99.908263195,4415.0
99.958397002,4479.0
99.991819540,4378.0