File: OriginPro/XRD from Panalytical X'Pert PRO/Nova Cu foil/Cufoil_400°C.csv
[Measurement conditions]
Sample identification,
Comment - 1,"finito"
Comment - 2,"Configuration=MRI TC-Basic Stage, Owner=User-1, Creation date=26-10-2009 9:18:44"
Comment - 3,"Goniometer=PW3050/60 (Theta/Theta); Minimum step size 2Theta:0.001; Minimum step size Omega:0.001"
Comment - 4,"Sample stage=MRI TC-Basic (PtRh heat strip)"
Comment - 5,"Diffractometer system=XPERT-PRO"
Comment - 6,"Measurement program=FlatStage, Owner=joana, Creation date=03-08-2011 15:43:53"
Anode material,Cu
K-Alpha1 wavelength,1.5405980
K-Alpha2 wavelength,1.5444260
Ratio K-Alpha2/K-Alpha1,0.500
Divergence slit,Fixed,0.76mm
Monochromator used,NO
Generator voltage, 45
Tube current, 40
File date and time,06/Dec/2012 23:39
Unit cell,
h k l, 0 0 0
Temperature [K],673
Scan axis,Gonio
Scan range,24.999999996,100.000175174
Scan step size,0.0167113
No. of points, 4488
Scan type,CONTINUOUS
Time per step,53.340
[Scan points]
Angle,Intensity
25.008355630,590.0
25.058489437,591.0
25.108623244,569.0
25.158757051,557.0
25.208890858,649.0
25.259024665,625.0
25.309158472,647.0
25.359292279,601.0
25.409426086,684.0
25.459559892,636.0
25.509693699,709.0
25.559827506,640.0
25.609961313,658.0
25.660095120,641.0
25.710228927,657.0
25.760362734,625.0
25.810496541,666.0
25.860630348,676.0
25.910764155,718.0
25.960897962,633.0
26.011031769,708.0
26.061165576,634.0
26.111299383,695.0
26.161433190,724.0
26.211566997,684.0
26.261700803,702.0
26.311834610,678.0
26.361968417,741.0
26.412102224,683.0
26.462236031,695.0
26.512369838,690.0
26.562503645,741.0
26.612637452,729.0
26.662771259,733.0
26.712905066,747.0
26.763038873,729.0
26.813172680,740.0
26.863306487,763.0
26.913440294,723.0
26.963574101,744.0
27.013707908,747.0
27.063841714,801.0
27.113975521,753.0
27.164109328,756.0
27.214243135,715.0
27.264376942,838.0
27.314510749,832.0
27.364644556,710.0
27.414778363,788.0
27.464912170,769.0
27.515045977,811.0
27.565179784,782.0
27.615313591,765.0
27.665447398,841.0
27.715581205,843.0
27.765715012,855.0
27.815848819,794.0
27.865982625,817.0
27.916116432,852.0
27.966250239,869.0
28.016384046,794.0
28.066517853,860.0
28.116651660,896.0
28.166785467,818.0
28.216919274,902.0
28.267053081,858.0
28.317186888,851.0
28.367320695,812.0
28.417454502,904.0
28.467588309,877.0
28.517722116,831.0
28.567855923,902.0
28.617989730,876.0
28.668123536,954.0
28.718257343,857.0
28.768391150,879.0
28.818524957,920.0
28.868658764,890.0
28.918792571,859.0
28.968926378,924.0
29.019060185,966.0
29.069193992,856.0
29.119327799,1043.0
29.169461606,887.0
29.219595413,995.0
29.269729220,968.0
29.319863027,974.0
29.369996834,1006.0
29.420130641,983.0
29.470264447,1019.0
29.520398254,1012.0
29.570532061,949.0
29.620665868,962.0
29.670799675,978.0
29.720933482,903.0
29.771067289,924.0
29.821201096,927.0
29.871334903,956.0
29.921468710,971.0
29.971602517,930.0
30.021736324,985.0
30.071870131,945.0
30.122003938,965.0
30.172137745,979.0
30.222271552,988.0
30.272405358,938.0
30.322539165,957.0
30.372672972,986.0
30.422806779,992.0
30.472940586,1003.0
30.523074393,1079.0
30.573208200,1037.0
30.623342007,1025.0
30.673475814,969.0
30.723609621,1017.0
30.773743428,1064.0
30.823877235,1043.0
30.874011042,1078.0
30.924144849,1035.0
30.974278656,1022.0
31.024412463,1057.0
31.074546269,992.0
31.124680076,1101.0
31.174813883,1022.0
31.224947690,1041.0
31.275081497,1025.0
31.325215304,1126.0
31.375349111,1062.0
31.425482918,1049.0
31.475616725,1029.0
31.525750532,1089.0
31.575884339,1091.0
31.626018146,1016.0
31.676151953,1015.0
31.726285760,1084.0
31.776419567,1065.0
31.826553374,1174.0
31.876687180,1096.0
31.926820987,1136.0
31.976954794,1158.0
32.027088601,1130.0
32.077222408,1133.0
32.127356215,1126.0
32.177490022,1163.0
32.227623829,1082.0
32.277757636,1158.0
32.327891443,1113.0
32.378025250,1103.0
32.428159057,1133.0
32.478292864,1141.0
32.528426671,1123.0
32.578560478,1127.0
32.628694285,1204.0
32.678828091,1124.0
32.728961898,1149.0
32.779095705,1122.0
32.829229512,1180.0
32.879363319,1167.0
32.929497126,1147.0
32.979630933,1180.0
33.029764740,1208.0
33.079898547,1200.0
33.130032354,1150.0
33.180166161,1209.0
33.230299968,1195.0
33.280433775,1228.0
33.330567582,1171.0
33.380701389,1156.0
33.430835196,1141.0
33.480969002,1209.0
33.531102809,1214.0
33.581236616,1257.0
33.631370423,1185.0
33.681504230,1248.0
33.731638037,1216.0
33.781771844,1223.0
33.831905651,1179.0
33.882039458,1310.0
33.932173265,1210.0
33.982307072,1252.0
34.032440879,1275.0
34.082574686,1215.0
34.132708493,1216.0
34.182842300,1267.0
34.232976107,1294.0
34.283109913,1281.0
34.333243720,1269.0
34.383377527,1309.0
34.433511334,1232.0
34.483645141,1266.0
34.533778948,1248.0
34.583912755,1312.0
34.634046562,1332.0
34.684180369,1305.0
34.734314176,1324.0
34.784447983,1231.0
34.834581790,1296.0
34.884715597,1303.0
34.934849404,1305.0
34.984983211,1364.0
35.035117018,1371.0
35.085250825,1404.0
35.135384631,1380.0
35.185518438,1411.0
35.235652245,1499.0
35.285786052,1449.0
35.335919859,1501.0
35.386053666,1512.0
35.436187473,1490.0
35.486321280,1462.0
35.536455087,1400.0
35.586588894,1425.0
35.636722701,1493.0
35.686856508,1456.0
35.736990315,1483.0
35.787124122,1561.0
35.837257929,1616.0
35.887391736,1759.0
35.937525542,1912.0
35.987659349,2125.0
36.037793156,2352.0
36.087926963,2601.0
36.138060770,2872.0
36.188194577,2935.0
36.238328384,2858.0
36.288462191,2677.0
36.338595998,2442.0
36.388729805,2292.0
36.438863612,2117.0
36.488997419,1928.0
36.539131226,1875.0
36.589265033,1680.0
36.639398840,1649.0
36.689532647,1632.0
36.739666453,1587.0
36.789800260,1528.0
36.839934067,1470.0
36.890067874,1456.0
36.940201681,1472.0
36.990335488,1436.0
37.040469295,1452.0
37.090603102,1456.0
37.140736909,1511.0
37.190870716,1468.0
37.241004523,1492.0
37.291138330,1469.0
37.341272137,1479.0
37.391405944,1483.0
37.441539751,1482.0
37.491673558,1499.0
37.541807364,1514.0
37.591941171,1419.0
37.642074978,1519.0
37.692208785,1480.0
37.742342592,1534.0
37.792476399,1571.0
37.842610206,1578.0
37.892744013,1455.0
37.942877820,1459.0
37.993011627,1582.0
38.043145434,1451.0
38.093279241,1562.0
38.143413048,1532.0
38.193546855,1618.0
38.243680662,1670.0
38.293814469,1633.0
38.343948275,1665.0
38.394082082,1674.0
38.444215889,1761.0
38.494349696,1653.0
38.544483503,1772.0
38.594617310,1886.0
38.644751117,1716.0
38.694884924,1635.0
38.745018731,1638.0
38.795152538,1618.0
38.845286345,1667.0
38.895420152,1573.0
38.945553959,1562.0
38.995687766,1586.0
39.045821573,1520.0
39.095955380,1624.0
39.146089186,1565.0
39.196222993,1518.0
39.246356800,1557.0
39.296490607,1665.0
39.346624414,1566.0
39.396758221,1593.0
39.446892028,1561.0
39.497025835,1569.0
39.547159642,1673.0
39.597293449,1684.0
39.647427256,1736.0
39.697561063,1730.0
39.747694870,2039.0
39.797828677,2042.0
39.847962484,2030.0
39.898096291,1848.0
39.948230097,1730.0
39.998363904,1707.0
40.048497711,1625.0
40.098631518,1692.0
40.148765325,1620.0
40.198899132,1684.0
40.249032939,1658.0
40.299166746,1619.0
40.349300553,1651.0
40.399434360,1680.0
40.449568167,1635.0
40.499701974,1622.0
40.549835781,1609.0
40.599969588,1600.0
40.650103395,1654.0
40.700237202,1701.0
40.750371008,1713.0
40.800504815,1722.0
40.850638622,1638.0
40.900772429,1706.0
40.950906236,1726.0
41.001040043,1721.0
41.051173850,1686.0
41.101307657,1718.0
41.151441464,1710.0
41.201575271,1730.0
41.251709078,1735.0
41.301842885,1861.0
41.351976692,1843.0
41.402110499,1922.0
41.452244306,2014.0
41.502378113,2110.0
41.552511919,2202.0
41.602645726,2146.0
41.652779533,2257.0
41.702913340,2293.0
41.753047147,2310.0
41.803180954,2292.0
41.853314761,2341.0
41.903448568,2375.0
41.953582375,2412.0
42.003716182,2340.0
42.053849989,2380.0
42.103983796,2382.0
42.154117603,2242.0
42.204251410,2402.0
42.254385217,2302.0
42.304519024,2308.0
42.354652830,2268.0
42.404786637,2310.0
42.454920444,2248.0
42.505054251,2361.0
42.555188058,2363.0
42.605321865,2550.0
42.655455672,3257.0
42.705589479,3833.0
42.755723286,4619.0
42.805857093,7760.0
42.855990900,24980.0
42.906124707,85952.0
42.956258514,46524.0
43.006392321,49972.0
43.056526128,34085.0
43.106659935,14735.0
43.156793741,8261.0
43.206927548,5382.0
43.257061355,4012.0
43.307195162,3291.0
43.357328969,2865.0
43.407462776,2649.0
43.457596583,2554.0
43.507730390,2479.0
43.557864197,2454.0
43.607998004,2350.0
43.658131811,2312.0
43.708265618,2261.0
43.758399425,2324.0
43.808533232,2196.0
43.858667039,2193.0
43.908800846,2074.0
43.958934652,2178.0
44.009068459,2150.0
44.059202266,2147.0
44.109336073,2116.0
44.159469880,2145.0
44.209603687,2083.0
44.259737494,2114.0
44.309871301,2170.0
44.360005108,2122.0
44.410138915,2107.0
44.460272722,2128.0
44.510406529,2142.0
44.560540336,2098.0
44.610674143,2165.0
44.660807950,2283.0
44.710941757,2136.0
44.761075564,2215.0
44.811209370,2164.0
44.861343177,2303.0
44.911476984,2301.0
44.961610791,2221.0
45.011744598,2207.0
45.061878405,2038.0
45.112012212,2237.0
45.162146019,2089.0
45.212279826,2073.0
45.262413633,2169.0
45.312547440,2065.0
45.362681247,2067.0
45.412815054,2135.0
45.462948861,1994.0
45.513082668,2073.0
45.563216475,1961.0
45.613350281,2113.0
45.663484088,2108.0
45.713617895,2158.0
45.763751702,2173.0
45.813885509,2255.0
45.864019316,2191.0
45.914153123,2223.0
45.964286930,2224.0
46.014420737,2357.0
46.064554544,2495.0
46.114688351,2503.0
46.164822158,2767.0
46.214955965,3338.0
46.265089772,4784.0
46.315223579,8082.0
46.365357386,7074.0
46.415491192,5409.0
46.465624999,5433.0
46.515758806,3786.0
46.565892613,2443.0
46.616026420,2266.0
46.666160227,2338.0
46.716294034,2333.0
46.766427841,2278.0
46.816561648,2156.0
46.866695455,2175.0
46.916829262,2118.0
46.966963069,2102.0
47.017096876,2105.0
47.067230683,2061.0
47.117364490,2081.0
47.167498297,2063.0
47.217632103,2092.0
47.267765910,2128.0
47.317899717,2111.0
47.368033524,2113.0
47.418167331,2128.0
47.468301138,2123.0
47.518434945,2143.0
47.568568752,2071.0
47.618702559,2012.0
47.668836366,2086.0
47.718970173,2109.0
47.769103980,2123.0
47.819237787,2169.0
47.869371594,2123.0
47.919505401,2184.0
47.969639208,2186.0
48.019773014,2151.0
48.069906821,2117.0
48.120040628,2119.0
48.170174435,2188.0
48.220308242,2324.0
48.270442049,2249.0
48.320575856,2327.0
48.370709663,2394.0
48.420843470,2307.0
48.470977277,2318.0
48.521111084,2275.0
48.571244891,2396.0
48.621378698,2409.0
48.671512505,2331.0
48.721646312,2293.0
48.771780119,2320.0
48.821913925,2328.0
48.872047732,2430.0
48.922181539,2292.0
48.972315346,2336.0
49.022449153,2246.0
49.072582960,2349.0
49.122716767,2407.0
49.172850574,2366.0
49.222984381,2306.0
49.273118188,2402.0
49.323251995,2335.0
49.373385802,2419.0
49.423519609,2468.0
49.473653416,2496.0
49.523787223,2525.0
49.573921030,2461.0
49.624054836,2571.0
49.674188643,2709.0
49.724322450,3106.0
49.774456257,3665.0
49.824590064,4231.0
49.874723871,5565.0
49.924857678,13566.0
49.974991485,48852.0
50.025125292,59602.0
50.075259099,28662.0
50.125392906,37464.0
50.175526713,25211.0
50.225660520,10011.0
50.275794327,5830.0
50.325928134,4509.0
50.376061941,3850.0
50.426195747,3477.0
50.476329554,3159.0
50.526463361,3130.0
50.576597168,2931.0
50.626730975,2861.0
50.676864782,2813.0
50.726998589,2611.0
50.777132396,2584.0
50.827266203,2507.0
50.877400010,2496.0
50.927533817,2379.0
50.977667624,2460.0
51.027801431,2318.0
51.077935238,2294.0
51.128069045,2390.0
51.178202852,2305.0
51.228336658,2295.0
51.278470465,2324.0
51.328604272,2245.0
51.378738079,2350.0
51.428871886,2318.0
51.479005693,2387.0
51.529139500,2489.0
51.579273307,2372.0
51.629407114,2374.0
51.679540921,2397.0
51.729674728,2376.0
51.779808535,2261.0
51.829942342,2358.0
51.880076149,2339.0
51.930209956,2352.0
51.980343763,2316.0
52.030477569,2325.0
52.080611376,2355.0
52.130745183,2318.0
52.180878990,2419.0
52.231012797,2349.0
52.281146604,2259.0
52.331280411,2328.0
52.381414218,2213.0
52.431548025,2316.0
52.481681832,2354.0
52.531815639,2301.0
52.581949446,2319.0
52.632083253,2234.0
52.682217060,2246.0
52.732350867,2257.0
52.782484674,2257.0
52.832618480,2279.0
52.882752287,2273.0
52.932886094,2193.0
52.983019901,2312.0
53.033153708,2326.0
53.083287515,2251.0
53.133421322,2296.0
53.183555129,2243.0
53.233688936,2308.0
53.283822743,2309.0
53.333956550,2266.0
53.384090357,2258.0
53.434224164,2326.0
53.484357971,2318.0
53.534491778,2272.0
53.584625585,2226.0
53.634759391,2269.0
53.684893198,2270.0
53.735027005,2356.0
53.785160812,2247.0
53.835294619,2318.0
53.885428426,2354.0
53.935562233,2160.0
53.985696040,2309.0
54.035829847,2382.0
54.085963654,2215.0
54.136097461,2330.0
54.186231268,2283.0
54.236365075,2297.0
54.286498882,2323.0
54.336632689,2367.0
54.386766496,2393.0
54.436900303,2268.0
54.487034109,2363.0
54.537167916,2428.0
54.587301723,2327.0
54.637435530,2270.0
54.687569337,2302.0
54.737703144,2191.0
54.787836951,2305.0
54.837970758,2322.0
54.888104565,2341.0
54.938238372,2234.0
54.988372179,2325.0
55.038505986,2236.0
55.088639793,2273.0
55.138773600,2162.0
55.188907407,2278.0
55.239041214,2274.0
55.289175020,2314.0
55.339308827,2373.0
55.389442634,2302.0
55.439576441,2312.0
55.489710248,2356.0
55.539844055,2290.0
55.589977862,2245.0
55.640111669,2225.0
55.690245476,2214.0
55.740379283,2298.0
55.790513090,2256.0
55.840646897,2287.0
55.890780704,2142.0
55.940914511,2240.0
55.991048318,2298.0
56.041182125,2284.0
56.091315931,2276.0
56.141449738,2314.0
56.191583545,2463.0
56.241717352,2313.0
56.291851159,2244.0
56.341984966,2256.0
56.392118773,2310.0
56.442252580,2229.0
56.492386387,2261.0
56.542520194,2217.0
56.592654001,2327.0
56.642787808,2325.0
56.692921615,2220.0
56.743055422,2202.0
56.793189229,2316.0
56.843323036,2290.0
56.893456842,2373.0
56.943590649,2273.0
56.993724456,2302.0
57.043858263,2341.0
57.093992070,2276.0
57.144125877,2353.0
57.194259684,2309.0
57.244393491,2279.0
57.294527298,2252.0
57.344661105,2336.0
57.394794912,2210.0
57.444928719,2317.0
57.495062526,2315.0
57.545196333,2350.0
57.595330140,2307.0
57.645463947,2333.0
57.695597753,2225.0
57.745731560,2384.0
57.795865367,2374.0
57.845999174,2379.0
57.896132981,2322.0
57.946266788,2283.0
57.996400595,2376.0
58.046534402,2345.0
58.096668209,2329.0
58.146802016,2319.0
58.196935823,2374.0
58.247069630,2286.0
58.297203437,2290.0
58.347337244,2269.0
58.397471051,2249.0
58.447604858,2274.0
58.497738664,2224.0
58.547872471,2276.0
58.598006278,2360.0
58.648140085,2288.0
58.698273892,2336.0
58.748407699,2344.0
58.798541506,2289.0
58.848675313,2262.0
58.898809120,2230.0
58.948942927,2254.0
58.999076734,2314.0
59.049210541,2324.0
59.099344348,2361.0
59.149478155,2258.0
59.199611962,2283.0
59.249745769,2293.0
59.299879575,2257.0
59.350013382,2401.0
59.400147189,2280.0
59.450280996,2381.0
59.500414803,2264.0
59.550548610,2321.0
59.600682417,2313.0
59.650816224,2311.0
59.700950031,2321.0
59.751083838,2269.0
59.801217645,2347.0
59.851351452,2396.0
59.901485259,2279.0
59.951619066,2281.0
60.001752873,2375.0
60.051886680,2259.0
60.102020486,2331.0
60.152154293,2316.0
60.202288100,2240.0
60.252421907,2308.0
60.302555714,2337.0
60.352689521,2371.0
60.402823328,2381.0
60.452957135,2368.0
60.503090942,2356.0
60.553224749,2450.0
60.603358556,2391.0
60.653492363,2344.0
60.703626170,2457.0
60.753759977,2434.0
60.803893784,2588.0
60.854027591,2550.0
60.904161397,2548.0
60.954295204,2555.0
61.004429011,2519.0
61.054562818,2653.0
61.104696625,2482.0
61.154830432,2597.0
61.204964239,2623.0
61.255098046,2598.0
61.305231853,2563.0
61.355365660,2594.0
61.405499467,2524.0
61.455633274,2610.0
61.505767081,2461.0
61.555900888,2522.0
61.606034695,2521.0
61.656168502,2487.0
61.706302308,2401.0
61.756436115,2332.0
61.806569922,2359.0
61.856703729,2380.0
61.906837536,2420.0
61.956971343,2433.0
62.007105150,2427.0
62.057238957,2323.0
62.107372764,2351.0
62.157506571,2375.0
62.207640378,2473.0
62.257774185,2408.0
62.307907992,2335.0
62.358041799,2272.0
62.408175606,2297.0
62.458309413,2317.0
62.508443219,2237.0
62.558577026,2331.0
62.608710833,2390.0
62.658844640,2314.0
62.708978447,2388.0
62.759112254,2378.0
62.809246061,2361.0
62.859379868,2324.0
62.909513675,2308.0
62.959647482,2405.0
63.009781289,2308.0
63.059915096,2316.0
63.110048903,2320.0
63.160182710,2236.0
63.210316517,2298.0
63.260450324,2306.0
63.310584130,2363.0
63.360717937,2255.0
63.410851744,2327.0
63.460985551,2400.0
63.511119358,2266.0
63.561253165,2332.0
63.611386972,2321.0
63.661520779,2347.0
63.711654586,2293.0
63.761788393,2329.0
63.811922200,2313.0
63.862056007,2244.0
63.912189814,2336.0
63.962323621,2295.0
64.012457428,2254.0
64.062591235,2319.0
64.112725041,2312.0
64.162858848,2267.0
64.212992655,2356.0
64.263126462,2223.0
64.313260269,2259.0
64.363394076,2277.0
64.413527883,2442.0
64.463661690,2268.0
64.513795497,2260.0
64.563929304,2311.0
64.614063111,2360.0
64.664196918,2233.0
64.714330725,2281.0
64.764464532,2284.0
64.814598339,2327.0
64.864732146,2391.0
64.914865953,2341.0
64.964999759,2331.0
65.015133566,2251.0
65.065267373,2368.0
65.115401180,2356.0
65.165534987,2289.0
65.215668794,2303.0
65.265802601,2393.0
65.315936408,2354.0
65.366070215,2240.0
65.416204022,2301.0
65.466337829,2384.0
65.516471636,2251.0
65.566605443,2340.0
65.616739250,2235.0
65.666873057,2343.0
65.717006864,2391.0
65.767140670,2438.0
65.817274477,2371.0
65.867408284,2236.0
65.917542091,2417.0
65.967675898,2294.0
66.017809705,2356.0
66.067943512,2361.0
66.118077319,2442.0
66.168211126,2357.0
66.218344933,2347.0
66.268478740,2340.0
66.318612547,2386.0
66.368746354,2252.0
66.418880161,2293.0
66.469013968,2351.0
66.519147775,2293.0
66.569281581,2331.0
66.619415388,2330.0
66.669549195,2383.0
66.719683002,2308.0
66.769816809,2382.0
66.819950616,2325.0
66.870084423,2334.0
66.920218230,2375.0
66.970352037,2309.0
67.020485844,2287.0
67.070619651,2388.0
67.120753458,2415.0
67.170887265,2388.0
67.221021072,2277.0
67.271154879,2383.0
67.321288686,2298.0
67.371422492,2407.0
67.421556299,2435.0
67.471690106,2427.0
67.521823913,2355.0
67.571957720,2496.0
67.622091527,2820.0
67.672225334,3072.0
67.722359141,3306.0
67.772492948,3180.0
67.822626755,2743.0
67.872760562,2716.0
67.922894369,2754.0
67.973028176,2652.0
68.023161983,2517.0
68.073295790,2320.0
68.123429597,2376.0
68.173563403,2302.0
68.223697210,2400.0
68.273831017,2307.0
68.323964824,2307.0
68.374098631,2413.0
68.424232438,2275.0
68.474366245,2347.0
68.524500052,2311.0
68.574633859,2381.0
68.624767666,2414.0
68.674901473,2356.0
68.725035280,2247.0
68.775169087,2336.0
68.825302894,2360.0
68.875436701,2345.0
68.925570508,2326.0
68.975704314,2329.0
69.025838121,2384.0
69.075971928,2316.0
69.126105735,2405.0
69.176239542,2437.0
69.226373349,2395.0
69.276507156,2282.0
69.326640963,2349.0
69.376774770,2330.0
69.426908577,2305.0
69.477042384,2351.0
69.527176191,2378.0
69.577309998,2417.0
69.627443805,2357.0
69.677577612,2371.0
69.727711419,2360.0
69.777845225,2373.0
69.827979032,2317.0
69.878112839,2456.0
69.928246646,2302.0
69.978380453,2369.0
70.028514260,2415.0
70.078648067,2273.0
70.128781874,2408.0
70.178915681,2364.0
70.229049488,2302.0
70.279183295,2372.0
70.329317102,2420.0
70.379450909,2470.0
70.429584716,2385.0
70.479718523,2348.0
70.529852330,2373.0
70.579986136,2414.0
70.630119943,2300.0
70.680253750,2460.0
70.730387557,2446.0
70.780521364,2416.0
70.830655171,2370.0
70.880788978,2446.0
70.930922785,2516.0
70.981056592,2365.0
71.031190399,2448.0
71.081324206,2426.0
71.131458013,2293.0
71.181591820,2377.0
71.231725627,2455.0
71.281859434,2490.0
71.331993241,2530.0
71.382127047,2404.0
71.432260854,2501.0
71.482394661,2477.0
71.532528468,2450.0
71.582662275,2446.0
71.632796082,2390.0
71.682929889,2503.0
71.733063696,2415.0
71.783197503,2454.0
71.833331310,2458.0
71.883465117,2425.0
71.933598924,2464.0
71.983732731,2560.0
72.033866538,2471.0
72.084000345,2475.0
72.134134152,2540.0
72.184267958,2426.0
72.234401765,2436.0
72.284535572,2480.0
72.334669379,2548.0
72.384803186,2553.0
72.434936993,2414.0
72.485070800,2451.0
72.535204607,2599.0
72.585338414,2615.0
72.635472221,2571.0
72.685606028,2600.0
72.735739835,2603.0
72.785873642,2655.0
72.836007449,2580.0
72.886141256,2612.0
72.936275063,2663.0
72.986408869,2694.0
73.036542676,2716.0
73.086676483,2612.0
73.136810290,2733.0
73.186944097,2753.0
73.237077904,3025.0
73.287211711,2986.0
73.337345518,3123.0
73.387479325,3658.0
73.437613132,6381.0
73.487746939,12612.0
73.537880746,9468.0
73.588014553,6481.0
73.638148360,6174.0
73.688282167,8597.0
73.738415974,7848.0
73.788549780,5890.0
73.838683587,4949.0
73.888817394,4728.0
73.938951201,4431.0
73.989085008,4205.0
74.039218815,4061.0
74.089352622,3849.0
74.139486429,3611.0
74.189620236,3467.0
74.239754043,3289.0
74.289887850,3217.0
74.340021657,3067.0
74.390155464,2963.0
74.440289271,2858.0
74.490423078,2803.0
74.540556885,2787.0
74.590690692,2735.0
74.640824498,2760.0
74.690958305,2646.0
74.741092112,2669.0
74.791225919,2663.0
74.841359726,2618.0
74.891493533,2599.0
74.941627340,2581.0
74.991761147,2635.0
75.041894954,2642.0
75.092028761,2463.0
75.142162568,2560.0
75.192296375,2570.0
75.242430182,2556.0
75.292563989,2626.0
75.342697796,2673.0
75.392831603,2581.0
75.442965409,2554.0
75.493099216,2581.0
75.543233023,2549.0
75.593366830,2586.0
75.643500637,2465.0
75.693634444,2494.0
75.743768251,2659.0
75.793902058,2499.0
75.844035865,2635.0
75.894169672,2592.0
75.944303479,2616.0
75.994437286,2641.0
76.044571093,2564.0
76.094704900,2606.0
76.144838707,2527.0
76.194972514,2595.0
76.245106320,2550.0
76.295240127,2705.0
76.345373934,2530.0
76.395507741,2666.0
76.445641548,2559.0
76.495775355,2584.0
76.545909162,2668.0
76.596042969,2623.0
76.646176776,2613.0
76.696310583,2561.0
76.746444390,2525.0
76.796578197,2665.0
76.846712004,2578.0
76.896845811,2604.0
76.946979618,2608.0
76.997113425,2656.0
77.047247231,2593.0
77.097381038,2656.0
77.147514845,2590.0
77.197648652,2695.0
77.247782459,2706.0
77.297916266,2628.0
77.348050073,2546.0
77.398183880,2626.0
77.448317687,2546.0
77.498451494,2637.0
77.548585301,2687.0
77.598719108,2519.0
77.648852915,2628.0
77.698986722,2612.0
77.749120529,2572.0
77.799254336,2525.0
77.849388142,2591.0
77.899521949,2629.0
77.949655756,2579.0
77.999789563,2646.0
78.049923370,2669.0
78.100057177,2711.0
78.150190984,2701.0
78.200324791,2639.0
78.250458598,2547.0
78.300592405,2612.0
78.350726212,2712.0
78.400860019,2596.0
78.450993826,2676.0
78.501127633,2714.0
78.551261440,2642.0
78.601395247,2666.0
78.651529053,2636.0
78.701662860,2763.0
78.751796667,2653.0
78.801930474,2649.0
78.852064281,2642.0
78.902198088,2649.0
78.952331895,2640.0
79.002465702,2591.0
79.052599509,2609.0
79.102733316,2640.0
79.152867123,2676.0
79.203000930,2753.0
79.253134737,2774.0
79.303268544,2680.0
79.353402351,2665.0
79.403536158,2626.0
79.453669964,2617.0
79.503803771,2749.0
79.553937578,2680.0
79.604071385,2640.0
79.654205192,2666.0
79.704338999,2695.0
79.754472806,2695.0
79.804606613,2730.0
79.854740420,2732.0
79.904874227,2726.0
79.955008034,2709.0
80.005141841,2738.0
80.055275648,2769.0
80.105409455,2782.0
80.155543262,2709.0
80.205677069,2785.0
80.255810875,2764.0
80.305944682,2755.0
80.356078489,2738.0
80.406212296,2788.0
80.456346103,2679.0
80.506479910,2727.0
80.556613717,2677.0
80.606747524,2758.0
80.656881331,2679.0
80.707015138,2737.0
80.757148945,2708.0
80.807282752,2656.0
80.857416559,2682.0
80.907550366,2796.0
80.957684173,2652.0
81.007817980,2679.0
81.057951786,2679.0
81.108085593,2644.0
81.158219400,2638.0
81.208353207,2630.0
81.258487014,2706.0
81.308620821,2753.0
81.358754628,2724.0
81.408888435,2751.0
81.459022242,2635.0
81.509156049,2747.0
81.559289856,2748.0
81.609423663,2780.0
81.659557470,2836.0
81.709691277,2851.0
81.759825084,2794.0
81.809958891,2664.0
81.860092697,2767.0
81.910226504,2724.0
81.960360311,2766.0
82.010494118,2798.0
82.060627925,2603.0
82.110761732,2604.0
82.160895539,2589.0
82.211029346,2631.0
82.261163153,2656.0
82.311296960,2631.0
82.361430767,2665.0
82.411564574,2614.0
82.461698381,2626.0
82.511832188,2640.0
82.561965995,2680.0
82.612099802,2754.0
82.662233608,2616.0
82.712367415,2750.0
82.762501222,2665.0
82.812635029,2687.0
82.862768836,2633.0
82.912902643,2614.0
82.963036450,2662.0
83.013170257,2598.0
83.063304064,2685.0
83.113437871,2745.0
83.163571678,2625.0
83.213705485,2704.0
83.263839292,2726.0
83.313973099,2594.0
83.364106906,2696.0
83.414240713,2666.0
83.464374519,2743.0
83.514508326,2664.0
83.564642133,2735.0
83.614775940,2729.0
83.664909747,2772.0
83.715043554,2737.0
83.765177361,2685.0
83.815311168,2751.0
83.865444975,2777.0
83.915578782,2773.0
83.965712589,2747.0
84.015846396,2739.0
84.065980203,2662.0
84.116114010,2720.0
84.166247817,2799.0
84.216381624,2916.0
84.266515431,2768.0
84.316649237,2774.0
84.366783044,2824.0
84.416916851,2749.0
84.467050658,2732.0
84.517184465,2885.0
84.567318272,2724.0
84.617452079,2802.0
84.667585886,2859.0
84.717719693,2740.0
84.767853500,2709.0
84.817987307,2867.0
84.868121114,2745.0
84.918254921,2775.0
84.968388728,2794.0
85.018522535,2875.0
85.068656342,2759.0
85.118790148,2888.0
85.168923955,2932.0
85.219057762,2964.0
85.269191569,2819.0
85.319325376,2865.0
85.369459183,2746.0
85.419592990,2763.0
85.469726797,2832.0
85.519860604,2857.0
85.569994411,2887.0
85.620128218,2898.0
85.670262025,2883.0
85.720395832,2930.0
85.770529639,3002.0
85.820663446,2951.0
85.870797253,2985.0
85.920931059,2835.0
85.971064866,2815.0
86.021198673,3006.0
86.071332480,3147.0
86.121466287,2983.0
86.171600094,3090.0
86.221733901,2956.0
86.271867708,2927.0
86.322001515,2854.0
86.372135322,2971.0
86.422269129,3041.0
86.472402936,3123.0
86.522536743,2925.0
86.572670550,3002.0
86.622804357,2954.0
86.672938164,2950.0
86.723071970,2882.0
86.773205777,2881.0
86.823339584,2982.0
86.873473391,3004.0
86.923607198,3009.0
86.973741005,2890.0
87.023874812,3003.0
87.074008619,2978.0
87.124142426,2972.0
87.174276233,3177.0
87.224410040,3102.0
87.274543847,3023.0
87.324677654,3032.0
87.374811461,3029.0
87.424945268,3040.0
87.475079075,2977.0
87.525212881,3029.0
87.575346688,3147.0
87.625480495,3102.0
87.675614302,3024.0
87.725748109,2985.0
87.775881916,3031.0
87.826015723,2914.0
87.876149530,3115.0
87.926283337,3046.0
87.976417144,3083.0
88.026550951,3093.0
88.076684758,3196.0
88.126818565,3146.0
88.176952372,3202.0
88.227086179,3226.0
88.277219986,3093.0
88.327353792,3197.0
88.377487599,3022.0
88.427621406,3156.0
88.477755213,3146.0
88.527889020,3154.0
88.578022827,3156.0
88.628156634,3240.0
88.678290441,3254.0
88.728424248,3210.0
88.778558055,3190.0
88.828691862,3351.0
88.878825669,3399.0
88.928959476,3464.0
88.979093283,3660.0
89.029227090,3895.0
89.079360897,4971.0
89.129494703,7096.0
89.179628510,7857.0
89.229762317,8113.0
89.279896124,7853.0
89.330029931,7404.0
89.380163738,6982.0
89.430297545,7030.0
89.480431352,6592.0
89.530565159,6474.0
89.580698966,5965.0
89.630832773,5307.0
89.680966580,4847.0
89.731100387,4379.0
89.781234194,4106.0
89.831368001,3936.0
89.881501808,3632.0
89.931635614,3565.0
89.981769421,3441.0
90.031903228,3509.0
90.082037035,3507.0
90.132170842,3541.0
90.182304649,3506.0
90.232438456,3410.0
90.282572263,3425.0
90.332706070,3398.0
90.382839877,3437.0
90.432973684,3335.0
90.483107491,3331.0
90.533241298,3338.0
90.583375105,3351.0
90.633508912,3295.0
90.683642719,3351.0
90.733776525,3228.0
90.783910332,3279.0
90.834044139,3267.0
90.884177946,3274.0
90.934311753,3335.0
90.984445560,3310.0
91.034579367,3218.0
91.084713174,3298.0
91.134846981,3330.0
91.184980788,3338.0
91.235114595,3364.0
91.285248402,3326.0
91.335382209,3398.0
91.385516016,3383.0
91.435649823,3328.0
91.485783630,3423.0
91.535917436,3405.0
91.586051243,3453.0
91.636185050,3298.0
91.686318857,3268.0
91.736452664,3409.0
91.786586471,3408.0
91.836720278,3478.0
91.886854085,3393.0
91.936987892,3406.0
91.987121699,3372.0
92.037255506,3430.0
92.087389313,3446.0
92.137523120,3384.0
92.187656927,3318.0
92.237790734,3398.0
92.287924541,3391.0
92.338058347,3419.0
92.388192154,3209.0
92.438325961,3335.0
92.488459768,3301.0
92.538593575,3428.0
92.588727382,3422.0
92.638861189,3439.0
92.688994996,3460.0
92.739128803,3260.0
92.789262610,3483.0
92.839396417,3527.0
92.889530224,3510.0
92.939664031,3409.0
92.989797838,3579.0
93.039931645,3329.0
93.090065452,3377.0
93.140199258,3410.0
93.190333065,3490.0
93.240466872,3506.0
93.290600679,3520.0
93.340734486,3466.0
93.390868293,3526.0
93.441002100,3410.0
93.491135907,3479.0
93.541269714,3435.0
93.591403521,3457.0
93.641537328,3490.0
93.691671135,3568.0
93.741804942,3487.0
93.791938749,3595.0
93.842072556,3619.0
93.892206363,3500.0
93.942340170,3523.0
93.992473976,3577.0
94.042607783,3711.0
94.092741590,3714.0
94.142875397,3949.0
94.193009204,4449.0
94.243143011,6632.0
94.293276818,7646.0
94.343410625,6249.0
94.393544432,5115.0
94.443678239,4523.0
94.493812046,4669.0
94.543945853,5469.0
94.594079660,6005.0
94.644213467,5045.0
94.694347274,4497.0
94.744481081,4214.0
94.794614887,4154.0
94.844748694,4041.0
94.894882501,3940.0
94.945016308,3920.0
94.995150115,3784.0
95.045283922,3746.0
95.095417729,3741.0
95.145551536,3734.0
95.195685343,3713.0
95.245819150,3605.0
95.295952957,3569.0
95.346086764,3632.0
95.396220571,3575.0
95.446354378,3636.0
95.496488185,3613.0
95.546621992,3533.0
95.596755798,3539.0
95.646889605,3505.0
95.697023412,3515.0
95.747157219,3560.0
95.797291026,3453.0
95.847424833,3558.0
95.897558640,3560.0
95.947692447,3550.0
95.997826254,3516.0
96.047960061,3588.0
96.098093868,3639.0
96.148227675,3581.0
96.198361482,3651.0
96.248495289,3513.0
96.298629096,3549.0
96.348762903,3606.0
96.398896709,3550.0
96.449030516,3485.0
96.499164323,3572.0
96.549298130,3682.0
96.599431937,3624.0
96.649565744,3563.0
96.699699551,3626.0
96.749833358,3545.0
96.799967165,3478.0
96.850100972,3469.0
96.900234779,3652.0
96.950368586,3598.0
97.000502393,3584.0
97.050636200,3584.0
97.100770007,3488.0
97.150903814,3571.0
97.201037620,3609.0
97.251171427,3635.0
97.301305234,3566.0
97.351439041,3583.0
97.401572848,3538.0
97.451706655,3577.0
97.501840462,3686.0
97.551974269,3684.0
97.602108076,3582.0
97.652241883,3588.0
97.702375690,3674.0
97.752509497,3545.0
97.802643304,3595.0
97.852777111,3643.0
97.902910918,3702.0
97.953044725,3549.0
98.003178531,3609.0
98.053312338,3608.0
98.103446145,3533.0
98.153579952,3663.0
98.203713759,3631.0
98.253847566,3701.0
98.303981373,3559.0
98.354115180,3746.0
98.404248987,3703.0
98.454382794,3609.0
98.504516601,3687.0
98.554650408,3651.0
98.604784215,3778.0
98.654918022,3606.0
98.705051829,3629.0
98.755185636,3631.0
98.805319442,3707.0
98.855453249,3655.0
98.905587056,3708.0
98.955720863,3570.0
99.005854670,3717.0
99.055988477,3680.0
99.106122284,3633.0
99.156256091,3668.0
99.206389898,3668.0
99.256523705,3722.0
99.306657512,3700.0
99.356791319,3648.0
99.406925126,3541.0
99.457058933,3730.0
99.507192740,3668.0
99.557326547,3703.0
99.607460353,3709.0
99.657594160,3694.0
99.707727967,3686.0
99.757861774,3743.0
99.807995581,3658.0
99.858129388,3759.0
99.908263195,3728.0
99.958397002,3761.0
99.991819540,3708.0