File: OriginPro/XRD from Panalytical X'Pert PRO/Nova Cu foil/Cufoil_500°C.csv
[Measurement conditions]
Sample identification,
Comment - 1,"finito"
Comment - 2,"Configuration=MRI TC-Basic Stage, Owner=User-1, Creation date=26-10-2009 9:18:44"
Comment - 3,"Goniometer=PW3050/60 (Theta/Theta); Minimum step size 2Theta:0.001; Minimum step size Omega:0.001"
Comment - 4,"Sample stage=MRI TC-Basic (PtRh heat strip)"
Comment - 5,"Diffractometer system=XPERT-PRO"
Comment - 6,"Measurement program=FlatStage, Owner=joana, Creation date=03-08-2011 15:43:53"
Anode material,Cu
K-Alpha1 wavelength,1.5405980
K-Alpha2 wavelength,1.5444260
Ratio K-Alpha2/K-Alpha1,0.500
Divergence slit,Fixed,0.76mm
Monochromator used,NO
Generator voltage, 45
Tube current, 40
File date and time,07/Dec/2012 00:49
Unit cell,
h k l, 0 0 0
Temperature [K],773
Scan axis,Gonio
Scan range,24.999999996,100.000175174
Scan step size,0.0167113
No. of points, 4488
Scan type,CONTINUOUS
Time per step,53.340
[Scan points]
Angle,Intensity
25.008355630,4718.0
25.058489437,4704.0
25.108623244,4725.0
25.158757051,4621.0
25.208890858,4824.0
25.259024665,4695.0
25.309158472,4580.0
25.359292279,4566.0
25.409426086,4748.0
25.459559892,4697.0
25.509693699,4786.0
25.559827506,4799.0
25.609961313,4728.0
25.660095120,4865.0
25.710228927,4720.0
25.760362734,4783.0
25.810496541,4628.0
25.860630348,4773.0
25.910764155,4972.0
25.960897962,4781.0
26.011031769,4909.0
26.061165576,4809.0
26.111299383,4696.0
26.161433190,4769.0
26.211566997,4811.0
26.261700803,4745.0
26.311834610,4737.0
26.361968417,4929.0
26.412102224,4684.0
26.462236031,4782.0
26.512369838,4752.0
26.562503645,4857.0
26.612637452,4721.0
26.662771259,4808.0
26.712905066,4798.0
26.763038873,4804.0
26.813172680,4833.0
26.863306487,4835.0
26.913440294,4797.0
26.963574101,4800.0
27.013707908,4706.0
27.063841714,4864.0
27.113975521,4848.0
27.164109328,4729.0
27.214243135,4769.0
27.264376942,4857.0
27.314510749,4749.0
27.364644556,4857.0
27.414778363,4765.0
27.464912170,4679.0
27.515045977,4798.0
27.565179784,4817.0
27.615313591,4690.0
27.665447398,4833.0
27.715581205,4782.0
27.765715012,4905.0
27.815848819,4851.0
27.865982625,4814.0
27.916116432,4783.0
27.966250239,4732.0
28.016384046,4830.0
28.066517853,4826.0
28.116651660,4903.0
28.166785467,4755.0
28.216919274,4776.0
28.267053081,4883.0
28.317186888,4719.0
28.367320695,4858.0
28.417454502,4843.0
28.467588309,4707.0
28.517722116,4918.0
28.567855923,4869.0
28.617989730,4822.0
28.668123536,4816.0
28.718257343,4754.0
28.768391150,4895.0
28.818524957,4823.0
28.868658764,4755.0
28.918792571,4737.0
28.968926378,4971.0
29.019060185,4863.0
29.069193992,4959.0
29.119327799,4915.0
29.169461606,5167.0
29.219595413,5156.0
29.269729220,5533.0
29.319863027,5869.0
29.369996834,6137.0
29.420130641,6823.0
29.470264447,7213.0
29.520398254,7575.0
29.570532061,7854.0
29.620665868,7438.0
29.670799675,6961.0
29.720933482,6163.0
29.771067289,5662.0
29.821201096,5206.0
29.871334903,4929.0
29.921468710,5000.0
29.971602517,4841.0
30.021736324,4878.0
30.071870131,4932.0
30.122003938,4899.0
30.172137745,4896.0
30.222271552,4851.0
30.272405358,4794.0
30.322539165,4817.0
30.372672972,4943.0
30.422806779,4805.0
30.472940586,4884.0
30.523074393,4748.0
30.573208200,4870.0
30.623342007,4913.0
30.673475814,4868.0
30.723609621,4865.0
30.773743428,4840.0
30.823877235,4756.0
30.874011042,4904.0
30.924144849,4957.0
30.974278656,4810.0
31.024412463,4770.0
31.074546269,4956.0
31.124680076,4876.0
31.174813883,4832.0
31.224947690,4917.0
31.275081497,4889.0
31.325215304,4985.0
31.375349111,5071.0
31.425482918,4798.0
31.475616725,4831.0
31.525750532,4934.0
31.575884339,4863.0
31.626018146,4878.0
31.676151953,4914.0
31.726285760,4935.0
31.776419567,4895.0
31.826553374,4934.0
31.876687180,4921.0
31.926820987,4956.0
31.976954794,5025.0
32.027088601,4868.0
32.077222408,4923.0
32.127356215,4930.0
32.177490022,4985.0
32.227623829,5154.0
32.277757636,5097.0
32.327891443,4999.0
32.378025250,5052.0
32.428159057,5088.0
32.478292864,4989.0
32.528426671,4950.0
32.578560478,5101.0
32.628694285,5028.0
32.678828091,5156.0
32.728961898,4988.0
32.779095705,5047.0
32.829229512,5026.0
32.879363319,5204.0
32.929497126,4974.0
32.979630933,4974.0
33.029764740,4818.0
33.079898547,4992.0
33.130032354,4980.0
33.180166161,4999.0
33.230299968,4927.0
33.280433775,4998.0
33.330567582,5086.0
33.380701389,5074.0
33.430835196,5034.0
33.480969002,5111.0
33.531102809,4965.0
33.581236616,5043.0
33.631370423,4949.0
33.681504230,4943.0
33.731638037,5015.0
33.781771844,5000.0
33.831905651,5062.0
33.882039458,4952.0
33.932173265,4999.0
33.982307072,4989.0
34.032440879,4909.0
34.082574686,5037.0
34.132708493,5078.0
34.182842300,5097.0
34.232976107,5045.0
34.283109913,5171.0
34.333243720,5132.0
34.383377527,5111.0
34.433511334,5006.0
34.483645141,5015.0
34.533778948,5116.0
34.583912755,5111.0
34.634046562,5066.0
34.684180369,5186.0
34.734314176,5225.0
34.784447983,5100.0
34.834581790,5098.0
34.884715597,5194.0
34.934849404,5303.0
34.984983211,5429.0
35.035117018,5337.0
35.085250825,5377.0
35.135384631,5433.0
35.185518438,5649.0
35.235652245,5786.0
35.285786052,6034.0
35.335919859,6158.0
35.386053666,6283.0
35.436187473,6510.0
35.486321280,6421.0
35.536455087,6527.0
35.586588894,6381.0
35.636722701,6233.0
35.686856508,6117.0
35.736990315,6049.0
35.787124122,6043.0
35.837257929,6088.0
35.887391736,6255.0
35.937525542,6803.0
35.987659349,7565.0
36.037793156,9113.0
36.087926963,11131.0
36.138060770,14600.0
36.188194577,19486.0
36.238328384,25339.0
36.288462191,31930.0
36.338595998,38863.0
36.388729805,44207.0
36.438863612,46018.0
36.488997419,43130.0
36.539131226,35249.0
36.589265033,25723.0
36.639398840,17019.0
36.689532647,11588.0
36.739666453,8513.0
36.789800260,7067.0
36.839934067,6408.0
36.890067874,5979.0
36.940201681,5794.0
36.990335488,5700.0
37.040469295,5668.0
37.090603102,5595.0
37.140736909,5591.0
37.190870716,5598.0
37.241004523,5630.0
37.291138330,5497.0
37.341272137,5470.0
37.391405944,5430.0
37.441539751,5576.0
37.491673558,5496.0
37.541807364,5338.0
37.591941171,5442.0
37.642074978,5532.0
37.692208785,5514.0
37.742342592,5446.0
37.792476399,5446.0
37.842610206,5599.0
37.892744013,5478.0
37.942877820,5439.0
37.993011627,5452.0
38.043145434,5510.0
38.093279241,5415.0
38.143413048,5551.0
38.193546855,5448.0
38.243680662,5545.0
38.293814469,5607.0
38.343948275,5608.0
38.394082082,5678.0
38.444215889,5801.0
38.494349696,5926.0
38.544483503,5883.0
38.594617310,5781.0
38.644751117,5983.0
38.694884924,6034.0
38.745018731,5997.0
38.795152538,5740.0
38.845286345,5845.0
38.895420152,5397.0
38.945553959,5634.0
38.995687766,5554.0
39.045821573,5460.0
39.095955380,5415.0
39.146089186,5386.0
39.196222993,5486.0
39.246356800,5309.0
39.296490607,5340.0
39.346624414,5236.0
39.396758221,5487.0
39.446892028,5135.0
39.497025835,5470.0
39.547159642,5326.0
39.597293449,5292.0
39.647427256,5349.0
39.697561063,5302.0
39.747694870,5263.0
39.797828677,5315.0
39.847962484,5219.0
39.898096291,5146.0
39.948230097,5276.0
39.998363904,5091.0
40.048497711,5178.0
40.098631518,5214.0
40.148765325,5025.0
40.198899132,5184.0
40.249032939,5311.0
40.299166746,5153.0
40.349300553,5144.0
40.399434360,5227.0
40.449568167,5175.0
40.499701974,5151.0
40.549835781,5200.0
40.599969588,5250.0
40.650103395,5286.0
40.700237202,5205.0
40.750371008,5312.0
40.800504815,5293.0
40.850638622,5417.0
40.900772429,5288.0
40.950906236,5325.0
41.001040043,5173.0
41.051173850,5255.0
41.101307657,5289.0
41.151441464,5226.0
41.201575271,5384.0
41.251709078,5342.0
41.301842885,5453.0
41.351976692,5376.0
41.402110499,5413.0
41.452244306,5506.0
41.502378113,5553.0
41.552511919,5893.0
41.602645726,5896.0
41.652779533,5991.0
41.702913340,6281.0
41.753047147,6662.0
41.803180954,6891.0
41.853314761,7410.0
41.903448568,8459.0
41.953582375,9236.0
42.003716182,10575.0
42.053849989,11973.0
42.103983796,13273.0
42.154117603,14380.0
42.204251410,15008.0
42.254385217,15208.0
42.304519024,14652.0
42.354652830,13226.0
42.404786637,11884.0
42.454920444,10488.0
42.505054251,9000.0
42.555188058,7932.0
42.605321865,7736.0
42.655455672,7772.0
42.705589479,8978.0
42.755723286,12483.0
42.805857093,17218.0
42.855990900,27738.0
42.906124707,40571.0
42.956258514,49276.0
43.006392321,57048.0
43.056526128,66741.0
43.106659935,81155.0
43.156793741,53366.0
43.206927548,37767.0
43.257061355,26315.0
43.307195162,11329.0
43.357328969,7449.0
43.407462776,6590.0
43.457596583,6410.0
43.507730390,6002.0
43.557864197,5839.0
43.607998004,5730.0
43.658131811,5609.0
43.708265618,5649.0
43.758399425,5632.0
43.808533232,5670.0
43.858667039,5595.0
43.908800846,5577.0
43.958934652,5486.0
44.009068459,5434.0
44.059202266,5423.0
44.109336073,5336.0
44.159469880,5302.0
44.209603687,5483.0
44.259737494,5518.0
44.309871301,5408.0
44.360005108,5384.0
44.410138915,5404.0
44.460272722,5295.0
44.510406529,5308.0
44.560540336,5412.0
44.610674143,5361.0
44.660807950,5295.0
44.710941757,5366.0
44.761075564,5202.0
44.811209370,5435.0
44.861343177,5506.0
44.911476984,5332.0
44.961610791,5443.0
45.011744598,5463.0
45.061878405,5389.0
45.112012212,5385.0
45.162146019,5308.0
45.212279826,5281.0
45.262413633,5245.0
45.312547440,5263.0
45.362681247,5240.0
45.412815054,5324.0
45.462948861,5252.0
45.513082668,5222.0
45.563216475,5183.0
45.613350281,5237.0
45.663484088,5368.0
45.713617895,5093.0
45.763751702,5232.0
45.813885509,5214.0
45.864019316,5250.0
45.914153123,5080.0
45.964286930,5073.0
46.014420737,5277.0
46.064554544,5388.0
46.114688351,5078.0
46.164822158,5107.0
46.214955965,5295.0
46.265089772,5312.0
46.315223579,5453.0
46.365357386,5462.0
46.415491192,5121.0
46.465624999,5283.0
46.515758806,5323.0
46.565892613,5064.0
46.616026420,5314.0
46.666160227,5097.0
46.716294034,5179.0
46.766427841,5065.0
46.816561648,5092.0
46.866695455,5356.0
46.916829262,5176.0
46.966963069,5168.0
47.017096876,5185.0
47.067230683,5211.0
47.117364490,5036.0
47.167498297,5033.0
47.217632103,5036.0
47.267765910,5004.0
47.317899717,5064.0
47.368033524,5000.0
47.418167331,5025.0
47.468301138,5067.0
47.518434945,5141.0
47.568568752,5246.0
47.618702559,5047.0
47.668836366,4983.0
47.718970173,5077.0
47.769103980,5112.0
47.819237787,4942.0
47.869371594,4952.0
47.919505401,5204.0
47.969639208,5112.0
48.019773014,5032.0
48.069906821,5142.0
48.120040628,5171.0
48.170174435,5156.0
48.220308242,5156.0
48.270442049,5329.0
48.320575856,5341.0
48.370709663,5386.0
48.420843470,5425.0
48.470977277,5665.0
48.521111084,5569.0
48.571244891,5660.0
48.621378698,5587.0
48.671512505,5650.0
48.721646312,5638.0
48.771780119,5732.0
48.821913925,5656.0
48.872047732,5575.0
48.922181539,5488.0
48.972315346,5416.0
49.022449153,5426.0
49.072582960,5427.0
49.122716767,5304.0
49.172850574,5487.0
49.222984381,5417.0
49.273118188,5459.0
49.323251995,5477.0
49.373385802,5398.0
49.423519609,5360.0
49.473653416,5449.0
49.523787223,5517.0
49.573921030,5533.0
49.624054836,5792.0
49.674188643,5851.0
49.724322450,6249.0
49.774456257,6855.0
49.824590064,8772.0
49.874723871,12009.0
49.924857678,18465.0
49.974991485,30561.0
50.025125292,42152.0
50.075259099,49388.0
50.125392906,61251.0
50.175526713,75488.0
50.225660520,65448.0
50.275794327,36571.0
50.325928134,35045.0
50.376061941,19796.0
50.426195747,8977.0
50.476329554,6823.0
50.526463361,6319.0
50.576597168,5986.0
50.626730975,5747.0
50.676864782,5607.0
50.726998589,5484.0
50.777132396,5361.0
50.827266203,5283.0
50.877400010,5314.0
50.927533817,5397.0
50.977667624,5284.0
51.027801431,5336.0
51.077935238,5324.0
51.128069045,5229.0
51.178202852,5130.0
51.228336658,5128.0
51.278470465,5095.0
51.328604272,5250.0
51.378738079,5005.0
51.428871886,5094.0
51.479005693,5119.0
51.529139500,5153.0
51.579273307,5142.0
51.629407114,5095.0
51.679540921,4949.0
51.729674728,5011.0
51.779808535,5084.0
51.829942342,5072.0
51.880076149,4979.0
51.930209956,5064.0
51.980343763,5012.0
52.030477569,5087.0
52.080611376,5078.0
52.130745183,5181.0
52.180878990,5072.0
52.231012797,5268.0
52.281146604,5257.0
52.331280411,5348.0
52.381414218,5181.0
52.431548025,5436.0
52.481681832,5341.0
52.531815639,5297.0
52.581949446,5113.0
52.632083253,5275.0
52.682217060,5079.0
52.732350867,5042.0
52.782484674,5104.0
52.832618480,4933.0
52.882752287,5030.0
52.932886094,4940.0
52.983019901,4892.0
53.033153708,4961.0
53.083287515,4965.0
53.133421322,4770.0
53.183555129,4932.0
53.233688936,4909.0
53.283822743,5061.0
53.333956550,4950.0
53.384090357,4977.0
53.434224164,4847.0
53.484357971,4930.0
53.534491778,4969.0
53.584625585,4971.0
53.634759391,5058.0
53.684893198,4957.0
53.735027005,4863.0
53.785160812,4955.0
53.835294619,5021.0
53.885428426,4917.0
53.935562233,4839.0
53.985696040,4926.0
54.035829847,4853.0
54.085963654,4945.0
54.136097461,4824.0
54.186231268,4877.0
54.236365075,4935.0
54.286498882,4859.0
54.336632689,5013.0
54.386766496,4943.0
54.436900303,4852.0
54.487034109,4960.0
54.537167916,5018.0
54.587301723,4961.0
54.637435530,4910.0
54.687569337,4848.0
54.737703144,4986.0
54.787836951,5058.0
54.837970758,4888.0
54.888104565,4930.0
54.938238372,4763.0
54.988372179,4913.0
55.038505986,4786.0
55.088639793,4760.0
55.138773600,4835.0
55.188907407,4821.0
55.239041214,4871.0
55.289175020,4902.0
55.339308827,4952.0
55.389442634,4910.0
55.439576441,4754.0
55.489710248,4830.0
55.539844055,4807.0
55.589977862,4780.0
55.640111669,4921.0
55.690245476,4867.0
55.740379283,4806.0
55.790513090,4620.0
55.840646897,4814.0
55.890780704,4849.0
55.940914511,4792.0
55.991048318,4837.0
56.041182125,4924.0
56.091315931,4830.0
56.141449738,4858.0
56.191583545,4914.0
56.241717352,4780.0
56.291851159,4754.0
56.341984966,4813.0
56.392118773,4831.0
56.442252580,4919.0
56.492386387,4760.0
56.542520194,4962.0
56.592654001,4759.0
56.642787808,4841.0
56.692921615,4768.0
56.743055422,4762.0
56.793189229,4920.0
56.843323036,4764.0
56.893456842,4786.0
56.943590649,4838.0
56.993724456,4834.0
57.043858263,4906.0
57.093992070,4833.0
57.144125877,4761.0
57.194259684,4768.0
57.244393491,4813.0
57.294527298,4948.0
57.344661105,4872.0
57.394794912,4800.0
57.444928719,4700.0
57.495062526,4794.0
57.545196333,4922.0
57.595330140,4641.0
57.645463947,4793.0
57.695597753,4813.0
57.745731560,4836.0
57.795865367,4759.0
57.845999174,4794.0
57.896132981,4794.0
57.946266788,4913.0
57.996400595,4780.0
58.046534402,4719.0
58.096668209,4836.0
58.146802016,4722.0
58.196935823,4913.0
58.247069630,4853.0
58.297203437,4867.0
58.347337244,4859.0
58.397471051,4751.0
58.447604858,4824.0
58.497738664,4861.0
58.547872471,4788.0
58.598006278,4729.0
58.648140085,4670.0
58.698273892,4801.0
58.748407699,4785.0
58.798541506,4832.0
58.848675313,4970.0
58.898809120,4857.0
58.948942927,4864.0
58.999076734,4886.0
59.049210541,4879.0
59.099344348,4847.0
59.149478155,4808.0
59.199611962,4959.0
59.249745769,4889.0
59.299879575,4964.0
59.350013382,4758.0
59.400147189,4790.0
59.450280996,4837.0
59.500414803,4812.0
59.550548610,4844.0
59.600682417,4909.0
59.650816224,4979.0
59.700950031,4801.0
59.751083838,4855.0
59.801217645,4912.0
59.851351452,4814.0
59.901485259,4826.0
59.951619066,4848.0
60.001752873,5075.0
60.051886680,4930.0
60.102020486,4847.0
60.152154293,4792.0
60.202288100,4864.0
60.252421907,5038.0
60.302555714,4975.0
60.352689521,4951.0
60.402823328,4982.0
60.452957135,4891.0
60.503090942,5037.0
60.553224749,5020.0
60.603358556,4976.0
60.653492363,5209.0
60.703626170,5181.0
60.753759977,5346.0
60.803893784,5395.0
60.854027591,5578.0
60.904161397,5679.0
60.954295204,6147.0
61.004429011,6666.0
61.054562818,7224.0
61.104696625,7884.0
61.154830432,8488.0
61.204964239,9442.0
61.255098046,10003.0
61.305231853,10064.0
61.355365660,10265.0
61.405499467,9874.0
61.455633274,9061.0
61.505767081,8340.0
61.555900888,7643.0
61.606034695,6845.0
61.656168502,6362.0
61.706302308,5803.0
61.756436115,5480.0
61.806569922,5112.0
61.856703729,5089.0
61.906837536,5329.0
61.956971343,5217.0
62.007105150,4990.0
62.057238957,4885.0
62.107372764,5000.0
62.157506571,4974.0
62.207640378,4980.0
62.257774185,5013.0
62.307907992,4908.0
62.358041799,4902.0
62.408175606,4984.0
62.458309413,4849.0
62.508443219,4943.0
62.558577026,4826.0
62.608710833,4900.0
62.658844640,4808.0
62.708978447,4947.0
62.759112254,4790.0
62.809246061,4823.0
62.859379868,4756.0
62.909513675,4778.0
62.959647482,4813.0
63.009781289,4908.0
63.059915096,4731.0
63.110048903,4836.0
63.160182710,5014.0
63.210316517,4751.0
63.260450324,4817.0
63.310584130,4898.0
63.360717937,4897.0
63.410851744,4782.0
63.460985551,4928.0
63.511119358,4876.0
63.561253165,4877.0
63.611386972,4757.0
63.661520779,4801.0
63.711654586,4840.0
63.761788393,4789.0
63.811922200,4766.0
63.862056007,4720.0
63.912189814,4804.0
63.962323621,4681.0
64.012457428,4843.0
64.062591235,4730.0
64.112725041,4843.0
64.162858848,4894.0
64.212992655,4800.0
64.263126462,4921.0
64.313260269,4822.0
64.363394076,4763.0
64.413527883,4746.0
64.463661690,4639.0
64.513795497,4835.0
64.563929304,4725.0
64.614063111,4708.0
64.664196918,4803.0
64.714330725,4834.0
64.764464532,4661.0
64.814598339,4791.0
64.864732146,4726.0
64.914865953,4744.0
64.964999759,4834.0
65.015133566,4753.0
65.065267373,4891.0
65.115401180,4761.0
65.165534987,4827.0
65.215668794,4870.0
65.265802601,4816.0
65.315936408,4817.0
65.366070215,4811.0
65.416204022,4773.0
65.466337829,4864.0
65.516471636,4840.0
65.566605443,4845.0
65.616739250,4896.0
65.666873057,4888.0
65.717006864,4928.0
65.767140670,4835.0
65.817274477,4858.0
65.867408284,4844.0
65.917542091,4917.0
65.967675898,5085.0
66.017809705,4759.0
66.067943512,5026.0
66.118077319,4909.0
66.168211126,4856.0
66.218344933,4942.0
66.268478740,4798.0
66.318612547,4930.0
66.368746354,4971.0
66.418880161,4602.0
66.469013968,4775.0
66.519147775,4873.0
66.569281581,4690.0
66.619415388,4911.0
66.669549195,4807.0
66.719683002,4785.0
66.769816809,4808.0
66.819950616,4762.0
66.870084423,4666.0
66.920218230,4643.0
66.970352037,4660.0
67.020485844,4847.0
67.070619651,4924.0
67.120753458,4742.0
67.170887265,4739.0
67.221021072,4792.0
67.271154879,4773.0
67.321288686,4811.0
67.371422492,4755.0
67.421556299,4707.0
67.471690106,4853.0
67.521823913,4844.0
67.571957720,4740.0
67.622091527,4799.0
67.672225334,5179.0
67.722359141,5205.0
67.772492948,5064.0
67.822626755,4834.0
67.872760562,4954.0
67.922894369,4820.0
67.973028176,4869.0
68.023161983,4757.0
68.073295790,4824.0
68.123429597,4906.0
68.173563403,4642.0
68.223697210,4743.0
68.273831017,4681.0
68.323964824,4944.0
68.374098631,4767.0
68.424232438,4729.0
68.474366245,4748.0
68.524500052,4677.0
68.574633859,4817.0
68.624767666,4655.0
68.674901473,4715.0
68.725035280,4759.0
68.775169087,4753.0
68.825302894,4759.0
68.875436701,4820.0
68.925570508,4813.0
68.975704314,4853.0
69.025838121,4717.0
69.075971928,4795.0
69.126105735,4739.0
69.176239542,4744.0
69.226373349,4767.0
69.276507156,4847.0
69.326640963,4754.0
69.376774770,4921.0
69.426908577,4748.0
69.477042384,4756.0
69.527176191,4872.0
69.577309998,4681.0
69.627443805,4844.0
69.677577612,4800.0
69.727711419,4829.0
69.777845225,4802.0
69.827979032,4782.0
69.878112839,4675.0
69.928246646,4779.0
69.978380453,4692.0
70.028514260,4657.0
70.078648067,4782.0
70.128781874,4830.0
70.178915681,4831.0
70.229049488,4835.0
70.279183295,4778.0
70.329317102,4887.0
70.379450909,4674.0
70.429584716,4843.0
70.479718523,4740.0
70.529852330,4918.0
70.579986136,4839.0
70.630119943,4724.0
70.680253750,4774.0
70.730387557,4765.0
70.780521364,4883.0
70.830655171,4734.0
70.880788978,4924.0
70.930922785,4755.0
70.981056592,4754.0
71.031190399,4910.0
71.081324206,4781.0
71.131458013,4861.0
71.181591820,4754.0
71.231725627,4803.0
71.281859434,4807.0
71.331993241,4896.0
71.382127047,4846.0
71.432260854,4875.0
71.482394661,4933.0
71.532528468,4916.0
71.582662275,4827.0
71.632796082,4793.0
71.682929889,4882.0
71.733063696,4805.0
71.783197503,4768.0
71.833331310,4809.0
71.883465117,4772.0
71.933598924,4887.0
71.983732731,5011.0
72.033866538,4906.0
72.084000345,4799.0
72.134134152,4934.0
72.184267958,4945.0
72.234401765,4892.0
72.284535572,4948.0
72.334669379,4944.0
72.384803186,5085.0
72.434936993,5089.0
72.485070800,4965.0
72.535204607,4901.0
72.585338414,4962.0
72.635472221,5055.0
72.685606028,5119.0
72.735739835,5123.0
72.785873642,5160.0
72.836007449,5209.0
72.886141256,5355.0
72.936275063,5564.0
72.986408869,5624.0
73.036542676,5902.0
73.086676483,6129.0
73.136810290,6651.0
73.186944097,7001.0
73.237077904,7468.0
73.287211711,8264.0
73.337345518,9460.0
73.387479325,11604.0
73.437613132,15317.0
73.487746939,18923.0
73.537880746,18949.0
73.588014553,16627.0
73.638148360,15818.0
73.688282167,13442.0
73.738415974,12203.0
73.788549780,10335.0
73.838683587,9045.0
73.888817394,6940.0
73.938951201,5877.0
73.989085008,5508.0
74.039218815,5264.0
74.089352622,5100.0
74.139486429,5153.0
74.189620236,5071.0
74.239754043,5105.0
74.289887850,5086.0
74.340021657,4994.0
74.390155464,4980.0
74.440289271,4791.0
74.490423078,4930.0
74.540556885,4886.0
74.590690692,5033.0
74.640824498,4952.0
74.690958305,4942.0
74.741092112,4970.0
74.791225919,4893.0
74.841359726,4872.0
74.891493533,4901.0
74.941627340,4821.0
74.991761147,4733.0
75.041894954,4772.0
75.092028761,4805.0
75.142162568,4817.0
75.192296375,4889.0
75.242430182,4733.0
75.292563989,4800.0
75.342697796,4821.0
75.392831603,4928.0
75.442965409,4767.0
75.493099216,4845.0
75.543233023,4941.0
75.593366830,4764.0
75.643500637,4906.0
75.693634444,4856.0
75.743768251,4714.0
75.793902058,4812.0
75.844035865,4712.0
75.894169672,4691.0
75.944303479,4700.0
75.994437286,4720.0
76.044571093,4697.0
76.094704900,4659.0
76.144838707,4819.0
76.194972514,4675.0
76.245106320,4691.0
76.295240127,4767.0
76.345373934,4806.0
76.395507741,4660.0
76.445641548,4755.0
76.495775355,4784.0
76.545909162,4790.0
76.596042969,4669.0
76.646176776,4731.0
76.696310583,4753.0
76.746444390,4719.0
76.796578197,4664.0
76.846712004,4758.0
76.896845811,4905.0
76.946979618,4892.0
76.997113425,4810.0
77.047247231,4913.0
77.097381038,4909.0
77.147514845,5086.0
77.197648652,5243.0
77.247782459,5206.0
77.297916266,5074.0
77.348050073,5326.0
77.398183880,5347.0
77.448317687,5121.0
77.498451494,5051.0
77.548585301,4913.0
77.598719108,4855.0
77.648852915,4792.0
77.698986722,4858.0
77.749120529,4774.0
77.799254336,4771.0
77.849388142,4744.0
77.899521949,4668.0
77.949655756,4678.0
77.999789563,4679.0
78.049923370,4683.0
78.100057177,4631.0
78.150190984,4837.0
78.200324791,4592.0
78.250458598,4697.0
78.300592405,4642.0
78.350726212,4696.0
78.400860019,4690.0
78.450993826,4683.0
78.501127633,4932.0
78.551261440,4676.0
78.601395247,4682.0
78.651529053,4713.0
78.701662860,4740.0
78.751796667,4724.0
78.801930474,4727.0
78.852064281,4679.0
78.902198088,4669.0
78.952331895,4636.0
79.002465702,4647.0
79.052599509,4752.0
79.102733316,4554.0
79.152867123,4716.0
79.203000930,4679.0
79.253134737,4774.0
79.303268544,4577.0
79.353402351,4731.0
79.403536158,4526.0
79.453669964,4729.0
79.503803771,4802.0
79.553937578,4745.0
79.604071385,4785.0
79.654205192,4628.0
79.704338999,4736.0
79.754472806,4585.0
79.804606613,4587.0
79.854740420,4751.0
79.904874227,4604.0
79.955008034,4683.0
80.005141841,4692.0
80.055275648,4674.0
80.105409455,4685.0
80.155543262,4715.0
80.205677069,4524.0
80.255810875,4607.0
80.305944682,4599.0
80.356078489,4613.0
80.406212296,4660.0
80.456346103,4629.0
80.506479910,4716.0
80.556613717,4610.0
80.606747524,4667.0
80.656881331,4740.0
80.707015138,4635.0
80.757148945,4578.0
80.807282752,4688.0
80.857416559,4594.0
80.907550366,4673.0
80.957684173,4666.0
81.007817980,4689.0
81.057951786,4619.0
81.108085593,4635.0
81.158219400,4659.0
81.208353207,4693.0
81.258487014,4679.0
81.308620821,4713.0
81.358754628,4605.0
81.408888435,4730.0
81.459022242,4669.0
81.509156049,4671.0
81.559289856,4667.0
81.609423663,4862.0
81.659557470,4835.0
81.709691277,4616.0
81.759825084,4675.0
81.809958891,4640.0
81.860092697,4591.0
81.910226504,4669.0
81.960360311,4585.0
82.010494118,4767.0
82.060627925,4602.0
82.110761732,4639.0
82.160895539,4715.0
82.211029346,4663.0
82.261163153,4655.0
82.311296960,4647.0
82.361430767,4758.0
82.411564574,4604.0
82.461698381,4619.0
82.511832188,4639.0
82.561965995,4672.0
82.612099802,4598.0
82.662233608,4641.0
82.712367415,4467.0
82.762501222,4590.0
82.812635029,4710.0
82.862768836,4665.0
82.912902643,4545.0
82.963036450,4591.0
83.013170257,4652.0
83.063304064,4532.0
83.113437871,4558.0
83.163571678,4608.0
83.213705485,4617.0
83.263839292,4538.0
83.313973099,4623.0
83.364106906,4632.0
83.414240713,4664.0
83.464374519,4545.0
83.514508326,4605.0
83.564642133,4628.0
83.614775940,4512.0
83.664909747,4491.0
83.715043554,4493.0
83.765177361,4531.0
83.815311168,4673.0
83.865444975,4594.0
83.915578782,4500.0
83.965712589,4590.0
84.015846396,4625.0
84.065980203,4530.0
84.116114010,4705.0
84.166247817,4430.0
84.216381624,4572.0
84.266515431,4594.0
84.316649237,4474.0
84.366783044,4568.0
84.416916851,4515.0
84.467050658,4734.0
84.517184465,4638.0
84.567318272,4680.0
84.617452079,4575.0
84.667585886,4575.0
84.717719693,4627.0
84.767853500,4671.0
84.817987307,4617.0
84.868121114,4537.0
84.918254921,4631.0
84.968388728,4594.0
85.018522535,4605.0
85.068656342,4672.0
85.118790148,4575.0
85.168923955,4606.0
85.219057762,4506.0
85.269191569,4542.0
85.319325376,4614.0
85.369459183,4606.0
85.419592990,4737.0
85.469726797,4629.0
85.519860604,4585.0
85.569994411,4538.0
85.620128218,4681.0
85.670262025,4456.0
85.720395832,4609.0
85.770529639,4550.0
85.820663446,4485.0
85.870797253,4617.0
85.920931059,4611.0
85.971064866,4613.0
86.021198673,4655.0
86.071332480,4553.0
86.121466287,4695.0
86.171600094,4561.0
86.221733901,4585.0
86.271867708,4616.0
86.322001515,4512.0
86.372135322,4505.0
86.422269129,4634.0
86.472402936,4629.0
86.522536743,4535.0
86.572670550,4676.0
86.622804357,4595.0
86.672938164,4617.0
86.723071970,4703.0
86.773205777,4621.0
86.823339584,4666.0
86.873473391,4588.0
86.923607198,4683.0
86.973741005,4465.0
87.023874812,4619.0
87.074008619,4688.0
87.124142426,4679.0
87.174276233,4543.0
87.224410040,4652.0
87.274543847,4591.0
87.324677654,4567.0
87.374811461,4593.0
87.424945268,4573.0
87.475079075,4698.0
87.525212881,4408.0
87.575346688,4464.0
87.625480495,4558.0
87.675614302,4516.0
87.725748109,4564.0
87.775881916,4476.0
87.826015723,4694.0
87.876149530,4647.0
87.926283337,4663.0
87.976417144,4555.0
88.026550951,4477.0
88.076684758,4614.0
88.126818565,4443.0
88.176952372,4582.0
88.227086179,4485.0
88.277219986,4609.0
88.327353792,4650.0
88.377487599,4529.0
88.427621406,4513.0
88.477755213,4528.0
88.527889020,4564.0
88.578022827,4675.0
88.628156634,4547.0
88.678290441,4602.0
88.728424248,4588.0
88.778558055,4592.0
88.828691862,4684.0
88.878825669,4989.0
88.928959476,5454.0
88.979093283,5943.0
89.029227090,6739.0
89.079360897,7356.0
89.129494703,7095.0
89.179628510,6473.0
89.229762317,6215.0
89.279896124,5973.0
89.330029931,6011.0
89.380163738,6045.0
89.430297545,5701.0
89.480431352,5291.0
89.530565159,4986.0
89.580698966,4758.0
89.630832773,4771.0
89.680966580,4787.0
89.731100387,4612.0
89.781234194,4580.0
89.831368001,4653.0
89.881501808,4622.0
89.931635614,4629.0
89.981769421,4575.0
90.031903228,4650.0
90.082037035,4661.0
90.132170842,4586.0
90.182304649,4674.0
90.232438456,4577.0
90.282572263,4582.0
90.332706070,4598.0
90.382839877,4546.0
90.432973684,4544.0
90.483107491,4599.0
90.533241298,4579.0
90.583375105,4595.0
90.633508912,4561.0
90.683642719,4610.0
90.733776525,4604.0
90.783910332,4578.0
90.834044139,4560.0
90.884177946,4587.0
90.934311753,4601.0
90.984445560,4725.0
91.034579367,4767.0
91.084713174,4511.0
91.134846981,4581.0
91.184980788,4586.0
91.235114595,4679.0
91.285248402,4607.0
91.335382209,4593.0
91.385516016,4614.0
91.435649823,4461.0
91.485783630,4716.0
91.535917436,4597.0
91.586051243,4625.0
91.636185050,4640.0
91.686318857,4742.0
91.736452664,4701.0
91.786586471,4622.0
91.836720278,4715.0
91.886854085,4778.0
91.936987892,4739.0
91.987121699,4739.0
92.037255506,4677.0
92.087389313,4634.0
92.137523120,4669.0
92.187656927,4780.0
92.237790734,4782.0
92.287924541,4653.0
92.338058347,4686.0
92.388192154,4771.0
92.438325961,4761.0
92.488459768,4653.0
92.538593575,4500.0
92.588727382,4599.0
92.638861189,4708.0
92.688994996,4753.0
92.739128803,4613.0
92.789262610,4749.0
92.839396417,4750.0
92.889530224,4642.0
92.939664031,4545.0
92.989797838,4607.0
93.039931645,4577.0
93.090065452,4666.0
93.140199258,4573.0
93.190333065,4598.0
93.240466872,4543.0
93.290600679,4575.0
93.340734486,4716.0
93.390868293,4631.0
93.441002100,4721.0
93.491135907,4544.0
93.541269714,4657.0
93.591403521,4617.0
93.641537328,4874.0
93.691671135,4687.0
93.741804942,4757.0
93.791938749,4743.0
93.842072556,4850.0
93.892206363,4737.0
93.942340170,4652.0
93.992473976,5002.0
94.042607783,5548.0
94.092741590,6328.0
94.142875397,7817.0
94.193009204,9816.0
94.243143011,9198.0
94.293276818,7343.0
94.343410625,7329.0
94.393544432,6671.0
94.443678239,6550.0
94.493812046,7100.0
94.543945853,6848.0
94.594079660,6006.0
94.644213467,5768.0
94.694347274,5463.0
94.744481081,4882.0
94.794614887,4779.0
94.844748694,4761.0
94.894882501,4571.0
94.945016308,4676.0
94.995150115,4592.0
95.045283922,4679.0
95.095417729,4561.0
95.145551536,4628.0
95.195685343,4626.0
95.245819150,4544.0
95.295952957,4596.0
95.346086764,4645.0
95.396220571,4628.0
95.446354378,4578.0
95.496488185,4496.0
95.546621992,4563.0
95.596755798,4592.0
95.646889605,4598.0
95.697023412,4646.0
95.747157219,4774.0
95.797291026,4696.0
95.847424833,4448.0
95.897558640,4574.0
95.947692447,4591.0
95.997826254,4585.0
96.047960061,4492.0
96.098093868,4505.0
96.148227675,4566.0
96.198361482,4516.0
96.248495289,4506.0
96.298629096,4522.0
96.348762903,4527.0
96.398896709,4551.0
96.449030516,4504.0
96.499164323,4504.0
96.549298130,4538.0
96.599431937,4571.0
96.649565744,4625.0
96.699699551,4444.0
96.749833358,4572.0
96.799967165,4555.0
96.850100972,4394.0
96.900234779,4521.0
96.950368586,4417.0
97.000502393,4660.0
97.050636200,4571.0
97.100770007,4631.0
97.150903814,4470.0
97.201037620,4602.0
97.251171427,4668.0
97.301305234,4586.0
97.351439041,4358.0
97.401572848,4545.0
97.451706655,4588.0
97.501840462,4670.0
97.551974269,4561.0
97.602108076,4604.0
97.652241883,4616.0
97.702375690,4566.0
97.752509497,4591.0
97.802643304,4435.0
97.852777111,4487.0
97.902910918,4539.0
97.953044725,4445.0
98.003178531,4576.0
98.053312338,4548.0
98.103446145,4635.0
98.153579952,4590.0
98.203713759,4498.0
98.253847566,4556.0
98.303981373,4595.0
98.354115180,4653.0
98.404248987,4511.0
98.454382794,4469.0
98.504516601,4531.0
98.554650408,4434.0
98.604784215,4443.0
98.654918022,4476.0
98.705051829,4449.0
98.755185636,4509.0
98.805319442,4449.0
98.855453249,4606.0
98.905587056,4532.0
98.955720863,4694.0
99.005854670,4459.0
99.055988477,4538.0
99.106122284,4413.0
99.156256091,4454.0
99.206389898,4389.0
99.256523705,4487.0
99.306657512,4643.0
99.356791319,4479.0
99.406925126,4575.0
99.457058933,4535.0
99.507192740,4647.0
99.557326547,4519.0
99.607460353,4571.0
99.657594160,4512.0
99.707727967,4435.0
99.757861774,4420.0
99.807995581,4438.0
99.858129388,4510.0
99.908263195,4619.0
99.958397002,4556.0
99.991819540,4563.0