File: OriginPro/XRD from Panalytical X'Pert PRO/Nova Cu foil/Cufoil_50°C.csv
[Measurement conditions]
Sample identification,
Comment - 1,"finito"
Comment - 2,"Configuration=MRI TC-Basic Stage, Owner=User-1, Creation date=26-10-2009 9:18:44"
Comment - 3,"Goniometer=PW3050/60 (Theta/Theta); Minimum step size 2Theta:0.001; Minimum step size Omega:0.001"
Comment - 4,"Sample stage=MRI TC-Basic (PtRh heat strip)"
Comment - 5,"Diffractometer system=XPERT-PRO"
Comment - 6,"Measurement program=FlatStage, Owner=joana, Creation date=03-08-2011 15:43:53"
Anode material,Cu
K-Alpha1 wavelength,1.5405980
K-Alpha2 wavelength,1.5444260
Ratio K-Alpha2/K-Alpha1,0.500
Divergence slit,Fixed,0.76mm
Monochromator used,NO
Generator voltage, 45
Tube current, 40
File date and time,06/Dec/2012 19:33
Unit cell,
h k l, 0 0 0
Temperature [K],324
Scan axis,Gonio
Scan range,24.999999996,100.000175174
Scan step size,0.0167113
No. of points, 4488
Scan type,CONTINUOUS
Time per step,53.340
[Scan points]
Angle,Intensity
25.008355630,4645.0
25.058489437,4656.0
25.108623244,4490.0
25.158757051,4559.0
25.208890858,4653.0
25.259024665,4581.0
25.309158472,4547.0
25.359292279,4673.0
25.409426086,4483.0
25.459559892,4677.0
25.509693699,4500.0
25.559827506,4544.0
25.609961313,4553.0
25.660095120,4510.0
25.710228927,4622.0
25.760362734,4413.0
25.810496541,4567.0
25.860630348,4527.0
25.910764155,4516.0
25.960897962,4602.0
26.011031769,4554.0
26.061165576,4566.0
26.111299383,4456.0
26.161433190,4475.0
26.211566997,4430.0
26.261700803,4528.0
26.311834610,4617.0
26.361968417,4598.0
26.412102224,4396.0
26.462236031,4555.0
26.512369838,4557.0
26.562503645,4570.0
26.612637452,4633.0
26.662771259,4460.0
26.712905066,4512.0
26.763038873,4563.0
26.813172680,4497.0
26.863306487,4441.0
26.913440294,4561.0
26.963574101,4588.0
27.013707908,4493.0
27.063841714,4513.0
27.113975521,4651.0
27.164109328,4569.0
27.214243135,4476.0
27.264376942,4597.0
27.314510749,4453.0
27.364644556,4433.0
27.414778363,4441.0
27.464912170,4480.0
27.515045977,4639.0
27.565179784,4595.0
27.615313591,4485.0
27.665447398,4531.0
27.715581205,4473.0
27.765715012,4661.0
27.815848819,4750.0
27.865982625,4573.0
27.916116432,4660.0
27.966250239,4440.0
28.016384046,4645.0
28.066517853,4506.0
28.116651660,4493.0
28.166785467,4552.0
28.216919274,4560.0
28.267053081,4557.0
28.317186888,4565.0
28.367320695,4592.0
28.417454502,4640.0
28.467588309,4499.0
28.517722116,4511.0
28.567855923,4559.0
28.617989730,4411.0
28.668123536,4599.0
28.718257343,4489.0
28.768391150,4604.0
28.818524957,4543.0
28.868658764,4506.0
28.918792571,4585.0
28.968926378,4492.0
29.019060185,4540.0
29.069193992,4430.0
29.119327799,4386.0
29.169461606,4542.0
29.219595413,4496.0
29.269729220,4586.0
29.319863027,4558.0
29.369996834,4564.0
29.420130641,4498.0
29.470264447,4643.0
29.520398254,4566.0
29.570532061,4429.0
29.620665868,4463.0
29.670799675,4475.0
29.720933482,4495.0
29.771067289,4515.0
29.821201096,4454.0
29.871334903,4480.0
29.921468710,4422.0
29.971602517,4427.0
30.021736324,4470.0
30.071870131,4496.0
30.122003938,4423.0
30.172137745,4408.0
30.222271552,4384.0
30.272405358,4450.0
30.322539165,4457.0
30.372672972,4461.0
30.422806779,4573.0
30.472940586,4441.0
30.523074393,4309.0
30.573208200,4494.0
30.623342007,4525.0
30.673475814,4462.0
30.723609621,4544.0
30.773743428,4495.0
30.823877235,4341.0
30.874011042,4494.0
30.924144849,4484.0
30.974278656,4504.0
31.024412463,4431.0
31.074546269,4515.0
31.124680076,4471.0
31.174813883,4491.0
31.224947690,4433.0
31.275081497,4467.0
31.325215304,4488.0
31.375349111,4405.0
31.425482918,4516.0
31.475616725,4462.0
31.525750532,4403.0
31.575884339,4454.0
31.626018146,4423.0
31.676151953,4490.0
31.726285760,4399.0
31.776419567,4459.0
31.826553374,4512.0
31.876687180,4458.0
31.926820987,4450.0
31.976954794,4555.0
32.027088601,4513.0
32.077222408,4461.0
32.127356215,4622.0
32.177490022,4430.0
32.227623829,4555.0
32.277757636,4447.0
32.327891443,4443.0
32.378025250,4446.0
32.428159057,4516.0
32.478292864,4508.0
32.528426671,4614.0
32.578560478,4545.0
32.628694285,4358.0
32.678828091,4589.0
32.728961898,4369.0
32.779095705,4507.0
32.829229512,4345.0
32.879363319,4393.0
32.929497126,4467.0
32.979630933,4446.0
33.029764740,4550.0
33.079898547,4488.0
33.130032354,4493.0
33.180166161,4349.0
33.230299968,4492.0
33.280433775,4549.0
33.330567582,4544.0
33.380701389,4479.0
33.430835196,4415.0
33.480969002,4346.0
33.531102809,4404.0
33.581236616,4573.0
33.631370423,4649.0
33.681504230,4490.0
33.731638037,4479.0
33.781771844,4335.0
33.831905651,4448.0
33.882039458,4432.0
33.932173265,4619.0
33.982307072,4473.0
34.032440879,4433.0
34.082574686,4587.0
34.132708493,4454.0
34.182842300,4437.0
34.232976107,4440.0
34.283109913,4506.0
34.333243720,4496.0
34.383377527,4462.0
34.433511334,4439.0
34.483645141,4591.0
34.533778948,4433.0
34.583912755,4387.0
34.634046562,4367.0
34.684180369,4420.0
34.734314176,4599.0
34.784447983,4541.0
34.834581790,4485.0
34.884715597,4575.0
34.934849404,4396.0
34.984983211,4394.0
35.035117018,4434.0
35.085250825,4474.0
35.135384631,4496.0
35.185518438,4444.0
35.235652245,4464.0
35.285786052,4420.0
35.335919859,4525.0
35.386053666,4493.0
35.436187473,4527.0
35.486321280,4447.0
35.536455087,4470.0
35.586588894,4447.0
35.636722701,4503.0
35.686856508,4365.0
35.736990315,4313.0
35.787124122,4375.0
35.837257929,4353.0
35.887391736,4424.0
35.937525542,4339.0
35.987659349,4474.0
36.037793156,4550.0
36.087926963,4441.0
36.138060770,4396.0
36.188194577,4509.0
36.238328384,4434.0
36.288462191,4334.0
36.338595998,4575.0
36.388729805,4438.0
36.438863612,4475.0
36.488997419,4411.0
36.539131226,4348.0
36.589265033,4432.0
36.639398840,4345.0
36.689532647,4425.0
36.739666453,4550.0
36.789800260,4467.0
36.839934067,4440.0
36.890067874,4492.0
36.940201681,4477.0
36.990335488,4584.0
37.040469295,4576.0
37.090603102,4468.0
37.140736909,4358.0
37.190870716,4422.0
37.241004523,4401.0
37.291138330,4565.0
37.341272137,4298.0
37.391405944,4489.0
37.441539751,4464.0
37.491673558,4470.0
37.541807364,4483.0
37.591941171,4656.0
37.642074978,4533.0
37.692208785,4560.0
37.742342592,4521.0
37.792476399,4462.0
37.842610206,4518.0
37.892744013,4596.0
37.942877820,4382.0
37.993011627,4543.0
38.043145434,4445.0
38.093279241,4515.0
38.143413048,4484.0
38.193546855,4461.0
38.243680662,4604.0
38.293814469,4634.0
38.343948275,4466.0
38.394082082,4592.0
38.444215889,4617.0
38.494349696,4568.0
38.544483503,4542.0
38.594617310,4528.0
38.644751117,4575.0
38.694884924,4728.0
38.745018731,5165.0
38.795152538,5483.0
38.845286345,4665.0
38.895420152,4529.0
38.945553959,4537.0
38.995687766,4427.0
39.045821573,4699.0
39.095955380,4650.0
39.146089186,4447.0
39.196222993,4637.0
39.246356800,4532.0
39.296490607,4548.0
39.346624414,4568.0
39.396758221,4569.0
39.446892028,4460.0
39.497025835,4790.0
39.547159642,4612.0
39.597293449,4587.0
39.647427256,4607.0
39.697561063,4529.0
39.747694870,4547.0
39.797828677,4577.0
39.847962484,4570.0
39.898096291,4459.0
39.948230097,4591.0
39.998363904,4350.0
40.048497711,4516.0
40.098631518,4594.0
40.148765325,4486.0
40.198899132,4566.0
40.249032939,4486.0
40.299166746,4460.0
40.349300553,4562.0
40.399434360,4428.0
40.449568167,4613.0
40.499701974,4656.0
40.549835781,4615.0
40.599969588,4498.0
40.650103395,4661.0
40.700237202,4572.0
40.750371008,4535.0
40.800504815,4526.0
40.850638622,4527.0
40.900772429,4653.0
40.950906236,4536.0
41.001040043,4501.0
41.051173850,4419.0
41.101307657,4697.0
41.151441464,4664.0
41.201575271,4438.0
41.251709078,4604.0
41.301842885,4575.0
41.351976692,4621.0
41.402110499,4697.0
41.452244306,4651.0
41.502378113,4656.0
41.552511919,4993.0
41.602645726,5460.0
41.652779533,5552.0
41.702913340,5387.0
41.753047147,5555.0
41.803180954,5491.0
41.853314761,5577.0
41.903448568,5468.0
41.953582375,5511.0
42.003716182,5417.0
42.053849989,5596.0
42.103983796,5617.0
42.154117603,5713.0
42.204251410,5946.0
42.254385217,5627.0
42.304519024,5627.0
42.354652830,5649.0
42.404786637,5680.0
42.454920444,5820.0
42.505054251,5866.0
42.555188058,5849.0
42.605321865,6015.0
42.655455672,6326.0
42.705589479,6451.0
42.755723286,7063.0
42.805857093,8484.0
42.855990900,11714.0
42.906124707,14672.0
42.956258514,19482.0
43.006392321,28770.0
43.056526128,73241.0
43.106659935,288425.0
43.156793741,329958.0
43.206927548,132503.0
43.257061355,228342.0
43.307195162,42845.0
43.357328969,18134.0
43.407462776,12182.0
43.457596583,9705.0
43.507730390,7977.0
43.557864197,7094.0
43.607998004,6771.0
43.658131811,6444.0
43.708265618,6434.0
43.758399425,6064.0
43.808533232,5921.0
43.858667039,5809.0
43.908800846,5720.0
43.958934652,5739.0
44.009068459,5691.0
44.059202266,5475.0
44.109336073,5505.0
44.159469880,5376.0
44.209603687,5515.0
44.259737494,5282.0
44.309871301,5322.0
44.360005108,5368.0
44.410138915,5255.0
44.460272722,5326.0
44.510406529,5123.0
44.560540336,5278.0
44.610674143,5270.0
44.660807950,5187.0
44.710941757,5420.0
44.761075564,5157.0
44.811209370,5186.0
44.861343177,5175.0
44.911476984,5234.0
44.961610791,5211.0
45.011744598,5103.0
45.061878405,5401.0
45.112012212,5918.0
45.162146019,5427.0
45.212279826,5102.0
45.262413633,5111.0
45.312547440,5201.0
45.362681247,4948.0
45.412815054,5095.0
45.462948861,4892.0
45.513082668,5056.0
45.563216475,5011.0
45.613350281,5110.0
45.663484088,5064.0
45.713617895,4975.0
45.763751702,5061.0
45.813885509,5078.0
45.864019316,4971.0
45.914153123,4917.0
45.964286930,4966.0
46.014420737,4947.0
46.064554544,4970.0
46.114688351,5038.0
46.164822158,4860.0
46.214955965,4887.0
46.265089772,5014.0
46.315223579,4922.0
46.365357386,4941.0
46.415491192,5032.0
46.465624999,5045.0
46.515758806,5204.0
46.565892613,5107.0
46.616026420,5236.0
46.666160227,5135.0
46.716294034,4969.0
46.766427841,4969.0
46.816561648,5047.0
46.866695455,5337.0
46.916829262,5250.0
46.966963069,5269.0
47.017096876,4985.0
47.067230683,4961.0
47.117364490,4836.0
47.167498297,4841.0
47.217632103,5008.0
47.267765910,4770.0
47.317899717,4944.0
47.368033524,4775.0
47.418167331,4919.0
47.468301138,4923.0
47.518434945,4773.0
47.568568752,4790.0
47.618702559,4744.0
47.668836366,4799.0
47.718970173,4781.0
47.769103980,4763.0
47.819237787,4811.0
47.869371594,4762.0
47.919505401,4782.0
47.969639208,4856.0
48.019773014,4709.0
48.069906821,4814.0
48.120040628,4729.0
48.170174435,4836.0
48.220308242,4881.0
48.270442049,4647.0
48.320575856,4833.0
48.370709663,4728.0
48.420843470,5248.0
48.470977277,5515.0
48.521111084,5485.0
48.571244891,5458.0
48.621378698,5302.0
48.671512505,5390.0
48.721646312,5447.0
48.771780119,5347.0
48.821913925,5468.0
48.872047732,5496.0
48.922181539,5403.0
48.972315346,5226.0
49.022449153,5351.0
49.072582960,5690.0
49.122716767,5660.0
49.172850574,5639.0
49.222984381,5462.0
49.273118188,5485.0
49.323251995,5467.0
49.373385802,5516.0
49.423519609,5551.0
49.473653416,5625.0
49.523787223,5719.0
49.573921030,5798.0
49.624054836,5828.0
49.674188643,5764.0
49.724322450,6065.0
49.774456257,6238.0
49.824590064,6550.0
49.874723871,7116.0
49.924857678,8200.0
49.974991485,11049.0
50.025125292,14413.0
50.075259099,16857.0
50.125392906,23315.0
50.175526713,50584.0
50.225660520,169264.0
50.275794327,353321.0
50.325928134,112301.0
50.376061941,144488.0
50.426195747,139586.0
50.476329554,34393.0
50.526463361,16382.0
50.576597168,11596.0
50.626730975,8972.0
50.676864782,7627.0
50.726998589,7062.0
50.777132396,6490.0
50.827266203,6127.0
50.877400010,5888.0
50.927533817,5770.0
50.977667624,5744.0
51.027801431,5802.0
51.077935238,5524.0
51.128069045,5423.0
51.178202852,5494.0
51.228336658,5387.0
51.278470465,5310.0
51.328604272,5334.0
51.378738079,5298.0
51.428871886,5227.0
51.479005693,5259.0
51.529139500,5081.0
51.579273307,5082.0
51.629407114,5124.0
51.679540921,5116.0
51.729674728,5082.0
51.779808535,5048.0
51.829942342,5094.0
51.880076149,5017.0
51.930209956,4864.0
51.980343763,5045.0
52.030477569,4893.0
52.080611376,4974.0
52.130745183,4955.0
52.180878990,4945.0
52.231012797,4902.0
52.281146604,4915.0
52.331280411,4860.0
52.381414218,4915.0
52.431548025,4890.0
52.481681832,4852.0
52.531815639,4845.0
52.581949446,4854.0
52.632083253,4841.0
52.682217060,4745.0
52.732350867,4816.0
52.782484674,4842.0
52.832618480,4907.0
52.882752287,4749.0
52.932886094,4731.0
52.983019901,4929.0
53.033153708,4790.0
53.083287515,4726.0
53.133421322,4757.0
53.183555129,4752.0
53.233688936,4732.0
53.283822743,4738.0
53.333956550,4717.0
53.384090357,4763.0
53.434224164,4708.0
53.484357971,4789.0
53.534491778,4812.0
53.584625585,4791.0
53.634759391,4692.0
53.684893198,4711.0
53.735027005,4788.0
53.785160812,4797.0
53.835294619,4585.0
53.885428426,4735.0
53.935562233,4619.0
53.985696040,4737.0
54.035829847,4781.0
54.085963654,4724.0
54.136097461,4697.0
54.186231268,4664.0
54.236365075,4622.0
54.286498882,4880.0
54.336632689,4806.0
54.386766496,4899.0
54.436900303,4714.0
54.487034109,4760.0
54.537167916,4782.0
54.587301723,4784.0
54.637435530,5088.0
54.687569337,5061.0
54.737703144,4854.0
54.787836951,4996.0
54.837970758,4825.0
54.888104565,4686.0
54.938238372,4697.0
54.988372179,4622.0
55.038505986,4525.0
55.088639793,4628.0
55.138773600,4639.0
55.188907407,4662.0
55.239041214,4606.0
55.289175020,4535.0
55.339308827,4568.0
55.389442634,4615.0
55.439576441,4607.0
55.489710248,4553.0
55.539844055,4510.0
55.589977862,4678.0
55.640111669,4583.0
55.690245476,4523.0
55.740379283,4635.0
55.790513090,4547.0
55.840646897,4561.0
55.890780704,4665.0
55.940914511,4427.0
55.991048318,4491.0
56.041182125,4635.0
56.091315931,4607.0
56.141449738,4567.0
56.191583545,4537.0
56.241717352,4593.0
56.291851159,4508.0
56.341984966,4443.0
56.392118773,4525.0
56.442252580,4535.0
56.492386387,4576.0
56.542520194,4670.0
56.592654001,4444.0
56.642787808,4499.0
56.692921615,4363.0
56.743055422,4511.0
56.793189229,4492.0
56.843323036,4496.0
56.893456842,4403.0
56.943590649,4443.0
56.993724456,4585.0
57.043858263,4391.0
57.093992070,4543.0
57.144125877,4441.0
57.194259684,4557.0
57.244393491,4388.0
57.294527298,4426.0
57.344661105,4547.0
57.394794912,4491.0
57.444928719,4485.0
57.495062526,4563.0
57.545196333,4477.0
57.595330140,4666.0
57.645463947,4577.0
57.695597753,4524.0
57.745731560,4430.0
57.795865367,4434.0
57.845999174,4534.0
57.896132981,4571.0
57.946266788,4466.0
57.996400595,4486.0
58.046534402,4463.0
58.096668209,4447.0
58.146802016,4459.0
58.196935823,4461.0
58.247069630,4507.0
58.297203437,4496.0
58.347337244,4494.0
58.397471051,4486.0
58.447604858,4463.0
58.497738664,4482.0
58.547872471,4493.0
58.598006278,4404.0
58.648140085,4463.0
58.698273892,4465.0
58.748407699,4350.0
58.798541506,4464.0
58.848675313,4500.0
58.898809120,4426.0
58.948942927,4432.0
58.999076734,4462.0
59.049210541,4487.0
59.099344348,4473.0
59.149478155,4395.0
59.199611962,4481.0
59.249745769,4480.0
59.299879575,4416.0
59.350013382,4328.0
59.400147189,4452.0
59.450280996,4455.0
59.500414803,4277.0
59.550548610,4372.0
59.600682417,4581.0
59.650816224,4358.0
59.700950031,4395.0
59.751083838,4533.0
59.801217645,4388.0
59.851351452,4459.0
59.901485259,4407.0
59.951619066,4355.0
60.001752873,4357.0
60.051886680,4472.0
60.102020486,4448.0
60.152154293,4459.0
60.202288100,4347.0
60.252421907,4458.0
60.302555714,4508.0
60.352689521,4377.0
60.402823328,4287.0
60.452957135,4423.0
60.503090942,4378.0
60.553224749,4366.0
60.603358556,4444.0
60.653492363,4407.0
60.703626170,4461.0
60.753759977,4450.0
60.803893784,4491.0
60.854027591,4567.0
60.904161397,4350.0
60.954295204,4529.0
61.004429011,4395.0
61.054562818,4305.0
61.104696625,4351.0
61.154830432,4451.0
61.204964239,4434.0
61.255098046,4373.0
61.305231853,4476.0
61.355365660,4456.0
61.405499467,4333.0
61.455633274,4309.0
61.505767081,4364.0
61.555900888,4451.0
61.606034695,4414.0
61.656168502,4433.0
61.706302308,4434.0
61.756436115,4481.0
61.806569922,4428.0
61.856703729,4400.0
61.906837536,4288.0
61.956971343,4407.0
62.007105150,4371.0
62.057238957,4362.0
62.107372764,4418.0
62.157506571,4431.0
62.207640378,4448.0
62.257774185,4276.0
62.307907992,4376.0
62.358041799,4413.0
62.408175606,4389.0
62.458309413,4412.0
62.508443219,4260.0
62.558577026,4484.0
62.608710833,4331.0
62.658844640,4382.0
62.708978447,4385.0
62.759112254,4448.0
62.809246061,4408.0
62.859379868,4353.0
62.909513675,4437.0
62.959647482,4416.0
63.009781289,4454.0
63.059915096,4463.0
63.110048903,4388.0
63.160182710,4409.0
63.210316517,4348.0
63.260450324,4432.0
63.310584130,4384.0
63.360717937,4385.0
63.410851744,4499.0
63.460985551,4514.0
63.511119358,4439.0
63.561253165,4525.0
63.611386972,4399.0
63.661520779,4470.0
63.711654586,4416.0
63.761788393,4457.0
63.811922200,4308.0
63.862056007,4283.0
63.912189814,4488.0
63.962323621,4360.0
64.012457428,4411.0
64.062591235,4280.0
64.112725041,4344.0
64.162858848,4325.0
64.212992655,4356.0
64.263126462,4346.0
64.313260269,4396.0
64.363394076,4283.0
64.413527883,4358.0
64.463661690,4362.0
64.513795497,4448.0
64.563929304,4306.0
64.614063111,4321.0
64.664196918,4499.0
64.714330725,4426.0
64.764464532,4327.0
64.814598339,4382.0
64.864732146,4300.0
64.914865953,4340.0
64.964999759,4404.0
65.015133566,4279.0
65.065267373,4401.0
65.115401180,4405.0
65.165534987,4330.0
65.215668794,4305.0
65.265802601,4251.0
65.315936408,4395.0
65.366070215,4397.0
65.416204022,4454.0
65.466337829,4412.0
65.516471636,4446.0
65.566605443,4515.0
65.616739250,4300.0
65.666873057,4367.0
65.717006864,4392.0
65.767140670,4529.0
65.817274477,4491.0
65.867408284,4468.0
65.917542091,4562.0
65.967675898,4372.0
66.017809705,4440.0
66.067943512,4328.0
66.118077319,4427.0
66.168211126,4432.0
66.218344933,4359.0
66.268478740,4406.0
66.318612547,4307.0
66.368746354,4352.0
66.418880161,4429.0
66.469013968,4339.0
66.519147775,4382.0
66.569281581,4385.0
66.619415388,4286.0
66.669549195,4462.0
66.719683002,4446.0
66.769816809,4330.0
66.819950616,4341.0
66.870084423,4369.0
66.920218230,4510.0
66.970352037,4443.0
67.020485844,4273.0
67.070619651,4318.0
67.120753458,4397.0
67.170887265,4430.0
67.221021072,4427.0
67.271154879,4304.0
67.321288686,4362.0
67.371422492,4367.0
67.421556299,4309.0
67.471690106,4393.0
67.521823913,4405.0
67.571957720,4347.0
67.622091527,4322.0
67.672225334,4253.0
67.722359141,4353.0
67.772492948,4360.0
67.822626755,4374.0
67.872760562,4532.0
67.922894369,4390.0
67.973028176,4607.0
68.023161983,4602.0
68.073295790,4463.0
68.123429597,4473.0
68.173563403,4525.0
68.223697210,4435.0
68.273831017,4410.0
68.323964824,4267.0
68.374098631,4442.0
68.424232438,4234.0
68.474366245,4305.0
68.524500052,4312.0
68.574633859,4330.0
68.624767666,4280.0
68.674901473,4374.0
68.725035280,4443.0
68.775169087,4367.0
68.825302894,4361.0
68.875436701,4266.0
68.925570508,4334.0
68.975704314,4394.0
69.025838121,4342.0
69.075971928,4282.0
69.126105735,4448.0
69.176239542,4367.0
69.226373349,4413.0
69.276507156,4382.0
69.326640963,4310.0
69.376774770,4366.0
69.426908577,4434.0
69.477042384,4415.0
69.527176191,4263.0
69.577309998,4358.0
69.627443805,4428.0
69.677577612,4356.0
69.727711419,4308.0
69.777845225,4302.0
69.827979032,4284.0
69.878112839,4395.0
69.928246646,4337.0
69.978380453,4394.0
70.028514260,4362.0
70.078648067,4364.0
70.128781874,4356.0
70.178915681,4335.0
70.229049488,4332.0
70.279183295,4380.0
70.329317102,4298.0
70.379450909,4339.0
70.429584716,4419.0
70.479718523,4341.0
70.529852330,4348.0
70.579986136,4309.0
70.630119943,4300.0
70.680253750,4391.0
70.730387557,4364.0
70.780521364,4297.0
70.830655171,4490.0
70.880788978,4424.0
70.930922785,4378.0
70.981056592,4430.0
71.031190399,4385.0
71.081324206,4516.0
71.131458013,4458.0
71.181591820,4428.0
71.231725627,4456.0
71.281859434,4556.0
71.331993241,4425.0
71.382127047,4436.0
71.432260854,4457.0
71.482394661,4609.0
71.532528468,4632.0
71.582662275,4448.0
71.632796082,4517.0
71.682929889,4483.0
71.733063696,4496.0
71.783197503,4569.0
71.833331310,4502.0
71.883465117,4563.0
71.933598924,4423.0
71.983732731,4587.0
72.033866538,4406.0
72.084000345,4639.0
72.134134152,4561.0
72.184267958,4471.0
72.234401765,4526.0
72.284535572,4559.0
72.334669379,4430.0
72.384803186,4537.0
72.434936993,4526.0
72.485070800,4399.0
72.535204607,4546.0
72.585338414,4337.0
72.635472221,4494.0
72.685606028,4352.0
72.735739835,4574.0
72.785873642,4555.0
72.836007449,4705.0
72.886141256,4556.0
72.936275063,4468.0
72.986408869,4558.0
73.036542676,4574.0
73.086676483,4488.0
73.136810290,4437.0
73.186944097,4516.0
73.237077904,4717.0
73.287211711,4579.0
73.337345518,4569.0
73.387479325,4653.0
73.437613132,4789.0
73.487746939,4992.0
73.537880746,5132.0
73.588014553,5265.0
73.638148360,5629.0
73.688282167,5775.0
73.738415974,6288.0
73.788549780,7381.0
73.838683587,9998.0
73.888817394,21675.0
73.938951201,62335.0
73.989085008,40668.0
74.039218815,14755.0
74.089352622,13508.0
74.139486429,27519.0
74.189620236,30445.0
74.239754043,11917.0
74.289887850,7327.0
74.340021657,5906.0
74.390155464,5467.0
74.440289271,5081.0
74.490423078,4904.0
74.540556885,4846.0
74.590690692,4930.0
74.640824498,4734.0
74.690958305,4621.0
74.741092112,4555.0
74.791225919,4675.0
74.841359726,4536.0
74.891493533,4645.0
74.941627340,4657.0
74.991761147,4386.0
75.041894954,4662.0
75.092028761,4436.0
75.142162568,4538.0
75.192296375,4488.0
75.242430182,4451.0
75.292563989,4445.0
75.342697796,4396.0
75.392831603,4482.0
75.442965409,4509.0
75.493099216,4570.0
75.543233023,4449.0
75.593366830,4635.0
75.643500637,4578.0
75.693634444,4533.0
75.743768251,4499.0
75.793902058,4540.0
75.844035865,4438.0
75.894169672,4366.0
75.944303479,4470.0
75.994437286,4562.0
76.044571093,4455.0
76.094704900,4443.0
76.144838707,4476.0
76.194972514,4484.0
76.245106320,4375.0
76.295240127,4442.0
76.345373934,4513.0
76.395507741,4400.0
76.445641548,4414.0
76.495775355,4369.0
76.545909162,4424.0
76.596042969,4561.0
76.646176776,4365.0
76.696310583,4401.0
76.746444390,4535.0
76.796578197,4283.0
76.846712004,4295.0
76.896845811,4316.0
76.946979618,4342.0
76.997113425,4364.0
77.047247231,4468.0
77.097381038,4312.0
77.147514845,4356.0
77.197648652,4495.0
77.247782459,4410.0
77.297916266,4386.0
77.348050073,4408.0
77.398183880,4474.0
77.448317687,4444.0
77.498451494,4565.0
77.548585301,4358.0
77.598719108,4473.0
77.648852915,4443.0
77.698986722,4381.0
77.749120529,4489.0
77.799254336,4525.0
77.849388142,4314.0
77.899521949,4426.0
77.949655756,4345.0
77.999789563,4440.0
78.049923370,4403.0
78.100057177,4362.0
78.150190984,4472.0
78.200324791,4421.0
78.250458598,4500.0
78.300592405,4508.0
78.350726212,4365.0
78.400860019,4285.0
78.450993826,4286.0
78.501127633,4409.0
78.551261440,4429.0
78.601395247,4474.0
78.651529053,4409.0
78.701662860,4356.0
78.751796667,4359.0
78.801930474,4494.0
78.852064281,4366.0
78.902198088,4369.0
78.952331895,4413.0
79.002465702,4390.0
79.052599509,4359.0
79.102733316,4449.0
79.152867123,4471.0
79.203000930,4504.0
79.253134737,4484.0
79.303268544,4298.0
79.353402351,4405.0
79.403536158,4372.0
79.453669964,4474.0
79.503803771,4409.0
79.553937578,4477.0
79.604071385,4307.0
79.654205192,4485.0
79.704338999,4448.0
79.754472806,4437.0
79.804606613,4407.0
79.854740420,4284.0
79.904874227,4291.0
79.955008034,4436.0
80.005141841,4374.0
80.055275648,4361.0
80.105409455,4140.0
80.155543262,4352.0
80.205677069,4437.0
80.255810875,4474.0
80.305944682,4376.0
80.356078489,4316.0
80.406212296,4294.0
80.456346103,4435.0
80.506479910,4292.0
80.556613717,4389.0
80.606747524,4355.0
80.656881331,4347.0
80.707015138,4532.0
80.757148945,4362.0
80.807282752,4258.0
80.857416559,4298.0
80.907550366,4431.0
80.957684173,4451.0
81.007817980,4350.0
81.057951786,4291.0
81.108085593,4351.0
81.158219400,4412.0
81.208353207,4339.0
81.258487014,4571.0
81.308620821,4399.0
81.358754628,4457.0
81.408888435,4373.0
81.459022242,4374.0
81.509156049,4323.0
81.559289856,4329.0
81.609423663,4462.0
81.659557470,4346.0
81.709691277,4285.0
81.759825084,4362.0
81.809958891,4398.0
81.860092697,4450.0
81.910226504,4440.0
81.960360311,4602.0
82.010494118,4355.0
82.060627925,4475.0
82.110761732,4449.0
82.160895539,4455.0
82.211029346,4435.0
82.261163153,4533.0
82.311296960,4541.0
82.361430767,4282.0
82.411564574,4424.0
82.461698381,4276.0
82.511832188,4310.0
82.561965995,4439.0
82.612099802,4402.0
82.662233608,4415.0
82.712367415,4425.0
82.762501222,4581.0
82.812635029,4310.0
82.862768836,4312.0
82.912902643,4350.0
82.963036450,4537.0
83.013170257,4438.0
83.063304064,4494.0
83.113437871,4477.0
83.163571678,4434.0
83.213705485,4420.0
83.263839292,4458.0
83.313973099,4408.0
83.364106906,4321.0
83.414240713,4383.0
83.464374519,4463.0
83.514508326,4455.0
83.564642133,4359.0
83.614775940,4495.0
83.664909747,4448.0
83.715043554,4417.0
83.765177361,4329.0
83.815311168,4353.0
83.865444975,4409.0
83.915578782,4182.0
83.965712589,4274.0
84.015846396,4478.0
84.065980203,4340.0
84.116114010,4290.0
84.166247817,4380.0
84.216381624,4408.0
84.266515431,4374.0
84.316649237,4288.0
84.366783044,4391.0
84.416916851,4365.0
84.467050658,4438.0
84.517184465,4380.0
84.567318272,4410.0
84.617452079,4338.0
84.667585886,4349.0
84.717719693,4434.0
84.767853500,4376.0
84.817987307,4444.0
84.868121114,4430.0
84.918254921,4337.0
84.968388728,4478.0
85.018522535,4317.0
85.068656342,4433.0
85.118790148,4323.0
85.168923955,4387.0
85.219057762,4305.0
85.269191569,4397.0
85.319325376,4471.0
85.369459183,4381.0
85.419592990,4317.0
85.469726797,4130.0
85.519860604,4350.0
85.569994411,4400.0
85.620128218,4402.0
85.670262025,4435.0
85.720395832,4285.0
85.770529639,4276.0
85.820663446,4240.0
85.870797253,4493.0
85.920931059,4510.0
85.971064866,4407.0
86.021198673,4309.0
86.071332480,4396.0
86.121466287,4284.0
86.171600094,4473.0
86.221733901,4391.0
86.271867708,4343.0
86.322001515,4357.0
86.372135322,4301.0
86.422269129,4425.0
86.472402936,4368.0
86.522536743,4470.0
86.572670550,4330.0
86.622804357,4286.0
86.672938164,4282.0
86.723071970,4431.0
86.773205777,4467.0
86.823339584,4525.0
86.873473391,4262.0
86.923607198,4415.0
86.973741005,4332.0
87.023874812,4299.0
87.074008619,4306.0
87.124142426,4375.0
87.174276233,4484.0
87.224410040,4232.0
87.274543847,4425.0
87.324677654,4483.0
87.374811461,4378.0
87.424945268,4338.0
87.475079075,4326.0
87.525212881,4458.0
87.575346688,4346.0
87.625480495,4408.0
87.675614302,4351.0
87.725748109,4315.0
87.775881916,4452.0
87.826015723,4440.0
87.876149530,4430.0
87.926283337,4300.0
87.976417144,4423.0
88.026550951,4465.0
88.076684758,4413.0
88.126818565,4440.0
88.176952372,4234.0
88.227086179,4311.0
88.277219986,4255.0
88.327353792,4472.0
88.377487599,4445.0
88.427621406,4380.0
88.477755213,4347.0
88.527889020,4412.0
88.578022827,4495.0
88.628156634,4391.0
88.678290441,4393.0
88.728424248,4473.0
88.778558055,4363.0
88.828691862,4416.0
88.878825669,4355.0
88.928959476,4454.0
88.979093283,4512.0
89.029227090,4417.0
89.079360897,4491.0
89.129494703,4419.0
89.179628510,4501.0
89.229762317,4546.0
89.279896124,4641.0
89.330029931,4711.0
89.380163738,4737.0
89.430297545,4837.0
89.480431352,4990.0
89.530565159,5130.0
89.580698966,5493.0
89.630832773,6427.0
89.680966580,8995.0
89.731100387,16696.0
89.781234194,22602.0
89.831368001,13096.0
89.881501808,8031.0
89.931635614,7066.0
89.981769421,8181.0
90.031903228,12669.0
90.082037035,12462.0
90.132170842,7925.0
90.182304649,5901.0
90.232438456,5217.0
90.282572263,5008.0
90.332706070,4744.0
90.382839877,4761.0
90.432973684,4669.0
90.483107491,4416.0
90.533241298,4550.0
90.583375105,4549.0
90.633508912,4474.0
90.683642719,4510.0
90.733776525,4496.0
90.783910332,4454.0
90.834044139,4454.0
90.884177946,4434.0
90.934311753,4310.0
90.984445560,4396.0
91.034579367,4489.0
91.084713174,4443.0
91.134846981,4422.0
91.184980788,4501.0
91.235114595,4528.0
91.285248402,4471.0
91.335382209,4416.0
91.385516016,4516.0
91.435649823,4354.0
91.485783630,4406.0
91.535917436,4418.0
91.586051243,4404.0
91.636185050,4366.0
91.686318857,4381.0
91.736452664,4342.0
91.786586471,4481.0
91.836720278,4374.0
91.886854085,4275.0
91.936987892,4341.0
91.987121699,4399.0
92.037255506,4360.0
92.087389313,4452.0
92.137523120,4436.0
92.187656927,4372.0
92.237790734,4443.0
92.287924541,4423.0
92.338058347,4416.0
92.388192154,4287.0
92.438325961,4474.0
92.488459768,4289.0
92.538593575,4553.0
92.588727382,4407.0
92.638861189,4446.0
92.688994996,4435.0
92.739128803,4408.0
92.789262610,4300.0
92.839396417,4425.0
92.889530224,4337.0
92.939664031,4444.0
92.989797838,4402.0
93.039931645,4437.0
93.090065452,4327.0
93.140199258,4317.0
93.190333065,4393.0
93.240466872,4433.0
93.290600679,4378.0
93.340734486,4462.0
93.390868293,4436.0
93.441002100,4524.0
93.491135907,4452.0
93.541269714,4452.0
93.591403521,4410.0
93.641537328,4552.0
93.691671135,4315.0
93.741804942,4497.0
93.791938749,4447.0
93.842072556,4409.0
93.892206363,4381.0
93.942340170,4436.0
93.992473976,4397.0
94.042607783,4455.0
94.092741590,4515.0
94.142875397,4541.0
94.193009204,4440.0
94.243143011,4414.0
94.293276818,4540.0
94.343410625,4564.0
94.393544432,4585.0
94.443678239,4629.0
94.493812046,4798.0
94.543945853,4661.0
94.594079660,4786.0
94.644213467,4815.0
94.694347274,4910.0
94.744481081,4968.0
94.794614887,5333.0
94.844748694,6153.0
94.894882501,8251.0
94.945016308,16736.0
94.995150115,25402.0
95.045283922,13063.0
95.095417729,7639.0
95.145551536,6349.0
95.195685343,6677.0
95.245819150,9650.0
95.295952957,14828.0
95.346086764,10200.0
95.396220571,6395.0
95.446354378,5173.0
95.496488185,4996.0
95.546621992,4806.0
95.596755798,4737.0
95.646889605,4494.0
95.697023412,4546.0
95.747157219,4503.0
95.797291026,4476.0
95.847424833,4481.0
95.897558640,4520.0
95.947692447,4502.0
95.997826254,4550.0
96.047960061,4528.0
96.098093868,4325.0
96.148227675,4430.0
96.198361482,4457.0
96.248495289,4410.0
96.298629096,4358.0
96.348762903,4349.0
96.398896709,4340.0
96.449030516,4410.0
96.499164323,4256.0
96.549298130,4397.0
96.599431937,4457.0
96.649565744,4359.0
96.699699551,4390.0
96.749833358,4376.0
96.799967165,4442.0
96.850100972,4434.0
96.900234779,4345.0
96.950368586,4369.0
97.000502393,4387.0
97.050636200,4417.0
97.100770007,4378.0
97.150903814,4302.0
97.201037620,4413.0
97.251171427,4318.0
97.301305234,4360.0
97.351439041,4540.0
97.401572848,4366.0
97.451706655,4438.0
97.501840462,4445.0
97.551974269,4428.0
97.602108076,4286.0
97.652241883,4318.0
97.702375690,4377.0
97.752509497,4424.0
97.802643304,4293.0
97.852777111,4437.0
97.902910918,4341.0
97.953044725,4420.0
98.003178531,4330.0
98.053312338,4384.0
98.103446145,4308.0
98.153579952,4318.0
98.203713759,4326.0
98.253847566,4229.0
98.303981373,4237.0
98.354115180,4417.0
98.404248987,4452.0
98.454382794,4377.0
98.504516601,4302.0
98.554650408,4374.0
98.604784215,4477.0
98.654918022,4167.0
98.705051829,4360.0
98.755185636,4404.0
98.805319442,4446.0
98.855453249,4417.0
98.905587056,4317.0
98.955720863,4419.0
99.005854670,4350.0
99.055988477,4362.0
99.106122284,4364.0
99.156256091,4322.0
99.206389898,4496.0
99.256523705,4445.0
99.306657512,4428.0
99.356791319,4432.0
99.406925126,4462.0
99.457058933,4308.0
99.507192740,4237.0
99.557326547,4241.0
99.607460353,4391.0
99.657594160,4283.0
99.707727967,4193.0
99.757861774,4390.0
99.807995581,4496.0
99.858129388,4309.0
99.908263195,4195.0
99.958397002,4308.0
99.991819540,4391.0