File: OriginPro/XRD from Panalytical X'Pert PRO/In-Situ/FicheirosXRD_Insitu/NiNws_150°C.csv
[Measurement conditions]
Sample identification,
Comment - 1,"finito"
Comment - 2,"Configuration=MRI TC-Basic Stage, Owner=User-1, Creation date=26-10-2009 9:18:44"
Comment - 3,"Goniometer=PW3050/60 (Theta/Theta); Minimum step size 2Theta:0.001; Minimum step size Omega:0.001"
Comment - 4,"Sample stage=MRI TC-Basic (PtRh heat strip)"
Comment - 5,"Diffractometer system=XPERT-PRO"
Comment - 6,"Measurement program=FS-L, Owner=joana, Creation date=25-11-2014 17:28:08"
Anode material,Cu
K-Alpha1 wavelength,1.5405980
K-Alpha2 wavelength,1.5444260
Ratio K-Alpha2/K-Alpha1,0.500
Divergence slit,Fixed,0.76mm
Monochromator used,NO
Generator voltage, 45
Tube current, 40
File date and time,15-Dez-2017 19:35
Unit cell,
h k l, 0 0 0
Temperature [K],423
Scan axis,Gonio
Scan range,24.995999996,94.999505744
Scan step size,0.0167113
No. of points, 4189
Scan type,CONTINUOUS
Time per step,118.110
[Scan points]
Angle,Intensity
25.004355630,2341.0
25.054489437,2249.0
25.104623244,2264.0
25.154757051,2289.0
25.204890858,2282.0
25.255024665,2248.0
25.305158472,2229.0
25.355292279,2395.0
25.405426085,2174.0
25.455559892,2295.0
25.505693699,2322.0
25.555827506,2330.0
25.605961313,2188.0
25.656095120,2277.0
25.706228927,2219.0
25.756362734,2301.0
25.806496541,2187.0
25.856630348,2269.0
25.906764155,2214.0
25.956897962,2245.0
26.007031769,2217.0
26.057165576,2204.0
26.107299383,2252.0
26.157433189,2254.0
26.207566996,2217.0
26.257700803,2264.0
26.307834610,2226.0
26.357968417,2247.0
26.408102224,2196.0
26.458236031,2202.0
26.508369838,2217.0
26.558503645,2156.0
26.608637452,2322.0
26.658771259,2220.0
26.708905066,2300.0
26.759038873,2284.0
26.809172680,2125.0
26.859306487,2146.0
26.909440293,2235.0
26.959574100,2209.0
27.009707907,2177.0
27.059841714,2181.0
27.109975521,2235.0
27.160109328,2229.0
27.210243135,2195.0
27.260376942,2138.0
27.310510749,2208.0
27.360644556,2204.0
27.410778363,2133.0
27.460912170,2227.0
27.511045977,2214.0
27.561179784,2295.0
27.611313591,2160.0
27.661447398,2192.0
27.711581204,2175.0
27.761715011,2193.0
27.811848818,2148.0
27.861982625,2172.0
27.912116432,2220.0
27.962250239,2188.0
28.012384046,2115.0
28.062517853,2237.0
28.112651660,2241.0
28.162785467,2300.0
28.212919274,2198.0
28.263053081,2717.0
28.313186888,2319.0
28.363320695,2709.0
28.413454502,2391.0
28.463588308,2386.0
28.513722115,2488.0
28.563855922,2480.0
28.613989729,2460.0
28.664123536,2321.0
28.714257343,2417.0
28.764391150,2361.0
28.814524957,2271.0
28.864658764,2283.0
28.914792571,2290.0
28.964926378,2163.0
29.015060185,2236.0
29.065193992,2184.0
29.115327799,2230.0
29.165461606,2298.0
29.215595412,2193.0
29.265729219,2313.0
29.315863026,2189.0
29.365996833,2187.0
29.416130640,2226.0
29.466264447,2218.0
29.516398254,2236.0
29.566532061,2270.0
29.616665868,2184.0
29.666799675,2081.0
29.716933482,2195.0
29.767067289,2182.0
29.817201096,2172.0
29.867334903,2145.0
29.917468710,2230.0
29.967602516,2228.0
30.017736323,2274.0
30.067870130,2197.0
30.118003937,2219.0
30.168137744,2164.0
30.218271551,2116.0
30.268405358,2183.0
30.318539165,2183.0
30.368672972,2126.0
30.418806779,2159.0
30.468940586,2162.0
30.519074393,2237.0
30.569208200,2061.0
30.619342007,2113.0
30.669475814,2124.0
30.719609620,2137.0
30.769743427,2150.0
30.819877234,2161.0
30.870011041,2139.0
30.920144848,2100.0
30.970278655,2093.0
31.020412462,2192.0
31.070546269,2238.0
31.120680076,2228.0
31.170813883,2156.0
31.220947690,2090.0
31.271081497,2145.0
31.321215304,2060.0
31.371349111,2079.0
31.421482918,2201.0
31.471616724,2128.0
31.521750531,2146.0
31.571884338,2217.0
31.622018145,2111.0
31.672151952,2129.0
31.722285759,2160.0
31.772419566,2156.0
31.822553373,2102.0
31.872687180,2162.0
31.922820987,2124.0
31.972954794,2075.0
32.023088601,2122.0
32.073222408,2066.0
32.123356215,2159.0
32.173490022,2202.0
32.223623829,2043.0
32.273757635,2125.0
32.323891442,2067.0
32.374025249,2168.0
32.424159056,2165.0
32.474292863,2097.0
32.524426670,2112.0
32.574560477,2178.0
32.624694284,2196.0
32.674828091,2134.0
32.724961898,2102.0
32.775095705,2223.0
32.825229512,2169.0
32.875363319,2156.0
32.925497126,2111.0
32.975630933,2167.0
33.025764739,2131.0
33.075898546,2136.0
33.126032353,2182.0
33.176166160,2001.0
33.226299967,2063.0
33.276433774,2102.0
33.326567581,2144.0
33.376701388,2072.0
33.426835195,2057.0
33.476969002,2046.0
33.527102809,2155.0
33.577236616,2151.0
33.627370423,2088.0
33.677504230,2114.0
33.727638037,2056.0
33.777771843,2167.0
33.827905650,2120.0
33.878039457,2041.0
33.928173264,2124.0
33.978307071,2106.0
34.028440878,2062.0
34.078574685,2064.0
34.128708492,2127.0
34.178842299,2055.0
34.228976106,2159.0
34.279109913,2119.0
34.329243720,2020.0
34.379377527,2044.0
34.429511334,2001.0
34.479645141,2005.0
34.529778947,2063.0
34.579912754,2107.0
34.630046561,2067.0
34.680180368,2166.0
34.730314175,2111.0
34.780447982,2127.0
34.830581789,2095.0
34.880715596,2056.0
34.930849403,2114.0
34.980983210,2087.0
35.031117017,2069.0
35.081250824,2176.0
35.131384631,2096.0
35.181518438,2054.0
35.231652245,2107.0
35.281786051,2185.0
35.331919858,2099.0
35.382053665,2141.0
35.432187472,2066.0
35.482321279,2091.0
35.532455086,2114.0
35.582588893,2114.0
35.632722700,2141.0
35.682856507,2080.0
35.732990314,2065.0
35.783124121,2163.0
35.833257928,2057.0
35.883391735,2098.0
35.933525542,2080.0
35.983659349,2115.0
36.033793156,2109.0
36.083926962,2047.0
36.134060769,2113.0
36.184194576,2056.0
36.234328383,2065.0
36.284462190,2066.0
36.334595997,2068.0
36.384729804,2055.0
36.434863611,1997.0
36.484997418,2068.0
36.535131225,2034.0
36.585265032,2070.0
36.635398839,2009.0
36.685532646,2086.0
36.735666453,2092.0
36.785800260,2004.0
36.835934066,2057.0
36.886067873,2104.0
36.936201680,2117.0
36.986335487,2041.0
37.036469294,2105.0
37.086603101,1984.0
37.136736908,2035.0
37.186870715,2070.0
37.237004522,2049.0
37.287138329,2163.0
37.337272136,2081.0
37.387405943,2066.0
37.437539750,2058.0
37.487673557,1980.0
37.537807364,1952.0
37.587941170,2032.0
37.638074977,2137.0
37.688208784,2090.0
37.738342591,2115.0
37.788476398,2054.0
37.838610205,2025.0
37.888744012,2052.0
37.938877819,2119.0
37.989011626,2132.0
38.039145433,2082.0
38.089279240,2140.0
38.139413047,2121.0
38.189546854,2094.0
38.239680661,2138.0
38.289814468,2060.0
38.339948274,2065.0
38.390082081,2129.0
38.440215888,2041.0
38.490349695,2065.0
38.540483502,2031.0
38.590617309,2070.0
38.640751116,2026.0
38.690884923,2100.0
38.741018730,2035.0
38.791152537,2071.0
38.841286344,1967.0
38.891420151,2072.0
38.941553958,2075.0
38.991687765,2073.0
39.041821572,1982.0
39.091955378,2038.0
39.142089185,2058.0
39.192222992,1964.0
39.242356799,1967.0
39.292490606,2012.0
39.342624413,2079.0
39.392758220,2044.0
39.442892027,1990.0
39.493025834,2022.0
39.543159641,2144.0
39.593293448,2142.0
39.643427255,2161.0
39.693561062,2276.0
39.743694869,2513.0
39.793828676,2415.0
39.843962482,2263.0
39.894096289,2178.0
39.944230096,2110.0
39.994363903,2073.0
40.044497710,2115.0
40.094631517,2301.0
40.144765324,2140.0
40.194899131,2071.0
40.245032938,2075.0
40.295166745,2036.0
40.345300552,2017.0
40.395434359,2052.0
40.445568166,2024.0
40.495701973,1955.0
40.545835780,1990.0
40.595969587,1992.0
40.646103393,1973.0
40.696237200,1987.0
40.746371007,1975.0
40.796504814,2034.0
40.846638621,2022.0
40.896772428,1954.0
40.946906235,2151.0
40.997040042,2044.0
41.047173849,2010.0
41.097307656,2048.0
41.147441463,2109.0
41.197575270,1960.0
41.247709077,1916.0
41.297842884,2079.0
41.347976691,2022.0
41.398110497,2154.0
41.448244304,2059.0
41.498378111,2056.0
41.548511918,2016.0
41.598645725,2110.0
41.648779532,2010.0
41.698913339,1977.0
41.749047146,2021.0
41.799180953,2041.0
41.849314760,1929.0
41.899448567,1999.0
41.949582374,2074.0
41.999716181,1997.0
42.049849988,1979.0
42.099983795,1921.0
42.150117601,2020.0
42.200251408,1947.0
42.250385215,2015.0
42.300519022,1938.0
42.350652829,2090.0
42.400786636,1971.0
42.450920443,2097.0
42.501054250,2031.0
42.551188057,2002.0
42.601321864,2009.0
42.651455671,2021.0
42.701589478,2011.0
42.751723285,2036.0
42.801857092,2084.0
42.851990899,2037.0
42.902124705,2075.0
42.952258512,2108.0
43.002392319,2109.0
43.052526126,2102.0
43.102659933,2057.0
43.152793740,2051.0
43.202927547,2137.0
43.253061354,2116.0
43.303195161,2169.0
43.353328968,2177.0
43.403462775,2083.0
43.453596582,2254.0
43.503730389,2280.0
43.553864196,2333.0
43.603998003,2283.0
43.654131809,2377.0
43.704265616,2412.0
43.754399423,2523.0
43.804533230,2675.0
43.854667037,2834.0
43.904800844,2995.0
43.954934651,3284.0
44.005068458,3580.0
44.055202265,3990.0
44.105336072,4521.0
44.155469879,5263.0
44.205603686,6088.0
44.255737493,7547.0
44.305871300,9093.0
44.356005107,10048.0
44.406138913,10126.0
44.456272720,9193.0
44.506406527,7521.0
44.556540334,5769.0
44.606674141,4288.0
44.656807948,3513.0
44.706941755,2806.0
44.757075562,2648.0
44.807209369,2492.0
44.857343176,2351.0
44.907476983,2338.0
44.957610790,2209.0
45.007744597,2233.0
45.057878404,2235.0
45.108012211,2104.0
45.158146018,2169.0
45.208279824,2137.0
45.258413631,2221.0
45.308547438,2186.0
45.358681245,2155.0
45.408815052,2251.0
45.458948859,2207.0
45.509082666,2207.0
45.559216473,2164.0
45.609350280,2080.0
45.659484087,2114.0
45.709617894,2161.0
45.759751701,2131.0
45.809885508,2106.0
45.860019315,2072.0
45.910153122,2097.0
45.960286928,2189.0
46.010420735,2259.0
46.060554542,2435.0
46.110688349,3001.0
46.160822156,3631.0
46.210955963,5265.0
46.261089770,8488.0
46.311223577,4185.0
46.361357384,4926.0
46.411491191,3803.0
46.461624998,3063.0
46.511758805,3257.0
46.561892612,3703.0
46.612026419,3720.0
46.662160226,3593.0
46.712294032,3292.0
46.762427839,2930.0
46.812561646,2427.0
46.862695453,2216.0
46.912829260,2020.0
46.962963067,2061.0
47.013096874,1933.0
47.063230681,1980.0
47.113364488,2026.0
47.163498295,2023.0
47.213632102,1889.0
47.263765909,1911.0
47.313899716,1862.0
47.364033523,1897.0
47.414167330,1909.0
47.464301136,1945.0
47.514434943,1987.0
47.564568750,1926.0
47.614702557,1845.0
47.664836364,2003.0
47.714970171,1922.0
47.765103978,1944.0
47.815237785,1894.0
47.865371592,1960.0
47.915505399,1977.0
47.965639206,1850.0
48.015773013,1943.0
48.065906820,1919.0
48.116040627,1877.0
48.166174434,1954.0
48.216308240,1937.0
48.266442047,1959.0
48.316575854,1892.0
48.366709661,1928.0
48.416843468,1868.0
48.466977275,1914.0
48.517111082,1826.0
48.567244889,1975.0
48.617378696,1929.0
48.667512503,1889.0
48.717646310,1857.0
48.767780117,1971.0
48.817913924,1864.0
48.868047731,1924.0
48.918181538,1843.0
48.968315344,1908.0
49.018449151,1947.0
49.068582958,1885.0
49.118716765,1875.0
49.168850572,1906.0
49.218984379,1940.0
49.269118186,1939.0
49.319251993,1987.0
49.369385800,1907.0
49.419519607,1962.0
49.469653414,2040.0
49.519787221,2028.0
49.569921028,2002.0
49.620054835,1977.0
49.670188642,1959.0
49.720322449,1911.0
49.770456255,1914.0
49.820590062,2001.0
49.870723869,1939.0
49.920857676,1913.0
49.970991483,1926.0
50.021125290,1862.0
50.071259097,1938.0
50.121392904,1985.0
50.171526711,1943.0
50.221660518,1998.0
50.271794325,2006.0
50.321928132,2144.0
50.372061939,2132.0
50.422195746,2255.0
50.472329553,2349.0
50.522463359,2400.0
50.572597166,2382.0
50.622730973,2218.0
50.672864780,2156.0
50.722998587,2167.0
50.773132394,2038.0
50.823266201,1978.0
50.873400008,2058.0
50.923533815,2054.0
50.973667622,2083.0
51.023801429,2100.0
51.073935236,2178.0
51.124069043,2188.0
51.174202850,2200.0
51.224336657,2305.0
51.274470463,2408.0
51.324604270,2477.0
51.374738077,2579.0
51.424871884,2772.0
51.475005691,3140.0
51.525139498,3320.0
51.575273305,3708.0
51.625407112,4086.0
51.675540919,4314.0
51.725674726,4436.0
51.775808533,4189.0
51.825942340,3969.0
51.876076147,3414.0
51.926209954,3025.0
51.976343761,2627.0
52.026477567,2597.0
52.076611374,2338.0
52.126745181,2137.0
52.176878988,2071.0
52.227012795,1981.0
52.277146602,1986.0
52.327280409,1967.0
52.377414216,1955.0
52.427548023,1869.0
52.477681830,1845.0
52.527815637,1888.0
52.577949444,1961.0
52.628083251,1864.0
52.678217058,1817.0
52.728350865,1861.0
52.778484671,1792.0
52.828618478,1810.0
52.878752285,1872.0
52.928886092,1795.0
52.979019899,1766.0
53.029153706,1722.0
53.079287513,1874.0
53.129421320,1927.0
53.179555127,1846.0
53.229688934,1843.0
53.279822741,1842.0
53.329956548,1815.0
53.380090355,1795.0
53.430224162,1830.0
53.480357969,1817.0
53.530491776,1844.0
53.580625582,1805.0
53.630759389,1876.0
53.680893196,1783.0
53.731027003,1859.0
53.781160810,1827.0
53.831294617,1790.0
53.881428424,1847.0
53.931562231,1780.0
53.981696038,1774.0
54.031829845,1781.0
54.081963652,1786.0
54.132097459,1770.0
54.182231266,1778.0
54.232365073,1800.0
54.282498880,1739.0
54.332632686,1765.0
54.382766493,1767.0
54.432900300,1735.0
54.483034107,1804.0
54.533167914,1805.0
54.583301721,1742.0
54.633435528,1779.0
54.683569335,1804.0
54.733703142,1798.0
54.783836949,1804.0
54.833970756,1749.0
54.884104563,1827.0
54.934238370,1821.0
54.984372177,1802.0
55.034505984,1780.0
55.084639790,1801.0
55.134773597,1776.0
55.184907404,1785.0
55.235041211,1794.0
55.285175018,1766.0
55.335308825,1811.0
55.385442632,1747.0
55.435576439,1829.0
55.485710246,1747.0
55.535844053,1810.0
55.585977860,1835.0
55.636111667,1779.0
55.686245474,1814.0
55.736379281,1755.0
55.786513088,1798.0
55.836646894,1735.0
55.886780701,1754.0
55.936914508,1750.0
55.987048315,1814.0
56.037182122,1809.0
56.087315929,1762.0
56.137449736,1804.0
56.187583543,1752.0
56.237717350,1771.0
56.287851157,1783.0
56.337984964,1787.0
56.388118771,1776.0
56.438252578,1844.0
56.488386385,1779.0
56.538520192,1715.0
56.588653998,1701.0
56.638787805,1753.0
56.688921612,1716.0
56.739055419,1747.0
56.789189226,1743.0
56.839323033,1793.0
56.889456840,1790.0
56.939590647,1829.0
56.989724454,1722.0
57.039858261,1764.0
57.089992068,1784.0
57.140125875,1714.0
57.190259682,1773.0
57.240393489,1757.0
57.290527296,1744.0
57.340661102,1783.0
57.390794909,1792.0
57.440928716,1747.0
57.491062523,1789.0
57.541196330,1716.0
57.591330137,1796.0
57.641463944,1807.0
57.691597751,1809.0
57.741731558,1695.0
57.791865365,1757.0
57.841999172,1783.0
57.892132979,1749.0
57.942266786,1786.0
57.992400593,1752.0
58.042534400,1733.0
58.092668207,1708.0
58.142802013,1743.0
58.192935820,1766.0
58.243069627,1697.0
58.293203434,1741.0
58.343337241,1729.0
58.393471048,1755.0
58.443604855,1733.0
58.493738662,1829.0
58.543872469,1695.0
58.594006276,1767.0
58.644140083,1716.0
58.694273890,1710.0
58.744407697,1705.0
58.794541504,1714.0
58.844675311,1794.0
58.894809117,1826.0
58.944942924,1728.0
58.995076731,1737.0
59.045210538,1706.0
59.095344345,1781.0
59.145478152,1776.0
59.195611959,1715.0
59.245745766,1744.0
59.295879573,1720.0
59.346013380,1735.0
59.396147187,1695.0
59.446280994,1750.0
59.496414801,1804.0
59.546548608,1794.0
59.596682415,1758.0
59.646816221,1754.0
59.696950028,1768.0
59.747083835,1801.0
59.797217642,1770.0
59.847351449,1864.0
59.897485256,1784.0
59.947619063,1815.0
59.997752870,1781.0
60.047886677,1771.0
60.098020484,1648.0
60.148154291,1828.0
60.198288098,1772.0
60.248421905,1736.0
60.298555712,1790.0
60.348689519,1807.0
60.398823325,1786.0
60.448957132,1754.0
60.499090939,1884.0
60.549224746,1743.0
60.599358553,1764.0
60.649492360,1742.0
60.699626167,1805.0
60.749759974,1781.0
60.799893781,1744.0
60.850027588,1761.0
60.900161395,1713.0
60.950295202,1693.0
61.000429009,1704.0
61.050562816,1835.0
61.100696623,1821.0
61.150830429,1869.0
61.200964236,1830.0
61.251098043,1843.0
61.301231850,1762.0
61.351365657,1784.0
61.401499464,1780.0
61.451633271,1734.0
61.501767078,1775.0
61.551900885,1743.0
61.602034692,1788.0
61.652168499,1718.0
61.702302306,1784.0
61.752436113,1745.0
61.802569920,1794.0
61.852703727,1770.0
61.902837533,1909.0
61.952971340,1805.0
62.003105147,1728.0
62.053238954,1890.0
62.103372761,1799.0
62.153506568,1772.0
62.203640375,1733.0
62.253774182,1844.0
62.303907989,1809.0
62.354041796,1820.0
62.404175603,1846.0
62.454309410,1812.0
62.504443217,1818.0
62.554577024,1825.0
62.604710831,1844.0
62.654844638,1818.0
62.704978444,1889.0
62.755112251,1862.0
62.805246058,1869.0
62.855379865,1779.0
62.905513672,1743.0
62.955647479,1803.0
63.005781286,1820.0
63.055915093,1851.0
63.106048900,1718.0
63.156182707,1861.0
63.206316514,1814.0
63.256450321,1803.0
63.306584128,1825.0
63.356717935,1790.0
63.406851742,1827.0
63.456985548,1904.0
63.507119355,1821.0
63.557253162,1882.0
63.607386969,1843.0
63.657520776,1775.0
63.707654583,1873.0
63.757788390,1865.0
63.807922197,1811.0
63.858056004,1888.0
63.908189811,1788.0
63.958323618,1879.0
64.008457425,1865.0
64.058591232,1845.0
64.108725039,1883.0
64.158858846,1838.0
64.208992652,1808.0
64.259126459,1820.0
64.309260266,1852.0
64.359394073,1833.0
64.409527880,1895.0
64.459661687,1836.0
64.509795494,1870.0
64.559929301,1890.0
64.610063108,1901.0
64.660196915,1798.0
64.710330722,1903.0
64.760464529,1851.0
64.810598336,1913.0
64.860732143,1909.0
64.910865950,1861.0
64.960999756,1896.0
65.011133563,1946.0
65.061267370,1935.0
65.111401177,1938.0
65.161534984,1895.0
65.211668791,1843.0
65.261802598,1889.0
65.311936405,1930.0
65.362070212,1825.0
65.412204019,1906.0
65.462337826,1821.0
65.512471633,1852.0
65.562605440,1933.0
65.612739247,1907.0
65.662873054,1894.0
65.713006860,1966.0
65.763140667,1897.0
65.813274474,1955.0
65.863408281,1877.0
65.913542088,1922.0
65.963675895,1929.0
66.013809702,1930.0
66.063943509,1857.0
66.114077316,1858.0
66.164211123,1890.0
66.214344930,1930.0
66.264478737,1884.0
66.314612544,1959.0
66.364746351,1899.0
66.414880158,1948.0
66.465013964,1952.0
66.515147771,1915.0
66.565281578,1903.0
66.615415385,1882.0
66.665549192,1981.0
66.715682999,1895.0
66.765816806,1986.0
66.815950613,1911.0
66.866084420,1956.0
66.916218227,1915.0
66.966352034,1847.0
67.016485841,1919.0
67.066619648,1887.0
67.116753455,1961.0
67.166887262,1888.0
67.217021069,1933.0
67.267154875,1945.0
67.317288682,1878.0
67.367422489,1981.0
67.417556296,1909.0
67.467690103,1918.0
67.517823910,1894.0
67.567957717,1948.0
67.618091524,1812.0
67.668225331,1879.0
67.718359138,1942.0
67.768492945,1903.0
67.818626752,1897.0
67.868760559,1976.0
67.918894366,1918.0
67.969028173,1974.0
68.019161979,1915.0
68.069295786,1947.0
68.119429593,1957.0
68.169563400,1944.0
68.219697207,1856.0
68.269831014,1950.0
68.319964821,1930.0
68.370098628,1950.0
68.420232435,1875.0
68.470366242,1944.0
68.520500049,1881.0
68.570633856,1864.0
68.620767663,1926.0
68.670901470,1930.0
68.721035277,1887.0
68.771169083,1855.0
68.821302890,1824.0
68.871436697,1837.0
68.921570504,1879.0
68.971704311,1989.0
69.021838118,1921.0
69.071971925,1837.0
69.122105732,1966.0
69.172239539,1839.0
69.222373346,1949.0
69.272507153,1823.0
69.322640960,1892.0
69.372774767,1899.0
69.422908574,1850.0
69.473042381,1992.0
69.523176187,1890.0
69.573309994,1932.0
69.623443801,1845.0
69.673577608,1862.0
69.723711415,1811.0
69.773845222,1826.0
69.823979029,1882.0
69.874112836,1915.0
69.924246643,1883.0
69.974380450,1914.0
70.024514257,1858.0
70.074648064,1864.0
70.124781871,1830.0
70.174915678,1840.0
70.225049485,1806.0
70.275183291,1775.0
70.325317098,1797.0
70.375450905,1879.0
70.425584712,1855.0
70.475718519,1820.0
70.525852326,1896.0
70.575986133,1889.0
70.626119940,1844.0
70.676253747,1939.0
70.726387554,1777.0
70.776521361,1882.0
70.826655168,1767.0
70.876788975,1772.0
70.926922782,1920.0
70.977056589,1838.0
71.027190396,1778.0
71.077324202,1790.0
71.127458009,1819.0
71.177591816,1818.0
71.227725623,1773.0
71.277859430,1832.0
71.327993237,1751.0
71.378127044,1779.0
71.428260851,1835.0
71.478394658,1792.0
71.528528465,1846.0
71.578662272,1827.0
71.628796079,1763.0
71.678929886,1843.0
71.729063693,1813.0
71.779197500,1806.0
71.829331306,1796.0
71.879465113,1757.0
71.929598920,1791.0
71.979732727,1842.0
72.029866534,1748.0
72.080000341,1672.0
72.130134148,1796.0
72.180267955,1803.0
72.230401762,1806.0
72.280535569,1904.0
72.330669376,1836.0
72.380803183,1748.0
72.430936990,1792.0
72.481070797,1819.0
72.531204604,1702.0
72.581338410,1752.0
72.631472217,1761.0
72.681606024,1665.0
72.731739831,1829.0
72.781873638,1791.0
72.832007445,1739.0
72.882141252,1749.0
72.932275059,1687.0
72.982408866,1683.0
73.032542673,1691.0
73.082676480,1742.0
73.132810287,1767.0
73.182944094,1745.0
73.233077901,1735.0
73.283211708,1712.0
73.333345514,1762.0
73.383479321,1768.0
73.433613128,1789.0
73.483746935,1794.0
73.533880742,1748.0
73.584014549,1691.0
73.634148356,1766.0
73.684282163,1688.0
73.734415970,1761.0
73.784549777,1741.0
73.834683584,1710.0
73.884817391,1769.0
73.934951198,1753.0
73.985085005,1725.0
74.035218812,1705.0
74.085352618,1727.0
74.135486425,1732.0
74.185620232,1717.0
74.235754039,1644.0
74.285887846,1686.0
74.336021653,1783.0
74.386155460,1704.0
74.436289267,1653.0
74.486423074,1690.0
74.536556881,1664.0
74.586690688,1684.0
74.636824495,1679.0
74.686958302,1631.0
74.737092109,1626.0
74.787225916,1671.0
74.837359722,1664.0
74.887493529,1749.0
74.937627336,1712.0
74.987761143,1657.0
75.037894950,1707.0
75.088028757,1667.0
75.138162564,1666.0
75.188296371,1737.0
75.238430178,1647.0
75.288563985,1695.0
75.338697792,1715.0
75.388831599,1768.0
75.438965406,1694.0
75.489099213,1841.0
75.539233020,1819.0
75.589366827,1820.0
75.639500633,1814.0
75.689634440,1735.0
75.739768247,1906.0
75.789902054,1944.0
75.840035861,1939.0
75.890169668,1911.0
75.940303475,1998.0
75.990437282,2086.0
76.040571089,2088.0
76.090704896,2241.0
76.140838703,2353.0
76.190972510,2250.0
76.241106317,2240.0
76.291240124,2095.0
76.341373931,2098.0
76.391507737,2022.0
76.441641544,1940.0
76.491775351,1898.0
76.541909158,1837.0
76.592042965,1779.0
76.642176772,1796.0
76.692310579,1714.0
76.742444386,1704.0
76.792578193,1593.0
76.842712000,1657.0
76.892845807,1605.0
76.942979614,1665.0
76.993113421,1580.0
77.043247228,1587.0
77.093381035,1559.0
77.143514841,1651.0
77.193648648,1642.0
77.243782455,1592.0
77.293916262,1528.0
77.344050069,1604.0
77.394183876,1594.0
77.444317683,1558.0
77.494451490,1550.0
77.544585297,1622.0
77.594719104,1636.0
77.644852911,1552.0
77.694986718,1548.0
77.745120525,1544.0
77.795254332,1554.0
77.845388139,1574.0
77.895521945,1569.0
77.945655752,1564.0
77.995789559,1515.0
78.045923366,1588.0
78.096057173,1549.0
78.146190980,1551.0
78.196324787,1507.0
78.246458594,1559.0
78.296592401,1557.0
78.346726208,1496.0
78.396860015,1545.0
78.446993822,1528.0
78.497127629,1556.0
78.547261436,1545.0
78.597395243,1566.0
78.647529049,1448.0
78.697662856,1509.0
78.747796663,1517.0
78.797930470,1511.0
78.848064277,1635.0
78.898198084,1528.0
78.948331891,1577.0
78.998465698,1598.0
79.048599505,1534.0
79.098733312,1498.0
79.148867119,1546.0
79.199000926,1558.0
79.249134733,1502.0
79.299268540,1545.0
79.349402347,1501.0
79.399536153,1466.0
79.449669960,1422.0
79.499803767,1490.0
79.549937574,1549.0
79.600071381,1496.0
79.650205188,1511.0
79.700338995,1391.0
79.750472802,1476.0
79.800606609,1484.0
79.850740416,1433.0
79.900874223,1459.0
79.951008030,1507.0
80.001141837,1481.0
80.051275644,1510.0
80.101409451,1553.0
80.151543258,1464.0
80.201677064,1435.0
80.251810871,1446.0
80.301944678,1521.0
80.352078485,1462.0
80.402212292,1457.0
80.452346099,1455.0
80.502479906,1437.0
80.552613713,1476.0
80.602747520,1516.0
80.652881327,1385.0
80.703015134,1404.0
80.753148941,1549.0
80.803282748,1447.0
80.853416555,1459.0
80.903550362,1436.0
80.953684168,1523.0
81.003817975,1430.0
81.053951782,1454.0
81.104085589,1554.0
81.154219396,1514.0
81.204353203,1448.0
81.254487010,1471.0
81.304620817,1436.0
81.354754624,1413.0
81.404888431,1353.0
81.455022238,1403.0
81.505156045,1476.0
81.555289852,1409.0
81.605423659,1458.0
81.655557466,1509.0
81.705691272,1479.0
81.755825079,1502.0
81.805958886,1485.0
81.856092693,1426.0
81.906226500,1401.0
81.956360307,1448.0
82.006494114,1488.0
82.056627921,1475.0
82.106761728,1402.0
82.156895535,1499.0
82.207029342,1459.0
82.257163149,1455.0
82.307296956,1399.0
82.357430763,1511.0
82.407564570,1464.0
82.457698376,1464.0
82.507832183,1457.0
82.557965990,1412.0
82.608099797,1389.0
82.658233604,1401.0
82.708367411,1421.0
82.758501218,1404.0
82.808635025,1423.0
82.858768832,1407.0
82.908902639,1465.0
82.959036446,1429.0
83.009170253,1460.0
83.059304060,1353.0
83.109437867,1400.0
83.159571674,1403.0
83.209705480,1345.0
83.259839287,1397.0
83.309973094,1387.0
83.360106901,1403.0
83.410240708,1401.0
83.460374515,1376.0
83.510508322,1387.0
83.560642129,1419.0
83.610775936,1425.0
83.660909743,1359.0
83.711043550,1400.0
83.761177357,1413.0
83.811311164,1410.0
83.861444971,1391.0
83.911578778,1435.0
83.961712584,1369.0
84.011846391,1436.0
84.061980198,1322.0
84.112114005,1378.0
84.162247812,1372.0
84.212381619,1374.0
84.262515426,1427.0
84.312649233,1351.0
84.362783040,1394.0
84.412916847,1361.0
84.463050654,1403.0
84.513184461,1400.0
84.563318268,1392.0
84.613452075,1361.0
84.663585882,1355.0
84.713719689,1343.0
84.763853495,1400.0
84.813987302,1322.0
84.864121109,1351.0
84.914254916,1348.0
84.964388723,1397.0
85.014522530,1366.0
85.064656337,1415.0
85.114790144,1355.0
85.164923951,1351.0
85.215057758,1333.0
85.265191565,1360.0
85.315325372,1321.0
85.365459179,1270.0
85.415592986,1300.0
85.465726793,1349.0
85.515860599,1404.0
85.565994406,1387.0
85.616128213,1404.0
85.666262020,1420.0
85.716395827,1345.0
85.766529634,1357.0
85.816663441,1341.0
85.866797248,1360.0
85.916931055,1303.0
85.967064862,1311.0
86.017198669,1387.0
86.067332476,1424.0
86.117466283,1379.0
86.167600090,1305.0
86.217733897,1354.0
86.267867703,1385.0
86.318001510,1392.0
86.368135317,1401.0
86.418269124,1399.0
86.468402931,1368.0
86.518536738,1376.0
86.568670545,1352.0
86.618804352,1363.0
86.668938159,1290.0
86.719071966,1386.0
86.769205773,1422.0
86.819339580,1398.0
86.869473387,1310.0
86.919607194,1303.0
86.969741001,1309.0
87.019874807,1356.0
87.070008614,1386.0
87.120142421,1361.0
87.170276228,1330.0
87.220410035,1319.0
87.270543842,1367.0
87.320677649,1366.0
87.370811456,1350.0
87.420945263,1412.0
87.471079070,1355.0
87.521212877,1404.0
87.571346684,1347.0
87.621480491,1338.0
87.671614298,1322.0
87.721748105,1371.0
87.771881911,1343.0
87.822015718,1361.0
87.872149525,1324.0
87.922283332,1394.0
87.972417139,1334.0
88.022550946,1338.0
88.072684753,1333.0
88.122818560,1393.0
88.172952367,1338.0
88.223086174,1319.0
88.273219981,1365.0
88.323353788,1340.0
88.373487595,1367.0
88.423621402,1368.0
88.473755209,1341.0
88.523889016,1275.0
88.574022822,1303.0
88.624156629,1317.0
88.674290436,1336.0
88.724424243,1372.0
88.774558050,1296.0
88.824691857,1327.0
88.874825664,1344.0
88.924959471,1420.0
88.975093278,1380.0
89.025227085,1292.0
89.075360892,1256.0
89.125494699,1311.0
89.175628506,1283.0
89.225762313,1347.0
89.275896120,1277.0
89.326029926,1334.0
89.376163733,1305.0
89.426297540,1334.0
89.476431347,1359.0
89.526565154,1326.0
89.576698961,1382.0
89.626832768,1300.0
89.676966575,1358.0
89.727100382,1351.0
89.777234189,1340.0
89.827367996,1309.0
89.877501803,1324.0
89.927635610,1302.0
89.977769417,1324.0
90.027903224,1371.0
90.078037030,1427.0
90.128170837,1346.0
90.178304644,1343.0
90.228438451,1304.0
90.278572258,1261.0
90.328706065,1335.0
90.378839872,1414.0
90.428973679,1385.0
90.479107486,1402.0
90.529241293,1283.0
90.579375100,1327.0
90.629508907,1372.0
90.679642714,1270.0
90.729776521,1293.0
90.779910328,1337.0
90.830044134,1306.0
90.880177941,1337.0
90.930311748,1315.0
90.980445555,1251.0
91.030579362,1333.0
91.080713169,1291.0
91.130846976,1289.0
91.180980783,1313.0
91.231114590,1355.0
91.281248397,1407.0
91.331382204,1388.0
91.381516011,1342.0
91.431649818,1344.0
91.481783625,1386.0
91.531917432,1372.0
91.582051238,1338.0
91.632185045,1352.0
91.682318852,1412.0
91.732452659,1377.0
91.782586466,1477.0
91.832720273,1409.0
91.882854080,1464.0
91.932987887,1339.0
91.983121694,1483.0
92.033255501,1420.0
92.083389308,1431.0
92.133523115,1456.0
92.183656922,1482.0
92.233790729,1532.0
92.283924536,1588.0
92.334058342,1568.0
92.384192149,1657.0
92.434325956,1637.0
92.484459763,1723.0
92.534593570,1717.0
92.584727377,1803.0
92.634861184,1822.0
92.684994991,1844.0
92.735128798,1784.0
92.785262605,1712.0
92.835396412,1640.0
92.885530219,1658.0
92.935664026,1685.0
92.985797833,1573.0
93.035931640,1510.0
93.086065447,1545.0
93.136199253,1438.0
93.186333060,1365.0
93.236466867,1443.0
93.286600674,1440.0
93.336734481,1358.0
93.386868288,1422.0
93.437002095,1365.0
93.487135902,1323.0
93.537269709,1356.0
93.587403516,1362.0
93.637537323,1330.0
93.687671130,1351.0
93.737804937,1241.0
93.787938744,1378.0
93.838072551,1337.0
93.888206357,1304.0
93.938340164,1360.0
93.988473971,1278.0
94.038607778,1274.0
94.088741585,1279.0
94.138875392,1348.0
94.189009199,1363.0
94.239143006,1319.0
94.289276813,1282.0
94.339410620,1244.0
94.389544427,1261.0
94.439678234,1251.0
94.489812041,1323.0
94.539945848,1285.0
94.590079655,1284.0
94.640213461,1200.0
94.690347268,1321.0
94.740481075,1229.0
94.790614882,1282.0
94.840748689,1312.0
94.890882496,1254.0
94.941016303,1259.0
94.991150110,1243.0