File: OriginPro/XRD from Panalytical X'Pert PRO/In-Situ/FicheirosXRD_Insitu/NiNws_250°C.csv
[Measurement conditions]
Sample identification,
Comment - 1,"finito"
Comment - 2,"Configuration=MRI TC-Basic Stage, Owner=User-1, Creation date=26-10-2009 9:18:44"
Comment - 3,"Goniometer=PW3050/60 (Theta/Theta); Minimum step size 2Theta:0.001; Minimum step size Omega:0.001"
Comment - 4,"Sample stage=MRI TC-Basic (PtRh heat strip)"
Comment - 5,"Diffractometer system=XPERT-PRO"
Comment - 6,"Measurement program=FS-L, Owner=joana, Creation date=25-11-2014 17:28:08"
Anode material,Cu
K-Alpha1 wavelength,1.5405980
K-Alpha2 wavelength,1.5444260
Ratio K-Alpha2/K-Alpha1,0.500
Divergence slit,Fixed,0.76mm
Monochromator used,NO
Generator voltage, 45
Tube current, 40
File date and time,15-Dez-2017 21:54
Unit cell,
h k l, 0 0 0
Temperature [K],523
Scan axis,Gonio
Scan range,24.995999996,94.999505744
Scan step size,0.0167113
No. of points, 4189
Scan type,CONTINUOUS
Time per step,118.110
[Scan points]
Angle,Intensity
25.004355630,2310.0
25.054489437,2266.0
25.104623244,2248.0
25.154757051,2243.0
25.204890858,2183.0
25.255024665,2206.0
25.305158472,2326.0
25.355292279,2248.0
25.405426085,2304.0
25.455559892,2202.0
25.505693699,2199.0
25.555827506,2217.0
25.605961313,2240.0
25.656095120,2212.0
25.706228927,2190.0
25.756362734,2265.0
25.806496541,2217.0
25.856630348,2261.0
25.906764155,2221.0
25.956897962,2176.0
26.007031769,2183.0
26.057165576,2218.0
26.107299383,2172.0
26.157433189,2151.0
26.207566996,2206.0
26.257700803,2167.0
26.307834610,2203.0
26.357968417,2158.0
26.408102224,2225.0
26.458236031,2203.0
26.508369838,2131.0
26.558503645,2199.0
26.608637452,2109.0
26.658771259,2166.0
26.708905066,2177.0
26.759038873,2194.0
26.809172680,2134.0
26.859306487,2117.0
26.909440293,2252.0
26.959574100,2234.0
27.009707907,2210.0
27.059841714,2214.0
27.109975521,2267.0
27.160109328,2162.0
27.210243135,2109.0
27.260376942,2177.0
27.310510749,2240.0
27.360644556,2223.0
27.410778363,2292.0
27.460912170,2186.0
27.511045977,2181.0
27.561179784,2251.0
27.611313591,2163.0
27.661447398,2071.0
27.711581204,2171.0
27.761715011,2276.0
27.811848818,2124.0
27.861982625,2195.0
27.912116432,2145.0
27.962250239,2261.0
28.012384046,2154.0
28.062517853,2263.0
28.112651660,2198.0
28.162785467,2197.0
28.212919274,2191.0
28.263053081,2423.0
28.313186888,2467.0
28.363320695,2798.0
28.413454502,2254.0
28.463588308,2427.0
28.513722115,2282.0
28.563855922,2331.0
28.613989729,2318.0
28.664123536,2405.0
28.714257343,2342.0
28.764391150,2267.0
28.814524957,2277.0
28.864658764,2206.0
28.914792571,2133.0
28.964926378,2174.0
29.015060185,2286.0
29.065193992,2192.0
29.115327799,2222.0
29.165461606,2278.0
29.215595412,2247.0
29.265729219,2190.0
29.315863026,2158.0
29.365996833,2282.0
29.416130640,2078.0
29.466264447,2237.0
29.516398254,2096.0
29.566532061,2190.0
29.616665868,2110.0
29.666799675,2196.0
29.716933482,2152.0
29.767067289,2061.0
29.817201096,2095.0
29.867334903,2090.0
29.917468710,2115.0
29.967602516,2088.0
30.017736323,2128.0
30.067870130,2154.0
30.118003937,2222.0
30.168137744,2130.0
30.218271551,2123.0
30.268405358,2166.0
30.318539165,2120.0
30.368672972,2202.0
30.418806779,2114.0
30.468940586,2185.0
30.519074393,2037.0
30.569208200,2101.0
30.619342007,2136.0
30.669475814,2062.0
30.719609620,2072.0
30.769743427,2116.0
30.819877234,2146.0
30.870011041,2156.0
30.920144848,2174.0
30.970278655,2130.0
31.020412462,2113.0
31.070546269,2162.0
31.120680076,2113.0
31.170813883,2127.0
31.220947690,2071.0
31.271081497,2128.0
31.321215304,2109.0
31.371349111,2124.0
31.421482918,2018.0
31.471616724,2066.0
31.521750531,2134.0
31.571884338,2087.0
31.622018145,2168.0
31.672151952,2075.0
31.722285759,2186.0
31.772419566,2237.0
31.822553373,2118.0
31.872687180,2082.0
31.922820987,2138.0
31.972954794,2208.0
32.023088601,2127.0
32.073222408,2162.0
32.123356215,2081.0
32.173490022,2161.0
32.223623829,2105.0
32.273757635,2147.0
32.323891442,2183.0
32.374025249,2098.0
32.424159056,2162.0
32.474292863,2119.0
32.524426670,2160.0
32.574560477,2165.0
32.624694284,2197.0
32.674828091,2182.0
32.724961898,2173.0
32.775095705,2118.0
32.825229512,2028.0
32.875363319,2067.0
32.925497126,2126.0
32.975630933,2135.0
33.025764739,2025.0
33.075898546,2089.0
33.126032353,2079.0
33.176166160,2051.0
33.226299967,2119.0
33.276433774,2104.0
33.326567581,2045.0
33.376701388,2142.0
33.426835195,1992.0
33.476969002,2104.0
33.527102809,2075.0
33.577236616,2136.0
33.627370423,2039.0
33.677504230,2057.0
33.727638037,2107.0
33.777771843,2082.0
33.827905650,2099.0
33.878039457,2045.0
33.928173264,2160.0
33.978307071,2116.0
34.028440878,1969.0
34.078574685,2127.0
34.128708492,2154.0
34.178842299,1979.0
34.228976106,2150.0
34.279109913,2089.0
34.329243720,1997.0
34.379377527,2078.0
34.429511334,2092.0
34.479645141,2131.0
34.529778947,2088.0
34.579912754,2012.0
34.630046561,2029.0
34.680180368,1995.0
34.730314175,2083.0
34.780447982,2044.0
34.830581789,2063.0
34.880715596,2062.0
34.930849403,2052.0
34.980983210,2066.0
35.031117017,1978.0
35.081250824,2078.0
35.131384631,2040.0
35.181518438,2029.0
35.231652245,2098.0
35.281786051,2080.0
35.331919858,2071.0
35.382053665,2084.0
35.432187472,2114.0
35.482321279,2151.0
35.532455086,2092.0
35.582588893,2137.0
35.632722700,2056.0
35.682856507,2063.0
35.732990314,1980.0
35.783124121,1910.0
35.833257928,2078.0
35.883391735,1999.0
35.933525542,2047.0
35.983659349,2130.0
36.033793156,2036.0
36.083926962,1993.0
36.134060769,2040.0
36.184194576,2034.0
36.234328383,2135.0
36.284462190,1934.0
36.334595997,2114.0
36.384729804,2113.0
36.434863611,2046.0
36.484997418,2036.0
36.535131225,2132.0
36.585265032,1998.0
36.635398839,2015.0
36.685532646,2123.0
36.735666453,2018.0
36.785800260,1986.0
36.835934066,2080.0
36.886067873,2019.0
36.936201680,2068.0
36.986335487,2095.0
37.036469294,2051.0
37.086603101,2058.0
37.136736908,2106.0
37.186870715,2047.0
37.237004522,2083.0
37.287138329,2144.0
37.337272136,2016.0
37.387405943,2083.0
37.437539750,2052.0
37.487673557,2063.0
37.537807364,2109.0
37.587941170,2009.0
37.638074977,2049.0
37.688208784,1983.0
37.738342591,2134.0
37.788476398,2022.0
37.838610205,2067.0
37.888744012,2006.0
37.938877819,2126.0
37.989011626,2075.0
38.039145433,2077.0
38.089279240,2117.0
38.139413047,2136.0
38.189546854,2047.0
38.239680661,2089.0
38.289814468,1983.0
38.339948274,2007.0
38.390082081,2052.0
38.440215888,1965.0
38.490349695,1936.0
38.540483502,2016.0
38.590617309,2048.0
38.640751116,2036.0
38.690884923,2063.0
38.741018730,2056.0
38.791152537,1992.0
38.841286344,2036.0
38.891420151,1963.0
38.941553958,1981.0
38.991687765,1953.0
39.041821572,2079.0
39.091955378,1989.0
39.142089185,2007.0
39.192222992,2048.0
39.242356799,2015.0
39.292490606,1990.0
39.342624413,2060.0
39.392758220,2036.0
39.442892027,2014.0
39.493025834,2085.0
39.543159641,2090.0
39.593293448,2155.0
39.643427255,2214.0
39.693561062,2271.0
39.743694869,2447.0
39.793828676,2268.0
39.843962482,2226.0
39.894096289,2100.0
39.944230096,2129.0
39.994363903,2094.0
40.044497710,2105.0
40.094631517,2167.0
40.144765324,2122.0
40.194899131,2116.0
40.245032938,2034.0
40.295166745,1965.0
40.345300552,2024.0
40.395434359,1956.0
40.445568166,2013.0
40.495701973,1989.0
40.545835780,1930.0
40.595969587,2006.0
40.646103393,2073.0
40.696237200,1997.0
40.746371007,1944.0
40.796504814,2059.0
40.846638621,1988.0
40.896772428,1977.0
40.946906235,2025.0
40.997040042,1915.0
41.047173849,1977.0
41.097307656,2020.0
41.147441463,2004.0
41.197575270,1978.0
41.247709077,1953.0
41.297842884,2091.0
41.347976691,1975.0
41.398110497,2084.0
41.448244304,2031.0
41.498378111,1973.0
41.548511918,1872.0
41.598645725,2021.0
41.648779532,2032.0
41.698913339,1969.0
41.749047146,1959.0
41.799180953,1955.0
41.849314760,1943.0
41.899448567,1986.0
41.949582374,2091.0
41.999716181,1956.0
42.049849988,2056.0
42.099983795,1892.0
42.150117601,1977.0
42.200251408,2000.0
42.250385215,1905.0
42.300519022,1979.0
42.350652829,1937.0
42.400786636,1994.0
42.450920443,1945.0
42.501054250,2005.0
42.551188057,1929.0
42.601321864,1994.0
42.651455671,2090.0
42.701589478,2005.0
42.751723285,2006.0
42.801857092,2099.0
42.851990899,2086.0
42.902124705,2122.0
42.952258512,2069.0
43.002392319,1962.0
43.052526126,2074.0
43.102659933,2055.0
43.152793740,2186.0
43.202927547,2093.0
43.253061354,2077.0
43.303195161,2221.0
43.353328968,2154.0
43.403462775,2190.0
43.453596582,2240.0
43.503730389,2292.0
43.553864196,2243.0
43.603998003,2261.0
43.654131809,2472.0
43.704265616,2489.0
43.754399423,2645.0
43.804533230,2757.0
43.854667037,2956.0
43.904800844,3190.0
43.954934651,3583.0
44.005068458,4079.0
44.055202265,4575.0
44.105336072,5365.0
44.155469879,6262.0
44.205603686,7586.0
44.255737493,9046.0
44.305871300,9848.0
44.356005107,10011.0
44.406138913,8866.0
44.456272720,7074.0
44.506406527,5402.0
44.556540334,3931.0
44.606674141,3254.0
44.656807948,2657.0
44.706941755,2504.0
44.757075562,2435.0
44.807209369,2302.0
44.857343176,2212.0
44.907476983,2168.0
44.957610790,2073.0
45.007744597,2153.0
45.057878404,2172.0
45.108012211,2077.0
45.158146018,2055.0
45.208279824,2130.0
45.258413631,2092.0
45.308547438,2073.0
45.358681245,2197.0
45.408815052,2081.0
45.458948859,2170.0
45.509082666,2209.0
45.559216473,2105.0
45.609350280,2082.0
45.659484087,2061.0
45.709617894,2040.0
45.759751701,2049.0
45.809885508,2103.0
45.860019315,2061.0
45.910153122,2015.0
45.960286928,2199.0
46.010420735,2524.0
46.060554542,2746.0
46.110688349,3285.0
46.160822156,4441.0
46.210955963,7682.0
46.261089770,4353.0
46.311223577,4084.0
46.361357384,4785.0
46.411491191,2788.0
46.461624998,2983.0
46.511758805,3376.0
46.561892612,3615.0
46.612026419,3524.0
46.662160226,3293.0
46.712294032,2912.0
46.762427839,2591.0
46.812561646,2183.0
46.862695453,2014.0
46.912829260,2002.0
46.962963067,1952.0
47.013096874,2020.0
47.063230681,1944.0
47.113364488,1971.0
47.163498295,1905.0
47.213632102,1997.0
47.263765909,1930.0
47.313899716,1914.0
47.364033523,1911.0
47.414167330,1910.0
47.464301136,1947.0
47.514434943,1938.0
47.564568750,1891.0
47.614702557,1883.0
47.664836364,1940.0
47.714970171,1881.0
47.765103978,1935.0
47.815237785,1921.0
47.865371592,1925.0
47.915505399,1934.0
47.965639206,1904.0
48.015773013,1974.0
48.065906820,1882.0
48.116040627,1875.0
48.166174434,1921.0
48.216308240,1833.0
48.266442047,1903.0
48.316575854,1898.0
48.366709661,1911.0
48.416843468,1932.0
48.466977275,1867.0
48.517111082,1917.0
48.567244889,1844.0
48.617378696,1885.0
48.667512503,1878.0
48.717646310,1824.0
48.767780117,1872.0
48.817913924,1949.0
48.868047731,1919.0
48.918181538,1845.0
48.968315344,1882.0
49.018449151,1870.0
49.068582958,1856.0
49.118716765,1892.0
49.168850572,1818.0
49.218984379,1851.0
49.269118186,1923.0
49.319251993,1948.0
49.369385800,1917.0
49.419519607,1942.0
49.469653414,2020.0
49.519787221,2131.0
49.569921028,1969.0
49.620054835,2058.0
49.670188642,1912.0
49.720322449,1926.0
49.770456255,1824.0
49.820590062,1968.0
49.870723869,1869.0
49.920857676,1891.0
49.970991483,1841.0
50.021125290,1959.0
50.071259097,1857.0
50.121392904,1981.0
50.171526711,1968.0
50.221660518,1991.0
50.271794325,1947.0
50.321928132,2113.0
50.372061939,2104.0
50.422195746,2328.0
50.472329553,2334.0
50.522463359,2309.0
50.572597166,2269.0
50.622730973,2175.0
50.672864780,2065.0
50.722998587,2020.0
50.773132394,2063.0
50.823266201,2024.0
50.873400008,2015.0
50.923533815,2093.0
50.973667622,2076.0
51.023801429,2100.0
51.073935236,2114.0
51.124069043,2100.0
51.174202850,2298.0
51.224336657,2276.0
51.274470463,2475.0
51.324604270,2679.0
51.374738077,2866.0
51.424871884,3246.0
51.475005691,3463.0
51.525139498,3942.0
51.575273305,4207.0
51.625407112,4492.0
51.675540919,4278.0
51.725674726,4039.0
51.775808533,3608.0
51.825942340,3168.0
51.876076147,2964.0
51.926209954,2612.0
51.976343761,2288.0
52.026477567,2240.0
52.076611374,2143.0
52.126745181,2069.0
52.176878988,2026.0
52.227012795,1945.0
52.277146602,1887.0
52.327280409,1906.0
52.377414216,1877.0
52.427548023,1858.0
52.477681830,1888.0
52.527815637,1885.0
52.577949444,1881.0
52.628083251,1886.0
52.678217058,1893.0
52.728350865,1818.0
52.778484671,1862.0
52.828618478,1853.0
52.878752285,1779.0
52.928886092,1834.0
52.979019899,1852.0
53.029153706,1890.0
53.079287513,1743.0
53.129421320,1737.0
53.179555127,1773.0
53.229688934,1682.0
53.279822741,1863.0
53.329956548,1803.0
53.380090355,1820.0
53.430224162,1694.0
53.480357969,1794.0
53.530491776,1746.0
53.580625582,1796.0
53.630759389,1743.0
53.680893196,1800.0
53.731027003,1743.0
53.781160810,1770.0
53.831294617,1857.0
53.881428424,1748.0
53.931562231,1776.0
53.981696038,1798.0
54.031829845,1808.0
54.081963652,1773.0
54.132097459,1710.0
54.182231266,1797.0
54.232365073,1802.0
54.282498880,1753.0
54.332632686,1848.0
54.382766493,1713.0
54.432900300,1842.0
54.483034107,1771.0
54.533167914,1700.0
54.583301721,1760.0
54.633435528,1837.0
54.683569335,1769.0
54.733703142,1691.0
54.783836949,1817.0
54.833970756,1738.0
54.884104563,1804.0
54.934238370,1793.0
54.984372177,1761.0
55.034505984,1742.0
55.084639790,1828.0
55.134773597,1714.0
55.184907404,1865.0
55.235041211,1728.0
55.285175018,1821.0
55.335308825,1701.0
55.385442632,1783.0
55.435576439,1742.0
55.485710246,1815.0
55.535844053,1809.0
55.585977860,1782.0
55.636111667,1825.0
55.686245474,1749.0
55.736379281,1754.0
55.786513088,1823.0
55.836646894,1759.0
55.886780701,1792.0
55.936914508,1706.0
55.987048315,1765.0
56.037182122,1739.0
56.087315929,1832.0
56.137449736,1778.0
56.187583543,1758.0
56.237717350,1741.0
56.287851157,1689.0
56.337984964,1791.0
56.388118771,1767.0
56.438252578,1770.0
56.488386385,1766.0
56.538520192,1695.0
56.588653998,1747.0
56.638787805,1752.0
56.688921612,1725.0
56.739055419,1716.0
56.789189226,1744.0
56.839323033,1821.0
56.889456840,1712.0
56.939590647,1752.0
56.989724454,1715.0
57.039858261,1742.0
57.089992068,1804.0
57.140125875,1740.0
57.190259682,1770.0
57.240393489,1700.0
57.290527296,1779.0
57.340661102,1757.0
57.390794909,1790.0
57.440928716,1747.0
57.491062523,1755.0
57.541196330,1742.0
57.591330137,1840.0
57.641463944,1770.0
57.691597751,1772.0
57.741731558,1717.0
57.791865365,1716.0
57.841999172,1859.0
57.892132979,1681.0
57.942266786,1818.0
57.992400593,1801.0
58.042534400,1802.0
58.092668207,1729.0
58.142802013,1800.0
58.192935820,1720.0
58.243069627,1802.0
58.293203434,1741.0
58.343337241,1826.0
58.393471048,1691.0
58.443604855,1791.0
58.493738662,1763.0
58.543872469,1759.0
58.594006276,1731.0
58.644140083,1781.0
58.694273890,1713.0
58.744407697,1793.0
58.794541504,1758.0
58.844675311,1804.0
58.894809117,1781.0
58.944942924,1709.0
58.995076731,1785.0
59.045210538,1765.0
59.095344345,1786.0
59.145478152,1798.0
59.195611959,1772.0
59.245745766,1740.0
59.295879573,1749.0
59.346013380,1784.0
59.396147187,1715.0
59.446280994,1823.0
59.496414801,1793.0
59.546548608,1788.0
59.596682415,1769.0
59.646816221,1795.0
59.696950028,1764.0
59.747083835,1863.0
59.797217642,1741.0
59.847351449,1704.0
59.897485256,1763.0
59.947619063,1771.0
59.997752870,1845.0
60.047886677,1782.0
60.098020484,1789.0
60.148154291,1730.0
60.198288098,1734.0
60.248421905,1742.0
60.298555712,1811.0
60.348689519,1811.0
60.398823325,1739.0
60.448957132,1795.0
60.499090939,1794.0
60.549224746,1878.0
60.599358553,1769.0
60.649492360,1763.0
60.699626167,1825.0
60.749759974,1798.0
60.799893781,1756.0
60.850027588,1836.0
60.900161395,1816.0
60.950295202,1775.0
61.000429009,1835.0
61.050562816,1815.0
61.100696623,1767.0
61.150830429,1787.0
61.200964236,1835.0
61.251098043,1777.0
61.301231850,1795.0
61.351365657,1818.0
61.401499464,1796.0
61.451633271,1868.0
61.501767078,1781.0
61.551900885,1875.0
61.602034692,1765.0
61.652168499,1839.0
61.702302306,1853.0
61.752436113,1873.0
61.802569920,1821.0
61.852703727,1801.0
61.902837533,1775.0
61.952971340,1719.0
62.003105147,1894.0
62.053238954,1827.0
62.103372761,1857.0
62.153506568,1795.0
62.203640375,1917.0
62.253774182,1823.0
62.303907989,1899.0
62.354041796,1855.0
62.404175603,1827.0
62.454309410,1885.0
62.504443217,1863.0
62.554577024,1882.0
62.604710831,1893.0
62.654844638,1849.0
62.704978444,1783.0
62.755112251,1802.0
62.805246058,1921.0
62.855379865,1862.0
62.905513672,1806.0
62.955647479,1918.0
63.005781286,1903.0
63.055915093,1864.0
63.106048900,1913.0
63.156182707,1886.0
63.206316514,1944.0
63.256450321,1872.0
63.306584128,1876.0
63.356717935,1858.0
63.406851742,1914.0
63.456985548,1844.0
63.507119355,1953.0
63.557253162,1876.0
63.607386969,1937.0
63.657520776,1888.0
63.707654583,1886.0
63.757788390,1901.0
63.807922197,1939.0
63.858056004,1876.0
63.908189811,1856.0
63.958323618,1962.0
64.008457425,1959.0
64.058591232,1946.0
64.108725039,1927.0
64.158858846,1980.0
64.208992652,1917.0
64.259126459,1969.0
64.309260266,1956.0
64.359394073,1962.0
64.409527880,1876.0
64.459661687,1996.0
64.509795494,2006.0
64.559929301,1968.0
64.610063108,1942.0
64.660196915,1849.0
64.710330722,1914.0
64.760464529,1912.0
64.810598336,1948.0
64.860732143,1933.0
64.910865950,1955.0
64.960999756,1976.0
65.011133563,1919.0
65.061267370,1910.0
65.111401177,2002.0
65.161534984,2033.0
65.211668791,1952.0
65.261802598,1987.0
65.311936405,1959.0
65.362070212,1954.0
65.412204019,1910.0
65.462337826,1934.0
65.512471633,1964.0
65.562605440,1918.0
65.612739247,1995.0
65.662873054,1887.0
65.713006860,1951.0
65.763140667,2046.0
65.813274474,1985.0
65.863408281,1978.0
65.913542088,1923.0
65.963675895,2105.0
66.013809702,1989.0
66.063943509,2016.0
66.114077316,2056.0
66.164211123,2075.0
66.214344930,1956.0
66.264478737,1976.0
66.314612544,1977.0
66.364746351,1962.0
66.414880158,1953.0
66.465013964,1979.0
66.515147771,1991.0
66.565281578,2052.0
66.615415385,1929.0
66.665549192,1993.0
66.715682999,1998.0
66.765816806,2075.0
66.815950613,2119.0
66.866084420,1953.0
66.916218227,2006.0
66.966352034,1995.0
67.016485841,2079.0
67.066619648,1978.0
67.116753455,2033.0
67.166887262,2002.0
67.217021069,1986.0
67.267154875,2035.0
67.317288682,2089.0
67.367422489,1966.0
67.417556296,2011.0
67.467690103,2036.0
67.517823910,1977.0
67.567957717,2091.0
67.618091524,1951.0
67.668225331,2068.0
67.718359138,1960.0
67.768492945,2075.0
67.818626752,1976.0
67.868760559,1988.0
67.918894366,2032.0
67.969028173,2063.0
68.019161979,2050.0
68.069295786,2028.0
68.119429593,1945.0
68.169563400,1909.0
68.219697207,2010.0
68.269831014,1990.0
68.319964821,1993.0
68.370098628,1859.0
68.420232435,2033.0
68.470366242,2004.0
68.520500049,1958.0
68.570633856,2023.0
68.620767663,1923.0
68.670901470,1933.0
68.721035277,2018.0
68.771169083,2068.0
68.821302890,1956.0
68.871436697,2077.0
68.921570504,1910.0
68.971704311,1991.0
69.021838118,2054.0
69.071971925,2003.0
69.122105732,2032.0
69.172239539,2009.0
69.222373346,1929.0
69.272507153,1900.0
69.322640960,1953.0
69.372774767,1919.0
69.422908574,1924.0
69.473042381,1944.0
69.523176187,2004.0
69.573309994,1988.0
69.623443801,1902.0
69.673577608,1966.0
69.723711415,2044.0
69.773845222,2037.0
69.823979029,1982.0
69.874112836,1926.0
69.924246643,1900.0
69.974380450,1915.0
70.024514257,1968.0
70.074648064,1869.0
70.124781871,1965.0
70.174915678,1900.0
70.225049485,1888.0
70.275183291,2056.0
70.325317098,1964.0
70.375450905,1957.0
70.425584712,1936.0
70.475718519,1898.0
70.525852326,2012.0
70.575986133,1862.0
70.626119940,1977.0
70.676253747,1905.0
70.726387554,1956.0
70.776521361,1905.0
70.826655168,1977.0
70.876788975,2011.0
70.926922782,1955.0
70.977056589,1878.0
71.027190396,1881.0
71.077324202,1907.0
71.127458009,1949.0
71.177591816,1900.0
71.227725623,1896.0
71.277859430,1833.0
71.327993237,1866.0
71.378127044,1886.0
71.428260851,1885.0
71.478394658,1884.0
71.528528465,1866.0
71.578662272,1904.0
71.628796079,1938.0
71.678929886,1887.0
71.729063693,1950.0
71.779197500,1878.0
71.829331306,1957.0
71.879465113,1869.0
71.929598920,1847.0
71.979732727,1860.0
72.029866534,1929.0
72.080000341,1916.0
72.130134148,1810.0
72.180267955,1724.0
72.230401762,1807.0
72.280535569,1870.0
72.330669376,1835.0
72.380803183,1836.0
72.430936990,1815.0
72.481070797,1854.0
72.531204604,1814.0
72.581338410,1882.0
72.631472217,1812.0
72.681606024,1910.0
72.731739831,1860.0
72.781873638,1882.0
72.832007445,1858.0
72.882141252,1770.0
72.932275059,1834.0
72.982408866,1844.0
73.032542673,1811.0
73.082676480,1709.0
73.132810287,1800.0
73.182944094,1812.0
73.233077901,1807.0
73.283211708,1828.0
73.333345514,1764.0
73.383479321,1831.0
73.433613128,1817.0
73.483746935,1746.0
73.533880742,1919.0
73.584014549,1827.0
73.634148356,1800.0
73.684282163,1836.0
73.734415970,1729.0
73.784549777,1805.0
73.834683584,1827.0
73.884817391,1797.0
73.934951198,1702.0
73.985085005,1715.0
74.035218812,1779.0
74.085352618,1740.0
74.135486425,1707.0
74.185620232,1767.0
74.235754039,1808.0
74.285887846,1819.0
74.336021653,1739.0
74.386155460,1727.0
74.436289267,1747.0
74.486423074,1715.0
74.536556881,1735.0
74.586690688,1687.0
74.636824495,1786.0
74.686958302,1817.0
74.737092109,1677.0
74.787225916,1818.0
74.837359722,1705.0
74.887493529,1784.0
74.937627336,1728.0
74.987761143,1771.0
75.037894950,1828.0
75.088028757,1697.0
75.138162564,1785.0
75.188296371,1723.0
75.238430178,1851.0
75.288563985,1784.0
75.338697792,1803.0
75.388831599,1814.0
75.438965406,1830.0
75.489099213,1815.0
75.539233020,1883.0
75.589366827,1935.0
75.639500633,1918.0
75.689634440,1942.0
75.739768247,1988.0
75.789902054,2054.0
75.840035861,2124.0
75.890169668,2197.0
75.940303475,2237.0
75.990437282,2161.0
76.040571089,2248.0
76.090704896,2196.0
76.140838703,2175.0
76.190972510,2219.0
76.241106317,2022.0
76.291240124,2004.0
76.341373931,1951.0
76.391507737,1857.0
76.441641544,1865.0
76.491775351,1854.0
76.541909158,1837.0
76.592042965,1721.0
76.642176772,1770.0
76.692310579,1731.0
76.742444386,1744.0
76.792578193,1609.0
76.842712000,1697.0
76.892845807,1694.0
76.942979614,1684.0
76.993113421,1609.0
77.043247228,1536.0
77.093381035,1623.0
77.143514841,1654.0
77.193648648,1623.0
77.243782455,1593.0
77.293916262,1664.0
77.344050069,1615.0
77.394183876,1642.0
77.444317683,1581.0
77.494451490,1683.0
77.544585297,1628.0
77.594719104,1619.0
77.644852911,1579.0
77.694986718,1554.0
77.745120525,1560.0
77.795254332,1559.0
77.845388139,1549.0
77.895521945,1587.0
77.945655752,1589.0
77.995789559,1602.0
78.045923366,1575.0
78.096057173,1629.0
78.146190980,1576.0
78.196324787,1549.0
78.246458594,1519.0
78.296592401,1486.0
78.346726208,1551.0
78.396860015,1535.0
78.446993822,1534.0
78.497127629,1494.0
78.547261436,1550.0
78.597395243,1611.0
78.647529049,1492.0
78.697662856,1468.0
78.747796663,1512.0
78.797930470,1521.0
78.848064277,1605.0
78.898198084,1551.0
78.948331891,1546.0
78.998465698,1550.0
79.048599505,1582.0
79.098733312,1518.0
79.148867119,1587.0
79.199000926,1587.0
79.249134733,1551.0
79.299268540,1498.0
79.349402347,1538.0
79.399536153,1515.0
79.449669960,1526.0
79.499803767,1523.0
79.549937574,1530.0
79.600071381,1558.0
79.650205188,1603.0
79.700338995,1485.0
79.750472802,1482.0
79.800606609,1484.0
79.850740416,1505.0
79.900874223,1556.0
79.951008030,1542.0
80.001141837,1513.0
80.051275644,1555.0
80.101409451,1516.0
80.151543258,1527.0
80.201677064,1525.0
80.251810871,1537.0
80.301944678,1492.0
80.352078485,1486.0
80.402212292,1504.0
80.452346099,1520.0
80.502479906,1596.0
80.552613713,1500.0
80.602747520,1477.0
80.652881327,1516.0
80.703015134,1565.0
80.753148941,1439.0
80.803282748,1498.0
80.853416555,1513.0
80.903550362,1579.0
80.953684168,1449.0
81.003817975,1489.0
81.053951782,1464.0
81.104085589,1537.0
81.154219396,1487.0
81.204353203,1467.0
81.254487010,1507.0
81.304620817,1470.0
81.354754624,1492.0
81.404888431,1491.0
81.455022238,1457.0
81.505156045,1414.0
81.555289852,1420.0
81.605423659,1508.0
81.655557466,1429.0
81.705691272,1503.0
81.755825079,1482.0
81.805958886,1574.0
81.856092693,1437.0
81.906226500,1439.0
81.956360307,1460.0
82.006494114,1462.0
82.056627921,1413.0
82.106761728,1456.0
82.156895535,1444.0
82.207029342,1423.0
82.257163149,1415.0
82.307296956,1457.0
82.357430763,1502.0
82.407564570,1472.0
82.457698376,1508.0
82.507832183,1491.0
82.557965990,1428.0
82.608099797,1416.0
82.658233604,1470.0
82.708367411,1443.0
82.758501218,1419.0
82.808635025,1355.0
82.858768832,1472.0
82.908902639,1525.0
82.959036446,1447.0
83.009170253,1540.0
83.059304060,1366.0
83.109437867,1368.0
83.159571674,1381.0
83.209705480,1402.0
83.259839287,1393.0
83.309973094,1463.0
83.360106901,1474.0
83.410240708,1476.0
83.460374515,1446.0
83.510508322,1420.0
83.560642129,1450.0
83.610775936,1437.0
83.660909743,1395.0
83.711043550,1408.0
83.761177357,1488.0
83.811311164,1409.0
83.861444971,1423.0
83.911578778,1455.0
83.961712584,1468.0
84.011846391,1426.0
84.061980198,1478.0
84.112114005,1418.0
84.162247812,1380.0
84.212381619,1422.0
84.262515426,1397.0
84.312649233,1416.0
84.362783040,1392.0
84.412916847,1371.0
84.463050654,1425.0
84.513184461,1421.0
84.563318268,1446.0
84.613452075,1446.0
84.663585882,1396.0
84.713719689,1361.0
84.763853495,1389.0
84.813987302,1480.0
84.864121109,1401.0
84.914254916,1375.0
84.964388723,1359.0
85.014522530,1417.0
85.064656337,1365.0
85.114790144,1436.0
85.164923951,1390.0
85.215057758,1433.0
85.265191565,1418.0
85.315325372,1392.0
85.365459179,1399.0
85.415592986,1364.0
85.465726793,1409.0
85.515860599,1457.0
85.565994406,1436.0
85.616128213,1412.0
85.666262020,1415.0
85.716395827,1428.0
85.766529634,1460.0
85.816663441,1405.0
85.866797248,1423.0
85.916931055,1393.0
85.967064862,1411.0
86.017198669,1379.0
86.067332476,1411.0
86.117466283,1413.0
86.167600090,1398.0
86.217733897,1345.0
86.267867703,1339.0
86.318001510,1380.0
86.368135317,1394.0
86.418269124,1390.0
86.468402931,1345.0
86.518536738,1416.0
86.568670545,1381.0
86.618804352,1360.0
86.668938159,1341.0
86.719071966,1327.0
86.769205773,1317.0
86.819339580,1327.0
86.869473387,1382.0
86.919607194,1360.0
86.969741001,1350.0
87.019874807,1338.0
87.070008614,1446.0
87.120142421,1398.0
87.170276228,1394.0
87.220410035,1399.0
87.270543842,1346.0
87.320677649,1385.0
87.370811456,1362.0
87.420945263,1284.0
87.471079070,1346.0
87.521212877,1358.0
87.571346684,1388.0
87.621480491,1321.0
87.671614298,1381.0
87.721748105,1349.0
87.771881911,1401.0
87.822015718,1453.0
87.872149525,1351.0
87.922283332,1294.0
87.972417139,1359.0
88.022550946,1346.0
88.072684753,1331.0
88.122818560,1268.0
88.172952367,1360.0
88.223086174,1346.0
88.273219981,1363.0
88.323353788,1361.0
88.373487595,1255.0
88.423621402,1332.0
88.473755209,1348.0
88.523889016,1333.0
88.574022822,1300.0
88.624156629,1388.0
88.674290436,1378.0
88.724424243,1331.0
88.774558050,1322.0
88.824691857,1374.0
88.874825664,1357.0
88.924959471,1364.0
88.975093278,1380.0
89.025227085,1287.0
89.075360892,1382.0
89.125494699,1326.0
89.175628506,1406.0
89.225762313,1345.0
89.275896120,1363.0
89.326029926,1370.0
89.376163733,1313.0
89.426297540,1352.0
89.476431347,1294.0
89.526565154,1351.0
89.576698961,1372.0
89.626832768,1296.0
89.676966575,1303.0
89.727100382,1298.0
89.777234189,1310.0
89.827367996,1252.0
89.877501803,1351.0
89.927635610,1299.0
89.977769417,1343.0
90.027903224,1315.0
90.078037030,1381.0
90.128170837,1371.0
90.178304644,1428.0
90.228438451,1304.0
90.278572258,1420.0
90.328706065,1317.0
90.378839872,1373.0
90.428973679,1376.0
90.479107486,1351.0
90.529241293,1315.0
90.579375100,1320.0
90.629508907,1419.0
90.679642714,1340.0
90.729776521,1336.0
90.779910328,1389.0
90.830044134,1360.0
90.880177941,1313.0
90.930311748,1314.0
90.980445555,1357.0
91.030579362,1437.0
91.080713169,1361.0
91.130846976,1401.0
91.180980783,1357.0
91.231114590,1325.0
91.281248397,1431.0
91.331382204,1302.0
91.381516011,1449.0
91.431649818,1347.0
91.481783625,1378.0
91.531917432,1415.0
91.582051238,1430.0
91.632185045,1393.0
91.682318852,1376.0
91.732452659,1377.0
91.782586466,1449.0
91.832720273,1464.0
91.882854080,1483.0
91.932987887,1450.0
91.983121694,1521.0
92.033255501,1538.0
92.083389308,1566.0
92.133523115,1621.0
92.183656922,1624.0
92.233790729,1655.0
92.283924536,1705.0
92.334058342,1683.0
92.384192149,1750.0
92.434325956,1871.0
92.484459763,1803.0
92.534593570,1834.0
92.584727377,1776.0
92.634861184,1693.0
92.684994991,1608.0
92.735128798,1740.0
92.785262605,1605.0
92.835396412,1521.0
92.885530219,1615.0
92.935664026,1484.0
92.985797833,1441.0
93.035931640,1417.0
93.086065447,1377.0
93.136199253,1443.0
93.186333060,1391.0
93.236466867,1366.0
93.286600674,1383.0
93.336734481,1335.0
93.386868288,1337.0
93.437002095,1362.0
93.487135902,1355.0
93.537269709,1343.0
93.587403516,1239.0
93.637537323,1286.0
93.687671130,1327.0
93.737804937,1243.0
93.787938744,1341.0
93.838072551,1348.0
93.888206357,1318.0
93.938340164,1303.0
93.988473971,1306.0
94.038607778,1320.0
94.088741585,1346.0
94.138875392,1274.0
94.189009199,1319.0
94.239143006,1311.0
94.289276813,1272.0
94.339410620,1293.0
94.389544427,1313.0
94.439678234,1249.0
94.489812041,1331.0
94.539945848,1275.0
94.590079655,1348.0
94.640213461,1325.0
94.690347268,1251.0
94.740481075,1287.0
94.790614882,1315.0
94.840748689,1328.0
94.890882496,1287.0
94.941016303,1363.0
94.991150110,1361.0