File: OriginPro/XRD from Panalytical X'Pert PRO/In-Situ/FicheirosXRD_Insitu/NiNws_200°C.csv
[Measurement conditions]
Sample identification,
Comment - 1,"finito"
Comment - 2,"Configuration=MRI TC-Basic Stage, Owner=User-1, Creation date=26-10-2009 9:18:44"
Comment - 3,"Goniometer=PW3050/60 (Theta/Theta); Minimum step size 2Theta:0.001; Minimum step size Omega:0.001"
Comment - 4,"Sample stage=MRI TC-Basic (PtRh heat strip)"
Comment - 5,"Diffractometer system=XPERT-PRO"
Comment - 6,"Measurement program=FS-L, Owner=joana, Creation date=25-11-2014 17:28:08"
Anode material,Cu
K-Alpha1 wavelength,1.5405980
K-Alpha2 wavelength,1.5444260
Ratio K-Alpha2/K-Alpha1,0.500
Divergence slit,Fixed,0.76mm
Monochromator used,NO
Generator voltage, 45
Tube current, 40
File date and time,15-Dez-2017 20:44
Unit cell,
h k l, 0 0 0
Temperature [K],473
Scan axis,Gonio
Scan range,24.995999996,94.999505744
Scan step size,0.0167113
No. of points, 4189
Scan type,CONTINUOUS
Time per step,118.110
[Scan points]
Angle,Intensity
25.004355630,2309.0
25.054489437,2196.0
25.104623244,2320.0
25.154757051,2279.0
25.204890858,2252.0
25.255024665,2317.0
25.305158472,2256.0
25.355292279,2239.0
25.405426085,2208.0
25.455559892,2231.0
25.505693699,2111.0
25.555827506,2295.0
25.605961313,2264.0
25.656095120,2231.0
25.706228927,2291.0
25.756362734,2227.0
25.806496541,2199.0
25.856630348,2203.0
25.906764155,2214.0
25.956897962,2176.0
26.007031769,2229.0
26.057165576,2165.0
26.107299383,2186.0
26.157433189,2273.0
26.207566996,2190.0
26.257700803,2225.0
26.307834610,2266.0
26.357968417,2181.0
26.408102224,2170.0
26.458236031,2288.0
26.508369838,2278.0
26.558503645,2172.0
26.608637452,2213.0
26.658771259,2270.0
26.708905066,2180.0
26.759038873,2194.0
26.809172680,2236.0
26.859306487,2198.0
26.909440293,2286.0
26.959574100,2220.0
27.009707907,2210.0
27.059841714,2200.0
27.109975521,2115.0
27.160109328,2195.0
27.210243135,2209.0
27.260376942,2217.0
27.310510749,2206.0
27.360644556,2331.0
27.410778363,2213.0
27.460912170,2178.0
27.511045977,2152.0
27.561179784,2198.0
27.611313591,2189.0
27.661447398,2187.0
27.711581204,2226.0
27.761715011,2245.0
27.811848818,2220.0
27.861982625,2191.0
27.912116432,2153.0
27.962250239,2199.0
28.012384046,2165.0
28.062517853,2245.0
28.112651660,2157.0
28.162785467,2117.0
28.212919274,2201.0
28.263053081,2450.0
28.313186888,2472.0
28.363320695,2846.0
28.413454502,2407.0
28.463588308,2389.0
28.513722115,2421.0
28.563855922,2318.0
28.613989729,2400.0
28.664123536,2260.0
28.714257343,2179.0
28.764391150,2300.0
28.814524957,2216.0
28.864658764,2305.0
28.914792571,2158.0
28.964926378,2338.0
29.015060185,2248.0
29.065193992,2247.0
29.115327799,2256.0
29.165461606,2198.0
29.215595412,2249.0
29.265729219,2181.0
29.315863026,2179.0
29.365996833,2167.0
29.416130640,2183.0
29.466264447,2140.0
29.516398254,2139.0
29.566532061,2131.0
29.616665868,2133.0
29.666799675,2183.0
29.716933482,2107.0
29.767067289,2198.0
29.817201096,2112.0
29.867334903,2088.0
29.917468710,2189.0
29.967602516,2218.0
30.017736323,2137.0
30.067870130,2148.0
30.118003937,2174.0
30.168137744,2122.0
30.218271551,2017.0
30.268405358,2152.0
30.318539165,2097.0
30.368672972,2143.0
30.418806779,2193.0
30.468940586,2211.0
30.519074393,2146.0
30.569208200,2036.0
30.619342007,2059.0
30.669475814,2081.0
30.719609620,2117.0
30.769743427,2236.0
30.819877234,2064.0
30.870011041,2199.0
30.920144848,2132.0
30.970278655,2128.0
31.020412462,2112.0
31.070546269,2052.0
31.120680076,2178.0
31.170813883,2152.0
31.220947690,2134.0
31.271081497,2075.0
31.321215304,2136.0
31.371349111,2133.0
31.421482918,2088.0
31.471616724,2094.0
31.521750531,2065.0
31.571884338,2114.0
31.622018145,2084.0
31.672151952,2066.0
31.722285759,2156.0
31.772419566,2057.0
31.822553373,2130.0
31.872687180,2112.0
31.922820987,2192.0
31.972954794,2144.0
32.023088601,2093.0
32.073222408,2109.0
32.123356215,2153.0
32.173490022,2131.0
32.223623829,2225.0
32.273757635,2081.0
32.323891442,2094.0
32.374025249,2139.0
32.424159056,2041.0
32.474292863,2082.0
32.524426670,2231.0
32.574560477,2075.0
32.624694284,2130.0
32.674828091,2144.0
32.724961898,2159.0
32.775095705,2141.0
32.825229512,2119.0
32.875363319,2197.0
32.925497126,2130.0
32.975630933,2096.0
33.025764739,2041.0
33.075898546,2046.0
33.126032353,2171.0
33.176166160,2140.0
33.226299967,2159.0
33.276433774,2041.0
33.326567581,2077.0
33.376701388,2101.0
33.426835195,2000.0
33.476969002,2141.0
33.527102809,2066.0
33.577236616,2226.0
33.627370423,2084.0
33.677504230,2060.0
33.727638037,2122.0
33.777771843,2024.0
33.827905650,1998.0
33.878039457,2183.0
33.928173264,2102.0
33.978307071,2036.0
34.028440878,2197.0
34.078574685,2098.0
34.128708492,2075.0
34.178842299,2151.0
34.228976106,2066.0
34.279109913,2136.0
34.329243720,2064.0
34.379377527,2092.0
34.429511334,2090.0
34.479645141,2087.0
34.529778947,2070.0
34.579912754,2092.0
34.630046561,2081.0
34.680180368,2113.0
34.730314175,2117.0
34.780447982,2098.0
34.830581789,2104.0
34.880715596,2039.0
34.930849403,2045.0
34.980983210,2045.0
35.031117017,2016.0
35.081250824,1976.0
35.131384631,2088.0
35.181518438,2122.0
35.231652245,2104.0
35.281786051,2059.0
35.331919858,1992.0
35.382053665,2047.0
35.432187472,2089.0
35.482321279,2089.0
35.532455086,2079.0
35.582588893,2014.0
35.632722700,2069.0
35.682856507,2128.0
35.732990314,1988.0
35.783124121,1984.0
35.833257928,2045.0
35.883391735,2039.0
35.933525542,2006.0
35.983659349,2025.0
36.033793156,2024.0
36.083926962,2139.0
36.134060769,2068.0
36.184194576,2085.0
36.234328383,2098.0
36.284462190,1990.0
36.334595997,2012.0
36.384729804,2078.0
36.434863611,2067.0
36.484997418,2124.0
36.535131225,2017.0
36.585265032,2125.0
36.635398839,2058.0
36.685532646,1984.0
36.735666453,1980.0
36.785800260,1923.0
36.835934066,2087.0
36.886067873,2057.0
36.936201680,1985.0
36.986335487,2042.0
37.036469294,2020.0
37.086603101,2038.0
37.136736908,1950.0
37.186870715,2056.0
37.237004522,1981.0
37.287138329,2073.0
37.337272136,2082.0
37.387405943,2030.0
37.437539750,2007.0
37.487673557,2069.0
37.537807364,2090.0
37.587941170,2124.0
37.638074977,2082.0
37.688208784,2048.0
37.738342591,2072.0
37.788476398,2012.0
37.838610205,2053.0
37.888744012,2166.0
37.938877819,1999.0
37.989011626,2027.0
38.039145433,2092.0
38.089279240,2084.0
38.139413047,2093.0
38.189546854,2129.0
38.239680661,2025.0
38.289814468,2085.0
38.339948274,2004.0
38.390082081,1971.0
38.440215888,2098.0
38.490349695,1992.0
38.540483502,1974.0
38.590617309,2040.0
38.640751116,2050.0
38.690884923,2064.0
38.741018730,2066.0
38.791152537,2036.0
38.841286344,2014.0
38.891420151,2031.0
38.941553958,2031.0
38.991687765,2029.0
39.041821572,1977.0
39.091955378,1962.0
39.142089185,2049.0
39.192222992,2037.0
39.242356799,1998.0
39.292490606,1985.0
39.342624413,2042.0
39.392758220,2031.0
39.442892027,2062.0
39.493025834,1981.0
39.543159641,2015.0
39.593293448,2168.0
39.643427255,2085.0
39.693561062,2257.0
39.743694869,2476.0
39.793828676,2327.0
39.843962482,2202.0
39.894096289,2178.0
39.944230096,2063.0
39.994363903,2169.0
40.044497710,2115.0
40.094631517,2118.0
40.144765324,2021.0
40.194899131,2111.0
40.245032938,2095.0
40.295166745,1970.0
40.345300552,1959.0
40.395434359,2018.0
40.445568166,1975.0
40.495701973,2072.0
40.545835780,1981.0
40.595969587,2094.0
40.646103393,1977.0
40.696237200,2002.0
40.746371007,1977.0
40.796504814,1975.0
40.846638621,2030.0
40.896772428,1957.0
40.946906235,1984.0
40.997040042,2025.0
41.047173849,2034.0
41.097307656,2063.0
41.147441463,2011.0
41.197575270,2033.0
41.247709077,2010.0
41.297842884,2066.0
41.347976691,1981.0
41.398110497,2082.0
41.448244304,1972.0
41.498378111,2034.0
41.548511918,2004.0
41.598645725,2019.0
41.648779532,1969.0
41.698913339,1967.0
41.749047146,1981.0
41.799180953,2032.0
41.849314760,2029.0
41.899448567,2047.0
41.949582374,2002.0
41.999716181,1991.0
42.049849988,2085.0
42.099983795,2113.0
42.150117601,2002.0
42.200251408,2066.0
42.250385215,1929.0
42.300519022,2033.0
42.350652829,2031.0
42.400786636,2135.0
42.450920443,1907.0
42.501054250,2018.0
42.551188057,1963.0
42.601321864,2029.0
42.651455671,1965.0
42.701589478,2017.0
42.751723285,2058.0
42.801857092,2119.0
42.851990899,2118.0
42.902124705,2009.0
42.952258512,2083.0
43.002392319,2053.0
43.052526126,2023.0
43.102659933,2062.0
43.152793740,2152.0
43.202927547,2111.0
43.253061354,2129.0
43.303195161,2104.0
43.353328968,2129.0
43.403462775,2227.0
43.453596582,2205.0
43.503730389,2229.0
43.553864196,2306.0
43.603998003,2367.0
43.654131809,2424.0
43.704265616,2513.0
43.754399423,2593.0
43.804533230,2752.0
43.854667037,2938.0
43.904800844,3054.0
43.954934651,3409.0
44.005068458,3791.0
44.055202265,4183.0
44.105336072,4871.0
44.155469879,5561.0
44.205603686,6872.0
44.255737493,8249.0
44.305871300,9435.0
44.356005107,10173.0
44.406138913,9814.0
44.456272720,8246.0
44.506406527,6385.0
44.556540334,4909.0
44.606674141,3738.0
44.656807948,2891.0
44.706941755,2766.0
44.757075562,2449.0
44.807209369,2451.0
44.857343176,2237.0
44.907476983,2215.0
44.957610790,2221.0
45.007744597,2121.0
45.057878404,2176.0
45.108012211,2217.0
45.158146018,2251.0
45.208279824,2194.0
45.258413631,2105.0
45.308547438,2166.0
45.358681245,2081.0
45.408815052,2299.0
45.458948859,2140.0
45.509082666,2142.0
45.559216473,2179.0
45.609350280,2033.0
45.659484087,2133.0
45.709617894,2052.0
45.759751701,2053.0
45.809885508,2212.0
45.860019315,2121.0
45.910153122,2102.0
45.960286928,2228.0
46.010420735,2443.0
46.060554542,2637.0
46.110688349,3055.0
46.160822156,4068.0
46.210955963,6155.0
46.261089770,6273.0
46.311223577,3933.0
46.361357384,5333.0
46.411491191,3105.0
46.461624998,2935.0
46.511758805,3315.0
46.561892612,3539.0
46.612026419,3608.0
46.662160226,3490.0
46.712294032,3023.0
46.762427839,2675.0
46.812561646,2339.0
46.862695453,2077.0
46.912829260,2006.0
46.962963067,1900.0
47.013096874,2052.0
47.063230681,1955.0
47.113364488,1973.0
47.163498295,1926.0
47.213632102,1968.0
47.263765909,1963.0
47.313899716,2008.0
47.364033523,1992.0
47.414167330,1980.0
47.464301136,1912.0
47.514434943,1903.0
47.564568750,2049.0
47.614702557,1886.0
47.664836364,1905.0
47.714970171,1945.0
47.765103978,1963.0
47.815237785,1915.0
47.865371592,1931.0
47.915505399,1916.0
47.965639206,1893.0
48.015773013,1910.0
48.065906820,1933.0
48.116040627,1815.0
48.166174434,1896.0
48.216308240,1974.0
48.266442047,1942.0
48.316575854,1913.0
48.366709661,1960.0
48.416843468,1839.0
48.466977275,1792.0
48.517111082,1902.0
48.567244889,1871.0
48.617378696,1847.0
48.667512503,1900.0
48.717646310,1905.0
48.767780117,1864.0
48.817913924,1923.0
48.868047731,1955.0
48.918181538,1955.0
48.968315344,1766.0
49.018449151,1852.0
49.068582958,1908.0
49.118716765,1995.0
49.168850572,1927.0
49.218984379,1944.0
49.269118186,1967.0
49.319251993,1915.0
49.369385800,1978.0
49.419519607,1943.0
49.469653414,2048.0
49.519787221,2079.0
49.569921028,2034.0
49.620054835,2013.0
49.670188642,2007.0
49.720322449,1965.0
49.770456255,1883.0
49.820590062,1853.0
49.870723869,1810.0
49.920857676,1914.0
49.970991483,1865.0
50.021125290,1896.0
50.071259097,1964.0
50.121392904,1938.0
50.171526711,1970.0
50.221660518,1900.0
50.271794325,1988.0
50.321928132,2110.0
50.372061939,2185.0
50.422195746,2269.0
50.472329553,2341.0
50.522463359,2320.0
50.572597166,2264.0
50.622730973,2205.0
50.672864780,2169.0
50.722998587,2127.0
50.773132394,2096.0
50.823266201,2065.0
50.873400008,2032.0
50.923533815,2050.0
50.973667622,2070.0
51.023801429,2032.0
51.073935236,2098.0
51.124069043,2168.0
51.174202850,2259.0
51.224336657,2248.0
51.274470463,2398.0
51.324604270,2534.0
51.374738077,2806.0
51.424871884,2969.0
51.475005691,3286.0
51.525139498,3687.0
51.575273305,4003.0
51.625407112,4176.0
51.675540919,4447.0
51.725674726,4383.0
51.775808533,3899.0
51.825942340,3470.0
51.876076147,3211.0
51.926209954,2844.0
51.976343761,2494.0
52.026477567,2205.0
52.076611374,2170.0
52.126745181,2148.0
52.176878988,2047.0
52.227012795,2080.0
52.277146602,2026.0
52.327280409,1915.0
52.377414216,1874.0
52.427548023,1968.0
52.477681830,1834.0
52.527815637,1847.0
52.577949444,2015.0
52.628083251,1968.0
52.678217058,1863.0
52.728350865,1936.0
52.778484671,1885.0
52.828618478,1805.0
52.878752285,1826.0
52.928886092,1862.0
52.979019899,1797.0
53.029153706,1799.0
53.079287513,1850.0
53.129421320,1831.0
53.179555127,1826.0
53.229688934,1767.0
53.279822741,1793.0
53.329956548,1931.0
53.380090355,1852.0
53.430224162,1798.0
53.480357969,1840.0
53.530491776,1782.0
53.580625582,1833.0
53.630759389,1831.0
53.680893196,1760.0
53.731027003,1886.0
53.781160810,1794.0
53.831294617,1863.0
53.881428424,1749.0
53.931562231,1833.0
53.981696038,1835.0
54.031829845,1776.0
54.081963652,1835.0
54.132097459,1781.0
54.182231266,1824.0
54.232365073,1722.0
54.282498880,1771.0
54.332632686,1816.0
54.382766493,1811.0
54.432900300,1880.0
54.483034107,1748.0
54.533167914,1739.0
54.583301721,1761.0
54.633435528,1783.0
54.683569335,1728.0
54.733703142,1934.0
54.783836949,1812.0
54.833970756,1751.0
54.884104563,1790.0
54.934238370,1773.0
54.984372177,1801.0
55.034505984,1718.0
55.084639790,1830.0
55.134773597,1751.0
55.184907404,1796.0
55.235041211,1846.0
55.285175018,1724.0
55.335308825,1752.0
55.385442632,1769.0
55.435576439,1747.0
55.485710246,1721.0
55.535844053,1716.0
55.585977860,1753.0
55.636111667,1723.0
55.686245474,1785.0
55.736379281,1736.0
55.786513088,1755.0
55.836646894,1783.0
55.886780701,1727.0
55.936914508,1813.0
55.987048315,1787.0
56.037182122,1764.0
56.087315929,1748.0
56.137449736,1725.0
56.187583543,1772.0
56.237717350,1735.0
56.287851157,1784.0
56.337984964,1816.0
56.388118771,1716.0
56.438252578,1823.0
56.488386385,1748.0
56.538520192,1762.0
56.588653998,1754.0
56.638787805,1799.0
56.688921612,1733.0
56.739055419,1737.0
56.789189226,1815.0
56.839323033,1758.0
56.889456840,1679.0
56.939590647,1797.0
56.989724454,1754.0
57.039858261,1725.0
57.089992068,1860.0
57.140125875,1766.0
57.190259682,1731.0
57.240393489,1758.0
57.290527296,1849.0
57.340661102,1741.0
57.390794909,1726.0
57.440928716,1782.0
57.491062523,1777.0
57.541196330,1749.0
57.591330137,1740.0
57.641463944,1753.0
57.691597751,1835.0
57.741731558,1794.0
57.791865365,1806.0
57.841999172,1775.0
57.892132979,1757.0
57.942266786,1779.0
57.992400593,1762.0
58.042534400,1712.0
58.092668207,1790.0
58.142802013,1794.0
58.192935820,1709.0
58.243069627,1725.0
58.293203434,1712.0
58.343337241,1773.0
58.393471048,1720.0
58.443604855,1791.0
58.493738662,1702.0
58.543872469,1734.0
58.594006276,1781.0
58.644140083,1805.0
58.694273890,1803.0
58.744407697,1794.0
58.794541504,1798.0
58.844675311,1812.0
58.894809117,1779.0
58.944942924,1762.0
58.995076731,1748.0
59.045210538,1758.0
59.095344345,1714.0
59.145478152,1797.0
59.195611959,1765.0
59.245745766,1805.0
59.295879573,1711.0
59.346013380,1753.0
59.396147187,1747.0
59.446280994,1748.0
59.496414801,1793.0
59.546548608,1821.0
59.596682415,1760.0
59.646816221,1745.0
59.696950028,1681.0
59.747083835,1702.0
59.797217642,1717.0
59.847351449,1769.0
59.897485256,1681.0
59.947619063,1825.0
59.997752870,1773.0
60.047886677,1765.0
60.098020484,1749.0
60.148154291,1801.0
60.198288098,1796.0
60.248421905,1793.0
60.298555712,1821.0
60.348689519,1732.0
60.398823325,1724.0
60.448957132,1767.0
60.499090939,1763.0
60.549224746,1752.0
60.599358553,1754.0
60.649492360,1859.0
60.699626167,1801.0
60.749759974,1757.0
60.799893781,1752.0
60.850027588,1812.0
60.900161395,1813.0
60.950295202,1787.0
61.000429009,1759.0
61.050562816,1796.0
61.100696623,1906.0
61.150830429,1855.0
61.200964236,1751.0
61.251098043,1786.0
61.301231850,1777.0
61.351365657,1797.0
61.401499464,1781.0
61.451633271,1776.0
61.501767078,1761.0
61.551900885,1770.0
61.602034692,1739.0
61.652168499,1872.0
61.702302306,1806.0
61.752436113,1801.0
61.802569920,1842.0
61.852703727,1861.0
61.902837533,1787.0
61.952971340,1822.0
62.003105147,1880.0
62.053238954,1847.0
62.103372761,1959.0
62.153506568,1792.0
62.203640375,1764.0
62.253774182,1872.0
62.303907989,1850.0
62.354041796,1801.0
62.404175603,1803.0
62.454309410,1831.0
62.504443217,1881.0
62.554577024,1850.0
62.604710831,1876.0
62.654844638,1944.0
62.704978444,1855.0
62.755112251,1817.0
62.805246058,1867.0
62.855379865,1874.0
62.905513672,1901.0
62.955647479,1858.0
63.005781286,1833.0
63.055915093,1767.0
63.106048900,1829.0
63.156182707,1817.0
63.206316514,1856.0
63.256450321,1957.0
63.306584128,1824.0
63.356717935,1874.0
63.406851742,1830.0
63.456985548,1900.0
63.507119355,1942.0
63.557253162,1924.0
63.607386969,1969.0
63.657520776,1909.0
63.707654583,1963.0
63.757788390,1937.0
63.807922197,1854.0
63.858056004,1761.0
63.908189811,1838.0
63.958323618,1907.0
64.008457425,1932.0
64.058591232,1910.0
64.108725039,1902.0
64.158858846,1928.0
64.208992652,1904.0
64.259126459,1886.0
64.309260266,1933.0
64.359394073,1901.0
64.409527880,1985.0
64.459661687,1924.0
64.509795494,1915.0
64.559929301,1952.0
64.610063108,1933.0
64.660196915,1942.0
64.710330722,1852.0
64.760464529,1905.0
64.810598336,1910.0
64.860732143,1952.0
64.910865950,1979.0
64.960999756,1981.0
65.011133563,1946.0
65.061267370,2041.0
65.111401177,1894.0
65.161534984,1918.0
65.211668791,1956.0
65.261802598,1865.0
65.311936405,1947.0
65.362070212,1865.0
65.412204019,1939.0
65.462337826,1912.0
65.512471633,1895.0
65.562605440,1871.0
65.612739247,2042.0
65.662873054,1982.0
65.713006860,1961.0
65.763140667,1971.0
65.813274474,1894.0
65.863408281,1998.0
65.913542088,2020.0
65.963675895,2023.0
66.013809702,2022.0
66.063943509,1968.0
66.114077316,1913.0
66.164211123,1963.0
66.214344930,1996.0
66.264478737,1947.0
66.314612544,1905.0
66.364746351,2041.0
66.414880158,1899.0
66.465013964,2029.0
66.515147771,1812.0
66.565281578,1940.0
66.615415385,1867.0
66.665549192,2048.0
66.715682999,1979.0
66.765816806,1953.0
66.815950613,2032.0
66.866084420,1981.0
66.916218227,2013.0
66.966352034,1944.0
67.016485841,1930.0
67.066619648,1965.0
67.116753455,2008.0
67.166887262,2021.0
67.217021069,2039.0
67.267154875,1938.0
67.317288682,1987.0
67.367422489,2067.0
67.417556296,1893.0
67.467690103,1982.0
67.517823910,1970.0
67.567957717,1939.0
67.618091524,1933.0
67.668225331,1953.0
67.718359138,1955.0
67.768492945,1956.0
67.818626752,1924.0
67.868760559,1912.0
67.918894366,1971.0
67.969028173,2001.0
68.019161979,1983.0
68.069295786,1982.0
68.119429593,1960.0
68.169563400,2067.0
68.219697207,1958.0
68.269831014,1951.0
68.319964821,2034.0
68.370098628,1941.0
68.420232435,1947.0
68.470366242,2006.0
68.520500049,1962.0
68.570633856,1995.0
68.620767663,1946.0
68.670901470,1933.0
68.721035277,1975.0
68.771169083,1966.0
68.821302890,1964.0
68.871436697,1985.0
68.921570504,1844.0
68.971704311,2004.0
69.021838118,1844.0
69.071971925,2001.0
69.122105732,1919.0
69.172239539,1931.0
69.222373346,1926.0
69.272507153,1960.0
69.322640960,1987.0
69.372774767,1923.0
69.422908574,1897.0
69.473042381,1899.0
69.523176187,1962.0
69.573309994,1944.0
69.623443801,1849.0
69.673577608,1926.0
69.723711415,1946.0
69.773845222,1917.0
69.823979029,1929.0
69.874112836,1878.0
69.924246643,1827.0
69.974380450,1963.0
70.024514257,1998.0
70.074648064,1915.0
70.124781871,1976.0
70.174915678,1893.0
70.225049485,1957.0
70.275183291,1933.0
70.325317098,1843.0
70.375450905,1900.0
70.425584712,1898.0
70.475718519,1840.0
70.525852326,1936.0
70.575986133,1889.0
70.626119940,1995.0
70.676253747,1877.0
70.726387554,1866.0
70.776521361,1840.0
70.826655168,1882.0
70.876788975,1921.0
70.926922782,1849.0
70.977056589,1948.0
71.027190396,1796.0
71.077324202,1857.0
71.127458009,1891.0
71.177591816,1790.0
71.227725623,1873.0
71.277859430,1815.0
71.327993237,1837.0
71.378127044,1895.0
71.428260851,1809.0
71.478394658,1862.0
71.528528465,1824.0
71.578662272,1868.0
71.628796079,1813.0
71.678929886,1782.0
71.729063693,1808.0
71.779197500,1875.0
71.829331306,1880.0
71.879465113,1762.0
71.929598920,1880.0
71.979732727,1813.0
72.029866534,1787.0
72.080000341,1764.0
72.130134148,1901.0
72.180267955,1904.0
72.230401762,1952.0
72.280535569,1807.0
72.330669376,1765.0
72.380803183,1803.0
72.430936990,1801.0
72.481070797,1843.0
72.531204604,1790.0
72.581338410,1815.0
72.631472217,1789.0
72.681606024,1773.0
72.731739831,1770.0
72.781873638,1761.0
72.832007445,1729.0
72.882141252,1712.0
72.932275059,1779.0
72.982408866,1822.0
73.032542673,1826.0
73.082676480,1790.0
73.132810287,1772.0
73.182944094,1799.0
73.233077901,1830.0
73.283211708,1794.0
73.333345514,1846.0
73.383479321,1798.0
73.433613128,1826.0
73.483746935,1710.0
73.533880742,1772.0
73.584014549,1733.0
73.634148356,1799.0
73.684282163,1690.0
73.734415970,1748.0
73.784549777,1810.0
73.834683584,1816.0
73.884817391,1690.0
73.934951198,1730.0
73.985085005,1765.0
74.035218812,1831.0
74.085352618,1802.0
74.135486425,1815.0
74.185620232,1764.0
74.235754039,1739.0
74.285887846,1801.0
74.336021653,1728.0
74.386155460,1741.0
74.436289267,1821.0
74.486423074,1744.0
74.536556881,1750.0
74.586690688,1682.0
74.636824495,1706.0
74.686958302,1741.0
74.737092109,1741.0
74.787225916,1686.0
74.837359722,1715.0
74.887493529,1716.0
74.937627336,1760.0
74.987761143,1700.0
75.037894950,1715.0
75.088028757,1736.0
75.138162564,1729.0
75.188296371,1762.0
75.238430178,1692.0
75.288563985,1875.0
75.338697792,1715.0
75.388831599,1780.0
75.438965406,1760.0
75.489099213,1860.0
75.539233020,1768.0
75.589366827,1819.0
75.639500633,1844.0
75.689634440,1823.0
75.739768247,1925.0
75.789902054,1934.0
75.840035861,1975.0
75.890169668,2033.0
75.940303475,2094.0
75.990437282,2177.0
76.040571089,2337.0
76.090704896,2272.0
76.140838703,2285.0
76.190972510,2276.0
76.241106317,2220.0
76.291240124,2147.0
76.341373931,2012.0
76.391507737,1996.0
76.441641544,1947.0
76.491775351,1749.0
76.541909158,1716.0
76.592042965,1769.0
76.642176772,1694.0
76.692310579,1687.0
76.742444386,1675.0
76.792578193,1731.0
76.842712000,1734.0
76.892845807,1674.0
76.942979614,1619.0
76.993113421,1615.0
77.043247228,1627.0
77.093381035,1631.0
77.143514841,1655.0
77.193648648,1618.0
77.243782455,1654.0
77.293916262,1574.0
77.344050069,1612.0
77.394183876,1569.0
77.444317683,1650.0
77.494451490,1610.0
77.544585297,1546.0
77.594719104,1564.0
77.644852911,1613.0
77.694986718,1555.0
77.745120525,1691.0
77.795254332,1584.0
77.845388139,1600.0
77.895521945,1549.0
77.945655752,1579.0
77.995789559,1563.0
78.045923366,1620.0
78.096057173,1570.0
78.146190980,1618.0
78.196324787,1541.0
78.246458594,1560.0
78.296592401,1556.0
78.346726208,1499.0
78.396860015,1554.0
78.446993822,1594.0
78.497127629,1497.0
78.547261436,1522.0
78.597395243,1501.0
78.647529049,1564.0
78.697662856,1500.0
78.747796663,1531.0
78.797930470,1541.0
78.848064277,1570.0
78.898198084,1514.0
78.948331891,1454.0
78.998465698,1549.0
79.048599505,1480.0
79.098733312,1495.0
79.148867119,1491.0
79.199000926,1606.0
79.249134733,1401.0
79.299268540,1516.0
79.349402347,1544.0
79.399536153,1534.0
79.449669960,1461.0
79.499803767,1527.0
79.549937574,1544.0
79.600071381,1492.0
79.650205188,1449.0
79.700338995,1511.0
79.750472802,1488.0
79.800606609,1530.0
79.850740416,1560.0
79.900874223,1493.0
79.951008030,1516.0
80.001141837,1473.0
80.051275644,1527.0
80.101409451,1533.0
80.151543258,1527.0
80.201677064,1512.0
80.251810871,1484.0
80.301944678,1487.0
80.352078485,1504.0
80.402212292,1495.0
80.452346099,1496.0
80.502479906,1523.0
80.552613713,1531.0
80.602747520,1474.0
80.652881327,1465.0
80.703015134,1521.0
80.753148941,1531.0
80.803282748,1494.0
80.853416555,1370.0
80.903550362,1458.0
80.953684168,1511.0
81.003817975,1415.0
81.053951782,1398.0
81.104085589,1446.0
81.154219396,1491.0
81.204353203,1446.0
81.254487010,1438.0
81.304620817,1415.0
81.354754624,1459.0
81.404888431,1452.0
81.455022238,1412.0
81.505156045,1526.0
81.555289852,1490.0
81.605423659,1388.0
81.655557466,1544.0
81.705691272,1397.0
81.755825079,1478.0
81.805958886,1385.0
81.856092693,1471.0
81.906226500,1408.0
81.956360307,1499.0
82.006494114,1412.0
82.056627921,1442.0
82.106761728,1444.0
82.156895535,1429.0
82.207029342,1480.0
82.257163149,1509.0
82.307296956,1497.0
82.357430763,1419.0
82.407564570,1470.0
82.457698376,1428.0
82.507832183,1407.0
82.557965990,1394.0
82.608099797,1409.0
82.658233604,1418.0
82.708367411,1427.0
82.758501218,1373.0
82.808635025,1403.0
82.858768832,1435.0
82.908902639,1436.0
82.959036446,1454.0
83.009170253,1508.0
83.059304060,1373.0
83.109437867,1513.0
83.159571674,1489.0
83.209705480,1384.0
83.259839287,1496.0
83.309973094,1383.0
83.360106901,1444.0
83.410240708,1396.0
83.460374515,1380.0
83.510508322,1419.0
83.560642129,1501.0
83.610775936,1476.0
83.660909743,1413.0
83.711043550,1446.0
83.761177357,1422.0
83.811311164,1443.0
83.861444971,1414.0
83.911578778,1402.0
83.961712584,1376.0
84.011846391,1376.0
84.061980198,1460.0
84.112114005,1413.0
84.162247812,1406.0
84.212381619,1384.0
84.262515426,1318.0
84.312649233,1369.0
84.362783040,1362.0
84.412916847,1385.0
84.463050654,1341.0
84.513184461,1468.0
84.563318268,1341.0
84.613452075,1400.0
84.663585882,1435.0
84.713719689,1484.0
84.763853495,1374.0
84.813987302,1440.0
84.864121109,1424.0
84.914254916,1419.0
84.964388723,1324.0
85.014522530,1458.0
85.064656337,1381.0
85.114790144,1334.0
85.164923951,1380.0
85.215057758,1346.0
85.265191565,1363.0
85.315325372,1429.0
85.365459179,1422.0
85.415592986,1364.0
85.465726793,1413.0
85.515860599,1408.0
85.565994406,1362.0
85.616128213,1335.0
85.666262020,1393.0
85.716395827,1383.0
85.766529634,1403.0
85.816663441,1395.0
85.866797248,1386.0
85.916931055,1382.0
85.967064862,1396.0
86.017198669,1348.0
86.067332476,1394.0
86.117466283,1366.0
86.167600090,1419.0
86.217733897,1428.0
86.267867703,1343.0
86.318001510,1330.0
86.368135317,1363.0
86.418269124,1434.0
86.468402931,1393.0
86.518536738,1341.0
86.568670545,1410.0
86.618804352,1369.0
86.668938159,1320.0
86.719071966,1405.0
86.769205773,1388.0
86.819339580,1382.0
86.869473387,1358.0
86.919607194,1446.0
86.969741001,1357.0
87.019874807,1378.0
87.070008614,1371.0
87.120142421,1377.0
87.170276228,1425.0
87.220410035,1359.0
87.270543842,1391.0
87.320677649,1390.0
87.370811456,1349.0
87.420945263,1367.0
87.471079070,1372.0
87.521212877,1291.0
87.571346684,1348.0
87.621480491,1414.0
87.671614298,1368.0
87.721748105,1320.0
87.771881911,1359.0
87.822015718,1310.0
87.872149525,1342.0
87.922283332,1344.0
87.972417139,1405.0
88.022550946,1348.0
88.072684753,1357.0
88.122818560,1281.0
88.172952367,1301.0
88.223086174,1370.0
88.273219981,1378.0
88.323353788,1306.0
88.373487595,1383.0
88.423621402,1342.0
88.473755209,1343.0
88.523889016,1361.0
88.574022822,1384.0
88.624156629,1328.0
88.674290436,1340.0
88.724424243,1294.0
88.774558050,1380.0
88.824691857,1335.0
88.874825664,1363.0
88.924959471,1309.0
88.975093278,1359.0
89.025227085,1358.0
89.075360892,1335.0
89.125494699,1269.0
89.175628506,1335.0
89.225762313,1353.0
89.275896120,1397.0
89.326029926,1325.0
89.376163733,1328.0
89.426297540,1299.0
89.476431347,1342.0
89.526565154,1305.0
89.576698961,1339.0
89.626832768,1298.0
89.676966575,1369.0
89.727100382,1350.0
89.777234189,1295.0
89.827367996,1329.0
89.877501803,1290.0
89.927635610,1434.0
89.977769417,1382.0
90.027903224,1294.0
90.078037030,1332.0
90.128170837,1328.0
90.178304644,1345.0
90.228438451,1349.0
90.278572258,1360.0
90.328706065,1337.0
90.378839872,1350.0
90.428973679,1384.0
90.479107486,1367.0
90.529241293,1367.0
90.579375100,1288.0
90.629508907,1394.0
90.679642714,1371.0
90.729776521,1370.0
90.779910328,1367.0
90.830044134,1374.0
90.880177941,1346.0
90.930311748,1299.0
90.980445555,1373.0
91.030579362,1355.0
91.080713169,1357.0
91.130846976,1348.0
91.180980783,1318.0
91.231114590,1325.0
91.281248397,1348.0
91.331382204,1361.0
91.381516011,1393.0
91.431649818,1406.0
91.481783625,1399.0
91.531917432,1349.0
91.582051238,1354.0
91.632185045,1422.0
91.682318852,1448.0
91.732452659,1420.0
91.782586466,1404.0
91.832720273,1449.0
91.882854080,1454.0
91.932987887,1409.0
91.983121694,1472.0
92.033255501,1570.0
92.083389308,1492.0
92.133523115,1515.0
92.183656922,1591.0
92.233790729,1597.0
92.283924536,1657.0
92.334058342,1697.0
92.384192149,1731.0
92.434325956,1828.0
92.484459763,1835.0
92.534593570,1849.0
92.584727377,1873.0
92.634861184,1827.0
92.684994991,1802.0
92.735128798,1734.0
92.785262605,1709.0
92.835396412,1559.0
92.885530219,1594.0
92.935664026,1673.0
92.985797833,1469.0
93.035931640,1412.0
93.086065447,1487.0
93.136199253,1430.0
93.186333060,1389.0
93.236466867,1308.0
93.286600674,1321.0
93.336734481,1367.0
93.386868288,1335.0
93.437002095,1325.0
93.487135902,1297.0
93.537269709,1313.0
93.587403516,1360.0
93.637537323,1292.0
93.687671130,1350.0
93.737804937,1259.0
93.787938744,1285.0
93.838072551,1354.0
93.888206357,1321.0
93.938340164,1284.0
93.988473971,1301.0
94.038607778,1281.0
94.088741585,1291.0
94.138875392,1279.0
94.189009199,1288.0
94.239143006,1302.0
94.289276813,1344.0
94.339410620,1302.0
94.389544427,1382.0
94.439678234,1349.0
94.489812041,1241.0
94.539945848,1293.0
94.590079655,1252.0
94.640213461,1353.0
94.690347268,1341.0
94.740481075,1284.0
94.790614882,1308.0
94.840748689,1353.0
94.890882496,1268.0
94.941016303,1283.0
94.991150110,1250.0