File: OriginPro/XRD from Panalytical X'Pert PRO/In-Situ/FicheirosXRD_Insitu/NiNws_550°C.csv
[Measurement conditions]
Sample identification,
Comment - 1,"finito"
Comment - 2,"Configuration=MRI TC-Basic Stage, Owner=User-1, Creation date=26-10-2009 9:18:44"
Comment - 3,"Goniometer=PW3050/60 (Theta/Theta); Minimum step size 2Theta:0.001; Minimum step size Omega:0.001"
Comment - 4,"Sample stage=MRI TC-Basic (PtRh heat strip)"
Comment - 5,"Diffractometer system=XPERT-PRO"
Comment - 6,"Measurement program=FS-L, Owner=joana, Creation date=25-11-2014 17:28:08"
Anode material,Cu
K-Alpha1 wavelength,1.5405980
K-Alpha2 wavelength,1.5444260
Ratio K-Alpha2/K-Alpha1,0.500
Divergence slit,Fixed,0.76mm
Monochromator used,NO
Generator voltage, 45
Tube current, 40
File date and time,16-Dez-2017 04:50
Unit cell,
h k l, 0 0 0
Temperature [K],823
Scan axis,Gonio
Scan range,24.995999996,94.999505744
Scan step size,0.0167113
No. of points, 4189
Scan type,CONTINUOUS
Time per step,118.110
[Scan points]
Angle,Intensity
25.004355630,2174.0
25.054489437,2191.0
25.104623244,2169.0
25.154757051,2208.0
25.204890858,2202.0
25.255024665,2234.0
25.305158472,2199.0
25.355292279,2279.0
25.405426085,2174.0
25.455559892,2179.0
25.505693699,2180.0
25.555827506,2215.0
25.605961313,2235.0
25.656095120,2202.0
25.706228927,2210.0
25.756362734,2212.0
25.806496541,2153.0
25.856630348,2083.0
25.906764155,2176.0
25.956897962,2217.0
26.007031769,2251.0
26.057165576,2259.0
26.107299383,2189.0
26.157433189,2194.0
26.207566996,2185.0
26.257700803,2154.0
26.307834610,2149.0
26.357968417,2206.0
26.408102224,2112.0
26.458236031,2231.0
26.508369838,2227.0
26.558503645,2181.0
26.608637452,2118.0
26.658771259,2169.0
26.708905066,2150.0
26.759038873,2179.0
26.809172680,2088.0
26.859306487,2163.0
26.909440293,2176.0
26.959574100,2092.0
27.009707907,2152.0
27.059841714,2158.0
27.109975521,2177.0
27.160109328,2200.0
27.210243135,2222.0
27.260376942,2180.0
27.310510749,2116.0
27.360644556,2176.0
27.410778363,2143.0
27.460912170,2191.0
27.511045977,2160.0
27.561179784,2119.0
27.611313591,2111.0
27.661447398,2075.0
27.711581204,2130.0
27.761715011,2200.0
27.811848818,2158.0
27.861982625,2146.0
27.912116432,2159.0
27.962250239,2151.0
28.012384046,2277.0
28.062517853,2178.0
28.112651660,2198.0
28.162785467,2218.0
28.212919274,2297.0
28.263053081,2411.0
28.313186888,2407.0
28.363320695,2721.0
28.413454502,2232.0
28.463588308,2216.0
28.513722115,2162.0
28.563855922,2253.0
28.613989729,2193.0
28.664123536,2267.0
28.714257343,2175.0
28.764391150,2183.0
28.814524957,2215.0
28.864658764,2221.0
28.914792571,2232.0
28.964926378,2253.0
29.015060185,2210.0
29.065193992,2172.0
29.115327799,2223.0
29.165461606,2113.0
29.215595412,2165.0
29.265729219,2127.0
29.315863026,2118.0
29.365996833,2174.0
29.416130640,2162.0
29.466264447,2174.0
29.516398254,2193.0
29.566532061,2169.0
29.616665868,2174.0
29.666799675,2245.0
29.716933482,2208.0
29.767067289,2259.0
29.817201096,2178.0
29.867334903,2166.0
29.917468710,2136.0
29.967602516,2171.0
30.017736323,2092.0
30.067870130,2168.0
30.118003937,2244.0
30.168137744,2139.0
30.218271551,2196.0
30.268405358,2198.0
30.318539165,2232.0
30.368672972,2280.0
30.418806779,2186.0
30.468940586,2094.0
30.519074393,2141.0
30.569208200,2147.0
30.619342007,2163.0
30.669475814,2166.0
30.719609620,2180.0
30.769743427,2065.0
30.819877234,2071.0
30.870011041,2036.0
30.920144848,2180.0
30.970278655,2129.0
31.020412462,2154.0
31.070546269,2121.0
31.120680076,2138.0
31.170813883,2205.0
31.220947690,2135.0
31.271081497,2131.0
31.321215304,2215.0
31.371349111,2124.0
31.421482918,2157.0
31.471616724,2045.0
31.521750531,2125.0
31.571884338,2136.0
31.622018145,2079.0
31.672151952,2074.0
31.722285759,2211.0
31.772419566,2051.0
31.822553373,2088.0
31.872687180,2152.0
31.922820987,2164.0
31.972954794,2216.0
32.023088601,2085.0
32.073222408,2146.0
32.123356215,2171.0
32.173490022,2078.0
32.223623829,2230.0
32.273757635,2057.0
32.323891442,1997.0
32.374025249,2164.0
32.424159056,2149.0
32.474292863,2131.0
32.524426670,2152.0
32.574560477,2083.0
32.624694284,2175.0
32.674828091,2121.0
32.724961898,2140.0
32.775095705,2059.0
32.825229512,2119.0
32.875363319,2073.0
32.925497126,2186.0
32.975630933,2080.0
33.025764739,2181.0
33.075898546,2094.0
33.126032353,2087.0
33.176166160,2098.0
33.226299967,2097.0
33.276433774,2188.0
33.326567581,2205.0
33.376701388,2104.0
33.426835195,2136.0
33.476969002,2151.0
33.527102809,2062.0
33.577236616,2043.0
33.627370423,2093.0
33.677504230,2186.0
33.727638037,2155.0
33.777771843,2093.0
33.827905650,2106.0
33.878039457,2152.0
33.928173264,2140.0
33.978307071,2142.0
34.028440878,2012.0
34.078574685,2072.0
34.128708492,2032.0
34.178842299,2040.0
34.228976106,2148.0
34.279109913,2029.0
34.329243720,2117.0
34.379377527,2209.0
34.429511334,2135.0
34.479645141,2094.0
34.529778947,2126.0
34.579912754,2116.0
34.630046561,2082.0
34.680180368,2059.0
34.730314175,2213.0
34.780447982,2203.0
34.830581789,2178.0
34.880715596,2160.0
34.930849403,2126.0
34.980983210,2242.0
35.031117017,2094.0
35.081250824,2106.0
35.131384631,2052.0
35.181518438,2135.0
35.231652245,2175.0
35.281786051,2223.0
35.331919858,2257.0
35.382053665,2277.0
35.432187472,2325.0
35.482321279,2302.0
35.532455086,2352.0
35.582588893,2227.0
35.632722700,2318.0
35.682856507,2220.0
35.732990314,2235.0
35.783124121,2179.0
35.833257928,2275.0
35.883391735,2200.0
35.933525542,2250.0
35.983659349,2155.0
36.033793156,2178.0
36.083926962,2137.0
36.134060769,2225.0
36.184194576,2243.0
36.234328383,2180.0
36.284462190,2291.0
36.334595997,2240.0
36.384729804,2255.0
36.434863611,2293.0
36.484997418,2440.0
36.535131225,2411.0
36.585265032,2524.0
36.635398839,2727.0
36.685532646,2972.0
36.735666453,3116.0
36.785800260,3549.0
36.835934066,3886.0
36.886067873,4486.0
36.936201680,4852.0
36.986335487,5174.0
37.036469294,5156.0
37.086603101,4955.0
37.136736908,4478.0
37.186870715,3906.0
37.237004522,3391.0
37.287138329,3130.0
37.337272136,2852.0
37.387405943,2633.0
37.437539750,2502.0
37.487673557,2416.0
37.537807364,2328.0
37.587941170,2276.0
37.638074977,2117.0
37.688208784,2139.0
37.738342591,2246.0
37.788476398,2162.0
37.838610205,2062.0
37.888744012,2177.0
37.938877819,2101.0
37.989011626,2163.0
38.039145433,2160.0
38.089279240,2068.0
38.139413047,2040.0
38.189546854,1939.0
38.239680661,2006.0
38.289814468,2004.0
38.339948274,2072.0
38.390082081,1978.0
38.440215888,2019.0
38.490349695,2063.0
38.540483502,2068.0
38.590617309,2021.0
38.640751116,2083.0
38.690884923,2160.0
38.741018730,1990.0
38.791152537,2017.0
38.841286344,2012.0
38.891420151,2094.0
38.941553958,2067.0
38.991687765,2054.0
39.041821572,1964.0
39.091955378,1979.0
39.142089185,2062.0
39.192222992,2025.0
39.242356799,1971.0
39.292490606,2022.0
39.342624413,1983.0
39.392758220,1982.0
39.442892027,2061.0
39.493025834,2125.0
39.543159641,2242.0
39.593293448,2315.0
39.643427255,2531.0
39.693561062,2262.0
39.743694869,2311.0
39.793828676,2058.0
39.843962482,2140.0
39.894096289,2091.0
39.944230096,2101.0
39.994363903,2150.0
40.044497710,2062.0
40.094631517,2063.0
40.144765324,1991.0
40.194899131,2091.0
40.245032938,2013.0
40.295166745,1928.0
40.345300552,2040.0
40.395434359,1961.0
40.445568166,1937.0
40.495701973,2017.0
40.545835780,1930.0
40.595969587,1909.0
40.646103393,1933.0
40.696237200,1976.0
40.746371007,1964.0
40.796504814,2020.0
40.846638621,1953.0
40.896772428,2032.0
40.946906235,2010.0
40.997040042,1971.0
41.047173849,2055.0
41.097307656,2007.0
41.147441463,2029.0
41.197575270,2056.0
41.247709077,1980.0
41.297842884,2003.0
41.347976691,1945.0
41.398110497,1948.0
41.448244304,1956.0
41.498378111,1989.0
41.548511918,2042.0
41.598645725,2011.0
41.648779532,2090.0
41.698913339,1982.0
41.749047146,1997.0
41.799180953,1989.0
41.849314760,2038.0
41.899448567,2035.0
41.949582374,1992.0
41.999716181,2104.0
42.049849988,2131.0
42.099983795,2168.0
42.150117601,2117.0
42.200251408,2095.0
42.250385215,2184.0
42.300519022,2196.0
42.350652829,2257.0
42.400786636,2383.0
42.450920443,2503.0
42.501054250,2478.0
42.551188057,2695.0
42.601321864,2814.0
42.651455671,2983.0
42.701589478,3423.0
42.751723285,3875.0
42.801857092,4283.0
42.851990899,4979.0
42.902124705,5523.0
42.952258512,5949.0
43.002392319,6217.0
43.052526126,6033.0
43.102659933,5700.0
43.152793740,4894.0
43.202927547,4393.0
43.253061354,3929.0
43.303195161,3362.0
43.353328968,3116.0
43.403462775,2811.0
43.453596582,2691.0
43.503730389,2465.0
43.553864196,2338.0
43.603998003,2266.0
43.654131809,2309.0
43.704265616,2195.0
43.754399423,2086.0
43.804533230,2138.0
43.854667037,2117.0
43.904800844,2163.0
43.954934651,2143.0
44.005068458,2133.0
44.055202265,2116.0
44.105336072,2083.0
44.155469879,2055.0
44.205603686,2118.0
44.255737493,2123.0
44.305871300,2140.0
44.356005107,2048.0
44.406138913,1996.0
44.456272720,1926.0
44.506406527,1955.0
44.556540334,1909.0
44.606674141,1926.0
44.656807948,1934.0
44.706941755,1965.0
44.757075562,1856.0
44.807209369,1968.0
44.857343176,1962.0
44.907476983,1934.0
44.957610790,1980.0
45.007744597,1960.0
45.057878404,1950.0
45.108012211,1931.0
45.158146018,2053.0
45.208279824,2006.0
45.258413631,2075.0
45.308547438,2016.0
45.358681245,2026.0
45.408815052,2017.0
45.458948859,2053.0
45.509082666,2025.0
45.559216473,1955.0
45.609350280,1944.0
45.659484087,1984.0
45.709617894,1978.0
45.759751701,1990.0
45.809885508,2076.0
45.860019315,2243.0
45.910153122,2382.0
45.960286928,2804.0
46.010420735,3280.0
46.060554542,5109.0
46.110688349,6909.0
46.160822156,3243.0
46.210955963,5123.0
46.261089770,3070.0
46.311223577,2768.0
46.361357384,3080.0
46.411491191,3286.0
46.461624998,3333.0
46.511758805,2960.0
46.561892612,2780.0
46.612026419,2335.0
46.662160226,2156.0
46.712294032,2080.0
46.762427839,1962.0
46.812561646,1879.0
46.862695453,1936.0
46.912829260,1948.0
46.962963067,1920.0
47.013096874,1879.0
47.063230681,1808.0
47.113364488,1952.0
47.163498295,1803.0
47.213632102,1874.0
47.263765909,1854.0
47.313899716,1891.0
47.364033523,1787.0
47.414167330,1868.0
47.464301136,1888.0
47.514434943,1874.0
47.564568750,1859.0
47.614702557,1851.0
47.664836364,1862.0
47.714970171,1909.0
47.765103978,1814.0
47.815237785,1830.0
47.865371592,1912.0
47.915505399,1786.0
47.965639206,1850.0
48.015773013,1824.0
48.065906820,1852.0
48.116040627,1779.0
48.166174434,1885.0
48.216308240,1834.0
48.266442047,1873.0
48.316575854,1805.0
48.366709661,1796.0
48.416843468,1798.0
48.466977275,1817.0
48.517111082,1795.0
48.567244889,1816.0
48.617378696,1849.0
48.667512503,1856.0
48.717646310,1842.0
48.767780117,1763.0
48.817913924,1850.0
48.868047731,1858.0
48.918181538,1829.0
48.968315344,1749.0
49.018449151,1851.0
49.068582958,1909.0
49.118716765,1754.0
49.168850572,1879.0
49.218984379,1849.0
49.269118186,1974.0
49.319251993,1930.0
49.369385800,1997.0
49.419519607,1886.0
49.469653414,1930.0
49.519787221,1890.0
49.569921028,1850.0
49.620054835,1841.0
49.670188642,1907.0
49.720322449,1751.0
49.770456255,1822.0
49.820590062,1837.0
49.870723869,1743.0
49.920857676,1879.0
49.970991483,1776.0
50.021125290,1830.0
50.071259097,1804.0
50.121392904,1917.0
50.171526711,1942.0
50.221660518,2070.0
50.271794325,2094.0
50.321928132,2177.0
50.372061939,2168.0
50.422195746,2160.0
50.472329553,2002.0
50.522463359,1990.0
50.572597166,1802.0
50.622730973,1788.0
50.672864780,1916.0
50.722998587,1778.0
50.773132394,1828.0
50.823266201,1795.0
50.873400008,1704.0
50.923533815,1733.0
50.973667622,1761.0
51.023801429,1713.0
51.073935236,1801.0
51.124069043,1822.0
51.174202850,1788.0
51.224336657,1740.0
51.274470463,1850.0
51.324604270,1766.0
51.374738077,1729.0
51.424871884,1775.0
51.475005691,1753.0
51.525139498,1828.0
51.575273305,1679.0
51.625407112,1860.0
51.675540919,1806.0
51.725674726,1729.0
51.775808533,1775.0
51.825942340,1745.0
51.876076147,1819.0
51.926209954,1787.0
51.976343761,1842.0
52.026477567,1639.0
52.076611374,1705.0
52.126745181,1692.0
52.176878988,1826.0
52.227012795,1728.0
52.277146602,1791.0
52.327280409,1785.0
52.377414216,1697.0
52.427548023,1777.0
52.477681830,1763.0
52.527815637,1809.0
52.577949444,1801.0
52.628083251,1774.0
52.678217058,1765.0
52.728350865,1790.0
52.778484671,1729.0
52.828618478,1884.0
52.878752285,1695.0
52.928886092,1706.0
52.979019899,1669.0
53.029153706,1771.0
53.079287513,1718.0
53.129421320,1761.0
53.179555127,1732.0
53.229688934,1738.0
53.279822741,1747.0
53.329956548,1728.0
53.380090355,1827.0
53.430224162,1740.0
53.480357969,1813.0
53.530491776,1893.0
53.580625582,1736.0
53.630759389,1769.0
53.680893196,1719.0
53.731027003,1879.0
53.781160810,1764.0
53.831294617,1778.0
53.881428424,1845.0
53.931562231,1879.0
53.981696038,1753.0
54.031829845,1790.0
54.081963652,1726.0
54.132097459,1741.0
54.182231266,1762.0
54.232365073,1765.0
54.282498880,1733.0
54.332632686,1763.0
54.382766493,1762.0
54.432900300,1773.0
54.483034107,1682.0
54.533167914,1806.0
54.583301721,1810.0
54.633435528,1737.0
54.683569335,1694.0
54.733703142,1724.0
54.783836949,1802.0
54.833970756,1864.0
54.884104563,1782.0
54.934238370,1773.0
54.984372177,1783.0
55.034505984,1780.0
55.084639790,1770.0
55.134773597,1796.0
55.184907404,1714.0
55.235041211,1782.0
55.285175018,1848.0
55.335308825,1775.0
55.385442632,1799.0
55.435576439,1754.0
55.485710246,1705.0
55.535844053,1766.0
55.585977860,1726.0
55.636111667,1759.0
55.686245474,1782.0
55.736379281,1836.0
55.786513088,1841.0
55.836646894,1795.0
55.886780701,1806.0
55.936914508,1734.0
55.987048315,1684.0
56.037182122,1807.0
56.087315929,1732.0
56.137449736,1797.0
56.187583543,1789.0
56.237717350,1851.0
56.287851157,1825.0
56.337984964,1806.0
56.388118771,1770.0
56.438252578,1815.0
56.488386385,1780.0
56.538520192,1812.0
56.588653998,1794.0
56.638787805,1901.0
56.688921612,1864.0
56.739055419,1762.0
56.789189226,1804.0
56.839323033,1843.0
56.889456840,1820.0
56.939590647,1817.0
56.989724454,1797.0
57.039858261,1719.0
57.089992068,1690.0
57.140125875,1828.0
57.190259682,1812.0
57.240393489,1791.0
57.290527296,1764.0
57.340661102,1819.0
57.390794909,1869.0
57.440928716,1829.0
57.491062523,1726.0
57.541196330,1812.0
57.591330137,1803.0
57.641463944,1820.0
57.691597751,1749.0
57.741731558,1764.0
57.791865365,1766.0
57.841999172,1910.0
57.892132979,1790.0
57.942266786,1718.0
57.992400593,1690.0
58.042534400,1785.0
58.092668207,1742.0
58.142802013,1804.0
58.192935820,1772.0
58.243069627,1809.0
58.293203434,1946.0
58.343337241,1886.0
58.393471048,1834.0
58.443604855,1744.0
58.493738662,1839.0
58.543872469,1847.0
58.594006276,1810.0
58.644140083,1825.0
58.694273890,1758.0
58.744407697,1820.0
58.794541504,1814.0
58.844675311,1891.0
58.894809117,1805.0
58.944942924,1833.0
58.995076731,1772.0
59.045210538,1796.0
59.095344345,1844.0
59.145478152,1853.0
59.195611959,1831.0
59.245745766,1955.0
59.295879573,1829.0
59.346013380,1817.0
59.396147187,1871.0
59.446280994,1815.0
59.496414801,1870.0
59.546548608,1895.0
59.596682415,1839.0
59.646816221,1839.0
59.696950028,1816.0
59.747083835,1848.0
59.797217642,1937.0
59.847351449,1878.0
59.897485256,1888.0
59.947619063,1883.0
59.997752870,1877.0
60.047886677,1916.0
60.098020484,1912.0
60.148154291,1906.0
60.198288098,1945.0
60.248421905,1915.0
60.298555712,1857.0
60.348689519,1801.0
60.398823325,1922.0
60.448957132,1890.0
60.499090939,1982.0
60.549224746,1903.0
60.599358553,1945.0
60.649492360,1917.0
60.699626167,1901.0
60.749759974,1942.0
60.799893781,1953.0
60.850027588,1971.0
60.900161395,1903.0
60.950295202,1931.0
61.000429009,1936.0
61.050562816,1960.0
61.100696623,2020.0
61.150830429,1895.0
61.200964236,2002.0
61.251098043,1979.0
61.301231850,2039.0
61.351365657,2046.0
61.401499464,1873.0
61.451633271,1997.0
61.501767078,1932.0
61.551900885,2029.0
61.602034692,2093.0
61.652168499,1978.0
61.702302306,2096.0
61.752436113,2063.0
61.802569920,2206.0
61.852703727,2196.0
61.902837533,2329.0
61.952971340,2365.0
62.003105147,2408.0
62.053238954,2484.0
62.103372761,2583.0
62.153506568,2730.0
62.203640375,2886.0
62.253774182,3078.0
62.303907989,3328.0
62.354041796,3486.0
62.404175603,3390.0
62.454309410,3324.0
62.504443217,3343.0
62.554577024,3166.0
62.604710831,3128.0
62.654844638,2957.0
62.704978444,2865.0
62.755112251,2677.0
62.805246058,2502.0
62.855379865,2471.0
62.905513672,2406.0
62.955647479,2296.0
63.005781286,2314.0
63.055915093,2178.0
63.106048900,2260.0
63.156182707,2228.0
63.206316514,2237.0
63.256450321,2197.0
63.306584128,2120.0
63.356717935,2100.0
63.406851742,2129.0
63.456985548,2067.0
63.507119355,2093.0
63.557253162,2096.0
63.607386969,2114.0
63.657520776,2194.0
63.707654583,2172.0
63.757788390,2130.0
63.807922197,2163.0
63.858056004,2128.0
63.908189811,2147.0
63.958323618,2208.0
64.008457425,2156.0
64.058591232,2105.0
64.108725039,2185.0
64.158858846,2197.0
64.208992652,2260.0
64.259126459,2175.0
64.309260266,2221.0
64.359394073,2163.0
64.409527880,2129.0
64.459661687,2246.0
64.509795494,2117.0
64.559929301,2183.0
64.610063108,2095.0
64.660196915,2301.0
64.710330722,2168.0
64.760464529,2156.0
64.810598336,2158.0
64.860732143,2196.0
64.910865950,2300.0
64.960999756,2227.0
65.011133563,2202.0
65.061267370,2229.0
65.111401177,2142.0
65.161534984,2240.0
65.211668791,2206.0
65.261802598,2216.0
65.311936405,2230.0
65.362070212,2121.0
65.412204019,2301.0
65.462337826,2225.0
65.512471633,2304.0
65.562605440,2260.0
65.612739247,2363.0
65.662873054,2258.0
65.713006860,2267.0
65.763140667,2211.0
65.813274474,2300.0
65.863408281,2268.0
65.913542088,2289.0
65.963675895,2327.0
66.013809702,2317.0
66.063943509,2303.0
66.114077316,2314.0
66.164211123,2271.0
66.214344930,2214.0
66.264478737,2219.0
66.314612544,2302.0
66.364746351,2204.0
66.414880158,2370.0
66.465013964,2284.0
66.515147771,2352.0
66.565281578,2341.0
66.615415385,2322.0
66.665549192,2221.0
66.715682999,2259.0
66.765816806,2259.0
66.815950613,2278.0
66.866084420,2305.0
66.916218227,2286.0
66.966352034,2284.0
67.016485841,2181.0
67.066619648,2307.0
67.116753455,2312.0
67.166887262,2347.0
67.217021069,2303.0
67.267154875,2285.0
67.317288682,2276.0
67.367422489,2210.0
67.417556296,2263.0
67.467690103,2309.0
67.517823910,2284.0
67.567957717,2310.0
67.618091524,2258.0
67.668225331,2310.0
67.718359138,2384.0
67.768492945,2414.0
67.818626752,2367.0
67.868760559,2365.0
67.918894366,2302.0
67.969028173,2354.0
68.019161979,2325.0
68.069295786,2270.0
68.119429593,2248.0
68.169563400,2240.0
68.219697207,2311.0
68.269831014,2338.0
68.319964821,2309.0
68.370098628,2255.0
68.420232435,2328.0
68.470366242,2271.0
68.520500049,2318.0
68.570633856,2218.0
68.620767663,2221.0
68.670901470,2243.0
68.721035277,2304.0
68.771169083,2266.0
68.821302890,2309.0
68.871436697,2307.0
68.921570504,2302.0
68.971704311,2213.0
69.021838118,2296.0
69.071971925,2177.0
69.122105732,2313.0
69.172239539,2254.0
69.222373346,2243.0
69.272507153,2282.0
69.322640960,2210.0
69.372774767,2220.0
69.422908574,2237.0
69.473042381,2262.0
69.523176187,2321.0
69.573309994,2296.0
69.623443801,2280.0
69.673577608,2218.0
69.723711415,2184.0
69.773845222,2211.0
69.823979029,2269.0
69.874112836,2270.0
69.924246643,2237.0
69.974380450,2252.0
70.024514257,2303.0
70.074648064,2215.0
70.124781871,2172.0
70.174915678,2142.0
70.225049485,2238.0
70.275183291,2296.0
70.325317098,2240.0
70.375450905,2103.0
70.425584712,2195.0
70.475718519,2181.0
70.525852326,2128.0
70.575986133,2191.0
70.626119940,2266.0
70.676253747,2177.0
70.726387554,2162.0
70.776521361,2238.0
70.826655168,2090.0
70.876788975,2215.0
70.926922782,2207.0
70.977056589,2137.0
71.027190396,2277.0
71.077324202,2216.0
71.127458009,2187.0
71.177591816,2139.0
71.227725623,2115.0
71.277859430,2193.0
71.327993237,2107.0
71.378127044,2107.0
71.428260851,2115.0
71.478394658,2067.0
71.528528465,2126.0
71.578662272,2147.0
71.628796079,2126.0
71.678929886,2152.0
71.729063693,2167.0
71.779197500,2120.0
71.829331306,2179.0
71.879465113,2120.0
71.929598920,2133.0
71.979732727,2237.0
72.029866534,2033.0
72.080000341,2155.0
72.130134148,2156.0
72.180267955,2065.0
72.230401762,2135.0
72.280535569,2110.0
72.330669376,2075.0
72.380803183,2083.0
72.430936990,2048.0
72.481070797,1964.0
72.531204604,2109.0
72.581338410,2099.0
72.631472217,1978.0
72.681606024,2113.0
72.731739831,2036.0
72.781873638,2107.0
72.832007445,2060.0
72.882141252,2145.0
72.932275059,2139.0
72.982408866,2078.0
73.032542673,2039.0
73.082676480,1952.0
73.132810287,2097.0
73.182944094,1919.0
73.233077901,1928.0
73.283211708,1966.0
73.333345514,2022.0
73.383479321,2033.0
73.433613128,2016.0
73.483746935,1979.0
73.533880742,1959.0
73.584014549,1976.0
73.634148356,1971.0
73.684282163,2030.0
73.734415970,1983.0
73.784549777,1995.0
73.834683584,1982.0
73.884817391,2092.0
73.934951198,1979.0
73.985085005,1961.0
74.035218812,1970.0
74.085352618,2017.0
74.135486425,2066.0
74.185620232,1977.0
74.235754039,2039.0
74.285887846,2004.0
74.336021653,2070.0
74.386155460,2089.0
74.436289267,2045.0
74.486423074,2037.0
74.536556881,2062.0
74.586690688,2143.0
74.636824495,2114.0
74.686958302,2234.0
74.737092109,2249.0
74.787225916,2304.0
74.837359722,2206.0
74.887493529,2290.0
74.937627336,2227.0
74.987761143,2244.0
75.037894950,2186.0
75.088028757,2124.0
75.138162564,2147.0
75.188296371,2013.0
75.238430178,2000.0
75.288563985,1988.0
75.338697792,2022.0
75.388831599,1907.0
75.438965406,1913.0
75.489099213,1937.0
75.539233020,1959.0
75.589366827,1861.0
75.639500633,1833.0
75.689634440,1835.0
75.739768247,1834.0
75.789902054,1850.0
75.840035861,1820.0
75.890169668,1911.0
75.940303475,1815.0
75.990437282,1862.0
76.040571089,1791.0
76.090704896,1830.0
76.140838703,1794.0
76.190972510,1793.0
76.241106317,1865.0
76.291240124,1841.0
76.341373931,1814.0
76.391507737,1849.0
76.441641544,1737.0
76.491775351,1806.0
76.541909158,1728.0
76.592042965,1744.0
76.642176772,1758.0
76.692310579,1784.0
76.742444386,1767.0
76.792578193,1795.0
76.842712000,1734.0
76.892845807,1833.0
76.942979614,1780.0
76.993113421,1717.0
77.043247228,1761.0
77.093381035,1725.0
77.143514841,1753.0
77.193648648,1646.0
77.243782455,1730.0
77.293916262,1783.0
77.344050069,1703.0
77.394183876,1713.0
77.444317683,1715.0
77.494451490,1725.0
77.544585297,1714.0
77.594719104,1673.0
77.644852911,1640.0
77.694986718,1675.0
77.745120525,1663.0
77.795254332,1696.0
77.845388139,1747.0
77.895521945,1701.0
77.945655752,1732.0
77.995789559,1678.0
78.045923366,1766.0
78.096057173,1698.0
78.146190980,1759.0
78.196324787,1826.0
78.246458594,1735.0
78.296592401,1725.0
78.346726208,1772.0
78.396860015,1825.0
78.446993822,1792.0
78.497127629,1828.0
78.547261436,1848.0
78.597395243,1763.0
78.647529049,1908.0
78.697662856,1941.0
78.747796663,1942.0
78.797930470,1948.0
78.848064277,1828.0
78.898198084,1882.0
78.948331891,1804.0
78.998465698,1834.0
79.048599505,1774.0
79.098733312,1818.0
79.148867119,1776.0
79.199000926,1713.0
79.249134733,1702.0
79.299268540,1711.0
79.349402347,1719.0
79.399536153,1618.0
79.449669960,1669.0
79.499803767,1755.0
79.549937574,1636.0
79.600071381,1638.0
79.650205188,1676.0
79.700338995,1638.0
79.750472802,1680.0
79.800606609,1607.0
79.850740416,1589.0
79.900874223,1689.0
79.951008030,1688.0
80.001141837,1590.0
80.051275644,1638.0
80.101409451,1618.0
80.151543258,1645.0
80.201677064,1569.0
80.251810871,1629.0
80.301944678,1586.0
80.352078485,1606.0
80.402212292,1582.0
80.452346099,1583.0
80.502479906,1605.0
80.552613713,1576.0
80.602747520,1573.0
80.652881327,1547.0
80.703015134,1547.0
80.753148941,1517.0
80.803282748,1628.0
80.853416555,1570.0
80.903550362,1527.0
80.953684168,1660.0
81.003817975,1655.0
81.053951782,1506.0
81.104085589,1553.0
81.154219396,1518.0
81.204353203,1559.0
81.254487010,1619.0
81.304620817,1555.0
81.354754624,1581.0
81.404888431,1586.0
81.455022238,1598.0
81.505156045,1579.0
81.555289852,1527.0
81.605423659,1534.0
81.655557466,1552.0
81.705691272,1520.0
81.755825079,1541.0
81.805958886,1548.0
81.856092693,1530.0
81.906226500,1479.0
81.956360307,1498.0
82.006494114,1545.0
82.056627921,1436.0
82.106761728,1598.0
82.156895535,1451.0
82.207029342,1535.0
82.257163149,1538.0
82.307296956,1522.0
82.357430763,1526.0
82.407564570,1438.0
82.457698376,1456.0
82.507832183,1493.0
82.557965990,1576.0
82.608099797,1503.0
82.658233604,1528.0
82.708367411,1547.0
82.758501218,1437.0
82.808635025,1504.0
82.858768832,1524.0
82.908902639,1538.0
82.959036446,1563.0
83.009170253,1487.0
83.059304060,1571.0
83.109437867,1532.0
83.159571674,1498.0
83.209705480,1479.0
83.259839287,1473.0
83.309973094,1483.0
83.360106901,1434.0
83.410240708,1461.0
83.460374515,1437.0
83.510508322,1541.0
83.560642129,1488.0
83.610775936,1551.0
83.660909743,1565.0
83.711043550,1487.0
83.761177357,1483.0
83.811311164,1475.0
83.861444971,1537.0
83.911578778,1505.0
83.961712584,1462.0
84.011846391,1443.0
84.061980198,1409.0
84.112114005,1489.0
84.162247812,1472.0
84.212381619,1526.0
84.262515426,1437.0
84.312649233,1422.0
84.362783040,1520.0
84.412916847,1465.0
84.463050654,1477.0
84.513184461,1429.0
84.563318268,1464.0
84.613452075,1487.0
84.663585882,1454.0
84.713719689,1447.0
84.763853495,1505.0
84.813987302,1415.0
84.864121109,1453.0
84.914254916,1447.0
84.964388723,1390.0
85.014522530,1458.0
85.064656337,1423.0
85.114790144,1524.0
85.164923951,1531.0
85.215057758,1516.0
85.265191565,1413.0
85.315325372,1498.0
85.365459179,1480.0
85.415592986,1435.0
85.465726793,1450.0
85.515860599,1464.0
85.565994406,1477.0
85.616128213,1522.0
85.666262020,1412.0
85.716395827,1420.0
85.766529634,1571.0
85.816663441,1457.0
85.866797248,1466.0
85.916931055,1395.0
85.967064862,1517.0
86.017198669,1372.0
86.067332476,1405.0
86.117466283,1441.0
86.167600090,1455.0
86.217733897,1438.0
86.267867703,1380.0
86.318001510,1465.0
86.368135317,1465.0
86.418269124,1415.0
86.468402931,1442.0
86.518536738,1440.0
86.568670545,1528.0
86.618804352,1454.0
86.668938159,1483.0
86.719071966,1489.0
86.769205773,1446.0
86.819339580,1441.0
86.869473387,1423.0
86.919607194,1414.0
86.969741001,1433.0
87.019874807,1498.0
87.070008614,1468.0
87.120142421,1459.0
87.170276228,1444.0
87.220410035,1432.0
87.270543842,1478.0
87.320677649,1464.0
87.370811456,1426.0
87.420945263,1439.0
87.471079070,1439.0
87.521212877,1431.0
87.571346684,1409.0
87.621480491,1354.0
87.671614298,1428.0
87.721748105,1442.0
87.771881911,1495.0
87.822015718,1411.0
87.872149525,1403.0
87.922283332,1402.0
87.972417139,1428.0
88.022550946,1377.0
88.072684753,1339.0
88.122818560,1369.0
88.172952367,1412.0
88.223086174,1329.0
88.273219981,1390.0
88.323353788,1387.0
88.373487595,1372.0
88.423621402,1442.0
88.473755209,1449.0
88.523889016,1362.0
88.574022822,1386.0
88.624156629,1362.0
88.674290436,1461.0
88.724424243,1362.0
88.774558050,1354.0
88.824691857,1339.0
88.874825664,1375.0
88.924959471,1369.0
88.975093278,1372.0
89.025227085,1372.0
89.075360892,1387.0
89.125494699,1401.0
89.175628506,1403.0
89.225762313,1421.0
89.275896120,1402.0
89.326029926,1331.0
89.376163733,1379.0
89.426297540,1393.0
89.476431347,1399.0
89.526565154,1396.0
89.576698961,1382.0
89.626832768,1373.0
89.676966575,1480.0
89.727100382,1438.0
89.777234189,1428.0
89.827367996,1394.0
89.877501803,1391.0
89.927635610,1408.0
89.977769417,1434.0
90.027903224,1357.0
90.078037030,1382.0
90.128170837,1374.0
90.178304644,1438.0
90.228438451,1427.0
90.278572258,1404.0
90.328706065,1385.0
90.378839872,1378.0
90.428973679,1380.0
90.479107486,1409.0
90.529241293,1294.0
90.579375100,1403.0
90.629508907,1370.0
90.679642714,1402.0
90.729776521,1471.0
90.779910328,1361.0
90.830044134,1373.0
90.880177941,1409.0
90.930311748,1387.0
90.980445555,1371.0
91.030579362,1401.0
91.080713169,1358.0
91.130846976,1354.0
91.180980783,1407.0
91.231114590,1369.0
91.281248397,1374.0
91.331382204,1380.0
91.381516011,1390.0
91.431649818,1425.0
91.481783625,1380.0
91.531917432,1374.0
91.582051238,1319.0
91.632185045,1351.0
91.682318852,1342.0
91.732452659,1394.0
91.782586466,1341.0
91.832720273,1422.0
91.882854080,1359.0
91.932987887,1307.0
91.983121694,1332.0
92.033255501,1333.0
92.083389308,1396.0
92.133523115,1376.0
92.183656922,1310.0
92.233790729,1366.0
92.283924536,1441.0
92.334058342,1288.0
92.384192149,1279.0
92.434325956,1356.0
92.484459763,1355.0
92.534593570,1300.0
92.584727377,1315.0
92.634861184,1353.0
92.684994991,1319.0
92.735128798,1302.0
92.785262605,1412.0
92.835396412,1323.0
92.885530219,1408.0
92.935664026,1343.0
92.985797833,1375.0
93.035931640,1398.0
93.086065447,1335.0
93.136199253,1336.0
93.186333060,1425.0
93.236466867,1347.0
93.286600674,1356.0
93.336734481,1415.0
93.386868288,1385.0
93.437002095,1369.0
93.487135902,1400.0
93.537269709,1332.0
93.587403516,1376.0
93.637537323,1368.0
93.687671130,1429.0
93.737804937,1368.0
93.787938744,1386.0
93.838072551,1410.0
93.888206357,1408.0
93.938340164,1461.0
93.988473971,1361.0
94.038607778,1401.0
94.088741585,1435.0
94.138875392,1414.0
94.189009199,1386.0
94.239143006,1430.0
94.289276813,1474.0
94.339410620,1411.0
94.389544427,1424.0
94.439678234,1422.0
94.489812041,1389.0
94.539945848,1409.0
94.590079655,1290.0
94.640213461,1430.0
94.690347268,1392.0
94.740481075,1379.0
94.790614882,1322.0
94.840748689,1434.0
94.890882496,1326.0
94.941016303,1345.0
94.991150110,1380.0