File: OriginPro/XRD from Panalytical X'Pert PRO/In-Situ/FicheirosXRD_Insitu/NiNws_400°C.csv
[Measurement conditions]
Sample identification,
Comment - 1,"finito"
Comment - 2,"Configuration=MRI TC-Basic Stage, Owner=User-1, Creation date=26-10-2009 9:18:44"
Comment - 3,"Goniometer=PW3050/60 (Theta/Theta); Minimum step size 2Theta:0.001; Minimum step size Omega:0.001"
Comment - 4,"Sample stage=MRI TC-Basic (PtRh heat strip)"
Comment - 5,"Diffractometer system=XPERT-PRO"
Comment - 6,"Measurement program=FS-L, Owner=joana, Creation date=25-11-2014 17:28:08"
Anode material,Cu
K-Alpha1 wavelength,1.5405980
K-Alpha2 wavelength,1.5444260
Ratio K-Alpha2/K-Alpha1,0.500
Divergence slit,Fixed,0.76mm
Monochromator used,NO
Generator voltage, 45
Tube current, 40
File date and time,16-Dez-2017 01:22
Unit cell,
h k l, 0 0 0
Temperature [K],673
Scan axis,Gonio
Scan range,24.995999996,94.999505744
Scan step size,0.0167113
No. of points, 4189
Scan type,CONTINUOUS
Time per step,118.110
[Scan points]
Angle,Intensity
25.004355630,2281.0
25.054489437,2213.0
25.104623244,2211.0
25.154757051,2233.0
25.204890858,2152.0
25.255024665,2205.0
25.305158472,2228.0
25.355292279,2223.0
25.405426085,2218.0
25.455559892,2206.0
25.505693699,2243.0
25.555827506,2179.0
25.605961313,2238.0
25.656095120,2192.0
25.706228927,2197.0
25.756362734,2171.0
25.806496541,2225.0
25.856630348,2167.0
25.906764155,2313.0
25.956897962,2176.0
26.007031769,2204.0
26.057165576,2151.0
26.107299383,2210.0
26.157433189,2242.0
26.207566996,2173.0
26.257700803,2155.0
26.307834610,2220.0
26.357968417,2196.0
26.408102224,2171.0
26.458236031,2170.0
26.508369838,2137.0
26.558503645,2219.0
26.608637452,2227.0
26.658771259,2192.0
26.708905066,2136.0
26.759038873,2145.0
26.809172680,2077.0
26.859306487,2109.0
26.909440293,2215.0
26.959574100,2156.0
27.009707907,2162.0
27.059841714,2062.0
27.109975521,2141.0
27.160109328,2140.0
27.210243135,2115.0
27.260376942,2077.0
27.310510749,2210.0
27.360644556,2132.0
27.410778363,2129.0
27.460912170,2112.0
27.511045977,2140.0
27.561179784,2173.0
27.611313591,2209.0
27.661447398,2160.0
27.711581204,2185.0
27.761715011,2146.0
27.811848818,2104.0
27.861982625,2234.0
27.912116432,2139.0
27.962250239,2239.0
28.012384046,2131.0
28.062517853,2164.0
28.112651660,2199.0
28.162785467,2253.0
28.212919274,2201.0
28.263053081,2415.0
28.313186888,2477.0
28.363320695,2881.0
28.413454502,2292.0
28.463588308,2296.0
28.513722115,2402.0
28.563855922,2371.0
28.613989729,2246.0
28.664123536,2310.0
28.714257343,2246.0
28.764391150,2194.0
28.814524957,2139.0
28.864658764,2182.0
28.914792571,2182.0
28.964926378,2157.0
29.015060185,2268.0
29.065193992,2155.0
29.115327799,2100.0
29.165461606,2148.0
29.215595412,2111.0
29.265729219,2217.0
29.315863026,2054.0
29.365996833,2227.0
29.416130640,2175.0
29.466264447,2077.0
29.516398254,2101.0
29.566532061,2120.0
29.616665868,2091.0
29.666799675,2241.0
29.716933482,2121.0
29.767067289,2167.0
29.817201096,2190.0
29.867334903,2074.0
29.917468710,2152.0
29.967602516,2211.0
30.017736323,2182.0
30.067870130,2096.0
30.118003937,2139.0
30.168137744,2165.0
30.218271551,2126.0
30.268405358,2010.0
30.318539165,2109.0
30.368672972,2117.0
30.418806779,2211.0
30.468940586,2140.0
30.519074393,2109.0
30.569208200,2146.0
30.619342007,2115.0
30.669475814,2084.0
30.719609620,2119.0
30.769743427,2188.0
30.819877234,2179.0
30.870011041,2103.0
30.920144848,2083.0
30.970278655,2157.0
31.020412462,2156.0
31.070546269,2154.0
31.120680076,2059.0
31.170813883,2140.0
31.220947690,2248.0
31.271081497,2191.0
31.321215304,2159.0
31.371349111,2100.0
31.421482918,2061.0
31.471616724,2204.0
31.521750531,2169.0
31.571884338,2127.0
31.622018145,2078.0
31.672151952,2168.0
31.722285759,2105.0
31.772419566,2072.0
31.822553373,2126.0
31.872687180,2077.0
31.922820987,2087.0
31.972954794,2157.0
32.023088601,2171.0
32.073222408,2235.0
32.123356215,2079.0
32.173490022,2113.0
32.223623829,2107.0
32.273757635,2079.0
32.323891442,2089.0
32.374025249,2170.0
32.424159056,2107.0
32.474292863,2079.0
32.524426670,2197.0
32.574560477,2123.0
32.624694284,2139.0
32.674828091,2086.0
32.724961898,2201.0
32.775095705,2100.0
32.825229512,2144.0
32.875363319,2158.0
32.925497126,2122.0
32.975630933,2213.0
33.025764739,2100.0
33.075898546,2194.0
33.126032353,2073.0
33.176166160,2112.0
33.226299967,2116.0
33.276433774,2079.0
33.326567581,2107.0
33.376701388,2132.0
33.426835195,2140.0
33.476969002,2199.0
33.527102809,2057.0
33.577236616,2114.0
33.627370423,2105.0
33.677504230,2096.0
33.727638037,2067.0
33.777771843,2146.0
33.827905650,2089.0
33.878039457,2101.0
33.928173264,2032.0
33.978307071,2173.0
34.028440878,2072.0
34.078574685,2129.0
34.128708492,2104.0
34.178842299,2054.0
34.228976106,2056.0
34.279109913,2041.0
34.329243720,2062.0
34.379377527,2034.0
34.429511334,2040.0
34.479645141,2061.0
34.529778947,2075.0
34.579912754,2107.0
34.630046561,2090.0
34.680180368,2110.0
34.730314175,1995.0
34.780447982,2117.0
34.830581789,2020.0
34.880715596,2001.0
34.930849403,2065.0
34.980983210,2128.0
35.031117017,2082.0
35.081250824,2080.0
35.131384631,2153.0
35.181518438,2130.0
35.231652245,2108.0
35.281786051,2111.0
35.331919858,2034.0
35.382053665,2266.0
35.432187472,2068.0
35.482321279,2047.0
35.532455086,2167.0
35.582588893,2079.0
35.632722700,2203.0
35.682856507,2090.0
35.732990314,2158.0
35.783124121,2082.0
35.833257928,2224.0
35.883391735,2095.0
35.933525542,2064.0
35.983659349,2037.0
36.033793156,2084.0
36.083926962,2012.0
36.134060769,2100.0
36.184194576,2053.0
36.234328383,2071.0
36.284462190,2138.0
36.334595997,2115.0
36.384729804,2092.0
36.434863611,2134.0
36.484997418,2197.0
36.535131225,2156.0
36.585265032,2143.0
36.635398839,2140.0
36.685532646,2240.0
36.735666453,2206.0
36.785800260,2199.0
36.835934066,2319.0
36.886067873,2203.0
36.936201680,2123.0
36.986335487,2275.0
37.036469294,2236.0
37.086603101,2292.0
37.136736908,2221.0
37.186870715,2257.0
37.237004522,2210.0
37.287138329,2143.0
37.337272136,2156.0
37.387405943,2153.0
37.437539750,2207.0
37.487673557,2128.0
37.537807364,2137.0
37.587941170,2123.0
37.638074977,2107.0
37.688208784,2146.0
37.738342591,2062.0
37.788476398,2056.0
37.838610205,2104.0
37.888744012,2101.0
37.938877819,2142.0
37.989011626,2087.0
38.039145433,2116.0
38.089279240,2084.0
38.139413047,2136.0
38.189546854,2041.0
38.239680661,2133.0
38.289814468,2089.0
38.339948274,1891.0
38.390082081,1989.0
38.440215888,1981.0
38.490349695,2000.0
38.540483502,2033.0
38.590617309,1965.0
38.640751116,2031.0
38.690884923,2121.0
38.741018730,1994.0
38.791152537,2005.0
38.841286344,2024.0
38.891420151,1952.0
38.941553958,2023.0
38.991687765,2043.0
39.041821572,2015.0
39.091955378,2066.0
39.142089185,2009.0
39.192222992,2002.0
39.242356799,2011.0
39.292490606,1969.0
39.342624413,1969.0
39.392758220,2054.0
39.442892027,1964.0
39.493025834,2045.0
39.543159641,2065.0
39.593293448,2124.0
39.643427255,2138.0
39.693561062,2402.0
39.743694869,2189.0
39.793828676,2165.0
39.843962482,2060.0
39.894096289,1995.0
39.944230096,2169.0
39.994363903,2105.0
40.044497710,2078.0
40.094631517,2044.0
40.144765324,2094.0
40.194899131,2038.0
40.245032938,1994.0
40.295166745,1915.0
40.345300552,1942.0
40.395434359,1973.0
40.445568166,1936.0
40.495701973,1992.0
40.545835780,1990.0
40.595969587,1973.0
40.646103393,1934.0
40.696237200,1950.0
40.746371007,2022.0
40.796504814,2033.0
40.846638621,2055.0
40.896772428,2013.0
40.946906235,1965.0
40.997040042,1957.0
41.047173849,1932.0
41.097307656,2046.0
41.147441463,2047.0
41.197575270,2000.0
41.247709077,1925.0
41.297842884,1929.0
41.347976691,1975.0
41.398110497,1984.0
41.448244304,2022.0
41.498378111,1954.0
41.548511918,2003.0
41.598645725,1951.0
41.648779532,2084.0
41.698913339,1930.0
41.749047146,2049.0
41.799180953,2027.0
41.849314760,1932.0
41.899448567,1966.0
41.949582374,1972.0
41.999716181,1971.0
42.049849988,1991.0
42.099983795,2019.0
42.150117601,1953.0
42.200251408,2007.0
42.250385215,2084.0
42.300519022,2053.0
42.350652829,2012.0
42.400786636,2033.0
42.450920443,1978.0
42.501054250,2057.0
42.551188057,2158.0
42.601321864,2179.0
42.651455671,2109.0
42.701589478,2071.0
42.751723285,2210.0
42.801857092,2254.0
42.851990899,2204.0
42.902124705,2279.0
42.952258512,2190.0
43.002392319,2324.0
43.052526126,2282.0
43.102659933,2347.0
43.152793740,2370.0
43.202927547,2256.0
43.253061354,2315.0
43.303195161,2364.0
43.353328968,2309.0
43.403462775,2343.0
43.453596582,2307.0
43.503730389,2351.0
43.553864196,2257.0
43.603998003,2334.0
43.654131809,2362.0
43.704265616,2432.0
43.754399423,2553.0
43.804533230,2745.0
43.854667037,3109.0
43.904800844,3414.0
43.954934651,4135.0
44.005068458,4856.0
44.055202265,6061.0
44.105336072,7304.0
44.155469879,8747.0
44.205603686,9503.0
44.255737493,9202.0
44.305871300,7775.0
44.356005107,6123.0
44.406138913,4527.0
44.456272720,3426.0
44.506406527,2778.0
44.556540334,2605.0
44.606674141,2319.0
44.656807948,2221.0
44.706941755,2203.0
44.757075562,2147.0
44.807209369,2099.0
44.857343176,2061.0
44.907476983,2153.0
44.957610790,2106.0
45.007744597,1994.0
45.057878404,2052.0
45.108012211,2109.0
45.158146018,2049.0
45.208279824,2067.0
45.258413631,2133.0
45.308547438,2203.0
45.358681245,2053.0
45.408815052,2079.0
45.458948859,2102.0
45.509082666,1978.0
45.559216473,1984.0
45.609350280,2050.0
45.659484087,2074.0
45.709617894,2026.0
45.759751701,2019.0
45.809885508,2006.0
45.860019315,2053.0
45.910153122,2278.0
45.960286928,2347.0
46.010420735,2716.0
46.060554542,3252.0
46.110688349,4274.0
46.160822156,8454.0
46.210955963,3638.0
46.261089770,4350.0
46.311223577,3695.0
46.361357384,2780.0
46.411491191,3071.0
46.461624998,3401.0
46.511758805,3404.0
46.561892612,3330.0
46.612026419,3035.0
46.662160226,2591.0
46.712294032,2324.0
46.762427839,2053.0
46.812561646,2019.0
46.862695453,2001.0
46.912829260,1919.0
46.962963067,1870.0
47.013096874,1910.0
47.063230681,1918.0
47.113364488,1967.0
47.163498295,1985.0
47.213632102,1904.0
47.263765909,1888.0
47.313899716,1930.0
47.364033523,1844.0
47.414167330,1921.0
47.464301136,1932.0
47.514434943,1876.0
47.564568750,1869.0
47.614702557,1865.0
47.664836364,1860.0
47.714970171,1924.0
47.765103978,1923.0
47.815237785,1911.0
47.865371592,1938.0
47.915505399,1895.0
47.965639206,1931.0
48.015773013,1892.0
48.065906820,1871.0
48.116040627,1828.0
48.166174434,1874.0
48.216308240,1915.0
48.266442047,1830.0
48.316575854,1855.0
48.366709661,1865.0
48.416843468,1860.0
48.466977275,1815.0
48.517111082,1823.0
48.567244889,1835.0
48.617378696,1894.0
48.667512503,1876.0
48.717646310,1908.0
48.767780117,1775.0
48.817913924,1810.0
48.868047731,1868.0
48.918181538,1898.0
48.968315344,1826.0
49.018449151,1822.0
49.068582958,1829.0
49.118716765,1796.0
49.168850572,1869.0
49.218984379,1899.0
49.269118186,1869.0
49.319251993,1951.0
49.369385800,1857.0
49.419519607,2084.0
49.469653414,2016.0
49.519787221,2006.0
49.569921028,1942.0
49.620054835,1901.0
49.670188642,1862.0
49.720322449,1874.0
49.770456255,1742.0
49.820590062,1872.0
49.870723869,1851.0
49.920857676,1882.0
49.970991483,1866.0
50.021125290,1911.0
50.071259097,1847.0
50.121392904,1886.0
50.171526711,1967.0
50.221660518,2008.0
50.271794325,2032.0
50.321928132,2167.0
50.372061939,2274.0
50.422195746,2248.0
50.472329553,2212.0
50.522463359,2091.0
50.572597166,2073.0
50.622730973,1967.0
50.672864780,1917.0
50.722998587,1940.0
50.773132394,1926.0
50.823266201,1882.0
50.873400008,1859.0
50.923533815,2104.0
50.973667622,2039.0
51.023801429,2047.0
51.073935236,2106.0
51.124069043,2235.0
51.174202850,2199.0
51.224336657,2467.0
51.274470463,2858.0
51.324604270,3166.0
51.374738077,3464.0
51.424871884,4011.0
51.475005691,4180.0
51.525139498,4158.0
51.575273305,4011.0
51.625407112,3595.0
51.675540919,3151.0
51.725674726,2807.0
51.775808533,2519.0
51.825942340,2241.0
51.876076147,2157.0
51.926209954,2085.0
51.976343761,1834.0
52.026477567,1922.0
52.076611374,1875.0
52.126745181,1900.0
52.176878988,1903.0
52.227012795,1857.0
52.277146602,1842.0
52.327280409,1868.0
52.377414216,1798.0
52.427548023,1811.0
52.477681830,1841.0
52.527815637,1761.0
52.577949444,1824.0
52.628083251,1816.0
52.678217058,1882.0
52.728350865,1792.0
52.778484671,1734.0
52.828618478,1796.0
52.878752285,1815.0
52.928886092,1749.0
52.979019899,1797.0
53.029153706,1744.0
53.079287513,1804.0
53.129421320,1764.0
53.179555127,1801.0
53.229688934,1807.0
53.279822741,1816.0
53.329956548,1755.0
53.380090355,1852.0
53.430224162,1815.0
53.480357969,1830.0
53.530491776,1756.0
53.580625582,1756.0
53.630759389,1826.0
53.680893196,1777.0
53.731027003,1782.0
53.781160810,1832.0
53.831294617,1800.0
53.881428424,1738.0
53.931562231,1842.0
53.981696038,1819.0
54.031829845,1811.0
54.081963652,1815.0
54.132097459,1777.0
54.182231266,1735.0
54.232365073,1761.0
54.282498880,1761.0
54.332632686,1790.0
54.382766493,1756.0
54.432900300,1766.0
54.483034107,1825.0
54.533167914,1726.0
54.583301721,1847.0
54.633435528,1751.0
54.683569335,1725.0
54.733703142,1731.0
54.783836949,1627.0
54.833970756,1700.0
54.884104563,1790.0
54.934238370,1774.0
54.984372177,1735.0
55.034505984,1716.0
55.084639790,1746.0
55.134773597,1778.0
55.184907404,1755.0
55.235041211,1780.0
55.285175018,1743.0
55.335308825,1816.0
55.385442632,1783.0
55.435576439,1816.0
55.485710246,1767.0
55.535844053,1749.0
55.585977860,1797.0
55.636111667,1777.0
55.686245474,1810.0
55.736379281,1716.0
55.786513088,1762.0
55.836646894,1779.0
55.886780701,1717.0
55.936914508,1723.0
55.987048315,1777.0
56.037182122,1799.0
56.087315929,1724.0
56.137449736,1746.0
56.187583543,1787.0
56.237717350,1750.0
56.287851157,1723.0
56.337984964,1796.0
56.388118771,1793.0
56.438252578,1802.0
56.488386385,1700.0
56.538520192,1808.0
56.588653998,1740.0
56.638787805,1817.0
56.688921612,1789.0
56.739055419,1706.0
56.789189226,1667.0
56.839323033,1819.0
56.889456840,1735.0
56.939590647,1765.0
56.989724454,1747.0
57.039858261,1888.0
57.089992068,1814.0
57.140125875,1811.0
57.190259682,1784.0
57.240393489,1793.0
57.290527296,1811.0
57.340661102,1741.0
57.390794909,1835.0
57.440928716,1832.0
57.491062523,1814.0
57.541196330,1724.0
57.591330137,1823.0
57.641463944,1852.0
57.691597751,1771.0
57.741731558,1762.0
57.791865365,1774.0
57.841999172,1798.0
57.892132979,1911.0
57.942266786,1785.0
57.992400593,1826.0
58.042534400,1748.0
58.092668207,1756.0
58.142802013,1723.0
58.192935820,1750.0
58.243069627,1715.0
58.293203434,1778.0
58.343337241,1837.0
58.393471048,1666.0
58.443604855,1799.0
58.493738662,1769.0
58.543872469,1821.0
58.594006276,1793.0
58.644140083,1836.0
58.694273890,1772.0
58.744407697,1744.0
58.794541504,1799.0
58.844675311,1809.0
58.894809117,1715.0
58.944942924,1704.0
58.995076731,1774.0
59.045210538,1731.0
59.095344345,1695.0
59.145478152,1752.0
59.195611959,1796.0
59.245745766,1764.0
59.295879573,1795.0
59.346013380,1846.0
59.396147187,1824.0
59.446280994,1730.0
59.496414801,1793.0
59.546548608,1829.0
59.596682415,1742.0
59.646816221,1809.0
59.696950028,1780.0
59.747083835,1800.0
59.797217642,1847.0
59.847351449,1812.0
59.897485256,1784.0
59.947619063,1790.0
59.997752870,1899.0
60.047886677,1876.0
60.098020484,1871.0
60.148154291,1849.0
60.198288098,1846.0
60.248421905,1796.0
60.298555712,1833.0
60.348689519,1782.0
60.398823325,1789.0
60.448957132,1909.0
60.499090939,1833.0
60.549224746,1884.0
60.599358553,1752.0
60.649492360,1850.0
60.699626167,1872.0
60.749759974,1819.0
60.799893781,1918.0
60.850027588,1879.0
60.900161395,1858.0
60.950295202,1860.0
61.000429009,1830.0
61.050562816,1858.0
61.100696623,1845.0
61.150830429,1809.0
61.200964236,1895.0
61.251098043,1959.0
61.301231850,1825.0
61.351365657,1820.0
61.401499464,1835.0
61.451633271,1846.0
61.501767078,1982.0
61.551900885,1866.0
61.602034692,1787.0
61.652168499,1942.0
61.702302306,1940.0
61.752436113,1955.0
61.802569920,1954.0
61.852703727,1925.0
61.902837533,1908.0
61.952971340,1894.0
62.003105147,1974.0
62.053238954,1972.0
62.103372761,2054.0
62.153506568,1981.0
62.203640375,2014.0
62.253774182,1967.0
62.303907989,2094.0
62.354041796,2036.0
62.404175603,2051.0
62.454309410,1955.0
62.504443217,2072.0
62.554577024,1943.0
62.604710831,2029.0
62.654844638,2051.0
62.704978444,2059.0
62.755112251,2021.0
62.805246058,2065.0
62.855379865,2008.0
62.905513672,2009.0
62.955647479,2084.0
63.005781286,2027.0
63.055915093,2027.0
63.106048900,1971.0
63.156182707,1992.0
63.206316514,2050.0
63.256450321,1928.0
63.306584128,1997.0
63.356717935,2056.0
63.406851742,1966.0
63.456985548,2024.0
63.507119355,1954.0
63.557253162,2025.0
63.607386969,2053.0
63.657520776,1999.0
63.707654583,1972.0
63.757788390,2021.0
63.807922197,2094.0
63.858056004,2036.0
63.908189811,1933.0
63.958323618,2037.0
64.008457425,2016.0
64.058591232,2020.0
64.108725039,1971.0
64.158858846,2058.0
64.208992652,2033.0
64.259126459,2056.0
64.309260266,2022.0
64.359394073,2000.0
64.409527880,2129.0
64.459661687,2094.0
64.509795494,2077.0
64.559929301,2038.0
64.610063108,1983.0
64.660196915,2087.0
64.710330722,2034.0
64.760464529,2092.0
64.810598336,2091.0
64.860732143,2164.0
64.910865950,2104.0
64.960999756,2108.0
65.011133563,2046.0
65.061267370,2114.0
65.111401177,2169.0
65.161534984,2122.0
65.211668791,2091.0
65.261802598,2109.0
65.311936405,2189.0
65.362070212,2125.0
65.412204019,2175.0
65.462337826,2114.0
65.512471633,2199.0
65.562605440,2070.0
65.612739247,2098.0
65.662873054,2090.0
65.713006860,2131.0
65.763140667,2136.0
65.813274474,2165.0
65.863408281,2143.0
65.913542088,2124.0
65.963675895,2151.0
66.013809702,2134.0
66.063943509,2158.0
66.114077316,2071.0
66.164211123,2152.0
66.214344930,2147.0
66.264478737,2164.0
66.314612544,2114.0
66.364746351,2112.0
66.414880158,2160.0
66.465013964,2162.0
66.515147771,2082.0
66.565281578,2189.0
66.615415385,2128.0
66.665549192,2183.0
66.715682999,2128.0
66.765816806,2185.0
66.815950613,2145.0
66.866084420,2160.0
66.916218227,2151.0
66.966352034,2145.0
67.016485841,2204.0
67.066619648,2191.0
67.116753455,2204.0
67.166887262,2211.0
67.217021069,2176.0
67.267154875,2176.0
67.317288682,2153.0
67.367422489,2072.0
67.417556296,2159.0
67.467690103,2188.0
67.517823910,2133.0
67.567957717,2134.0
67.618091524,2164.0
67.668225331,2082.0
67.718359138,2187.0
67.768492945,2118.0
67.818626752,2220.0
67.868760559,2118.0
67.918894366,2179.0
67.969028173,2230.0
68.019161979,2102.0
68.069295786,2263.0
68.119429593,2174.0
68.169563400,2162.0
68.219697207,2135.0
68.269831014,2195.0
68.319964821,2185.0
68.370098628,2144.0
68.420232435,2162.0
68.470366242,2092.0
68.520500049,2082.0
68.570633856,2142.0
68.620767663,2176.0
68.670901470,2115.0
68.721035277,2138.0
68.771169083,2113.0
68.821302890,2088.0
68.871436697,2019.0
68.921570504,2129.0
68.971704311,2058.0
69.021838118,2193.0
69.071971925,2224.0
69.122105732,2163.0
69.172239539,2135.0
69.222373346,2149.0
69.272507153,2219.0
69.322640960,2208.0
69.372774767,2102.0
69.422908574,2207.0
69.473042381,2171.0
69.523176187,2193.0
69.573309994,2049.0
69.623443801,2232.0
69.673577608,2049.0
69.723711415,2165.0
69.773845222,1986.0
69.823979029,2177.0
69.874112836,2114.0
69.924246643,2127.0
69.974380450,2024.0
70.024514257,2102.0
70.074648064,2031.0
70.124781871,2103.0
70.174915678,2103.0
70.225049485,2148.0
70.275183291,2114.0
70.325317098,2065.0
70.375450905,1999.0
70.425584712,2116.0
70.475718519,2166.0
70.525852326,2029.0
70.575986133,2058.0
70.626119940,2089.0
70.676253747,2014.0
70.726387554,2032.0
70.776521361,2058.0
70.826655168,1953.0
70.876788975,2124.0
70.926922782,2017.0
70.977056589,2053.0
71.027190396,2095.0
71.077324202,1969.0
71.127458009,2042.0
71.177591816,2000.0
71.227725623,2097.0
71.277859430,1967.0
71.327993237,2040.0
71.378127044,2004.0
71.428260851,2038.0
71.478394658,1904.0
71.528528465,1979.0
71.578662272,1984.0
71.628796079,1999.0
71.678929886,2066.0
71.729063693,2049.0
71.779197500,2059.0
71.829331306,1928.0
71.879465113,1990.0
71.929598920,1957.0
71.979732727,1986.0
72.029866534,1972.0
72.080000341,1969.0
72.130134148,1894.0
72.180267955,1923.0
72.230401762,1922.0
72.280535569,1991.0
72.330669376,1896.0
72.380803183,2044.0
72.430936990,1916.0
72.481070797,2008.0
72.531204604,1935.0
72.581338410,1903.0
72.631472217,1976.0
72.681606024,2003.0
72.731739831,1888.0
72.781873638,1956.0
72.832007445,1963.0
72.882141252,1880.0
72.932275059,1974.0
72.982408866,2008.0
73.032542673,1934.0
73.082676480,1964.0
73.132810287,1958.0
73.182944094,1882.0
73.233077901,1933.0
73.283211708,1896.0
73.333345514,1969.0
73.383479321,1988.0
73.433613128,1819.0
73.483746935,1883.0
73.533880742,1873.0
73.584014549,1854.0
73.634148356,1788.0
73.684282163,1855.0
73.734415970,1855.0
73.784549777,1861.0
73.834683584,1834.0
73.884817391,1788.0
73.934951198,1874.0
73.985085005,1838.0
74.035218812,1911.0
74.085352618,1862.0
74.135486425,1905.0
74.185620232,1827.0
74.235754039,1810.0
74.285887846,1904.0
74.336021653,1856.0
74.386155460,1861.0
74.436289267,1840.0
74.486423074,1867.0
74.536556881,1860.0
74.586690688,1852.0
74.636824495,1799.0
74.686958302,1860.0
74.737092109,1902.0
74.787225916,1860.0
74.837359722,1844.0
74.887493529,1794.0
74.937627336,1880.0
74.987761143,1838.0
75.037894950,1928.0
75.088028757,1935.0
75.138162564,1883.0
75.188296371,1874.0
75.238430178,1886.0
75.288563985,1905.0
75.338697792,1942.0
75.388831599,2005.0
75.438965406,1960.0
75.489099213,2052.0
75.539233020,2098.0
75.589366827,2151.0
75.639500633,2141.0
75.689634440,2211.0
75.739768247,2349.0
75.789902054,2418.0
75.840035861,2342.0
75.890169668,2449.0
75.940303475,2142.0
75.990437282,2184.0
76.040571089,2059.0
76.090704896,2102.0
76.140838703,1972.0
76.190972510,1861.0
76.241106317,1781.0
76.291240124,1824.0
76.341373931,1811.0
76.391507737,1779.0
76.441641544,1729.0
76.491775351,1658.0
76.541909158,1765.0
76.592042965,1732.0
76.642176772,1768.0
76.692310579,1718.0
76.742444386,1715.0
76.792578193,1763.0
76.842712000,1710.0
76.892845807,1724.0
76.942979614,1668.0
76.993113421,1665.0
77.043247228,1765.0
77.093381035,1664.0
77.143514841,1663.0
77.193648648,1691.0
77.243782455,1701.0
77.293916262,1718.0
77.344050069,1676.0
77.394183876,1699.0
77.444317683,1655.0
77.494451490,1666.0
77.544585297,1703.0
77.594719104,1652.0
77.644852911,1676.0
77.694986718,1661.0
77.745120525,1608.0
77.795254332,1615.0
77.845388139,1689.0
77.895521945,1659.0
77.945655752,1665.0
77.995789559,1697.0
78.045923366,1694.0
78.096057173,1650.0
78.146190980,1623.0
78.196324787,1644.0
78.246458594,1536.0
78.296592401,1634.0
78.346726208,1562.0
78.396860015,1593.0
78.446993822,1643.0
78.497127629,1656.0
78.547261436,1599.0
78.597395243,1669.0
78.647529049,1573.0
78.697662856,1594.0
78.747796663,1670.0
78.797930470,1645.0
78.848064277,1598.0
78.898198084,1581.0
78.948331891,1629.0
78.998465698,1630.0
79.048599505,1589.0
79.098733312,1591.0
79.148867119,1551.0
79.199000926,1599.0
79.249134733,1614.0
79.299268540,1617.0
79.349402347,1562.0
79.399536153,1567.0
79.449669960,1634.0
79.499803767,1608.0
79.549937574,1560.0
79.600071381,1587.0
79.650205188,1571.0
79.700338995,1517.0
79.750472802,1603.0
79.800606609,1623.0
79.850740416,1606.0
79.900874223,1559.0
79.951008030,1564.0
80.001141837,1547.0
80.051275644,1502.0
80.101409451,1478.0
80.151543258,1581.0
80.201677064,1573.0
80.251810871,1590.0
80.301944678,1493.0
80.352078485,1583.0
80.402212292,1559.0
80.452346099,1466.0
80.502479906,1564.0
80.552613713,1482.0
80.602747520,1569.0
80.652881327,1472.0
80.703015134,1568.0
80.753148941,1552.0
80.803282748,1607.0
80.853416555,1593.0
80.903550362,1538.0
80.953684168,1537.0
81.003817975,1535.0
81.053951782,1498.0
81.104085589,1512.0
81.154219396,1537.0
81.204353203,1601.0
81.254487010,1499.0
81.304620817,1485.0
81.354754624,1521.0
81.404888431,1514.0
81.455022238,1499.0
81.505156045,1537.0
81.555289852,1457.0
81.605423659,1558.0
81.655557466,1584.0
81.705691272,1494.0
81.755825079,1508.0
81.805958886,1524.0
81.856092693,1502.0
81.906226500,1526.0
81.956360307,1535.0
82.006494114,1490.0
82.056627921,1465.0
82.106761728,1512.0
82.156895535,1475.0
82.207029342,1552.0
82.257163149,1436.0
82.307296956,1547.0
82.357430763,1480.0
82.407564570,1504.0
82.457698376,1465.0
82.507832183,1523.0
82.557965990,1438.0
82.608099797,1490.0
82.658233604,1479.0
82.708367411,1487.0
82.758501218,1430.0
82.808635025,1544.0
82.858768832,1431.0
82.908902639,1459.0
82.959036446,1401.0
83.009170253,1519.0
83.059304060,1466.0
83.109437867,1476.0
83.159571674,1498.0
83.209705480,1521.0
83.259839287,1458.0
83.309973094,1450.0
83.360106901,1487.0
83.410240708,1460.0
83.460374515,1426.0
83.510508322,1496.0
83.560642129,1431.0
83.610775936,1569.0
83.660909743,1442.0
83.711043550,1447.0
83.761177357,1433.0
83.811311164,1431.0
83.861444971,1417.0
83.911578778,1482.0
83.961712584,1429.0
84.011846391,1477.0
84.061980198,1389.0
84.112114005,1489.0
84.162247812,1433.0
84.212381619,1450.0
84.262515426,1427.0
84.312649233,1413.0
84.362783040,1444.0
84.412916847,1480.0
84.463050654,1441.0
84.513184461,1400.0
84.563318268,1410.0
84.613452075,1453.0
84.663585882,1436.0
84.713719689,1406.0
84.763853495,1451.0
84.813987302,1483.0
84.864121109,1430.0
84.914254916,1536.0
84.964388723,1462.0
85.014522530,1415.0
85.064656337,1432.0
85.114790144,1408.0
85.164923951,1437.0
85.215057758,1407.0
85.265191565,1399.0
85.315325372,1433.0
85.365459179,1410.0
85.415592986,1415.0
85.465726793,1452.0
85.515860599,1454.0
85.565994406,1439.0
85.616128213,1445.0
85.666262020,1382.0
85.716395827,1382.0
85.766529634,1424.0
85.816663441,1476.0
85.866797248,1372.0
85.916931055,1387.0
85.967064862,1435.0
86.017198669,1449.0
86.067332476,1442.0
86.117466283,1390.0
86.167600090,1414.0
86.217733897,1395.0
86.267867703,1433.0
86.318001510,1474.0
86.368135317,1415.0
86.418269124,1445.0
86.468402931,1497.0
86.518536738,1382.0
86.568670545,1343.0
86.618804352,1477.0
86.668938159,1428.0
86.719071966,1395.0
86.769205773,1354.0
86.819339580,1438.0
86.869473387,1351.0
86.919607194,1309.0
86.969741001,1401.0
87.019874807,1411.0
87.070008614,1416.0
87.120142421,1381.0
87.170276228,1375.0
87.220410035,1428.0
87.270543842,1402.0
87.320677649,1409.0
87.370811456,1451.0
87.420945263,1369.0
87.471079070,1438.0
87.521212877,1362.0
87.571346684,1364.0
87.621480491,1337.0
87.671614298,1423.0
87.721748105,1376.0
87.771881911,1393.0
87.822015718,1365.0
87.872149525,1391.0
87.922283332,1426.0
87.972417139,1377.0
88.022550946,1453.0
88.072684753,1373.0
88.122818560,1342.0
88.172952367,1361.0
88.223086174,1384.0
88.273219981,1375.0
88.323353788,1352.0
88.373487595,1398.0
88.423621402,1387.0
88.473755209,1336.0
88.523889016,1430.0
88.574022822,1380.0
88.624156629,1368.0
88.674290436,1369.0
88.724424243,1357.0
88.774558050,1361.0
88.824691857,1428.0
88.874825664,1365.0
88.924959471,1428.0
88.975093278,1403.0
89.025227085,1436.0
89.075360892,1447.0
89.125494699,1407.0
89.175628506,1394.0
89.225762313,1363.0
89.275896120,1367.0
89.326029926,1425.0
89.376163733,1432.0
89.426297540,1422.0
89.476431347,1383.0
89.526565154,1338.0
89.576698961,1394.0
89.626832768,1352.0
89.676966575,1386.0
89.727100382,1320.0
89.777234189,1366.0
89.827367996,1396.0
89.877501803,1347.0
89.927635610,1366.0
89.977769417,1400.0
90.027903224,1335.0
90.078037030,1416.0
90.128170837,1311.0
90.178304644,1387.0
90.228438451,1350.0
90.278572258,1335.0
90.328706065,1364.0
90.378839872,1399.0
90.428973679,1332.0
90.479107486,1399.0
90.529241293,1367.0
90.579375100,1356.0
90.629508907,1267.0
90.679642714,1300.0
90.729776521,1312.0
90.779910328,1355.0
90.830044134,1353.0
90.880177941,1412.0
90.930311748,1371.0
90.980445555,1385.0
91.030579362,1362.0
91.080713169,1368.0
91.130846976,1403.0
91.180980783,1375.0
91.231114590,1406.0
91.281248397,1491.0
91.331382204,1419.0
91.381516011,1438.0
91.431649818,1418.0
91.481783625,1473.0
91.531917432,1452.0
91.582051238,1477.0
91.632185045,1443.0
91.682318852,1493.0
91.732452659,1509.0
91.782586466,1598.0
91.832720273,1558.0
91.882854080,1616.0
91.932987887,1624.0
91.983121694,1627.0
92.033255501,1747.0
92.083389308,1829.0
92.133523115,1798.0
92.183656922,1764.0
92.233790729,1786.0
92.283924536,1708.0
92.334058342,1711.0
92.384192149,1742.0
92.434325956,1663.0
92.484459763,1552.0
92.534593570,1554.0
92.584727377,1529.0
92.634861184,1468.0
92.684994991,1365.0
92.735128798,1448.0
92.785262605,1446.0
92.835396412,1396.0
92.885530219,1453.0
92.935664026,1343.0
92.985797833,1352.0
93.035931640,1402.0
93.086065447,1383.0
93.136199253,1366.0
93.186333060,1405.0
93.236466867,1399.0
93.286600674,1370.0
93.336734481,1368.0
93.386868288,1357.0
93.437002095,1370.0
93.487135902,1458.0
93.537269709,1310.0
93.587403516,1305.0
93.637537323,1363.0
93.687671130,1345.0
93.737804937,1357.0
93.787938744,1348.0
93.838072551,1335.0
93.888206357,1381.0
93.938340164,1394.0
93.988473971,1289.0
94.038607778,1290.0
94.088741585,1343.0
94.138875392,1360.0
94.189009199,1338.0
94.239143006,1299.0
94.289276813,1320.0
94.339410620,1337.0
94.389544427,1345.0
94.439678234,1381.0
94.489812041,1323.0
94.539945848,1293.0
94.590079655,1311.0
94.640213461,1342.0
94.690347268,1327.0
94.740481075,1338.0
94.790614882,1349.0
94.840748689,1320.0
94.890882496,1280.0
94.941016303,1288.0
94.991150110,1352.0