File: OriginPro/XRD from Panalytical X'Pert PRO/In-Situ/FicheirosXRD_Insitu/NiNws_450°C.csv
[Measurement conditions]
Sample identification,
Comment - 1,"finito"
Comment - 2,"Configuration=MRI TC-Basic Stage, Owner=User-1, Creation date=26-10-2009 9:18:44"
Comment - 3,"Goniometer=PW3050/60 (Theta/Theta); Minimum step size 2Theta:0.001; Minimum step size Omega:0.001"
Comment - 4,"Sample stage=MRI TC-Basic (PtRh heat strip)"
Comment - 5,"Diffractometer system=XPERT-PRO"
Comment - 6,"Measurement program=FS-L, Owner=joana, Creation date=25-11-2014 17:28:08"
Anode material,Cu
K-Alpha1 wavelength,1.5405980
K-Alpha2 wavelength,1.5444260
Ratio K-Alpha2/K-Alpha1,0.500
Divergence slit,Fixed,0.76mm
Monochromator used,NO
Generator voltage, 45
Tube current, 40
File date and time,16-Dez-2017 02:31
Unit cell,
h k l, 0 0 0
Temperature [K],723
Scan axis,Gonio
Scan range,24.995999996,94.999505744
Scan step size,0.0167113
No. of points, 4189
Scan type,CONTINUOUS
Time per step,118.110
[Scan points]
Angle,Intensity
25.004355630,2187.0
25.054489437,2146.0
25.104623244,2244.0
25.154757051,2206.0
25.204890858,2202.0
25.255024665,2110.0
25.305158472,2212.0
25.355292279,2237.0
25.405426085,2186.0
25.455559892,2287.0
25.505693699,2203.0
25.555827506,2115.0
25.605961313,2233.0
25.656095120,2199.0
25.706228927,2089.0
25.756362734,2149.0
25.806496541,2212.0
25.856630348,2138.0
25.906764155,2293.0
25.956897962,2214.0
26.007031769,2179.0
26.057165576,2189.0
26.107299383,2186.0
26.157433189,2272.0
26.207566996,2149.0
26.257700803,2201.0
26.307834610,2131.0
26.357968417,2174.0
26.408102224,2091.0
26.458236031,2284.0
26.508369838,2240.0
26.558503645,2183.0
26.608637452,2165.0
26.658771259,2208.0
26.708905066,2144.0
26.759038873,2206.0
26.809172680,2239.0
26.859306487,2181.0
26.909440293,2163.0
26.959574100,2119.0
27.009707907,2110.0
27.059841714,2129.0
27.109975521,2126.0
27.160109328,2252.0
27.210243135,2187.0
27.260376942,2205.0
27.310510749,2123.0
27.360644556,2216.0
27.410778363,2245.0
27.460912170,2202.0
27.511045977,2193.0
27.561179784,2227.0
27.611313591,2179.0
27.661447398,2135.0
27.711581204,2194.0
27.761715011,2109.0
27.811848818,2193.0
27.861982625,2134.0
27.912116432,2143.0
27.962250239,2091.0
28.012384046,2147.0
28.062517853,2156.0
28.112651660,2137.0
28.162785467,2142.0
28.212919274,2151.0
28.263053081,2392.0
28.313186888,2469.0
28.363320695,2674.0
28.413454502,2325.0
28.463588308,2303.0
28.513722115,2319.0
28.563855922,2417.0
28.613989729,2234.0
28.664123536,2209.0
28.714257343,2158.0
28.764391150,2288.0
28.814524957,2174.0
28.864658764,2217.0
28.914792571,2164.0
28.964926378,2181.0
29.015060185,2191.0
29.065193992,2212.0
29.115327799,2126.0
29.165461606,2164.0
29.215595412,2174.0
29.265729219,2158.0
29.315863026,2090.0
29.365996833,2232.0
29.416130640,2125.0
29.466264447,2142.0
29.516398254,2141.0
29.566532061,2154.0
29.616665868,2142.0
29.666799675,2102.0
29.716933482,2095.0
29.767067289,2176.0
29.817201096,2101.0
29.867334903,2198.0
29.917468710,2129.0
29.967602516,2196.0
30.017736323,2270.0
30.067870130,2133.0
30.118003937,2135.0
30.168137744,2113.0
30.218271551,2089.0
30.268405358,2160.0
30.318539165,2178.0
30.368672972,2092.0
30.418806779,2213.0
30.468940586,2146.0
30.519074393,2167.0
30.569208200,2125.0
30.619342007,2047.0
30.669475814,2094.0
30.719609620,2209.0
30.769743427,2164.0
30.819877234,2055.0
30.870011041,2164.0
30.920144848,2249.0
30.970278655,2157.0
31.020412462,2081.0
31.070546269,2177.0
31.120680076,2100.0
31.170813883,2084.0
31.220947690,2130.0
31.271081497,2067.0
31.321215304,2093.0
31.371349111,2193.0
31.421482918,2140.0
31.471616724,2146.0
31.521750531,2123.0
31.571884338,2103.0
31.622018145,2066.0
31.672151952,2233.0
31.722285759,2091.0
31.772419566,2149.0
31.822553373,2126.0
31.872687180,2059.0
31.922820987,2031.0
31.972954794,2156.0
32.023088601,2197.0
32.073222408,2122.0
32.123356215,2069.0
32.173490022,2071.0
32.223623829,2029.0
32.273757635,2136.0
32.323891442,2161.0
32.374025249,2042.0
32.424159056,2161.0
32.474292863,2010.0
32.524426670,2108.0
32.574560477,2114.0
32.624694284,2117.0
32.674828091,2130.0
32.724961898,2123.0
32.775095705,2088.0
32.825229512,2074.0
32.875363319,2213.0
32.925497126,2177.0
32.975630933,2195.0
33.025764739,2183.0
33.075898546,2200.0
33.126032353,2157.0
33.176166160,2154.0
33.226299967,2115.0
33.276433774,2175.0
33.326567581,2102.0
33.376701388,2108.0
33.426835195,2036.0
33.476969002,2115.0
33.527102809,2063.0
33.577236616,2208.0
33.627370423,2004.0
33.677504230,2083.0
33.727638037,2230.0
33.777771843,2040.0
33.827905650,2055.0
33.878039457,2207.0
33.928173264,2165.0
33.978307071,2070.0
34.028440878,2192.0
34.078574685,2138.0
34.128708492,2085.0
34.178842299,2097.0
34.228976106,2131.0
34.279109913,2068.0
34.329243720,2142.0
34.379377527,2081.0
34.429511334,2086.0
34.479645141,2112.0
34.529778947,2168.0
34.579912754,2144.0
34.630046561,2054.0
34.680180368,2102.0
34.730314175,2145.0
34.780447982,2105.0
34.830581789,2166.0
34.880715596,2109.0
34.930849403,2200.0
34.980983210,2105.0
35.031117017,2129.0
35.081250824,2057.0
35.131384631,2180.0
35.181518438,2091.0
35.231652245,2138.0
35.281786051,2159.0
35.331919858,2202.0
35.382053665,2126.0
35.432187472,2180.0
35.482321279,2079.0
35.532455086,2234.0
35.582588893,2252.0
35.632722700,2222.0
35.682856507,2182.0
35.732990314,2107.0
35.783124121,2119.0
35.833257928,2208.0
35.883391735,2150.0
35.933525542,2130.0
35.983659349,2159.0
36.033793156,2157.0
36.083926962,2176.0
36.134060769,2134.0
36.184194576,2183.0
36.234328383,2113.0
36.284462190,2182.0
36.334595997,2203.0
36.384729804,2185.0
36.434863611,2231.0
36.484997418,2257.0
36.535131225,2269.0
36.585265032,2267.0
36.635398839,2362.0
36.685532646,2452.0
36.735666453,2463.0
36.785800260,2636.0
36.835934066,2711.0
36.886067873,2865.0
36.936201680,2979.0
36.986335487,3147.0
37.036469294,3123.0
37.086603101,3217.0
37.136736908,3082.0
37.186870715,3002.0
37.237004522,2814.0
37.287138329,2769.0
37.337272136,2624.0
37.387405943,2373.0
37.437539750,2391.0
37.487673557,2449.0
37.537807364,2333.0
37.587941170,2261.0
37.638074977,2216.0
37.688208784,2204.0
37.738342591,2072.0
37.788476398,2191.0
37.838610205,2149.0
37.888744012,2182.0
37.938877819,2200.0
37.989011626,2095.0
38.039145433,2053.0
38.089279240,2112.0
38.139413047,2013.0
38.189546854,1999.0
38.239680661,2033.0
38.289814468,2073.0
38.339948274,2142.0
38.390082081,2062.0
38.440215888,2055.0
38.490349695,1971.0
38.540483502,1991.0
38.590617309,2099.0
38.640751116,2005.0
38.690884923,1951.0
38.741018730,1952.0
38.791152537,2056.0
38.841286344,2053.0
38.891420151,2089.0
38.941553958,2069.0
38.991687765,2002.0
39.041821572,2035.0
39.091955378,2010.0
39.142089185,2001.0
39.192222992,1967.0
39.242356799,1964.0
39.292490606,2051.0
39.342624413,1948.0
39.392758220,1991.0
39.442892027,2035.0
39.493025834,2106.0
39.543159641,2115.0
39.593293448,2156.0
39.643427255,2265.0
39.693561062,2527.0
39.743694869,2190.0
39.793828676,2242.0
39.843962482,2047.0
39.894096289,2003.0
39.944230096,2067.0
39.994363903,2123.0
40.044497710,2077.0
40.094631517,2045.0
40.144765324,2042.0
40.194899131,1966.0
40.245032938,1991.0
40.295166745,2010.0
40.345300552,2015.0
40.395434359,1927.0
40.445568166,2053.0
40.495701973,1959.0
40.545835780,2004.0
40.595969587,2033.0
40.646103393,2015.0
40.696237200,2101.0
40.746371007,1924.0
40.796504814,1934.0
40.846638621,2014.0
40.896772428,1962.0
40.946906235,2063.0
40.997040042,1941.0
41.047173849,2024.0
41.097307656,2052.0
41.147441463,2037.0
41.197575270,2011.0
41.247709077,1905.0
41.297842884,1941.0
41.347976691,2050.0
41.398110497,2013.0
41.448244304,1932.0
41.498378111,2042.0
41.548511918,1953.0
41.598645725,2035.0
41.648779532,2001.0
41.698913339,2047.0
41.749047146,2040.0
41.799180953,1966.0
41.849314760,2089.0
41.899448567,2028.0
41.949582374,2000.0
41.999716181,1971.0
42.049849988,2072.0
42.099983795,2079.0
42.150117601,2115.0
42.200251408,2052.0
42.250385215,2045.0
42.300519022,2168.0
42.350652829,2193.0
42.400786636,2158.0
42.450920443,2177.0
42.501054250,2276.0
42.551188057,2328.0
42.601321864,2420.0
42.651455671,2499.0
42.701589478,2644.0
42.751723285,2686.0
42.801857092,2872.0
42.851990899,3130.0
42.902124705,3283.0
42.952258512,3481.0
43.002392319,3509.0
43.052526126,3655.0
43.102659933,3555.0
43.152793740,3457.0
43.202927547,3434.0
43.253061354,3153.0
43.303195161,3037.0
43.353328968,2766.0
43.403462775,2710.0
43.453596582,2653.0
43.503730389,2404.0
43.553864196,2404.0
43.603998003,2490.0
43.654131809,2364.0
43.704265616,2416.0
43.754399423,2480.0
43.804533230,2860.0
43.854667037,3032.0
43.904800844,3194.0
43.954934651,3775.0
44.005068458,4410.0
44.055202265,5337.0
44.105336072,5978.0
44.155469879,6339.0
44.205603686,6103.0
44.255737493,5187.0
44.305871300,4322.0
44.356005107,3336.0
44.406138913,2849.0
44.456272720,2447.0
44.506406527,2246.0
44.556540334,2159.0
44.606674141,2153.0
44.656807948,2116.0
44.706941755,2002.0
44.757075562,1994.0
44.807209369,2007.0
44.857343176,2052.0
44.907476983,2092.0
44.957610790,2062.0
45.007744597,1951.0
45.057878404,2063.0
45.108012211,2053.0
45.158146018,2064.0
45.208279824,2089.0
45.258413631,2105.0
45.308547438,2129.0
45.358681245,2119.0
45.408815052,1964.0
45.458948859,2095.0
45.509082666,2095.0
45.559216473,1979.0
45.609350280,1954.0
45.659484087,2071.0
45.709617894,1993.0
45.759751701,2034.0
45.809885508,2054.0
45.860019315,1961.0
45.910153122,2207.0
45.960286928,2405.0
46.010420735,2813.0
46.060554542,3378.0
46.110688349,5542.0
46.160822156,5942.0
46.210955963,3392.0
46.261089770,5155.0
46.311223577,2877.0
46.361357384,2708.0
46.411491191,3194.0
46.461624998,3338.0
46.511758805,3346.0
46.561892612,3094.0
46.612026419,2847.0
46.662160226,2445.0
46.712294032,2301.0
46.762427839,2074.0
46.812561646,1898.0
46.862695453,1967.0
46.912829260,1945.0
46.962963067,1973.0
47.013096874,1897.0
47.063230681,1884.0
47.113364488,1953.0
47.163498295,1822.0
47.213632102,1874.0
47.263765909,1899.0
47.313899716,1940.0
47.364033523,1841.0
47.414167330,1928.0
47.464301136,1896.0
47.514434943,1871.0
47.564568750,1830.0
47.614702557,1868.0
47.664836364,1853.0
47.714970171,1871.0
47.765103978,1845.0
47.815237785,1838.0
47.865371592,1822.0
47.915505399,1857.0
47.965639206,1803.0
48.015773013,1871.0
48.065906820,1967.0
48.116040627,1837.0
48.166174434,1820.0
48.216308240,1814.0
48.266442047,1881.0
48.316575854,1928.0
48.366709661,1839.0
48.416843468,1885.0
48.466977275,1893.0
48.517111082,1803.0
48.567244889,1905.0
48.617378696,1868.0
48.667512503,1820.0
48.717646310,1788.0
48.767780117,1859.0
48.817913924,1870.0
48.868047731,1790.0
48.918181538,1811.0
48.968315344,1771.0
49.018449151,1767.0
49.068582958,1793.0
49.118716765,1863.0
49.168850572,1819.0
49.218984379,1798.0
49.269118186,1926.0
49.319251993,1951.0
49.369385800,2000.0
49.419519607,1992.0
49.469653414,2002.0
49.519787221,2010.0
49.569921028,1892.0
49.620054835,1828.0
49.670188642,1848.0
49.720322449,1786.0
49.770456255,1778.0
49.820590062,1803.0
49.870723869,1820.0
49.920857676,1723.0
49.970991483,1835.0
50.021125290,1936.0
50.071259097,1901.0
50.121392904,1894.0
50.171526711,1900.0
50.221660518,1954.0
50.271794325,2010.0
50.321928132,2044.0
50.372061939,2249.0
50.422195746,2207.0
50.472329553,2104.0
50.522463359,2013.0
50.572597166,1923.0
50.622730973,1931.0
50.672864780,1863.0
50.722998587,1842.0
50.773132394,1885.0
50.823266201,1826.0
50.873400008,1933.0
50.923533815,1898.0
50.973667622,1920.0
51.023801429,2022.0
51.073935236,2027.0
51.124069043,2116.0
51.174202850,2237.0
51.224336657,2368.0
51.274470463,2555.0
51.324604270,2801.0
51.374738077,3009.0
51.424871884,3129.0
51.475005691,3079.0
51.525139498,2964.0
51.575273305,2746.0
51.625407112,2490.0
51.675540919,2364.0
51.725674726,2213.0
51.775808533,2002.0
51.825942340,2046.0
51.876076147,1878.0
51.926209954,1870.0
51.976343761,1898.0
52.026477567,1759.0
52.076611374,1827.0
52.126745181,1811.0
52.176878988,1769.0
52.227012795,1804.0
52.277146602,1852.0
52.327280409,1793.0
52.377414216,1748.0
52.427548023,1775.0
52.477681830,1755.0
52.527815637,1741.0
52.577949444,1846.0
52.628083251,1729.0
52.678217058,1811.0
52.728350865,1771.0
52.778484671,1785.0
52.828618478,1753.0
52.878752285,1728.0
52.928886092,1737.0
52.979019899,1874.0
53.029153706,1758.0
53.079287513,1739.0
53.129421320,1835.0
53.179555127,1771.0
53.229688934,1798.0
53.279822741,1732.0
53.329956548,1757.0
53.380090355,1783.0
53.430224162,1844.0
53.480357969,1762.0
53.530491776,1794.0
53.580625582,1833.0
53.630759389,1803.0
53.680893196,1732.0
53.731027003,1837.0
53.781160810,1748.0
53.831294617,1829.0
53.881428424,1747.0
53.931562231,1810.0
53.981696038,1766.0
54.031829845,1769.0
54.081963652,1644.0
54.132097459,1839.0
54.182231266,1680.0
54.232365073,1822.0
54.282498880,1815.0
54.332632686,1762.0
54.382766493,1736.0
54.432900300,1786.0
54.483034107,1781.0
54.533167914,1706.0
54.583301721,1839.0
54.633435528,1832.0
54.683569335,1723.0
54.733703142,1767.0
54.783836949,1775.0
54.833970756,1731.0
54.884104563,1788.0
54.934238370,1715.0
54.984372177,1708.0
55.034505984,1821.0
55.084639790,1769.0
55.134773597,1783.0
55.184907404,1790.0
55.235041211,1737.0
55.285175018,1782.0
55.335308825,1748.0
55.385442632,1799.0
55.435576439,1766.0
55.485710246,1772.0
55.535844053,1734.0
55.585977860,1855.0
55.636111667,1761.0
55.686245474,1852.0
55.736379281,1794.0
55.786513088,1764.0
55.836646894,1734.0
55.886780701,1659.0
55.936914508,1736.0
55.987048315,1772.0
56.037182122,1783.0
56.087315929,1729.0
56.137449736,1751.0
56.187583543,1755.0
56.237717350,1761.0
56.287851157,1726.0
56.337984964,1770.0
56.388118771,1887.0
56.438252578,1787.0
56.488386385,1757.0
56.538520192,1765.0
56.588653998,1704.0
56.638787805,1781.0
56.688921612,1773.0
56.739055419,1724.0
56.789189226,1786.0
56.839323033,1788.0
56.889456840,1809.0
56.939590647,1796.0
56.989724454,1711.0
57.039858261,1721.0
57.089992068,1767.0
57.140125875,1781.0
57.190259682,1702.0
57.240393489,1721.0
57.290527296,1714.0
57.340661102,1683.0
57.390794909,1797.0
57.440928716,1703.0
57.491062523,1844.0
57.541196330,1715.0
57.591330137,1883.0
57.641463944,1736.0
57.691597751,1790.0
57.741731558,1823.0
57.791865365,1797.0
57.841999172,1781.0
57.892132979,1840.0
57.942266786,1805.0
57.992400593,1694.0
58.042534400,1870.0
58.092668207,1878.0
58.142802013,1813.0
58.192935820,1844.0
58.243069627,1814.0
58.293203434,1782.0
58.343337241,1699.0
58.393471048,1797.0
58.443604855,1843.0
58.493738662,1817.0
58.543872469,1758.0
58.594006276,1849.0
58.644140083,1813.0
58.694273890,1821.0
58.744407697,1785.0
58.794541504,1768.0
58.844675311,1716.0
58.894809117,1890.0
58.944942924,1800.0
58.995076731,1725.0
59.045210538,1726.0
59.095344345,1857.0
59.145478152,1748.0
59.195611959,1812.0
59.245745766,1821.0
59.295879573,1818.0
59.346013380,1797.0
59.396147187,1790.0
59.446280994,1840.0
59.496414801,1837.0
59.546548608,1839.0
59.596682415,1946.0
59.646816221,1842.0
59.696950028,1824.0
59.747083835,1793.0
59.797217642,1842.0
59.847351449,1841.0
59.897485256,1870.0
59.947619063,1873.0
59.997752870,1801.0
60.047886677,1763.0
60.098020484,1960.0
60.148154291,1844.0
60.198288098,1885.0
60.248421905,1882.0
60.298555712,1806.0
60.348689519,1868.0
60.398823325,1873.0
60.448957132,1807.0
60.499090939,1868.0
60.549224746,1868.0
60.599358553,1816.0
60.649492360,1845.0
60.699626167,1842.0
60.749759974,1867.0
60.799893781,1837.0
60.850027588,1878.0
60.900161395,1899.0
60.950295202,1876.0
61.000429009,1916.0
61.050562816,1838.0
61.100696623,1940.0
61.150830429,1964.0
61.200964236,1836.0
61.251098043,1806.0
61.301231850,1957.0
61.351365657,1842.0
61.401499464,1968.0
61.451633271,1938.0
61.501767078,1957.0
61.551900885,1963.0
61.602034692,1997.0
61.652168499,1987.0
61.702302306,2009.0
61.752436113,1962.0
61.802569920,2030.0
61.852703727,2031.0
61.902837533,2000.0
61.952971340,2124.0
62.003105147,2139.0
62.053238954,2193.0
62.103372761,2200.0
62.153506568,2199.0
62.203640375,2343.0
62.253774182,2371.0
62.303907989,2350.0
62.354041796,2393.0
62.404175603,2389.0
62.454309410,2425.0
62.504443217,2524.0
62.554577024,2471.0
62.604710831,2545.0
62.654844638,2478.0
62.704978444,2507.0
62.755112251,2387.0
62.805246058,2213.0
62.855379865,2329.0
62.905513672,2269.0
62.955647479,2258.0
63.005781286,2130.0
63.055915093,2174.0
63.106048900,2144.0
63.156182707,2102.0
63.206316514,2174.0
63.256450321,2077.0
63.306584128,2130.0
63.356717935,2176.0
63.406851742,2069.0
63.456985548,2062.0
63.507119355,2082.0
63.557253162,2098.0
63.607386969,2210.0
63.657520776,2085.0
63.707654583,2058.0
63.757788390,2073.0
63.807922197,2088.0
63.858056004,2045.0
63.908189811,2136.0
63.958323618,2051.0
64.008457425,2092.0
64.058591232,2023.0
64.108725039,2060.0
64.158858846,2091.0
64.208992652,2119.0
64.259126459,2139.0
64.309260266,2070.0
64.359394073,2063.0
64.409527880,2109.0
64.459661687,2113.0
64.509795494,2141.0
64.559929301,2015.0
64.610063108,2108.0
64.660196915,2023.0
64.710330722,2128.0
64.760464529,2046.0
64.810598336,2102.0
64.860732143,2169.0
64.910865950,2134.0
64.960999756,2135.0
65.011133563,2154.0
65.061267370,2125.0
65.111401177,2148.0
65.161534984,2121.0
65.211668791,2112.0
65.261802598,2245.0
65.311936405,2131.0
65.362070212,2093.0
65.412204019,2156.0
65.462337826,2245.0
65.512471633,2208.0
65.562605440,2195.0
65.612739247,2162.0
65.662873054,2030.0
65.713006860,2208.0
65.763140667,2187.0
65.813274474,2158.0
65.863408281,2137.0
65.913542088,2167.0
65.963675895,2135.0
66.013809702,2172.0
66.063943509,2152.0
66.114077316,2214.0
66.164211123,2149.0
66.214344930,2260.0
66.264478737,2234.0
66.314612544,2159.0
66.364746351,2210.0
66.414880158,2179.0
66.465013964,2158.0
66.515147771,2122.0
66.565281578,2265.0
66.615415385,2198.0
66.665549192,2128.0
66.715682999,2185.0
66.765816806,2204.0
66.815950613,2222.0
66.866084420,2165.0
66.916218227,2187.0
66.966352034,2177.0
67.016485841,2205.0
67.066619648,2159.0
67.116753455,2216.0
67.166887262,2208.0
67.217021069,2256.0
67.267154875,2214.0
67.317288682,2278.0
67.367422489,2209.0
67.417556296,2209.0
67.467690103,2204.0
67.517823910,2230.0
67.567957717,2266.0
67.618091524,2175.0
67.668225331,2176.0
67.718359138,2181.0
67.768492945,2180.0
67.818626752,2183.0
67.868760559,2185.0
67.918894366,2224.0
67.969028173,2087.0
68.019161979,2131.0
68.069295786,2213.0
68.119429593,2285.0
68.169563400,2255.0
68.219697207,2184.0
68.269831014,2150.0
68.319964821,2183.0
68.370098628,2166.0
68.420232435,2243.0
68.470366242,2150.0
68.520500049,2153.0
68.570633856,2213.0
68.620767663,2120.0
68.670901470,2122.0
68.721035277,2174.0
68.771169083,2175.0
68.821302890,2111.0
68.871436697,2143.0
68.921570504,2214.0
68.971704311,2165.0
69.021838118,2154.0
69.071971925,2267.0
69.122105732,2170.0
69.172239539,2152.0
69.222373346,2283.0
69.272507153,2142.0
69.322640960,2189.0
69.372774767,2212.0
69.422908574,2208.0
69.473042381,2166.0
69.523176187,2148.0
69.573309994,2199.0
69.623443801,2211.0
69.673577608,2206.0
69.723711415,2067.0
69.773845222,2057.0
69.823979029,2141.0
69.874112836,2086.0
69.924246643,2149.0
69.974380450,2142.0
70.024514257,2116.0
70.074648064,2069.0
70.124781871,2203.0
70.174915678,2154.0
70.225049485,2147.0
70.275183291,2113.0
70.325317098,2137.0
70.375450905,2120.0
70.425584712,2157.0
70.475718519,2146.0
70.525852326,2139.0
70.575986133,2161.0
70.626119940,2101.0
70.676253747,2136.0
70.726387554,2061.0
70.776521361,2098.0
70.826655168,2109.0
70.876788975,2116.0
70.926922782,2127.0
70.977056589,2072.0
71.027190396,2075.0
71.077324202,2033.0
71.127458009,2119.0
71.177591816,2101.0
71.227725623,2104.0
71.277859430,2059.0
71.327993237,2121.0
71.378127044,2115.0
71.428260851,2140.0
71.478394658,2039.0
71.528528465,2029.0
71.578662272,2103.0
71.628796079,2062.0
71.678929886,1941.0
71.729063693,2035.0
71.779197500,2072.0
71.829331306,1974.0
71.879465113,2058.0
71.929598920,2000.0
71.979732727,2009.0
72.029866534,1997.0
72.080000341,2000.0
72.130134148,2001.0
72.180267955,1996.0
72.230401762,1960.0
72.280535569,1947.0
72.330669376,1976.0
72.380803183,2019.0
72.430936990,2027.0
72.481070797,2018.0
72.531204604,1982.0
72.581338410,1983.0
72.631472217,2053.0
72.681606024,1867.0
72.731739831,1922.0
72.781873638,2031.0
72.832007445,2027.0
72.882141252,1938.0
72.932275059,1988.0
72.982408866,1919.0
73.032542673,1987.0
73.082676480,1946.0
73.132810287,1994.0
73.182944094,2000.0
73.233077901,1950.0
73.283211708,1938.0
73.333345514,1925.0
73.383479321,1952.0
73.433613128,1992.0
73.483746935,1921.0
73.533880742,1953.0
73.584014549,1983.0
73.634148356,1925.0
73.684282163,1903.0
73.734415970,1911.0
73.784549777,1843.0
73.834683584,1983.0
73.884817391,1929.0
73.934951198,1906.0
73.985085005,1880.0
74.035218812,1886.0
74.085352618,1924.0
74.135486425,2009.0
74.185620232,1865.0
74.235754039,1905.0
74.285887846,1949.0
74.336021653,1962.0
74.386155460,2061.0
74.436289267,1869.0
74.486423074,1931.0
74.536556881,1984.0
74.586690688,1957.0
74.636824495,1911.0
74.686958302,2018.0
74.737092109,2051.0
74.787225916,1973.0
74.837359722,2022.0
74.887493529,1997.0
74.937627336,1975.0
74.987761143,2106.0
75.037894950,1942.0
75.088028757,1956.0
75.138162564,2028.0
75.188296371,2018.0
75.238430178,1926.0
75.288563985,2036.0
75.338697792,2060.0
75.388831599,1913.0
75.438965406,2018.0
75.489099213,2073.0
75.539233020,2095.0
75.589366827,2099.0
75.639500633,2156.0
75.689634440,2153.0
75.739768247,2215.0
75.789902054,2158.0
75.840035861,2070.0
75.890169668,2002.0
75.940303475,1947.0
75.990437282,1968.0
76.040571089,1857.0
76.090704896,1888.0
76.140838703,1843.0
76.190972510,1726.0
76.241106317,1803.0
76.291240124,1736.0
76.341373931,1780.0
76.391507737,1721.0
76.441641544,1795.0
76.491775351,1729.0
76.541909158,1785.0
76.592042965,1793.0
76.642176772,1765.0
76.692310579,1749.0
76.742444386,1713.0
76.792578193,1705.0
76.842712000,1669.0
76.892845807,1732.0
76.942979614,1733.0
76.993113421,1673.0
77.043247228,1690.0
77.093381035,1728.0
77.143514841,1757.0
77.193648648,1681.0
77.243782455,1681.0
77.293916262,1748.0
77.344050069,1661.0
77.394183876,1674.0
77.444317683,1738.0
77.494451490,1642.0
77.544585297,1738.0
77.594719104,1629.0
77.644852911,1671.0
77.694986718,1710.0
77.745120525,1787.0
77.795254332,1717.0
77.845388139,1653.0
77.895521945,1671.0
77.945655752,1631.0
77.995789559,1698.0
78.045923366,1657.0
78.096057173,1691.0
78.146190980,1695.0
78.196324787,1584.0
78.246458594,1737.0
78.296592401,1698.0
78.346726208,1728.0
78.396860015,1658.0
78.446993822,1682.0
78.497127629,1656.0
78.547261436,1716.0
78.597395243,1728.0
78.647529049,1700.0
78.697662856,1753.0
78.747796663,1723.0
78.797930470,1737.0
78.848064277,1780.0
78.898198084,1772.0
78.948331891,1671.0
78.998465698,1711.0
79.048599505,1755.0
79.098733312,1714.0
79.148867119,1703.0
79.199000926,1618.0
79.249134733,1614.0
79.299268540,1717.0
79.349402347,1614.0
79.399536153,1654.0
79.449669960,1561.0
79.499803767,1518.0
79.549937574,1707.0
79.600071381,1599.0
79.650205188,1608.0
79.700338995,1562.0
79.750472802,1555.0
79.800606609,1567.0
79.850740416,1571.0
79.900874223,1600.0
79.951008030,1594.0
80.001141837,1576.0
80.051275644,1551.0
80.101409451,1510.0
80.151543258,1594.0
80.201677064,1605.0
80.251810871,1546.0
80.301944678,1546.0
80.352078485,1597.0
80.402212292,1583.0
80.452346099,1581.0
80.502479906,1556.0
80.552613713,1511.0
80.602747520,1595.0
80.652881327,1550.0
80.703015134,1587.0
80.753148941,1517.0
80.803282748,1535.0
80.853416555,1521.0
80.903550362,1537.0
80.953684168,1552.0
81.003817975,1485.0
81.053951782,1550.0
81.104085589,1578.0
81.154219396,1623.0
81.204353203,1529.0
81.254487010,1484.0
81.304620817,1496.0
81.354754624,1525.0
81.404888431,1495.0
81.455022238,1522.0
81.505156045,1494.0
81.555289852,1548.0
81.605423659,1499.0
81.655557466,1534.0
81.705691272,1566.0
81.755825079,1577.0
81.805958886,1509.0
81.856092693,1529.0
81.906226500,1548.0
81.956360307,1525.0
82.006494114,1581.0
82.056627921,1457.0
82.106761728,1539.0
82.156895535,1543.0
82.207029342,1524.0
82.257163149,1542.0
82.307296956,1545.0
82.357430763,1457.0
82.407564570,1459.0
82.457698376,1477.0
82.507832183,1493.0
82.557965990,1466.0
82.608099797,1468.0
82.658233604,1525.0
82.708367411,1527.0
82.758501218,1564.0
82.808635025,1515.0
82.858768832,1490.0
82.908902639,1431.0
82.959036446,1422.0
83.009170253,1482.0
83.059304060,1511.0
83.109437867,1507.0
83.159571674,1447.0
83.209705480,1527.0
83.259839287,1525.0
83.309973094,1476.0
83.360106901,1522.0
83.410240708,1464.0
83.460374515,1450.0
83.510508322,1504.0
83.560642129,1427.0
83.610775936,1432.0
83.660909743,1487.0
83.711043550,1464.0
83.761177357,1451.0
83.811311164,1422.0
83.861444971,1389.0
83.911578778,1413.0
83.961712584,1481.0
84.011846391,1453.0
84.061980198,1483.0
84.112114005,1528.0
84.162247812,1471.0
84.212381619,1461.0
84.262515426,1472.0
84.312649233,1450.0
84.362783040,1474.0
84.412916847,1404.0
84.463050654,1505.0
84.513184461,1459.0
84.563318268,1507.0
84.613452075,1382.0
84.663585882,1478.0
84.713719689,1415.0
84.763853495,1477.0
84.813987302,1395.0
84.864121109,1392.0
84.914254916,1385.0
84.964388723,1518.0
85.014522530,1413.0
85.064656337,1504.0
85.114790144,1415.0
85.164923951,1426.0
85.215057758,1412.0
85.265191565,1487.0
85.315325372,1453.0
85.365459179,1398.0
85.415592986,1476.0
85.465726793,1567.0
85.515860599,1457.0
85.565994406,1429.0
85.616128213,1432.0
85.666262020,1462.0
85.716395827,1453.0
85.766529634,1351.0
85.816663441,1392.0
85.866797248,1435.0
85.916931055,1370.0
85.967064862,1431.0
86.017198669,1461.0
86.067332476,1421.0
86.117466283,1399.0
86.167600090,1422.0
86.217733897,1416.0
86.267867703,1461.0
86.318001510,1393.0
86.368135317,1467.0
86.418269124,1456.0
86.468402931,1401.0
86.518536738,1419.0
86.568670545,1373.0
86.618804352,1422.0
86.668938159,1396.0
86.719071966,1377.0
86.769205773,1434.0
86.819339580,1420.0
86.869473387,1456.0
86.919607194,1415.0
86.969741001,1388.0
87.019874807,1477.0
87.070008614,1434.0
87.120142421,1420.0
87.170276228,1401.0
87.220410035,1402.0
87.270543842,1392.0
87.320677649,1413.0
87.370811456,1420.0
87.420945263,1447.0
87.471079070,1428.0
87.521212877,1433.0
87.571346684,1421.0
87.621480491,1334.0
87.671614298,1345.0
87.721748105,1392.0
87.771881911,1334.0
87.822015718,1450.0
87.872149525,1401.0
87.922283332,1353.0
87.972417139,1359.0
88.022550946,1336.0
88.072684753,1416.0
88.122818560,1343.0
88.172952367,1456.0
88.223086174,1462.0
88.273219981,1333.0
88.323353788,1388.0
88.373487595,1392.0
88.423621402,1359.0
88.473755209,1411.0
88.523889016,1408.0
88.574022822,1418.0
88.624156629,1391.0
88.674290436,1443.0
88.724424243,1404.0
88.774558050,1389.0
88.824691857,1373.0
88.874825664,1338.0
88.924959471,1423.0
88.975093278,1389.0
89.025227085,1443.0
89.075360892,1283.0
89.125494699,1414.0
89.175628506,1433.0
89.225762313,1379.0
89.275896120,1393.0
89.326029926,1339.0
89.376163733,1377.0
89.426297540,1359.0
89.476431347,1484.0
89.526565154,1353.0
89.576698961,1366.0
89.626832768,1339.0
89.676966575,1358.0
89.727100382,1349.0
89.777234189,1358.0
89.827367996,1397.0
89.877501803,1376.0
89.927635610,1341.0
89.977769417,1421.0
90.027903224,1332.0
90.078037030,1363.0
90.128170837,1300.0
90.178304644,1341.0
90.228438451,1376.0
90.278572258,1368.0
90.328706065,1330.0
90.378839872,1312.0
90.428973679,1379.0
90.479107486,1313.0
90.529241293,1349.0
90.579375100,1376.0
90.629508907,1335.0
90.679642714,1363.0
90.729776521,1369.0
90.779910328,1366.0
90.830044134,1397.0
90.880177941,1365.0
90.930311748,1360.0
90.980445555,1311.0
91.030579362,1380.0
91.080713169,1397.0
91.130846976,1366.0
91.180980783,1443.0
91.231114590,1345.0
91.281248397,1324.0
91.331382204,1371.0
91.381516011,1442.0
91.431649818,1421.0
91.481783625,1360.0
91.531917432,1469.0
91.582051238,1383.0
91.632185045,1382.0
91.682318852,1458.0
91.732452659,1531.0
91.782586466,1534.0
91.832720273,1483.0
91.882854080,1598.0
91.932987887,1597.0
91.983121694,1533.0
92.033255501,1687.0
92.083389308,1584.0
92.133523115,1524.0
92.183656922,1502.0
92.233790729,1471.0
92.283924536,1479.0
92.334058342,1451.0
92.384192149,1516.0
92.434325956,1436.0
92.484459763,1426.0
92.534593570,1378.0
92.584727377,1441.0
92.634861184,1349.0
92.684994991,1385.0
92.735128798,1357.0
92.785262605,1368.0
92.835396412,1340.0
92.885530219,1306.0
92.935664026,1412.0
92.985797833,1362.0
93.035931640,1323.0
93.086065447,1380.0
93.136199253,1374.0
93.186333060,1318.0
93.236466867,1392.0
93.286600674,1381.0
93.336734481,1368.0
93.386868288,1332.0
93.437002095,1278.0
93.487135902,1309.0
93.537269709,1356.0
93.587403516,1299.0
93.637537323,1361.0
93.687671130,1329.0
93.737804937,1286.0
93.787938744,1322.0
93.838072551,1360.0
93.888206357,1288.0
93.938340164,1369.0
93.988473971,1366.0
94.038607778,1391.0
94.088741585,1388.0
94.138875392,1357.0
94.189009199,1343.0
94.239143006,1404.0
94.289276813,1369.0
94.339410620,1446.0
94.389544427,1382.0
94.439678234,1337.0
94.489812041,1318.0
94.539945848,1373.0
94.590079655,1327.0
94.640213461,1375.0
94.690347268,1301.0
94.740481075,1396.0
94.790614882,1310.0
94.840748689,1296.0
94.890882496,1340.0
94.941016303,1317.0
94.991150110,1385.0