File: OriginPro/XRD from Panalytical X'Pert PRO/In-Situ/FicheirosXRD_Insitu/NiNws_300°C.csv
[Measurement conditions]
Sample identification,
Comment - 1,"finito"
Comment - 2,"Configuration=MRI TC-Basic Stage, Owner=User-1, Creation date=26-10-2009 9:18:44"
Comment - 3,"Goniometer=PW3050/60 (Theta/Theta); Minimum step size 2Theta:0.001; Minimum step size Omega:0.001"
Comment - 4,"Sample stage=MRI TC-Basic (PtRh heat strip)"
Comment - 5,"Diffractometer system=XPERT-PRO"
Comment - 6,"Measurement program=FS-L, Owner=joana, Creation date=25-11-2014 17:28:08"
Anode material,Cu
K-Alpha1 wavelength,1.5405980
K-Alpha2 wavelength,1.5444260
Ratio K-Alpha2/K-Alpha1,0.500
Divergence slit,Fixed,0.76mm
Monochromator used,NO
Generator voltage, 45
Tube current, 40
File date and time,15-Dez-2017 23:03
Unit cell,
h k l, 0 0 0
Temperature [K],573
Scan axis,Gonio
Scan range,24.995999996,94.999505744
Scan step size,0.0167113
No. of points, 4189
Scan type,CONTINUOUS
Time per step,118.110
[Scan points]
Angle,Intensity
25.004355630,2283.0
25.054489437,2203.0
25.104623244,2197.0
25.154757051,2316.0
25.204890858,2228.0
25.255024665,2227.0
25.305158472,2121.0
25.355292279,2165.0
25.405426085,2277.0
25.455559892,2202.0
25.505693699,2191.0
25.555827506,2296.0
25.605961313,2310.0
25.656095120,2197.0
25.706228927,2119.0
25.756362734,2179.0
25.806496541,2265.0
25.856630348,2128.0
25.906764155,2184.0
25.956897962,2169.0
26.007031769,2094.0
26.057165576,2302.0
26.107299383,2305.0
26.157433189,2202.0
26.207566996,2167.0
26.257700803,2207.0
26.307834610,2305.0
26.357968417,2238.0
26.408102224,2289.0
26.458236031,2186.0
26.508369838,2121.0
26.558503645,2099.0
26.608637452,2146.0
26.658771259,2141.0
26.708905066,2124.0
26.759038873,2098.0
26.809172680,2196.0
26.859306487,2222.0
26.909440293,2126.0
26.959574100,2160.0
27.009707907,2088.0
27.059841714,2211.0
27.109975521,2200.0
27.160109328,2149.0
27.210243135,2155.0
27.260376942,2139.0
27.310510749,2076.0
27.360644556,2149.0
27.410778363,2122.0
27.460912170,2158.0
27.511045977,2157.0
27.561179784,2225.0
27.611313591,2181.0
27.661447398,2263.0
27.711581204,2107.0
27.761715011,2197.0
27.811848818,2195.0
27.861982625,2212.0
27.912116432,2116.0
27.962250239,2187.0
28.012384046,2148.0
28.062517853,2169.0
28.112651660,2204.0
28.162785467,2139.0
28.212919274,2250.0
28.263053081,2325.0
28.313186888,2499.0
28.363320695,2853.0
28.413454502,2294.0
28.463588308,2359.0
28.513722115,2269.0
28.563855922,2267.0
28.613989729,2314.0
28.664123536,2280.0
28.714257343,2254.0
28.764391150,2241.0
28.814524957,2224.0
28.864658764,2264.0
28.914792571,2203.0
28.964926378,2265.0
29.015060185,2186.0
29.065193992,2205.0
29.115327799,2138.0
29.165461606,2184.0
29.215595412,2174.0
29.265729219,2096.0
29.315863026,2214.0
29.365996833,2193.0
29.416130640,2124.0
29.466264447,2125.0
29.516398254,2132.0
29.566532061,2190.0
29.616665868,2223.0
29.666799675,2130.0
29.716933482,2134.0
29.767067289,2150.0
29.817201096,2103.0
29.867334903,2166.0
29.917468710,2123.0
29.967602516,2107.0
30.017736323,2219.0
30.067870130,2156.0
30.118003937,2151.0
30.168137744,2105.0
30.218271551,2135.0
30.268405358,2103.0
30.318539165,2128.0
30.368672972,2085.0
30.418806779,2186.0
30.468940586,2121.0
30.519074393,2099.0
30.569208200,2073.0
30.619342007,2091.0
30.669475814,2115.0
30.719609620,2132.0
30.769743427,2141.0
30.819877234,2202.0
30.870011041,2112.0
30.920144848,2131.0
30.970278655,2111.0
31.020412462,2134.0
31.070546269,2086.0
31.120680076,2101.0
31.170813883,2072.0
31.220947690,2136.0
31.271081497,2155.0
31.321215304,2116.0
31.371349111,2135.0
31.421482918,2075.0
31.471616724,2121.0
31.521750531,2042.0
31.571884338,2042.0
31.622018145,2101.0
31.672151952,2135.0
31.722285759,2111.0
31.772419566,2196.0
31.822553373,2156.0
31.872687180,2132.0
31.922820987,2127.0
31.972954794,2144.0
32.023088601,2035.0
32.073222408,2029.0
32.123356215,2140.0
32.173490022,2100.0
32.223623829,2064.0
32.273757635,2083.0
32.323891442,2164.0
32.374025249,2066.0
32.424159056,2119.0
32.474292863,2140.0
32.524426670,2134.0
32.574560477,2126.0
32.624694284,2112.0
32.674828091,2132.0
32.724961898,2178.0
32.775095705,2156.0
32.825229512,2084.0
32.875363319,2118.0
32.925497126,2056.0
32.975630933,2059.0
33.025764739,2139.0
33.075898546,2162.0
33.126032353,2093.0
33.176166160,2217.0
33.226299967,2102.0
33.276433774,2109.0
33.326567581,2097.0
33.376701388,2105.0
33.426835195,2047.0
33.476969002,2059.0
33.527102809,2102.0
33.577236616,2069.0
33.627370423,2092.0
33.677504230,2112.0
33.727638037,2092.0
33.777771843,2066.0
33.827905650,2101.0
33.878039457,2116.0
33.928173264,2061.0
33.978307071,2076.0
34.028440878,2002.0
34.078574685,2092.0
34.128708492,2054.0
34.178842299,2149.0
34.228976106,2078.0
34.279109913,2060.0
34.329243720,2077.0
34.379377527,2167.0
34.429511334,2210.0
34.479645141,2112.0
34.529778947,2113.0
34.579912754,2102.0
34.630046561,2027.0
34.680180368,2126.0
34.730314175,2112.0
34.780447982,2232.0
34.830581789,2041.0
34.880715596,2120.0
34.930849403,2087.0
34.980983210,2111.0
35.031117017,2090.0
35.081250824,2041.0
35.131384631,2085.0
35.181518438,2122.0
35.231652245,2078.0
35.281786051,1957.0
35.331919858,2108.0
35.382053665,2052.0
35.432187472,2039.0
35.482321279,2145.0
35.532455086,2204.0
35.582588893,1991.0
35.632722700,2106.0
35.682856507,2052.0
35.732990314,2080.0
35.783124121,2055.0
35.833257928,2054.0
35.883391735,2027.0
35.933525542,2016.0
35.983659349,2091.0
36.033793156,2106.0
36.083926962,2099.0
36.134060769,2079.0
36.184194576,2053.0
36.234328383,2095.0
36.284462190,2085.0
36.334595997,2104.0
36.384729804,2095.0
36.434863611,2004.0
36.484997418,2039.0
36.535131225,2133.0
36.585265032,2084.0
36.635398839,2097.0
36.685532646,2135.0
36.735666453,2053.0
36.785800260,2158.0
36.835934066,2062.0
36.886067873,2169.0
36.936201680,2119.0
36.986335487,2038.0
37.036469294,2116.0
37.086603101,2040.0
37.136736908,2032.0
37.186870715,2079.0
37.237004522,2022.0
37.287138329,2026.0
37.337272136,2094.0
37.387405943,2041.0
37.437539750,2034.0
37.487673557,2060.0
37.537807364,1986.0
37.587941170,1950.0
37.638074977,1891.0
37.688208784,2164.0
37.738342591,2056.0
37.788476398,1979.0
37.838610205,2084.0
37.888744012,2072.0
37.938877819,2154.0
37.989011626,2043.0
38.039145433,2161.0
38.089279240,2115.0
38.139413047,2198.0
38.189546854,2068.0
38.239680661,2052.0
38.289814468,2006.0
38.339948274,2012.0
38.390082081,2090.0
38.440215888,2091.0
38.490349695,2000.0
38.540483502,1977.0
38.590617309,2049.0
38.640751116,2010.0
38.690884923,2013.0
38.741018730,2001.0
38.791152537,1963.0
38.841286344,1999.0
38.891420151,2010.0
38.941553958,2040.0
38.991687765,2018.0
39.041821572,1999.0
39.091955378,2029.0
39.142089185,1868.0
39.192222992,2051.0
39.242356799,1983.0
39.292490606,1992.0
39.342624413,2042.0
39.392758220,2007.0
39.442892027,2065.0
39.493025834,2002.0
39.543159641,2088.0
39.593293448,2043.0
39.643427255,2142.0
39.693561062,2390.0
39.743694869,2462.0
39.793828676,2217.0
39.843962482,2307.0
39.894096289,2120.0
39.944230096,2078.0
39.994363903,2043.0
40.044497710,2111.0
40.094631517,2158.0
40.144765324,2121.0
40.194899131,2010.0
40.245032938,1963.0
40.295166745,2041.0
40.345300552,1969.0
40.395434359,2026.0
40.445568166,2014.0
40.495701973,1965.0
40.545835780,2021.0
40.595969587,2053.0
40.646103393,1904.0
40.696237200,1999.0
40.746371007,1999.0
40.796504814,1891.0
40.846638621,1778.0
40.896772428,1981.0
40.946906235,1927.0
40.997040042,1980.0
41.047173849,1952.0
41.097307656,1993.0
41.147441463,2003.0
41.197575270,1985.0
41.247709077,1955.0
41.297842884,2003.0
41.347976691,1923.0
41.398110497,1955.0
41.448244304,2065.0
41.498378111,2048.0
41.548511918,1963.0
41.598645725,1995.0
41.648779532,2062.0
41.698913339,1942.0
41.749047146,2033.0
41.799180953,2024.0
41.849314760,1995.0
41.899448567,1960.0
41.949582374,1950.0
41.999716181,1963.0
42.049849988,1976.0
42.099983795,2023.0
42.150117601,1917.0
42.200251408,1894.0
42.250385215,1977.0
42.300519022,1966.0
42.350652829,1957.0
42.400786636,2021.0
42.450920443,1987.0
42.501054250,1996.0
42.551188057,2070.0
42.601321864,1967.0
42.651455671,1960.0
42.701589478,2059.0
42.751723285,2006.0
42.801857092,2019.0
42.851990899,2092.0
42.902124705,1918.0
42.952258512,2066.0
43.002392319,2011.0
43.052526126,2057.0
43.102659933,2069.0
43.152793740,2092.0
43.202927547,2073.0
43.253061354,2182.0
43.303195161,2119.0
43.353328968,2160.0
43.403462775,2142.0
43.453596582,2221.0
43.503730389,2119.0
43.553864196,2256.0
43.603998003,2289.0
43.654131809,2285.0
43.704265616,2375.0
43.754399423,2518.0
43.804533230,2827.0
43.854667037,3149.0
43.904800844,3354.0
43.954934651,3710.0
44.005068458,4091.0
44.055202265,4870.0
44.105336072,5833.0
44.155469879,7063.0
44.205603686,8693.0
44.255737493,9743.0
44.305871300,10237.0
44.356005107,9130.0
44.406138913,7669.0
44.456272720,5759.0
44.506406527,4340.0
44.556540334,3364.0
44.606674141,2777.0
44.656807948,2547.0
44.706941755,2316.0
44.757075562,2383.0
44.807209369,2201.0
44.857343176,2173.0
44.907476983,2248.0
44.957610790,2128.0
45.007744597,2113.0
45.057878404,2137.0
45.108012211,1997.0
45.158146018,2096.0
45.208279824,2122.0
45.258413631,2126.0
45.308547438,2177.0
45.358681245,2171.0
45.408815052,2120.0
45.458948859,2064.0
45.509082666,2157.0
45.559216473,2083.0
45.609350280,2054.0
45.659484087,1935.0
45.709617894,2033.0
45.759751701,2090.0
45.809885508,2039.0
45.860019315,2073.0
45.910153122,2129.0
45.960286928,2261.0
46.010420735,2491.0
46.060554542,2826.0
46.110688349,3440.0
46.160822156,5018.0
46.210955963,8201.0
46.261089770,3696.0
46.311223577,4699.0
46.361357384,3463.0
46.411491191,2810.0
46.461624998,3162.0
46.511758805,3468.0
46.561892612,3494.0
46.612026419,3318.0
46.662160226,3069.0
46.712294032,2823.0
46.762427839,2406.0
46.812561646,2168.0
46.862695453,2061.0
46.912829260,1922.0
46.962963067,1905.0
47.013096874,1964.0
47.063230681,1954.0
47.113364488,1934.0
47.163498295,1877.0
47.213632102,1943.0
47.263765909,1974.0
47.313899716,1983.0
47.364033523,1821.0
47.414167330,1953.0
47.464301136,1906.0
47.514434943,1825.0
47.564568750,1898.0
47.614702557,1825.0
47.664836364,1849.0
47.714970171,1877.0
47.765103978,1896.0
47.815237785,1843.0
47.865371592,1959.0
47.915505399,1858.0
47.965639206,1828.0
48.015773013,1840.0
48.065906820,1901.0
48.116040627,1915.0
48.166174434,1864.0
48.216308240,1833.0
48.266442047,1923.0
48.316575854,1843.0
48.366709661,1883.0
48.416843468,1870.0
48.466977275,1903.0
48.517111082,1927.0
48.567244889,1861.0
48.617378696,1921.0
48.667512503,1797.0
48.717646310,1857.0
48.767780117,1806.0
48.817913924,1842.0
48.868047731,1850.0
48.918181538,1910.0
48.968315344,1998.0
49.018449151,1845.0
49.068582958,1881.0
49.118716765,1838.0
49.168850572,1833.0
49.218984379,1840.0
49.269118186,1868.0
49.319251993,1888.0
49.369385800,1972.0
49.419519607,1998.0
49.469653414,2049.0
49.519787221,1971.0
49.569921028,2040.0
49.620054835,1902.0
49.670188642,1952.0
49.720322449,1810.0
49.770456255,1877.0
49.820590062,1922.0
49.870723869,1894.0
49.920857676,1969.0
49.970991483,1818.0
50.021125290,1903.0
50.071259097,1903.0
50.121392904,1880.0
50.171526711,1906.0
50.221660518,1910.0
50.271794325,1976.0
50.321928132,2089.0
50.372061939,2235.0
50.422195746,2301.0
50.472329553,2281.0
50.522463359,2217.0
50.572597166,2190.0
50.622730973,2139.0
50.672864780,1956.0
50.722998587,1964.0
50.773132394,1985.0
50.823266201,2006.0
50.873400008,1989.0
50.923533815,2002.0
50.973667622,2128.0
51.023801429,2051.0
51.073935236,2165.0
51.124069043,2184.0
51.174202850,2274.0
51.224336657,2334.0
51.274470463,2714.0
51.324604270,2850.0
51.374738077,3066.0
51.424871884,3509.0
51.475005691,3856.0
51.525139498,4188.0
51.575273305,4324.0
51.625407112,4258.0
51.675540919,4050.0
51.725674726,3650.0
51.775808533,3221.0
51.825942340,2866.0
51.876076147,2466.0
51.926209954,2303.0
51.976343761,2308.0
52.026477567,2053.0
52.076611374,2053.0
52.126745181,2060.0
52.176878988,1993.0
52.227012795,1850.0
52.277146602,1900.0
52.327280409,1900.0
52.377414216,1871.0
52.427548023,1858.0
52.477681830,1842.0
52.527815637,1769.0
52.577949444,1849.0
52.628083251,1812.0
52.678217058,1785.0
52.728350865,1841.0
52.778484671,1757.0
52.828618478,1870.0
52.878752285,1753.0
52.928886092,1804.0
52.979019899,1832.0
53.029153706,1759.0
53.079287513,1813.0
53.129421320,1771.0
53.179555127,1842.0
53.229688934,1861.0
53.279822741,1821.0
53.329956548,1818.0
53.380090355,1779.0
53.430224162,1753.0
53.480357969,1754.0
53.530491776,1827.0
53.580625582,1806.0
53.630759389,1728.0
53.680893196,1813.0
53.731027003,1783.0
53.781160810,1751.0
53.831294617,1746.0
53.881428424,1785.0
53.931562231,1806.0
53.981696038,1762.0
54.031829845,1748.0
54.081963652,1753.0
54.132097459,1827.0
54.182231266,1796.0
54.232365073,1766.0
54.282498880,1769.0
54.332632686,1775.0
54.382766493,1822.0
54.432900300,1771.0
54.483034107,1842.0
54.533167914,1757.0
54.583301721,1766.0
54.633435528,1746.0
54.683569335,1853.0
54.733703142,1820.0
54.783836949,1677.0
54.833970756,1782.0
54.884104563,1774.0
54.934238370,1794.0
54.984372177,1787.0
55.034505984,1686.0
55.084639790,1756.0
55.134773597,1713.0
55.184907404,1824.0
55.235041211,1716.0
55.285175018,1762.0
55.335308825,1772.0
55.385442632,1839.0
55.435576439,1773.0
55.485710246,1712.0
55.535844053,1826.0
55.585977860,1738.0
55.636111667,1806.0
55.686245474,1746.0
55.736379281,1724.0
55.786513088,1774.0
55.836646894,1854.0
55.886780701,1824.0
55.936914508,1726.0
55.987048315,1728.0
56.037182122,1815.0
56.087315929,1737.0
56.137449736,1830.0
56.187583543,1727.0
56.237717350,1794.0
56.287851157,1748.0
56.337984964,1690.0
56.388118771,1780.0
56.438252578,1744.0
56.488386385,1742.0
56.538520192,1801.0
56.588653998,1822.0
56.638787805,1746.0
56.688921612,1796.0
56.739055419,1754.0
56.789189226,1762.0
56.839323033,1743.0
56.889456840,1802.0
56.939590647,1826.0
56.989724454,1757.0
57.039858261,1731.0
57.089992068,1688.0
57.140125875,1712.0
57.190259682,1778.0
57.240393489,1775.0
57.290527296,1759.0
57.340661102,1754.0
57.390794909,1710.0
57.440928716,1759.0
57.491062523,1734.0
57.541196330,1730.0
57.591330137,1752.0
57.641463944,1793.0
57.691597751,1806.0
57.741731558,1784.0
57.791865365,1840.0
57.841999172,1759.0
57.892132979,1848.0
57.942266786,1654.0
57.992400593,1800.0
58.042534400,1744.0
58.092668207,1823.0
58.142802013,1782.0
58.192935820,1757.0
58.243069627,1893.0
58.293203434,1742.0
58.343337241,1797.0
58.393471048,1796.0
58.443604855,1820.0
58.493738662,1818.0
58.543872469,1743.0
58.594006276,1841.0
58.644140083,1829.0
58.694273890,1787.0
58.744407697,1764.0
58.794541504,1883.0
58.844675311,1772.0
58.894809117,1708.0
58.944942924,1761.0
58.995076731,1776.0
59.045210538,1860.0
59.095344345,1787.0
59.145478152,1759.0
59.195611959,1802.0
59.245745766,1744.0
59.295879573,1702.0
59.346013380,1802.0
59.396147187,1779.0
59.446280994,1843.0
59.496414801,1758.0
59.546548608,1801.0
59.596682415,1789.0
59.646816221,1752.0
59.696950028,1775.0
59.747083835,1851.0
59.797217642,1747.0
59.847351449,1779.0
59.897485256,1792.0
59.947619063,1831.0
59.997752870,1767.0
60.047886677,1817.0
60.098020484,1810.0
60.148154291,1752.0
60.198288098,1803.0
60.248421905,1819.0
60.298555712,1775.0
60.348689519,1850.0
60.398823325,1758.0
60.448957132,1849.0
60.499090939,1880.0
60.549224746,1759.0
60.599358553,1829.0
60.649492360,1756.0
60.699626167,1801.0
60.749759974,1745.0
60.799893781,1838.0
60.850027588,1840.0
60.900161395,1847.0
60.950295202,1833.0
61.000429009,1841.0
61.050562816,1834.0
61.100696623,1855.0
61.150830429,1819.0
61.200964236,1784.0
61.251098043,1868.0
61.301231850,1816.0
61.351365657,1805.0
61.401499464,1758.0
61.451633271,1884.0
61.501767078,1875.0
61.551900885,1897.0
61.602034692,1832.0
61.652168499,1821.0
61.702302306,1861.0
61.752436113,1851.0
61.802569920,1886.0
61.852703727,1927.0
61.902837533,1788.0
61.952971340,1893.0
62.003105147,1894.0
62.053238954,1859.0
62.103372761,1820.0
62.153506568,1817.0
62.203640375,1821.0
62.253774182,1868.0
62.303907989,1881.0
62.354041796,1954.0
62.404175603,1965.0
62.454309410,1866.0
62.504443217,1909.0
62.554577024,1914.0
62.604710831,1883.0
62.654844638,1903.0
62.704978444,1887.0
62.755112251,1844.0
62.805246058,1939.0
62.855379865,1858.0
62.905513672,1884.0
62.955647479,1751.0
63.005781286,2011.0
63.055915093,1893.0
63.106048900,1923.0
63.156182707,1870.0
63.206316514,1858.0
63.256450321,1938.0
63.306584128,1870.0
63.356717935,1971.0
63.406851742,1879.0
63.456985548,1961.0
63.507119355,1915.0
63.557253162,1915.0
63.607386969,2094.0
63.657520776,1953.0
63.707654583,1946.0
63.757788390,1962.0
63.807922197,1998.0
63.858056004,1917.0
63.908189811,1846.0
63.958323618,2008.0
64.008457425,1986.0
64.058591232,1908.0
64.108725039,2010.0
64.158858846,2008.0
64.208992652,2023.0
64.259126459,2010.0
64.309260266,1997.0
64.359394073,2013.0
64.409527880,1968.0
64.459661687,1868.0
64.509795494,1937.0
64.559929301,1977.0
64.610063108,1848.0
64.660196915,1943.0
64.710330722,1986.0
64.760464529,1895.0
64.810598336,2001.0
64.860732143,1933.0
64.910865950,2024.0
64.960999756,1954.0
65.011133563,2002.0
65.061267370,2049.0
65.111401177,2017.0
65.161534984,1979.0
65.211668791,2128.0
65.261802598,1975.0
65.311936405,2037.0
65.362070212,2066.0
65.412204019,2045.0
65.462337826,2029.0
65.512471633,1994.0
65.562605440,2104.0
65.612739247,1953.0
65.662873054,2099.0
65.713006860,2060.0
65.763140667,2040.0
65.813274474,2027.0
65.863408281,2057.0
65.913542088,2040.0
65.963675895,2036.0
66.013809702,2071.0
66.063943509,2112.0
66.114077316,1959.0
66.164211123,2041.0
66.214344930,2068.0
66.264478737,2004.0
66.314612544,2095.0
66.364746351,2006.0
66.414880158,2139.0
66.465013964,2022.0
66.515147771,2021.0
66.565281578,2008.0
66.615415385,1965.0
66.665549192,2008.0
66.715682999,1985.0
66.765816806,2008.0
66.815950613,2038.0
66.866084420,2055.0
66.916218227,2097.0
66.966352034,2104.0
67.016485841,2063.0
67.066619648,2009.0
67.116753455,2087.0
67.166887262,2032.0
67.217021069,2100.0
67.267154875,2126.0
67.317288682,2147.0
67.367422489,2042.0
67.417556296,2157.0
67.467690103,2067.0
67.517823910,2013.0
67.567957717,2024.0
67.618091524,2103.0
67.668225331,2021.0
67.718359138,2086.0
67.768492945,2030.0
67.818626752,2134.0
67.868760559,2078.0
67.918894366,2061.0
67.969028173,2072.0
68.019161979,2103.0
68.069295786,2054.0
68.119429593,2124.0
68.169563400,2090.0
68.219697207,2131.0
68.269831014,2064.0
68.319964821,2078.0
68.370098628,2044.0
68.420232435,2021.0
68.470366242,2098.0
68.520500049,2055.0
68.570633856,2025.0
68.620767663,2089.0
68.670901470,2031.0
68.721035277,2058.0
68.771169083,2085.0
68.821302890,1994.0
68.871436697,1992.0
68.921570504,2047.0
68.971704311,2014.0
69.021838118,2121.0
69.071971925,2122.0
69.122105732,2061.0
69.172239539,2037.0
69.222373346,1940.0
69.272507153,2086.0
69.322640960,1967.0
69.372774767,2027.0
69.422908574,2060.0
69.473042381,1990.0
69.523176187,1996.0
69.573309994,1962.0
69.623443801,2011.0
69.673577608,2050.0
69.723711415,1967.0
69.773845222,1980.0
69.823979029,2009.0
69.874112836,2025.0
69.924246643,2022.0
69.974380450,1874.0
70.024514257,1972.0
70.074648064,1977.0
70.124781871,2031.0
70.174915678,1950.0
70.225049485,1962.0
70.275183291,1979.0
70.325317098,2009.0
70.375450905,2001.0
70.425584712,2057.0
70.475718519,1978.0
70.525852326,1976.0
70.575986133,1977.0
70.626119940,2008.0
70.676253747,1925.0
70.726387554,1995.0
70.776521361,1997.0
70.826655168,1964.0
70.876788975,2008.0
70.926922782,1985.0
70.977056589,1972.0
71.027190396,1934.0
71.077324202,1919.0
71.127458009,2031.0
71.177591816,1995.0
71.227725623,1979.0
71.277859430,1975.0
71.327993237,1960.0
71.378127044,1862.0
71.428260851,1951.0
71.478394658,1986.0
71.528528465,1946.0
71.578662272,1860.0
71.628796079,1947.0
71.678929886,1855.0
71.729063693,1953.0
71.779197500,1895.0
71.829331306,1835.0
71.879465113,1841.0
71.929598920,1886.0
71.979732727,1887.0
72.029866534,1860.0
72.080000341,1890.0
72.130134148,1928.0
72.180267955,1932.0
72.230401762,1961.0
72.280535569,1922.0
72.330669376,1947.0
72.380803183,1857.0
72.430936990,1907.0
72.481070797,1821.0
72.531204604,1890.0
72.581338410,1866.0
72.631472217,1817.0
72.681606024,1810.0
72.731739831,1848.0
72.781873638,1837.0
72.832007445,1828.0
72.882141252,1812.0
72.932275059,1826.0
72.982408866,1898.0
73.032542673,1830.0
73.082676480,1851.0
73.132810287,1898.0
73.182944094,1828.0
73.233077901,1837.0
73.283211708,1903.0
73.333345514,1839.0
73.383479321,1786.0
73.433613128,1794.0
73.483746935,1878.0
73.533880742,1834.0
73.584014549,1798.0
73.634148356,1825.0
73.684282163,1813.0
73.734415970,1841.0
73.784549777,1806.0
73.834683584,1840.0
73.884817391,1795.0
73.934951198,1790.0
73.985085005,1831.0
74.035218812,1798.0
74.085352618,1773.0
74.135486425,1791.0
74.185620232,1779.0
74.235754039,1829.0
74.285887846,1743.0
74.336021653,1813.0
74.386155460,1751.0
74.436289267,1825.0
74.486423074,1773.0
74.536556881,1687.0
74.586690688,1815.0
74.636824495,1816.0
74.686958302,1792.0
74.737092109,1809.0
74.787225916,1824.0
74.837359722,1791.0
74.887493529,1849.0
74.937627336,1785.0
74.987761143,1795.0
75.037894950,1742.0
75.088028757,1805.0
75.138162564,1838.0
75.188296371,1803.0
75.238430178,1869.0
75.288563985,1844.0
75.338697792,1895.0
75.388831599,1933.0
75.438965406,1747.0
75.489099213,1958.0
75.539233020,1937.0
75.589366827,1991.0
75.639500633,1950.0
75.689634440,2052.0
75.739768247,2120.0
75.789902054,2176.0
75.840035861,2195.0
75.890169668,2220.0
75.940303475,2417.0
75.990437282,2333.0
76.040571089,2290.0
76.090704896,2302.0
76.140838703,2197.0
76.190972510,2120.0
76.241106317,2111.0
76.291240124,1927.0
76.341373931,1907.0
76.391507737,1845.0
76.441641544,1831.0
76.491775351,1742.0
76.541909158,1780.0
76.592042965,1743.0
76.642176772,1669.0
76.692310579,1696.0
76.742444386,1817.0
76.792578193,1725.0
76.842712000,1613.0
76.892845807,1673.0
76.942979614,1580.0
76.993113421,1641.0
77.043247228,1655.0
77.093381035,1680.0
77.143514841,1654.0
77.193648648,1732.0
77.243782455,1606.0
77.293916262,1672.0
77.344050069,1651.0
77.394183876,1665.0
77.444317683,1656.0
77.494451490,1645.0
77.544585297,1663.0
77.594719104,1643.0
77.644852911,1676.0
77.694986718,1659.0
77.745120525,1636.0
77.795254332,1594.0
77.845388139,1623.0
77.895521945,1596.0
77.945655752,1649.0
77.995789559,1767.0
78.045923366,1635.0
78.096057173,1634.0
78.146190980,1588.0
78.196324787,1554.0
78.246458594,1555.0
78.296592401,1606.0
78.346726208,1583.0
78.396860015,1590.0
78.446993822,1623.0
78.497127629,1560.0
78.547261436,1544.0
78.597395243,1578.0
78.647529049,1522.0
78.697662856,1587.0
78.747796663,1597.0
78.797930470,1587.0
78.848064277,1540.0
78.898198084,1524.0
78.948331891,1497.0
78.998465698,1624.0
79.048599505,1579.0
79.098733312,1588.0
79.148867119,1622.0
79.199000926,1529.0
79.249134733,1563.0
79.299268540,1570.0
79.349402347,1513.0
79.399536153,1530.0
79.449669960,1505.0
79.499803767,1528.0
79.549937574,1529.0
79.600071381,1543.0
79.650205188,1619.0
79.700338995,1545.0
79.750472802,1620.0
79.800606609,1542.0
79.850740416,1542.0
79.900874223,1567.0
79.951008030,1434.0
80.001141837,1536.0
80.051275644,1556.0
80.101409451,1626.0
80.151543258,1485.0
80.201677064,1538.0
80.251810871,1494.0
80.301944678,1516.0
80.352078485,1531.0
80.402212292,1554.0
80.452346099,1547.0
80.502479906,1461.0
80.552613713,1555.0
80.602747520,1516.0
80.652881327,1553.0
80.703015134,1561.0
80.753148941,1451.0
80.803282748,1481.0
80.853416555,1521.0
80.903550362,1486.0
80.953684168,1519.0
81.003817975,1524.0
81.053951782,1451.0
81.104085589,1517.0
81.154219396,1481.0
81.204353203,1498.0
81.254487010,1443.0
81.304620817,1500.0
81.354754624,1516.0
81.404888431,1569.0
81.455022238,1463.0
81.505156045,1568.0
81.555289852,1512.0
81.605423659,1457.0
81.655557466,1471.0
81.705691272,1453.0
81.755825079,1433.0
81.805958886,1365.0
81.856092693,1452.0
81.906226500,1508.0
81.956360307,1468.0
82.006494114,1468.0
82.056627921,1511.0
82.106761728,1530.0
82.156895535,1441.0
82.207029342,1497.0
82.257163149,1505.0
82.307296956,1445.0
82.357430763,1395.0
82.407564570,1464.0
82.457698376,1467.0
82.507832183,1522.0
82.557965990,1456.0
82.608099797,1396.0
82.658233604,1566.0
82.708367411,1391.0
82.758501218,1409.0
82.808635025,1422.0
82.858768832,1492.0
82.908902639,1520.0
82.959036446,1377.0
83.009170253,1476.0
83.059304060,1360.0
83.109437867,1445.0
83.159571674,1394.0
83.209705480,1427.0
83.259839287,1395.0
83.309973094,1458.0
83.360106901,1383.0
83.410240708,1362.0
83.460374515,1518.0
83.510508322,1467.0
83.560642129,1499.0
83.610775936,1422.0
83.660909743,1477.0
83.711043550,1519.0
83.761177357,1449.0
83.811311164,1470.0
83.861444971,1352.0
83.911578778,1399.0
83.961712584,1418.0
84.011846391,1385.0
84.061980198,1447.0
84.112114005,1405.0
84.162247812,1447.0
84.212381619,1454.0
84.262515426,1504.0
84.312649233,1423.0
84.362783040,1402.0
84.412916847,1378.0
84.463050654,1454.0
84.513184461,1437.0
84.563318268,1417.0
84.613452075,1445.0
84.663585882,1380.0
84.713719689,1432.0
84.763853495,1397.0
84.813987302,1440.0
84.864121109,1430.0
84.914254916,1415.0
84.964388723,1467.0
85.014522530,1409.0
85.064656337,1412.0
85.114790144,1403.0
85.164923951,1485.0
85.215057758,1442.0
85.265191565,1370.0
85.315325372,1446.0
85.365459179,1438.0
85.415592986,1437.0
85.465726793,1451.0
85.515860599,1362.0
85.565994406,1412.0
85.616128213,1396.0
85.666262020,1425.0
85.716395827,1360.0
85.766529634,1313.0
85.816663441,1442.0
85.866797248,1502.0
85.916931055,1428.0
85.967064862,1398.0
86.017198669,1423.0
86.067332476,1470.0
86.117466283,1422.0
86.167600090,1357.0
86.217733897,1421.0
86.267867703,1403.0
86.318001510,1423.0
86.368135317,1364.0
86.418269124,1489.0
86.468402931,1442.0
86.518536738,1370.0
86.568670545,1386.0
86.618804352,1421.0
86.668938159,1358.0
86.719071966,1378.0
86.769205773,1410.0
86.819339580,1311.0
86.869473387,1338.0
86.919607194,1400.0
86.969741001,1425.0
87.019874807,1357.0
87.070008614,1367.0
87.120142421,1405.0
87.170276228,1339.0
87.220410035,1330.0
87.270543842,1377.0
87.320677649,1387.0
87.370811456,1407.0
87.420945263,1412.0
87.471079070,1388.0
87.521212877,1350.0
87.571346684,1376.0
87.621480491,1384.0
87.671614298,1399.0
87.721748105,1507.0
87.771881911,1399.0
87.822015718,1343.0
87.872149525,1313.0
87.922283332,1395.0
87.972417139,1304.0
88.022550946,1381.0
88.072684753,1363.0
88.122818560,1344.0
88.172952367,1397.0
88.223086174,1362.0
88.273219981,1326.0
88.323353788,1372.0
88.373487595,1327.0
88.423621402,1358.0
88.473755209,1370.0
88.523889016,1375.0
88.574022822,1338.0
88.624156629,1356.0
88.674290436,1353.0
88.724424243,1346.0
88.774558050,1383.0
88.824691857,1399.0
88.874825664,1342.0
88.924959471,1283.0
88.975093278,1308.0
89.025227085,1407.0
89.075360892,1342.0
89.125494699,1368.0
89.175628506,1310.0
89.225762313,1370.0
89.275896120,1375.0
89.326029926,1290.0
89.376163733,1344.0
89.426297540,1331.0
89.476431347,1403.0
89.526565154,1384.0
89.576698961,1339.0
89.626832768,1389.0
89.676966575,1388.0
89.727100382,1354.0
89.777234189,1348.0
89.827367996,1365.0
89.877501803,1319.0
89.927635610,1463.0
89.977769417,1326.0
90.027903224,1356.0
90.078037030,1305.0
90.128170837,1353.0
90.178304644,1314.0
90.228438451,1398.0
90.278572258,1349.0
90.328706065,1422.0
90.378839872,1302.0
90.428973679,1348.0
90.479107486,1355.0
90.529241293,1361.0
90.579375100,1375.0
90.629508907,1389.0
90.679642714,1319.0
90.729776521,1409.0
90.779910328,1250.0
90.830044134,1322.0
90.880177941,1379.0
90.930311748,1425.0
90.980445555,1332.0
91.030579362,1424.0
91.080713169,1334.0
91.130846976,1400.0
91.180980783,1445.0
91.231114590,1375.0
91.281248397,1399.0
91.331382204,1403.0
91.381516011,1400.0
91.431649818,1427.0
91.481783625,1447.0
91.531917432,1457.0
91.582051238,1447.0
91.632185045,1400.0
91.682318852,1504.0
91.732452659,1405.0
91.782586466,1481.0
91.832720273,1435.0
91.882854080,1443.0
91.932987887,1543.0
91.983121694,1637.0
92.033255501,1615.0
92.083389308,1636.0
92.133523115,1663.0
92.183656922,1737.0
92.233790729,1777.0
92.283924536,1878.0
92.334058342,1846.0
92.384192149,1801.0
92.434325956,1836.0
92.484459763,1745.0
92.534593570,1708.0
92.584727377,1762.0
92.634861184,1620.0
92.684994991,1654.0
92.735128798,1554.0
92.785262605,1553.0
92.835396412,1409.0
92.885530219,1464.0
92.935664026,1477.0
92.985797833,1423.0
93.035931640,1418.0
93.086065447,1358.0
93.136199253,1330.0
93.186333060,1393.0
93.236466867,1338.0
93.286600674,1297.0
93.336734481,1342.0
93.386868288,1319.0
93.437002095,1339.0
93.487135902,1300.0
93.537269709,1304.0
93.587403516,1330.0
93.637537323,1327.0
93.687671130,1345.0
93.737804937,1322.0
93.787938744,1309.0
93.838072551,1302.0
93.888206357,1317.0
93.938340164,1383.0
93.988473971,1310.0
94.038607778,1271.0
94.088741585,1324.0
94.138875392,1266.0
94.189009199,1277.0
94.239143006,1336.0
94.289276813,1411.0
94.339410620,1339.0
94.389544427,1270.0
94.439678234,1323.0
94.489812041,1298.0
94.539945848,1302.0
94.590079655,1369.0
94.640213461,1345.0
94.690347268,1280.0
94.740481075,1232.0
94.790614882,1308.0
94.840748689,1274.0
94.890882496,1283.0
94.941016303,1278.0
94.991150110,1296.0