File: OriginPro/XRD from Panalytical X'Pert PRO/In-Situ/FicheirosXRD_Insitu/NiNws_Inicio_30°C.csv
[Measurement conditions]
Sample identification,
Comment - 1,"finito"
Comment - 2,"Configuration=MRI TC-Basic Stage, Owner=User-1, Creation date=26-10-2009 9:18:44"
Comment - 3,"Goniometer=PW3050/60 (Theta/Theta); Minimum step size 2Theta:0.001; Minimum step size Omega:0.001"
Comment - 4,"Sample stage=MRI TC-Basic (PtRh heat strip)"
Comment - 5,"Diffractometer system=XPERT-PRO"
Comment - 6,"Measurement program=FS-L, Owner=joana, Creation date=25-11-2014 17:28:08"
Anode material,Cu
K-Alpha1 wavelength,1.5405980
K-Alpha2 wavelength,1.5444260
Ratio K-Alpha2/K-Alpha1,0.500
Divergence slit,Fixed,0.76mm
Monochromator used,NO
Generator voltage, 45
Tube current, 40
File date and time,15-Dez-2017 16:06
Unit cell,
h k l, 0 0 0
Temperature [K],301
Scan axis,Gonio
Scan range,24.995999996,94.999505744
Scan step size,0.0167113
No. of points, 4189
Scan type,CONTINUOUS
Time per step,118.110
[Scan points]
Angle,Intensity
25.004355630,2324.0
25.054489437,2303.0
25.104623244,2366.0
25.154757051,2256.0
25.204890858,2282.0
25.255024665,2279.0
25.305158472,2271.0
25.355292279,2229.0
25.405426085,2270.0
25.455559892,2242.0
25.505693699,2279.0
25.555827506,2285.0
25.605961313,2192.0
25.656095120,2387.0
25.706228927,2272.0
25.756362734,2301.0
25.806496541,2361.0
25.856630348,2252.0
25.906764155,2294.0
25.956897962,2307.0
26.007031769,2232.0
26.057165576,2228.0
26.107299383,2287.0
26.157433189,2279.0
26.207566996,2340.0
26.257700803,2260.0
26.307834610,2235.0
26.357968417,2274.0
26.408102224,2225.0
26.458236031,2249.0
26.508369838,2254.0
26.558503645,2218.0
26.608637452,2297.0
26.658771259,2248.0
26.708905066,2268.0
26.759038873,2349.0
26.809172680,2210.0
26.859306487,2245.0
26.909440293,2358.0
26.959574100,2163.0
27.009707907,2228.0
27.059841714,2188.0
27.109975521,2204.0
27.160109328,2231.0
27.210243135,2265.0
27.260376942,2278.0
27.310510749,2250.0
27.360644556,2142.0
27.410778363,2247.0
27.460912170,2193.0
27.511045977,2269.0
27.561179784,2220.0
27.611313591,2227.0
27.661447398,2270.0
27.711581204,2198.0
27.761715011,2333.0
27.811848818,2221.0
27.861982625,2217.0
27.912116432,2217.0
27.962250239,2170.0
28.012384046,2230.0
28.062517853,2173.0
28.112651660,2137.0
28.162785467,2237.0
28.212919274,2165.0
28.263053081,2277.0
28.313186888,2365.0
28.363320695,2384.0
28.413454502,2365.0
28.463588308,2403.0
28.513722115,2385.0
28.563855922,2338.0
28.613989729,2494.0
28.664123536,2348.0
28.714257343,2314.0
28.764391150,2385.0
28.814524957,2221.0
28.864658764,2288.0
28.914792571,2227.0
28.964926378,2309.0
29.015060185,2118.0
29.065193992,2242.0
29.115327799,2271.0
29.165461606,2214.0
29.215595412,2311.0
29.265729219,2192.0
29.315863026,2274.0
29.365996833,2179.0
29.416130640,2204.0
29.466264447,2181.0
29.516398254,2146.0
29.566532061,2251.0
29.616665868,2148.0
29.666799675,2182.0
29.716933482,2226.0
29.767067289,2191.0
29.817201096,2185.0
29.867334903,2078.0
29.917468710,2136.0
29.967602516,2082.0
30.017736323,2181.0
30.067870130,2159.0
30.118003937,2141.0
30.168137744,2144.0
30.218271551,2205.0
30.268405358,2124.0
30.318539165,2038.0
30.368672972,2191.0
30.418806779,2094.0
30.468940586,2177.0
30.519074393,2159.0
30.569208200,2069.0
30.619342007,2147.0
30.669475814,2135.0
30.719609620,2116.0
30.769743427,2140.0
30.819877234,2112.0
30.870011041,2165.0
30.920144848,2152.0
30.970278655,2166.0
31.020412462,2212.0
31.070546269,2046.0
31.120680076,2135.0
31.170813883,2229.0
31.220947690,2092.0
31.271081497,2195.0
31.321215304,2160.0
31.371349111,2134.0
31.421482918,2045.0
31.471616724,2175.0
31.521750531,2110.0
31.571884338,2121.0
31.622018145,2173.0
31.672151952,2132.0
31.722285759,2144.0
31.772419566,2119.0
31.822553373,2109.0
31.872687180,2061.0
31.922820987,2090.0
31.972954794,2201.0
32.023088601,2101.0
32.073222408,2173.0
32.123356215,2071.0
32.173490022,2129.0
32.223623829,2095.0
32.273757635,2171.0
32.323891442,2139.0
32.374025249,2099.0
32.424159056,2196.0
32.474292863,2081.0
32.524426670,2080.0
32.574560477,2174.0
32.624694284,2159.0
32.674828091,2131.0
32.724961898,2104.0
32.775095705,2095.0
32.825229512,2165.0
32.875363319,2086.0
32.925497126,2159.0
32.975630933,2146.0
33.025764739,2079.0
33.075898546,2122.0
33.126032353,2089.0
33.176166160,2091.0
33.226299967,2144.0
33.276433774,2155.0
33.326567581,2086.0
33.376701388,2126.0
33.426835195,2101.0
33.476969002,2141.0
33.527102809,2088.0
33.577236616,2165.0
33.627370423,2029.0
33.677504230,2013.0
33.727638037,2086.0
33.777771843,2130.0
33.827905650,2026.0
33.878039457,2198.0
33.928173264,2124.0
33.978307071,2147.0
34.028440878,2014.0
34.078574685,2062.0
34.128708492,2173.0
34.178842299,2037.0
34.228976106,2096.0
34.279109913,2061.0
34.329243720,2018.0
34.379377527,2073.0
34.429511334,2021.0
34.479645141,2019.0
34.529778947,2124.0
34.579912754,2091.0
34.630046561,2140.0
34.680180368,2103.0
34.730314175,2035.0
34.780447982,2128.0
34.830581789,2033.0
34.880715596,2034.0
34.930849403,2039.0
34.980983210,2100.0
35.031117017,2054.0
35.081250824,2168.0
35.131384631,2129.0
35.181518438,2030.0
35.231652245,2020.0
35.281786051,2118.0
35.331919858,2136.0
35.382053665,2092.0
35.432187472,2080.0
35.482321279,1940.0
35.532455086,2015.0
35.582588893,2092.0
35.632722700,2011.0
35.682856507,2160.0
35.732990314,2035.0
35.783124121,2035.0
35.833257928,2113.0
35.883391735,2056.0
35.933525542,2058.0
35.983659349,1999.0
36.033793156,2085.0
36.083926962,2098.0
36.134060769,1976.0
36.184194576,2006.0
36.234328383,2049.0
36.284462190,2124.0
36.334595997,2046.0
36.384729804,2010.0
36.434863611,2079.0
36.484997418,2088.0
36.535131225,1939.0
36.585265032,2051.0
36.635398839,2021.0
36.685532646,2015.0
36.735666453,2057.0
36.785800260,1995.0
36.835934066,1989.0
36.886067873,1947.0
36.936201680,1985.0
36.986335487,1977.0
37.036469294,2059.0
37.086603101,1977.0
37.136736908,2082.0
37.186870715,2072.0
37.237004522,2100.0
37.287138329,2041.0
37.337272136,1948.0
37.387405943,1978.0
37.437539750,2066.0
37.487673557,2114.0
37.537807364,2055.0
37.587941170,2063.0
37.638074977,1957.0
37.688208784,2012.0
37.738342591,2041.0
37.788476398,1988.0
37.838610205,2063.0
37.888744012,2050.0
37.938877819,2028.0
37.989011626,2074.0
38.039145433,1995.0
38.089279240,2043.0
38.139413047,2052.0
38.189546854,2157.0
38.239680661,2114.0
38.289814468,2037.0
38.339948274,2048.0
38.390082081,2004.0
38.440215888,2071.0
38.490349695,1999.0
38.540483502,1973.0
38.590617309,2027.0
38.640751116,2031.0
38.690884923,1930.0
38.741018730,1989.0
38.791152537,1989.0
38.841286344,2036.0
38.891420151,2037.0
38.941553958,1983.0
38.991687765,2027.0
39.041821572,1922.0
39.091955378,1959.0
39.142089185,1993.0
39.192222992,2070.0
39.242356799,2030.0
39.292490606,1984.0
39.342624413,2003.0
39.392758220,2027.0
39.442892027,2027.0
39.493025834,2107.0
39.543159641,2057.0
39.593293448,2072.0
39.643427255,2003.0
39.693561062,2104.0
39.743694869,2134.0
39.793828676,2334.0
39.843962482,2309.0
39.894096289,2157.0
39.944230096,2165.0
39.994363903,2015.0
40.044497710,2128.0
40.094631517,2079.0
40.144765324,2037.0
40.194899131,2052.0
40.245032938,2003.0
40.295166745,2086.0
40.345300552,1892.0
40.395434359,1953.0
40.445568166,1979.0
40.495701973,1957.0
40.545835780,1964.0
40.595969587,2048.0
40.646103393,2012.0
40.696237200,1952.0
40.746371007,2031.0
40.796504814,1973.0
40.846638621,1985.0
40.896772428,1990.0
40.946906235,1981.0
40.997040042,1997.0
41.047173849,1910.0
41.097307656,1992.0
41.147441463,1896.0
41.197575270,2000.0
41.247709077,2008.0
41.297842884,1975.0
41.347976691,1934.0
41.398110497,1933.0
41.448244304,1959.0
41.498378111,2034.0
41.548511918,1903.0
41.598645725,1961.0
41.648779532,1976.0
41.698913339,2009.0
41.749047146,1960.0
41.799180953,1953.0
41.849314760,1973.0
41.899448567,2083.0
41.949582374,2005.0
41.999716181,1973.0
42.049849988,1982.0
42.099983795,1937.0
42.150117601,1943.0
42.200251408,2030.0
42.250385215,2014.0
42.300519022,1960.0
42.350652829,2000.0
42.400786636,1975.0
42.450920443,2053.0
42.501054250,2022.0
42.551188057,1958.0
42.601321864,1961.0
42.651455671,1962.0
42.701589478,1942.0
42.751723285,2061.0
42.801857092,1992.0
42.851990899,2031.0
42.902124705,2023.0
42.952258512,1964.0
43.002392319,2015.0
43.052526126,2051.0
43.102659933,2106.0
43.152793740,2057.0
43.202927547,2035.0
43.253061354,2092.0
43.303195161,2015.0
43.353328968,2032.0
43.403462775,2087.0
43.453596582,2086.0
43.503730389,2156.0
43.553864196,2170.0
43.603998003,2249.0
43.654131809,2183.0
43.704265616,2284.0
43.754399423,2344.0
43.804533230,2377.0
43.854667037,2525.0
43.904800844,2627.0
43.954934651,2817.0
44.005068458,2992.0
44.055202265,3365.0
44.105336072,3666.0
44.155469879,3981.0
44.205603686,4438.0
44.255737493,5183.0
44.305871300,6243.0
44.356005107,7447.0
44.406138913,8946.0
44.456272720,9784.0
44.506406527,9904.0
44.556540334,8838.0
44.606674141,6959.0
44.656807948,5439.0
44.706941755,4086.0
44.757075562,3258.0
44.807209369,2836.0
44.857343176,2592.0
44.907476983,2315.0
44.957610790,2322.0
45.007744597,2117.0
45.057878404,2132.0
45.108012211,2149.0
45.158146018,2174.0
45.208279824,2144.0
45.258413631,2077.0
45.308547438,2131.0
45.358681245,2119.0
45.408815052,2119.0
45.458948859,2270.0
45.509082666,2151.0
45.559216473,2043.0
45.609350280,2059.0
45.659484087,2119.0
45.709617894,2120.0
45.759751701,2015.0
45.809885508,2037.0
45.860019315,2044.0
45.910153122,1985.0
45.960286928,2084.0
46.010420735,2043.0
46.060554542,2214.0
46.110688349,2366.0
46.160822156,2864.0
46.210955963,3239.0
46.261089770,4401.0
46.311223577,7367.0
46.361357384,5542.0
46.411491191,4032.0
46.461624998,5371.0
46.511758805,2931.0
46.561892612,2934.0
46.612026419,3258.0
46.662160226,3494.0
46.712294032,3486.0
46.762427839,3339.0
46.812561646,2913.0
46.862695453,2577.0
46.912829260,2203.0
46.962963067,2092.0
47.013096874,2069.0
47.063230681,2037.0
47.113364488,1870.0
47.163498295,1979.0
47.213632102,1934.0
47.263765909,1916.0
47.313899716,1931.0
47.364033523,1902.0
47.414167330,1873.0
47.464301136,1917.0
47.514434943,1934.0
47.564568750,1879.0
47.614702557,1818.0
47.664836364,1905.0
47.714970171,1933.0
47.765103978,1866.0
47.815237785,1883.0
47.865371592,1870.0
47.915505399,1820.0
47.965639206,1904.0
48.015773013,1914.0
48.065906820,1911.0
48.116040627,1850.0
48.166174434,1839.0
48.216308240,1744.0
48.266442047,1853.0
48.316575854,1891.0
48.366709661,1874.0
48.416843468,1909.0
48.466977275,1886.0
48.517111082,1882.0
48.567244889,1868.0
48.617378696,1819.0
48.667512503,1835.0
48.717646310,1880.0
48.767780117,1798.0
48.817913924,1811.0
48.868047731,1840.0
48.918181538,1826.0
48.968315344,1866.0
49.018449151,1840.0
49.068582958,1894.0
49.118716765,1851.0
49.168850572,1872.0
49.218984379,1868.0
49.269118186,1898.0
49.319251993,1866.0
49.369385800,1887.0
49.419519607,1885.0
49.469653414,1842.0
49.519787221,1880.0
49.569921028,2053.0
49.620054835,2046.0
49.670188642,2007.0
49.720322449,1911.0
49.770456255,1858.0
49.820590062,1872.0
49.870723869,1844.0
49.920857676,1839.0
49.970991483,1878.0
50.021125290,1805.0
50.071259097,1853.0
50.121392904,1818.0
50.171526711,1845.0
50.221660518,1892.0
50.271794325,1898.0
50.321928132,1881.0
50.372061939,1938.0
50.422195746,1935.0
50.472329553,2043.0
50.522463359,2117.0
50.572597166,2265.0
50.622730973,2304.0
50.672864780,2249.0
50.722998587,2197.0
50.773132394,2053.0
50.823266201,1980.0
50.873400008,2038.0
50.923533815,1962.0
50.973667622,1991.0
51.023801429,2001.0
51.073935236,1976.0
51.124069043,2027.0
51.174202850,2131.0
51.224336657,2043.0
51.274470463,2124.0
51.324604270,2203.0
51.374738077,2290.0
51.424871884,2422.0
51.475005691,2535.0
51.525139498,2791.0
51.575273305,2967.0
51.625407112,3211.0
51.675540919,3654.0
51.725674726,3974.0
51.775808533,4127.0
51.825942340,4392.0
51.876076147,4190.0
51.926209954,3844.0
51.976343761,3446.0
52.026477567,3022.0
52.076611374,2691.0
52.126745181,2485.0
52.176878988,2269.0
52.227012795,2087.0
52.277146602,2022.0
52.327280409,2059.0
52.377414216,1906.0
52.427548023,1926.0
52.477681830,1928.0
52.527815637,1926.0
52.577949444,1843.0
52.628083251,1849.0
52.678217058,1798.0
52.728350865,1714.0
52.778484671,1786.0
52.828618478,1838.0
52.878752285,1722.0
52.928886092,1719.0
52.979019899,1765.0
53.029153706,1695.0
53.079287513,1794.0
53.129421320,1807.0
53.179555127,1739.0
53.229688934,1790.0
53.279822741,1731.0
53.329956548,1763.0
53.380090355,1782.0
53.430224162,1680.0
53.480357969,1756.0
53.530491776,1806.0
53.580625582,1767.0
53.630759389,1645.0
53.680893196,1812.0
53.731027003,1728.0
53.781160810,1724.0
53.831294617,1756.0
53.881428424,1743.0
53.931562231,1712.0
53.981696038,1684.0
54.031829845,1781.0
54.081963652,1656.0
54.132097459,1708.0
54.182231266,1793.0
54.232365073,1728.0
54.282498880,1766.0
54.332632686,1673.0
54.382766493,1676.0
54.432900300,1712.0
54.483034107,1698.0
54.533167914,1649.0
54.583301721,1815.0
54.633435528,1727.0
54.683569335,1722.0
54.733703142,1712.0
54.783836949,1755.0
54.833970756,1778.0
54.884104563,1714.0
54.934238370,1673.0
54.984372177,1638.0
55.034505984,1731.0
55.084639790,1741.0
55.134773597,1710.0
55.184907404,1751.0
55.235041211,1706.0
55.285175018,1746.0
55.335308825,1710.0
55.385442632,1705.0
55.435576439,1704.0
55.485710246,1728.0
55.535844053,1698.0
55.585977860,1752.0
55.636111667,1638.0
55.686245474,1701.0
55.736379281,1741.0
55.786513088,1629.0
55.836646894,1712.0
55.886780701,1685.0
55.936914508,1708.0
55.987048315,1686.0
56.037182122,1699.0
56.087315929,1682.0
56.137449736,1770.0
56.187583543,1650.0
56.237717350,1712.0
56.287851157,1685.0
56.337984964,1710.0
56.388118771,1652.0
56.438252578,1723.0
56.488386385,1656.0
56.538520192,1678.0
56.588653998,1687.0
56.638787805,1715.0
56.688921612,1726.0
56.739055419,1715.0
56.789189226,1688.0
56.839323033,1702.0
56.889456840,1717.0
56.939590647,1692.0
56.989724454,1683.0
57.039858261,1709.0
57.089992068,1735.0
57.140125875,1782.0
57.190259682,1656.0
57.240393489,1676.0
57.290527296,1645.0
57.340661102,1716.0
57.390794909,1642.0
57.440928716,1660.0
57.491062523,1770.0
57.541196330,1700.0
57.591330137,1682.0
57.641463944,1637.0
57.691597751,1563.0
57.741731558,1672.0
57.791865365,1735.0
57.841999172,1761.0
57.892132979,1679.0
57.942266786,1635.0
57.992400593,1729.0
58.042534400,1561.0
58.092668207,1653.0
58.142802013,1705.0
58.192935820,1764.0
58.243069627,1742.0
58.293203434,1789.0
58.343337241,1727.0
58.393471048,1656.0
58.443604855,1695.0
58.493738662,1680.0
58.543872469,1695.0
58.594006276,1646.0
58.644140083,1692.0
58.694273890,1688.0
58.744407697,1712.0
58.794541504,1704.0
58.844675311,1666.0
58.894809117,1646.0
58.944942924,1733.0
58.995076731,1648.0
59.045210538,1682.0
59.095344345,1689.0
59.145478152,1750.0
59.195611959,1651.0
59.245745766,1696.0
59.295879573,1704.0
59.346013380,1651.0
59.396147187,1593.0
59.446280994,1668.0
59.496414801,1734.0
59.546548608,1780.0
59.596682415,1637.0
59.646816221,1729.0
59.696950028,1708.0
59.747083835,1702.0
59.797217642,1726.0
59.847351449,1678.0
59.897485256,1713.0
59.947619063,1639.0
59.997752870,1714.0
60.047886677,1658.0
60.098020484,1729.0
60.148154291,1698.0
60.198288098,1705.0
60.248421905,1676.0
60.298555712,1671.0
60.348689519,1655.0
60.398823325,1688.0
60.448957132,1750.0
60.499090939,1742.0
60.549224746,1699.0
60.599358553,1797.0
60.649492360,1689.0
60.699626167,1734.0
60.749759974,1715.0
60.799893781,1645.0
60.850027588,1686.0
60.900161395,1688.0
60.950295202,1675.0
61.000429009,1701.0
61.050562816,1675.0
61.100696623,1717.0
61.150830429,1637.0
61.200964236,1718.0
61.251098043,1763.0
61.301231850,1662.0
61.351365657,1630.0
61.401499464,1723.0
61.451633271,1780.0
61.501767078,1742.0
61.551900885,1731.0
61.602034692,1701.0
61.652168499,1619.0
61.702302306,1683.0
61.752436113,1725.0
61.802569920,1719.0
61.852703727,1698.0
61.902837533,1672.0
61.952971340,1679.0
62.003105147,1685.0
62.053238954,1639.0
62.103372761,1691.0
62.153506568,1680.0
62.203640375,1745.0
62.253774182,1706.0
62.303907989,1651.0
62.354041796,1676.0
62.404175603,1669.0
62.454309410,1685.0
62.504443217,1650.0
62.554577024,1678.0
62.604710831,1739.0
62.654844638,1633.0
62.704978444,1688.0
62.755112251,1632.0
62.805246058,1741.0
62.855379865,1654.0
62.905513672,1744.0
62.955647479,1697.0
63.005781286,1681.0
63.055915093,1706.0
63.106048900,1682.0
63.156182707,1743.0
63.206316514,1677.0
63.256450321,1656.0
63.306584128,1745.0
63.356717935,1689.0
63.406851742,1653.0
63.456985548,1830.0
63.507119355,1787.0
63.557253162,1781.0
63.607386969,1722.0
63.657520776,1695.0
63.707654583,1745.0
63.757788390,1683.0
63.807922197,1705.0
63.858056004,1852.0
63.908189811,1705.0
63.958323618,1714.0
64.008457425,1737.0
64.058591232,1742.0
64.108725039,1750.0
64.158858846,1697.0
64.208992652,1821.0
64.259126459,1847.0
64.309260266,1739.0
64.359394073,1726.0
64.409527880,1757.0
64.459661687,1679.0
64.509795494,1684.0
64.559929301,1753.0
64.610063108,1764.0
64.660196915,1760.0
64.710330722,1732.0
64.760464529,1767.0
64.810598336,1734.0
64.860732143,1799.0
64.910865950,1725.0
64.960999756,1713.0
65.011133563,1749.0
65.061267370,1867.0
65.111401177,1741.0
65.161534984,1731.0
65.211668791,1834.0
65.261802598,1774.0
65.311936405,1711.0
65.362070212,1734.0
65.412204019,1816.0
65.462337826,1818.0
65.512471633,1815.0
65.562605440,1651.0
65.612739247,1795.0
65.662873054,1851.0
65.713006860,1760.0
65.763140667,1735.0
65.813274474,1729.0
65.863408281,1790.0
65.913542088,1774.0
65.963675895,1770.0
66.013809702,1843.0
66.063943509,1742.0
66.114077316,1752.0
66.164211123,1897.0
66.214344930,1645.0
66.264478737,1714.0
66.314612544,1775.0
66.364746351,1816.0
66.414880158,1719.0
66.465013964,1695.0
66.515147771,1745.0
66.565281578,1784.0
66.615415385,1820.0
66.665549192,1816.0
66.715682999,1740.0
66.765816806,1717.0
66.815950613,1793.0
66.866084420,1676.0
66.916218227,1770.0
66.966352034,1698.0
67.016485841,1819.0
67.066619648,1737.0
67.116753455,1770.0
67.166887262,1752.0
67.217021069,1725.0
67.267154875,1815.0
67.317288682,1805.0
67.367422489,1676.0
67.417556296,1827.0
67.467690103,1707.0
67.517823910,1724.0
67.567957717,1807.0
67.618091524,1714.0
67.668225331,1751.0
67.718359138,1841.0
67.768492945,1760.0
67.818626752,1806.0
67.868760559,1839.0
67.918894366,1757.0
67.969028173,1735.0
68.019161979,1857.0
68.069295786,1795.0
68.119429593,1750.0
68.169563400,1784.0
68.219697207,1755.0
68.269831014,1729.0
68.319964821,1742.0
68.370098628,1776.0
68.420232435,1693.0
68.470366242,1714.0
68.520500049,1762.0
68.570633856,1699.0
68.620767663,1644.0
68.670901470,1752.0
68.721035277,1817.0
68.771169083,1705.0
68.821302890,1761.0
68.871436697,1736.0
68.921570504,1736.0
68.971704311,1784.0
69.021838118,1776.0
69.071971925,1690.0
69.122105732,1817.0
69.172239539,1720.0
69.222373346,1748.0
69.272507153,1788.0
69.322640960,1678.0
69.372774767,1758.0
69.422908574,1716.0
69.473042381,1673.0
69.523176187,1707.0
69.573309994,1696.0
69.623443801,1738.0
69.673577608,1755.0
69.723711415,1800.0
69.773845222,1732.0
69.823979029,1672.0
69.874112836,1782.0
69.924246643,1740.0
69.974380450,1644.0
70.024514257,1749.0
70.074648064,1798.0
70.124781871,1757.0
70.174915678,1741.0
70.225049485,1630.0
70.275183291,1722.0
70.325317098,1672.0
70.375450905,1756.0
70.425584712,1670.0
70.475718519,1666.0
70.525852326,1746.0
70.575986133,1644.0
70.626119940,1752.0
70.676253747,1647.0
70.726387554,1650.0
70.776521361,1758.0
70.826655168,1647.0
70.876788975,1732.0
70.926922782,1695.0
70.977056589,1759.0
71.027190396,1776.0
71.077324202,1660.0
71.127458009,1669.0
71.177591816,1665.0
71.227725623,1650.0
71.277859430,1650.0
71.327993237,1675.0
71.378127044,1709.0
71.428260851,1722.0
71.478394658,1617.0
71.528528465,1640.0
71.578662272,1710.0
71.628796079,1554.0
71.678929886,1738.0
71.729063693,1627.0
71.779197500,1686.0
71.829331306,1659.0
71.879465113,1671.0
71.929598920,1711.0
71.979732727,1670.0
72.029866534,1586.0
72.080000341,1682.0
72.130134148,1751.0
72.180267955,1636.0
72.230401762,1702.0
72.280535569,1647.0
72.330669376,1640.0
72.380803183,1670.0
72.430936990,1634.0
72.481070797,1656.0
72.531204604,1586.0
72.581338410,1625.0
72.631472217,1703.0
72.681606024,1701.0
72.731739831,1599.0
72.781873638,1647.0
72.832007445,1696.0
72.882141252,1615.0
72.932275059,1620.0
72.982408866,1606.0
73.032542673,1636.0
73.082676480,1659.0
73.132810287,1623.0
73.182944094,1635.0
73.233077901,1623.0
73.283211708,1632.0
73.333345514,1611.0
73.383479321,1691.0
73.433613128,1615.0
73.483746935,1639.0
73.533880742,1669.0
73.584014549,1553.0
73.634148356,1609.0
73.684282163,1634.0
73.734415970,1610.0
73.784549777,1601.0
73.834683584,1619.0
73.884817391,1683.0
73.934951198,1633.0
73.985085005,1618.0
74.035218812,1682.0
74.085352618,1547.0
74.135486425,1620.0
74.185620232,1600.0
74.235754039,1613.0
74.285887846,1593.0
74.336021653,1626.0
74.386155460,1577.0
74.436289267,1587.0
74.486423074,1620.0
74.536556881,1617.0
74.586690688,1557.0
74.636824495,1620.0
74.686958302,1629.0
74.737092109,1626.0
74.787225916,1660.0
74.837359722,1589.0
74.887493529,1553.0
74.937627336,1668.0
74.987761143,1545.0
75.037894950,1650.0
75.088028757,1696.0
75.138162564,1559.0
75.188296371,1605.0
75.238430178,1657.0
75.288563985,1624.0
75.338697792,1608.0
75.388831599,1622.0
75.438965406,1601.0
75.489099213,1658.0
75.539233020,1638.0
75.589366827,1672.0
75.639500633,1712.0
75.689634440,1708.0
75.739768247,1668.0
75.789902054,1719.0
75.840035861,1793.0
75.890169668,1761.0
75.940303475,1821.0
75.990437282,1862.0
76.040571089,1903.0
76.090704896,1908.0
76.140838703,1943.0
76.190972510,2066.0
76.241106317,2144.0
76.291240124,2092.0
76.341373931,2149.0
76.391507737,2120.0
76.441641544,2052.0
76.491775351,2012.0
76.541909158,1909.0
76.592042965,1895.0
76.642176772,1852.0
76.692310579,1806.0
76.742444386,1643.0
76.792578193,1742.0
76.842712000,1602.0
76.892845807,1609.0
76.942979614,1624.0
76.993113421,1564.0
77.043247228,1567.0
77.093381035,1569.0
77.143514841,1574.0
77.193648648,1489.0
77.243782455,1485.0
77.293916262,1501.0
77.344050069,1521.0
77.394183876,1500.0
77.444317683,1582.0
77.494451490,1479.0
77.544585297,1509.0
77.594719104,1507.0
77.644852911,1545.0
77.694986718,1473.0
77.745120525,1494.0
77.795254332,1556.0
77.845388139,1528.0
77.895521945,1503.0
77.945655752,1550.0
77.995789559,1486.0
78.045923366,1493.0
78.096057173,1528.0
78.146190980,1428.0
78.196324787,1468.0
78.246458594,1516.0
78.296592401,1451.0
78.346726208,1528.0
78.396860015,1514.0
78.446993822,1499.0
78.497127629,1492.0
78.547261436,1468.0
78.597395243,1495.0
78.647529049,1523.0
78.697662856,1507.0
78.747796663,1416.0
78.797930470,1572.0
78.848064277,1411.0
78.898198084,1514.0
78.948331891,1470.0
78.998465698,1407.0
79.048599505,1541.0
79.098733312,1463.0
79.148867119,1472.0
79.199000926,1429.0
79.249134733,1497.0
79.299268540,1512.0
79.349402347,1446.0
79.399536153,1436.0
79.449669960,1421.0
79.499803767,1442.0
79.549937574,1520.0
79.600071381,1505.0
79.650205188,1369.0
79.700338995,1358.0
79.750472802,1433.0
79.800606609,1403.0
79.850740416,1420.0
79.900874223,1458.0
79.951008030,1393.0
80.001141837,1427.0
80.051275644,1427.0
80.101409451,1417.0
80.151543258,1435.0
80.201677064,1407.0
80.251810871,1513.0
80.301944678,1460.0
80.352078485,1423.0
80.402212292,1417.0
80.452346099,1483.0
80.502479906,1441.0
80.552613713,1428.0
80.602747520,1454.0
80.652881327,1424.0
80.703015134,1342.0
80.753148941,1408.0
80.803282748,1448.0
80.853416555,1429.0
80.903550362,1431.0
80.953684168,1409.0
81.003817975,1346.0
81.053951782,1455.0
81.104085589,1362.0
81.154219396,1425.0
81.204353203,1477.0
81.254487010,1388.0
81.304620817,1439.0
81.354754624,1418.0
81.404888431,1389.0
81.455022238,1404.0
81.505156045,1420.0
81.555289852,1423.0
81.605423659,1366.0
81.655557466,1375.0
81.705691272,1392.0
81.755825079,1374.0
81.805958886,1450.0
81.856092693,1358.0
81.906226500,1340.0
81.956360307,1411.0
82.006494114,1382.0
82.056627921,1357.0
82.106761728,1312.0
82.156895535,1326.0
82.207029342,1356.0
82.257163149,1429.0
82.307296956,1410.0
82.357430763,1326.0
82.407564570,1367.0
82.457698376,1445.0
82.507832183,1407.0
82.557965990,1370.0
82.608099797,1338.0
82.658233604,1367.0
82.708367411,1400.0
82.758501218,1406.0
82.808635025,1438.0
82.858768832,1428.0
82.908902639,1382.0
82.959036446,1352.0
83.009170253,1379.0
83.059304060,1369.0
83.109437867,1385.0
83.159571674,1413.0
83.209705480,1460.0
83.259839287,1411.0
83.309973094,1372.0
83.360106901,1368.0
83.410240708,1333.0
83.460374515,1394.0
83.510508322,1342.0
83.560642129,1378.0
83.610775936,1400.0
83.660909743,1346.0
83.711043550,1405.0
83.761177357,1409.0
83.811311164,1385.0
83.861444971,1383.0
83.911578778,1413.0
83.961712584,1337.0
84.011846391,1354.0
84.061980198,1351.0
84.112114005,1380.0
84.162247812,1337.0
84.212381619,1344.0
84.262515426,1345.0
84.312649233,1360.0
84.362783040,1331.0
84.412916847,1333.0
84.463050654,1370.0
84.513184461,1320.0
84.563318268,1354.0
84.613452075,1401.0
84.663585882,1382.0
84.713719689,1335.0
84.763853495,1310.0
84.813987302,1344.0
84.864121109,1399.0
84.914254916,1373.0
84.964388723,1395.0
85.014522530,1305.0
85.064656337,1373.0
85.114790144,1330.0
85.164923951,1304.0
85.215057758,1376.0
85.265191565,1284.0
85.315325372,1311.0
85.365459179,1399.0
85.415592986,1290.0
85.465726793,1315.0
85.515860599,1369.0
85.565994406,1331.0
85.616128213,1419.0
85.666262020,1320.0
85.716395827,1380.0
85.766529634,1314.0
85.816663441,1297.0
85.866797248,1286.0
85.916931055,1389.0
85.967064862,1329.0
86.017198669,1338.0
86.067332476,1323.0
86.117466283,1344.0
86.167600090,1293.0
86.217733897,1334.0
86.267867703,1303.0
86.318001510,1277.0
86.368135317,1372.0
86.418269124,1283.0
86.468402931,1315.0
86.518536738,1409.0
86.568670545,1303.0
86.618804352,1337.0
86.668938159,1350.0
86.719071966,1348.0
86.769205773,1322.0
86.819339580,1286.0
86.869473387,1214.0
86.919607194,1272.0
86.969741001,1316.0
87.019874807,1314.0
87.070008614,1354.0
87.120142421,1292.0
87.170276228,1334.0
87.220410035,1270.0
87.270543842,1349.0
87.320677649,1329.0
87.370811456,1298.0
87.420945263,1320.0
87.471079070,1275.0
87.521212877,1289.0
87.571346684,1239.0
87.621480491,1278.0
87.671614298,1262.0
87.721748105,1318.0
87.771881911,1285.0
87.822015718,1272.0
87.872149525,1333.0
87.922283332,1247.0
87.972417139,1269.0
88.022550946,1361.0
88.072684753,1271.0
88.122818560,1236.0
88.172952367,1322.0
88.223086174,1309.0
88.273219981,1269.0
88.323353788,1268.0
88.373487595,1323.0
88.423621402,1231.0
88.473755209,1286.0
88.523889016,1315.0
88.574022822,1299.0
88.624156629,1346.0
88.674290436,1325.0
88.724424243,1299.0
88.774558050,1300.0
88.824691857,1316.0
88.874825664,1294.0
88.924959471,1283.0
88.975093278,1330.0
89.025227085,1331.0
89.075360892,1355.0
89.125494699,1309.0
89.175628506,1289.0
89.225762313,1352.0
89.275896120,1352.0
89.326029926,1259.0
89.376163733,1339.0
89.426297540,1289.0
89.476431347,1360.0
89.526565154,1370.0
89.576698961,1278.0
89.626832768,1307.0
89.676966575,1315.0
89.727100382,1320.0
89.777234189,1307.0
89.827367996,1346.0
89.877501803,1293.0
89.927635610,1324.0
89.977769417,1342.0
90.027903224,1219.0
90.078037030,1266.0
90.128170837,1298.0
90.178304644,1337.0
90.228438451,1352.0
90.278572258,1326.0
90.328706065,1272.0
90.378839872,1256.0
90.428973679,1292.0
90.479107486,1302.0
90.529241293,1297.0
90.579375100,1263.0
90.629508907,1343.0
90.679642714,1331.0
90.729776521,1295.0
90.779910328,1333.0
90.830044134,1311.0
90.880177941,1309.0
90.930311748,1297.0
90.980445555,1257.0
91.030579362,1325.0
91.080713169,1264.0
91.130846976,1324.0
91.180980783,1329.0
91.231114590,1376.0
91.281248397,1299.0
91.331382204,1308.0
91.381516011,1341.0
91.431649818,1304.0
91.481783625,1310.0
91.531917432,1292.0
91.582051238,1373.0
91.632185045,1335.0
91.682318852,1375.0
91.732452659,1436.0
91.782586466,1378.0
91.832720273,1352.0
91.882854080,1393.0
91.932987887,1349.0
91.983121694,1368.0
92.033255501,1346.0
92.083389308,1329.0
92.133523115,1422.0
92.183656922,1501.0
92.233790729,1439.0
92.283924536,1469.0
92.334058342,1545.0
92.384192149,1490.0
92.434325956,1508.0
92.484459763,1545.0
92.534593570,1627.0
92.584727377,1626.0
92.634861184,1677.0
92.684994991,1724.0
92.735128798,1728.0
92.785262605,1845.0
92.835396412,1833.0
92.885530219,1783.0
92.935664026,1754.0
92.985797833,1830.0
93.035931640,1662.0
93.086065447,1676.0
93.136199253,1672.0
93.186333060,1638.0
93.236466867,1501.0
93.286600674,1530.0
93.336734481,1487.0
93.386868288,1350.0
93.437002095,1436.0
93.487135902,1372.0
93.537269709,1402.0
93.587403516,1338.0
93.637537323,1286.0
93.687671130,1313.0
93.737804937,1300.0
93.787938744,1324.0
93.838072551,1271.0
93.888206357,1382.0
93.938340164,1258.0
93.988473971,1278.0
94.038607778,1336.0
94.088741585,1231.0
94.138875392,1206.0
94.189009199,1303.0
94.239143006,1162.0
94.289276813,1323.0
94.339410620,1262.0
94.389544427,1272.0
94.439678234,1318.0
94.489812041,1263.0
94.539945848,1292.0
94.590079655,1290.0
94.640213461,1291.0
94.690347268,1290.0
94.740481075,1311.0
94.790614882,1228.0
94.840748689,1276.0
94.890882496,1248.0
94.941016303,1268.0
94.991150110,1322.0