File: OriginPro/XRD from Panalytical X'Pert PRO/In-Situ/FicheirosXRD_Insitu/NiNws_350°C.csv
[Measurement conditions]
Sample identification,
Comment - 1,"finito"
Comment - 2,"Configuration=MRI TC-Basic Stage, Owner=User-1, Creation date=26-10-2009 9:18:44"
Comment - 3,"Goniometer=PW3050/60 (Theta/Theta); Minimum step size 2Theta:0.001; Minimum step size Omega:0.001"
Comment - 4,"Sample stage=MRI TC-Basic (PtRh heat strip)"
Comment - 5,"Diffractometer system=XPERT-PRO"
Comment - 6,"Measurement program=FS-L, Owner=joana, Creation date=25-11-2014 17:28:08"
Anode material,Cu
K-Alpha1 wavelength,1.5405980
K-Alpha2 wavelength,1.5444260
Ratio K-Alpha2/K-Alpha1,0.500
Divergence slit,Fixed,0.76mm
Monochromator used,NO
Generator voltage, 45
Tube current, 40
File date and time,16-Dez-2017 00:13
Unit cell,
h k l, 0 0 0
Temperature [K],623
Scan axis,Gonio
Scan range,24.995999996,94.999505744
Scan step size,0.0167113
No. of points, 4189
Scan type,CONTINUOUS
Time per step,118.110
[Scan points]
Angle,Intensity
25.004355630,2234.0
25.054489437,2322.0
25.104623244,2148.0
25.154757051,2200.0
25.204890858,2201.0
25.255024665,2214.0
25.305158472,2226.0
25.355292279,2156.0
25.405426085,2191.0
25.455559892,2217.0
25.505693699,2194.0
25.555827506,2131.0
25.605961313,2216.0
25.656095120,2127.0
25.706228927,2224.0
25.756362734,2164.0
25.806496541,2150.0
25.856630348,2188.0
25.906764155,2194.0
25.956897962,2114.0
26.007031769,2211.0
26.057165576,2253.0
26.107299383,2086.0
26.157433189,2254.0
26.207566996,2159.0
26.257700803,2208.0
26.307834610,2123.0
26.357968417,2174.0
26.408102224,2191.0
26.458236031,2163.0
26.508369838,2111.0
26.558503645,2180.0
26.608637452,2229.0
26.658771259,2089.0
26.708905066,2165.0
26.759038873,2253.0
26.809172680,2206.0
26.859306487,2235.0
26.909440293,2187.0
26.959574100,2158.0
27.009707907,2213.0
27.059841714,2219.0
27.109975521,2223.0
27.160109328,2135.0
27.210243135,2182.0
27.260376942,2113.0
27.310510749,2149.0
27.360644556,2226.0
27.410778363,2191.0
27.460912170,2150.0
27.511045977,2077.0
27.561179784,2165.0
27.611313591,2179.0
27.661447398,2240.0
27.711581204,2208.0
27.761715011,2115.0
27.811848818,2175.0
27.861982625,2068.0
27.912116432,2258.0
27.962250239,2225.0
28.012384046,2183.0
28.062517853,2161.0
28.112651660,2049.0
28.162785467,2202.0
28.212919274,2253.0
28.263053081,2278.0
28.313186888,2510.0
28.363320695,2818.0
28.413454502,2299.0
28.463588308,2409.0
28.513722115,2283.0
28.563855922,2361.0
28.613989729,2346.0
28.664123536,2263.0
28.714257343,2191.0
28.764391150,2266.0
28.814524957,2179.0
28.864658764,2172.0
28.914792571,2257.0
28.964926378,2179.0
29.015060185,2117.0
29.065193992,2174.0
29.115327799,2230.0
29.165461606,2044.0
29.215595412,2160.0
29.265729219,2152.0
29.315863026,2172.0
29.365996833,2129.0
29.416130640,2098.0
29.466264447,2130.0
29.516398254,2124.0
29.566532061,2214.0
29.616665868,2054.0
29.666799675,2109.0
29.716933482,2150.0
29.767067289,2189.0
29.817201096,2146.0
29.867334903,2194.0
29.917468710,2150.0
29.967602516,2199.0
30.017736323,2099.0
30.067870130,2173.0
30.118003937,2135.0
30.168137744,2140.0
30.218271551,2103.0
30.268405358,2113.0
30.318539165,2130.0
30.368672972,2126.0
30.418806779,2084.0
30.468940586,2125.0
30.519074393,2130.0
30.569208200,2109.0
30.619342007,2077.0
30.669475814,2121.0
30.719609620,2060.0
30.769743427,2125.0
30.819877234,2226.0
30.870011041,2098.0
30.920144848,2191.0
30.970278655,2081.0
31.020412462,2081.0
31.070546269,2042.0
31.120680076,2053.0
31.170813883,2170.0
31.220947690,2167.0
31.271081497,2185.0
31.321215304,2124.0
31.371349111,2170.0
31.421482918,2018.0
31.471616724,2126.0
31.521750531,2081.0
31.571884338,2099.0
31.622018145,2176.0
31.672151952,2130.0
31.722285759,2140.0
31.772419566,2121.0
31.822553373,2080.0
31.872687180,2150.0
31.922820987,2085.0
31.972954794,2158.0
32.023088601,2145.0
32.073222408,2066.0
32.123356215,2113.0
32.173490022,2078.0
32.223623829,2183.0
32.273757635,2107.0
32.323891442,2118.0
32.374025249,2188.0
32.424159056,2121.0
32.474292863,2190.0
32.524426670,2173.0
32.574560477,2113.0
32.624694284,2128.0
32.674828091,2143.0
32.724961898,2155.0
32.775095705,2140.0
32.825229512,2095.0
32.875363319,2087.0
32.925497126,2104.0
32.975630933,2142.0
33.025764739,2099.0
33.075898546,2106.0
33.126032353,2166.0
33.176166160,2057.0
33.226299967,2141.0
33.276433774,2187.0
33.326567581,2153.0
33.376701388,2111.0
33.426835195,2190.0
33.476969002,2043.0
33.527102809,2045.0
33.577236616,2089.0
33.627370423,2106.0
33.677504230,2151.0
33.727638037,2088.0
33.777771843,2132.0
33.827905650,2103.0
33.878039457,2026.0
33.928173264,2028.0
33.978307071,2110.0
34.028440878,2110.0
34.078574685,2064.0
34.128708492,2117.0
34.178842299,2064.0
34.228976106,2033.0
34.279109913,2103.0
34.329243720,2162.0
34.379377527,2087.0
34.429511334,2098.0
34.479645141,2031.0
34.529778947,2048.0
34.579912754,2061.0
34.630046561,2103.0
34.680180368,2068.0
34.730314175,2028.0
34.780447982,2120.0
34.830581789,2044.0
34.880715596,2017.0
34.930849403,2003.0
34.980983210,2015.0
35.031117017,2116.0
35.081250824,2025.0
35.131384631,2142.0
35.181518438,2035.0
35.231652245,2130.0
35.281786051,2066.0
35.331919858,2053.0
35.382053665,2098.0
35.432187472,2144.0
35.482321279,2092.0
35.532455086,2106.0
35.582588893,2090.0
35.632722700,2127.0
35.682856507,2095.0
35.732990314,2042.0
35.783124121,2132.0
35.833257928,2181.0
35.883391735,2094.0
35.933525542,2112.0
35.983659349,2076.0
36.033793156,2063.0
36.083926962,2103.0
36.134060769,2101.0
36.184194576,2060.0
36.234328383,2163.0
36.284462190,2079.0
36.334595997,2122.0
36.384729804,2125.0
36.434863611,2045.0
36.484997418,2066.0
36.535131225,2167.0
36.585265032,2034.0
36.635398839,2029.0
36.685532646,2006.0
36.735666453,2058.0
36.785800260,2022.0
36.835934066,2206.0
36.886067873,2091.0
36.936201680,2124.0
36.986335487,2087.0
37.036469294,2028.0
37.086603101,2175.0
37.136736908,1989.0
37.186870715,2045.0
37.237004522,2144.0
37.287138329,2000.0
37.337272136,2085.0
37.387405943,2089.0
37.437539750,2112.0
37.487673557,2075.0
37.537807364,2082.0
37.587941170,2054.0
37.638074977,2030.0
37.688208784,2047.0
37.738342591,2107.0
37.788476398,2036.0
37.838610205,2041.0
37.888744012,2097.0
37.938877819,2082.0
37.989011626,2138.0
38.039145433,2038.0
38.089279240,2008.0
38.139413047,2132.0
38.189546854,2087.0
38.239680661,2024.0
38.289814468,2077.0
38.339948274,2050.0
38.390082081,2021.0
38.440215888,2079.0
38.490349695,1992.0
38.540483502,2017.0
38.590617309,1994.0
38.640751116,2165.0
38.690884923,1984.0
38.741018730,1976.0
38.791152537,2125.0
38.841286344,2113.0
38.891420151,1990.0
38.941553958,2010.0
38.991687765,2067.0
39.041821572,1974.0
39.091955378,2025.0
39.142089185,2097.0
39.192222992,1939.0
39.242356799,2025.0
39.292490606,2041.0
39.342624413,1995.0
39.392758220,1971.0
39.442892027,1979.0
39.493025834,2065.0
39.543159641,2064.0
39.593293448,2151.0
39.643427255,2226.0
39.693561062,2352.0
39.743694869,2218.0
39.793828676,2221.0
39.843962482,2121.0
39.894096289,2094.0
39.944230096,2086.0
39.994363903,2132.0
40.044497710,2122.0
40.094631517,2069.0
40.144765324,2106.0
40.194899131,2068.0
40.245032938,2010.0
40.295166745,2015.0
40.345300552,2037.0
40.395434359,2015.0
40.445568166,2047.0
40.495701973,1986.0
40.545835780,1972.0
40.595969587,2062.0
40.646103393,1984.0
40.696237200,2014.0
40.746371007,1956.0
40.796504814,2007.0
40.846638621,2055.0
40.896772428,1953.0
40.946906235,2038.0
40.997040042,2032.0
41.047173849,1962.0
41.097307656,1959.0
41.147441463,2052.0
41.197575270,1929.0
41.247709077,2018.0
41.297842884,1937.0
41.347976691,2002.0
41.398110497,1983.0
41.448244304,1966.0
41.498378111,1888.0
41.548511918,1982.0
41.598645725,1992.0
41.648779532,1953.0
41.698913339,2021.0
41.749047146,1977.0
41.799180953,1945.0
41.849314760,1992.0
41.899448567,1951.0
41.949582374,2030.0
41.999716181,1969.0
42.049849988,2026.0
42.099983795,1987.0
42.150117601,1976.0
42.200251408,2001.0
42.250385215,1992.0
42.300519022,2045.0
42.350652829,2042.0
42.400786636,1963.0
42.450920443,2052.0
42.501054250,2070.0
42.551188057,2033.0
42.601321864,2087.0
42.651455671,2119.0
42.701589478,2092.0
42.751723285,2154.0
42.801857092,2045.0
42.851990899,2022.0
42.902124705,2098.0
42.952258512,2078.0
43.002392319,2036.0
43.052526126,2094.0
43.102659933,2002.0
43.152793740,2036.0
43.202927547,2137.0
43.253061354,2206.0
43.303195161,2187.0
43.353328968,2188.0
43.403462775,2158.0
43.453596582,2115.0
43.503730389,2212.0
43.553864196,2303.0
43.603998003,2369.0
43.654131809,2340.0
43.704265616,2457.0
43.754399423,2489.0
43.804533230,2816.0
43.854667037,3093.0
43.904800844,3501.0
43.954934651,3894.0
44.005068458,4660.0
44.055202265,5307.0
44.105336072,6696.0
44.155469879,8260.0
44.205603686,9486.0
44.255737493,10370.0
44.305871300,9425.0
44.356005107,7753.0
44.406138913,6010.0
44.456272720,4629.0
44.506406527,3386.0
44.556540334,2900.0
44.606674141,2625.0
44.656807948,2388.0
44.706941755,2235.0
44.757075562,2183.0
44.807209369,2230.0
44.857343176,2176.0
44.907476983,2122.0
44.957610790,2088.0
45.007744597,2023.0
45.057878404,2058.0
45.108012211,2188.0
45.158146018,2172.0
45.208279824,2153.0
45.258413631,2098.0
45.308547438,2212.0
45.358681245,2185.0
45.408815052,2099.0
45.458948859,2171.0
45.509082666,2028.0
45.559216473,1946.0
45.609350280,2059.0
45.659484087,2024.0
45.709617894,2087.0
45.759751701,2083.0
45.809885508,2119.0
45.860019315,2058.0
45.910153122,2111.0
45.960286928,2330.0
46.010420735,2570.0
46.060554542,3248.0
46.110688349,3882.0
46.160822156,6671.0
46.210955963,5255.0
46.261089770,3693.0
46.311223577,5260.0
46.361357384,2856.0
46.411491191,3060.0
46.461624998,3310.0
46.511758805,3554.0
46.561892612,3562.0
46.612026419,3213.0
46.662160226,2964.0
46.712294032,2578.0
46.762427839,2198.0
46.812561646,2044.0
46.862695453,1946.0
46.912829260,1928.0
46.962963067,2019.0
47.013096874,1909.0
47.063230681,1895.0
47.113364488,1823.0
47.163498295,1943.0
47.213632102,1922.0
47.263765909,1928.0
47.313899716,1874.0
47.364033523,1919.0
47.414167330,1935.0
47.464301136,1785.0
47.514434943,1821.0
47.564568750,1948.0
47.614702557,2000.0
47.664836364,1881.0
47.714970171,1833.0
47.765103978,1906.0
47.815237785,1898.0
47.865371592,1872.0
47.915505399,1944.0
47.965639206,1920.0
48.015773013,1956.0
48.065906820,1943.0
48.116040627,1897.0
48.166174434,1851.0
48.216308240,1903.0
48.266442047,1919.0
48.316575854,1907.0
48.366709661,1929.0
48.416843468,1897.0
48.466977275,1942.0
48.517111082,1903.0
48.567244889,1898.0
48.617378696,1809.0
48.667512503,1819.0
48.717646310,1859.0
48.767780117,1949.0
48.817913924,1870.0
48.868047731,1869.0
48.918181538,1877.0
48.968315344,1839.0
49.018449151,1785.0
49.068582958,1845.0
49.118716765,1936.0
49.168850572,1844.0
49.218984379,1884.0
49.269118186,1933.0
49.319251993,1928.0
49.369385800,2015.0
49.419519607,1983.0
49.469653414,1924.0
49.519787221,1938.0
49.569921028,1949.0
49.620054835,1852.0
49.670188642,1903.0
49.720322449,1875.0
49.770456255,1885.0
49.820590062,1890.0
49.870723869,1900.0
49.920857676,1785.0
49.970991483,1901.0
50.021125290,1869.0
50.071259097,1905.0
50.121392904,1888.0
50.171526711,1898.0
50.221660518,1964.0
50.271794325,1978.0
50.321928132,2123.0
50.372061939,2271.0
50.422195746,2204.0
50.472329553,2274.0
50.522463359,2249.0
50.572597166,2179.0
50.622730973,2069.0
50.672864780,1995.0
50.722998587,1991.0
50.773132394,1996.0
50.823266201,2009.0
50.873400008,2024.0
50.923533815,2005.0
50.973667622,2037.0
51.023801429,2086.0
51.073935236,2145.0
51.124069043,2221.0
51.174202850,2414.0
51.224336657,2493.0
51.274470463,2634.0
51.324604270,2953.0
51.374738077,3363.0
51.424871884,3818.0
51.475005691,4196.0
51.525139498,4343.0
51.575273305,4288.0
51.625407112,4003.0
51.675540919,3789.0
51.725674726,3226.0
51.775808533,2788.0
51.825942340,2535.0
51.876076147,2328.0
51.926209954,2106.0
51.976343761,2090.0
52.026477567,1954.0
52.076611374,1999.0
52.126745181,1827.0
52.176878988,1900.0
52.227012795,1857.0
52.277146602,1904.0
52.327280409,1819.0
52.377414216,1833.0
52.427548023,1802.0
52.477681830,1797.0
52.527815637,1800.0
52.577949444,1806.0
52.628083251,1803.0
52.678217058,1827.0
52.728350865,1799.0
52.778484671,1846.0
52.828618478,1843.0
52.878752285,1886.0
52.928886092,1805.0
52.979019899,1743.0
53.029153706,1703.0
53.079287513,1870.0
53.129421320,1749.0
53.179555127,1825.0
53.229688934,1762.0
53.279822741,1751.0
53.329956548,1849.0
53.380090355,1822.0
53.430224162,1799.0
53.480357969,1777.0
53.530491776,1849.0
53.580625582,1773.0
53.630759389,1819.0
53.680893196,1908.0
53.731027003,1785.0
53.781160810,1733.0
53.831294617,1799.0
53.881428424,1827.0
53.931562231,1756.0
53.981696038,1776.0
54.031829845,1809.0
54.081963652,1809.0
54.132097459,1799.0
54.182231266,1902.0
54.232365073,1808.0
54.282498880,1781.0
54.332632686,1781.0
54.382766493,1748.0
54.432900300,1800.0
54.483034107,1766.0
54.533167914,1732.0
54.583301721,1793.0
54.633435528,1786.0
54.683569335,1774.0
54.733703142,1727.0
54.783836949,1810.0
54.833970756,1873.0
54.884104563,1858.0
54.934238370,1713.0
54.984372177,1775.0
55.034505984,1767.0
55.084639790,1764.0
55.134773597,1771.0
55.184907404,1760.0
55.235041211,1818.0
55.285175018,1742.0
55.335308825,1769.0
55.385442632,1781.0
55.435576439,1807.0
55.485710246,1775.0
55.535844053,1741.0
55.585977860,1776.0
55.636111667,1783.0
55.686245474,1800.0
55.736379281,1761.0
55.786513088,1712.0
55.836646894,1824.0
55.886780701,1819.0
55.936914508,1802.0
55.987048315,1767.0
56.037182122,1790.0
56.087315929,1742.0
56.137449736,1816.0
56.187583543,1720.0
56.237717350,1710.0
56.287851157,1752.0
56.337984964,1769.0
56.388118771,1729.0
56.438252578,1745.0
56.488386385,1763.0
56.538520192,1758.0
56.588653998,1762.0
56.638787805,1783.0
56.688921612,1675.0
56.739055419,1814.0
56.789189226,1746.0
56.839323033,1766.0
56.889456840,1765.0
56.939590647,1757.0
56.989724454,1747.0
57.039858261,1752.0
57.089992068,1753.0
57.140125875,1679.0
57.190259682,1757.0
57.240393489,1880.0
57.290527296,1860.0
57.340661102,1817.0
57.390794909,1804.0
57.440928716,1780.0
57.491062523,1819.0
57.541196330,1751.0
57.591330137,1737.0
57.641463944,1809.0
57.691597751,1831.0
57.741731558,1771.0
57.791865365,1891.0
57.841999172,1720.0
57.892132979,1808.0
57.942266786,1722.0
57.992400593,1760.0
58.042534400,1796.0
58.092668207,1781.0
58.142802013,1785.0
58.192935820,1710.0
58.243069627,1787.0
58.293203434,1777.0
58.343337241,1770.0
58.393471048,1794.0
58.443604855,1826.0
58.493738662,1782.0
58.543872469,1755.0
58.594006276,1760.0
58.644140083,1748.0
58.694273890,1758.0
58.744407697,1852.0
58.794541504,1825.0
58.844675311,1788.0
58.894809117,1695.0
58.944942924,1831.0
58.995076731,1765.0
59.045210538,1766.0
59.095344345,1799.0
59.145478152,1789.0
59.195611959,1812.0
59.245745766,1777.0
59.295879573,1797.0
59.346013380,1813.0
59.396147187,1852.0
59.446280994,1761.0
59.496414801,1814.0
59.546548608,1767.0
59.596682415,1789.0
59.646816221,1844.0
59.696950028,1876.0
59.747083835,1750.0
59.797217642,1794.0
59.847351449,1828.0
59.897485256,1843.0
59.947619063,1772.0
59.997752870,1797.0
60.047886677,1765.0
60.098020484,1742.0
60.148154291,1815.0
60.198288098,1789.0
60.248421905,1828.0
60.298555712,1817.0
60.348689519,1807.0
60.398823325,1874.0
60.448957132,1809.0
60.499090939,1795.0
60.549224746,1800.0
60.599358553,1845.0
60.649492360,1818.0
60.699626167,1820.0
60.749759974,1860.0
60.799893781,1834.0
60.850027588,1810.0
60.900161395,1817.0
60.950295202,1847.0
61.000429009,1889.0
61.050562816,1915.0
61.100696623,1868.0
61.150830429,1778.0
61.200964236,1819.0
61.251098043,1824.0
61.301231850,1788.0
61.351365657,1777.0
61.401499464,1790.0
61.451633271,1857.0
61.501767078,1859.0
61.551900885,1888.0
61.602034692,1900.0
61.652168499,1797.0
61.702302306,1883.0
61.752436113,1850.0
61.802569920,1894.0
61.852703727,1793.0
61.902837533,1915.0
61.952971340,1871.0
62.003105147,1918.0
62.053238954,1921.0
62.103372761,1868.0
62.153506568,1893.0
62.203640375,1962.0
62.253774182,1941.0
62.303907989,1969.0
62.354041796,1921.0
62.404175603,1959.0
62.454309410,1878.0
62.504443217,1895.0
62.554577024,1959.0
62.604710831,1937.0
62.654844638,1966.0
62.704978444,2056.0
62.755112251,1900.0
62.805246058,1989.0
62.855379865,1987.0
62.905513672,1882.0
62.955647479,2038.0
63.005781286,1970.0
63.055915093,1941.0
63.106048900,1973.0
63.156182707,1965.0
63.206316514,1882.0
63.256450321,1963.0
63.306584128,1928.0
63.356717935,2015.0
63.406851742,1981.0
63.456985548,1918.0
63.507119355,1994.0
63.557253162,1984.0
63.607386969,2035.0
63.657520776,2001.0
63.707654583,1975.0
63.757788390,2003.0
63.807922197,1986.0
63.858056004,1975.0
63.908189811,2011.0
63.958323618,1927.0
64.008457425,2005.0
64.058591232,2029.0
64.108725039,2039.0
64.158858846,1925.0
64.208992652,2050.0
64.259126459,2024.0
64.309260266,1975.0
64.359394073,2008.0
64.409527880,2046.0
64.459661687,2044.0
64.509795494,2015.0
64.559929301,1986.0
64.610063108,2041.0
64.660196915,2009.0
64.710330722,2143.0
64.760464529,2094.0
64.810598336,2058.0
64.860732143,2076.0
64.910865950,2062.0
64.960999756,1992.0
65.011133563,2027.0
65.061267370,2084.0
65.111401177,2009.0
65.161534984,2082.0
65.211668791,2076.0
65.261802598,2068.0
65.311936405,2057.0
65.362070212,2064.0
65.412204019,2020.0
65.462337826,2071.0
65.512471633,2048.0
65.562605440,2098.0
65.612739247,2026.0
65.662873054,2008.0
65.713006860,2136.0
65.763140667,2035.0
65.813274474,2074.0
65.863408281,2099.0
65.913542088,2092.0
65.963675895,2168.0
66.013809702,2122.0
66.063943509,2117.0
66.114077316,2150.0
66.164211123,2092.0
66.214344930,2065.0
66.264478737,2065.0
66.314612544,2006.0
66.364746351,2168.0
66.414880158,2124.0
66.465013964,2018.0
66.515147771,2076.0
66.565281578,2058.0
66.615415385,2141.0
66.665549192,2145.0
66.715682999,2036.0
66.765816806,2038.0
66.815950613,2052.0
66.866084420,2072.0
66.916218227,2141.0
66.966352034,2157.0
67.016485841,2123.0
67.066619648,1981.0
67.116753455,2032.0
67.166887262,2190.0
67.217021069,2059.0
67.267154875,2078.0
67.317288682,2058.0
67.367422489,2070.0
67.417556296,2091.0
67.467690103,2060.0
67.517823910,2100.0
67.567957717,2239.0
67.618091524,2142.0
67.668225331,2172.0
67.718359138,2120.0
67.768492945,2096.0
67.818626752,2098.0
67.868760559,2143.0
67.918894366,2106.0
67.969028173,2108.0
68.019161979,2107.0
68.069295786,2081.0
68.119429593,2047.0
68.169563400,2066.0
68.219697207,2108.0
68.269831014,2084.0
68.319964821,2059.0
68.370098628,2035.0
68.420232435,2058.0
68.470366242,2061.0
68.520500049,2096.0
68.570633856,2031.0
68.620767663,2175.0
68.670901470,2137.0
68.721035277,2114.0
68.771169083,2158.0
68.821302890,2068.0
68.871436697,2072.0
68.921570504,2082.0
68.971704311,2083.0
69.021838118,2107.0
69.071971925,2094.0
69.122105732,2157.0
69.172239539,2138.0
69.222373346,2111.0
69.272507153,2176.0
69.322640960,2029.0
69.372774767,2044.0
69.422908574,1978.0
69.473042381,2056.0
69.523176187,2125.0
69.573309994,2050.0
69.623443801,2053.0
69.673577608,2061.0
69.723711415,2091.0
69.773845222,1993.0
69.823979029,2146.0
69.874112836,2090.0
69.924246643,2156.0
69.974380450,2038.0
70.024514257,1978.0
70.074648064,2001.0
70.124781871,1988.0
70.174915678,2084.0
70.225049485,2067.0
70.275183291,2073.0
70.325317098,2044.0
70.375450905,2038.0
70.425584712,2016.0
70.475718519,2034.0
70.525852326,2082.0
70.575986133,2004.0
70.626119940,2056.0
70.676253747,2043.0
70.726387554,2045.0
70.776521361,1988.0
70.826655168,2011.0
70.876788975,1958.0
70.926922782,1966.0
70.977056589,2029.0
71.027190396,2002.0
71.077324202,2012.0
71.127458009,1963.0
71.177591816,2014.0
71.227725623,2000.0
71.277859430,1972.0
71.327993237,2013.0
71.378127044,1982.0
71.428260851,1953.0
71.478394658,1956.0
71.528528465,2033.0
71.578662272,1937.0
71.628796079,2021.0
71.678929886,1928.0
71.729063693,1961.0
71.779197500,1909.0
71.829331306,1990.0
71.879465113,1913.0
71.929598920,1906.0
71.979732727,1922.0
72.029866534,2005.0
72.080000341,1910.0
72.130134148,1919.0
72.180267955,1948.0
72.230401762,1854.0
72.280535569,1924.0
72.330669376,1868.0
72.380803183,2009.0
72.430936990,1951.0
72.481070797,1923.0
72.531204604,1951.0
72.581338410,1888.0
72.631472217,1854.0
72.681606024,1887.0
72.731739831,1836.0
72.781873638,1920.0
72.832007445,1924.0
72.882141252,1870.0
72.932275059,1958.0
72.982408866,1872.0
73.032542673,1852.0
73.082676480,1974.0
73.132810287,1903.0
73.182944094,1834.0
73.233077901,1889.0
73.283211708,1831.0
73.333345514,1907.0
73.383479321,1860.0
73.433613128,1942.0
73.483746935,1876.0
73.533880742,1727.0
73.584014549,1821.0
73.634148356,1894.0
73.684282163,1867.0
73.734415970,1837.0
73.784549777,1802.0
73.834683584,1825.0
73.884817391,1835.0
73.934951198,1881.0
73.985085005,1794.0
74.035218812,1883.0
74.085352618,1887.0
74.135486425,1822.0
74.185620232,1809.0
74.235754039,1832.0
74.285887846,1837.0
74.336021653,1734.0
74.386155460,1829.0
74.436289267,1808.0
74.486423074,1809.0
74.536556881,1903.0
74.586690688,1856.0
74.636824495,1815.0
74.686958302,1782.0
74.737092109,1735.0
74.787225916,1789.0
74.837359722,1808.0
74.887493529,1726.0
74.937627336,1802.0
74.987761143,1879.0
75.037894950,1827.0
75.088028757,1803.0
75.138162564,1842.0
75.188296371,1837.0
75.238430178,1884.0
75.288563985,1824.0
75.338697792,1814.0
75.388831599,1963.0
75.438965406,1939.0
75.489099213,1852.0
75.539233020,2006.0
75.589366827,2061.0
75.639500633,2078.0
75.689634440,2095.0
75.739768247,2180.0
75.789902054,2311.0
75.840035861,2357.0
75.890169668,2408.0
75.940303475,2307.0
75.990437282,2294.0
76.040571089,2224.0
76.090704896,2166.0
76.140838703,2121.0
76.190972510,2025.0
76.241106317,1928.0
76.291240124,1864.0
76.341373931,1801.0
76.391507737,1848.0
76.441641544,1873.0
76.491775351,1736.0
76.541909158,1714.0
76.592042965,1716.0
76.642176772,1744.0
76.692310579,1783.0
76.742444386,1744.0
76.792578193,1710.0
76.842712000,1759.0
76.892845807,1696.0
76.942979614,1645.0
76.993113421,1658.0
77.043247228,1625.0
77.093381035,1717.0
77.143514841,1739.0
77.193648648,1697.0
77.243782455,1605.0
77.293916262,1646.0
77.344050069,1520.0
77.394183876,1614.0
77.444317683,1623.0
77.494451490,1615.0
77.544585297,1607.0
77.594719104,1677.0
77.644852911,1556.0
77.694986718,1696.0
77.745120525,1575.0
77.795254332,1615.0
77.845388139,1662.0
77.895521945,1600.0
77.945655752,1597.0
77.995789559,1637.0
78.045923366,1623.0
78.096057173,1647.0
78.146190980,1618.0
78.196324787,1600.0
78.246458594,1621.0
78.296592401,1628.0
78.346726208,1660.0
78.396860015,1599.0
78.446993822,1595.0
78.497127629,1644.0
78.547261436,1588.0
78.597395243,1616.0
78.647529049,1587.0
78.697662856,1644.0
78.747796663,1556.0
78.797930470,1607.0
78.848064277,1619.0
78.898198084,1582.0
78.948331891,1689.0
78.998465698,1574.0
79.048599505,1549.0
79.098733312,1571.0
79.148867119,1612.0
79.199000926,1592.0
79.249134733,1658.0
79.299268540,1628.0
79.349402347,1611.0
79.399536153,1566.0
79.449669960,1583.0
79.499803767,1555.0
79.549937574,1581.0
79.600071381,1584.0
79.650205188,1583.0
79.700338995,1484.0
79.750472802,1605.0
79.800606609,1585.0
79.850740416,1523.0
79.900874223,1560.0
79.951008030,1535.0
80.001141837,1531.0
80.051275644,1544.0
80.101409451,1521.0
80.151543258,1550.0
80.201677064,1523.0
80.251810871,1507.0
80.301944678,1470.0
80.352078485,1551.0
80.402212292,1569.0
80.452346099,1489.0
80.502479906,1502.0
80.552613713,1553.0
80.602747520,1567.0
80.652881327,1509.0
80.703015134,1619.0
80.753148941,1563.0
80.803282748,1510.0
80.853416555,1537.0
80.903550362,1574.0
80.953684168,1519.0
81.003817975,1484.0
81.053951782,1525.0
81.104085589,1517.0
81.154219396,1543.0
81.204353203,1470.0
81.254487010,1559.0
81.304620817,1553.0
81.354754624,1452.0
81.404888431,1472.0
81.455022238,1499.0
81.505156045,1488.0
81.555289852,1511.0
81.605423659,1458.0
81.655557466,1431.0
81.705691272,1501.0
81.755825079,1475.0
81.805958886,1555.0
81.856092693,1462.0
81.906226500,1394.0
81.956360307,1482.0
82.006494114,1466.0
82.056627921,1467.0
82.106761728,1442.0
82.156895535,1482.0
82.207029342,1482.0
82.257163149,1459.0
82.307296956,1488.0
82.357430763,1558.0
82.407564570,1432.0
82.457698376,1493.0
82.507832183,1538.0
82.557965990,1458.0
82.608099797,1457.0
82.658233604,1461.0
82.708367411,1452.0
82.758501218,1454.0
82.808635025,1494.0
82.858768832,1513.0
82.908902639,1473.0
82.959036446,1544.0
83.009170253,1443.0
83.059304060,1406.0
83.109437867,1416.0
83.159571674,1491.0
83.209705480,1464.0
83.259839287,1442.0
83.309973094,1459.0
83.360106901,1419.0
83.410240708,1437.0
83.460374515,1465.0
83.510508322,1470.0
83.560642129,1446.0
83.610775936,1409.0
83.660909743,1469.0
83.711043550,1492.0
83.761177357,1443.0
83.811311164,1441.0
83.861444971,1469.0
83.911578778,1499.0
83.961712584,1419.0
84.011846391,1381.0
84.061980198,1452.0
84.112114005,1368.0
84.162247812,1437.0
84.212381619,1485.0
84.262515426,1423.0
84.312649233,1432.0
84.362783040,1431.0
84.412916847,1424.0
84.463050654,1444.0
84.513184461,1470.0
84.563318268,1427.0
84.613452075,1399.0
84.663585882,1451.0
84.713719689,1449.0
84.763853495,1445.0
84.813987302,1425.0
84.864121109,1463.0
84.914254916,1451.0
84.964388723,1423.0
85.014522530,1397.0
85.064656337,1418.0
85.114790144,1457.0
85.164923951,1429.0
85.215057758,1538.0
85.265191565,1353.0
85.315325372,1476.0
85.365459179,1408.0
85.415592986,1427.0
85.465726793,1402.0
85.515860599,1443.0
85.565994406,1404.0
85.616128213,1428.0
85.666262020,1397.0
85.716395827,1370.0
85.766529634,1346.0
85.816663441,1452.0
85.866797248,1360.0
85.916931055,1430.0
85.967064862,1437.0
86.017198669,1414.0
86.067332476,1440.0
86.117466283,1352.0
86.167600090,1392.0
86.217733897,1428.0
86.267867703,1309.0
86.318001510,1389.0
86.368135317,1535.0
86.418269124,1435.0
86.468402931,1357.0
86.518536738,1329.0
86.568670545,1418.0
86.618804352,1407.0
86.668938159,1404.0
86.719071966,1382.0
86.769205773,1356.0
86.819339580,1442.0
86.869473387,1409.0
86.919607194,1409.0
86.969741001,1371.0
87.019874807,1360.0
87.070008614,1408.0
87.120142421,1297.0
87.170276228,1367.0
87.220410035,1467.0
87.270543842,1372.0
87.320677649,1428.0
87.370811456,1357.0
87.420945263,1409.0
87.471079070,1325.0
87.521212877,1328.0
87.571346684,1466.0
87.621480491,1365.0
87.671614298,1395.0
87.721748105,1387.0
87.771881911,1343.0
87.822015718,1300.0
87.872149525,1337.0
87.922283332,1418.0
87.972417139,1345.0
88.022550946,1399.0
88.072684753,1365.0
88.122818560,1429.0
88.172952367,1398.0
88.223086174,1439.0
88.273219981,1370.0
88.323353788,1386.0
88.373487595,1391.0
88.423621402,1389.0
88.473755209,1380.0
88.523889016,1408.0
88.574022822,1386.0
88.624156629,1353.0
88.674290436,1420.0
88.724424243,1362.0
88.774558050,1457.0
88.824691857,1323.0
88.874825664,1402.0
88.924959471,1333.0
88.975093278,1356.0
89.025227085,1386.0
89.075360892,1368.0
89.125494699,1350.0
89.175628506,1342.0
89.225762313,1412.0
89.275896120,1363.0
89.326029926,1361.0
89.376163733,1381.0
89.426297540,1340.0
89.476431347,1359.0
89.526565154,1406.0
89.576698961,1334.0
89.626832768,1372.0
89.676966575,1401.0
89.727100382,1324.0
89.777234189,1367.0
89.827367996,1368.0
89.877501803,1392.0
89.927635610,1370.0
89.977769417,1368.0
90.027903224,1419.0
90.078037030,1241.0
90.128170837,1307.0
90.178304644,1398.0
90.228438451,1355.0
90.278572258,1403.0
90.328706065,1316.0
90.378839872,1376.0
90.428973679,1389.0
90.479107486,1376.0
90.529241293,1406.0
90.579375100,1388.0
90.629508907,1344.0
90.679642714,1360.0
90.729776521,1365.0
90.779910328,1337.0
90.830044134,1308.0
90.880177941,1311.0
90.930311748,1359.0
90.980445555,1368.0
91.030579362,1396.0
91.080713169,1408.0
91.130846976,1362.0
91.180980783,1446.0
91.231114590,1394.0
91.281248397,1445.0
91.331382204,1302.0
91.381516011,1394.0
91.431649818,1412.0
91.481783625,1452.0
91.531917432,1394.0
91.582051238,1429.0
91.632185045,1476.0
91.682318852,1435.0
91.732452659,1487.0
91.782586466,1491.0
91.832720273,1492.0
91.882854080,1577.0
91.932987887,1549.0
91.983121694,1707.0
92.033255501,1589.0
92.083389308,1645.0
92.133523115,1736.0
92.183656922,1771.0
92.233790729,1865.0
92.283924536,1887.0
92.334058342,1718.0
92.384192149,1867.0
92.434325956,1689.0
92.484459763,1725.0
92.534593570,1722.0
92.584727377,1589.0
92.634861184,1617.0
92.684994991,1516.0
92.735128798,1515.0
92.785262605,1433.0
92.835396412,1440.0
92.885530219,1429.0
92.935664026,1369.0
92.985797833,1368.0
93.035931640,1393.0
93.086065447,1316.0
93.136199253,1380.0
93.186333060,1279.0
93.236466867,1397.0
93.286600674,1319.0
93.336734481,1314.0
93.386868288,1350.0
93.437002095,1401.0
93.487135902,1203.0
93.537269709,1375.0
93.587403516,1270.0
93.637537323,1371.0
93.687671130,1292.0
93.737804937,1352.0
93.787938744,1309.0
93.838072551,1311.0
93.888206357,1344.0
93.938340164,1327.0
93.988473971,1310.0
94.038607778,1315.0
94.088741585,1328.0
94.138875392,1366.0
94.189009199,1275.0
94.239143006,1247.0
94.289276813,1329.0
94.339410620,1339.0
94.389544427,1287.0
94.439678234,1345.0
94.489812041,1294.0
94.539945848,1313.0
94.590079655,1324.0
94.640213461,1305.0
94.690347268,1297.0
94.740481075,1283.0
94.790614882,1382.0
94.840748689,1277.0
94.890882496,1274.0
94.941016303,1324.0
94.991150110,1291.0