File: OriginPro/XRD from Panalytical X'Pert PRO/In-Situ/FicheirosXRD_Insitu/NiNws_100°C.csv
[Measurement conditions]
Sample identification,
Comment - 1,"finito"
Comment - 2,"Configuration=MRI TC-Basic Stage, Owner=User-1, Creation date=26-10-2009 9:18:44"
Comment - 3,"Goniometer=PW3050/60 (Theta/Theta); Minimum step size 2Theta:0.001; Minimum step size Omega:0.001"
Comment - 4,"Sample stage=MRI TC-Basic (PtRh heat strip)"
Comment - 5,"Diffractometer system=XPERT-PRO"
Comment - 6,"Measurement program=FS-L, Owner=joana, Creation date=25-11-2014 17:28:08"
Anode material,Cu
K-Alpha1 wavelength,1.5405980
K-Alpha2 wavelength,1.5444260
Ratio K-Alpha2/K-Alpha1,0.500
Divergence slit,Fixed,0.76mm
Monochromator used,NO
Generator voltage, 45
Tube current, 40
File date and time,15-Dez-2017 18:25
Unit cell,
h k l, 0 0 0
Temperature [K],373
Scan axis,Gonio
Scan range,24.995999996,94.999505744
Scan step size,0.0167113
No. of points, 4189
Scan type,CONTINUOUS
Time per step,118.110
[Scan points]
Angle,Intensity
25.004355630,2446.0
25.054489437,2328.0
25.104623244,2372.0
25.154757051,2283.0
25.204890858,2374.0
25.255024665,2319.0
25.305158472,2292.0
25.355292279,2266.0
25.405426085,2280.0
25.455559892,2301.0
25.505693699,2235.0
25.555827506,2373.0
25.605961313,2311.0
25.656095120,2256.0
25.706228927,2262.0
25.756362734,2209.0
25.806496541,2209.0
25.856630348,2326.0
25.906764155,2216.0
25.956897962,2220.0
26.007031769,2295.0
26.057165576,2253.0
26.107299383,2213.0
26.157433189,2359.0
26.207566996,2276.0
26.257700803,2245.0
26.307834610,2242.0
26.357968417,2245.0
26.408102224,2299.0
26.458236031,2210.0
26.508369838,2205.0
26.558503645,2257.0
26.608637452,2248.0
26.658771259,2247.0
26.708905066,2233.0
26.759038873,2177.0
26.809172680,2222.0
26.859306487,2204.0
26.909440293,2181.0
26.959574100,2232.0
27.009707907,2241.0
27.059841714,2283.0
27.109975521,2211.0
27.160109328,2182.0
27.210243135,2142.0
27.260376942,2213.0
27.310510749,2151.0
27.360644556,2251.0
27.410778363,2206.0
27.460912170,2278.0
27.511045977,2168.0
27.561179784,2210.0
27.611313591,2239.0
27.661447398,2243.0
27.711581204,2170.0
27.761715011,2183.0
27.811848818,2249.0
27.861982625,2183.0
27.912116432,2300.0
27.962250239,2116.0
28.012384046,2087.0
28.062517853,2291.0
28.112651660,2160.0
28.162785467,2300.0
28.212919274,2298.0
28.263053081,2546.0
28.313186888,2434.0
28.363320695,2824.0
28.413454502,2389.0
28.463588308,2377.0
28.513722115,2415.0
28.563855922,2389.0
28.613989729,2415.0
28.664123536,2338.0
28.714257343,2366.0
28.764391150,2314.0
28.814524957,2265.0
28.864658764,2297.0
28.914792571,2243.0
28.964926378,2250.0
29.015060185,2241.0
29.065193992,2231.0
29.115327799,2252.0
29.165461606,2329.0
29.215595412,2220.0
29.265729219,2278.0
29.315863026,2271.0
29.365996833,2258.0
29.416130640,2195.0
29.466264447,2205.0
29.516398254,2225.0
29.566532061,2231.0
29.616665868,2147.0
29.666799675,2114.0
29.716933482,2183.0
29.767067289,2157.0
29.817201096,2216.0
29.867334903,2145.0
29.917468710,2126.0
29.967602516,2114.0
30.017736323,2143.0
30.067870130,2217.0
30.118003937,2211.0
30.168137744,2157.0
30.218271551,2112.0
30.268405358,2182.0
30.318539165,2193.0
30.368672972,2141.0
30.418806779,2108.0
30.468940586,2108.0
30.519074393,2095.0
30.569208200,2186.0
30.619342007,2169.0
30.669475814,2142.0
30.719609620,2152.0
30.769743427,2207.0
30.819877234,2204.0
30.870011041,2232.0
30.920144848,2171.0
30.970278655,2097.0
31.020412462,2159.0
31.070546269,2148.0
31.120680076,2246.0
31.170813883,2072.0
31.220947690,2092.0
31.271081497,2165.0
31.321215304,2151.0
31.371349111,2081.0
31.421482918,2174.0
31.471616724,2117.0
31.521750531,2213.0
31.571884338,2135.0
31.622018145,2085.0
31.672151952,2186.0
31.722285759,2152.0
31.772419566,2108.0
31.822553373,2165.0
31.872687180,2195.0
31.922820987,2140.0
31.972954794,2156.0
32.023088601,2012.0
32.073222408,2119.0
32.123356215,2071.0
32.173490022,2159.0
32.223623829,2168.0
32.273757635,2094.0
32.323891442,2064.0
32.374025249,2148.0
32.424159056,2160.0
32.474292863,2148.0
32.524426670,2187.0
32.574560477,2094.0
32.624694284,2096.0
32.674828091,2089.0
32.724961898,2124.0
32.775095705,2192.0
32.825229512,2080.0
32.875363319,2215.0
32.925497126,2123.0
32.975630933,2063.0
33.025764739,2116.0
33.075898546,2071.0
33.126032353,2100.0
33.176166160,2102.0
33.226299967,2099.0
33.276433774,2130.0
33.326567581,2156.0
33.376701388,2185.0
33.426835195,2136.0
33.476969002,2076.0
33.527102809,2023.0
33.577236616,2036.0
33.627370423,2142.0
33.677504230,2070.0
33.727638037,2088.0
33.777771843,2064.0
33.827905650,2121.0
33.878039457,2102.0
33.928173264,2090.0
33.978307071,2133.0
34.028440878,2038.0
34.078574685,2111.0
34.128708492,2023.0
34.178842299,2141.0
34.228976106,2112.0
34.279109913,2086.0
34.329243720,2094.0
34.379377527,2045.0
34.429511334,2033.0
34.479645141,2080.0
34.529778947,2082.0
34.579912754,2004.0
34.630046561,2116.0
34.680180368,2043.0
34.730314175,2056.0
34.780447982,2033.0
34.830581789,2077.0
34.880715596,2027.0
34.930849403,2125.0
34.980983210,2100.0
35.031117017,2019.0
35.081250824,2079.0
35.131384631,2140.0
35.181518438,2110.0
35.231652245,2084.0
35.281786051,2054.0
35.331919858,2020.0
35.382053665,2126.0
35.432187472,2117.0
35.482321279,2061.0
35.532455086,1992.0
35.582588893,2039.0
35.632722700,2064.0
35.682856507,2114.0
35.732990314,2079.0
35.783124121,2098.0
35.833257928,1957.0
35.883391735,2101.0
35.933525542,2025.0
35.983659349,2057.0
36.033793156,2174.0
36.083926962,2062.0
36.134060769,1994.0
36.184194576,2082.0
36.234328383,2009.0
36.284462190,2122.0
36.334595997,2041.0
36.384729804,2093.0
36.434863611,2019.0
36.484997418,1996.0
36.535131225,2059.0
36.585265032,2126.0
36.635398839,2085.0
36.685532646,2078.0
36.735666453,2001.0
36.785800260,2000.0
36.835934066,1995.0
36.886067873,1936.0
36.936201680,2096.0
36.986335487,1998.0
37.036469294,2143.0
37.086603101,2096.0
37.136736908,1995.0
37.186870715,2110.0
37.237004522,2070.0
37.287138329,2039.0
37.337272136,2009.0
37.387405943,2054.0
37.437539750,1999.0
37.487673557,2016.0
37.537807364,2040.0
37.587941170,2043.0
37.638074977,2040.0
37.688208784,2109.0
37.738342591,2019.0
37.788476398,2064.0
37.838610205,2048.0
37.888744012,2033.0
37.938877819,2166.0
37.989011626,2149.0
38.039145433,2137.0
38.089279240,2097.0
38.139413047,2101.0
38.189546854,2073.0
38.239680661,2135.0
38.289814468,2097.0
38.339948274,2025.0
38.390082081,2034.0
38.440215888,2054.0
38.490349695,1990.0
38.540483502,2093.0
38.590617309,2079.0
38.640751116,2024.0
38.690884923,1996.0
38.741018730,2050.0
38.791152537,1958.0
38.841286344,2113.0
38.891420151,1975.0
38.941553958,1997.0
38.991687765,2037.0
39.041821572,2086.0
39.091955378,2094.0
39.142089185,2011.0
39.192222992,2036.0
39.242356799,1992.0
39.292490606,2000.0
39.342624413,1984.0
39.392758220,2074.0
39.442892027,2085.0
39.493025834,2035.0
39.543159641,2174.0
39.593293448,2075.0
39.643427255,2081.0
39.693561062,2215.0
39.743694869,2314.0
39.793828676,2441.0
39.843962482,2160.0
39.894096289,2271.0
39.944230096,2124.0
39.994363903,1998.0
40.044497710,2188.0
40.094631517,2169.0
40.144765324,2116.0
40.194899131,2148.0
40.245032938,2092.0
40.295166745,2104.0
40.345300552,2112.0
40.395434359,2039.0
40.445568166,2104.0
40.495701973,1910.0
40.545835780,2032.0
40.595969587,1917.0
40.646103393,2018.0
40.696237200,2060.0
40.746371007,1961.0
40.796504814,2116.0
40.846638621,1964.0
40.896772428,1955.0
40.946906235,2021.0
40.997040042,1950.0
41.047173849,2054.0
41.097307656,2001.0
41.147441463,2013.0
41.197575270,2081.0
41.247709077,1982.0
41.297842884,2010.0
41.347976691,1962.0
41.398110497,2038.0
41.448244304,1988.0
41.498378111,2050.0
41.548511918,1945.0
41.598645725,1962.0
41.648779532,2045.0
41.698913339,2009.0
41.749047146,1998.0
41.799180953,2074.0
41.849314760,2055.0
41.899448567,2032.0
41.949582374,2083.0
41.999716181,1944.0
42.049849988,2007.0
42.099983795,2034.0
42.150117601,2000.0
42.200251408,1991.0
42.250385215,2080.0
42.300519022,2058.0
42.350652829,1978.0
42.400786636,2009.0
42.450920443,2015.0
42.501054250,1981.0
42.551188057,1961.0
42.601321864,2055.0
42.651455671,2107.0
42.701589478,2017.0
42.751723285,2075.0
42.801857092,2004.0
42.851990899,1983.0
42.902124705,1963.0
42.952258512,2066.0
43.002392319,2078.0
43.052526126,2085.0
43.102659933,2083.0
43.152793740,2096.0
43.202927547,2071.0
43.253061354,2129.0
43.303195161,2236.0
43.353328968,2228.0
43.403462775,2171.0
43.453596582,2207.0
43.503730389,2177.0
43.553864196,2275.0
43.603998003,2211.0
43.654131809,2425.0
43.704265616,2324.0
43.754399423,2450.0
43.804533230,2604.0
43.854667037,2657.0
43.904800844,2891.0
43.954934651,3056.0
44.005068458,3225.0
44.055202265,3646.0
44.105336072,4081.0
44.155469879,4690.0
44.205603686,5410.0
44.255737493,6559.0
44.305871300,7735.0
44.356005107,9124.0
44.406138913,10005.0
44.456272720,10180.0
44.506406527,8703.0
44.556540334,6941.0
44.606674141,5385.0
44.656807948,4061.0
44.706941755,3230.0
44.757075562,2794.0
44.807209369,2422.0
44.857343176,2395.0
44.907476983,2227.0
44.957610790,2238.0
45.007744597,2220.0
45.057878404,2225.0
45.108012211,2212.0
45.158146018,2186.0
45.208279824,2163.0
45.258413631,2181.0
45.308547438,2154.0
45.358681245,2072.0
45.408815052,2328.0
45.458948859,2175.0
45.509082666,2164.0
45.559216473,2185.0
45.609350280,2108.0
45.659484087,2086.0
45.709617894,1993.0
45.759751701,2043.0
45.809885508,2080.0
45.860019315,2121.0
45.910153122,2098.0
45.960286928,2179.0
46.010420735,2225.0
46.060554542,2421.0
46.110688349,2820.0
46.160822156,3317.0
46.210955963,4215.0
46.261089770,6765.0
46.311223577,5676.0
46.361357384,4113.0
46.411491191,5455.0
46.461624998,3045.0
46.511758805,3125.0
46.561892612,3340.0
46.612026419,3646.0
46.662160226,3740.0
46.712294032,3329.0
46.762427839,2986.0
46.812561646,2712.0
46.862695453,2380.0
46.912829260,2087.0
46.962963067,2084.0
47.013096874,2008.0
47.063230681,1929.0
47.113364488,1963.0
47.163498295,1875.0
47.213632102,1986.0
47.263765909,1974.0
47.313899716,1962.0
47.364033523,1981.0
47.414167330,1886.0
47.464301136,1870.0
47.514434943,1879.0
47.564568750,1924.0
47.614702557,1901.0
47.664836364,1921.0
47.714970171,1942.0
47.765103978,1894.0
47.815237785,1916.0
47.865371592,1928.0
47.915505399,1989.0
47.965639206,1963.0
48.015773013,1938.0
48.065906820,1944.0
48.116040627,1930.0
48.166174434,2022.0
48.216308240,1927.0
48.266442047,1915.0
48.316575854,1905.0
48.366709661,1913.0
48.416843468,1905.0
48.466977275,1893.0
48.517111082,1908.0
48.567244889,1905.0
48.617378696,1952.0
48.667512503,1916.0
48.717646310,1889.0
48.767780117,1834.0
48.817913924,1845.0
48.868047731,1864.0
48.918181538,1908.0
48.968315344,1926.0
49.018449151,1903.0
49.068582958,1904.0
49.118716765,1828.0
49.168850572,1900.0
49.218984379,1838.0
49.269118186,1922.0
49.319251993,1856.0
49.369385800,1900.0
49.419519607,1914.0
49.469653414,1940.0
49.519787221,2109.0
49.569921028,2187.0
49.620054835,2019.0
49.670188642,1927.0
49.720322449,1968.0
49.770456255,1985.0
49.820590062,1853.0
49.870723869,1922.0
49.920857676,1922.0
49.970991483,1847.0
50.021125290,1904.0
50.071259097,1933.0
50.121392904,1912.0
50.171526711,1919.0
50.221660518,1956.0
50.271794325,2000.0
50.321928132,2009.0
50.372061939,2056.0
50.422195746,2072.0
50.472329553,2221.0
50.522463359,2290.0
50.572597166,2348.0
50.622730973,2286.0
50.672864780,2287.0
50.722998587,2123.0
50.773132394,2070.0
50.823266201,2073.0
50.873400008,1978.0
50.923533815,2001.0
50.973667622,2058.0
51.023801429,2111.0
51.073935236,2077.0
51.124069043,2017.0
51.174202850,2175.0
51.224336657,2196.0
51.274470463,2315.0
51.324604270,2440.0
51.374738077,2407.0
51.424871884,2676.0
51.475005691,2864.0
51.525139498,3180.0
51.575273305,3459.0
51.625407112,3864.0
51.675540919,4155.0
51.725674726,4303.0
51.775808533,4219.0
51.825942340,4151.0
51.876076147,3816.0
51.926209954,3490.0
51.976343761,3064.0
52.026477567,2751.0
52.076611374,2413.0
52.126745181,2371.0
52.176878988,2196.0
52.227012795,2070.0
52.277146602,2019.0
52.327280409,1899.0
52.377414216,1981.0
52.427548023,1830.0
52.477681830,1893.0
52.527815637,1840.0
52.577949444,1864.0
52.628083251,1882.0
52.678217058,1868.0
52.728350865,1786.0
52.778484671,1842.0
52.828618478,1834.0
52.878752285,1827.0
52.928886092,1864.0
52.979019899,1836.0
53.029153706,1843.0
53.079287513,1857.0
53.129421320,1825.0
53.179555127,1763.0
53.229688934,1801.0
53.279822741,1806.0
53.329956548,1748.0
53.380090355,1811.0
53.430224162,1846.0
53.480357969,1801.0
53.530491776,1801.0
53.580625582,1744.0
53.630759389,1819.0
53.680893196,1779.0
53.731027003,1806.0
53.781160810,1834.0
53.831294617,1782.0
53.881428424,1782.0
53.931562231,1810.0
53.981696038,1798.0
54.031829845,1778.0
54.081963652,1718.0
54.132097459,1792.0
54.182231266,1757.0
54.232365073,1744.0
54.282498880,1790.0
54.332632686,1747.0
54.382766493,1803.0
54.432900300,1756.0
54.483034107,1751.0
54.533167914,1736.0
54.583301721,1693.0
54.633435528,1761.0
54.683569335,1771.0
54.733703142,1753.0
54.783836949,1742.0
54.833970756,1824.0
54.884104563,1730.0
54.934238370,1724.0
54.984372177,1726.0
55.034505984,1730.0
55.084639790,1847.0
55.134773597,1693.0
55.184907404,1840.0
55.235041211,1805.0
55.285175018,1809.0
55.335308825,1780.0
55.385442632,1799.0
55.435576439,1799.0
55.485710246,1711.0
55.535844053,1804.0
55.585977860,1673.0
55.636111667,1781.0
55.686245474,1775.0
55.736379281,1782.0
55.786513088,1686.0
55.836646894,1713.0
55.886780701,1741.0
55.936914508,1822.0
55.987048315,1759.0
56.037182122,1764.0
56.087315929,1783.0
56.137449736,1773.0
56.187583543,1697.0
56.237717350,1748.0
56.287851157,1762.0
56.337984964,1839.0
56.388118771,1709.0
56.438252578,1762.0
56.488386385,1752.0
56.538520192,1741.0
56.588653998,1738.0
56.638787805,1720.0
56.688921612,1764.0
56.739055419,1689.0
56.789189226,1773.0
56.839323033,1792.0
56.889456840,1743.0
56.939590647,1690.0
56.989724454,1717.0
57.039858261,1691.0
57.089992068,1734.0
57.140125875,1706.0
57.190259682,1787.0
57.240393489,1693.0
57.290527296,1706.0
57.340661102,1656.0
57.390794909,1759.0
57.440928716,1789.0
57.491062523,1700.0
57.541196330,1679.0
57.591330137,1676.0
57.641463944,1773.0
57.691597751,1751.0
57.741731558,1660.0
57.791865365,1713.0
57.841999172,1741.0
57.892132979,1783.0
57.942266786,1803.0
57.992400593,1706.0
58.042534400,1756.0
58.092668207,1704.0
58.142802013,1831.0
58.192935820,1725.0
58.243069627,1729.0
58.293203434,1663.0
58.343337241,1697.0
58.393471048,1877.0
58.443604855,1637.0
58.493738662,1690.0
58.543872469,1718.0
58.594006276,1703.0
58.644140083,1663.0
58.694273890,1743.0
58.744407697,1682.0
58.794541504,1687.0
58.844675311,1717.0
58.894809117,1714.0
58.944942924,1703.0
58.995076731,1710.0
59.045210538,1783.0
59.095344345,1803.0
59.145478152,1733.0
59.195611959,1784.0
59.245745766,1831.0
59.295879573,1708.0
59.346013380,1772.0
59.396147187,1734.0
59.446280994,1715.0
59.496414801,1759.0
59.546548608,1737.0
59.596682415,1837.0
59.646816221,1726.0
59.696950028,1765.0
59.747083835,1735.0
59.797217642,1749.0
59.847351449,1759.0
59.897485256,1766.0
59.947619063,1772.0
59.997752870,1748.0
60.047886677,1706.0
60.098020484,1831.0
60.148154291,1773.0
60.198288098,1645.0
60.248421905,1763.0
60.298555712,1667.0
60.348689519,1729.0
60.398823325,1721.0
60.448957132,1771.0
60.499090939,1722.0
60.549224746,1698.0
60.599358553,1854.0
60.649492360,1710.0
60.699626167,1697.0
60.749759974,1799.0
60.799893781,1687.0
60.850027588,1742.0
60.900161395,1713.0
60.950295202,1672.0
61.000429009,1807.0
61.050562816,1730.0
61.100696623,1813.0
61.150830429,1718.0
61.200964236,1669.0
61.251098043,1695.0
61.301231850,1810.0
61.351365657,1735.0
61.401499464,1719.0
61.451633271,1758.0
61.501767078,1804.0
61.551900885,1741.0
61.602034692,1682.0
61.652168499,1755.0
61.702302306,1818.0
61.752436113,1772.0
61.802569920,1734.0
61.852703727,1666.0
61.902837533,1753.0
61.952971340,1845.0
62.003105147,1751.0
62.053238954,1686.0
62.103372761,1732.0
62.153506568,1746.0
62.203640375,1772.0
62.253774182,1780.0
62.303907989,1719.0
62.354041796,1841.0
62.404175603,1817.0
62.454309410,1819.0
62.504443217,1723.0
62.554577024,1737.0
62.604710831,1740.0
62.654844638,1761.0
62.704978444,1776.0
62.755112251,1852.0
62.805246058,1763.0
62.855379865,1767.0
62.905513672,1834.0
62.955647479,1757.0
63.005781286,1787.0
63.055915093,1776.0
63.106048900,1879.0
63.156182707,1820.0
63.206316514,1775.0
63.256450321,1778.0
63.306584128,1758.0
63.356717935,1725.0
63.406851742,1789.0
63.456985548,1794.0
63.507119355,1784.0
63.557253162,1807.0
63.607386969,1841.0
63.657520776,1822.0
63.707654583,1768.0
63.757788390,1826.0
63.807922197,1772.0
63.858056004,1828.0
63.908189811,1773.0
63.958323618,1756.0
64.008457425,1870.0
64.058591232,1737.0
64.108725039,1828.0
64.158858846,1794.0
64.208992652,1799.0
64.259126459,1839.0
64.309260266,1851.0
64.359394073,1873.0
64.409527880,1862.0
64.459661687,1858.0
64.509795494,1888.0
64.559929301,1827.0
64.610063108,1789.0
64.660196915,1872.0
64.710330722,1852.0
64.760464529,1733.0
64.810598336,1789.0
64.860732143,1885.0
64.910865950,1824.0
64.960999756,1818.0
65.011133563,1808.0
65.061267370,1852.0
65.111401177,1805.0
65.161534984,1803.0
65.211668791,1813.0
65.261802598,1823.0
65.311936405,1869.0
65.362070212,1850.0
65.412204019,1796.0
65.462337826,1887.0
65.512471633,1820.0
65.562605440,1859.0
65.612739247,1895.0
65.662873054,1808.0
65.713006860,1861.0
65.763140667,1813.0
65.813274474,1862.0
65.863408281,1834.0
65.913542088,1881.0
65.963675895,1762.0
66.013809702,1853.0
66.063943509,1827.0
66.114077316,1891.0
66.164211123,1874.0
66.214344930,1913.0
66.264478737,1952.0
66.314612544,1822.0
66.364746351,1866.0
66.414880158,1823.0
66.465013964,1798.0
66.515147771,1838.0
66.565281578,1824.0
66.615415385,1867.0
66.665549192,1803.0
66.715682999,1786.0
66.765816806,1828.0
66.815950613,1825.0
66.866084420,1880.0
66.916218227,1866.0
66.966352034,1866.0
67.016485841,1920.0
67.066619648,1918.0
67.116753455,1760.0
67.166887262,1764.0
67.217021069,1845.0
67.267154875,1842.0
67.317288682,1845.0
67.367422489,1833.0
67.417556296,1849.0
67.467690103,1846.0
67.517823910,1909.0
67.567957717,1835.0
67.618091524,1841.0
67.668225331,1858.0
67.718359138,1904.0
67.768492945,1799.0
67.818626752,1804.0
67.868760559,1840.0
67.918894366,1846.0
67.969028173,1788.0
68.019161979,1848.0
68.069295786,1842.0
68.119429593,1830.0
68.169563400,1854.0
68.219697207,1866.0
68.269831014,1829.0
68.319964821,1899.0
68.370098628,1802.0
68.420232435,1796.0
68.470366242,1769.0
68.520500049,1734.0
68.570633856,1754.0
68.620767663,1766.0
68.670901470,1798.0
68.721035277,1798.0
68.771169083,1851.0
68.821302890,1832.0
68.871436697,1827.0
68.921570504,1830.0
68.971704311,1911.0
69.021838118,1883.0
69.071971925,1838.0
69.122105732,1762.0
69.172239539,1880.0
69.222373346,1841.0
69.272507153,1844.0
69.322640960,1802.0
69.372774767,1815.0
69.422908574,1721.0
69.473042381,1732.0
69.523176187,1841.0
69.573309994,1924.0
69.623443801,1740.0
69.673577608,1856.0
69.723711415,1787.0
69.773845222,1769.0
69.823979029,1827.0
69.874112836,1840.0
69.924246643,1830.0
69.974380450,1798.0
70.024514257,1800.0
70.074648064,1799.0
70.124781871,1859.0
70.174915678,1768.0
70.225049485,1790.0
70.275183291,1766.0
70.325317098,1838.0
70.375450905,1835.0
70.425584712,1751.0
70.475718519,1837.0
70.525852326,1784.0
70.575986133,1659.0
70.626119940,1714.0
70.676253747,1798.0
70.726387554,1826.0
70.776521361,1685.0
70.826655168,1799.0
70.876788975,1709.0
70.926922782,1746.0
70.977056589,1755.0
71.027190396,1817.0
71.077324202,1854.0
71.127458009,1739.0
71.177591816,1775.0
71.227725623,1769.0
71.277859430,1826.0
71.327993237,1784.0
71.378127044,1731.0
71.428260851,1766.0
71.478394658,1768.0
71.528528465,1684.0
71.578662272,1747.0
71.628796079,1791.0
71.678929886,1785.0
71.729063693,1798.0
71.779197500,1821.0
71.829331306,1787.0
71.879465113,1744.0
71.929598920,1763.0
71.979732727,1682.0
72.029866534,1742.0
72.080000341,1677.0
72.130134148,1676.0
72.180267955,1743.0
72.230401762,1673.0
72.280535569,1791.0
72.330669376,1718.0
72.380803183,1735.0
72.430936990,1665.0
72.481070797,1701.0
72.531204604,1768.0
72.581338410,1751.0
72.631472217,1676.0
72.681606024,1691.0
72.731739831,1687.0
72.781873638,1746.0
72.832007445,1680.0
72.882141252,1701.0
72.932275059,1666.0
72.982408866,1731.0
73.032542673,1672.0
73.082676480,1710.0
73.132810287,1744.0
73.182944094,1632.0
73.233077901,1739.0
73.283211708,1715.0
73.333345514,1654.0
73.383479321,1771.0
73.433613128,1707.0
73.483746935,1671.0
73.533880742,1720.0
73.584014549,1608.0
73.634148356,1684.0
73.684282163,1645.0
73.734415970,1622.0
73.784549777,1666.0
73.834683584,1737.0
73.884817391,1707.0
73.934951198,1609.0
73.985085005,1695.0
74.035218812,1672.0
74.085352618,1624.0
74.135486425,1671.0
74.185620232,1700.0
74.235754039,1685.0
74.285887846,1671.0
74.336021653,1643.0
74.386155460,1650.0
74.436289267,1659.0
74.486423074,1716.0
74.536556881,1661.0
74.586690688,1646.0
74.636824495,1680.0
74.686958302,1699.0
74.737092109,1629.0
74.787225916,1630.0
74.837359722,1632.0
74.887493529,1681.0
74.937627336,1684.0
74.987761143,1680.0
75.037894950,1691.0
75.088028757,1749.0
75.138162564,1666.0
75.188296371,1659.0
75.238430178,1716.0
75.288563985,1673.0
75.338697792,1666.0
75.388831599,1695.0
75.438965406,1741.0
75.489099213,1708.0
75.539233020,1715.0
75.589366827,1781.0
75.639500633,1731.0
75.689634440,1776.0
75.739768247,1831.0
75.789902054,1768.0
75.840035861,1862.0
75.890169668,1856.0
75.940303475,1879.0
75.990437282,1949.0
76.040571089,1964.0
76.090704896,2171.0
76.140838703,2079.0
76.190972510,2218.0
76.241106317,2320.0
76.291240124,2279.0
76.341373931,2126.0
76.391507737,2153.0
76.441641544,2058.0
76.491775351,1894.0
76.541909158,1890.0
76.592042965,1832.0
76.642176772,1719.0
76.692310579,1682.0
76.742444386,1617.0
76.792578193,1661.0
76.842712000,1566.0
76.892845807,1608.0
76.942979614,1617.0
76.993113421,1649.0
77.043247228,1625.0
77.093381035,1584.0
77.143514841,1527.0
77.193648648,1505.0
77.243782455,1568.0
77.293916262,1518.0
77.344050069,1572.0
77.394183876,1568.0
77.444317683,1510.0
77.494451490,1507.0
77.544585297,1560.0
77.594719104,1630.0
77.644852911,1544.0
77.694986718,1491.0
77.745120525,1556.0
77.795254332,1591.0
77.845388139,1516.0
77.895521945,1544.0
77.945655752,1539.0
77.995789559,1507.0
78.045923366,1519.0
78.096057173,1538.0
78.146190980,1490.0
78.196324787,1554.0
78.246458594,1525.0
78.296592401,1457.0
78.346726208,1480.0
78.396860015,1543.0
78.446993822,1536.0
78.497127629,1490.0
78.547261436,1493.0
78.597395243,1423.0
78.647529049,1493.0
78.697662856,1490.0
78.747796663,1473.0
78.797930470,1488.0
78.848064277,1499.0
78.898198084,1430.0
78.948331891,1447.0
78.998465698,1506.0
79.048599505,1475.0
79.098733312,1486.0
79.148867119,1460.0
79.199000926,1509.0
79.249134733,1540.0
79.299268540,1459.0
79.349402347,1462.0
79.399536153,1497.0
79.449669960,1498.0
79.499803767,1507.0
79.549937574,1502.0
79.600071381,1424.0
79.650205188,1418.0
79.700338995,1506.0
79.750472802,1412.0
79.800606609,1489.0
79.850740416,1514.0
79.900874223,1450.0
79.951008030,1432.0
80.001141837,1433.0
80.051275644,1413.0
80.101409451,1448.0
80.151543258,1463.0
80.201677064,1471.0
80.251810871,1534.0
80.301944678,1497.0
80.352078485,1483.0
80.402212292,1472.0
80.452346099,1529.0
80.502479906,1493.0
80.552613713,1475.0
80.602747520,1456.0
80.652881327,1415.0
80.703015134,1428.0
80.753148941,1437.0
80.803282748,1418.0
80.853416555,1471.0
80.903550362,1375.0
80.953684168,1387.0
81.003817975,1421.0
81.053951782,1367.0
81.104085589,1501.0
81.154219396,1484.0
81.204353203,1456.0
81.254487010,1435.0
81.304620817,1501.0
81.354754624,1427.0
81.404888431,1381.0
81.455022238,1388.0
81.505156045,1434.0
81.555289852,1441.0
81.605423659,1482.0
81.655557466,1475.0
81.705691272,1464.0
81.755825079,1422.0
81.805958886,1457.0
81.856092693,1344.0
81.906226500,1474.0
81.956360307,1419.0
82.006494114,1425.0
82.056627921,1402.0
82.106761728,1499.0
82.156895535,1364.0
82.207029342,1385.0
82.257163149,1427.0
82.307296956,1441.0
82.357430763,1430.0
82.407564570,1449.0
82.457698376,1439.0
82.507832183,1408.0
82.557965990,1356.0
82.608099797,1413.0
82.658233604,1415.0
82.708367411,1374.0
82.758501218,1435.0
82.808635025,1346.0
82.858768832,1412.0
82.908902639,1455.0
82.959036446,1345.0
83.009170253,1445.0
83.059304060,1373.0
83.109437867,1388.0
83.159571674,1437.0
83.209705480,1380.0
83.259839287,1401.0
83.309973094,1423.0
83.360106901,1418.0
83.410240708,1378.0
83.460374515,1403.0
83.510508322,1384.0
83.560642129,1451.0
83.610775936,1414.0
83.660909743,1330.0
83.711043550,1407.0
83.761177357,1428.0
83.811311164,1373.0
83.861444971,1332.0
83.911578778,1399.0
83.961712584,1423.0
84.011846391,1447.0
84.061980198,1382.0
84.112114005,1400.0
84.162247812,1358.0
84.212381619,1373.0
84.262515426,1388.0
84.312649233,1460.0
84.362783040,1401.0
84.412916847,1400.0
84.463050654,1381.0
84.513184461,1448.0
84.563318268,1464.0
84.613452075,1361.0
84.663585882,1393.0
84.713719689,1358.0
84.763853495,1410.0
84.813987302,1422.0
84.864121109,1369.0
84.914254916,1337.0
84.964388723,1405.0
85.014522530,1317.0
85.064656337,1348.0
85.114790144,1344.0
85.164923951,1358.0
85.215057758,1340.0
85.265191565,1271.0
85.315325372,1394.0
85.365459179,1355.0
85.415592986,1398.0
85.465726793,1373.0
85.515860599,1339.0
85.565994406,1388.0
85.616128213,1350.0
85.666262020,1398.0
85.716395827,1323.0
85.766529634,1333.0
85.816663441,1334.0
85.866797248,1365.0
85.916931055,1378.0
85.967064862,1290.0
86.017198669,1302.0
86.067332476,1286.0
86.117466283,1396.0
86.167600090,1443.0
86.217733897,1326.0
86.267867703,1267.0
86.318001510,1346.0
86.368135317,1359.0
86.418269124,1386.0
86.468402931,1280.0
86.518536738,1386.0
86.568670545,1378.0
86.618804352,1328.0
86.668938159,1405.0
86.719071966,1403.0
86.769205773,1286.0
86.819339580,1294.0
86.869473387,1385.0
86.919607194,1393.0
86.969741001,1398.0
87.019874807,1320.0
87.070008614,1353.0
87.120142421,1317.0
87.170276228,1355.0
87.220410035,1383.0
87.270543842,1409.0
87.320677649,1402.0
87.370811456,1336.0
87.420945263,1278.0
87.471079070,1348.0
87.521212877,1335.0
87.571346684,1392.0
87.621480491,1332.0
87.671614298,1281.0
87.721748105,1322.0
87.771881911,1296.0
87.822015718,1399.0
87.872149525,1278.0
87.922283332,1329.0
87.972417139,1317.0
88.022550946,1320.0
88.072684753,1374.0
88.122818560,1301.0
88.172952367,1300.0
88.223086174,1326.0
88.273219981,1348.0
88.323353788,1261.0
88.373487595,1305.0
88.423621402,1345.0
88.473755209,1344.0
88.523889016,1372.0
88.574022822,1285.0
88.624156629,1399.0
88.674290436,1293.0
88.724424243,1325.0
88.774558050,1316.0
88.824691857,1307.0
88.874825664,1332.0
88.924959471,1368.0
88.975093278,1267.0
89.025227085,1310.0
89.075360892,1319.0
89.125494699,1306.0
89.175628506,1279.0
89.225762313,1341.0
89.275896120,1296.0
89.326029926,1358.0
89.376163733,1342.0
89.426297540,1288.0
89.476431347,1355.0
89.526565154,1331.0
89.576698961,1333.0
89.626832768,1338.0
89.676966575,1337.0
89.727100382,1356.0
89.777234189,1342.0
89.827367996,1294.0
89.877501803,1321.0
89.927635610,1341.0
89.977769417,1292.0
90.027903224,1353.0
90.078037030,1293.0
90.128170837,1303.0
90.178304644,1306.0
90.228438451,1324.0
90.278572258,1325.0
90.328706065,1391.0
90.378839872,1340.0
90.428973679,1343.0
90.479107486,1321.0
90.529241293,1285.0
90.579375100,1314.0
90.629508907,1263.0
90.679642714,1290.0
90.729776521,1293.0
90.779910328,1293.0
90.830044134,1352.0
90.880177941,1368.0
90.930311748,1359.0
90.980445555,1334.0
91.030579362,1370.0
91.080713169,1305.0
91.130846976,1312.0
91.180980783,1333.0
91.231114590,1351.0
91.281248397,1351.0
91.331382204,1390.0
91.381516011,1396.0
91.431649818,1407.0
91.481783625,1345.0
91.531917432,1297.0
91.582051238,1358.0
91.632185045,1391.0
91.682318852,1357.0
91.732452659,1384.0
91.782586466,1407.0
91.832720273,1397.0
91.882854080,1412.0
91.932987887,1439.0
91.983121694,1424.0
92.033255501,1446.0
92.083389308,1440.0
92.133523115,1454.0
92.183656922,1391.0
92.233790729,1490.0
92.283924536,1486.0
92.334058342,1562.0
92.384192149,1575.0
92.434325956,1615.0
92.484459763,1660.0
92.534593570,1655.0
92.584727377,1778.0
92.634861184,1751.0
92.684994991,1850.0
92.735128798,1789.0
92.785262605,1741.0
92.835396412,1710.0
92.885530219,1706.0
92.935664026,1769.0
92.985797833,1705.0
93.035931640,1636.0
93.086065447,1641.0
93.136199253,1474.0
93.186333060,1507.0
93.236466867,1432.0
93.286600674,1461.0
93.336734481,1349.0
93.386868288,1485.0
93.437002095,1338.0
93.487135902,1382.0
93.537269709,1377.0
93.587403516,1391.0
93.637537323,1286.0
93.687671130,1285.0
93.737804937,1284.0
93.787938744,1314.0
93.838072551,1375.0
93.888206357,1241.0
93.938340164,1244.0
93.988473971,1367.0
94.038607778,1286.0
94.088741585,1244.0
94.138875392,1191.0
94.189009199,1322.0
94.239143006,1317.0
94.289276813,1263.0
94.339410620,1236.0
94.389544427,1228.0
94.439678234,1257.0
94.489812041,1257.0
94.539945848,1353.0
94.590079655,1293.0
94.640213461,1309.0
94.690347268,1301.0
94.740481075,1318.0
94.790614882,1216.0
94.840748689,1260.0
94.890882496,1279.0
94.941016303,1290.0
94.991150110,1262.0