File: OriginPro/XRD from Panalytical X'Pert PRO/In-Situ/FicheirosXRD_Insitu/NiNws_600°C.csv
[Measurement conditions]
Sample identification,
Comment - 1,"finito"
Comment - 2,"Configuration=MRI TC-Basic Stage, Owner=User-1, Creation date=26-10-2009 9:18:44"
Comment - 3,"Goniometer=PW3050/60 (Theta/Theta); Minimum step size 2Theta:0.001; Minimum step size Omega:0.001"
Comment - 4,"Sample stage=MRI TC-Basic (PtRh heat strip)"
Comment - 5,"Diffractometer system=XPERT-PRO"
Comment - 6,"Measurement program=FS-L, Owner=joana, Creation date=25-11-2014 17:28:08"
Anode material,Cu
K-Alpha1 wavelength,1.5405980
K-Alpha2 wavelength,1.5444260
Ratio K-Alpha2/K-Alpha1,0.500
Divergence slit,Fixed,0.76mm
Monochromator used,NO
Generator voltage, 45
Tube current, 40
File date and time,16-Dez-2017 05:59
Unit cell,
h k l, 0 0 0
Temperature [K],873
Scan axis,Gonio
Scan range,24.995999996,94.999505744
Scan step size,0.0167113
No. of points, 4189
Scan type,CONTINUOUS
Time per step,118.110
[Scan points]
Angle,Intensity
25.004355630,2294.0
25.054489437,2190.0
25.104623244,2217.0
25.154757051,2200.0
25.204890858,2258.0
25.255024665,2227.0
25.305158472,2220.0
25.355292279,2140.0
25.405426085,2201.0
25.455559892,2121.0
25.505693699,2174.0
25.555827506,2115.0
25.605961313,2246.0
25.656095120,2272.0
25.706228927,2208.0
25.756362734,2272.0
25.806496541,2187.0
25.856630348,2132.0
25.906764155,2203.0
25.956897962,2260.0
26.007031769,2216.0
26.057165576,2245.0
26.107299383,2114.0
26.157433189,2139.0
26.207566996,2142.0
26.257700803,2082.0
26.307834610,2149.0
26.357968417,2154.0
26.408102224,2129.0
26.458236031,2147.0
26.508369838,2220.0
26.558503645,2144.0
26.608637452,2131.0
26.658771259,2137.0
26.708905066,2074.0
26.759038873,2218.0
26.809172680,2192.0
26.859306487,2083.0
26.909440293,2144.0
26.959574100,2114.0
27.009707907,2185.0
27.059841714,2123.0
27.109975521,2179.0
27.160109328,2144.0
27.210243135,2133.0
27.260376942,2213.0
27.310510749,2219.0
27.360644556,2128.0
27.410778363,2198.0
27.460912170,2091.0
27.511045977,2231.0
27.561179784,2226.0
27.611313591,2158.0
27.661447398,2127.0
27.711581204,2195.0
27.761715011,2174.0
27.811848818,2173.0
27.861982625,2185.0
27.912116432,2130.0
27.962250239,2221.0
28.012384046,2158.0
28.062517853,2103.0
28.112651660,2152.0
28.162785467,2264.0
28.212919274,2225.0
28.263053081,2259.0
28.313186888,2371.0
28.363320695,2843.0
28.413454502,2135.0
28.463588308,2205.0
28.513722115,2204.0
28.563855922,2195.0
28.613989729,2138.0
28.664123536,2228.0
28.714257343,2230.0
28.764391150,2216.0
28.814524957,2280.0
28.864658764,2177.0
28.914792571,2198.0
28.964926378,2218.0
29.015060185,2177.0
29.065193992,2206.0
29.115327799,2211.0
29.165461606,2187.0
29.215595412,2168.0
29.265729219,2163.0
29.315863026,2155.0
29.365996833,2224.0
29.416130640,2139.0
29.466264447,2186.0
29.516398254,2183.0
29.566532061,2166.0
29.616665868,2177.0
29.666799675,2162.0
29.716933482,2092.0
29.767067289,2144.0
29.817201096,2110.0
29.867334903,2064.0
29.917468710,2223.0
29.967602516,2231.0
30.017736323,2249.0
30.067870130,2222.0
30.118003937,2241.0
30.168137744,2207.0
30.218271551,2332.0
30.268405358,2157.0
30.318539165,2163.0
30.368672972,2131.0
30.418806779,2073.0
30.468940586,2127.0
30.519074393,2078.0
30.569208200,2161.0
30.619342007,2149.0
30.669475814,2065.0
30.719609620,2105.0
30.769743427,2127.0
30.819877234,2108.0
30.870011041,2107.0
30.920144848,2195.0
30.970278655,2095.0
31.020412462,2071.0
31.070546269,2062.0
31.120680076,2197.0
31.170813883,1977.0
31.220947690,2086.0
31.271081497,2144.0
31.321215304,2124.0
31.371349111,2124.0
31.421482918,2154.0
31.471616724,2134.0
31.521750531,2067.0
31.571884338,2235.0
31.622018145,2140.0
31.672151952,2038.0
31.722285759,2150.0
31.772419566,2185.0
31.822553373,2112.0
31.872687180,2000.0
31.922820987,2089.0
31.972954794,2137.0
32.023088601,2165.0
32.073222408,2160.0
32.123356215,2101.0
32.173490022,2161.0
32.223623829,2091.0
32.273757635,2112.0
32.323891442,2098.0
32.374025249,2173.0
32.424159056,2026.0
32.474292863,2212.0
32.524426670,2097.0
32.574560477,2076.0
32.624694284,2152.0
32.674828091,2150.0
32.724961898,2131.0
32.775095705,2115.0
32.825229512,2128.0
32.875363319,2050.0
32.925497126,1978.0
32.975630933,2224.0
33.025764739,2142.0
33.075898546,2091.0
33.126032353,1988.0
33.176166160,2116.0
33.226299967,2210.0
33.276433774,2117.0
33.326567581,2150.0
33.376701388,2030.0
33.426835195,2030.0
33.476969002,2099.0
33.527102809,2124.0
33.577236616,2075.0
33.627370423,2098.0
33.677504230,2124.0
33.727638037,2101.0
33.777771843,2119.0
33.827905650,2132.0
33.878039457,2083.0
33.928173264,2080.0
33.978307071,2092.0
34.028440878,2120.0
34.078574685,2160.0
34.128708492,2102.0
34.178842299,2119.0
34.228976106,2083.0
34.279109913,2092.0
34.329243720,2070.0
34.379377527,2170.0
34.429511334,2090.0
34.479645141,2103.0
34.529778947,2059.0
34.579912754,2155.0
34.630046561,2176.0
34.680180368,2162.0
34.730314175,2194.0
34.780447982,2118.0
34.830581789,2200.0
34.880715596,2125.0
34.930849403,2102.0
34.980983210,2110.0
35.031117017,2135.0
35.081250824,2210.0
35.131384631,2123.0
35.181518438,2197.0
35.231652245,2159.0
35.281786051,2284.0
35.331919858,2348.0
35.382053665,2315.0
35.432187472,2417.0
35.482321279,2329.0
35.532455086,2401.0
35.582588893,2288.0
35.632722700,2371.0
35.682856507,2228.0
35.732990314,2355.0
35.783124121,2183.0
35.833257928,2272.0
35.883391735,2176.0
35.933525542,2176.0
35.983659349,2164.0
36.033793156,2214.0
36.083926962,2248.0
36.134060769,2201.0
36.184194576,2263.0
36.234328383,2202.0
36.284462190,2252.0
36.334595997,2234.0
36.384729804,2354.0
36.434863611,2238.0
36.484997418,2368.0
36.535131225,2392.0
36.585265032,2509.0
36.635398839,2668.0
36.685532646,2952.0
36.735666453,3092.0
36.785800260,3649.0
36.835934066,4218.0
36.886067873,4756.0
36.936201680,5322.0
36.986335487,5431.0
37.036469294,5292.0
37.086603101,5022.0
37.136736908,4395.0
37.186870715,3732.0
37.237004522,3353.0
37.287138329,2886.0
37.337272136,2747.0
37.387405943,2531.0
37.437539750,2468.0
37.487673557,2325.0
37.537807364,2201.0
37.587941170,2188.0
37.638074977,2161.0
37.688208784,2205.0
37.738342591,2123.0
37.788476398,2101.0
37.838610205,2104.0
37.888744012,2075.0
37.938877819,2167.0
37.989011626,2134.0
38.039145433,2084.0
38.089279240,2032.0
38.139413047,2078.0
38.189546854,2122.0
38.239680661,2119.0
38.289814468,2087.0
38.339948274,2031.0
38.390082081,2116.0
38.440215888,2060.0
38.490349695,2041.0
38.540483502,1977.0
38.590617309,2043.0
38.640751116,2085.0
38.690884923,2092.0
38.741018730,1917.0
38.791152537,1953.0
38.841286344,1987.0
38.891420151,1995.0
38.941553958,2051.0
38.991687765,2008.0
39.041821572,2024.0
39.091955378,1988.0
39.142089185,2048.0
39.192222992,2035.0
39.242356799,1906.0
39.292490606,1923.0
39.342624413,2037.0
39.392758220,1984.0
39.442892027,2031.0
39.493025834,2113.0
39.543159641,2171.0
39.593293448,2327.0
39.643427255,2711.0
39.693561062,2272.0
39.743694869,2257.0
39.793828676,2094.0
39.843962482,2017.0
39.894096289,2112.0
39.944230096,2035.0
39.994363903,1946.0
40.044497710,1984.0
40.094631517,1928.0
40.144765324,1989.0
40.194899131,1920.0
40.245032938,1937.0
40.295166745,1984.0
40.345300552,1974.0
40.395434359,2011.0
40.445568166,1970.0
40.495701973,1998.0
40.545835780,1980.0
40.595969587,1952.0
40.646103393,1877.0
40.696237200,1940.0
40.746371007,2016.0
40.796504814,1955.0
40.846638621,1988.0
40.896772428,2002.0
40.946906235,1907.0
40.997040042,1966.0
41.047173849,1964.0
41.097307656,1940.0
41.147441463,2014.0
41.197575270,1855.0
41.247709077,1920.0
41.297842884,2028.0
41.347976691,2001.0
41.398110497,1952.0
41.448244304,1966.0
41.498378111,1920.0
41.548511918,1991.0
41.598645725,2016.0
41.648779532,2011.0
41.698913339,1974.0
41.749047146,1968.0
41.799180953,2019.0
41.849314760,1989.0
41.899448567,1992.0
41.949582374,2113.0
41.999716181,2044.0
42.049849988,2016.0
42.099983795,2097.0
42.150117601,2042.0
42.200251408,2170.0
42.250385215,2062.0
42.300519022,2232.0
42.350652829,2310.0
42.400786636,2318.0
42.450920443,2323.0
42.501054250,2466.0
42.551188057,2620.0
42.601321864,2717.0
42.651455671,3200.0
42.701589478,3418.0
42.751723285,3882.0
42.801857092,4543.0
42.851990899,5501.0
42.902124705,6095.0
42.952258512,6692.0
43.002392319,6460.0
43.052526126,6042.0
43.102659933,5363.0
43.152793740,4788.0
43.202927547,4166.0
43.253061354,3547.0
43.303195161,3143.0
43.353328968,2835.0
43.403462775,2631.0
43.453596582,2522.0
43.503730389,2481.0
43.553864196,2309.0
43.603998003,2214.0
43.654131809,2283.0
43.704265616,2060.0
43.754399423,2112.0
43.804533230,2099.0
43.854667037,2025.0
43.904800844,2093.0
43.954934651,2013.0
44.005068458,2065.0
44.055202265,1968.0
44.105336072,1961.0
44.155469879,2018.0
44.205603686,2039.0
44.255737493,1972.0
44.305871300,1959.0
44.356005107,1958.0
44.406138913,2028.0
44.456272720,1839.0
44.506406527,1954.0
44.556540334,1909.0
44.606674141,1831.0
44.656807948,1945.0
44.706941755,1931.0
44.757075562,1895.0
44.807209369,1906.0
44.857343176,1978.0
44.907476983,1958.0
44.957610790,1877.0
45.007744597,2004.0
45.057878404,1894.0
45.108012211,2000.0
45.158146018,2005.0
45.208279824,2080.0
45.258413631,2059.0
45.308547438,2104.0
45.358681245,1946.0
45.408815052,1927.0
45.458948859,1996.0
45.509082666,1997.0
45.559216473,1989.0
45.609350280,1898.0
45.659484087,1923.0
45.709617894,2015.0
45.759751701,2011.0
45.809885508,1994.0
45.860019315,2206.0
45.910153122,2409.0
45.960286928,2827.0
46.010420735,3541.0
46.060554542,7336.0
46.110688349,3970.0
46.160822156,3650.0
46.210955963,4416.0
46.261089770,2677.0
46.311223577,2779.0
46.361357384,3151.0
46.411491191,3220.0
46.461624998,3070.0
46.511758805,2821.0
46.561892612,2611.0
46.612026419,2203.0
46.662160226,2071.0
46.712294032,2023.0
46.762427839,1878.0
46.812561646,1878.0
46.862695453,1920.0
46.912829260,1860.0
46.962963067,1890.0
47.013096874,1868.0
47.063230681,1842.0
47.113364488,1834.0
47.163498295,1920.0
47.213632102,1818.0
47.263765909,1863.0
47.313899716,1835.0
47.364033523,1817.0
47.414167330,1718.0
47.464301136,1903.0
47.514434943,1854.0
47.564568750,1854.0
47.614702557,1868.0
47.664836364,1838.0
47.714970171,1947.0
47.765103978,1837.0
47.815237785,1812.0
47.865371592,1863.0
47.915505399,1802.0
47.965639206,1810.0
48.015773013,1800.0
48.065906820,1824.0
48.116040627,1787.0
48.166174434,1740.0
48.216308240,1762.0
48.266442047,1856.0
48.316575854,1879.0
48.366709661,1866.0
48.416843468,1853.0
48.466977275,1784.0
48.517111082,1824.0
48.567244889,1806.0
48.617378696,1815.0
48.667512503,1809.0
48.717646310,1830.0
48.767780117,1741.0
48.817913924,1920.0
48.868047731,1789.0
48.918181538,1833.0
48.968315344,1830.0
49.018449151,1824.0
49.068582958,1847.0
49.118716765,1803.0
49.168850572,1825.0
49.218984379,1882.0
49.269118186,1946.0
49.319251993,2041.0
49.369385800,1917.0
49.419519607,1894.0
49.469653414,1883.0
49.519787221,1846.0
49.569921028,1845.0
49.620054835,1780.0
49.670188642,1750.0
49.720322449,1753.0
49.770456255,1756.0
49.820590062,1838.0
49.870723869,1850.0
49.920857676,1751.0
49.970991483,1838.0
50.021125290,1870.0
50.071259097,1802.0
50.121392904,1860.0
50.171526711,1905.0
50.221660518,2098.0
50.271794325,2214.0
50.321928132,2098.0
50.372061939,2042.0
50.422195746,1999.0
50.472329553,1901.0
50.522463359,1814.0
50.572597166,1815.0
50.622730973,1779.0
50.672864780,1781.0
50.722998587,1805.0
50.773132394,1818.0
50.823266201,1816.0
50.873400008,1719.0
50.923533815,1846.0
50.973667622,1828.0
51.023801429,1709.0
51.073935236,1787.0
51.124069043,1755.0
51.174202850,1745.0
51.224336657,1727.0
51.274470463,1796.0
51.324604270,1720.0
51.374738077,1797.0
51.424871884,1801.0
51.475005691,1747.0
51.525139498,1755.0
51.575273305,1728.0
51.625407112,1788.0
51.675540919,1774.0
51.725674726,1779.0
51.775808533,1747.0
51.825942340,1720.0
51.876076147,1713.0
51.926209954,1797.0
51.976343761,1788.0
52.026477567,1794.0
52.076611374,1691.0
52.126745181,1764.0
52.176878988,1781.0
52.227012795,1763.0
52.277146602,1682.0
52.327280409,1757.0
52.377414216,1728.0
52.427548023,1739.0
52.477681830,1821.0
52.527815637,1734.0
52.577949444,1712.0
52.628083251,1767.0
52.678217058,1803.0
52.728350865,1841.0
52.778484671,1740.0
52.828618478,1715.0
52.878752285,1689.0
52.928886092,1762.0
52.979019899,1785.0
53.029153706,1766.0
53.079287513,1767.0
53.129421320,1803.0
53.179555127,1779.0
53.229688934,1742.0
53.279822741,1785.0
53.329956548,1732.0
53.380090355,1784.0
53.430224162,1819.0
53.480357969,1810.0
53.530491776,1826.0
53.580625582,1784.0
53.630759389,1762.0
53.680893196,1788.0
53.731027003,1763.0
53.781160810,1768.0
53.831294617,1737.0
53.881428424,1678.0
53.931562231,1748.0
53.981696038,1754.0
54.031829845,1733.0
54.081963652,1733.0
54.132097459,1718.0
54.182231266,1705.0
54.232365073,1816.0
54.282498880,1754.0
54.332632686,1734.0
54.382766493,1783.0
54.432900300,1671.0
54.483034107,1740.0
54.533167914,1771.0
54.583301721,1789.0
54.633435528,1735.0
54.683569335,1806.0
54.733703142,1834.0
54.783836949,1750.0
54.833970756,1724.0
54.884104563,1762.0
54.934238370,1905.0
54.984372177,1747.0
55.034505984,1831.0
55.084639790,1833.0
55.134773597,1791.0
55.184907404,1778.0
55.235041211,1699.0
55.285175018,1850.0
55.335308825,1807.0
55.385442632,1716.0
55.435576439,1834.0
55.485710246,1720.0
55.535844053,1753.0
55.585977860,1754.0
55.636111667,1781.0
55.686245474,1777.0
55.736379281,1831.0
55.786513088,1759.0
55.836646894,1815.0
55.886780701,1832.0
55.936914508,1765.0
55.987048315,1753.0
56.037182122,1796.0
56.087315929,1809.0
56.137449736,1780.0
56.187583543,1820.0
56.237717350,1833.0
56.287851157,1761.0
56.337984964,1720.0
56.388118771,1729.0
56.438252578,1829.0
56.488386385,1754.0
56.538520192,1784.0
56.588653998,1804.0
56.638787805,1731.0
56.688921612,1775.0
56.739055419,1794.0
56.789189226,1791.0
56.839323033,1790.0
56.889456840,1800.0
56.939590647,1785.0
56.989724454,1857.0
57.039858261,1873.0
57.089992068,1842.0
57.140125875,1857.0
57.190259682,1856.0
57.240393489,1816.0
57.290527296,1780.0
57.340661102,1777.0
57.390794909,1790.0
57.440928716,1869.0
57.491062523,1798.0
57.541196330,1803.0
57.591330137,1829.0
57.641463944,1783.0
57.691597751,1761.0
57.741731558,1767.0
57.791865365,1798.0
57.841999172,1734.0
57.892132979,1832.0
57.942266786,1841.0
57.992400593,1826.0
58.042534400,1795.0
58.092668207,1781.0
58.142802013,1824.0
58.192935820,1713.0
58.243069627,1815.0
58.293203434,1860.0
58.343337241,1738.0
58.393471048,1811.0
58.443604855,1839.0
58.493738662,1764.0
58.543872469,1752.0
58.594006276,1936.0
58.644140083,1834.0
58.694273890,1823.0
58.744407697,1807.0
58.794541504,1806.0
58.844675311,1867.0
58.894809117,1766.0
58.944942924,1780.0
58.995076731,1785.0
59.045210538,1754.0
59.095344345,1861.0
59.145478152,1861.0
59.195611959,1815.0
59.245745766,1837.0
59.295879573,1824.0
59.346013380,1848.0
59.396147187,1752.0
59.446280994,1852.0
59.496414801,1826.0
59.546548608,1834.0
59.596682415,1913.0
59.646816221,1838.0
59.696950028,1785.0
59.747083835,1781.0
59.797217642,1895.0
59.847351449,1829.0
59.897485256,1831.0
59.947619063,1899.0
59.997752870,1833.0
60.047886677,1871.0
60.098020484,1826.0
60.148154291,1873.0
60.198288098,1931.0
60.248421905,1876.0
60.298555712,1867.0
60.348689519,1882.0
60.398823325,1775.0
60.448957132,1883.0
60.499090939,1848.0
60.549224746,1901.0
60.599358553,1731.0
60.649492360,1904.0
60.699626167,1905.0
60.749759974,1890.0
60.799893781,1942.0
60.850027588,1924.0
60.900161395,1975.0
60.950295202,1978.0
61.000429009,1842.0
61.050562816,1920.0
61.100696623,2034.0
61.150830429,1973.0
61.200964236,2020.0
61.251098043,1977.0
61.301231850,1996.0
61.351365657,2015.0
61.401499464,2026.0
61.451633271,2154.0
61.501767078,2068.0
61.551900885,2071.0
61.602034692,2068.0
61.652168499,2081.0
61.702302306,2086.0
61.752436113,2101.0
61.802569920,2171.0
61.852703727,2307.0
61.902837533,2236.0
61.952971340,2266.0
62.003105147,2451.0
62.053238954,2544.0
62.103372761,2664.0
62.153506568,2972.0
62.203640375,3021.0
62.253774182,3362.0
62.303907989,3503.0
62.354041796,3531.0
62.404175603,3612.0
62.454309410,3545.0
62.504443217,3343.0
62.554577024,3233.0
62.604710831,2973.0
62.654844638,2917.0
62.704978444,2704.0
62.755112251,2499.0
62.805246058,2389.0
62.855379865,2375.0
62.905513672,2314.0
62.955647479,2321.0
63.005781286,2284.0
63.055915093,2254.0
63.106048900,2216.0
63.156182707,2152.0
63.206316514,2239.0
63.256450321,2222.0
63.306584128,2160.0
63.356717935,2230.0
63.406851742,2192.0
63.456985548,2077.0
63.507119355,2149.0
63.557253162,2206.0
63.607386969,2088.0
63.657520776,2223.0
63.707654583,2133.0
63.757788390,2170.0
63.807922197,2213.0
63.858056004,2171.0
63.908189811,2127.0
63.958323618,2150.0
64.008457425,2093.0
64.058591232,2226.0
64.108725039,2290.0
64.158858846,2085.0
64.208992652,2198.0
64.259126459,2180.0
64.309260266,2124.0
64.359394073,2115.0
64.409527880,2210.0
64.459661687,2292.0
64.509795494,2332.0
64.559929301,2156.0
64.610063108,2321.0
64.660196915,2179.0
64.710330722,2250.0
64.760464529,2232.0
64.810598336,2190.0
64.860732143,2229.0
64.910865950,2251.0
64.960999756,2299.0
65.011133563,2351.0
65.061267370,2253.0
65.111401177,2268.0
65.161534984,2256.0
65.211668791,2251.0
65.261802598,2182.0
65.311936405,2330.0
65.362070212,2336.0
65.412204019,2227.0
65.462337826,2351.0
65.512471633,2236.0
65.562605440,2253.0
65.612739247,2298.0
65.662873054,2257.0
65.713006860,2247.0
65.763140667,2370.0
65.813274474,2276.0
65.863408281,2300.0
65.913542088,2350.0
65.963675895,2346.0
66.013809702,2403.0
66.063943509,2308.0
66.114077316,2328.0
66.164211123,2388.0
66.214344930,2405.0
66.264478737,2375.0
66.314612544,2422.0
66.364746351,2378.0
66.414880158,2350.0
66.465013964,2340.0
66.515147771,2368.0
66.565281578,2459.0
66.615415385,2344.0
66.665549192,2317.0
66.715682999,2250.0
66.765816806,2368.0
66.815950613,2342.0
66.866084420,2357.0
66.916218227,2346.0
66.966352034,2308.0
67.016485841,2375.0
67.066619648,2444.0
67.116753455,2455.0
67.166887262,2302.0
67.217021069,2331.0
67.267154875,2435.0
67.317288682,2425.0
67.367422489,2371.0
67.417556296,2356.0
67.467690103,2360.0
67.517823910,2360.0
67.567957717,2378.0
67.618091524,2375.0
67.668225331,2430.0
67.718359138,2408.0
67.768492945,2392.0
67.818626752,2405.0
67.868760559,2429.0
67.918894366,2478.0
67.969028173,2392.0
68.019161979,2312.0
68.069295786,2475.0
68.119429593,2355.0
68.169563400,2380.0
68.219697207,2289.0
68.269831014,2355.0
68.319964821,2341.0
68.370098628,2338.0
68.420232435,2355.0
68.470366242,2385.0
68.520500049,2321.0
68.570633856,2494.0
68.620767663,2413.0
68.670901470,2358.0
68.721035277,2283.0
68.771169083,2295.0
68.821302890,2382.0
68.871436697,2349.0
68.921570504,2403.0
68.971704311,2341.0
69.021838118,2440.0
69.071971925,2306.0
69.122105732,2314.0
69.172239539,2350.0
69.222373346,2375.0
69.272507153,2327.0
69.322640960,2396.0
69.372774767,2268.0
69.422908574,2444.0
69.473042381,2243.0
69.523176187,2258.0
69.573309994,2249.0
69.623443801,2282.0
69.673577608,2274.0
69.723711415,2311.0
69.773845222,2230.0
69.823979029,2266.0
69.874112836,2251.0
69.924246643,2357.0
69.974380450,2326.0
70.024514257,2278.0
70.074648064,2353.0
70.124781871,2292.0
70.174915678,2278.0
70.225049485,2087.0
70.275183291,2397.0
70.325317098,2333.0
70.375450905,2302.0
70.425584712,2188.0
70.475718519,2258.0
70.525852326,2307.0
70.575986133,2293.0
70.626119940,2264.0
70.676253747,2230.0
70.726387554,2326.0
70.776521361,2253.0
70.826655168,2237.0
70.876788975,2097.0
70.926922782,2227.0
70.977056589,2252.0
71.027190396,2222.0
71.077324202,2144.0
71.127458009,2198.0
71.177591816,2200.0
71.227725623,2155.0
71.277859430,2209.0
71.327993237,2258.0
71.378127044,2203.0
71.428260851,2170.0
71.478394658,2126.0
71.528528465,2252.0
71.578662272,2240.0
71.628796079,2271.0
71.678929886,2193.0
71.729063693,2185.0
71.779197500,2095.0
71.829331306,2153.0
71.879465113,2234.0
71.929598920,2218.0
71.979732727,2182.0
72.029866534,2155.0
72.080000341,2066.0
72.130134148,2123.0
72.180267955,2110.0
72.230401762,2109.0
72.280535569,2110.0
72.330669376,2089.0
72.380803183,2120.0
72.430936990,2086.0
72.481070797,2151.0
72.531204604,2204.0
72.581338410,2098.0
72.631472217,2064.0
72.681606024,2093.0
72.731739831,2106.0
72.781873638,2105.0
72.832007445,2171.0
72.882141252,2164.0
72.932275059,2103.0
72.982408866,2074.0
73.032542673,2084.0
73.082676480,2134.0
73.132810287,2059.0
73.182944094,2064.0
73.233077901,2106.0
73.283211708,2040.0
73.333345514,2094.0
73.383479321,2035.0
73.433613128,2068.0
73.483746935,2047.0
73.533880742,1986.0
73.584014549,2021.0
73.634148356,2042.0
73.684282163,2000.0
73.734415970,1975.0
73.784549777,2014.0
73.834683584,2086.0
73.884817391,2018.0
73.934951198,2027.0
73.985085005,1994.0
74.035218812,2025.0
74.085352618,2021.0
74.135486425,2067.0
74.185620232,2109.0
74.235754039,2108.0
74.285887846,2079.0
74.336021653,2018.0
74.386155460,2146.0
74.436289267,2089.0
74.486423074,2085.0
74.536556881,2192.0
74.586690688,2265.0
74.636824495,2259.0
74.686958302,2375.0
74.737092109,2307.0
74.787225916,2405.0
74.837359722,2401.0
74.887493529,2328.0
74.937627336,2316.0
74.987761143,2205.0
75.037894950,2123.0
75.088028757,2033.0
75.138162564,2035.0
75.188296371,2055.0
75.238430178,1958.0
75.288563985,1973.0
75.338697792,2005.0
75.388831599,1904.0
75.438965406,1941.0
75.489099213,1912.0
75.539233020,1915.0
75.589366827,1840.0
75.639500633,1949.0
75.689634440,1798.0
75.739768247,1914.0
75.789902054,1793.0
75.840035861,1855.0
75.890169668,1847.0
75.940303475,1885.0
75.990437282,1771.0
76.040571089,1830.0
76.090704896,1765.0
76.140838703,1855.0
76.190972510,1875.0
76.241106317,1883.0
76.291240124,1853.0
76.341373931,1841.0
76.391507737,1830.0
76.441641544,1781.0
76.491775351,1837.0
76.541909158,1737.0
76.592042965,1708.0
76.642176772,1761.0
76.692310579,1864.0
76.742444386,1772.0
76.792578193,1742.0
76.842712000,1710.0
76.892845807,1786.0
76.942979614,1841.0
76.993113421,1722.0
77.043247228,1762.0
77.093381035,1697.0
77.143514841,1693.0
77.193648648,1757.0
77.243782455,1851.0
77.293916262,1693.0
77.344050069,1785.0
77.394183876,1809.0
77.444317683,1735.0
77.494451490,1781.0
77.544585297,1723.0
77.594719104,1721.0
77.644852911,1676.0
77.694986718,1726.0
77.745120525,1690.0
77.795254332,1726.0
77.845388139,1706.0
77.895521945,1784.0
77.945655752,1670.0
77.995789559,1770.0
78.045923366,1724.0
78.096057173,1800.0
78.146190980,1794.0
78.196324787,1845.0
78.246458594,1744.0
78.296592401,1855.0
78.346726208,1807.0
78.396860015,1866.0
78.446993822,1847.0
78.497127629,1863.0
78.547261436,1974.0
78.597395243,1931.0
78.647529049,2038.0
78.697662856,1921.0
78.747796663,1993.0
78.797930470,1936.0
78.848064277,1832.0
78.898198084,1883.0
78.948331891,1827.0
78.998465698,1705.0
79.048599505,1780.0
79.098733312,1717.0
79.148867119,1772.0
79.199000926,1705.0
79.249134733,1698.0
79.299268540,1733.0
79.349402347,1664.0
79.399536153,1666.0
79.449669960,1629.0
79.499803767,1746.0
79.549937574,1640.0
79.600071381,1591.0
79.650205188,1688.0
79.700338995,1621.0
79.750472802,1618.0
79.800606609,1591.0
79.850740416,1630.0
79.900874223,1641.0
79.951008030,1617.0
80.001141837,1568.0
80.051275644,1619.0
80.101409451,1612.0
80.151543258,1707.0
80.201677064,1615.0
80.251810871,1632.0
80.301944678,1656.0
80.352078485,1627.0
80.402212292,1643.0
80.452346099,1628.0
80.502479906,1590.0
80.552613713,1565.0
80.602747520,1661.0
80.652881327,1616.0
80.703015134,1681.0
80.753148941,1573.0
80.803282748,1567.0
80.853416555,1574.0
80.903550362,1529.0
80.953684168,1640.0
81.003817975,1683.0
81.053951782,1528.0
81.104085589,1669.0
81.154219396,1581.0
81.204353203,1604.0
81.254487010,1557.0
81.304620817,1519.0
81.354754624,1508.0
81.404888431,1617.0
81.455022238,1552.0
81.505156045,1545.0
81.555289852,1551.0
81.605423659,1570.0
81.655557466,1566.0
81.705691272,1596.0
81.755825079,1634.0
81.805958886,1546.0
81.856092693,1586.0
81.906226500,1564.0
81.956360307,1607.0
82.006494114,1508.0
82.056627921,1612.0
82.106761728,1574.0
82.156895535,1571.0
82.207029342,1538.0
82.257163149,1462.0
82.307296956,1520.0
82.357430763,1525.0
82.407564570,1526.0
82.457698376,1548.0
82.507832183,1538.0
82.557965990,1462.0
82.608099797,1515.0
82.658233604,1472.0
82.708367411,1490.0
82.758501218,1545.0
82.808635025,1572.0
82.858768832,1524.0
82.908902639,1449.0
82.959036446,1559.0
83.009170253,1511.0
83.059304060,1540.0
83.109437867,1562.0
83.159571674,1543.0
83.209705480,1545.0
83.259839287,1528.0
83.309973094,1480.0
83.360106901,1467.0
83.410240708,1530.0
83.460374515,1480.0
83.510508322,1534.0
83.560642129,1481.0
83.610775936,1483.0
83.660909743,1468.0
83.711043550,1529.0
83.761177357,1525.0
83.811311164,1552.0
83.861444971,1540.0
83.911578778,1539.0
83.961712584,1489.0
84.011846391,1421.0
84.061980198,1552.0
84.112114005,1554.0
84.162247812,1495.0
84.212381619,1432.0
84.262515426,1527.0
84.312649233,1476.0
84.362783040,1413.0
84.412916847,1543.0
84.463050654,1458.0
84.513184461,1509.0
84.563318268,1459.0
84.613452075,1441.0
84.663585882,1490.0
84.713719689,1421.0
84.763853495,1457.0
84.813987302,1446.0
84.864121109,1484.0
84.914254916,1516.0
84.964388723,1517.0
85.014522530,1534.0
85.064656337,1448.0
85.114790144,1527.0
85.164923951,1494.0
85.215057758,1395.0
85.265191565,1469.0
85.315325372,1440.0
85.365459179,1483.0
85.415592986,1492.0
85.465726793,1509.0
85.515860599,1499.0
85.565994406,1402.0
85.616128213,1451.0
85.666262020,1490.0
85.716395827,1455.0
85.766529634,1472.0
85.816663441,1506.0
85.866797248,1441.0
85.916931055,1454.0
85.967064862,1451.0
86.017198669,1427.0
86.067332476,1429.0
86.117466283,1437.0
86.167600090,1495.0
86.217733897,1499.0
86.267867703,1480.0
86.318001510,1439.0
86.368135317,1477.0
86.418269124,1441.0
86.468402931,1410.0
86.518536738,1367.0
86.568670545,1430.0
86.618804352,1415.0
86.668938159,1455.0
86.719071966,1423.0
86.769205773,1471.0
86.819339580,1402.0
86.869473387,1461.0
86.919607194,1374.0
86.969741001,1450.0
87.019874807,1395.0
87.070008614,1460.0
87.120142421,1371.0
87.170276228,1377.0
87.220410035,1465.0
87.270543842,1441.0
87.320677649,1420.0
87.370811456,1429.0
87.420945263,1462.0
87.471079070,1429.0
87.521212877,1418.0
87.571346684,1436.0
87.621480491,1389.0
87.671614298,1375.0
87.721748105,1524.0
87.771881911,1375.0
87.822015718,1369.0
87.872149525,1456.0
87.922283332,1464.0
87.972417139,1413.0
88.022550946,1401.0
88.072684753,1469.0
88.122818560,1413.0
88.172952367,1398.0
88.223086174,1389.0
88.273219981,1327.0
88.323353788,1437.0
88.373487595,1466.0
88.423621402,1422.0
88.473755209,1350.0
88.523889016,1437.0
88.574022822,1391.0
88.624156629,1442.0
88.674290436,1377.0
88.724424243,1390.0
88.774558050,1433.0
88.824691857,1382.0
88.874825664,1382.0
88.924959471,1441.0
88.975093278,1397.0
89.025227085,1382.0
89.075360892,1453.0
89.125494699,1383.0
89.175628506,1308.0
89.225762313,1402.0
89.275896120,1409.0
89.326029926,1373.0
89.376163733,1373.0
89.426297540,1450.0
89.476431347,1382.0
89.526565154,1382.0
89.576698961,1407.0
89.626832768,1381.0
89.676966575,1412.0
89.727100382,1319.0
89.777234189,1441.0
89.827367996,1433.0
89.877501803,1385.0
89.927635610,1430.0
89.977769417,1351.0
90.027903224,1374.0
90.078037030,1439.0
90.128170837,1388.0
90.178304644,1385.0
90.228438451,1364.0
90.278572258,1395.0
90.328706065,1347.0
90.378839872,1409.0
90.428973679,1390.0
90.479107486,1427.0
90.529241293,1363.0
90.579375100,1396.0
90.629508907,1388.0
90.679642714,1434.0
90.729776521,1401.0
90.779910328,1374.0
90.830044134,1403.0
90.880177941,1419.0
90.930311748,1355.0
90.980445555,1321.0
91.030579362,1358.0
91.080713169,1281.0
91.130846976,1447.0
91.180980783,1442.0
91.231114590,1439.0
91.281248397,1317.0
91.331382204,1334.0
91.381516011,1343.0
91.431649818,1420.0
91.481783625,1353.0
91.531917432,1342.0
91.582051238,1322.0
91.632185045,1380.0
91.682318852,1330.0
91.732452659,1392.0
91.782586466,1365.0
91.832720273,1337.0
91.882854080,1405.0
91.932987887,1456.0
91.983121694,1409.0
92.033255501,1334.0
92.083389308,1353.0
92.133523115,1349.0
92.183656922,1348.0
92.233790729,1333.0
92.283924536,1363.0
92.334058342,1410.0
92.384192149,1286.0
92.434325956,1394.0
92.484459763,1333.0
92.534593570,1367.0
92.584727377,1343.0
92.634861184,1404.0
92.684994991,1308.0
92.735128798,1388.0
92.785262605,1336.0
92.835396412,1319.0
92.885530219,1383.0
92.935664026,1387.0
92.985797833,1413.0
93.035931640,1435.0
93.086065447,1410.0
93.136199253,1297.0
93.186333060,1388.0
93.236466867,1352.0
93.286600674,1412.0
93.336734481,1344.0
93.386868288,1379.0
93.437002095,1323.0
93.487135902,1399.0
93.537269709,1372.0
93.587403516,1407.0
93.637537323,1378.0
93.687671130,1340.0
93.737804937,1373.0
93.787938744,1398.0
93.838072551,1372.0
93.888206357,1444.0
93.938340164,1353.0
93.988473971,1357.0
94.038607778,1357.0
94.088741585,1423.0
94.138875392,1472.0
94.189009199,1396.0
94.239143006,1428.0
94.289276813,1402.0
94.339410620,1456.0
94.389544427,1374.0
94.439678234,1404.0
94.489812041,1411.0
94.539945848,1363.0
94.590079655,1333.0
94.640213461,1327.0
94.690347268,1409.0
94.740481075,1426.0
94.790614882,1329.0
94.840748689,1356.0
94.890882496,1347.0
94.941016303,1317.0
94.991150110,1374.0