File: OriginPro/XRD from Panalytical X'Pert PRO/In-Situ/FicheirosXRD_Insitu/NiNws_30°C.csv
[Measurement conditions]
Sample identification,
Comment - 1,"finito"
Comment - 2,"Configuration=MRI TC-Basic Stage, Owner=User-1, Creation date=26-10-2009 9:18:44"
Comment - 3,"Goniometer=PW3050/60 (Theta/Theta); Minimum step size 2Theta:0.001; Minimum step size Omega:0.001"
Comment - 4,"Sample stage=MRI TC-Basic (PtRh heat strip)"
Comment - 5,"Diffractometer system=XPERT-PRO"
Comment - 6,"Measurement program=FS-L, Owner=joana, Creation date=25-11-2014 17:28:08"
Anode material,Cu
K-Alpha1 wavelength,1.5405980
K-Alpha2 wavelength,1.5444260
Ratio K-Alpha2/K-Alpha1,0.500
Divergence slit,Fixed,0.76mm
Monochromator used,NO
Generator voltage, 45
Tube current, 40
File date and time,16-Dez-2017 07:19
Unit cell,
h k l, 0 0 0
Temperature [K],303
Scan axis,Gonio
Scan range,24.995999996,94.999505744
Scan step size,0.0167113
No. of points, 4189
Scan type,CONTINUOUS
Time per step,118.110
[Scan points]
Angle,Intensity
25.004355630,2440.0
25.054489437,2356.0
25.104623244,2255.0
25.154757051,2316.0
25.204890858,2295.0
25.255024665,2310.0
25.305158472,2323.0
25.355292279,2282.0
25.405426085,2328.0
25.455559892,2337.0
25.505693699,2331.0
25.555827506,2285.0
25.605961313,2318.0
25.656095120,2226.0
25.706228927,2304.0
25.756362734,2205.0
25.806496541,2312.0
25.856630348,2271.0
25.906764155,2271.0
25.956897962,2332.0
26.007031769,2128.0
26.057165576,2300.0
26.107299383,2289.0
26.157433189,2309.0
26.207566996,2310.0
26.257700803,2311.0
26.307834610,2331.0
26.357968417,2284.0
26.408102224,2286.0
26.458236031,2202.0
26.508369838,2274.0
26.558503645,2341.0
26.608637452,2335.0
26.658771259,2270.0
26.708905066,2311.0
26.759038873,2176.0
26.809172680,2311.0
26.859306487,2288.0
26.909440293,2292.0
26.959574100,2261.0
27.009707907,2281.0
27.059841714,2211.0
27.109975521,2305.0
27.160109328,2285.0
27.210243135,2249.0
27.260376942,2320.0
27.310510749,2244.0
27.360644556,2274.0
27.410778363,2244.0
27.460912170,2233.0
27.511045977,2255.0
27.561179784,2173.0
27.611313591,2300.0
27.661447398,2317.0
27.711581204,2268.0
27.761715011,2174.0
27.811848818,2222.0
27.861982625,2304.0
27.912116432,2272.0
27.962250239,2299.0
28.012384046,2185.0
28.062517853,2174.0
28.112651660,2219.0
28.162785467,2343.0
28.212919274,2253.0
28.263053081,2367.0
28.313186888,2950.0
28.363320695,2536.0
28.413454502,2288.0
28.463588308,2304.0
28.513722115,2347.0
28.563855922,2232.0
28.613989729,2338.0
28.664123536,2363.0
28.714257343,2397.0
28.764391150,2403.0
28.814524957,2405.0
28.864658764,2422.0
28.914792571,2250.0
28.964926378,2431.0
29.015060185,2336.0
29.065193992,2289.0
29.115327799,2261.0
29.165461606,2328.0
29.215595412,2287.0
29.265729219,2281.0
29.315863026,2244.0
29.365996833,2285.0
29.416130640,2234.0
29.466264447,2227.0
29.516398254,2148.0
29.566532061,2194.0
29.616665868,2142.0
29.666799675,2228.0
29.716933482,2226.0
29.767067289,2255.0
29.817201096,2179.0
29.867334903,2256.0
29.917468710,2351.0
29.967602516,2318.0
30.017736323,2308.0
30.067870130,2150.0
30.118003937,2294.0
30.168137744,2240.0
30.218271551,2290.0
30.268405358,2325.0
30.318539165,2326.0
30.368672972,2260.0
30.418806779,2177.0
30.468940586,2236.0
30.519074393,2244.0
30.569208200,2271.0
30.619342007,2208.0
30.669475814,2199.0
30.719609620,2101.0
30.769743427,2320.0
30.819877234,2072.0
30.870011041,2152.0
30.920144848,2157.0
30.970278655,2163.0
31.020412462,2092.0
31.070546269,2154.0
31.120680076,2179.0
31.170813883,2170.0
31.220947690,2203.0
31.271081497,2180.0
31.321215304,2237.0
31.371349111,2206.0
31.421482918,2194.0
31.471616724,2176.0
31.521750531,2130.0
31.571884338,2228.0
31.622018145,2103.0
31.672151952,2129.0
31.722285759,2161.0
31.772419566,2099.0
31.822553373,2141.0
31.872687180,2237.0
31.922820987,2183.0
31.972954794,2114.0
32.023088601,2186.0
32.073222408,2133.0
32.123356215,2102.0
32.173490022,2146.0
32.223623829,2125.0
32.273757635,2100.0
32.323891442,2145.0
32.374025249,2172.0
32.424159056,2178.0
32.474292863,2118.0
32.524426670,2118.0
32.574560477,2131.0
32.624694284,2194.0
32.674828091,2191.0
32.724961898,2188.0
32.775095705,2146.0
32.825229512,2189.0
32.875363319,2136.0
32.925497126,2185.0
32.975630933,2201.0
33.025764739,2145.0
33.075898546,2191.0
33.126032353,2190.0
33.176166160,2126.0
33.226299967,2139.0
33.276433774,2098.0
33.326567581,2113.0
33.376701388,2129.0
33.426835195,2094.0
33.476969002,2190.0
33.527102809,2069.0
33.577236616,2165.0
33.627370423,2081.0
33.677504230,2060.0
33.727638037,2137.0
33.777771843,2114.0
33.827905650,2136.0
33.878039457,2120.0
33.928173264,2144.0
33.978307071,2174.0
34.028440878,2166.0
34.078574685,2093.0
34.128708492,2146.0
34.178842299,2079.0
34.228976106,2220.0
34.279109913,2108.0
34.329243720,2166.0
34.379377527,2069.0
34.429511334,2064.0
34.479645141,2184.0
34.529778947,2120.0
34.579912754,2111.0
34.630046561,2146.0
34.680180368,2184.0
34.730314175,2100.0
34.780447982,2099.0
34.830581789,2021.0
34.880715596,2193.0
34.930849403,2155.0
34.980983210,2263.0
35.031117017,2135.0
35.081250824,2192.0
35.131384631,2222.0
35.181518438,2143.0
35.231652245,2158.0
35.281786051,2191.0
35.331919858,2231.0
35.382053665,2227.0
35.432187472,2337.0
35.482321279,2284.0
35.532455086,2385.0
35.582588893,2416.0
35.632722700,2397.0
35.682856507,2479.0
35.732990314,2366.0
35.783124121,2406.0
35.833257928,2299.0
35.883391735,2241.0
35.933525542,2392.0
35.983659349,2258.0
36.033793156,2267.0
36.083926962,2305.0
36.134060769,2212.0
36.184194576,2208.0
36.234328383,2147.0
36.284462190,2173.0
36.334595997,2118.0
36.384729804,2310.0
36.434863611,2165.0
36.484997418,2214.0
36.535131225,2254.0
36.585265032,2260.0
36.635398839,2318.0
36.685532646,2346.0
36.735666453,2354.0
36.785800260,2492.0
36.835934066,2537.0
36.886067873,2719.0
36.936201680,2802.0
36.986335487,3107.0
37.036469294,3481.0
37.086603101,4112.0
37.136736908,4701.0
37.186870715,5453.0
37.237004522,5737.0
37.287138329,5796.0
37.337272136,5479.0
37.387405943,5022.0
37.437539750,4321.0
37.487673557,3631.0
37.537807364,3129.0
37.587941170,2917.0
37.638074977,2736.0
37.688208784,2502.0
37.738342591,2474.0
37.788476398,2312.0
37.838610205,2346.0
37.888744012,2212.0
37.938877819,2293.0
37.989011626,2244.0
38.039145433,2234.0
38.089279240,2185.0
38.139413047,2197.0
38.189546854,2284.0
38.239680661,2245.0
38.289814468,2098.0
38.339948274,2106.0
38.390082081,2075.0
38.440215888,2066.0
38.490349695,2057.0
38.540483502,2079.0
38.590617309,2165.0
38.640751116,2029.0
38.690884923,2165.0
38.741018730,2095.0
38.791152537,2006.0
38.841286344,2058.0
38.891420151,2103.0
38.941553958,2135.0
38.991687765,2113.0
39.041821572,2115.0
39.091955378,2075.0
39.142089185,2101.0
39.192222992,2041.0
39.242356799,2010.0
39.292490606,2136.0
39.342624413,2004.0
39.392758220,2079.0
39.442892027,2084.0
39.493025834,2083.0
39.543159641,1999.0
39.593293448,1997.0
39.643427255,2090.0
39.693561062,2209.0
39.743694869,2202.0
39.793828676,2511.0
39.843962482,2657.0
39.894096289,2333.0
39.944230096,2418.0
39.994363903,2185.0
40.044497710,2105.0
40.094631517,2160.0
40.144765324,2081.0
40.194899131,2177.0
40.245032938,2066.0
40.295166745,2082.0
40.345300552,2016.0
40.395434359,2024.0
40.445568166,1965.0
40.495701973,2036.0
40.545835780,2040.0
40.595969587,2039.0
40.646103393,2085.0
40.696237200,2043.0
40.746371007,2008.0
40.796504814,1953.0
40.846638621,2131.0
40.896772428,1973.0
40.946906235,2013.0
40.997040042,1923.0
41.047173849,2065.0
41.097307656,1971.0
41.147441463,2050.0
41.197575270,2007.0
41.247709077,2026.0
41.297842884,2078.0
41.347976691,2020.0
41.398110497,2003.0
41.448244304,2056.0
41.498378111,2064.0
41.548511918,2096.0
41.598645725,2051.0
41.648779532,1989.0
41.698913339,2004.0
41.749047146,2045.0
41.799180953,2045.0
41.849314760,2017.0
41.899448567,2157.0
41.949582374,1990.0
41.999716181,2062.0
42.049849988,1987.0
42.099983795,1997.0
42.150117601,2098.0
42.200251408,2039.0
42.250385215,2120.0
42.300519022,2101.0
42.350652829,2172.0
42.400786636,2168.0
42.450920443,2128.0
42.501054250,2097.0
42.551188057,2209.0
42.601321864,2233.0
42.651455671,2284.0
42.701589478,2280.0
42.751723285,2382.0
42.801857092,2458.0
42.851990899,2724.0
42.902124705,2804.0
42.952258512,2974.0
43.002392319,3324.0
43.052526126,3781.0
43.102659933,4577.0
43.152793740,5321.0
43.202927547,6291.0
43.253061354,6957.0
43.303195161,7247.0
43.353328968,7257.0
43.403462775,6596.0
43.453596582,5910.0
43.503730389,4891.0
43.553864196,4246.0
43.603998003,3642.0
43.654131809,3144.0
43.704265616,2896.0
43.754399423,2648.0
43.804533230,2496.0
43.854667037,2380.0
43.904800844,2421.0
43.954934651,2374.0
44.005068458,2223.0
44.055202265,2147.0
44.105336072,2132.0
44.155469879,2144.0
44.205603686,2118.0
44.255737493,2162.0
44.305871300,2079.0
44.356005107,2058.0
44.406138913,2053.0
44.456272720,2161.0
44.506406527,2153.0
44.556540334,2092.0
44.606674141,2046.0
44.656807948,1984.0
44.706941755,1943.0
44.757075562,2003.0
44.807209369,2040.0
44.857343176,2006.0
44.907476983,2004.0
44.957610790,1985.0
45.007744597,1986.0
45.057878404,1987.0
45.108012211,1923.0
45.158146018,2001.0
45.208279824,2001.0
45.258413631,2007.0
45.308547438,2050.0
45.358681245,2099.0
45.408815052,2204.0
45.458948859,2176.0
45.509082666,2173.0
45.559216473,2030.0
45.609350280,2122.0
45.659484087,1913.0
45.709617894,1977.0
45.759751701,1949.0
45.809885508,2019.0
45.860019315,1983.0
45.910153122,2015.0
45.960286928,2054.0
46.010420735,2172.0
46.060554542,2214.0
46.110688349,2339.0
46.160822156,2711.0
46.210955963,3085.0
46.261089770,4437.0
46.311223577,7339.0
46.361357384,5495.0
46.411491191,3929.0
46.461624998,5501.0
46.511758805,3035.0
46.561892612,2962.0
46.612026419,3284.0
46.662160226,3542.0
46.712294032,3626.0
46.762427839,3319.0
46.812561646,3094.0
46.862695453,2572.0
46.912829260,2227.0
46.962963067,2135.0
47.013096874,2002.0
47.063230681,1951.0
47.113364488,1943.0
47.163498295,1909.0
47.213632102,1897.0
47.263765909,1920.0
47.313899716,1854.0
47.364033523,1919.0
47.414167330,1969.0
47.464301136,1907.0
47.514434943,1956.0
47.564568750,1848.0
47.614702557,1857.0
47.664836364,1799.0
47.714970171,1918.0
47.765103978,1955.0
47.815237785,1901.0
47.865371592,1958.0
47.915505399,1878.0
47.965639206,1871.0
48.015773013,1962.0
48.065906820,1867.0
48.116040627,1895.0
48.166174434,1910.0
48.216308240,1807.0
48.266442047,1855.0
48.316575854,1857.0
48.366709661,1814.0
48.416843468,1857.0
48.466977275,1778.0
48.517111082,1909.0
48.567244889,1849.0
48.617378696,1824.0
48.667512503,1886.0
48.717646310,1916.0
48.767780117,1884.0
48.817913924,1909.0
48.868047731,1880.0
48.918181538,1881.0
48.968315344,1909.0
49.018449151,1730.0
49.068582958,1923.0
49.118716765,1808.0
49.168850572,1818.0
49.218984379,1888.0
49.269118186,1793.0
49.319251993,1800.0
49.369385800,1837.0
49.419519607,1746.0
49.469653414,1893.0
49.519787221,1946.0
49.569921028,1918.0
49.620054835,2097.0
49.670188642,1967.0
49.720322449,1950.0
49.770456255,1913.0
49.820590062,1859.0
49.870723869,1801.0
49.920857676,1854.0
49.970991483,1801.0
50.021125290,1865.0
50.071259097,1908.0
50.121392904,1810.0
50.171526711,1826.0
50.221660518,1816.0
50.271794325,1857.0
50.321928132,1832.0
50.372061939,1904.0
50.422195746,1867.0
50.472329553,2014.0
50.522463359,2172.0
50.572597166,2188.0
50.622730973,2253.0
50.672864780,2111.0
50.722998587,2131.0
50.773132394,1994.0
50.823266201,1916.0
50.873400008,1855.0
50.923533815,1911.0
50.973667622,1827.0
51.023801429,1857.0
51.073935236,1805.0
51.124069043,1784.0
51.174202850,1761.0
51.224336657,1851.0
51.274470463,1771.0
51.324604270,1749.0
51.374738077,1738.0
51.424871884,1719.0
51.475005691,1752.0
51.525139498,1792.0
51.575273305,1815.0
51.625407112,1901.0
51.675540919,1742.0
51.725674726,1707.0
51.775808533,1784.0
51.825942340,1826.0
51.876076147,1750.0
51.926209954,1849.0
51.976343761,1805.0
52.026477567,1789.0
52.076611374,1781.0
52.126745181,1813.0
52.176878988,1766.0
52.227012795,1824.0
52.277146602,1768.0
52.327280409,1760.0
52.377414216,1797.0
52.427548023,1752.0
52.477681830,1796.0
52.527815637,1765.0
52.577949444,1863.0
52.628083251,1770.0
52.678217058,1841.0
52.728350865,1787.0
52.778484671,1735.0
52.828618478,1792.0
52.878752285,1892.0
52.928886092,1777.0
52.979019899,1761.0
53.029153706,1777.0
53.079287513,1776.0
53.129421320,1749.0
53.179555127,1685.0
53.229688934,1739.0
53.279822741,1804.0
53.329956548,1787.0
53.380090355,1754.0
53.430224162,1791.0
53.480357969,1834.0
53.530491776,1775.0
53.580625582,1809.0
53.630759389,1737.0
53.680893196,1736.0
53.731027003,1690.0
53.781160810,1782.0
53.831294617,1787.0
53.881428424,1752.0
53.931562231,1773.0
53.981696038,1780.0
54.031829845,1797.0
54.081963652,1796.0
54.132097459,1755.0
54.182231266,1748.0
54.232365073,1737.0
54.282498880,1741.0
54.332632686,1750.0
54.382766493,1705.0
54.432900300,1719.0
54.483034107,1663.0
54.533167914,1746.0
54.583301721,1702.0
54.633435528,1781.0
54.683569335,1727.0
54.733703142,1725.0
54.783836949,1759.0
54.833970756,1739.0
54.884104563,1691.0
54.934238370,1750.0
54.984372177,1719.0
55.034505984,1763.0
55.084639790,1868.0
55.134773597,1694.0
55.184907404,1709.0
55.235041211,1670.0
55.285175018,1658.0
55.335308825,1774.0
55.385442632,1699.0
55.435576439,1709.0
55.485710246,1760.0
55.535844053,1803.0
55.585977860,1707.0
55.636111667,1750.0
55.686245474,1745.0
55.736379281,1770.0
55.786513088,1723.0
55.836646894,1790.0
55.886780701,1730.0
55.936914508,1757.0
55.987048315,1670.0
56.037182122,1771.0
56.087315929,1714.0
56.137449736,1720.0
56.187583543,1742.0
56.237717350,1722.0
56.287851157,1737.0
56.337984964,1719.0
56.388118771,1702.0
56.438252578,1738.0
56.488386385,1697.0
56.538520192,1728.0
56.588653998,1785.0
56.638787805,1728.0
56.688921612,1742.0
56.739055419,1711.0
56.789189226,1745.0
56.839323033,1722.0
56.889456840,1677.0
56.939590647,1698.0
56.989724454,1762.0
57.039858261,1679.0
57.089992068,1772.0
57.140125875,1817.0
57.190259682,1782.0
57.240393489,1797.0
57.290527296,1694.0
57.340661102,1801.0
57.390794909,1779.0
57.440928716,1808.0
57.491062523,1822.0
57.541196330,1820.0
57.591330137,1737.0
57.641463944,1765.0
57.691597751,1745.0
57.741731558,1729.0
57.791865365,1718.0
57.841999172,1678.0
57.892132979,1792.0
57.942266786,1758.0
57.992400593,1744.0
58.042534400,1699.0
58.092668207,1629.0
58.142802013,1714.0
58.192935820,1739.0
58.243069627,1654.0
58.293203434,1756.0
58.343337241,1710.0
58.393471048,1659.0
58.443604855,1773.0
58.493738662,1610.0
58.543872469,1736.0
58.594006276,1702.0
58.644140083,1765.0
58.694273890,1668.0
58.744407697,1713.0
58.794541504,1823.0
58.844675311,1717.0
58.894809117,1759.0
58.944942924,1704.0
58.995076731,1738.0
59.045210538,1706.0
59.095344345,1691.0
59.145478152,1674.0
59.195611959,1608.0
59.245745766,1699.0
59.295879573,1785.0
59.346013380,1644.0
59.396147187,1718.0
59.446280994,1676.0
59.496414801,1681.0
59.546548608,1638.0
59.596682415,1685.0
59.646816221,1735.0
59.696950028,1709.0
59.747083835,1701.0
59.797217642,1653.0
59.847351449,1674.0
59.897485256,1726.0
59.947619063,1713.0
59.997752870,1699.0
60.047886677,1707.0
60.098020484,1631.0
60.148154291,1707.0
60.198288098,1712.0
60.248421905,1776.0
60.298555712,1723.0
60.348689519,1704.0
60.398823325,1678.0
60.448957132,1714.0
60.499090939,1735.0
60.549224746,1804.0
60.599358553,1754.0
60.649492360,1748.0
60.699626167,1605.0
60.749759974,1731.0
60.799893781,1745.0
60.850027588,1661.0
60.900161395,1690.0
60.950295202,1715.0
61.000429009,1666.0
61.050562816,1734.0
61.100696623,1763.0
61.150830429,1730.0
61.200964236,1803.0
61.251098043,1751.0
61.301231850,1860.0
61.351365657,1735.0
61.401499464,1794.0
61.451633271,1807.0
61.501767078,1712.0
61.551900885,1747.0
61.602034692,1792.0
61.652168499,1768.0
61.702302306,1836.0
61.752436113,1814.0
61.802569920,1857.0
61.852703727,1823.0
61.902837533,1857.0
61.952971340,1773.0
62.003105147,1902.0
62.053238954,1804.0
62.103372761,1867.0
62.153506568,1822.0
62.203640375,1907.0
62.253774182,1910.0
62.303907989,1998.0
62.354041796,2048.0
62.404175603,2007.0
62.454309410,2041.0
62.504443217,2153.0
62.554577024,2326.0
62.604710831,2459.0
62.654844638,2574.0
62.704978444,2718.0
62.755112251,3157.0
62.805246058,3479.0
62.855379865,3523.0
62.905513672,3705.0
62.955647479,3655.0
63.005781286,3492.0
63.055915093,3371.0
63.106048900,3133.0
63.156182707,2810.0
63.206316514,2668.0
63.256450321,2512.0
63.306584128,2354.0
63.356717935,2267.0
63.406851742,2117.0
63.456985548,2078.0
63.507119355,2087.0
63.557253162,1995.0
63.607386969,1926.0
63.657520776,1939.0
63.707654583,1807.0
63.757788390,1844.0
63.807922197,1782.0
63.858056004,1842.0
63.908189811,1805.0
63.958323618,1814.0
64.008457425,1797.0
64.058591232,1825.0
64.108725039,1840.0
64.158858846,1839.0
64.208992652,1867.0
64.259126459,1855.0
64.309260266,1821.0
64.359394073,1792.0
64.409527880,1823.0
64.459661687,1885.0
64.509795494,1846.0
64.559929301,1833.0
64.610063108,1814.0
64.660196915,1804.0
64.710330722,1805.0
64.760464529,1803.0
64.810598336,1854.0
64.860732143,1829.0
64.910865950,1771.0
64.960999756,1762.0
65.011133563,1817.0
65.061267370,1804.0
65.111401177,1764.0
65.161534984,1811.0
65.211668791,1830.0
65.261802598,1720.0
65.311936405,1849.0
65.362070212,1763.0
65.412204019,1822.0
65.462337826,1809.0
65.512471633,1745.0
65.562605440,1806.0
65.612739247,1783.0
65.662873054,1917.0
65.713006860,1811.0
65.763140667,1798.0
65.813274474,1757.0
65.863408281,1813.0
65.913542088,1789.0
65.963675895,1832.0
66.013809702,1776.0
66.063943509,1754.0
66.114077316,1767.0
66.164211123,1788.0
66.214344930,1790.0
66.264478737,1870.0
66.314612544,1831.0
66.364746351,1781.0
66.414880158,1768.0
66.465013964,1867.0
66.515147771,1803.0
66.565281578,1806.0
66.615415385,1762.0
66.665549192,1851.0
66.715682999,1835.0
66.765816806,1785.0
66.815950613,1757.0
66.866084420,1794.0
66.916218227,1845.0
66.966352034,1769.0
67.016485841,1870.0
67.066619648,1811.0
67.116753455,1710.0
67.166887262,1784.0
67.217021069,1778.0
67.267154875,1806.0
67.317288682,1775.0
67.367422489,1804.0
67.417556296,1736.0
67.467690103,1814.0
67.517823910,1775.0
67.567957717,1773.0
67.618091524,1734.0
67.668225331,1723.0
67.718359138,1772.0
67.768492945,1798.0
67.818626752,1786.0
67.868760559,1792.0
67.918894366,1843.0
67.969028173,1820.0
68.019161979,1846.0
68.069295786,1905.0
68.119429593,1764.0
68.169563400,1822.0
68.219697207,1805.0
68.269831014,1823.0
68.319964821,1742.0
68.370098628,1828.0
68.420232435,1776.0
68.470366242,1809.0
68.520500049,1808.0
68.570633856,1740.0
68.620767663,1812.0
68.670901470,1724.0
68.721035277,1737.0
68.771169083,1721.0
68.821302890,1838.0
68.871436697,1776.0
68.921570504,1742.0
68.971704311,1768.0
69.021838118,1780.0
69.071971925,1620.0
69.122105732,1866.0
69.172239539,1817.0
69.222373346,1826.0
69.272507153,1810.0
69.322640960,1803.0
69.372774767,1737.0
69.422908574,1739.0
69.473042381,1804.0
69.523176187,1782.0
69.573309994,1837.0
69.623443801,1775.0
69.673577608,1685.0
69.723711415,1716.0
69.773845222,1804.0
69.823979029,1778.0
69.874112836,1688.0
69.924246643,1727.0
69.974380450,1703.0
70.024514257,1777.0
70.074648064,1808.0
70.124781871,1790.0
70.174915678,1759.0
70.225049485,1761.0
70.275183291,1733.0
70.325317098,1701.0
70.375450905,1729.0
70.425584712,1751.0
70.475718519,1778.0
70.525852326,1755.0
70.575986133,1727.0
70.626119940,1675.0
70.676253747,1667.0
70.726387554,1745.0
70.776521361,1725.0
70.826655168,1684.0
70.876788975,1687.0
70.926922782,1790.0
70.977056589,1699.0
71.027190396,1756.0
71.077324202,1714.0
71.127458009,1734.0
71.177591816,1688.0
71.227725623,1722.0
71.277859430,1691.0
71.327993237,1677.0
71.378127044,1696.0
71.428260851,1649.0
71.478394658,1659.0
71.528528465,1776.0
71.578662272,1764.0
71.628796079,1751.0
71.678929886,1692.0
71.729063693,1728.0
71.779197500,1714.0
71.829331306,1729.0
71.879465113,1721.0
71.929598920,1752.0
71.979732727,1674.0
72.029866534,1691.0
72.080000341,1714.0
72.130134148,1720.0
72.180267955,1635.0
72.230401762,1702.0
72.280535569,1573.0
72.330669376,1674.0
72.380803183,1713.0
72.430936990,1687.0
72.481070797,1667.0
72.531204604,1700.0
72.581338410,1700.0
72.631472217,1649.0
72.681606024,1642.0
72.731739831,1677.0
72.781873638,1701.0
72.832007445,1635.0
72.882141252,1580.0
72.932275059,1704.0
72.982408866,1665.0
73.032542673,1677.0
73.082676480,1624.0
73.132810287,1693.0
73.182944094,1695.0
73.233077901,1717.0
73.283211708,1707.0
73.333345514,1628.0
73.383479321,1619.0
73.433613128,1630.0
73.483746935,1634.0
73.533880742,1648.0
73.584014549,1625.0
73.634148356,1672.0
73.684282163,1603.0
73.734415970,1642.0
73.784549777,1604.0
73.834683584,1662.0
73.884817391,1579.0
73.934951198,1615.0
73.985085005,1694.0
74.035218812,1570.0
74.085352618,1623.0
74.135486425,1687.0
74.185620232,1677.0
74.235754039,1615.0
74.285887846,1691.0
74.336021653,1645.0
74.386155460,1643.0
74.436289267,1650.0
74.486423074,1657.0
74.536556881,1674.0
74.586690688,1668.0
74.636824495,1651.0
74.686958302,1647.0
74.737092109,1621.0
74.787225916,1708.0
74.837359722,1664.0
74.887493529,1656.0
74.937627336,1688.0
74.987761143,1740.0
75.037894950,1732.0
75.088028757,1759.0
75.138162564,1884.0
75.188296371,1844.0
75.238430178,1927.0
75.288563985,2047.0
75.338697792,2066.0
75.388831599,2127.0
75.438965406,2060.0
75.489099213,2102.0
75.539233020,2012.0
75.589366827,2153.0
75.639500633,2075.0
75.689634440,1942.0
75.739768247,1937.0
75.789902054,1884.0
75.840035861,1785.0
75.890169668,1706.0
75.940303475,1704.0
75.990437282,1661.0
76.040571089,1645.0
76.090704896,1685.0
76.140838703,1562.0
76.190972510,1591.0
76.241106317,1595.0
76.291240124,1596.0
76.341373931,1629.0
76.391507737,1544.0
76.441641544,1605.0
76.491775351,1567.0
76.541909158,1607.0
76.592042965,1566.0
76.642176772,1579.0
76.692310579,1567.0
76.742444386,1509.0
76.792578193,1492.0
76.842712000,1605.0
76.892845807,1527.0
76.942979614,1584.0
76.993113421,1531.0
77.043247228,1561.0
77.093381035,1476.0
77.143514841,1555.0
77.193648648,1515.0
77.243782455,1525.0
77.293916262,1563.0
77.344050069,1549.0
77.394183876,1499.0
77.444317683,1547.0
77.494451490,1570.0
77.544585297,1507.0
77.594719104,1521.0
77.644852911,1472.0
77.694986718,1464.0
77.745120525,1531.0
77.795254332,1479.0
77.845388139,1478.0
77.895521945,1545.0
77.945655752,1519.0
77.995789559,1505.0
78.045923366,1481.0
78.096057173,1446.0
78.146190980,1570.0
78.196324787,1524.0
78.246458594,1547.0
78.296592401,1533.0
78.346726208,1502.0
78.396860015,1497.0
78.446993822,1476.0
78.497127629,1526.0
78.547261436,1473.0
78.597395243,1542.0
78.647529049,1569.0
78.697662856,1433.0
78.747796663,1531.0
78.797930470,1497.0
78.848064277,1552.0
78.898198084,1528.0
78.948331891,1584.0
78.998465698,1576.0
79.048599505,1503.0
79.098733312,1550.0
79.148867119,1550.0
79.199000926,1667.0
79.249134733,1729.0
79.299268540,1678.0
79.349402347,1854.0
79.399536153,1786.0
79.449669960,1777.0
79.499803767,1855.0
79.549937574,1801.0
79.600071381,1805.0
79.650205188,1675.0
79.700338995,1785.0
79.750472802,1713.0
79.800606609,1580.0
79.850740416,1606.0
79.900874223,1607.0
79.951008030,1491.0
80.001141837,1561.0
80.051275644,1554.0
80.101409451,1482.0
80.151543258,1553.0
80.201677064,1476.0
80.251810871,1512.0
80.301944678,1481.0
80.352078485,1457.0
80.402212292,1530.0
80.452346099,1422.0
80.502479906,1481.0
80.552613713,1426.0
80.602747520,1421.0
80.652881327,1439.0
80.703015134,1470.0
80.753148941,1485.0
80.803282748,1416.0
80.853416555,1437.0
80.903550362,1438.0
80.953684168,1450.0
81.003817975,1462.0
81.053951782,1405.0
81.104085589,1434.0
81.154219396,1417.0
81.204353203,1429.0
81.254487010,1438.0
81.304620817,1385.0
81.354754624,1389.0
81.404888431,1393.0
81.455022238,1391.0
81.505156045,1443.0
81.555289852,1407.0
81.605423659,1386.0
81.655557466,1478.0
81.705691272,1397.0
81.755825079,1446.0
81.805958886,1430.0
81.856092693,1410.0
81.906226500,1349.0
81.956360307,1439.0
82.006494114,1419.0
82.056627921,1417.0
82.106761728,1447.0
82.156895535,1375.0
82.207029342,1445.0
82.257163149,1402.0
82.307296956,1386.0
82.357430763,1397.0
82.407564570,1449.0
82.457698376,1432.0
82.507832183,1394.0
82.557965990,1392.0
82.608099797,1411.0
82.658233604,1394.0
82.708367411,1358.0
82.758501218,1377.0
82.808635025,1381.0
82.858768832,1334.0
82.908902639,1429.0
82.959036446,1366.0
83.009170253,1392.0
83.059304060,1424.0
83.109437867,1345.0
83.159571674,1378.0
83.209705480,1485.0
83.259839287,1433.0
83.309973094,1420.0
83.360106901,1413.0
83.410240708,1419.0
83.460374515,1338.0
83.510508322,1360.0
83.560642129,1373.0
83.610775936,1373.0
83.660909743,1449.0
83.711043550,1360.0
83.761177357,1400.0
83.811311164,1343.0
83.861444971,1403.0
83.911578778,1315.0
83.961712584,1374.0
84.011846391,1424.0
84.061980198,1409.0
84.112114005,1408.0
84.162247812,1423.0
84.212381619,1394.0
84.262515426,1313.0
84.312649233,1367.0
84.362783040,1385.0
84.412916847,1370.0
84.463050654,1408.0
84.513184461,1408.0
84.563318268,1403.0
84.613452075,1370.0
84.663585882,1248.0
84.713719689,1391.0
84.763853495,1334.0
84.813987302,1295.0
84.864121109,1417.0
84.914254916,1396.0
84.964388723,1388.0
85.014522530,1379.0
85.064656337,1413.0
85.114790144,1360.0
85.164923951,1257.0
85.215057758,1341.0
85.265191565,1376.0
85.315325372,1332.0
85.365459179,1374.0
85.415592986,1345.0
85.465726793,1389.0
85.515860599,1315.0
85.565994406,1359.0
85.616128213,1334.0
85.666262020,1357.0
85.716395827,1424.0
85.766529634,1366.0
85.816663441,1346.0
85.866797248,1375.0
85.916931055,1353.0
85.967064862,1344.0
86.017198669,1364.0
86.067332476,1304.0
86.117466283,1276.0
86.167600090,1360.0
86.217733897,1322.0
86.267867703,1378.0
86.318001510,1336.0
86.368135317,1347.0
86.418269124,1331.0
86.468402931,1349.0
86.518536738,1349.0
86.568670545,1341.0
86.618804352,1356.0
86.668938159,1322.0
86.719071966,1320.0
86.769205773,1268.0
86.819339580,1313.0
86.869473387,1373.0
86.919607194,1336.0
86.969741001,1318.0
87.019874807,1366.0
87.070008614,1323.0
87.120142421,1324.0
87.170276228,1300.0
87.220410035,1307.0
87.270543842,1332.0
87.320677649,1350.0
87.370811456,1342.0
87.420945263,1379.0
87.471079070,1375.0
87.521212877,1279.0
87.571346684,1374.0
87.621480491,1381.0
87.671614298,1274.0
87.721748105,1255.0
87.771881911,1267.0
87.822015718,1306.0
87.872149525,1318.0
87.922283332,1310.0
87.972417139,1367.0
88.022550946,1326.0
88.072684753,1430.0
88.122818560,1352.0
88.172952367,1319.0
88.223086174,1357.0
88.273219981,1367.0
88.323353788,1295.0
88.373487595,1315.0
88.423621402,1374.0
88.473755209,1295.0
88.523889016,1345.0
88.574022822,1362.0
88.624156629,1378.0
88.674290436,1334.0
88.724424243,1293.0
88.774558050,1314.0
88.824691857,1311.0
88.874825664,1242.0
88.924959471,1349.0
88.975093278,1325.0
89.025227085,1284.0
89.075360892,1258.0
89.125494699,1339.0
89.175628506,1301.0
89.225762313,1346.0
89.275896120,1252.0
89.326029926,1236.0
89.376163733,1295.0
89.426297540,1294.0
89.476431347,1350.0
89.526565154,1381.0
89.576698961,1211.0
89.626832768,1211.0
89.676966575,1397.0
89.727100382,1239.0
89.777234189,1285.0
89.827367996,1309.0
89.877501803,1292.0
89.927635610,1341.0
89.977769417,1267.0
90.027903224,1331.0
90.078037030,1297.0
90.128170837,1275.0
90.178304644,1331.0
90.228438451,1360.0
90.278572258,1403.0
90.328706065,1290.0
90.378839872,1306.0
90.428973679,1370.0
90.479107486,1275.0
90.529241293,1319.0
90.579375100,1306.0
90.629508907,1353.0
90.679642714,1254.0
90.729776521,1275.0
90.779910328,1277.0
90.830044134,1249.0
90.880177941,1328.0
90.930311748,1303.0
90.980445555,1254.0
91.030579362,1209.0
91.080713169,1290.0
91.130846976,1343.0
91.180980783,1263.0
91.231114590,1252.0
91.281248397,1317.0
91.331382204,1315.0
91.381516011,1283.0
91.431649818,1343.0
91.481783625,1308.0
91.531917432,1257.0
91.582051238,1251.0
91.632185045,1268.0
91.682318852,1325.0
91.732452659,1332.0
91.782586466,1315.0
91.832720273,1278.0
91.882854080,1309.0
91.932987887,1343.0
91.983121694,1251.0
92.033255501,1315.0
92.083389308,1270.0
92.133523115,1332.0
92.183656922,1282.0
92.233790729,1200.0
92.283924536,1294.0
92.334058342,1266.0
92.384192149,1275.0
92.434325956,1279.0
92.484459763,1243.0
92.534593570,1170.0
92.584727377,1284.0
92.634861184,1284.0
92.684994991,1271.0
92.735128798,1342.0
92.785262605,1243.0
92.835396412,1267.0
92.885530219,1292.0
92.935664026,1247.0
92.985797833,1278.0
93.035931640,1286.0
93.086065447,1312.0
93.136199253,1280.0
93.186333060,1294.0
93.236466867,1266.0
93.286600674,1292.0
93.336734481,1303.0
93.386868288,1317.0
93.437002095,1324.0
93.487135902,1273.0
93.537269709,1271.0
93.587403516,1244.0
93.637537323,1292.0
93.687671130,1312.0
93.737804937,1232.0
93.787938744,1291.0
93.838072551,1269.0
93.888206357,1263.0
93.938340164,1340.0
93.988473971,1327.0
94.038607778,1293.0
94.088741585,1329.0
94.138875392,1222.0
94.189009199,1327.0
94.239143006,1292.0
94.289276813,1281.0
94.339410620,1278.0
94.389544427,1268.0
94.439678234,1241.0
94.489812041,1207.0
94.539945848,1333.0
94.590079655,1267.0
94.640213461,1297.0
94.690347268,1310.0
94.740481075,1291.0
94.790614882,1310.0
94.840748689,1328.0
94.890882496,1328.0
94.941016303,1384.0
94.991150110,1361.0