File: OriginPro/XRD from Panalytical X'Pert PRO/In-Situ/FicheirosXRD_Insitu/NiNws_50°C.csv
[Measurement conditions]
Sample identification,
Comment - 1,"finito"
Comment - 2,"Configuration=MRI TC-Basic Stage, Owner=User-1, Creation date=26-10-2009 9:18:44"
Comment - 3,"Goniometer=PW3050/60 (Theta/Theta); Minimum step size 2Theta:0.001; Minimum step size Omega:0.001"
Comment - 4,"Sample stage=MRI TC-Basic (PtRh heat strip)"
Comment - 5,"Diffractometer system=XPERT-PRO"
Comment - 6,"Measurement program=FS-L, Owner=joana, Creation date=25-11-2014 17:28:08"
Anode material,Cu
K-Alpha1 wavelength,1.5405980
K-Alpha2 wavelength,1.5444260
Ratio K-Alpha2/K-Alpha1,0.500
Divergence slit,Fixed,0.76mm
Monochromator used,NO
Generator voltage, 45
Tube current, 40
File date and time,15-Dez-2017 17:16
Unit cell,
h k l, 0 0 0
Temperature [K],324
Scan axis,Gonio
Scan range,24.995999996,94.999505744
Scan step size,0.0167113
No. of points, 4189
Scan type,CONTINUOUS
Time per step,118.110
[Scan points]
Angle,Intensity
25.004355630,2317.0
25.054489437,2292.0
25.104623244,2181.0
25.154757051,2382.0
25.204890858,2356.0
25.255024665,2285.0
25.305158472,2235.0
25.355292279,2345.0
25.405426085,2280.0
25.455559892,2320.0
25.505693699,2254.0
25.555827506,2288.0
25.605961313,2299.0
25.656095120,2261.0
25.706228927,2237.0
25.756362734,2305.0
25.806496541,2302.0
25.856630348,2231.0
25.906764155,2344.0
25.956897962,2313.0
26.007031769,2253.0
26.057165576,2238.0
26.107299383,2252.0
26.157433189,2207.0
26.207566996,2169.0
26.257700803,2343.0
26.307834610,2269.0
26.357968417,2222.0
26.408102224,2240.0
26.458236031,2268.0
26.508369838,2258.0
26.558503645,2241.0
26.608637452,2219.0
26.658771259,2286.0
26.708905066,2218.0
26.759038873,2238.0
26.809172680,2166.0
26.859306487,2225.0
26.909440293,2155.0
26.959574100,2202.0
27.009707907,2277.0
27.059841714,2328.0
27.109975521,2167.0
27.160109328,2224.0
27.210243135,2177.0
27.260376942,2177.0
27.310510749,2254.0
27.360644556,2256.0
27.410778363,2279.0
27.460912170,2144.0
27.511045977,2244.0
27.561179784,2256.0
27.611313591,2254.0
27.661447398,2155.0
27.711581204,2163.0
27.761715011,2276.0
27.811848818,2226.0
27.861982625,2240.0
27.912116432,2266.0
27.962250239,2302.0
28.012384046,2187.0
28.062517853,2229.0
28.112651660,2294.0
28.162785467,2239.0
28.212919274,2176.0
28.263053081,2375.0
28.313186888,2732.0
28.363320695,2700.0
28.413454502,2404.0
28.463588308,2422.0
28.513722115,2487.0
28.563855922,2401.0
28.613989729,2419.0
28.664123536,2365.0
28.714257343,2321.0
28.764391150,2200.0
28.814524957,2354.0
28.864658764,2228.0
28.914792571,2345.0
28.964926378,2227.0
29.015060185,2382.0
29.065193992,2303.0
29.115327799,2244.0
29.165461606,2184.0
29.215595412,2253.0
29.265729219,2255.0
29.315863026,2273.0
29.365996833,2216.0
29.416130640,2224.0
29.466264447,2193.0
29.516398254,2119.0
29.566532061,2173.0
29.616665868,2208.0
29.666799675,2161.0
29.716933482,2182.0
29.767067289,2026.0
29.817201096,2124.0
29.867334903,2196.0
29.917468710,2181.0
29.967602516,2159.0
30.017736323,2198.0
30.067870130,2136.0
30.118003937,2127.0
30.168137744,2152.0
30.218271551,2144.0
30.268405358,2205.0
30.318539165,2191.0
30.368672972,2232.0
30.418806779,2144.0
30.468940586,2193.0
30.519074393,2159.0
30.569208200,2174.0
30.619342007,2115.0
30.669475814,2108.0
30.719609620,2139.0
30.769743427,2142.0
30.819877234,2131.0
30.870011041,2147.0
30.920144848,2165.0
30.970278655,2137.0
31.020412462,2086.0
31.070546269,2130.0
31.120680076,2114.0
31.170813883,2185.0
31.220947690,2020.0
31.271081497,2088.0
31.321215304,2086.0
31.371349111,2133.0
31.421482918,2107.0
31.471616724,2168.0
31.521750531,2095.0
31.571884338,2077.0
31.622018145,2114.0
31.672151952,2082.0
31.722285759,2140.0
31.772419566,2117.0
31.822553373,2045.0
31.872687180,2171.0
31.922820987,2166.0
31.972954794,2046.0
32.023088601,2127.0
32.073222408,2202.0
32.123356215,2183.0
32.173490022,2070.0
32.223623829,2126.0
32.273757635,2067.0
32.323891442,2091.0
32.374025249,2126.0
32.424159056,2069.0
32.474292863,2189.0
32.524426670,2161.0
32.574560477,2172.0
32.624694284,2139.0
32.674828091,2127.0
32.724961898,2035.0
32.775095705,2084.0
32.825229512,2146.0
32.875363319,2158.0
32.925497126,2137.0
32.975630933,2069.0
33.025764739,2087.0
33.075898546,2104.0
33.126032353,2088.0
33.176166160,2211.0
33.226299967,2071.0
33.276433774,1996.0
33.326567581,2125.0
33.376701388,2032.0
33.426835195,2065.0
33.476969002,2102.0
33.527102809,2136.0
33.577236616,2090.0
33.627370423,2149.0
33.677504230,2097.0
33.727638037,2165.0
33.777771843,2007.0
33.827905650,2008.0
33.878039457,2063.0
33.928173264,2118.0
33.978307071,2035.0
34.028440878,2006.0
34.078574685,2058.0
34.128708492,2124.0
34.178842299,1944.0
34.228976106,2087.0
34.279109913,2053.0
34.329243720,2074.0
34.379377527,2087.0
34.429511334,2121.0
34.479645141,2056.0
34.529778947,2204.0
34.579912754,2105.0
34.630046561,2108.0
34.680180368,2179.0
34.730314175,2110.0
34.780447982,2107.0
34.830581789,2137.0
34.880715596,2125.0
34.930849403,2090.0
34.980983210,2015.0
35.031117017,2124.0
35.081250824,2068.0
35.131384631,2128.0
35.181518438,2115.0
35.231652245,2085.0
35.281786051,1973.0
35.331919858,2131.0
35.382053665,2116.0
35.432187472,2008.0
35.482321279,2042.0
35.532455086,2134.0
35.582588893,2098.0
35.632722700,2061.0
35.682856507,1994.0
35.732990314,2066.0
35.783124121,2035.0
35.833257928,2057.0
35.883391735,2048.0
35.933525542,2076.0
35.983659349,2010.0
36.033793156,2063.0
36.083926962,2075.0
36.134060769,1951.0
36.184194576,2045.0
36.234328383,2132.0
36.284462190,2052.0
36.334595997,2092.0
36.384729804,2037.0
36.434863611,2052.0
36.484997418,2110.0
36.535131225,2025.0
36.585265032,2059.0
36.635398839,2149.0
36.685532646,2046.0
36.735666453,2063.0
36.785800260,2087.0
36.835934066,2083.0
36.886067873,2043.0
36.936201680,2033.0
36.986335487,1995.0
37.036469294,2058.0
37.086603101,2058.0
37.136736908,1997.0
37.186870715,2042.0
37.237004522,2103.0
37.287138329,1985.0
37.337272136,2096.0
37.387405943,1995.0
37.437539750,2006.0
37.487673557,2000.0
37.537807364,2087.0
37.587941170,2064.0
37.638074977,2063.0
37.688208784,2000.0
37.738342591,1986.0
37.788476398,2093.0
37.838610205,2065.0
37.888744012,2035.0
37.938877819,2048.0
37.989011626,2064.0
38.039145433,2016.0
38.089279240,2054.0
38.139413047,2067.0
38.189546854,2035.0
38.239680661,2110.0
38.289814468,1973.0
38.339948274,2042.0
38.390082081,2019.0
38.440215888,1968.0
38.490349695,1991.0
38.540483502,2137.0
38.590617309,2038.0
38.640751116,2057.0
38.690884923,2067.0
38.741018730,2063.0
38.791152537,1964.0
38.841286344,1992.0
38.891420151,2054.0
38.941553958,2078.0
38.991687765,1968.0
39.041821572,2002.0
39.091955378,2160.0
39.142089185,2048.0
39.192222992,2016.0
39.242356799,2023.0
39.292490606,2024.0
39.342624413,2063.0
39.392758220,2123.0
39.442892027,2000.0
39.493025834,2055.0
39.543159641,2074.0
39.593293448,2078.0
39.643427255,2036.0
39.693561062,2203.0
39.743694869,2094.0
39.793828676,2267.0
39.843962482,2341.0
39.894096289,2136.0
39.944230096,2193.0
39.994363903,2143.0
40.044497710,2091.0
40.094631517,2118.0
40.144765324,2175.0
40.194899131,2077.0
40.245032938,2072.0
40.295166745,1993.0
40.345300552,1956.0
40.395434359,1922.0
40.445568166,1975.0
40.495701973,1909.0
40.545835780,1919.0
40.595969587,1941.0
40.646103393,1996.0
40.696237200,1843.0
40.746371007,1983.0
40.796504814,1997.0
40.846638621,1997.0
40.896772428,1942.0
40.946906235,2026.0
40.997040042,1957.0
41.047173849,1916.0
41.097307656,1895.0
41.147441463,1992.0
41.197575270,2003.0
41.247709077,1925.0
41.297842884,1948.0
41.347976691,1928.0
41.398110497,1999.0
41.448244304,1817.0
41.498378111,2047.0
41.548511918,1973.0
41.598645725,2070.0
41.648779532,1963.0
41.698913339,2019.0
41.749047146,1957.0
41.799180953,1964.0
41.849314760,2008.0
41.899448567,1976.0
41.949582374,1982.0
41.999716181,1984.0
42.049849988,1939.0
42.099983795,1947.0
42.150117601,2052.0
42.200251408,1984.0
42.250385215,2015.0
42.300519022,2007.0
42.350652829,1950.0
42.400786636,1948.0
42.450920443,1999.0
42.501054250,1981.0
42.551188057,2022.0
42.601321864,1978.0
42.651455671,1905.0
42.701589478,1933.0
42.751723285,1889.0
42.801857092,1963.0
42.851990899,2063.0
42.902124705,1980.0
42.952258512,2035.0
43.002392319,2065.0
43.052526126,2034.0
43.102659933,2026.0
43.152793740,1990.0
43.202927547,2095.0
43.253061354,2072.0
43.303195161,2108.0
43.353328968,2134.0
43.403462775,2120.0
43.453596582,2148.0
43.503730389,2163.0
43.553864196,2142.0
43.603998003,2196.0
43.654131809,2250.0
43.704265616,2261.0
43.754399423,2279.0
43.804533230,2519.0
43.854667037,2595.0
43.904800844,2762.0
43.954934651,2904.0
44.005068458,3072.0
44.055202265,3308.0
44.105336072,3504.0
44.155469879,4111.0
44.205603686,4770.0
44.255737493,5356.0
44.305871300,6531.0
44.356005107,7936.0
44.406138913,9442.0
44.456272720,10195.0
44.506406527,9664.0
44.556540334,8243.0
44.606674141,6608.0
44.656807948,4963.0
44.706941755,3847.0
44.757075562,3181.0
44.807209369,2769.0
44.857343176,2570.0
44.907476983,2361.0
44.957610790,2252.0
45.007744597,2179.0
45.057878404,2203.0
45.108012211,2170.0
45.158146018,2081.0
45.208279824,2085.0
45.258413631,2123.0
45.308547438,2128.0
45.358681245,2209.0
45.408815052,2209.0
45.458948859,2219.0
45.509082666,2203.0
45.559216473,2136.0
45.609350280,2117.0
45.659484087,2064.0
45.709617894,2025.0
45.759751701,2030.0
45.809885508,1962.0
45.860019315,2053.0
45.910153122,2123.0
45.960286928,2060.0
46.010420735,2151.0
46.060554542,2233.0
46.110688349,2452.0
46.160822156,2891.0
46.210955963,3448.0
46.261089770,4877.0
46.311223577,8877.0
46.361357384,4588.0
46.411491191,4548.0
46.461624998,4463.0
46.511758805,2872.0
46.561892612,2996.0
46.612026419,3440.0
46.662160226,3682.0
46.712294032,3519.0
46.762427839,3245.0
46.812561646,2769.0
46.862695453,2513.0
46.912829260,2145.0
46.962963067,2134.0
47.013096874,1979.0
47.063230681,1970.0
47.113364488,1925.0
47.163498295,1921.0
47.213632102,1989.0
47.263765909,1939.0
47.313899716,1906.0
47.364033523,1895.0
47.414167330,1995.0
47.464301136,1941.0
47.514434943,1813.0
47.564568750,1927.0
47.614702557,1898.0
47.664836364,1902.0
47.714970171,1910.0
47.765103978,1876.0
47.815237785,1857.0
47.865371592,1886.0
47.915505399,1826.0
47.965639206,1898.0
48.015773013,1880.0
48.065906820,1852.0
48.116040627,1849.0
48.166174434,1939.0
48.216308240,1906.0
48.266442047,1935.0
48.316575854,1898.0
48.366709661,1950.0
48.416843468,1780.0
48.466977275,1903.0
48.517111082,1867.0
48.567244889,1900.0
48.617378696,1802.0
48.667512503,1856.0
48.717646310,1868.0
48.767780117,1842.0
48.817913924,1845.0
48.868047731,1815.0
48.918181538,1919.0
48.968315344,1854.0
49.018449151,1819.0
49.068582958,1799.0
49.118716765,1962.0
49.168850572,1835.0
49.218984379,1837.0
49.269118186,1742.0
49.319251993,1847.0
49.369385800,1962.0
49.419519607,1903.0
49.469653414,1960.0
49.519787221,1965.0
49.569921028,1998.0
49.620054835,2027.0
49.670188642,1995.0
49.720322449,1911.0
49.770456255,1933.0
49.820590062,1869.0
49.870723869,1862.0
49.920857676,1814.0
49.970991483,1901.0
50.021125290,1976.0
50.071259097,1931.0
50.121392904,1850.0
50.171526711,1939.0
50.221660518,1953.0
50.271794325,1885.0
50.321928132,1920.0
50.372061939,1928.0
50.422195746,2034.0
50.472329553,2130.0
50.522463359,2221.0
50.572597166,2320.0
50.622730973,2316.0
50.672864780,2291.0
50.722998587,2170.0
50.773132394,2126.0
50.823266201,2034.0
50.873400008,1951.0
50.923533815,2028.0
50.973667622,2072.0
51.023801429,1999.0
51.073935236,1964.0
51.124069043,2152.0
51.174202850,2074.0
51.224336657,2148.0
51.274470463,2171.0
51.324604270,2281.0
51.374738077,2393.0
51.424871884,2450.0
51.475005691,2637.0
51.525139498,2833.0
51.575273305,3014.0
51.625407112,3457.0
51.675540919,3845.0
51.725674726,4072.0
51.775808533,4413.0
51.825942340,4361.0
51.876076147,4007.0
51.926209954,3690.0
51.976343761,3335.0
52.026477567,2971.0
52.076611374,2557.0
52.126745181,2344.0
52.176878988,2245.0
52.227012795,2123.0
52.277146602,2139.0
52.327280409,2010.0
52.377414216,1990.0
52.427548023,1937.0
52.477681830,1900.0
52.527815637,1903.0
52.577949444,1930.0
52.628083251,1892.0
52.678217058,1819.0
52.728350865,1858.0
52.778484671,1802.0
52.828618478,1790.0
52.878752285,1779.0
52.928886092,1835.0
52.979019899,1905.0
53.029153706,1827.0
53.079287513,1705.0
53.129421320,1874.0
53.179555127,1853.0
53.229688934,1824.0
53.279822741,1684.0
53.329956548,1770.0
53.380090355,1832.0
53.430224162,1757.0
53.480357969,1827.0
53.530491776,1658.0
53.580625582,1729.0
53.630759389,1830.0
53.680893196,1731.0
53.731027003,1832.0
53.781160810,1682.0
53.831294617,1750.0
53.881428424,1754.0
53.931562231,1775.0
53.981696038,1748.0
54.031829845,1792.0
54.081963652,1731.0
54.132097459,1750.0
54.182231266,1747.0
54.232365073,1774.0
54.282498880,1718.0
54.332632686,1718.0
54.382766493,1663.0
54.432900300,1745.0
54.483034107,1687.0
54.533167914,1752.0
54.583301721,1780.0
54.633435528,1747.0
54.683569335,1782.0
54.733703142,1749.0
54.783836949,1713.0
54.833970756,1809.0
54.884104563,1743.0
54.934238370,1761.0
54.984372177,1838.0
55.034505984,1718.0
55.084639790,1743.0
55.134773597,1702.0
55.184907404,1674.0
55.235041211,1816.0
55.285175018,1666.0
55.335308825,1795.0
55.385442632,1739.0
55.435576439,1796.0
55.485710246,1710.0
55.535844053,1648.0
55.585977860,1777.0
55.636111667,1755.0
55.686245474,1762.0
55.736379281,1629.0
55.786513088,1726.0
55.836646894,1777.0
55.886780701,1793.0
55.936914508,1716.0
55.987048315,1712.0
56.037182122,1786.0
56.087315929,1677.0
56.137449736,1727.0
56.187583543,1623.0
56.237717350,1739.0
56.287851157,1727.0
56.337984964,1792.0
56.388118771,1705.0
56.438252578,1660.0
56.488386385,1746.0
56.538520192,1803.0
56.588653998,1711.0
56.638787805,1724.0
56.688921612,1672.0
56.739055419,1709.0
56.789189226,1728.0
56.839323033,1639.0
56.889456840,1727.0
56.939590647,1716.0
56.989724454,1688.0
57.039858261,1697.0
57.089992068,1688.0
57.140125875,1720.0
57.190259682,1645.0
57.240393489,1745.0
57.290527296,1771.0
57.340661102,1709.0
57.390794909,1761.0
57.440928716,1623.0
57.491062523,1752.0
57.541196330,1741.0
57.591330137,1736.0
57.641463944,1662.0
57.691597751,1721.0
57.741731558,1717.0
57.791865365,1671.0
57.841999172,1761.0
57.892132979,1764.0
57.942266786,1720.0
57.992400593,1693.0
58.042534400,1646.0
58.092668207,1719.0
58.142802013,1733.0
58.192935820,1730.0
58.243069627,1632.0
58.293203434,1759.0
58.343337241,1738.0
58.393471048,1726.0
58.443604855,1635.0
58.493738662,1713.0
58.543872469,1754.0
58.594006276,1692.0
58.644140083,1628.0
58.694273890,1728.0
58.744407697,1733.0
58.794541504,1695.0
58.844675311,1737.0
58.894809117,1768.0
58.944942924,1729.0
58.995076731,1741.0
59.045210538,1754.0
59.095344345,1679.0
59.145478152,1783.0
59.195611959,1696.0
59.245745766,1725.0
59.295879573,1745.0
59.346013380,1671.0
59.396147187,1660.0
59.446280994,1762.0
59.496414801,1652.0
59.546548608,1730.0
59.596682415,1667.0
59.646816221,1770.0
59.696950028,1747.0
59.747083835,1643.0
59.797217642,1673.0
59.847351449,1689.0
59.897485256,1703.0
59.947619063,1724.0
59.997752870,1669.0
60.047886677,1770.0
60.098020484,1716.0
60.148154291,1686.0
60.198288098,1652.0
60.248421905,1792.0
60.298555712,1696.0
60.348689519,1683.0
60.398823325,1618.0
60.448957132,1709.0
60.499090939,1730.0
60.549224746,1764.0
60.599358553,1655.0
60.649492360,1731.0
60.699626167,1677.0
60.749759974,1703.0
60.799893781,1706.0
60.850027588,1725.0
60.900161395,1660.0
60.950295202,1645.0
61.000429009,1723.0
61.050562816,1725.0
61.100696623,1729.0
61.150830429,1622.0
61.200964236,1708.0
61.251098043,1721.0
61.301231850,1791.0
61.351365657,1723.0
61.401499464,1708.0
61.451633271,1665.0
61.501767078,1726.0
61.551900885,1771.0
61.602034692,1669.0
61.652168499,1693.0
61.702302306,1716.0
61.752436113,1626.0
61.802569920,1741.0
61.852703727,1775.0
61.902837533,1736.0
61.952971340,1743.0
62.003105147,1704.0
62.053238954,1723.0
62.103372761,1690.0
62.153506568,1733.0
62.203640375,1679.0
62.253774182,1762.0
62.303907989,1710.0
62.354041796,1687.0
62.404175603,1710.0
62.454309410,1786.0
62.504443217,1758.0
62.554577024,1765.0
62.604710831,1831.0
62.654844638,1721.0
62.704978444,1740.0
62.755112251,1805.0
62.805246058,1827.0
62.855379865,1705.0
62.905513672,1820.0
62.955647479,1706.0
63.005781286,1735.0
63.055915093,1749.0
63.106048900,1764.0
63.156182707,1817.0
63.206316514,1711.0
63.256450321,1688.0
63.306584128,1753.0
63.356717935,1761.0
63.406851742,1729.0
63.456985548,1755.0
63.507119355,1818.0
63.557253162,1678.0
63.607386969,1703.0
63.657520776,1691.0
63.707654583,1818.0
63.757788390,1720.0
63.807922197,1809.0
63.858056004,1782.0
63.908189811,1804.0
63.958323618,1734.0
64.008457425,1690.0
64.058591232,1795.0
64.108725039,1818.0
64.158858846,1801.0
64.208992652,1723.0
64.259126459,1787.0
64.309260266,1802.0
64.359394073,1702.0
64.409527880,1768.0
64.459661687,1719.0
64.509795494,1866.0
64.559929301,1775.0
64.610063108,1762.0
64.660196915,1839.0
64.710330722,1807.0
64.760464529,1795.0
64.810598336,1743.0
64.860732143,1772.0
64.910865950,1756.0
64.960999756,1740.0
65.011133563,1808.0
65.061267370,1779.0
65.111401177,1826.0
65.161534984,1739.0
65.211668791,1753.0
65.261802598,1845.0
65.311936405,1735.0
65.362070212,1771.0
65.412204019,1777.0
65.462337826,1807.0
65.512471633,1770.0
65.562605440,1736.0
65.612739247,1828.0
65.662873054,1775.0
65.713006860,1776.0
65.763140667,1742.0
65.813274474,1786.0
65.863408281,1821.0
65.913542088,1765.0
65.963675895,1751.0
66.013809702,1697.0
66.063943509,1771.0
66.114077316,1744.0
66.164211123,1822.0
66.214344930,1816.0
66.264478737,1779.0
66.314612544,1810.0
66.364746351,1870.0
66.414880158,1825.0
66.465013964,1834.0
66.515147771,1835.0
66.565281578,1791.0
66.615415385,1829.0
66.665549192,1798.0
66.715682999,1875.0
66.765816806,1774.0
66.815950613,1744.0
66.866084420,1839.0
66.916218227,1777.0
66.966352034,1704.0
67.016485841,1803.0
67.066619648,1804.0
67.116753455,1787.0
67.166887262,1798.0
67.217021069,1708.0
67.267154875,1769.0
67.317288682,1810.0
67.367422489,1755.0
67.417556296,1836.0
67.467690103,1745.0
67.517823910,1818.0
67.567957717,1790.0
67.618091524,1882.0
67.668225331,1771.0
67.718359138,1807.0
67.768492945,1910.0
67.818626752,1757.0
67.868760559,1744.0
67.918894366,1717.0
67.969028173,1799.0
68.019161979,1743.0
68.069295786,1790.0
68.119429593,1799.0
68.169563400,1849.0
68.219697207,1837.0
68.269831014,1893.0
68.319964821,1814.0
68.370098628,1838.0
68.420232435,1744.0
68.470366242,1793.0
68.520500049,1759.0
68.570633856,1718.0
68.620767663,1778.0
68.670901470,1762.0
68.721035277,1785.0
68.771169083,1823.0
68.821302890,1756.0
68.871436697,1782.0
68.921570504,1770.0
68.971704311,1705.0
69.021838118,1756.0
69.071971925,1816.0
69.122105732,1771.0
69.172239539,1792.0
69.222373346,1763.0
69.272507153,1800.0
69.322640960,1774.0
69.372774767,1771.0
69.422908574,1750.0
69.473042381,1780.0
69.523176187,1770.0
69.573309994,1759.0
69.623443801,1717.0
69.673577608,1730.0
69.723711415,1736.0
69.773845222,1706.0
69.823979029,1775.0
69.874112836,1790.0
69.924246643,1709.0
69.974380450,1752.0
70.024514257,1790.0
70.074648064,1749.0
70.124781871,1735.0
70.174915678,1712.0
70.225049485,1727.0
70.275183291,1748.0
70.325317098,1743.0
70.375450905,1745.0
70.425584712,1681.0
70.475718519,1728.0
70.525852326,1663.0
70.575986133,1762.0
70.626119940,1748.0
70.676253747,1644.0
70.726387554,1693.0
70.776521361,1694.0
70.826655168,1719.0
70.876788975,1710.0
70.926922782,1737.0
70.977056589,1692.0
71.027190396,1710.0
71.077324202,1694.0
71.127458009,1690.0
71.177591816,1700.0
71.227725623,1726.0
71.277859430,1696.0
71.327993237,1717.0
71.378127044,1673.0
71.428260851,1660.0
71.478394658,1730.0
71.528528465,1705.0
71.578662272,1683.0
71.628796079,1756.0
71.678929886,1720.0
71.729063693,1684.0
71.779197500,1719.0
71.829331306,1709.0
71.879465113,1720.0
71.929598920,1606.0
71.979732727,1745.0
72.029866534,1670.0
72.080000341,1638.0
72.130134148,1657.0
72.180267955,1653.0
72.230401762,1683.0
72.280535569,1600.0
72.330669376,1700.0
72.380803183,1642.0
72.430936990,1636.0
72.481070797,1682.0
72.531204604,1707.0
72.581338410,1750.0
72.631472217,1659.0
72.681606024,1634.0
72.731739831,1633.0
72.781873638,1597.0
72.832007445,1639.0
72.882141252,1708.0
72.932275059,1624.0
72.982408866,1637.0
73.032542673,1652.0
73.082676480,1684.0
73.132810287,1676.0
73.182944094,1669.0
73.233077901,1590.0
73.283211708,1711.0
73.333345514,1651.0
73.383479321,1600.0
73.433613128,1676.0
73.483746935,1717.0
73.533880742,1632.0
73.584014549,1669.0
73.634148356,1623.0
73.684282163,1643.0
73.734415970,1635.0
73.784549777,1589.0
73.834683584,1647.0
73.884817391,1568.0
73.934951198,1622.0
73.985085005,1586.0
74.035218812,1595.0
74.085352618,1619.0
74.135486425,1581.0
74.185620232,1593.0
74.235754039,1657.0
74.285887846,1666.0
74.336021653,1664.0
74.386155460,1642.0
74.436289267,1622.0
74.486423074,1569.0
74.536556881,1698.0
74.586690688,1687.0
74.636824495,1635.0
74.686958302,1704.0
74.737092109,1587.0
74.787225916,1662.0
74.837359722,1638.0
74.887493529,1586.0
74.937627336,1628.0
74.987761143,1582.0
75.037894950,1683.0
75.088028757,1576.0
75.138162564,1594.0
75.188296371,1659.0
75.238430178,1653.0
75.288563985,1645.0
75.338697792,1658.0
75.388831599,1672.0
75.438965406,1669.0
75.489099213,1642.0
75.539233020,1701.0
75.589366827,1761.0
75.639500633,1738.0
75.689634440,1695.0
75.739768247,1762.0
75.789902054,1738.0
75.840035861,1795.0
75.890169668,1824.0
75.940303475,1833.0
75.990437282,1801.0
76.040571089,1867.0
76.090704896,2003.0
76.140838703,1986.0
76.190972510,2040.0
76.241106317,2167.0
76.291240124,2315.0
76.341373931,2202.0
76.391507737,2236.0
76.441641544,2065.0
76.491775351,2056.0
76.541909158,1897.0
76.592042965,1933.0
76.642176772,1839.0
76.692310579,1834.0
76.742444386,1726.0
76.792578193,1713.0
76.842712000,1692.0
76.892845807,1605.0
76.942979614,1611.0
76.993113421,1603.0
77.043247228,1603.0
77.093381035,1585.0
77.143514841,1497.0
77.193648648,1488.0
77.243782455,1540.0
77.293916262,1566.0
77.344050069,1587.0
77.394183876,1560.0
77.444317683,1535.0
77.494451490,1489.0
77.544585297,1526.0
77.594719104,1467.0
77.644852911,1572.0
77.694986718,1571.0
77.745120525,1528.0
77.795254332,1443.0
77.845388139,1519.0
77.895521945,1512.0
77.945655752,1444.0
77.995789559,1535.0
78.045923366,1479.0
78.096057173,1436.0
78.146190980,1504.0
78.196324787,1556.0
78.246458594,1452.0
78.296592401,1568.0
78.346726208,1481.0
78.396860015,1478.0
78.446993822,1495.0
78.497127629,1453.0
78.547261436,1455.0
78.597395243,1483.0
78.647529049,1472.0
78.697662856,1520.0
78.747796663,1490.0
78.797930470,1452.0
78.848064277,1512.0
78.898198084,1442.0
78.948331891,1414.0
78.998465698,1472.0
79.048599505,1444.0
79.098733312,1501.0
79.148867119,1525.0
79.199000926,1453.0
79.249134733,1479.0
79.299268540,1519.0
79.349402347,1406.0
79.399536153,1437.0
79.449669960,1431.0
79.499803767,1489.0
79.549937574,1452.0
79.600071381,1429.0
79.650205188,1399.0
79.700338995,1453.0
79.750472802,1430.0
79.800606609,1396.0
79.850740416,1418.0
79.900874223,1391.0
79.951008030,1453.0
80.001141837,1435.0
80.051275644,1497.0
80.101409451,1387.0
80.151543258,1486.0
80.201677064,1396.0
80.251810871,1460.0
80.301944678,1480.0
80.352078485,1491.0
80.402212292,1465.0
80.452346099,1372.0
80.502479906,1453.0
80.552613713,1402.0
80.602747520,1459.0
80.652881327,1414.0
80.703015134,1463.0
80.753148941,1467.0
80.803282748,1502.0
80.853416555,1409.0
80.903550362,1419.0
80.953684168,1423.0
81.003817975,1467.0
81.053951782,1477.0
81.104085589,1418.0
81.154219396,1467.0
81.204353203,1421.0
81.254487010,1417.0
81.304620817,1503.0
81.354754624,1430.0
81.404888431,1482.0
81.455022238,1393.0
81.505156045,1415.0
81.555289852,1450.0
81.605423659,1469.0
81.655557466,1388.0
81.705691272,1418.0
81.755825079,1441.0
81.805958886,1389.0
81.856092693,1399.0
81.906226500,1418.0
81.956360307,1398.0
82.006494114,1351.0
82.056627921,1362.0
82.106761728,1399.0
82.156895535,1394.0
82.207029342,1432.0
82.257163149,1397.0
82.307296956,1386.0
82.357430763,1385.0
82.407564570,1347.0
82.457698376,1383.0
82.507832183,1337.0
82.557965990,1316.0
82.608099797,1357.0
82.658233604,1385.0
82.708367411,1343.0
82.758501218,1361.0
82.808635025,1424.0
82.858768832,1417.0
82.908902639,1413.0
82.959036446,1380.0
83.009170253,1353.0
83.059304060,1357.0
83.109437867,1428.0
83.159571674,1352.0
83.209705480,1363.0
83.259839287,1329.0
83.309973094,1355.0
83.360106901,1331.0
83.410240708,1433.0
83.460374515,1358.0
83.510508322,1414.0
83.560642129,1329.0
83.610775936,1352.0
83.660909743,1287.0
83.711043550,1300.0
83.761177357,1353.0
83.811311164,1350.0
83.861444971,1404.0
83.911578778,1380.0
83.961712584,1390.0
84.011846391,1337.0
84.061980198,1363.0
84.112114005,1347.0
84.162247812,1318.0
84.212381619,1349.0
84.262515426,1398.0
84.312649233,1330.0
84.362783040,1408.0
84.412916847,1333.0
84.463050654,1334.0
84.513184461,1382.0
84.563318268,1344.0
84.613452075,1374.0
84.663585882,1333.0
84.713719689,1351.0
84.763853495,1335.0
84.813987302,1372.0
84.864121109,1273.0
84.914254916,1271.0
84.964388723,1313.0
85.014522530,1335.0
85.064656337,1370.0
85.114790144,1345.0
85.164923951,1296.0
85.215057758,1367.0
85.265191565,1358.0
85.315325372,1402.0
85.365459179,1354.0
85.415592986,1333.0
85.465726793,1308.0
85.515860599,1348.0
85.565994406,1341.0
85.616128213,1289.0
85.666262020,1407.0
85.716395827,1337.0
85.766529634,1375.0
85.816663441,1273.0
85.866797248,1240.0
85.916931055,1400.0
85.967064862,1356.0
86.017198669,1368.0
86.067332476,1310.0
86.117466283,1429.0
86.167600090,1384.0
86.217733897,1338.0
86.267867703,1386.0
86.318001510,1342.0
86.368135317,1323.0
86.418269124,1360.0
86.468402931,1350.0
86.518536738,1366.0
86.568670545,1383.0
86.618804352,1343.0
86.668938159,1327.0
86.719071966,1351.0
86.769205773,1304.0
86.819339580,1320.0
86.869473387,1284.0
86.919607194,1350.0
86.969741001,1380.0
87.019874807,1366.0
87.070008614,1380.0
87.120142421,1404.0
87.170276228,1364.0
87.220410035,1303.0
87.270543842,1352.0
87.320677649,1341.0
87.370811456,1263.0
87.420945263,1391.0
87.471079070,1407.0
87.521212877,1377.0
87.571346684,1335.0
87.621480491,1354.0
87.671614298,1321.0
87.721748105,1384.0
87.771881911,1341.0
87.822015718,1349.0
87.872149525,1325.0
87.922283332,1284.0
87.972417139,1311.0
88.022550946,1459.0
88.072684753,1306.0
88.122818560,1292.0
88.172952367,1295.0
88.223086174,1300.0
88.273219981,1402.0
88.323353788,1293.0
88.373487595,1301.0
88.423621402,1324.0
88.473755209,1259.0
88.523889016,1310.0
88.574022822,1370.0
88.624156629,1279.0
88.674290436,1316.0
88.724424243,1343.0
88.774558050,1290.0
88.824691857,1242.0
88.874825664,1375.0
88.924959471,1288.0
88.975093278,1292.0
89.025227085,1326.0
89.075360892,1296.0
89.125494699,1216.0
89.175628506,1274.0
89.225762313,1357.0
89.275896120,1312.0
89.326029926,1332.0
89.376163733,1275.0
89.426297540,1317.0
89.476431347,1306.0
89.526565154,1297.0
89.576698961,1203.0
89.626832768,1324.0
89.676966575,1248.0
89.727100382,1357.0
89.777234189,1356.0
89.827367996,1339.0
89.877501803,1312.0
89.927635610,1272.0
89.977769417,1316.0
90.027903224,1234.0
90.078037030,1289.0
90.128170837,1342.0
90.178304644,1247.0
90.228438451,1301.0
90.278572258,1242.0
90.328706065,1300.0
90.378839872,1247.0
90.428973679,1333.0
90.479107486,1269.0
90.529241293,1281.0
90.579375100,1315.0
90.629508907,1305.0
90.679642714,1260.0
90.729776521,1317.0
90.779910328,1372.0
90.830044134,1370.0
90.880177941,1304.0
90.930311748,1362.0
90.980445555,1264.0
91.030579362,1297.0
91.080713169,1284.0
91.130846976,1303.0
91.180980783,1316.0
91.231114590,1325.0
91.281248397,1312.0
91.331382204,1371.0
91.381516011,1317.0
91.431649818,1284.0
91.481783625,1384.0
91.531917432,1349.0
91.582051238,1337.0
91.632185045,1401.0
91.682318852,1299.0
91.732452659,1362.0
91.782586466,1325.0
91.832720273,1307.0
91.882854080,1343.0
91.932987887,1343.0
91.983121694,1402.0
92.033255501,1327.0
92.083389308,1385.0
92.133523115,1476.0
92.183656922,1404.0
92.233790729,1462.0
92.283924536,1484.0
92.334058342,1427.0
92.384192149,1469.0
92.434325956,1520.0
92.484459763,1566.0
92.534593570,1684.0
92.584727377,1570.0
92.634861184,1693.0
92.684994991,1712.0
92.735128798,1789.0
92.785262605,1758.0
92.835396412,1814.0
92.885530219,1750.0
92.935664026,1752.0
92.985797833,1693.0
93.035931640,1737.0
93.086065447,1628.0
93.136199253,1710.0
93.186333060,1603.0
93.236466867,1518.0
93.286600674,1430.0
93.336734481,1471.0
93.386868288,1475.0
93.437002095,1311.0
93.487135902,1323.0
93.537269709,1370.0
93.587403516,1241.0
93.637537323,1351.0
93.687671130,1316.0
93.737804937,1278.0
93.787938744,1315.0
93.838072551,1264.0
93.888206357,1338.0
93.938340164,1293.0
93.988473971,1249.0
94.038607778,1228.0
94.088741585,1382.0
94.138875392,1307.0
94.189009199,1280.0
94.239143006,1323.0
94.289276813,1240.0
94.339410620,1195.0
94.389544427,1314.0
94.439678234,1248.0
94.489812041,1293.0
94.539945848,1258.0
94.590079655,1260.0
94.640213461,1248.0
94.690347268,1260.0
94.740481075,1289.0
94.790614882,1266.0
94.840748689,1281.0
94.890882496,1306.0
94.941016303,1257.0
94.991150110,1300.0