File: OriginPro/XRD from Panalytical X'Pert PRO/In-Situ/XRD_1565Rep_500°C.csv
[Measurement conditions]
Sample identification,
Comment - 1,"Configuration=MRI TC-Basic Stage, Owner=User-1, Creation date=26-10-2009 9:18:44"
Comment - 2,"Goniometer=PW3050/60 (Theta/Theta); Minimum step size 2Theta:0.001; Minimum step size Omega:0.001"
Comment - 3,"Sample stage=MRI TC-Basic (PtRh heat strip)"
Comment - 4,"Diffractometer system=XPERT-PRO"
Comment - 5,"Measurement program=SGSi2TO_1565Rep, Owner=joana, Creation date=27-05-2015 11:04:00"
Comment - 6,"Fine Calibration Offset for 2Theta = 0.044 deg"
Anode material,Cu
K-Alpha1 wavelength,1.5405980
K-Alpha2 wavelength,1.5444260
Ratio K-Alpha2/K-Alpha1,0.500
Divergence slit,Fixed,0.76mm
Monochromator used,NO
Generator voltage, 45
Tube current, 40
File date and time,27/mai/2015 20:59
Unit cell,
h k l, 0 0 0
Temperature [K],773
Scan axis,2Theta-Omega
Scan range,15.000000001,65.000115719
Scan step size,0.0334225
Omega offset,-1.49999999
No. of points, 1496
Scan type,CONTINUOUS
Time per step,250.825
[Scan points]
Angle,Intensity
15.016711270,3707.0
15.050133807,3641.0
15.083556344,3818.0
15.116978882,3575.0
15.150401419,3662.0
15.183823956,3753.0
15.217246493,3749.0
15.250669031,3676.0
15.284091568,3744.0
15.317514105,3596.0
15.350936642,3522.0
15.384359180,3647.0
15.417781717,3759.0
15.451204254,3692.0
15.484626791,3576.0
15.518049329,3704.0
15.551471866,3629.0
15.584894403,3616.0
15.618316940,3573.0
15.651739478,3541.0
15.685162015,3615.0
15.718584552,3476.0
15.752007089,3482.0
15.785429627,3498.0
15.818852164,3597.0
15.852274701,3567.0
15.885697238,3552.0
15.919119776,3443.0
15.952542313,3547.0
15.985964850,3475.0
16.019387387,3475.0
16.052809925,3569.0
16.086232462,3536.0
16.119654999,3432.0
16.153077536,3465.0
16.186500074,3373.0
16.219922611,3399.0
16.253345148,3480.0
16.286767685,3453.0
16.320190223,3554.0
16.353612760,3417.0
16.387035297,3458.0
16.420457834,3264.0
16.453880371,3340.0
16.487302909,3440.0
16.520725446,3471.0
16.554147983,3411.0
16.587570520,3453.0
16.620993058,3343.0
16.654415595,3393.0
16.687838132,3433.0
16.721260669,3375.0
16.754683207,3583.0
16.788105744,3429.0
16.821528281,3384.0
16.854950818,3290.0
16.888373356,3415.0
16.921795893,3301.0
16.955218430,3361.0
16.988640967,3313.0
17.022063505,3256.0
17.055486042,3295.0
17.088908579,3283.0
17.122331116,3360.0
17.155753654,3361.0
17.189176191,3295.0
17.222598728,3318.0
17.256021265,3423.0
17.289443803,3434.0
17.322866340,3297.0
17.356288877,3319.0
17.389711414,3295.0
17.423133952,3296.0
17.456556489,3305.0
17.489979026,3240.0
17.523401563,3382.0
17.556824101,3235.0
17.590246638,3255.0
17.623669175,3198.0
17.657091712,3318.0
17.690514250,3284.0
17.723936787,3141.0
17.757359324,3247.0
17.790781861,3183.0
17.824204399,3218.0
17.857626936,3259.0
17.891049473,3314.0
17.924472010,3161.0
17.957894547,3253.0
17.991317085,3289.0
18.024739622,3259.0
18.058162159,3306.0
18.091584696,3299.0
18.125007234,3295.0
18.158429771,3270.0
18.191852308,3273.0
18.225274845,3245.0
18.258697383,3271.0
18.292119920,3328.0
18.325542457,3339.0
18.358964994,3328.0
18.392387532,3227.0
18.425810069,3175.0
18.459232606,3328.0
18.492655143,3143.0
18.526077681,3132.0
18.559500218,3119.0
18.592922755,3264.0
18.626345292,3110.0
18.659767830,3142.0
18.693190367,3014.0
18.726612904,2964.0
18.760035441,3038.0
18.793457979,3084.0
18.826880516,3033.0
18.860303053,3000.0
18.893725590,3050.0
18.927148128,3036.0
18.960570665,2983.0
18.993993202,2963.0
19.027415739,2981.0
19.060838277,3065.0
19.094260814,2953.0
19.127683351,2905.0
19.161105888,3045.0
19.194528426,2946.0
19.227950963,2934.0
19.261373500,2789.0
19.294796037,2926.0
19.328218574,2886.0
19.361641112,3020.0
19.395063649,2963.0
19.428486186,2923.0
19.461908723,2823.0
19.495331261,2916.0
19.528753798,2841.0
19.562176335,2851.0
19.595598872,2986.0
19.629021410,2945.0
19.662443947,2894.0
19.695866484,2848.0
19.729289021,2867.0
19.762711559,2835.0
19.796134096,2878.0
19.829556633,2850.0
19.862979170,2890.0
19.896401708,2823.0
19.929824245,2848.0
19.963246782,2881.0
19.996669319,2811.0
20.030091857,2804.0
20.063514394,2796.0
20.096936931,2741.0
20.130359468,2770.0
20.163782006,2808.0
20.197204543,2912.0
20.230627080,2862.0
20.264049617,2874.0
20.297472155,2765.0
20.330894692,2830.0
20.364317229,2874.0
20.397739766,2703.0
20.431162304,2762.0
20.464584841,2848.0
20.498007378,2792.0
20.531429915,2761.0
20.564852453,2792.0
20.598274990,2708.0
20.631697527,2787.0
20.665120064,2720.0
20.698542602,2739.0
20.731965139,2761.0
20.765387676,2729.0
20.798810213,2765.0
20.832232750,2853.0
20.865655288,2802.0
20.899077825,2667.0
20.932500362,2729.0
20.965922899,2734.0
20.999345437,2678.0
21.032767974,2735.0
21.066190511,2694.0
21.099613048,2708.0
21.133035586,2652.0
21.166458123,2818.0
21.199880660,2744.0
21.233303197,2628.0
21.266725735,2759.0
21.300148272,2662.0
21.333570809,2678.0
21.366993346,2698.0
21.400415884,2638.0
21.433838421,2673.0
21.467260958,2598.0
21.500683495,2613.0
21.534106033,2624.0
21.567528570,2718.0
21.600951107,2634.0
21.634373644,2565.0
21.667796182,2552.0
21.701218719,2731.0
21.734641256,2667.0
21.768063793,2707.0
21.801486331,2671.0
21.834908868,2782.0
21.868331405,2648.0
21.901753942,2608.0
21.935176480,2573.0
21.968599017,2635.0
22.002021554,2535.0
22.035444091,2559.0
22.068866629,2478.0
22.102289166,2577.0
22.135711703,2657.0
22.169134240,2566.0
22.202556777,2650.0
22.235979315,2526.0
22.269401852,2578.0
22.302824389,2618.0
22.336246926,2496.0
22.369669464,2530.0
22.403092001,2582.0
22.436514538,2590.0
22.469937075,2619.0
22.503359613,2615.0
22.536782150,2578.0
22.570204687,2562.0
22.603627224,2576.0
22.637049762,2486.0
22.670472299,2491.0
22.703894836,2434.0
22.737317373,2530.0
22.770739911,2502.0
22.804162448,2513.0
22.837584985,2472.0
22.871007522,2512.0
22.904430060,2517.0
22.937852597,2539.0
22.971275134,2462.0
23.004697671,2534.0
23.038120209,2505.0
23.071542746,2573.0
23.104965283,2546.0
23.138387820,2558.0
23.171810358,2480.0
23.205232895,2473.0
23.238655432,2505.0
23.272077969,2539.0
23.305500507,2560.0
23.338923044,2482.0
23.372345581,2551.0
23.405768118,2554.0
23.439190656,2573.0
23.472613193,2464.0
23.506035730,2505.0
23.539458267,2387.0
23.572880805,2401.0
23.606303342,2552.0
23.639725879,2531.0
23.673148416,2503.0
23.706570953,2398.0
23.739993491,2420.0
23.773416028,2522.0
23.806838565,2472.0
23.840261102,2492.0
23.873683640,2412.0
23.907106177,2529.0
23.940528714,2486.0
23.973951251,2507.0
24.007373789,2393.0
24.040796326,2339.0
24.074218863,2427.0
24.107641400,2422.0
24.141063938,2490.0
24.174486475,2384.0
24.207909012,2345.0
24.241331549,2397.0
24.274754087,2470.0
24.308176624,2397.0
24.341599161,2431.0
24.375021698,2335.0
24.408444236,2528.0
24.441866773,2366.0
24.475289310,2499.0
24.508711847,2413.0
24.542134385,2415.0
24.575556922,2440.0
24.608979459,2404.0
24.642401996,2412.0
24.675824534,2421.0
24.709247071,2391.0
24.742669608,2441.0
24.776092145,2402.0
24.809514683,2357.0
24.842937220,2344.0
24.876359757,2420.0
24.909782294,2312.0
24.943204832,2432.0
24.976627369,2387.0
25.010049906,2366.0
25.043472443,2365.0
25.076894980,2383.0
25.110317518,2250.0
25.143740055,2348.0
25.177162592,2381.0
25.210585129,2373.0
25.244007667,2382.0
25.277430204,2324.0
25.310852741,2424.0
25.344275278,2289.0
25.377697816,2347.0
25.411120353,2328.0
25.444542890,2323.0
25.477965427,2330.0
25.511387965,2398.0
25.544810502,2346.0
25.578233039,2279.0
25.611655576,2403.0
25.645078114,2387.0
25.678500651,2411.0
25.711923188,2247.0
25.745345725,2318.0
25.778768263,2268.0
25.812190800,2302.0
25.845613337,2341.0
25.879035874,2314.0
25.912458412,2289.0
25.945880949,2272.0
25.979303486,2304.0
26.012726023,2419.0
26.046148561,2185.0
26.079571098,2315.0
26.112993635,2298.0
26.146416172,2304.0
26.179838710,2261.0
26.213261247,2329.0
26.246683784,2281.0
26.280106321,2319.0
26.313528859,2352.0
26.346951396,2493.0
26.380373933,2293.0
26.413796470,2403.0
26.447219007,2363.0
26.480641545,2474.0
26.514064082,2340.0
26.547486619,2435.0
26.580909156,2478.0
26.614331694,2348.0
26.647754231,2352.0
26.681176768,2400.0
26.714599305,2404.0
26.748021843,2419.0
26.781444380,2478.0
26.814866917,2481.0
26.848289454,2531.0
26.881711992,2499.0
26.915134529,2572.0
26.948557066,2612.0
26.981979603,2544.0
27.015402141,2723.0
27.048824678,2679.0
27.082247215,2922.0
27.115669752,2884.0
27.149092290,3028.0
27.182514827,3213.0
27.215937364,3402.0
27.249359901,3380.0
27.282782439,3728.0
27.316204976,3743.0
27.349627513,3904.0
27.383050050,3823.0
27.416472588,3731.0
27.449895125,3621.0
27.483317662,3511.0
27.516740199,3427.0
27.550162737,3218.0
27.583585274,3142.0
27.617007811,2946.0
27.650430348,2909.0
27.683852886,2664.0
27.717275423,2621.0
27.750697960,2640.0
27.784120497,2478.0
27.817543035,2502.0
27.850965572,2444.0
27.884388109,2472.0
27.917810646,2384.0
27.951233183,2319.0
27.984655721,2387.0
28.018078258,2321.0
28.051500795,2336.0
28.084923332,2339.0
28.118345870,2251.0
28.151768407,2119.0
28.185190944,2136.0
28.218613481,2181.0
28.252036019,2161.0
28.285458556,2228.0
28.318881093,2161.0
28.352303630,2217.0
28.385726168,2219.0
28.419148705,2240.0
28.452571242,2187.0
28.485993779,2156.0
28.519416317,2229.0
28.552838854,2088.0
28.586261391,2155.0
28.619683928,2223.0
28.653106466,2261.0
28.686529003,1992.0
28.719951540,2121.0
28.753374077,2179.0
28.786796615,2075.0
28.820219152,2142.0
28.853641689,2218.0
28.887064226,2054.0
28.920486764,2030.0
28.953909301,2045.0
28.987331838,2071.0
29.020754375,2022.0
29.054176913,1969.0
29.087599450,2096.0
29.121021987,2162.0
29.154444524,2104.0
29.187867062,2050.0
29.221289599,2030.0
29.254712136,2068.0
29.288134673,2046.0
29.321557210,2065.0
29.354979748,2084.0
29.388402285,2025.0
29.421824822,1993.0
29.455247359,2082.0
29.488669897,2022.0
29.522092434,1982.0
29.555514971,2063.0
29.588937508,2098.0
29.622360046,2033.0
29.655782583,2006.0
29.689205120,2036.0
29.722627657,2020.0
29.756050195,2055.0
29.789472732,1999.0
29.822895269,1977.0
29.856317806,1997.0
29.889740344,2022.0
29.923162881,2000.0
29.956585418,2010.0
29.990007955,1950.0
30.023430493,1980.0
30.056853030,1939.0
30.090275567,2003.0
30.123698104,1926.0
30.157120642,1982.0
30.190543179,1917.0
30.223965716,1963.0
30.257388253,1981.0
30.290810791,1931.0
30.324233328,2016.0
30.357655865,1982.0
30.391078402,1974.0
30.424500940,1936.0
30.457923477,2021.0
30.491346014,2051.0
30.524768551,1911.0
30.558191089,1946.0
30.591613626,1903.0
30.625036163,1915.0
30.658458700,2015.0
30.691881238,1931.0
30.725303775,1967.0
30.758726312,1883.0
30.792148849,1950.0
30.825571386,1937.0
30.858993924,1888.0
30.892416461,1876.0
30.925838998,1945.0
30.959261535,1874.0
30.992684073,1981.0
31.026106610,1881.0
31.059529147,1854.0
31.092951684,1873.0
31.126374222,1822.0
31.159796759,1839.0
31.193219296,1849.0
31.226641833,1816.0
31.260064371,1848.0
31.293486908,1815.0
31.326909445,1924.0
31.360331982,1883.0
31.393754520,1849.0
31.427177057,1878.0
31.460599594,1795.0
31.494022131,1814.0
31.527444669,1815.0
31.560867206,1861.0
31.594289743,1869.0
31.627712280,1839.0
31.661134818,1860.0
31.694557355,1805.0
31.727979892,1867.0
31.761402429,1783.0
31.794824967,1811.0
31.828247504,1738.0
31.861670041,1788.0
31.895092578,1825.0
31.928515116,1769.0
31.961937653,1755.0
31.995360190,1783.0
32.028782727,1802.0
32.062205265,1800.0
32.095627802,1868.0
32.129050339,1823.0
32.162472876,1821.0
32.195895413,1735.0
32.229317951,1895.0
32.262740488,1778.0
32.296163025,1754.0
32.329585562,1818.0
32.363008100,1859.0
32.396430637,1850.0
32.429853174,1788.0
32.463275711,1687.0
32.496698249,1812.0
32.530120786,1838.0
32.563543323,1791.0
32.596965860,1778.0
32.630388398,1803.0
32.663810935,1797.0
32.697233472,1862.0
32.730656009,1816.0
32.764078547,1781.0
32.797501084,1774.0
32.830923621,1739.0
32.864346158,1716.0
32.897768696,1778.0
32.931191233,1765.0
32.964613770,1789.0
32.998036307,1673.0
33.031458845,1740.0
33.064881382,1720.0
33.098303919,1775.0
33.131726456,1734.0
33.165148994,1724.0
33.198571531,1733.0
33.231994068,1815.0
33.265416605,1826.0
33.298839143,1773.0
33.332261680,1695.0
33.365684217,1686.0
33.399106754,1741.0
33.432529292,1780.0
33.465951829,1739.0
33.499374366,1695.0
33.532796903,1670.0
33.566219441,1662.0
33.599641978,1695.0
33.633064515,1722.0
33.666487052,1706.0
33.699909589,1744.0
33.733332127,1696.0
33.766754664,1682.0
33.800177201,1706.0
33.833599738,1743.0
33.867022276,1774.0
33.900444813,1695.0
33.933867350,1682.0
33.967289887,1682.0
34.000712425,1682.0
34.034134962,1684.0
34.067557499,1664.0
34.100980036,1647.0
34.134402574,1646.0
34.167825111,1708.0
34.201247648,1665.0
34.234670185,1650.0
34.268092723,1670.0
34.301515260,1674.0
34.334937797,1698.0
34.368360334,1657.0
34.401782872,1616.0
34.435205409,1690.0
34.468627946,1703.0
34.502050483,1708.0
34.535473021,1654.0
34.568895558,1637.0
34.602318095,1688.0
34.635740632,1639.0
34.669163170,1691.0
34.702585707,1675.0
34.736008244,1653.0
34.769430781,1694.0
34.802853319,1618.0
34.836275856,1645.0
34.869698393,1617.0
34.903120930,1640.0
34.936543468,1644.0
34.969966005,1751.0
35.003388542,1669.0
35.036811079,1668.0
35.070233616,1700.0
35.103656154,1644.0
35.137078691,1673.0
35.170501228,1719.0
35.203923765,1574.0
35.237346303,1679.0
35.270768840,1735.0
35.304191377,1684.0
35.337613914,1667.0
35.371036452,1757.0
35.404458989,1742.0
35.437881526,1735.0
35.471304063,1718.0
35.504726601,1842.0
35.538149138,1871.0
35.571571675,1820.0
35.604994212,1890.0
35.638416750,1917.0
35.671839287,2034.0
35.705261824,2060.0
35.738684361,2121.0
35.772106899,2273.0
35.805529436,2269.0
35.838951973,2387.0
35.872374510,2384.0
35.905797048,2217.0
35.939219585,2195.0
35.972642122,2178.0
36.006064659,2075.0
36.039487197,1990.0
36.072909734,1938.0
36.106332271,1965.0
36.139754808,1902.0
36.173177346,1842.0
36.206599883,1873.0
36.240022420,1793.0
36.273444957,1838.0
36.306867495,1906.0
36.340290032,1835.0
36.373712569,1883.0
36.407135106,1880.0
36.440557643,1935.0
36.473980181,2046.0
36.507402718,2080.0
36.540825255,2265.0
36.574247792,2314.0
36.607670330,2503.0
36.641092867,2780.0
36.674515404,2987.0
36.707937941,3298.0
36.741360479,3963.0
36.774783016,4594.0
36.808205553,5329.0
36.841628090,5950.0
36.875050628,6353.0
36.908473165,6533.0
36.941895702,6614.0
36.975318239,6348.0
37.008740777,5797.0
37.042163314,5147.0
37.075585851,4684.0
37.109008388,3888.0
37.142430926,3365.0
37.175853463,3099.0
37.209276000,2814.0
37.242698537,2652.0
37.276121075,2414.0
37.309543612,2267.0
37.342966149,2128.0
37.376388686,2018.0
37.409811224,2035.0
37.443233761,1951.0
37.476656298,1887.0
37.510078835,1846.0
37.543501373,1772.0
37.576923910,1761.0
37.610346447,1725.0
37.643768984,1681.0
37.677191522,1650.0
37.710614059,1662.0
37.744036596,1595.0
37.777459133,1683.0
37.810881671,1638.0
37.844304208,1526.0
37.877726745,1582.0
37.911149282,1503.0
37.944571819,1474.0
37.977994357,1539.0
38.011416894,1620.0
38.044839431,1545.0
38.078261968,1597.0
38.111684506,1548.0
38.145107043,1538.0
38.178529580,1581.0
38.211952117,1558.0
38.245374655,1530.0
38.278797192,1647.0
38.312219729,1453.0
38.345642266,1572.0
38.379064804,1577.0
38.412487341,1538.0
38.445909878,1556.0
38.479332415,1505.0
38.512754953,1513.0
38.546177490,1523.0
38.579600027,1606.0
38.613022564,1465.0
38.646445102,1563.0
38.679867639,1633.0
38.713290176,1507.0
38.746712713,1636.0
38.780135251,1549.0
38.813557788,1643.0
38.846980325,1602.0
38.880402862,1627.0
38.913825400,1569.0
38.947247937,1534.0
38.980670474,1559.0
39.014093011,1534.0
39.047515549,1557.0
39.080938086,1490.0
39.114360623,1619.0
39.147783160,1506.0
39.181205698,1610.0
39.214628235,1537.0
39.248050772,1570.0
39.281473309,1545.0
39.314895846,1586.0
39.348318384,1508.0
39.381740921,1524.0
39.415163458,1557.0
39.448585995,1450.0
39.482008533,1547.0
39.515431070,1465.0
39.548853607,1479.0
39.582276144,1480.0
39.615698682,1437.0
39.649121219,1466.0
39.682543756,1460.0
39.715966293,1397.0
39.749388831,1452.0
39.782811368,1543.0
39.816233905,1602.0
39.849656442,1624.0
39.883078980,1546.0
39.916501517,1510.0
39.949924054,1477.0
39.983346591,1515.0
40.016769129,1425.0
40.050191666,1363.0
40.083614203,1303.0
40.117036740,1362.0
40.150459278,1368.0
40.183881815,1353.0
40.217304352,1352.0
40.250726889,1395.0
40.284149427,1329.0
40.317571964,1340.0
40.350994501,1359.0
40.384417038,1304.0
40.417839576,1308.0
40.451262113,1351.0
40.484684650,1382.0
40.518107187,1341.0
40.551529725,1351.0
40.584952262,1349.0
40.618374799,1394.0
40.651797336,1364.0
40.685219874,1434.0
40.718642411,1358.0
40.752064948,1441.0
40.785487485,1410.0
40.818910022,1351.0
40.852332560,1436.0
40.885755097,1369.0
40.919177634,1422.0
40.952600171,1433.0
40.986022709,1387.0
41.019445246,1458.0
41.052867783,1430.0
41.086290320,1430.0
41.119712858,1421.0
41.153135395,1467.0
41.186557932,1375.0
41.219980469,1375.0
41.253403007,1358.0
41.286825544,1283.0
41.320248081,1316.0
41.353670618,1353.0
41.387093156,1387.0
41.420515693,1357.0
41.453938230,1336.0
41.487360767,1327.0
41.520783305,1367.0
41.554205842,1242.0
41.587628379,1306.0
41.621050916,1260.0
41.654473454,1287.0
41.687895991,1233.0
41.721318528,1252.0
41.754741065,1325.0
41.788163603,1253.0
41.821586140,1238.0
41.855008677,1315.0
41.888431214,1320.0
41.921853752,1333.0
41.955276289,1309.0
41.988698826,1323.0
42.022121363,1337.0
42.055543901,1274.0
42.088966438,1304.0
42.122388975,1332.0
42.155811512,1368.0
42.189234049,1337.0
42.222656587,1367.0
42.256079124,1290.0
42.289501661,1279.0
42.322924198,1280.0
42.356346736,1315.0
42.389769273,1307.0
42.423191810,1338.0
42.456614347,1335.0
42.490036885,1355.0
42.523459422,1396.0
42.556881959,1362.0
42.590304496,1384.0
42.623727034,1313.0
42.657149571,1327.0
42.690572108,1290.0
42.723994645,1347.0
42.757417183,1307.0
42.790839720,1292.0
42.824262257,1307.0
42.857684794,1333.0
42.891107332,1289.0
42.924529869,1355.0
42.957952406,1295.0
42.991374943,1374.0
43.024797481,1408.0
43.058220018,1380.0
43.091642555,1449.0
43.125065092,1444.0
43.158487630,1461.0
43.191910167,1509.0
43.225332704,1561.0
43.258755241,1535.0
43.292177779,1467.0
43.325600316,1523.0
43.359022853,1557.0
43.392445390,1636.0
43.425867928,1557.0
43.459290465,1473.0
43.492713002,1546.0
43.526135539,1554.0
43.559558077,1517.0
43.592980614,1421.0
43.626403151,1485.0
43.659825688,1429.0
43.693248225,1398.0
43.726670763,1403.0
43.760093300,1424.0
43.793515837,1421.0
43.826938374,1461.0
43.860360912,1398.0
43.893783449,1435.0
43.927205986,1286.0
43.960628523,1318.0
43.994051061,1394.0
44.027473598,1318.0
44.060896135,1270.0
44.094318672,1305.0
44.127741210,1284.0
44.161163747,1300.0
44.194586284,1296.0
44.228008821,1297.0
44.261431359,1298.0
44.294853896,1268.0
44.328276433,1323.0
44.361698970,1253.0
44.395121508,1226.0
44.428544045,1306.0
44.461966582,1360.0
44.495389119,1467.0
44.528811657,1424.0
44.562234194,1389.0
44.595656731,1263.0
44.629079268,1244.0
44.662501806,1228.0
44.695924343,1260.0
44.729346880,1220.0
44.762769417,1216.0
44.796191955,1201.0
44.829614492,1236.0
44.863037029,1196.0
44.896459566,1251.0
44.929882104,1270.0
44.963304641,1206.0
44.996727178,1202.0
45.030149715,1254.0
45.063572252,1231.0
45.096994790,1342.0
45.130417327,1303.0
45.163839864,1312.0
45.197262401,1387.0
45.230684939,1353.0
45.264107476,1281.0
45.297530013,1208.0
45.330952550,1237.0
45.364375088,1219.0
45.397797625,1246.0
45.431220162,1209.0
45.464642699,1154.0
45.498065237,1196.0
45.531487774,1212.0
45.564910311,1205.0
45.598332848,1218.0
45.631755386,1177.0
45.665177923,1212.0
45.698600460,1214.0
45.732022997,1237.0
45.765445535,1227.0
45.798868072,1170.0
45.832290609,1153.0
45.865713146,1244.0
45.899135684,1185.0
45.932558221,1279.0
45.965980758,1124.0
45.999403295,1126.0
46.032825833,1227.0
46.066248370,1213.0
46.099670907,1218.0
46.133093444,1220.0
46.166515982,1227.0
46.199938519,1190.0
46.233361056,1217.0
46.266783593,1160.0
46.300206131,1284.0
46.333628668,1207.0
46.367051205,1179.0
46.400473742,1262.0
46.433896279,1251.0
46.467318817,1201.0
46.500741354,1191.0
46.534163891,1210.0
46.567586428,1178.0
46.601008966,1162.0
46.634431503,1147.0
46.667854040,1179.0
46.701276577,1099.0
46.734699115,1184.0
46.768121652,1183.0
46.801544189,1188.0
46.834966726,1190.0
46.868389264,1138.0
46.901811801,1109.0
46.935234338,1139.0
46.968656875,1159.0
47.002079413,1165.0
47.035501950,1132.0
47.068924487,1107.0
47.102347024,1169.0
47.135769562,1137.0
47.169192099,1153.0
47.202614636,1120.0
47.236037173,1178.0
47.269459711,1139.0
47.302882248,1113.0
47.336304785,1199.0
47.369727322,1191.0
47.403149860,1171.0
47.436572397,1166.0
47.469994934,1127.0
47.503417471,1170.0
47.536840009,1136.0
47.570262546,1106.0
47.603685083,1164.0
47.637107620,1116.0
47.670530158,1153.0
47.703952695,1117.0
47.737375232,1123.0
47.770797769,1128.0
47.804220307,1096.0
47.837642844,1155.0
47.871065381,1148.0
47.904487918,1134.0
47.937910455,1108.0
47.971332993,1099.0
48.004755530,1093.0
48.038178067,1190.0
48.071600604,1114.0
48.105023142,1151.0
48.138445679,1134.0
48.171868216,1129.0
48.205290753,1165.0
48.238713291,1085.0
48.272135828,1116.0
48.305558365,1113.0
48.338980902,1210.0
48.372403440,1052.0
48.405825977,1107.0
48.439248514,1080.0
48.472671051,1070.0
48.506093589,1124.0
48.539516126,1142.0
48.572938663,1091.0
48.606361200,1099.0
48.639783738,1130.0
48.673206275,1071.0
48.706628812,1053.0
48.740051349,1043.0
48.773473887,1101.0
48.806896424,1111.0
48.840318961,1133.0
48.873741498,1132.0
48.907164036,1121.0
48.940586573,1065.0
48.974009110,1086.0
49.007431647,1092.0
49.040854185,1103.0
49.074276722,1120.0
49.107699259,1088.0
49.141121796,1111.0
49.174544334,1067.0
49.207966871,1148.0
49.241389408,1053.0
49.274811945,1110.0
49.308234482,1085.0
49.341657020,1116.0
49.375079557,1139.0
49.408502094,1097.0
49.441924631,1155.0
49.475347169,1131.0
49.508769706,1256.0
49.542192243,1357.0
49.575614780,1424.0
49.609037318,1442.0
49.642459855,1366.0
49.675882392,1275.0
49.709304929,1232.0
49.742727467,1210.0
49.776150004,1154.0
49.809572541,1145.0
49.842995078,1094.0
49.876417616,1060.0
49.909840153,1102.0
49.943262690,1069.0
49.976685227,1084.0
50.010107765,1159.0
50.043530302,1084.0
50.076952839,1113.0
50.110375376,1134.0
50.143797914,1101.0
50.177220451,1130.0
50.210642988,1144.0
50.244065525,1161.0
50.277488063,1174.0
50.310910600,1226.0
50.344333137,1121.0
50.377755674,1130.0
50.411178212,1170.0
50.444600749,1138.0
50.478023286,1099.0
50.511445823,1136.0
50.544868361,1103.0
50.578290898,1121.0
50.611713435,1137.0
50.645135972,1111.0
50.678558510,1100.0
50.711981047,1055.0
50.745403584,1119.0
50.778826121,1088.0
50.812248658,1029.0
50.845671196,996.0
50.879093733,1098.0
50.912516270,1104.0
50.945938807,1002.0
50.979361345,1112.0
51.012783882,1162.0
51.046206419,1137.0
51.079628956,1073.0
51.113051494,1049.0
51.146474031,1129.0
51.179896568,1047.0
51.213319105,1058.0
51.246741643,1097.0
51.280164180,994.0
51.313586717,1075.0
51.347009254,1124.0
51.380431792,1105.0
51.413854329,1065.0
51.447276866,1100.0
51.480699403,1129.0
51.514121941,1034.0
51.547544478,1051.0
51.580967015,1021.0
51.614389552,1085.0
51.647812090,1126.0
51.681234627,1115.0
51.714657164,994.0
51.748079701,1122.0
51.781502239,1068.0
51.814924776,1036.0
51.848347313,1083.0
51.881769850,1043.0
51.915192388,1017.0
51.948614925,1085.0
51.982037462,1057.0
52.015459999,1066.0
52.048882537,1055.0
52.082305074,1073.0
52.115727611,1068.0
52.149150148,1045.0
52.182572685,1052.0
52.215995223,1034.0
52.249417760,1119.0
52.282840297,1104.0
52.316262834,1107.0
52.349685372,1013.0
52.383107909,1092.0
52.416530446,1128.0
52.449952983,1045.0
52.483375521,1062.0
52.516798058,1080.0
52.550220595,1121.0
52.583643132,1116.0
52.617065670,1098.0
52.650488207,1095.0
52.683910744,1090.0
52.717333281,1104.0
52.750755819,1002.0
52.784178356,1082.0
52.817600893,1034.0
52.851023430,1099.0
52.884445968,1043.0
52.917868505,1048.0
52.951291042,1063.0
52.984713579,1079.0
53.018136117,1073.0
53.051558654,1071.0
53.084981191,1047.0
53.118403728,1090.0
53.151826266,1045.0
53.185248803,1044.0
53.218671340,1120.0
53.252093877,1114.0
53.285516415,1119.0
53.318938952,1064.0
53.352361489,1087.0
53.385784026,1119.0
53.419206564,1151.0
53.452629101,1149.0
53.486051638,1093.0
53.519474175,1147.0
53.552896713,1131.0
53.586319250,1162.0
53.619741787,1129.0
53.653164324,1132.0
53.686586861,1176.0
53.720009399,1190.0
53.753431936,1205.0
53.786854473,1147.0
53.820277010,1181.0
53.853699548,1221.0
53.887122085,1230.0
53.920544622,1355.0
53.953967159,1233.0
53.987389697,1272.0
54.020812234,1305.0
54.054234771,1336.0
54.087657308,1332.0
54.121079846,1293.0
54.154502383,1274.0
54.187924920,1280.0
54.221347457,1329.0
54.254769995,1271.0
54.288192532,1241.0
54.321615069,1207.0
54.355037606,1226.0
54.388460144,1231.0
54.421882681,1180.0
54.455305218,1171.0
54.488727755,1181.0
54.522150293,1107.0
54.555572830,1148.0
54.588995367,1105.0
54.622417904,1080.0
54.655840442,1157.0
54.689262979,1135.0
54.722685516,1081.0
54.756108053,1051.0
54.789530591,1092.0
54.822953128,1177.0
54.856375665,1107.0
54.889798202,1109.0
54.923220740,1062.0
54.956643277,1052.0
54.990065814,1052.0
55.023488351,1134.0
55.056910888,1054.0
55.090333426,1074.0
55.123755963,1057.0
55.157178500,1054.0
55.190601037,1121.0
55.224023575,1067.0
55.257446112,1102.0
55.290868649,1063.0
55.324291186,1090.0
55.357713724,1096.0
55.391136261,1076.0
55.424558798,1120.0
55.457981335,1148.0
55.491403873,1134.0
55.524826410,1134.0
55.558248947,1097.0
55.591671484,1091.0
55.625094022,1025.0
55.658516559,1087.0
55.691939096,1088.0
55.725361633,1080.0
55.758784171,1127.0
55.792206708,1049.0
55.825629245,1153.0
55.859051782,1168.0
55.892474320,1055.0
55.925896857,1105.0
55.959319394,1154.0
55.992741931,1198.0
56.026164469,1121.0
56.059587006,1213.0
56.093009543,1212.0
56.126432080,1209.0
56.159854618,1168.0
56.193277155,1226.0
56.226699692,1178.0
56.260122229,1235.0
56.293544767,1210.0
56.326967304,1198.0
56.360389841,1244.0
56.393812378,1305.0
56.427234915,1161.0
56.460657453,1275.0
56.494079990,1158.0
56.527502527,1313.0
56.560925064,1235.0
56.594347602,1245.0
56.627770139,1281.0
56.661192676,1234.0
56.694615213,1203.0
56.728037751,1210.0
56.761460288,1261.0
56.794882825,1203.0
56.828305362,1254.0
56.861727900,1206.0
56.895150437,1253.0
56.928572974,1261.0
56.961995511,1224.0
56.995418049,1196.0
57.028840586,1238.0
57.062263123,1200.0
57.095685660,1160.0
57.129108198,1198.0
57.162530735,1163.0
57.195953272,1186.0
57.229375809,1051.0
57.262798347,1193.0
57.296220884,1182.0
57.329643421,1100.0
57.363065958,1186.0
57.396488496,1151.0
57.429911033,1156.0
57.463333570,1128.0
57.496756107,1135.0
57.530178645,1167.0
57.563601182,1140.0
57.597023719,1101.0
57.630446256,1139.0
57.663868794,1127.0
57.697291331,1061.0
57.730713868,1151.0
57.764136405,1160.0
57.797558943,1130.0
57.830981480,1152.0
57.864404017,1156.0
57.897826554,1182.0
57.931249091,1203.0
57.964671629,1136.0
57.998094166,1187.0
58.031516703,1131.0
58.064939240,1189.0
58.098361778,1136.0
58.131784315,1185.0
58.165206852,1192.0
58.198629389,1169.0
58.232051927,1119.0
58.265474464,1156.0
58.298897001,1114.0
58.332319538,1222.0
58.365742076,1199.0
58.399164613,1139.0
58.432587150,1080.0
58.466009687,1049.0
58.499432225,1170.0
58.532854762,1190.0
58.566277299,1146.0
58.599699836,1186.0
58.633122374,1199.0
58.666544911,1218.0
58.699967448,1174.0
58.733389985,1167.0
58.766812523,1203.0
58.800235060,1164.0
58.833657597,1194.0
58.867080134,1177.0
58.900502672,1150.0
58.933925209,1189.0
58.967347746,1209.0
59.000770283,1186.0
59.034192821,1212.0
59.067615358,1151.0
59.101037895,1171.0
59.134460432,1172.0
59.167882970,1225.0
59.201305507,1196.0
59.234728044,1283.0
59.268150581,1235.0
59.301573118,1250.0
59.334995656,1178.0
59.368418193,1311.0
59.401840730,1242.0
59.435263267,1277.0
59.468685805,1224.0
59.502108342,1220.0
59.535530879,1272.0
59.568953416,1218.0
59.602375954,1257.0
59.635798491,1213.0
59.669221028,1227.0
59.702643565,1325.0
59.736066103,1313.0
59.769488640,1200.0
59.802911177,1277.0
59.836333714,1269.0
59.869756252,1244.0
59.903178789,1345.0
59.936601326,1268.0
59.970023863,1309.0
60.003446401,1316.0
60.036868938,1302.0
60.070291475,1319.0
60.103714012,1284.0
60.137136550,1323.0
60.170559087,1318.0
60.203981624,1324.0
60.237404161,1306.0
60.270826699,1332.0
60.304249236,1374.0
60.337671773,1348.0
60.371094310,1338.0
60.404516848,1369.0
60.437939385,1388.0
60.471361922,1331.0
60.504784459,1331.0
60.538206997,1401.0
60.571629534,1358.0
60.605052071,1408.0
60.638474608,1432.0
60.671897146,1348.0
60.705319683,1337.0
60.738742220,1400.0
60.772164757,1499.0
60.805587294,1396.0
60.839009832,1461.0
60.872432369,1450.0
60.905854906,1530.0
60.939277443,1504.0
60.972699981,1513.0
61.006122518,1448.0
61.039545055,1565.0
61.072967592,1457.0
61.106390130,1583.0
61.139812667,1513.0
61.173235204,1523.0
61.206657741,1539.0
61.240080279,1570.0
61.273502816,1551.0
61.306925353,1607.0
61.340347890,1699.0
61.373770428,1777.0
61.407192965,1849.0
61.440615502,1848.0
61.474038039,1813.0
61.507460577,1678.0
61.540883114,1762.0
61.574305651,1684.0
61.607728188,1730.0
61.641150726,1744.0
61.674573263,1699.0
61.707995800,1792.0
61.741418337,1699.0
61.774840875,1763.0
61.808263412,1696.0
61.841685949,1688.0
61.875108486,1789.0
61.908531024,1823.0
61.941953561,1818.0
61.975376098,1814.0
62.008798635,1910.0
62.042221173,1877.0
62.075643710,1902.0
62.109066247,1866.0
62.142488784,1817.0
62.175911321,1883.0
62.209333859,1895.0
62.242756396,1979.0
62.276178933,1961.0
62.309601470,1930.0
62.343024008,1891.0
62.376446545,1925.0
62.409869082,1900.0
62.443291619,2050.0
62.476714157,2024.0
62.510136694,1933.0
62.543559231,2058.0
62.576981768,2010.0
62.610404306,1985.0
62.643826843,2006.0
62.677249380,2025.0
62.710671917,2046.0
62.744094455,1971.0
62.777516992,1886.0
62.810939529,1935.0
62.844362066,2038.0
62.877784604,2058.0
62.911207141,2001.0
62.944629678,2131.0
62.978052215,2024.0
63.011474753,2127.0
63.044897290,2125.0
63.078319827,2025.0
63.111742364,2082.0
63.145164902,2026.0
63.178587439,2031.0
63.212009976,2150.0
63.245432513,2087.0
63.278855051,2188.0
63.312277588,2130.0
63.345700125,2067.0
63.379122662,2124.0
63.412545200,2130.0
63.445967737,2233.0
63.479390274,2219.0
63.512812811,2177.0
63.546235349,2210.0
63.579657886,2252.0
63.613080423,2283.0
63.646502960,2227.0
63.679925497,2244.0
63.713348035,2302.0
63.746770572,2251.0
63.780193109,2316.0
63.813615646,2324.0
63.847038184,2260.0
63.880460721,2312.0
63.913883258,2278.0
63.947305795,2318.0
63.980728333,2218.0
64.014150870,2246.0
64.047573407,2327.0
64.080995944,2374.0
64.114418482,2392.0
64.147841019,2322.0
64.181263556,2460.0
64.214686093,2402.0
64.248108631,2503.0
64.281531168,2393.0
64.314953705,2322.0
64.348376242,2450.0
64.381798780,2489.0
64.415221317,2558.0
64.448643854,2564.0
64.482066391,2655.0
64.515488929,2643.0
64.548911466,2595.0
64.582334003,2734.0
64.615756540,2545.0
64.649179078,2724.0
64.682601615,2712.0
64.716024152,2796.0
64.749446689,2787.0
64.782869227,2821.0
64.816291764,2872.0
64.849714301,2899.0
64.883136838,2924.0
64.916559376,2899.0
64.949981913,2998.0
64.983404450,3011.0