File: OriginPro/XRD from Panalytical X'Pert PRO/In-Situ/XRD_1565Rep_450°C.csv
[Measurement conditions]
Sample identification,
Comment - 1,"Configuration=MRI TC-Basic Stage, Owner=User-1, Creation date=26-10-2009 9:18:44"
Comment - 2,"Goniometer=PW3050/60 (Theta/Theta); Minimum step size 2Theta:0.001; Minimum step size Omega:0.001"
Comment - 3,"Sample stage=MRI TC-Basic (PtRh heat strip)"
Comment - 4,"Diffractometer system=XPERT-PRO"
Comment - 5,"Measurement program=SGSi2TO_1565Rep, Owner=joana, Creation date=27-05-2015 11:04:00"
Comment - 6,"Fine Calibration Offset for 2Theta = 0.044 deg"
Anode material,Cu
K-Alpha1 wavelength,1.5405980
K-Alpha2 wavelength,1.5444260
Ratio K-Alpha2/K-Alpha1,0.500
Divergence slit,Fixed,0.76mm
Monochromator used,NO
Generator voltage, 45
Tube current, 40
File date and time,27/mai/2015 19:49
Unit cell,
h k l, 0 0 0
Temperature [K],723
Scan axis,2Theta-Omega
Scan range,15.000000001,65.000115719
Scan step size,0.0334225
Omega offset,-1.49999999
No. of points, 1496
Scan type,CONTINUOUS
Time per step,250.825
[Scan points]
Angle,Intensity
15.016711270,3812.0
15.050133807,3804.0
15.083556344,3722.0
15.116978882,3736.0
15.150401419,3747.0
15.183823956,3722.0
15.217246493,3622.0
15.250669031,3720.0
15.284091568,3654.0
15.317514105,3652.0
15.350936642,3648.0
15.384359180,3856.0
15.417781717,3747.0
15.451204254,3733.0
15.484626791,3626.0
15.518049329,3696.0
15.551471866,3704.0
15.584894403,3705.0
15.618316940,3668.0
15.651739478,3663.0
15.685162015,3690.0
15.718584552,3650.0
15.752007089,3619.0
15.785429627,3631.0
15.818852164,3560.0
15.852274701,3605.0
15.885697238,3635.0
15.919119776,3554.0
15.952542313,3476.0
15.985964850,3529.0
16.019387387,3604.0
16.052809925,3498.0
16.086232462,3658.0
16.119654999,3549.0
16.153077536,3458.0
16.186500074,3409.0
16.219922611,3484.0
16.253345148,3547.0
16.286767685,3588.0
16.320190223,3491.0
16.353612760,3560.0
16.387035297,3562.0
16.420457834,3527.0
16.453880371,3492.0
16.487302909,3551.0
16.520725446,3480.0
16.554147983,3435.0
16.587570520,3448.0
16.620993058,3397.0
16.654415595,3444.0
16.687838132,3409.0
16.721260669,3520.0
16.754683207,3356.0
16.788105744,3335.0
16.821528281,3456.0
16.854950818,3293.0
16.888373356,3411.0
16.921795893,3280.0
16.955218430,3383.0
16.988640967,3347.0
17.022063505,3224.0
17.055486042,3212.0
17.088908579,3423.0
17.122331116,3414.0
17.155753654,3248.0
17.189176191,3421.0
17.222598728,3298.0
17.256021265,3310.0
17.289443803,3190.0
17.322866340,3219.0
17.356288877,3329.0
17.389711414,3367.0
17.423133952,3236.0
17.456556489,3352.0
17.489979026,3383.0
17.523401563,3369.0
17.556824101,3431.0
17.590246638,3411.0
17.623669175,3327.0
17.657091712,3253.0
17.690514250,3226.0
17.723936787,3233.0
17.757359324,3373.0
17.790781861,3238.0
17.824204399,3330.0
17.857626936,3263.0
17.891049473,3263.0
17.924472010,3189.0
17.957894547,3246.0
17.991317085,3215.0
18.024739622,3338.0
18.058162159,3182.0
18.091584696,3290.0
18.125007234,3325.0
18.158429771,3362.0
18.191852308,3508.0
18.225274845,3524.0
18.258697383,3345.0
18.292119920,3315.0
18.325542457,3314.0
18.358964994,3437.0
18.392387532,3359.0
18.425810069,3341.0
18.459232606,3285.0
18.492655143,3379.0
18.526077681,3303.0
18.559500218,3287.0
18.592922755,3252.0
18.626345292,3170.0
18.659767830,3220.0
18.693190367,3192.0
18.726612904,3137.0
18.760035441,3135.0
18.793457979,3090.0
18.826880516,3192.0
18.860303053,3126.0
18.893725590,3139.0
18.927148128,3030.0
18.960570665,3039.0
18.993993202,3110.0
19.027415739,3079.0
19.060838277,2958.0
19.094260814,3130.0
19.127683351,2985.0
19.161105888,3007.0
19.194528426,3026.0
19.227950963,2961.0
19.261373500,3025.0
19.294796037,2968.0
19.328218574,2822.0
19.361641112,3048.0
19.395063649,2952.0
19.428486186,2955.0
19.461908723,2913.0
19.495331261,3016.0
19.528753798,2866.0
19.562176335,2934.0
19.595598872,2809.0
19.629021410,2968.0
19.662443947,2859.0
19.695866484,2892.0
19.729289021,2949.0
19.762711559,2866.0
19.796134096,2957.0
19.829556633,2969.0
19.862979170,2808.0
19.896401708,2836.0
19.929824245,2883.0
19.963246782,2910.0
19.996669319,2951.0
20.030091857,2911.0
20.063514394,2798.0
20.096936931,2839.0
20.130359468,2912.0
20.163782006,2751.0
20.197204543,2883.0
20.230627080,2885.0
20.264049617,2877.0
20.297472155,2853.0
20.330894692,2814.0
20.364317229,2865.0
20.397739766,2746.0
20.431162304,2818.0
20.464584841,2765.0
20.498007378,2804.0
20.531429915,2657.0
20.564852453,2850.0
20.598274990,2846.0
20.631697527,2743.0
20.665120064,2764.0
20.698542602,2703.0
20.731965139,2788.0
20.765387676,2728.0
20.798810213,2746.0
20.832232750,2753.0
20.865655288,2710.0
20.899077825,2742.0
20.932500362,2724.0
20.965922899,2674.0
20.999345437,2665.0
21.032767974,2694.0
21.066190511,2725.0
21.099613048,2726.0
21.133035586,2688.0
21.166458123,2741.0
21.199880660,2733.0
21.233303197,2721.0
21.266725735,2733.0
21.300148272,2669.0
21.333570809,2715.0
21.366993346,2680.0
21.400415884,2675.0
21.433838421,2632.0
21.467260958,2579.0
21.500683495,2697.0
21.534106033,2571.0
21.567528570,2621.0
21.600951107,2614.0
21.634373644,2649.0
21.667796182,2567.0
21.701218719,2722.0
21.734641256,2544.0
21.768063793,2587.0
21.801486331,2605.0
21.834908868,2696.0
21.868331405,2629.0
21.901753942,2658.0
21.935176480,2635.0
21.968599017,2667.0
22.002021554,2669.0
22.035444091,2635.0
22.068866629,2563.0
22.102289166,2608.0
22.135711703,2672.0
22.169134240,2536.0
22.202556777,2613.0
22.235979315,2504.0
22.269401852,2607.0
22.302824389,2659.0
22.336246926,2551.0
22.369669464,2510.0
22.403092001,2567.0
22.436514538,2567.0
22.469937075,2583.0
22.503359613,2632.0
22.536782150,2567.0
22.570204687,2568.0
22.603627224,2525.0
22.637049762,2404.0
22.670472299,2431.0
22.703894836,2465.0
22.737317373,2504.0
22.770739911,2522.0
22.804162448,2566.0
22.837584985,2490.0
22.871007522,2511.0
22.904430060,2571.0
22.937852597,2517.0
22.971275134,2470.0
23.004697671,2454.0
23.038120209,2448.0
23.071542746,2457.0
23.104965283,2409.0
23.138387820,2533.0
23.171810358,2449.0
23.205232895,2519.0
23.238655432,2493.0
23.272077969,2480.0
23.305500507,2359.0
23.338923044,2523.0
23.372345581,2390.0
23.405768118,2465.0
23.439190656,2429.0
23.472613193,2496.0
23.506035730,2416.0
23.539458267,2395.0
23.572880805,2415.0
23.606303342,2427.0
23.639725879,2466.0
23.673148416,2457.0
23.706570953,2473.0
23.739993491,2405.0
23.773416028,2388.0
23.806838565,2375.0
23.840261102,2406.0
23.873683640,2395.0
23.907106177,2413.0
23.940528714,2404.0
23.973951251,2413.0
24.007373789,2396.0
24.040796326,2367.0
24.074218863,2359.0
24.107641400,2389.0
24.141063938,2456.0
24.174486475,2401.0
24.207909012,2331.0
24.241331549,2469.0
24.274754087,2437.0
24.308176624,2369.0
24.341599161,2363.0
24.375021698,2315.0
24.408444236,2338.0
24.441866773,2365.0
24.475289310,2367.0
24.508711847,2348.0
24.542134385,2431.0
24.575556922,2346.0
24.608979459,2327.0
24.642401996,2277.0
24.675824534,2288.0
24.709247071,2339.0
24.742669608,2325.0
24.776092145,2356.0
24.809514683,2328.0
24.842937220,2349.0
24.876359757,2264.0
24.909782294,2305.0
24.943204832,2289.0
24.976627369,2336.0
25.010049906,2346.0
25.043472443,2228.0
25.076894980,2244.0
25.110317518,2326.0
25.143740055,2336.0
25.177162592,2324.0
25.210585129,2289.0
25.244007667,2289.0
25.277430204,2239.0
25.310852741,2389.0
25.344275278,2373.0
25.377697816,2251.0
25.411120353,2330.0
25.444542890,2275.0
25.477965427,2265.0
25.511387965,2279.0
25.544810502,2262.0
25.578233039,2234.0
25.611655576,2230.0
25.645078114,2297.0
25.678500651,2195.0
25.711923188,2189.0
25.745345725,2253.0
25.778768263,2315.0
25.812190800,2265.0
25.845613337,2206.0
25.879035874,2248.0
25.912458412,2312.0
25.945880949,2233.0
25.979303486,2319.0
26.012726023,2176.0
26.046148561,2226.0
26.079571098,2322.0
26.112993635,2200.0
26.146416172,2270.0
26.179838710,2268.0
26.213261247,2228.0
26.246683784,2320.0
26.280106321,2254.0
26.313528859,2271.0
26.346951396,2151.0
26.380373933,2259.0
26.413796470,2260.0
26.447219007,2294.0
26.480641545,2313.0
26.514064082,2306.0
26.547486619,2292.0
26.580909156,2219.0
26.614331694,2345.0
26.647754231,2287.0
26.681176768,2197.0
26.714599305,2398.0
26.748021843,2254.0
26.781444380,2339.0
26.814866917,2304.0
26.848289454,2374.0
26.881711992,2302.0
26.915134529,2361.0
26.948557066,2389.0
26.981979603,2410.0
27.015402141,2437.0
27.048824678,2385.0
27.082247215,2441.0
27.115669752,2462.0
27.149092290,2461.0
27.182514827,2559.0
27.215937364,2562.0
27.249359901,2588.0
27.282782439,2637.0
27.316204976,2554.0
27.349627513,2620.0
27.383050050,2455.0
27.416472588,2511.0
27.449895125,2526.0
27.483317662,2481.0
27.516740199,2596.0
27.550162737,2447.0
27.583585274,2473.0
27.617007811,2487.0
27.650430348,2319.0
27.683852886,2407.0
27.717275423,2305.0
27.750697960,2358.0
27.784120497,2369.0
27.817543035,2254.0
27.850965572,2270.0
27.884388109,2172.0
27.917810646,2244.0
27.951233183,2211.0
27.984655721,2238.0
28.018078258,2110.0
28.051500795,2163.0
28.084923332,2161.0
28.118345870,2063.0
28.151768407,2135.0
28.185190944,2095.0
28.218613481,2060.0
28.252036019,2080.0
28.285458556,2146.0
28.318881093,2072.0
28.352303630,2101.0
28.385726168,2124.0
28.419148705,2024.0
28.452571242,2091.0
28.485993779,2085.0
28.519416317,2039.0
28.552838854,2035.0
28.586261391,2051.0
28.619683928,2029.0
28.653106466,2064.0
28.686529003,1961.0
28.719951540,2092.0
28.753374077,2018.0
28.786796615,1996.0
28.820219152,2034.0
28.853641689,2038.0
28.887064226,2062.0
28.920486764,2050.0
28.953909301,2029.0
28.987331838,2003.0
29.020754375,1962.0
29.054176913,2025.0
29.087599450,2026.0
29.121021987,1976.0
29.154444524,1942.0
29.187867062,1933.0
29.221289599,1998.0
29.254712136,1905.0
29.288134673,1970.0
29.321557210,1996.0
29.354979748,2058.0
29.388402285,1889.0
29.421824822,1946.0
29.455247359,1917.0
29.488669897,1796.0
29.522092434,2005.0
29.555514971,1836.0
29.588937508,1952.0
29.622360046,1927.0
29.655782583,1947.0
29.689205120,1993.0
29.722627657,1955.0
29.756050195,1927.0
29.789472732,1885.0
29.822895269,1827.0
29.856317806,1870.0
29.889740344,1900.0
29.923162881,1980.0
29.956585418,1996.0
29.990007955,2032.0
30.023430493,1995.0
30.056853030,1921.0
30.090275567,1838.0
30.123698104,1847.0
30.157120642,1862.0
30.190543179,1880.0
30.223965716,1819.0
30.257388253,1935.0
30.290810791,1843.0
30.324233328,1950.0
30.357655865,1857.0
30.391078402,1910.0
30.424500940,1824.0
30.457923477,1849.0
30.491346014,1886.0
30.524768551,1918.0
30.558191089,1789.0
30.591613626,1839.0
30.625036163,1884.0
30.658458700,1877.0
30.691881238,1781.0
30.725303775,1897.0
30.758726312,1781.0
30.792148849,1920.0
30.825571386,1913.0
30.858993924,1795.0
30.892416461,1802.0
30.925838998,1910.0
30.959261535,1850.0
30.992684073,1803.0
31.026106610,1888.0
31.059529147,1832.0
31.092951684,1810.0
31.126374222,1798.0
31.159796759,1793.0
31.193219296,1805.0
31.226641833,1803.0
31.260064371,1812.0
31.293486908,1801.0
31.326909445,1787.0
31.360331982,1802.0
31.393754520,1824.0
31.427177057,1745.0
31.460599594,1754.0
31.494022131,1695.0
31.527444669,1759.0
31.560867206,1776.0
31.594289743,1848.0
31.627712280,1688.0
31.661134818,1741.0
31.694557355,1733.0
31.727979892,1671.0
31.761402429,1689.0
31.794824967,1603.0
31.828247504,1779.0
31.861670041,1788.0
31.895092578,1751.0
31.928515116,1647.0
31.961937653,1720.0
31.995360190,1722.0
32.028782727,1805.0
32.062205265,1739.0
32.095627802,1747.0
32.129050339,1735.0
32.162472876,1793.0
32.195895413,1837.0
32.229317951,1741.0
32.262740488,1758.0
32.296163025,1618.0
32.329585562,1701.0
32.363008100,1718.0
32.396430637,1841.0
32.429853174,1771.0
32.463275711,1753.0
32.496698249,1799.0
32.530120786,1760.0
32.563543323,1785.0
32.596965860,1759.0
32.630388398,1742.0
32.663810935,1697.0
32.697233472,1746.0
32.730656009,1745.0
32.764078547,1699.0
32.797501084,1698.0
32.830923621,1686.0
32.864346158,1680.0
32.897768696,1735.0
32.931191233,1649.0
32.964613770,1609.0
32.998036307,1678.0
33.031458845,1715.0
33.064881382,1751.0
33.098303919,1777.0
33.131726456,1636.0
33.165148994,1672.0
33.198571531,1687.0
33.231994068,1664.0
33.265416605,1717.0
33.298839143,1739.0
33.332261680,1700.0
33.365684217,1712.0
33.399106754,1615.0
33.432529292,1760.0
33.465951829,1703.0
33.499374366,1660.0
33.532796903,1584.0
33.566219441,1773.0
33.599641978,1645.0
33.633064515,1645.0
33.666487052,1579.0
33.699909589,1706.0
33.733332127,1651.0
33.766754664,1629.0
33.800177201,1663.0
33.833599738,1636.0
33.867022276,1659.0
33.900444813,1605.0
33.933867350,1582.0
33.967289887,1645.0
34.000712425,1627.0
34.034134962,1504.0
34.067557499,1643.0
34.100980036,1737.0
34.134402574,1639.0
34.167825111,1647.0
34.201247648,1580.0
34.234670185,1534.0
34.268092723,1627.0
34.301515260,1683.0
34.334937797,1627.0
34.368360334,1556.0
34.401782872,1638.0
34.435205409,1649.0
34.468627946,1668.0
34.502050483,1594.0
34.535473021,1657.0
34.568895558,1634.0
34.602318095,1636.0
34.635740632,1517.0
34.669163170,1566.0
34.702585707,1599.0
34.736008244,1608.0
34.769430781,1591.0
34.802853319,1611.0
34.836275856,1599.0
34.869698393,1611.0
34.903120930,1572.0
34.936543468,1502.0
34.969966005,1598.0
35.003388542,1554.0
35.036811079,1595.0
35.070233616,1683.0
35.103656154,1590.0
35.137078691,1637.0
35.170501228,1605.0
35.203923765,1631.0
35.237346303,1554.0
35.270768840,1528.0
35.304191377,1644.0
35.337613914,1565.0
35.371036452,1616.0
35.404458989,1532.0
35.437881526,1572.0
35.471304063,1607.0
35.504726601,1589.0
35.538149138,1595.0
35.571571675,1608.0
35.604994212,1664.0
35.638416750,1627.0
35.671839287,1697.0
35.705261824,1656.0
35.738684361,1702.0
35.772106899,1601.0
35.805529436,1727.0
35.838951973,1677.0
35.872374510,1709.0
35.905797048,1719.0
35.939219585,1748.0
35.972642122,1683.0
36.006064659,1737.0
36.039487197,1768.0
36.072909734,1853.0
36.106332271,1819.0
36.139754808,1757.0
36.173177346,1810.0
36.206599883,1881.0
36.240022420,1802.0
36.273444957,1910.0
36.306867495,1858.0
36.340290032,1892.0
36.373712569,2017.0
36.407135106,2097.0
36.440557643,2088.0
36.473980181,2205.0
36.507402718,2427.0
36.540825255,2515.0
36.574247792,2656.0
36.607670330,2977.0
36.641092867,3546.0
36.674515404,3823.0
36.707937941,4761.0
36.741360479,5139.0
36.774783016,6302.0
36.808205553,7373.0
36.841628090,8783.0
36.875050628,10330.0
36.908473165,11787.0
36.941895702,13119.0
36.975318239,14012.0
37.008740777,13986.0
37.042163314,13530.0
37.075585851,12255.0
37.109008388,11253.0
37.142430926,9791.0
37.175853463,8394.0
37.209276000,7235.0
37.242698537,5968.0
37.276121075,4930.0
37.309543612,4086.0
37.342966149,3380.0
37.376388686,3001.0
37.409811224,2561.0
37.443233761,2429.0
37.476656298,2113.0
37.510078835,1997.0
37.543501373,1942.0
37.576923910,1811.0
37.610346447,1826.0
37.643768984,1783.0
37.677191522,1705.0
37.710614059,1727.0
37.744036596,1656.0
37.777459133,1688.0
37.810881671,1628.0
37.844304208,1629.0
37.877726745,1508.0
37.911149282,1665.0
37.944571819,1566.0
37.977994357,1524.0
38.011416894,1595.0
38.044839431,1549.0
38.078261968,1424.0
38.111684506,1572.0
38.145107043,1475.0
38.178529580,1479.0
38.211952117,1516.0
38.245374655,1505.0
38.278797192,1464.0
38.312219729,1569.0
38.345642266,1530.0
38.379064804,1443.0
38.412487341,1492.0
38.445909878,1484.0
38.479332415,1532.0
38.512754953,1411.0
38.546177490,1497.0
38.579600027,1428.0
38.613022564,1562.0
38.646445102,1448.0
38.679867639,1465.0
38.713290176,1494.0
38.746712713,1535.0
38.780135251,1589.0
38.813557788,1505.0
38.846980325,1572.0
38.880402862,1588.0
38.913825400,1548.0
38.947247937,1586.0
38.980670474,1589.0
39.014093011,1587.0
39.047515549,1623.0
39.080938086,1721.0
39.114360623,1658.0
39.147783160,1711.0
39.181205698,1603.0
39.214628235,1694.0
39.248050772,1643.0
39.281473309,1668.0
39.314895846,1710.0
39.348318384,1722.0
39.381740921,1618.0
39.415163458,1603.0
39.448585995,1538.0
39.482008533,1594.0
39.515431070,1504.0
39.548853607,1506.0
39.582276144,1535.0
39.615698682,1527.0
39.649121219,1493.0
39.682543756,1587.0
39.715966293,1432.0
39.749388831,1470.0
39.782811368,1499.0
39.816233905,1566.0
39.849656442,1592.0
39.883078980,1544.0
39.916501517,1509.0
39.949924054,1481.0
39.983346591,1439.0
40.016769129,1373.0
40.050191666,1283.0
40.083614203,1289.0
40.117036740,1282.0
40.150459278,1371.0
40.183881815,1304.0
40.217304352,1346.0
40.250726889,1290.0
40.284149427,1278.0
40.317571964,1335.0
40.350994501,1351.0
40.384417038,1350.0
40.417839576,1307.0
40.451262113,1305.0
40.484684650,1219.0
40.518107187,1255.0
40.551529725,1293.0
40.584952262,1290.0
40.618374799,1342.0
40.651797336,1235.0
40.685219874,1318.0
40.718642411,1322.0
40.752064948,1305.0
40.785487485,1304.0
40.818910022,1366.0
40.852332560,1305.0
40.885755097,1283.0
40.919177634,1385.0
40.952600171,1284.0
40.986022709,1212.0
41.019445246,1230.0
41.052867783,1259.0
41.086290320,1298.0
41.119712858,1312.0
41.153135395,1313.0
41.186557932,1188.0
41.219980469,1366.0
41.253403007,1325.0
41.286825544,1252.0
41.320248081,1270.0
41.353670618,1301.0
41.387093156,1229.0
41.420515693,1271.0
41.453938230,1256.0
41.487360767,1193.0
41.520783305,1259.0
41.554205842,1267.0
41.587628379,1193.0
41.621050916,1254.0
41.654473454,1308.0
41.687895991,1237.0
41.721318528,1190.0
41.754741065,1233.0
41.788163603,1204.0
41.821586140,1200.0
41.855008677,1235.0
41.888431214,1329.0
41.921853752,1216.0
41.955276289,1223.0
41.988698826,1185.0
42.022121363,1211.0
42.055543901,1269.0
42.088966438,1253.0
42.122388975,1294.0
42.155811512,1206.0
42.189234049,1183.0
42.222656587,1210.0
42.256079124,1152.0
42.289501661,1234.0
42.322924198,1197.0
42.356346736,1177.0
42.389769273,1273.0
42.423191810,1275.0
42.456614347,1303.0
42.490036885,1347.0
42.523459422,1273.0
42.556881959,1193.0
42.590304496,1242.0
42.623727034,1246.0
42.657149571,1251.0
42.690572108,1236.0
42.723994645,1208.0
42.757417183,1211.0
42.790839720,1187.0
42.824262257,1218.0
42.857684794,1220.0
42.891107332,1219.0
42.924529869,1201.0
42.957952406,1204.0
42.991374943,1259.0
43.024797481,1258.0
43.058220018,1240.0
43.091642555,1236.0
43.125065092,1297.0
43.158487630,1345.0
43.191910167,1281.0
43.225332704,1316.0
43.258755241,1283.0
43.292177779,1249.0
43.325600316,1154.0
43.359022853,1262.0
43.392445390,1270.0
43.425867928,1235.0
43.459290465,1222.0
43.492713002,1174.0
43.526135539,1270.0
43.559558077,1242.0
43.592980614,1217.0
43.626403151,1245.0
43.659825688,1181.0
43.693248225,1213.0
43.726670763,1307.0
43.760093300,1245.0
43.793515837,1233.0
43.826938374,1178.0
43.860360912,1179.0
43.893783449,1176.0
43.927205986,1152.0
43.960628523,1185.0
43.994051061,1205.0
44.027473598,1241.0
44.060896135,1118.0
44.094318672,1170.0
44.127741210,1207.0
44.161163747,1169.0
44.194586284,1204.0
44.228008821,1151.0
44.261431359,1250.0
44.294853896,1181.0
44.328276433,1159.0
44.361698970,1210.0
44.395121508,1196.0
44.428544045,1254.0
44.461966582,1245.0
44.495389119,1322.0
44.528811657,1346.0
44.562234194,1342.0
44.595656731,1292.0
44.629079268,1254.0
44.662501806,1209.0
44.695924343,1292.0
44.729346880,1169.0
44.762769417,1145.0
44.796191955,1091.0
44.829614492,1192.0
44.863037029,1185.0
44.896459566,1098.0
44.929882104,1194.0
44.963304641,1125.0
44.996727178,1132.0
45.030149715,1176.0
45.063572252,1180.0
45.096994790,1176.0
45.130417327,1361.0
45.163839864,1325.0
45.197262401,1316.0
45.230684939,1248.0
45.264107476,1213.0
45.297530013,1204.0
45.330952550,1129.0
45.364375088,1129.0
45.397797625,1140.0
45.431220162,1158.0
45.464642699,1153.0
45.498065237,1158.0
45.531487774,1161.0
45.564910311,1081.0
45.598332848,1158.0
45.631755386,1130.0
45.665177923,1154.0
45.698600460,1113.0
45.732022997,1128.0
45.765445535,1141.0
45.798868072,1105.0
45.832290609,1079.0
45.865713146,1183.0
45.899135684,1154.0
45.932558221,1123.0
45.965980758,1141.0
45.999403295,1108.0
46.032825833,1109.0
46.066248370,1154.0
46.099670907,1075.0
46.133093444,1153.0
46.166515982,1145.0
46.199938519,1096.0
46.233361056,1100.0
46.266783593,1131.0
46.300206131,1187.0
46.333628668,1147.0
46.367051205,1181.0
46.400473742,1142.0
46.433896279,1209.0
46.467318817,1140.0
46.500741354,1133.0
46.534163891,1178.0
46.567586428,1141.0
46.601008966,1212.0
46.634431503,1035.0
46.667854040,1135.0
46.701276577,1161.0
46.734699115,1076.0
46.768121652,1060.0
46.801544189,1156.0
46.834966726,1105.0
46.868389264,1111.0
46.901811801,1095.0
46.935234338,1070.0
46.968656875,1114.0
47.002079413,1118.0
47.035501950,1113.0
47.068924487,1058.0
47.102347024,1094.0
47.135769562,1111.0
47.169192099,1113.0
47.202614636,1089.0
47.236037173,1085.0
47.269459711,1093.0
47.302882248,1111.0
47.336304785,1109.0
47.369727322,1101.0
47.403149860,1114.0
47.436572397,1082.0
47.469994934,1069.0
47.503417471,1039.0
47.536840009,1132.0
47.570262546,1059.0
47.603685083,1142.0
47.637107620,1055.0
47.670530158,1063.0
47.703952695,1095.0
47.737375232,998.0
47.770797769,1147.0
47.804220307,1103.0
47.837642844,1175.0
47.871065381,1116.0
47.904487918,1116.0
47.937910455,1068.0
47.971332993,1071.0
48.004755530,1072.0
48.038178067,1061.0
48.071600604,1114.0
48.105023142,1140.0
48.138445679,1075.0
48.171868216,1065.0
48.205290753,1094.0
48.238713291,1121.0
48.272135828,1060.0
48.305558365,1087.0
48.338980902,1097.0
48.372403440,1004.0
48.405825977,1014.0
48.439248514,1092.0
48.472671051,1036.0
48.506093589,1071.0
48.539516126,1136.0
48.572938663,984.0
48.606361200,1075.0
48.639783738,1068.0
48.673206275,1140.0
48.706628812,1093.0
48.740051349,1088.0
48.773473887,1077.0
48.806896424,1077.0
48.840318961,1101.0
48.873741498,1112.0
48.907164036,1085.0
48.940586573,1048.0
48.974009110,1100.0
49.007431647,1063.0
49.040854185,1094.0
49.074276722,1028.0
49.107699259,1046.0
49.141121796,1095.0
49.174544334,1019.0
49.207966871,1058.0
49.241389408,1069.0
49.274811945,1036.0
49.308234482,1087.0
49.341657020,1064.0
49.375079557,1007.0
49.408502094,1050.0
49.441924631,1121.0
49.475347169,1135.0
49.508769706,1162.0
49.542192243,1229.0
49.575614780,1368.0
49.609037318,1386.0
49.642459855,1285.0
49.675882392,1147.0
49.709304929,1203.0
49.742727467,1185.0
49.776150004,1145.0
49.809572541,1100.0
49.842995078,1040.0
49.876417616,1017.0
49.909840153,1035.0
49.943262690,1069.0
49.976685227,1098.0
50.010107765,1037.0
50.043530302,981.0
50.076952839,1115.0
50.110375376,1159.0
50.143797914,1061.0
50.177220451,1054.0
50.210642988,1145.0
50.244065525,1201.0
50.277488063,1177.0
50.310910600,1220.0
50.344333137,1105.0
50.377755674,1164.0
50.411178212,1189.0
50.444600749,1098.0
50.478023286,1186.0
50.511445823,1087.0
50.544868361,1029.0
50.578290898,1033.0
50.611713435,1006.0
50.645135972,1039.0
50.678558510,1065.0
50.711981047,1072.0
50.745403584,1016.0
50.778826121,1020.0
50.812248658,948.0
50.845671196,1029.0
50.879093733,1005.0
50.912516270,1013.0
50.945938807,1067.0
50.979361345,1071.0
51.012783882,1069.0
51.046206419,1082.0
51.079628956,1035.0
51.113051494,1081.0
51.146474031,1080.0
51.179896568,1015.0
51.213319105,1038.0
51.246741643,1106.0
51.280164180,1037.0
51.313586717,1071.0
51.347009254,1135.0
51.380431792,1085.0
51.413854329,1116.0
51.447276866,1090.0
51.480699403,1059.0
51.514121941,1070.0
51.547544478,1180.0
51.580967015,1095.0
51.614389552,1097.0
51.647812090,1075.0
51.681234627,1087.0
51.714657164,1092.0
51.748079701,1079.0
51.781502239,1079.0
51.814924776,1104.0
51.848347313,1009.0
51.881769850,1094.0
51.915192388,1079.0
51.948614925,1034.0
51.982037462,1022.0
52.015459999,1119.0
52.048882537,1001.0
52.082305074,1004.0
52.115727611,1112.0
52.149150148,1069.0
52.182572685,1021.0
52.215995223,1058.0
52.249417760,1031.0
52.282840297,1043.0
52.316262834,1125.0
52.349685372,1095.0
52.383107909,1101.0
52.416530446,1031.0
52.449952983,1036.0
52.483375521,1073.0
52.516798058,1066.0
52.550220595,1045.0
52.583643132,1014.0
52.617065670,980.0
52.650488207,1097.0
52.683910744,1059.0
52.717333281,1066.0
52.750755819,1040.0
52.784178356,1072.0
52.817600893,1044.0
52.851023430,1004.0
52.884445968,1006.0
52.917868505,1020.0
52.951291042,1037.0
52.984713579,1009.0
53.018136117,1051.0
53.051558654,997.0
53.084981191,1090.0
53.118403728,1051.0
53.151826266,1044.0
53.185248803,1082.0
53.218671340,1048.0
53.252093877,1065.0
53.285516415,1060.0
53.318938952,1139.0
53.352361489,1043.0
53.385784026,1092.0
53.419206564,1085.0
53.452629101,1029.0
53.486051638,1059.0
53.519474175,1105.0
53.552896713,1132.0
53.586319250,1065.0
53.619741787,1080.0
53.653164324,1041.0
53.686586861,1105.0
53.720009399,1055.0
53.753431936,1085.0
53.786854473,1096.0
53.820277010,1051.0
53.853699548,1116.0
53.887122085,1072.0
53.920544622,1085.0
53.953967159,1095.0
53.987389697,1108.0
54.020812234,1043.0
54.054234771,1129.0
54.087657308,1130.0
54.121079846,1063.0
54.154502383,1104.0
54.187924920,1113.0
54.221347457,1068.0
54.254769995,1123.0
54.288192532,1056.0
54.321615069,1176.0
54.355037606,1148.0
54.388460144,1106.0
54.421882681,1096.0
54.455305218,1079.0
54.488727755,1037.0
54.522150293,1063.0
54.555572830,1066.0
54.588995367,1117.0
54.622417904,1078.0
54.655840442,1029.0
54.689262979,1051.0
54.722685516,995.0
54.756108053,1089.0
54.789530591,1079.0
54.822953128,1089.0
54.856375665,1057.0
54.889798202,1005.0
54.923220740,990.0
54.956643277,1039.0
54.990065814,994.0
55.023488351,1034.0
55.056910888,1027.0
55.090333426,1041.0
55.123755963,1053.0
55.157178500,1029.0
55.190601037,1092.0
55.224023575,1006.0
55.257446112,1082.0
55.290868649,1046.0
55.324291186,1050.0
55.357713724,1025.0
55.391136261,1057.0
55.424558798,1124.0
55.457981335,1077.0
55.491403873,1039.0
55.524826410,1042.0
55.558248947,1107.0
55.591671484,1029.0
55.625094022,1036.0
55.658516559,1085.0
55.691939096,1064.0
55.725361633,1076.0
55.758784171,1061.0
55.792206708,1110.0
55.825629245,1101.0
55.859051782,1104.0
55.892474320,1079.0
55.925896857,1127.0
55.959319394,1146.0
55.992741931,1092.0
56.026164469,1134.0
56.059587006,1154.0
56.093009543,1155.0
56.126432080,1111.0
56.159854618,1192.0
56.193277155,1104.0
56.226699692,1183.0
56.260122229,1150.0
56.293544767,1126.0
56.326967304,1212.0
56.360389841,1217.0
56.393812378,1225.0
56.427234915,1214.0
56.460657453,1182.0
56.494079990,1147.0
56.527502527,1274.0
56.560925064,1234.0
56.594347602,1270.0
56.627770139,1280.0
56.661192676,1172.0
56.694615213,1293.0
56.728037751,1242.0
56.761460288,1300.0
56.794882825,1248.0
56.828305362,1214.0
56.861727900,1268.0
56.895150437,1428.0
56.928572974,1293.0
56.961995511,1285.0
56.995418049,1221.0
57.028840586,1203.0
57.062263123,1236.0
57.095685660,1180.0
57.129108198,1170.0
57.162530735,1184.0
57.195953272,1248.0
57.229375809,1178.0
57.262798347,1190.0
57.296220884,1163.0
57.329643421,1178.0
57.363065958,1108.0
57.396488496,1124.0
57.429911033,1139.0
57.463333570,1159.0
57.496756107,1190.0
57.530178645,1155.0
57.563601182,1133.0
57.597023719,1191.0
57.630446256,1092.0
57.663868794,1170.0
57.697291331,1099.0
57.730713868,1119.0
57.764136405,1108.0
57.797558943,1156.0
57.830981480,1133.0
57.864404017,1127.0
57.897826554,1064.0
57.931249091,1126.0
57.964671629,1198.0
57.998094166,1021.0
58.031516703,1110.0
58.064939240,1052.0
58.098361778,1177.0
58.131784315,1113.0
58.165206852,1062.0
58.198629389,1016.0
58.232051927,1193.0
58.265474464,1174.0
58.298897001,1118.0
58.332319538,1126.0
58.365742076,1129.0
58.399164613,1143.0
58.432587150,1158.0
58.466009687,1124.0
58.499432225,1188.0
58.532854762,1150.0
58.566277299,1174.0
58.599699836,1135.0
58.633122374,1161.0
58.666544911,1098.0
58.699967448,1144.0
58.733389985,1172.0
58.766812523,1135.0
58.800235060,1162.0
58.833657597,1150.0
58.867080134,1062.0
58.900502672,1147.0
58.933925209,1170.0
58.967347746,1090.0
59.000770283,1132.0
59.034192821,1200.0
59.067615358,1139.0
59.101037895,1129.0
59.134460432,1130.0
59.167882970,1185.0
59.201305507,1167.0
59.234728044,1235.0
59.268150581,1166.0
59.301573118,1168.0
59.334995656,1234.0
59.368418193,1127.0
59.401840730,1145.0
59.435263267,1206.0
59.468685805,1151.0
59.502108342,1151.0
59.535530879,1178.0
59.568953416,1197.0
59.602375954,1242.0
59.635798491,1183.0
59.669221028,1261.0
59.702643565,1282.0
59.736066103,1233.0
59.769488640,1254.0
59.802911177,1290.0
59.836333714,1258.0
59.869756252,1248.0
59.903178789,1232.0
59.936601326,1245.0
59.970023863,1248.0
60.003446401,1253.0
60.036868938,1211.0
60.070291475,1240.0
60.103714012,1222.0
60.137136550,1192.0
60.170559087,1383.0
60.203981624,1208.0
60.237404161,1263.0
60.270826699,1259.0
60.304249236,1293.0
60.337671773,1255.0
60.371094310,1263.0
60.404516848,1285.0
60.437939385,1329.0
60.471361922,1305.0
60.504784459,1353.0
60.538206997,1304.0
60.571629534,1358.0
60.605052071,1403.0
60.638474608,1339.0
60.671897146,1369.0
60.705319683,1318.0
60.738742220,1393.0
60.772164757,1388.0
60.805587294,1356.0
60.839009832,1377.0
60.872432369,1363.0
60.905854906,1383.0
60.939277443,1418.0
60.972699981,1442.0
61.006122518,1367.0
61.039545055,1454.0
61.072967592,1490.0
61.106390130,1477.0
61.139812667,1499.0
61.173235204,1509.0
61.206657741,1377.0
61.240080279,1509.0
61.273502816,1526.0
61.306925353,1590.0
61.340347890,1615.0
61.373770428,1707.0
61.407192965,1707.0
61.440615502,1657.0
61.474038039,1649.0
61.507460577,1667.0
61.540883114,1568.0
61.574305651,1615.0
61.607728188,1592.0
61.641150726,1590.0
61.674573263,1616.0
61.707995800,1620.0
61.741418337,1627.0
61.774840875,1554.0
61.808263412,1705.0
61.841685949,1696.0
61.875108486,1671.0
61.908531024,1675.0
61.941953561,1742.0
61.975376098,1643.0
62.008798635,1686.0
62.042221173,1713.0
62.075643710,1792.0
62.109066247,1666.0
62.142488784,1662.0
62.175911321,1680.0
62.209333859,1748.0
62.242756396,1625.0
62.276178933,1696.0
62.309601470,1660.0
62.343024008,1727.0
62.376446545,1710.0
62.409869082,1776.0
62.443291619,1748.0
62.476714157,1772.0
62.510136694,1699.0
62.543559231,1779.0
62.576981768,1802.0
62.610404306,1780.0
62.643826843,1735.0
62.677249380,1802.0
62.710671917,1798.0
62.744094455,1862.0
62.777516992,1795.0
62.810939529,1868.0
62.844362066,1833.0
62.877784604,1827.0
62.911207141,1836.0
62.944629678,1765.0
62.978052215,1951.0
63.011474753,1925.0
63.044897290,1875.0
63.078319827,1907.0
63.111742364,1901.0
63.145164902,1895.0
63.178587439,1912.0
63.212009976,1921.0
63.245432513,1861.0
63.278855051,1871.0
63.312277588,2022.0
63.345700125,1934.0
63.379122662,1995.0
63.412545200,1936.0
63.445967737,1888.0
63.479390274,1976.0
63.512812811,1995.0
63.546235349,1949.0
63.579657886,1933.0
63.613080423,2130.0
63.646502960,2032.0
63.679925497,2130.0
63.713348035,2092.0
63.746770572,2077.0
63.780193109,2052.0
63.813615646,2114.0
63.847038184,2149.0
63.880460721,2132.0
63.913883258,2102.0
63.947305795,2084.0
63.980728333,2117.0
64.014150870,2202.0
64.047573407,2171.0
64.080995944,2303.0
64.114418482,2130.0
64.147841019,2164.0
64.181263556,2306.0
64.214686093,2198.0
64.248108631,2342.0
64.281531168,2357.0
64.314953705,2340.0
64.348376242,2379.0
64.381798780,2293.0
64.415221317,2399.0
64.448643854,2347.0
64.482066391,2415.0
64.515488929,2492.0
64.548911466,2424.0
64.582334003,2475.0
64.615756540,2475.0
64.649179078,2522.0
64.682601615,2616.0
64.716024152,2558.0
64.749446689,2589.0
64.782869227,2649.0
64.816291764,2710.0
64.849714301,2791.0
64.883136838,2826.0
64.916559376,2760.0
64.949981913,2793.0
64.983404450,3004.0