File: OriginPro/XRD from Panalytical X'Pert PRO/XRD_Cu_NWs/A1_250C.csv
[Measurement conditions]
Sample identification,
Comment - 1,"Configuration=Flat Samole Stage, Owner=User-1, Creation date=26-10-2009 9:12:11"
Comment - 2,"Goniometer=PW3050/60 (Theta/Theta); Minimum step size 2Theta:0.001; Minimum step size Omega:0.001"
Comment - 3,"Sample stage=PW3071/xx Bracket"
Comment - 4,"Diffractometer system=XPERT-PRO"
Comment - 5,"Measurement program=lixo, Owner=AnaP, Creation date=26-07-2013 11:02:14"
Comment - 6,"Fine Calibration Offset for 2Theta = 0.021 deg"
Anode material,Cu
K-Alpha1 wavelength,1.5405980
K-Alpha2 wavelength,1.5444260
Ratio K-Alpha2/K-Alpha1,0.500
Divergence slit,Fixed,0.76mm
Monochromator used,NO
Generator voltage, 45
Tube current, 40
File date and time,29-Jun-2017 13:02
Unit cell,
h k l, 0 0 0
Scan axis,Gonio
Scan range,25.012999996,69.999736084
Scan step size,0.0167113
No. of points, 2692
Scan type,CONTINUOUS
Time per step,29.845
[Scan points]
Angle,Intensity
25.021355630,2493.0
25.054778168,2430.0
25.088200706,2440.0
25.121623244,2354.0
25.155045782,2444.0
25.188468320,2294.0
25.221890858,2363.0
25.255313396,2383.0
25.288735934,2332.0
25.322158472,2425.0
25.355581010,2254.0
25.389003548,2331.0
25.422426085,2248.0
25.455848623,2200.0
25.489271161,2316.0
25.522693699,2273.0
25.556116237,2309.0
25.589538775,2185.0
25.622961313,2271.0
25.656383851,2304.0
25.689806389,2195.0
25.723228927,2157.0
25.756651465,2249.0
25.790074003,2190.0
25.823496541,2206.0
25.856919079,2227.0
25.890341617,2180.0
25.923764155,2147.0
25.957186693,2193.0
25.990609231,2205.0
26.024031769,2205.0
26.057454307,2097.0
26.090876845,2167.0
26.124299383,2097.0
26.157721921,2144.0
26.191144458,2043.0
26.224566996,2114.0
26.257989534,2126.0
26.291412072,2020.0
26.324834610,2074.0
26.358257148,2048.0
26.391679686,2064.0
26.425102224,2031.0
26.458524762,2023.0
26.491947300,2027.0
26.525369838,2066.0
26.558792376,2124.0
26.592214914,2008.0
26.625637452,1909.0
26.659059990,1950.0
26.692482528,1940.0
26.725905066,1971.0
26.759327604,1989.0
26.792750142,2009.0
26.826172680,1901.0
26.859595218,1998.0
26.893017756,1967.0
26.926440294,1915.0
26.959862831,1904.0
26.993285369,1960.0
27.026707907,1908.0
27.060130445,1926.0
27.093552983,1957.0
27.126975521,1899.0
27.160398059,1945.0
27.193820597,1851.0
27.227243135,1834.0
27.260665673,1870.0
27.294088211,1953.0
27.327510749,1898.0
27.360933287,1767.0
27.394355825,1865.0
27.427778363,1911.0
27.461200901,1817.0
27.494623439,1843.0
27.528045977,1804.0
27.561468515,1817.0
27.594891053,1858.0
27.628313591,1793.0
27.661736129,1794.0
27.695158666,1822.0
27.728581204,1836.0
27.762003742,1755.0
27.795426280,1738.0
27.828848818,1787.0
27.862271356,1771.0
27.895693894,1861.0
27.929116432,1722.0
27.962538970,1754.0
27.995961508,1795.0
28.029384046,1731.0
28.062806584,1812.0
28.096229122,1788.0
28.129651660,1769.0
28.163074198,1795.0
28.196496736,1802.0
28.229919274,1715.0
28.263341812,1759.0
28.296764350,1732.0
28.330186888,1753.0
28.363609426,1701.0
28.397031964,1752.0
28.430454502,1631.0
28.463877039,1737.0
28.497299577,1652.0
28.530722115,1725.0
28.564144653,1655.0
28.597567191,1775.0
28.630989729,1702.0
28.664412267,1663.0
28.697834805,1721.0
28.731257343,1697.0
28.764679881,1636.0
28.798102419,1729.0
28.831524957,1678.0
28.864947495,1639.0
28.898370033,1723.0
28.931792571,1673.0
28.965215109,1604.0
28.998637647,1692.0
29.032060185,1520.0
29.065482723,1576.0
29.098905261,1580.0
29.132327799,1684.0
29.165750337,1588.0
29.199172875,1605.0
29.232595412,1581.0
29.266017950,1576.0
29.299440488,1631.0
29.332863026,1627.0
29.366285564,1638.0
29.399708102,1587.0
29.433130640,1676.0
29.466553178,1625.0
29.499975716,1699.0
29.533398254,1622.0
29.566820792,1616.0
29.600243330,1566.0
29.633665868,1613.0
29.667088406,1560.0
29.700510944,1652.0
29.733933482,1607.0
29.767356020,1595.0
29.800778558,1601.0
29.834201096,1512.0
29.867623634,1540.0
29.901046172,1530.0
29.934468710,1579.0
29.967891248,1562.0
30.001313785,1589.0
30.034736323,1539.0
30.068158861,1554.0
30.101581399,1528.0
30.135003937,1449.0
30.168426475,1471.0
30.201849013,1483.0
30.235271551,1503.0
30.268694089,1488.0
30.302116627,1524.0
30.335539165,1515.0
30.368961703,1392.0
30.402384241,1511.0
30.435806779,1532.0
30.469229317,1508.0
30.502651855,1484.0
30.536074393,1519.0
30.569496931,1542.0
30.602919469,1444.0
30.636342007,1487.0
30.669764545,1535.0
30.703187083,1378.0
30.736609621,1425.0
30.770032158,1474.0
30.803454696,1442.0
30.836877234,1522.0
30.870299772,1416.0
30.903722310,1434.0
30.937144848,1505.0
30.970567386,1392.0
31.003989924,1447.0
31.037412462,1402.0
31.070835000,1385.0
31.104257538,1470.0
31.137680076,1466.0
31.171102614,1404.0
31.204525152,1475.0
31.237947690,1456.0
31.271370228,1486.0
31.304792766,1432.0
31.338215304,1462.0
31.371637842,1357.0
31.405060380,1445.0
31.438482918,1431.0
31.471905456,1364.0
31.505327993,1408.0
31.538750531,1416.0
31.572173069,1373.0
31.605595607,1428.0
31.639018145,1371.0
31.672440683,1344.0
31.705863221,1402.0
31.739285759,1354.0
31.772708297,1454.0
31.806130835,1330.0
31.839553373,1378.0
31.872975911,1385.0
31.906398449,1318.0
31.939820987,1397.0
31.973243525,1396.0
32.006666063,1341.0
32.040088601,1338.0
32.073511139,1346.0
32.106933677,1401.0
32.140356215,1383.0
32.173778753,1360.0
32.207201291,1355.0
32.240623829,1365.0
32.274046366,1383.0
32.307468904,1354.0
32.340891442,1376.0
32.374313980,1393.0
32.407736518,1400.0
32.441159056,1250.0
32.474581594,1386.0
32.508004132,1348.0
32.541426670,1346.0
32.574849208,1354.0
32.608271746,1333.0
32.641694284,1341.0
32.675116822,1374.0
32.708539360,1327.0
32.741961898,1352.0
32.775384436,1340.0
32.808806974,1360.0
32.842229512,1283.0
32.875652050,1326.0
32.909074588,1348.0
32.942497126,1363.0
32.975919664,1269.0
33.009342202,1334.0
33.042764739,1298.0
33.076187277,1324.0
33.109609815,1294.0
33.143032353,1357.0
33.176454891,1291.0
33.209877429,1262.0
33.243299967,1345.0
33.276722505,1354.0
33.310145043,1263.0
33.343567581,1323.0
33.376990119,1330.0
33.410412657,1251.0
33.443835195,1347.0
33.477257733,1254.0
33.510680271,1298.0
33.544102809,1227.0
33.577525347,1251.0
33.610947885,1274.0
33.644370423,1256.0
33.677792961,1285.0
33.711215499,1276.0
33.744638037,1267.0
33.778060575,1258.0
33.811483112,1277.0
33.844905650,1314.0
33.878328188,1255.0
33.911750726,1275.0
33.945173264,1241.0
33.978595802,1249.0
34.012018340,1265.0
34.045440878,1290.0
34.078863416,1274.0
34.112285954,1243.0
34.145708492,1243.0
34.179131030,1244.0
34.212553568,1284.0
34.245976106,1275.0
34.279398644,1277.0
34.312821182,1328.0
34.346243720,1211.0
34.379666258,1211.0
34.413088796,1252.0
34.446511334,1270.0
34.479933872,1305.0
34.513356410,1304.0
34.546778948,1293.0
34.580201485,1332.0
34.613624023,1328.0
34.647046561,1303.0
34.680469099,1279.0
34.713891637,1293.0
34.747314175,1265.0
34.780736713,1354.0
34.814159251,1286.0
34.847581789,1340.0
34.881004327,1270.0
34.914426865,1318.0
34.947849403,1350.0
34.981271941,1325.0
35.014694479,1339.0
35.048117017,1389.0
35.081539555,1391.0
35.114962093,1355.0
35.148384631,1429.0
35.181807169,1422.0
35.215229707,1376.0
35.248652245,1350.0
35.282074783,1400.0
35.315497320,1333.0
35.348919858,1369.0
35.382342396,1344.0
35.415764934,1470.0
35.449187472,1427.0
35.482610010,1459.0
35.516032548,1459.0
35.549455086,1424.0
35.582877624,1443.0
35.616300162,1483.0
35.649722700,1450.0
35.683145238,1532.0
35.716567776,1422.0
35.749990314,1447.0
35.783412852,1492.0
35.816835390,1599.0
35.850257928,1572.0
35.883680466,1585.0
35.917103004,1644.0
35.950525542,1624.0
35.983948080,1573.0
36.017370618,1651.0
36.050793156,1721.0
36.084215693,1798.0
36.117638231,1732.0
36.151060769,1843.0
36.184483307,1787.0
36.217905845,1899.0
36.251328383,1919.0
36.284750921,2025.0
36.318173459,2154.0
36.351595997,2123.0
36.385018535,2133.0
36.418441073,2186.0
36.451863611,2226.0
36.485286149,2216.0
36.518708687,2325.0
36.552131225,2301.0
36.585553763,2174.0
36.618976301,2242.0
36.652398839,2176.0
36.685821377,2108.0
36.719243915,2072.0
36.752666453,2037.0
36.786088991,1955.0
36.819511529,1854.0
36.852934066,1793.0
36.886356604,1785.0
36.919779142,1788.0
36.953201680,1668.0
36.986624218,1653.0
37.020046756,1629.0
37.053469294,1604.0
37.086891832,1483.0
37.120314370,1488.0
37.153736908,1414.0
37.187159446,1418.0
37.220581984,1328.0
37.254004522,1336.0
37.287427060,1303.0
37.320849598,1332.0
37.354272136,1326.0
37.387694674,1342.0
37.421117212,1282.0
37.454539750,1326.0
37.487962288,1226.0
37.521384826,1221.0
37.554807364,1257.0
37.588229902,1280.0
37.621652439,1240.0
37.655074977,1202.0
37.688497515,1178.0
37.721920053,1228.0
37.755342591,1209.0
37.788765129,1237.0
37.822187667,1194.0
37.855610205,1166.0
37.889032743,1214.0
37.922455281,1156.0
37.955877819,1209.0
37.989300357,1165.0
38.022722895,1197.0
38.056145433,1179.0
38.089567971,1203.0
38.122990509,1137.0
38.156413047,1151.0
38.189835585,1208.0
38.223258123,1157.0
38.256680661,1136.0
38.290103199,1134.0
38.323525737,1100.0
38.356948275,1089.0
38.390370812,1177.0
38.423793350,1180.0
38.457215888,1124.0
38.490638426,1158.0
38.524060964,1116.0
38.557483502,1112.0
38.590906040,1188.0
38.624328578,1132.0
38.657751116,1100.0
38.691173654,1138.0
38.724596192,1069.0
38.758018730,1125.0
38.791441268,1063.0
38.824863806,1112.0
38.858286344,1137.0
38.891708882,1134.0
38.925131420,1100.0
38.958553958,1047.0
38.991976496,1054.0
39.025399034,1101.0
39.058821572,1101.0
39.092244110,1147.0
39.125666647,1100.0
39.159089185,1056.0
39.192511723,1072.0
39.225934261,1083.0
39.259356799,1070.0
39.292779337,1053.0
39.326201875,1062.0
39.359624413,1054.0
39.393046951,1101.0
39.426469489,1058.0
39.459892027,1098.0
39.493314565,1045.0
39.526737103,1017.0
39.560159641,999.0
39.593582179,1025.0
39.627004717,1058.0
39.660427255,1035.0
39.693849793,1061.0
39.727272331,1000.0
39.760694869,979.0
39.794117407,1042.0
39.827539945,990.0
39.860962483,960.0
39.894385020,1007.0
39.927807558,992.0
39.961230096,1036.0
39.994652634,1004.0
40.028075172,998.0
40.061497710,998.0
40.094920248,982.0
40.128342786,967.0
40.161765324,1008.0
40.195187862,1000.0
40.228610400,1039.0
40.262032938,1015.0
40.295455476,1025.0
40.328878014,987.0
40.362300552,1015.0
40.395723090,961.0
40.429145628,1018.0
40.462568166,973.0
40.495990704,926.0
40.529413242,1002.0
40.562835780,961.0
40.596258318,971.0
40.629680856,966.0
40.663103393,976.0
40.696525931,965.0
40.729948469,1025.0
40.763371007,1013.0
40.796793545,931.0
40.830216083,990.0
40.863638621,1047.0
40.897061159,910.0
40.930483697,947.0
40.963906235,1025.0
40.997328773,943.0
41.030751311,980.0
41.064173849,989.0
41.097596387,918.0
41.131018925,997.0
41.164441463,1000.0
41.197864001,947.0
41.231286539,994.0
41.264709077,1036.0
41.298131615,1004.0
41.331554153,939.0
41.364976691,1028.0
41.398399229,973.0
41.431821766,1032.0
41.465244304,1029.0
41.498666842,1020.0
41.532089380,1016.0
41.565511918,1049.0
41.598934456,1087.0
41.632356994,1069.0
41.665779532,1031.0
41.699202070,1078.0
41.732624608,1062.0
41.766047146,1133.0
41.799469684,1064.0
41.832892222,1049.0
41.866314760,1065.0
41.899737298,1086.0
41.933159836,1078.0
41.966582374,1049.0
42.000004912,1155.0
42.033427450,1131.0
42.066849988,1142.0
42.100272526,1143.0
42.133695064,1103.0
42.167117602,1164.0
42.200540139,1156.0
42.233962677,1113.0
42.267385215,1186.0
42.300807753,1150.0
42.334230291,1145.0
42.367652829,1082.0
42.401075367,1201.0
42.434497905,1137.0
42.467920443,1155.0
42.501342981,1134.0
42.534765519,1112.0
42.568188057,1148.0
42.601610595,1170.0
42.635033133,1180.0
42.668455671,1117.0
42.701878209,1111.0
42.735300747,1201.0
42.768723285,1114.0
42.802145823,1164.0
42.835568361,1071.0
42.868990899,1182.0
42.902413437,1111.0
42.935835974,1108.0
42.969258512,1074.0
43.002681050,1133.0
43.036103588,1117.0
43.069526126,1118.0
43.102948664,1175.0
43.136371202,1211.0
43.169793740,1359.0
43.203216278,1417.0
43.236638816,1598.0
43.270061354,1804.0
43.303483892,2360.0
43.336906430,3329.0
43.370328968,4711.0
43.403751506,4934.0
43.437174044,4224.0
43.470596582,3719.0
43.504019120,3471.0
43.537441658,2841.0
43.570864196,2059.0
43.604286734,1681.0
43.637709272,1368.0
43.671131810,1306.0
43.704554347,1174.0
43.737976885,1086.0
43.771399423,1112.0
43.804821961,1126.0
43.838244499,1042.0
43.871667037,1069.0
43.905089575,1018.0
43.938512113,952.0
43.971934651,1019.0
44.005357189,1039.0
44.038779727,988.0
44.072202265,965.0
44.105624803,999.0
44.139047341,976.0
44.172469879,937.0
44.205892417,975.0
44.239314955,986.0
44.272737493,997.0
44.306160031,900.0
44.339582569,1022.0
44.373005107,928.0
44.406427645,960.0
44.439850183,1011.0
44.473272720,1008.0
44.506695258,910.0
44.540117796,890.0
44.573540334,949.0
44.606962872,888.0
44.640385410,963.0
44.673807948,887.0
44.707230486,959.0
44.740653024,975.0
44.774075562,965.0
44.807498100,902.0
44.840920638,904.0
44.874343176,970.0
44.907765714,908.0
44.941188252,907.0
44.974610790,907.0
45.008033328,964.0
45.041455866,902.0
45.074878404,926.0
45.108300942,921.0
45.141723480,918.0
45.175146018,861.0
45.208568556,919.0
45.241991093,953.0
45.275413631,893.0
45.308836169,984.0
45.342258707,934.0
45.375681245,931.0
45.409103783,906.0
45.442526321,961.0
45.475948859,896.0
45.509371397,903.0
45.542793935,897.0
45.576216473,961.0
45.609639011,924.0
45.643061549,904.0
45.676484087,930.0
45.709906625,934.0
45.743329163,932.0
45.776751701,900.0
45.810174239,881.0
45.843596777,887.0
45.877019315,931.0
45.910441853,910.0
45.943864391,938.0
45.977286929,869.0
46.010709466,863.0
46.044132004,904.0
46.077554542,935.0
46.110977080,855.0
46.144399618,922.0
46.177822156,920.0
46.211244694,916.0
46.244667232,928.0
46.278089770,888.0
46.311512308,870.0
46.344934846,873.0
46.378357384,926.0
46.411779922,854.0
46.445202460,900.0
46.478624998,904.0
46.512047536,906.0
46.545470074,873.0
46.578892612,900.0
46.612315150,914.0
46.645737688,934.0
46.679160226,887.0
46.712582764,920.0
46.746005301,862.0
46.779427839,890.0
46.812850377,916.0
46.846272915,933.0
46.879695453,925.0
46.913117991,898.0
46.946540529,867.0
46.979963067,940.0
47.013385605,926.0
47.046808143,916.0
47.080230681,834.0
47.113653219,928.0
47.147075757,957.0
47.180498295,850.0
47.213920833,922.0
47.247343371,861.0
47.280765909,929.0
47.314188447,880.0
47.347610985,869.0
47.381033523,903.0
47.414456061,888.0
47.447878599,912.0
47.481301137,887.0
47.514723674,864.0
47.548146212,874.0
47.581568750,828.0
47.614991288,898.0
47.648413826,921.0
47.681836364,861.0
47.715258902,860.0
47.748681440,897.0
47.782103978,879.0
47.815526516,885.0
47.848949054,884.0
47.882371592,928.0
47.915794130,929.0
47.949216668,920.0
47.982639206,852.0
48.016061744,917.0
48.049484282,879.0
48.082906820,910.0
48.116329358,898.0
48.149751896,902.0
48.183174434,890.0
48.216596972,910.0
48.250019510,896.0
48.283442047,862.0
48.316864585,912.0
48.350287123,846.0
48.383709661,900.0
48.417132199,881.0
48.450554737,880.0
48.483977275,865.0
48.517399813,860.0
48.550822351,859.0
48.584244889,882.0
48.617667427,904.0
48.651089965,885.0
48.684512503,877.0
48.717935041,853.0
48.751357579,871.0
48.784780117,875.0
48.818202655,880.0
48.851625193,887.0
48.885047731,905.0
48.918470269,857.0
48.951892807,915.0
48.985315345,922.0
49.018737883,851.0
49.052160420,894.0
49.085582958,877.0
49.119005496,861.0
49.152428034,879.0
49.185850572,902.0
49.219273110,849.0
49.252695648,908.0
49.286118186,904.0
49.319540724,884.0
49.352963262,864.0
49.386385800,880.0
49.419808338,859.0
49.453230876,881.0
49.486653414,833.0
49.520075952,903.0
49.553498490,908.0
49.586921028,911.0
49.620343566,917.0
49.653766104,896.0
49.687188642,884.0
49.720611180,884.0
49.754033718,852.0
49.787456256,909.0
49.820878793,922.0
49.854301331,920.0
49.887723869,859.0
49.921146407,903.0
49.954568945,867.0
49.987991483,861.0
50.021414021,873.0
50.054836559,891.0
50.088259097,883.0
50.121681635,881.0
50.155104173,903.0
50.188526711,896.0
50.221949249,951.0
50.255371787,966.0
50.288794325,1003.0
50.322216863,1007.0
50.355639401,1146.0
50.389061939,1233.0
50.422484477,1307.0
50.455907015,1402.0
50.489329553,1529.0
50.522752091,1697.0
50.556174628,1713.0
50.589597166,1767.0
50.623019704,1721.0
50.656442242,1602.0
50.689864780,1512.0
50.723287318,1438.0
50.756709856,1341.0
50.790132394,1164.0
50.823554932,1155.0
50.856977470,1057.0
50.890400008,1025.0
50.923822546,1077.0
50.957245084,942.0
50.990667622,944.0
51.024090160,892.0
51.057512698,852.0
51.090935236,938.0
51.124357774,824.0
51.157780312,853.0
51.191202850,829.0
51.224625388,880.0
51.258047926,930.0
51.291470464,861.0
51.324893001,866.0
51.358315539,833.0
51.391738077,928.0
51.425160615,790.0
51.458583153,824.0
51.492005691,890.0
51.525428229,888.0
51.558850767,793.0
51.592273305,834.0
51.625695843,862.0
51.659118381,835.0
51.692540919,887.0
51.725963457,839.0
51.759385995,819.0
51.792808533,832.0
51.826231071,874.0
51.859653609,792.0
51.893076147,802.0
51.926498685,841.0
51.959921223,799.0
51.993343761,834.0
52.026766299,848.0
52.060188837,878.0
52.093611374,813.0
52.127033912,852.0
52.160456450,846.0
52.193878988,836.0
52.227301526,833.0
52.260724064,825.0
52.294146602,808.0
52.327569140,850.0
52.360991678,914.0
52.394414216,874.0
52.427836754,843.0
52.461259292,824.0
52.494681830,774.0
52.528104368,762.0
52.561526906,823.0
52.594949444,828.0
52.628371982,813.0
52.661794520,792.0
52.695217058,842.0
52.728639596,824.0
52.762062134,821.0
52.795484672,823.0
52.828907210,812.0
52.862329747,852.0
52.895752285,831.0
52.929174823,813.0
52.962597361,863.0
52.996019899,861.0
53.029442437,874.0
53.062864975,870.0
53.096287513,876.0
53.129710051,848.0
53.163132589,823.0
53.196555127,837.0
53.229977665,822.0
53.263400203,823.0
53.296822741,853.0
53.330245279,831.0
53.363667817,850.0
53.397090355,829.0
53.430512893,893.0
53.463935431,810.0
53.497357969,838.0
53.530780507,874.0
53.564203045,808.0
53.597625583,811.0
53.631048120,827.0
53.664470658,853.0
53.697893196,855.0
53.731315734,835.0
53.764738272,802.0
53.798160810,802.0
53.831583348,778.0
53.865005886,743.0
53.898428424,802.0
53.931850962,829.0
53.965273500,780.0
53.998696038,823.0
54.032118576,811.0
54.065541114,810.0
54.098963652,814.0
54.132386190,824.0
54.165808728,836.0
54.199231266,828.0
54.232653804,848.0
54.266076342,782.0
54.299498880,773.0
54.332921418,837.0
54.366343955,794.0
54.399766493,837.0
54.433189031,891.0
54.466611569,815.0
54.500034107,797.0
54.533456645,788.0
54.566879183,820.0
54.600301721,817.0
54.633724259,825.0
54.667146797,833.0
54.700569335,842.0
54.733991873,853.0
54.767414411,784.0
54.800836949,814.0
54.834259487,815.0
54.867682025,831.0
54.901104563,852.0
54.934527101,821.0
54.967949639,807.0
55.001372177,817.0
55.034794715,827.0
55.068217253,828.0
55.101639791,796.0
55.135062328,759.0
55.168484866,881.0
55.201907404,741.0
55.235329942,774.0
55.268752480,839.0
55.302175018,779.0
55.335597556,836.0
55.369020094,815.0
55.402442632,780.0
55.435865170,809.0
55.469287708,838.0
55.502710246,815.0
55.536132784,794.0
55.569555322,787.0
55.602977860,870.0
55.636400398,802.0
55.669822936,771.0
55.703245474,817.0
55.736668012,801.0
55.770090550,799.0
55.803513088,798.0
55.836935626,806.0
55.870358164,846.0
55.903780701,792.0
55.937203239,843.0
55.970625777,795.0
56.004048315,805.0
56.037470853,842.0
56.070893391,835.0
56.104315929,794.0
56.137738467,875.0
56.171161005,797.0
56.204583543,817.0
56.238006081,786.0
56.271428619,806.0
56.304851157,876.0
56.338273695,848.0
56.371696233,776.0
56.405118771,815.0
56.438541309,826.0
56.471963847,884.0
56.505386385,801.0
56.538808923,834.0
56.572231461,766.0
56.605653999,811.0
56.639076537,836.0
56.672499074,787.0
56.705921612,843.0
56.739344150,786.0
56.772766688,784.0
56.806189226,821.0
56.839611764,776.0
56.873034302,793.0
56.906456840,820.0
56.939879378,777.0
56.973301916,836.0
57.006724454,806.0
57.040146992,795.0
57.073569530,790.0
57.106992068,827.0
57.140414606,813.0
57.173837144,842.0
57.207259682,815.0
57.240682220,792.0
57.274104758,820.0
57.307527296,765.0
57.340949834,812.0
57.374372372,735.0
57.407794910,827.0
57.441217447,840.0
57.474639985,836.0
57.508062523,799.0
57.541485061,764.0
57.574907599,780.0
57.608330137,790.0
57.641752675,798.0
57.675175213,782.0
57.708597751,776.0
57.742020289,783.0
57.775442827,831.0
57.808865365,839.0
57.842287903,762.0
57.875710441,814.0
57.909132979,804.0
57.942555517,774.0
57.975978055,861.0
58.009400593,746.0
58.042823131,809.0
58.076245669,755.0
58.109668207,867.0
58.143090745,826.0
58.176513283,820.0
58.209935820,792.0
58.243358358,821.0
58.276780896,791.0
58.310203434,851.0
58.343625972,771.0
58.377048510,822.0
58.410471048,793.0
58.443893586,828.0
58.477316124,770.0
58.510738662,868.0
58.544161200,857.0
58.577583738,814.0
58.611006276,839.0
58.644428814,817.0
58.677851352,807.0
58.711273890,784.0
58.744696428,851.0
58.778118966,819.0
58.811541504,856.0
58.844964042,841.0
58.878386580,838.0
58.911809118,881.0
58.945231655,806.0
58.978654193,780.0
59.012076731,818.0
59.045499269,773.0
59.078921807,831.0
59.112344345,798.0
59.145766883,774.0
59.179189421,855.0
59.212611959,818.0
59.246034497,809.0
59.279457035,825.0
59.312879573,902.0
59.346302111,822.0
59.379724649,819.0
59.413147187,873.0
59.446569725,778.0
59.479992263,834.0
59.513414801,828.0
59.546837339,848.0
59.580259877,895.0
59.613682415,852.0
59.647104953,823.0
59.680527491,828.0
59.713950028,838.0
59.747372566,773.0
59.780795104,817.0
59.814217642,863.0
59.847640180,854.0
59.881062718,764.0
59.914485256,826.0
59.947907794,818.0
59.981330332,824.0
60.014752870,824.0
60.048175408,819.0
60.081597946,852.0
60.115020484,859.0
60.148443022,866.0
60.181865560,831.0
60.215288098,894.0
60.248710636,836.0
60.282133174,805.0
60.315555712,901.0
60.348978250,873.0
60.382400788,871.0
60.415823326,853.0
60.449245864,865.0
60.482668401,918.0
60.516090939,888.0
60.549513477,853.0
60.582936015,880.0
60.616358553,841.0
60.649781091,879.0
60.683203629,874.0
60.716626167,821.0
60.750048705,825.0
60.783471243,880.0
60.816893781,897.0
60.850316319,946.0
60.883738857,965.0
60.917161395,871.0
60.950583933,832.0
60.984006471,924.0
61.017429009,939.0
61.050851547,946.0
61.084274085,923.0
61.117696623,895.0
61.151119161,907.0
61.184541699,892.0
61.217964237,908.0
61.251386774,971.0
61.284809312,944.0
61.318231850,981.0
61.351654388,907.0
61.385076926,1019.0
61.418499464,920.0
61.451922002,964.0
61.485344540,965.0
61.518767078,1007.0
61.552189616,1014.0
61.585612154,966.0
61.619034692,957.0
61.652457230,896.0
61.685879768,951.0
61.719302306,875.0
61.752724844,934.0
61.786147382,908.0
61.819569920,932.0
61.852992458,934.0
61.886414996,959.0
61.919837534,904.0
61.953260072,889.0
61.986682610,935.0
62.020105147,917.0
62.053527685,950.0
62.086950223,908.0
62.120372761,916.0
62.153795299,889.0
62.187217837,869.0
62.220640375,919.0
62.254062913,897.0
62.287485451,877.0
62.320907989,910.0
62.354330527,945.0
62.387753065,868.0
62.421175603,857.0
62.454598141,857.0
62.488020679,883.0
62.521443217,841.0
62.554865755,838.0
62.588288293,868.0
62.621710831,883.0
62.655133369,819.0
62.688555907,864.0
62.721978445,827.0
62.755400982,790.0
62.788823520,843.0
62.822246058,795.0
62.855668596,870.0
62.889091134,862.0
62.922513672,796.0
62.955936210,836.0
62.989358748,845.0
63.022781286,831.0
63.056203824,812.0
63.089626362,829.0
63.123048900,864.0
63.156471438,790.0
63.189893976,843.0
63.223316514,891.0
63.256739052,849.0
63.290161590,853.0
63.323584128,836.0
63.357006666,792.0
63.390429204,831.0
63.423851742,834.0
63.457274280,812.0
63.490696818,810.0
63.524119355,874.0
63.557541893,788.0
63.590964431,819.0
63.624386969,836.0
63.657809507,782.0
63.691232045,856.0
63.724654583,778.0
63.758077121,878.0
63.791499659,851.0
63.824922197,843.0
63.858344735,742.0
63.891767273,840.0
63.925189811,883.0
63.958612349,812.0
63.992034887,797.0
64.025457425,818.0
64.058879963,800.0
64.092302501,857.0
64.125725039,810.0
64.159147577,793.0
64.192570115,824.0
64.225992653,813.0
64.259415191,834.0
64.292837728,779.0
64.326260266,827.0
64.359682804,810.0
64.393105342,802.0
64.426527880,822.0
64.459950418,773.0
64.493372956,838.0
64.526795494,864.0
64.560218032,826.0
64.593640570,785.0
64.627063108,812.0
64.660485646,793.0
64.693908184,797.0
64.727330722,848.0
64.760753260,791.0
64.794175798,853.0
64.827598336,809.0
64.861020874,774.0
64.894443412,862.0
64.927865950,787.0
64.961288488,849.0
64.994711026,807.0
65.028133564,835.0
65.061556101,748.0
65.094978639,832.0
65.128401177,777.0
65.161823715,823.0
65.195246253,859.0
65.228668791,794.0
65.262091329,795.0
65.295513867,797.0
65.328936405,837.0
65.362358943,856.0
65.395781481,814.0
65.429204019,856.0
65.462626557,850.0
65.496049095,824.0
65.529471633,804.0
65.562894171,794.0
65.596316709,787.0
65.629739247,797.0
65.663161785,767.0
65.696584323,855.0
65.730006861,799.0
65.763429399,851.0
65.796851937,777.0
65.830274474,812.0
65.863697012,841.0
65.897119550,795.0
65.930542088,856.0
65.963964626,819.0
65.997387164,821.0
66.030809702,781.0
66.064232240,809.0
66.097654778,818.0
66.131077316,765.0
66.164499854,820.0
66.197922392,857.0
66.231344930,850.0
66.264767468,796.0
66.298190006,828.0
66.331612544,795.0
66.365035082,799.0
66.398457620,772.0
66.431880158,813.0
66.465302696,818.0
66.498725234,801.0
66.532147772,777.0
66.565570309,773.0
66.598992847,787.0
66.632415385,862.0
66.665837923,839.0
66.699260461,809.0
66.732682999,787.0
66.766105537,795.0
66.799528075,854.0
66.832950613,809.0
66.866373151,783.0
66.899795689,825.0
66.933218227,815.0
66.966640765,811.0
67.000063303,876.0
67.033485841,767.0
67.066908379,770.0
67.100330917,773.0
67.133753455,833.0
67.167175993,798.0
67.200598531,819.0
67.234021069,796.0
67.267443607,808.0
67.300866145,790.0
67.334288682,862.0
67.367711220,807.0
67.401133758,821.0
67.434556296,834.0
67.467978834,755.0
67.501401372,804.0
67.534823910,753.0
67.568246448,836.0
67.601668986,753.0
67.635091524,841.0
67.668514062,850.0
67.701936600,812.0
67.735359138,785.0
67.768781676,835.0
67.802204214,785.0
67.835626752,818.0
67.869049290,821.0
67.902471828,824.0
67.935894366,790.0
67.969316904,793.0
68.002739442,792.0
68.036161980,820.0
68.069584518,794.0
68.103007055,820.0
68.136429593,804.0
68.169852131,755.0
68.203274669,828.0
68.236697207,822.0
68.270119745,778.0
68.303542283,845.0
68.336964821,818.0
68.370387359,788.0
68.403809897,744.0
68.437232435,750.0
68.470654973,752.0
68.504077511,835.0
68.537500049,781.0
68.570922587,793.0
68.604345125,744.0
68.637767663,791.0
68.671190201,783.0
68.704612739,778.0
68.738035277,804.0
68.771457815,756.0
68.804880353,791.0
68.838302891,788.0
68.871725428,773.0
68.905147966,769.0
68.938570504,786.0
68.971993042,798.0
69.005415580,768.0
69.038838118,801.0
69.072260656,797.0
69.105683194,774.0
69.139105732,756.0
69.172528270,750.0
69.205950808,707.0
69.239373346,763.0
69.272795884,764.0
69.306218422,746.0
69.339640960,764.0
69.373063498,766.0
69.406486036,760.0
69.439908574,758.0
69.473331112,814.0
69.506753650,757.0
69.540176188,740.0
69.573598726,759.0
69.607021264,759.0
69.640443801,730.0
69.673866339,732.0
69.707288877,749.0
69.740711415,773.0
69.774133953,754.0
69.807556491,753.0
69.840979029,795.0
69.874401567,810.0
69.907824105,763.0
69.941246643,786.0
69.974669181,764.0
69.991380450,786.0