File: OriginPro/XRD from Panalytical X'Pert PRO/XRD_Cu_NWs/A2_300C.csv
[Measurement conditions]
Sample identification,
Comment - 1,"Configuration=Flat Samole Stage, Owner=User-1, Creation date=26-10-2009 9:12:11"
Comment - 2,"Goniometer=PW3050/60 (Theta/Theta); Minimum step size 2Theta:0.001; Minimum step size Omega:0.001"
Comment - 3,"Sample stage=PW3071/xx Bracket"
Comment - 4,"Diffractometer system=XPERT-PRO"
Comment - 5,"Measurement program=lixo, Owner=AnaP, Creation date=26-07-2013 11:02:14"
Comment - 6,"Fine Calibration Offset for 2Theta = 0.021 deg"
Anode material,Cu
K-Alpha1 wavelength,1.5405980
K-Alpha2 wavelength,1.5444260
Ratio K-Alpha2/K-Alpha1,0.500
Divergence slit,Fixed,0.76mm
Monochromator used,NO
Generator voltage, 45
Tube current, 40
File date and time,29-Jun-2017 13:16
Unit cell,
h k l, 0 0 0
Scan axis,Gonio
Scan range,25.012999996,69.999736084
Scan step size,0.0167113
No. of points, 2692
Scan type,CONTINUOUS
Time per step,29.845
[Scan points]
Angle,Intensity
25.021355630,2484.0
25.054778168,2449.0
25.088200706,2375.0
25.121623244,2309.0
25.155045782,2386.0
25.188468320,2262.0
25.221890858,2355.0
25.255313396,2386.0
25.288735934,2378.0
25.322158472,2283.0
25.355581010,2307.0
25.389003548,2246.0
25.422426085,2214.0
25.455848623,2290.0
25.489271161,2237.0
25.522693699,2221.0
25.556116237,2214.0
25.589538775,2250.0
25.622961313,2228.0
25.656383851,2293.0
25.689806389,2125.0
25.723228927,2268.0
25.756651465,2143.0
25.790074003,2152.0
25.823496541,2133.0
25.856919079,2193.0
25.890341617,2138.0
25.923764155,2167.0
25.957186693,2045.0
25.990609231,2151.0
26.024031769,2100.0
26.057454307,2030.0
26.090876845,2002.0
26.124299383,2031.0
26.157721921,2188.0
26.191144458,2088.0
26.224566996,2092.0
26.257989534,2071.0
26.291412072,1981.0
26.324834610,2079.0
26.358257148,2008.0
26.391679686,2025.0
26.425102224,2022.0
26.458524762,2026.0
26.491947300,2037.0
26.525369838,1975.0
26.558792376,2004.0
26.592214914,2062.0
26.625637452,2060.0
26.659059990,1950.0
26.692482528,2014.0
26.725905066,1968.0
26.759327604,1963.0
26.792750142,1909.0
26.826172680,1970.0
26.859595218,1957.0
26.893017756,1854.0
26.926440294,1895.0
26.959862831,1908.0
26.993285369,1916.0
27.026707907,1953.0
27.060130445,1909.0
27.093552983,1882.0
27.126975521,1923.0
27.160398059,1865.0
27.193820597,1902.0
27.227243135,1826.0
27.260665673,1945.0
27.294088211,1844.0
27.327510749,1885.0
27.360933287,1878.0
27.394355825,1865.0
27.427778363,1897.0
27.461200901,1897.0
27.494623439,1890.0
27.528045977,1801.0
27.561468515,1863.0
27.594891053,1777.0
27.628313591,1765.0
27.661736129,1770.0
27.695158666,1735.0
27.728581204,1805.0
27.762003742,1810.0
27.795426280,1764.0
27.828848818,1815.0
27.862271356,1802.0
27.895693894,1759.0
27.929116432,1718.0
27.962538970,1737.0
27.995961508,1736.0
28.029384046,1691.0
28.062806584,1697.0
28.096229122,1673.0
28.129651660,1718.0
28.163074198,1687.0
28.196496736,1748.0
28.229919274,1788.0
28.263341812,1674.0
28.296764350,1673.0
28.330186888,1747.0
28.363609426,1709.0
28.397031964,1686.0
28.430454502,1638.0
28.463877039,1650.0
28.497299577,1669.0
28.530722115,1653.0
28.564144653,1599.0
28.597567191,1632.0
28.630989729,1654.0
28.664412267,1637.0
28.697834805,1618.0
28.731257343,1681.0
28.764679881,1621.0
28.798102419,1655.0
28.831524957,1656.0
28.864947495,1597.0
28.898370033,1594.0
28.931792571,1615.0
28.965215109,1583.0
28.998637647,1603.0
29.032060185,1687.0
29.065482723,1616.0
29.098905261,1531.0
29.132327799,1656.0
29.165750337,1641.0
29.199172875,1599.0
29.232595412,1558.0
29.266017950,1626.0
29.299440488,1605.0
29.332863026,1605.0
29.366285564,1596.0
29.399708102,1537.0
29.433130640,1609.0
29.466553178,1664.0
29.499975716,1652.0
29.533398254,1673.0
29.566820792,1589.0
29.600243330,1562.0
29.633665868,1539.0
29.667088406,1646.0
29.700510944,1594.0
29.733933482,1555.0
29.767356020,1584.0
29.800778558,1555.0
29.834201096,1593.0
29.867623634,1617.0
29.901046172,1551.0
29.934468710,1475.0
29.967891248,1451.0
30.001313785,1551.0
30.034736323,1511.0
30.068158861,1427.0
30.101581399,1489.0
30.135003937,1505.0
30.168426475,1513.0
30.201849013,1512.0
30.235271551,1449.0
30.268694089,1553.0
30.302116627,1510.0
30.335539165,1498.0
30.368961703,1468.0
30.402384241,1483.0
30.435806779,1462.0
30.469229317,1457.0
30.502651855,1460.0
30.536074393,1440.0
30.569496931,1527.0
30.602919469,1461.0
30.636342007,1464.0
30.669764545,1432.0
30.703187083,1469.0
30.736609621,1458.0
30.770032158,1358.0
30.803454696,1465.0
30.836877234,1489.0
30.870299772,1390.0
30.903722310,1348.0
30.937144848,1367.0
30.970567386,1387.0
31.003989924,1406.0
31.037412462,1437.0
31.070835000,1496.0
31.104257538,1405.0
31.137680076,1374.0
31.171102614,1363.0
31.204525152,1394.0
31.237947690,1393.0
31.271370228,1456.0
31.304792766,1337.0
31.338215304,1361.0
31.371637842,1430.0
31.405060380,1366.0
31.438482918,1404.0
31.471905456,1373.0
31.505327993,1323.0
31.538750531,1437.0
31.572173069,1443.0
31.605595607,1383.0
31.639018145,1282.0
31.672440683,1386.0
31.705863221,1341.0
31.739285759,1388.0
31.772708297,1405.0
31.806130835,1354.0
31.839553373,1344.0
31.872975911,1349.0
31.906398449,1360.0
31.939820987,1340.0
31.973243525,1308.0
32.006666063,1347.0
32.040088601,1331.0
32.073511139,1403.0
32.106933677,1297.0
32.140356215,1376.0
32.173778753,1408.0
32.207201291,1355.0
32.240623829,1374.0
32.274046366,1355.0
32.307468904,1278.0
32.340891442,1340.0
32.374313980,1293.0
32.407736518,1325.0
32.441159056,1303.0
32.474581594,1383.0
32.508004132,1345.0
32.541426670,1357.0
32.574849208,1348.0
32.608271746,1300.0
32.641694284,1337.0
32.675116822,1351.0
32.708539360,1286.0
32.741961898,1274.0
32.775384436,1294.0
32.808806974,1391.0
32.842229512,1261.0
32.875652050,1331.0
32.909074588,1242.0
32.942497126,1262.0
32.975919664,1349.0
33.009342202,1318.0
33.042764739,1316.0
33.076187277,1228.0
33.109609815,1311.0
33.143032353,1264.0
33.176454891,1350.0
33.209877429,1271.0
33.243299967,1182.0
33.276722505,1266.0
33.310145043,1251.0
33.343567581,1247.0
33.376990119,1266.0
33.410412657,1223.0
33.443835195,1269.0
33.477257733,1248.0
33.510680271,1160.0
33.544102809,1282.0
33.577525347,1184.0
33.610947885,1255.0
33.644370423,1319.0
33.677792961,1225.0
33.711215499,1264.0
33.744638037,1296.0
33.778060575,1207.0
33.811483112,1282.0
33.844905650,1184.0
33.878328188,1239.0
33.911750726,1248.0
33.945173264,1247.0
33.978595802,1242.0
34.012018340,1327.0
34.045440878,1292.0
34.078863416,1282.0
34.112285954,1240.0
34.145708492,1233.0
34.179131030,1186.0
34.212553568,1196.0
34.245976106,1208.0
34.279398644,1191.0
34.312821182,1243.0
34.346243720,1171.0
34.379666258,1226.0
34.413088796,1228.0
34.446511334,1266.0
34.479933872,1257.0
34.513356410,1276.0
34.546778948,1302.0
34.580201485,1270.0
34.613624023,1238.0
34.647046561,1222.0
34.680469099,1234.0
34.713891637,1322.0
34.747314175,1227.0
34.780736713,1283.0
34.814159251,1226.0
34.847581789,1305.0
34.881004327,1255.0
34.914426865,1264.0
34.947849403,1328.0
34.981271941,1310.0
35.014694479,1245.0
35.048117017,1391.0
35.081539555,1345.0
35.114962093,1290.0
35.148384631,1368.0
35.181807169,1299.0
35.215229707,1349.0
35.248652245,1436.0
35.282074783,1387.0
35.315497320,1432.0
35.348919858,1473.0
35.382342396,1446.0
35.415764934,1459.0
35.449187472,1518.0
35.482610010,1450.0
35.516032548,1554.0
35.549455086,1507.0
35.582877624,1577.0
35.616300162,1462.0
35.649722700,1631.0
35.683145238,1543.0
35.716567776,1490.0
35.749990314,1574.0
35.783412852,1524.0
35.816835390,1634.0
35.850257928,1603.0
35.883680466,1497.0
35.917103004,1584.0
35.950525542,1630.0
35.983948080,1664.0
36.017370618,1582.0
36.050793156,1690.0
36.084215693,1712.0
36.117638231,1806.0
36.151060769,1880.0
36.184483307,1909.0
36.217905845,1949.0
36.251328383,2098.0
36.284750921,2304.0
36.318173459,2352.0
36.351595997,2482.0
36.385018535,2711.0
36.418441073,2786.0
36.451863611,2966.0
36.485286149,2939.0
36.518708687,3001.0
36.552131225,2971.0
36.585553763,2840.0
36.618976301,2825.0
36.652398839,2689.0
36.685821377,2531.0
36.719243915,2277.0
36.752666453,2198.0
36.786088991,2089.0
36.819511529,1981.0
36.852934066,1811.0
36.886356604,1850.0
36.919779142,1617.0
36.953201680,1562.0
36.986624218,1570.0
37.020046756,1552.0
37.053469294,1407.0
37.086891832,1450.0
37.120314370,1422.0
37.153736908,1348.0
37.187159446,1372.0
37.220581984,1278.0
37.254004522,1261.0
37.287427060,1281.0
37.320849598,1261.0
37.354272136,1235.0
37.387694674,1211.0
37.421117212,1253.0
37.454539750,1184.0
37.487962288,1094.0
37.521384826,1188.0
37.554807364,1175.0
37.588229902,1178.0
37.621652439,1197.0
37.655074977,1179.0
37.688497515,1165.0
37.721920053,1193.0
37.755342591,1225.0
37.788765129,1105.0
37.822187667,1103.0
37.855610205,1124.0
37.889032743,1194.0
37.922455281,1141.0
37.955877819,1124.0
37.989300357,1037.0
38.022722895,1164.0
38.056145433,1109.0
38.089567971,1182.0
38.122990509,1113.0
38.156413047,1118.0
38.189835585,1219.0
38.223258123,1138.0
38.256680661,1144.0
38.290103199,1202.0
38.323525737,1104.0
38.356948275,1210.0
38.390370812,1228.0
38.423793350,1193.0
38.457215888,1137.0
38.490638426,1136.0
38.524060964,1185.0
38.557483502,1143.0
38.590906040,1216.0
38.624328578,1183.0
38.657751116,1167.0
38.691173654,1192.0
38.724596192,1192.0
38.758018730,1211.0
38.791441268,1197.0
38.824863806,1160.0
38.858286344,1193.0
38.891708882,1186.0
38.925131420,1151.0
38.958553958,1139.0
38.991976496,1164.0
39.025399034,1129.0
39.058821572,1124.0
39.092244110,1099.0
39.125666647,1089.0
39.159089185,1109.0
39.192511723,1182.0
39.225934261,1101.0
39.259356799,1080.0
39.292779337,1095.0
39.326201875,1050.0
39.359624413,997.0
39.393046951,1042.0
39.426469489,979.0
39.459892027,1071.0
39.493314565,1033.0
39.526737103,1017.0
39.560159641,1091.0
39.593582179,903.0
39.627004717,976.0
39.660427255,971.0
39.693849793,1021.0
39.727272331,1009.0
39.760694869,949.0
39.794117407,992.0
39.827539945,979.0
39.860962483,959.0
39.894385020,949.0
39.927807558,936.0
39.961230096,961.0
39.994652634,966.0
40.028075172,1017.0
40.061497710,946.0
40.094920248,915.0
40.128342786,949.0
40.161765324,882.0
40.195187862,954.0
40.228610400,997.0
40.262032938,940.0
40.295455476,921.0
40.328878014,972.0
40.362300552,922.0
40.395723090,960.0
40.429145628,910.0
40.462568166,938.0
40.495990704,880.0
40.529413242,930.0
40.562835780,856.0
40.596258318,958.0
40.629680856,929.0
40.663103393,909.0
40.696525931,890.0
40.729948469,924.0
40.763371007,956.0
40.796793545,896.0
40.830216083,932.0
40.863638621,907.0
40.897061159,940.0
40.930483697,950.0
40.963906235,908.0
40.997328773,940.0
41.030751311,947.0
41.064173849,904.0
41.097596387,911.0
41.131018925,865.0
41.164441463,931.0
41.197864001,929.0
41.231286539,894.0
41.264709077,928.0
41.298131615,916.0
41.331554153,936.0
41.364976691,949.0
41.398399229,909.0
41.431821766,953.0
41.465244304,894.0
41.498666842,903.0
41.532089380,949.0
41.565511918,992.0
41.598934456,928.0
41.632356994,942.0
41.665779532,1091.0
41.699202070,968.0
41.732624608,984.0
41.766047146,1007.0
41.799469684,995.0
41.832892222,1057.0
41.866314760,1050.0
41.899737298,1077.0
41.933159836,1044.0
41.966582374,1015.0
42.000004912,1061.0
42.033427450,1045.0
42.066849988,1087.0
42.100272526,1111.0
42.133695064,1170.0
42.167117602,1144.0
42.200540139,1229.0
42.233962677,1215.0
42.267385215,1165.0
42.300807753,1219.0
42.334230291,1238.0
42.367652829,1236.0
42.401075367,1224.0
42.434497905,1229.0
42.467920443,1183.0
42.501342981,1181.0
42.534765519,1196.0
42.568188057,1183.0
42.601610595,1162.0
42.635033133,1160.0
42.668455671,1056.0
42.701878209,1059.0
42.735300747,1113.0
42.768723285,1048.0
42.802145823,1070.0
42.835568361,1073.0
42.868990899,1062.0
42.902413437,1006.0
42.935835974,999.0
42.969258512,960.0
43.002681050,905.0
43.036103588,1039.0
43.069526126,998.0
43.102948664,964.0
43.136371202,912.0
43.169793740,971.0
43.203216278,980.0
43.236638816,975.0
43.270061354,956.0
43.303483892,1044.0
43.336906430,1004.0
43.370328968,1085.0
43.403751506,1099.0
43.437174044,1123.0
43.470596582,1056.0
43.504019120,1017.0
43.537441658,1043.0
43.570864196,963.0
43.604286734,967.0
43.637709272,914.0
43.671131810,921.0
43.704554347,924.0
43.737976885,902.0
43.771399423,860.0
43.804821961,891.0
43.838244499,851.0
43.871667037,837.0
43.905089575,850.0
43.938512113,890.0
43.971934651,859.0
44.005357189,848.0
44.038779727,882.0
44.072202265,857.0
44.105624803,901.0
44.139047341,914.0
44.172469879,901.0
44.205892417,847.0
44.239314955,851.0
44.272737493,825.0
44.306160031,852.0
44.339582569,859.0
44.373005107,861.0
44.406427645,826.0
44.439850183,876.0
44.473272720,813.0
44.506695258,843.0
44.540117796,880.0
44.573540334,887.0
44.606962872,892.0
44.640385410,841.0
44.673807948,873.0
44.707230486,909.0
44.740653024,885.0
44.774075562,826.0
44.807498100,854.0
44.840920638,856.0
44.874343176,878.0
44.907765714,892.0
44.941188252,876.0
44.974610790,807.0
45.008033328,781.0
45.041455866,884.0
45.074878404,807.0
45.108300942,870.0
45.141723480,831.0
45.175146018,882.0
45.208568556,834.0
45.241991093,896.0
45.275413631,857.0
45.308836169,840.0
45.342258707,833.0
45.375681245,902.0
45.409103783,851.0
45.442526321,808.0
45.475948859,868.0
45.509371397,893.0
45.542793935,854.0
45.576216473,863.0
45.609639011,875.0
45.643061549,881.0
45.676484087,885.0
45.709906625,832.0
45.743329163,848.0
45.776751701,873.0
45.810174239,834.0
45.843596777,824.0
45.877019315,802.0
45.910441853,861.0
45.943864391,916.0
45.977286929,828.0
46.010709466,852.0
46.044132004,885.0
46.077554542,804.0
46.110977080,834.0
46.144399618,825.0
46.177822156,838.0
46.211244694,882.0
46.244667232,834.0
46.278089770,868.0
46.311512308,868.0
46.344934846,900.0
46.378357384,839.0
46.411779922,788.0
46.445202460,822.0
46.478624998,776.0
46.512047536,820.0
46.545470074,884.0
46.578892612,822.0
46.612315150,854.0
46.645737688,845.0
46.679160226,862.0
46.712582764,821.0
46.746005301,738.0
46.779427839,865.0
46.812850377,811.0
46.846272915,851.0
46.879695453,825.0
46.913117991,838.0
46.946540529,859.0
46.979963067,860.0
47.013385605,768.0
47.046808143,834.0
47.080230681,869.0
47.113653219,849.0
47.147075757,820.0
47.180498295,848.0
47.213920833,874.0
47.247343371,856.0
47.280765909,795.0
47.314188447,827.0
47.347610985,798.0
47.381033523,792.0
47.414456061,806.0
47.447878599,831.0
47.481301137,845.0
47.514723674,852.0
47.548146212,742.0
47.581568750,841.0
47.614991288,897.0
47.648413826,860.0
47.681836364,849.0
47.715258902,812.0
47.748681440,882.0
47.782103978,818.0
47.815526516,859.0
47.848949054,809.0
47.882371592,859.0
47.915794130,811.0
47.949216668,838.0
47.982639206,791.0
48.016061744,802.0
48.049484282,787.0
48.082906820,826.0
48.116329358,836.0
48.149751896,795.0
48.183174434,893.0
48.216596972,824.0
48.250019510,888.0
48.283442047,795.0
48.316864585,814.0
48.350287123,793.0
48.383709661,801.0
48.417132199,898.0
48.450554737,800.0
48.483977275,827.0
48.517399813,818.0
48.550822351,780.0
48.584244889,801.0
48.617667427,786.0
48.651089965,908.0
48.684512503,846.0
48.717935041,867.0
48.751357579,892.0
48.784780117,786.0
48.818202655,823.0
48.851625193,783.0
48.885047731,776.0
48.918470269,835.0
48.951892807,763.0
48.985315345,813.0
49.018737883,897.0
49.052160420,837.0
49.085582958,833.0
49.119005496,831.0
49.152428034,777.0
49.185850572,773.0
49.219273110,812.0
49.252695648,811.0
49.286118186,869.0
49.319540724,851.0
49.352963262,820.0
49.386385800,762.0
49.419808338,798.0
49.453230876,834.0
49.486653414,869.0
49.520075952,813.0
49.553498490,797.0
49.586921028,832.0
49.620343566,840.0
49.653766104,802.0
49.687188642,800.0
49.720611180,838.0
49.754033718,825.0
49.787456256,808.0
49.820878793,825.0
49.854301331,849.0
49.887723869,824.0
49.921146407,794.0
49.954568945,786.0
49.987991483,811.0
50.021414021,813.0
50.054836559,795.0
50.088259097,778.0
50.121681635,796.0
50.155104173,818.0
50.188526711,815.0
50.221949249,752.0
50.255371787,783.0
50.288794325,824.0
50.322216863,738.0
50.355639401,820.0
50.389061939,724.0
50.422484477,765.0
50.455907015,817.0
50.489329553,804.0
50.522752091,801.0
50.556174628,875.0
50.589597166,812.0
50.623019704,901.0
50.656442242,819.0
50.689864780,791.0
50.723287318,786.0
50.756709856,801.0
50.790132394,800.0
50.823554932,774.0
50.856977470,807.0
50.890400008,738.0
50.923822546,798.0
50.957245084,835.0
50.990667622,766.0
51.024090160,815.0
51.057512698,732.0
51.090935236,786.0
51.124357774,768.0
51.157780312,726.0
51.191202850,793.0
51.224625388,808.0
51.258047926,684.0
51.291470464,790.0
51.324893001,750.0
51.358315539,793.0
51.391738077,758.0
51.425160615,749.0
51.458583153,774.0
51.492005691,812.0
51.525428229,736.0
51.558850767,788.0
51.592273305,793.0
51.625695843,712.0
51.659118381,792.0
51.692540919,744.0
51.725963457,770.0
51.759385995,759.0
51.792808533,771.0
51.826231071,783.0
51.859653609,749.0
51.893076147,766.0
51.926498685,749.0
51.959921223,759.0
51.993343761,771.0
52.026766299,812.0
52.060188837,735.0
52.093611374,833.0
52.127033912,765.0
52.160456450,777.0
52.193878988,771.0
52.227301526,788.0
52.260724064,750.0
52.294146602,773.0
52.327569140,748.0
52.360991678,768.0
52.394414216,743.0
52.427836754,785.0
52.461259292,746.0
52.494681830,786.0
52.528104368,713.0
52.561526906,754.0
52.594949444,732.0
52.628371982,793.0
52.661794520,759.0
52.695217058,730.0
52.728639596,807.0
52.762062134,777.0
52.795484672,746.0
52.828907210,774.0
52.862329747,742.0
52.895752285,748.0
52.929174823,752.0
52.962597361,767.0
52.996019899,726.0
53.029442437,724.0
53.062864975,739.0
53.096287513,791.0
53.129710051,760.0
53.163132589,753.0
53.196555127,688.0
53.229977665,713.0
53.263400203,772.0
53.296822741,767.0
53.330245279,788.0
53.363667817,800.0
53.397090355,738.0
53.430512893,766.0
53.463935431,786.0
53.497357969,754.0
53.530780507,734.0
53.564203045,738.0
53.597625583,734.0
53.631048120,755.0
53.664470658,808.0
53.697893196,683.0
53.731315734,743.0
53.764738272,799.0
53.798160810,720.0
53.831583348,687.0
53.865005886,754.0
53.898428424,736.0
53.931850962,716.0
53.965273500,683.0
53.998696038,730.0
54.032118576,712.0
54.065541114,764.0
54.098963652,802.0
54.132386190,712.0
54.165808728,778.0
54.199231266,753.0
54.232653804,725.0
54.266076342,736.0
54.299498880,764.0
54.332921418,683.0
54.366343955,752.0
54.399766493,737.0
54.433189031,696.0
54.466611569,822.0
54.500034107,732.0
54.533456645,746.0
54.566879183,811.0
54.600301721,732.0
54.633724259,750.0
54.667146797,710.0
54.700569335,804.0
54.733991873,788.0
54.767414411,739.0
54.800836949,774.0
54.834259487,748.0
54.867682025,727.0
54.901104563,722.0
54.934527101,716.0
54.967949639,776.0
55.001372177,725.0
55.034794715,793.0
55.068217253,729.0
55.101639791,716.0
55.135062328,770.0
55.168484866,755.0
55.201907404,725.0
55.235329942,752.0
55.268752480,729.0
55.302175018,748.0
55.335597556,746.0
55.369020094,731.0
55.402442632,740.0
55.435865170,710.0
55.469287708,690.0
55.502710246,779.0
55.536132784,720.0
55.569555322,754.0
55.602977860,688.0
55.636400398,700.0
55.669822936,672.0
55.703245474,702.0
55.736668012,746.0
55.770090550,721.0
55.803513088,750.0
55.836935626,698.0
55.870358164,727.0
55.903780701,766.0
55.937203239,724.0
55.970625777,756.0
56.004048315,704.0
56.037470853,741.0
56.070893391,682.0
56.104315929,669.0
56.137738467,654.0
56.171161005,732.0
56.204583543,731.0
56.238006081,731.0
56.271428619,723.0
56.304851157,703.0
56.338273695,751.0
56.371696233,689.0
56.405118771,677.0
56.438541309,721.0
56.471963847,750.0
56.505386385,748.0
56.538808923,700.0
56.572231461,730.0
56.605653999,771.0
56.639076537,713.0
56.672499074,688.0
56.705921612,742.0
56.739344150,785.0
56.772766688,690.0
56.806189226,746.0
56.839611764,693.0
56.873034302,741.0
56.906456840,737.0
56.939879378,769.0
56.973301916,697.0
57.006724454,771.0
57.040146992,752.0
57.073569530,764.0
57.106992068,726.0
57.140414606,662.0
57.173837144,764.0
57.207259682,745.0
57.240682220,782.0
57.274104758,735.0
57.307527296,726.0
57.340949834,782.0
57.374372372,806.0
57.407794910,685.0
57.441217447,701.0
57.474639985,755.0
57.508062523,732.0
57.541485061,729.0
57.574907599,728.0
57.608330137,721.0
57.641752675,754.0
57.675175213,717.0
57.708597751,756.0
57.742020289,727.0
57.775442827,725.0
57.808865365,765.0
57.842287903,750.0
57.875710441,788.0
57.909132979,705.0
57.942555517,764.0
57.975978055,774.0
58.009400593,735.0
58.042823131,763.0
58.076245669,754.0
58.109668207,657.0
58.143090745,739.0
58.176513283,753.0
58.209935820,717.0
58.243358358,737.0
58.276780896,754.0
58.310203434,704.0
58.343625972,749.0
58.377048510,777.0
58.410471048,768.0
58.443893586,741.0
58.477316124,726.0
58.510738662,738.0
58.544161200,754.0
58.577583738,705.0
58.611006276,696.0
58.644428814,723.0
58.677851352,726.0
58.711273890,768.0
58.744696428,737.0
58.778118966,704.0
58.811541504,756.0
58.844964042,751.0
58.878386580,756.0
58.911809118,723.0
58.945231655,738.0
58.978654193,702.0
59.012076731,762.0
59.045499269,724.0
59.078921807,693.0
59.112344345,745.0
59.145766883,739.0
59.179189421,762.0
59.212611959,785.0
59.246034497,763.0
59.279457035,768.0
59.312879573,739.0
59.346302111,783.0
59.379724649,713.0
59.413147187,714.0
59.446569725,735.0
59.479992263,716.0
59.513414801,727.0
59.546837339,737.0
59.580259877,701.0
59.613682415,722.0
59.647104953,750.0
59.680527491,723.0
59.713950028,738.0
59.747372566,707.0
59.780795104,713.0
59.814217642,722.0
59.847640180,759.0
59.881062718,743.0
59.914485256,725.0
59.947907794,736.0
59.981330332,746.0
60.014752870,764.0
60.048175408,726.0
60.081597946,724.0
60.115020484,744.0
60.148443022,743.0
60.181865560,735.0
60.215288098,685.0
60.248710636,752.0
60.282133174,768.0
60.315555712,777.0
60.348978250,731.0
60.382400788,721.0
60.415823326,759.0
60.449245864,778.0
60.482668401,794.0
60.516090939,753.0
60.549513477,717.0
60.582936015,759.0
60.616358553,739.0
60.649781091,759.0
60.683203629,804.0
60.716626167,750.0
60.750048705,771.0
60.783471243,807.0
60.816893781,814.0
60.850316319,827.0
60.883738857,812.0
60.917161395,823.0
60.950583933,851.0
60.984006471,794.0
61.017429009,851.0
61.050851547,794.0
61.084274085,807.0
61.117696623,880.0
61.151119161,860.0
61.184541699,834.0
61.217964237,914.0
61.251386774,892.0
61.284809312,848.0
61.318231850,922.0
61.351654388,921.0
61.385076926,932.0
61.418499464,887.0
61.451922002,883.0
61.485344540,880.0
61.518767078,931.0
61.552189616,901.0
61.585612154,865.0
61.619034692,877.0
61.652457230,862.0
61.685879768,877.0
61.719302306,895.0
61.752724844,850.0
61.786147382,852.0
61.819569920,892.0
61.852992458,869.0
61.886414996,833.0
61.919837534,819.0
61.953260072,809.0
61.986682610,800.0
62.020105147,837.0
62.053527685,847.0
62.086950223,784.0
62.120372761,778.0
62.153795299,840.0
62.187217837,829.0
62.220640375,773.0
62.254062913,823.0
62.287485451,786.0
62.320907989,776.0
62.354330527,831.0
62.387753065,811.0
62.421175603,746.0
62.454598141,806.0
62.488020679,784.0
62.521443217,836.0
62.554865755,805.0
62.588288293,754.0
62.621710831,736.0
62.655133369,754.0
62.688555907,746.0
62.721978445,743.0
62.755400982,790.0
62.788823520,739.0
62.822246058,732.0
62.855668596,795.0
62.889091134,726.0
62.922513672,717.0
62.955936210,753.0
62.989358748,741.0
63.022781286,724.0
63.056203824,737.0
63.089626362,750.0
63.123048900,745.0
63.156471438,743.0
63.189893976,712.0
63.223316514,726.0
63.256739052,790.0
63.290161590,776.0
63.323584128,776.0
63.357006666,742.0
63.390429204,752.0
63.423851742,768.0
63.457274280,723.0
63.490696818,737.0
63.524119355,764.0
63.557541893,779.0
63.590964431,718.0
63.624386969,717.0
63.657809507,783.0
63.691232045,755.0
63.724654583,717.0
63.758077121,730.0
63.791499659,793.0
63.824922197,779.0
63.858344735,735.0
63.891767273,752.0
63.925189811,767.0
63.958612349,708.0
63.992034887,748.0
64.025457425,715.0
64.058879963,744.0
64.092302501,756.0
64.125725039,785.0
64.159147577,725.0
64.192570115,782.0
64.225992653,769.0
64.259415191,742.0
64.292837728,714.0
64.326260266,696.0
64.359682804,773.0
64.393105342,720.0
64.426527880,737.0
64.459950418,735.0
64.493372956,735.0
64.526795494,724.0
64.560218032,766.0
64.593640570,768.0
64.627063108,756.0
64.660485646,722.0
64.693908184,757.0
64.727330722,738.0
64.760753260,739.0
64.794175798,749.0
64.827598336,791.0
64.861020874,788.0
64.894443412,757.0
64.927865950,756.0
64.961288488,756.0
64.994711026,714.0
65.028133564,763.0
65.061556101,781.0
65.094978639,750.0
65.128401177,742.0
65.161823715,707.0
65.195246253,755.0
65.228668791,736.0
65.262091329,722.0
65.295513867,740.0
65.328936405,743.0
65.362358943,724.0
65.395781481,744.0
65.429204019,741.0
65.462626557,742.0
65.496049095,679.0
65.529471633,707.0
65.562894171,727.0
65.596316709,675.0
65.629739247,773.0
65.663161785,709.0
65.696584323,752.0
65.730006861,752.0
65.763429399,707.0
65.796851937,746.0
65.830274474,740.0
65.863697012,685.0
65.897119550,735.0
65.930542088,730.0
65.963964626,728.0
65.997387164,753.0
66.030809702,717.0
66.064232240,726.0
66.097654778,774.0
66.131077316,741.0
66.164499854,674.0
66.197922392,725.0
66.231344930,698.0
66.264767468,735.0
66.298190006,713.0
66.331612544,741.0
66.365035082,732.0
66.398457620,746.0
66.431880158,780.0
66.465302696,794.0
66.498725234,729.0
66.532147772,770.0
66.565570309,716.0
66.598992847,759.0
66.632415385,751.0
66.665837923,791.0
66.699260461,752.0
66.732682999,734.0
66.766105537,724.0
66.799528075,773.0
66.832950613,805.0
66.866373151,712.0
66.899795689,732.0
66.933218227,699.0
66.966640765,754.0
67.000063303,702.0
67.033485841,732.0
67.066908379,704.0
67.100330917,759.0
67.133753455,782.0
67.167175993,758.0
67.200598531,741.0
67.234021069,716.0
67.267443607,756.0
67.300866145,764.0
67.334288682,712.0
67.367711220,779.0
67.401133758,741.0
67.434556296,740.0
67.467978834,740.0
67.501401372,693.0
67.534823910,708.0
67.568246448,707.0
67.601668986,749.0
67.635091524,684.0
67.668514062,740.0
67.701936600,711.0
67.735359138,780.0
67.768781676,726.0
67.802204214,753.0
67.835626752,717.0
67.869049290,720.0
67.902471828,744.0
67.935894366,691.0
67.969316904,717.0
68.002739442,725.0
68.036161980,735.0
68.069584518,751.0
68.103007055,744.0
68.136429593,732.0
68.169852131,773.0
68.203274669,724.0
68.236697207,690.0
68.270119745,688.0
68.303542283,686.0
68.336964821,690.0
68.370387359,710.0
68.403809897,710.0
68.437232435,772.0
68.470654973,693.0
68.504077511,712.0
68.537500049,712.0
68.570922587,683.0
68.604345125,739.0
68.637767663,703.0
68.671190201,699.0
68.704612739,695.0
68.738035277,710.0
68.771457815,685.0
68.804880353,751.0
68.838302891,656.0
68.871725428,734.0
68.905147966,641.0
68.938570504,698.0
68.971993042,675.0
69.005415580,779.0
69.038838118,675.0
69.072260656,721.0
69.105683194,713.0
69.139105732,691.0
69.172528270,667.0
69.205950808,709.0
69.239373346,715.0
69.272795884,695.0
69.306218422,727.0
69.339640960,717.0
69.373063498,716.0
69.406486036,694.0
69.439908574,682.0
69.473331112,713.0
69.506753650,709.0
69.540176188,713.0
69.573598726,708.0
69.607021264,703.0
69.640443801,698.0
69.673866339,705.0
69.707288877,717.0
69.740711415,702.0
69.774133953,657.0
69.807556491,681.0
69.840979029,756.0
69.874401567,708.0
69.907824105,723.0
69.941246643,638.0
69.974669181,699.0
69.991380450,698.0