File: OriginPro/XRD from Panalytical X'Pert PRO/XRD_Cu_NWs/A3_400C.csv
[Measurement conditions]
Sample identification,
Comment - 1,"Configuration=Flat Samole Stage, Owner=User-1, Creation date=26-10-2009 9:12:11"
Comment - 2,"Goniometer=PW3050/60 (Theta/Theta); Minimum step size 2Theta:0.001; Minimum step size Omega:0.001"
Comment - 3,"Sample stage=PW3071/xx Bracket"
Comment - 4,"Diffractometer system=XPERT-PRO"
Comment - 5,"Measurement program=lixo, Owner=AnaP, Creation date=26-07-2013 11:02:14"
Comment - 6,"Fine Calibration Offset for 2Theta = 0.021 deg"
Anode material,Cu
K-Alpha1 wavelength,1.5405980
K-Alpha2 wavelength,1.5444260
Ratio K-Alpha2/K-Alpha1,0.500
Divergence slit,Fixed,0.76mm
Monochromator used,NO
Generator voltage, 45
Tube current, 40
File date and time,29-Jun-2017 13:42
Unit cell,
h k l, 0 0 0
Scan axis,Gonio
Scan range,25.012999996,69.999736084
Scan step size,0.0167113
No. of points, 2692
Scan type,CONTINUOUS
Time per step,29.845
[Scan points]
Angle,Intensity
25.021355630,2276.0
25.054778168,2331.0
25.088200706,2265.0
25.121623244,2274.0
25.155045782,2334.0
25.188468320,2293.0
25.221890858,2194.0
25.255313396,2236.0
25.288735934,2172.0
25.322158472,2264.0
25.355581010,2240.0
25.389003548,2231.0
25.422426085,2134.0
25.455848623,2108.0
25.489271161,2123.0
25.522693699,2089.0
25.556116237,2196.0
25.589538775,2203.0
25.622961313,2119.0
25.656383851,2143.0
25.689806389,2092.0
25.723228927,2002.0
25.756651465,2196.0
25.790074003,2148.0
25.823496541,2102.0
25.856919079,2068.0
25.890341617,2025.0
25.923764155,2067.0
25.957186693,2085.0
25.990609231,2160.0
26.024031769,2117.0
26.057454307,2079.0
26.090876845,2058.0
26.124299383,2109.0
26.157721921,1999.0
26.191144458,2083.0
26.224566996,1996.0
26.257989534,2010.0
26.291412072,1946.0
26.324834610,1960.0
26.358257148,2014.0
26.391679686,2061.0
26.425102224,1985.0
26.458524762,1926.0
26.491947300,2004.0
26.525369838,1919.0
26.558792376,1964.0
26.592214914,1949.0
26.625637452,1981.0
26.659059990,1903.0
26.692482528,1854.0
26.725905066,1932.0
26.759327604,1878.0
26.792750142,1836.0
26.826172680,1866.0
26.859595218,1877.0
26.893017756,1908.0
26.926440294,1859.0
26.959862831,1811.0
26.993285369,1763.0
27.026707907,1824.0
27.060130445,1835.0
27.093552983,1876.0
27.126975521,1861.0
27.160398059,1854.0
27.193820597,1838.0
27.227243135,1770.0
27.260665673,1668.0
27.294088211,1777.0
27.327510749,1845.0
27.360933287,1802.0
27.394355825,1713.0
27.427778363,1790.0
27.461200901,1734.0
27.494623439,1732.0
27.528045977,1741.0
27.561468515,1718.0
27.594891053,1677.0
27.628313591,1734.0
27.661736129,1695.0
27.695158666,1748.0
27.728581204,1735.0
27.762003742,1722.0
27.795426280,1721.0
27.828848818,1752.0
27.862271356,1708.0
27.895693894,1712.0
27.929116432,1632.0
27.962538970,1706.0
27.995961508,1659.0
28.029384046,1679.0
28.062806584,1608.0
28.096229122,1640.0
28.129651660,1663.0
28.163074198,1611.0
28.196496736,1694.0
28.229919274,1628.0
28.263341812,1648.0
28.296764350,1576.0
28.330186888,1615.0
28.363609426,1635.0
28.397031964,1584.0
28.430454502,1632.0
28.463877039,1643.0
28.497299577,1610.0
28.530722115,1569.0
28.564144653,1551.0
28.597567191,1589.0
28.630989729,1493.0
28.664412267,1582.0
28.697834805,1610.0
28.731257343,1562.0
28.764679881,1499.0
28.798102419,1580.0
28.831524957,1490.0
28.864947495,1562.0
28.898370033,1538.0
28.931792571,1573.0
28.965215109,1486.0
28.998637647,1496.0
29.032060185,1515.0
29.065482723,1581.0
29.098905261,1503.0
29.132327799,1496.0
29.165750337,1512.0
29.199172875,1557.0
29.232595412,1473.0
29.266017950,1513.0
29.299440488,1505.0
29.332863026,1518.0
29.366285564,1484.0
29.399708102,1499.0
29.433130640,1463.0
29.466553178,1502.0
29.499975716,1461.0
29.533398254,1451.0
29.566820792,1450.0
29.600243330,1558.0
29.633665868,1485.0
29.667088406,1455.0
29.700510944,1423.0
29.733933482,1456.0
29.767356020,1444.0
29.800778558,1422.0
29.834201096,1386.0
29.867623634,1444.0
29.901046172,1438.0
29.934468710,1452.0
29.967891248,1425.0
30.001313785,1490.0
30.034736323,1383.0
30.068158861,1429.0
30.101581399,1429.0
30.135003937,1442.0
30.168426475,1411.0
30.201849013,1361.0
30.235271551,1393.0
30.268694089,1351.0
30.302116627,1328.0
30.335539165,1365.0
30.368961703,1432.0
30.402384241,1403.0
30.435806779,1355.0
30.469229317,1445.0
30.502651855,1294.0
30.536074393,1394.0
30.569496931,1396.0
30.602919469,1386.0
30.636342007,1325.0
30.669764545,1381.0
30.703187083,1296.0
30.736609621,1423.0
30.770032158,1348.0
30.803454696,1366.0
30.836877234,1372.0
30.870299772,1274.0
30.903722310,1361.0
30.937144848,1342.0
30.970567386,1404.0
31.003989924,1299.0
31.037412462,1305.0
31.070835000,1277.0
31.104257538,1340.0
31.137680076,1314.0
31.171102614,1296.0
31.204525152,1269.0
31.237947690,1328.0
31.271370228,1320.0
31.304792766,1300.0
31.338215304,1316.0
31.371637842,1290.0
31.405060380,1291.0
31.438482918,1359.0
31.471905456,1307.0
31.505327993,1230.0
31.538750531,1229.0
31.572173069,1349.0
31.605595607,1254.0
31.639018145,1319.0
31.672440683,1269.0
31.705863221,1257.0
31.739285759,1352.0
31.772708297,1313.0
31.806130835,1253.0
31.839553373,1291.0
31.872975911,1298.0
31.906398449,1245.0
31.939820987,1253.0
31.973243525,1271.0
32.006666063,1248.0
32.040088601,1270.0
32.073511139,1317.0
32.106933677,1327.0
32.140356215,1187.0
32.173778753,1283.0
32.207201291,1230.0
32.240623829,1313.0
32.274046366,1254.0
32.307468904,1285.0
32.340891442,1291.0
32.374313980,1254.0
32.407736518,1282.0
32.441159056,1322.0
32.474581594,1299.0
32.508004132,1341.0
32.541426670,1338.0
32.574849208,1270.0
32.608271746,1262.0
32.641694284,1325.0
32.675116822,1220.0
32.708539360,1194.0
32.741961898,1230.0
32.775384436,1174.0
32.808806974,1183.0
32.842229512,1186.0
32.875652050,1314.0
32.909074588,1193.0
32.942497126,1282.0
32.975919664,1226.0
33.009342202,1167.0
33.042764739,1217.0
33.076187277,1235.0
33.109609815,1186.0
33.143032353,1183.0
33.176454891,1270.0
33.209877429,1284.0
33.243299967,1209.0
33.276722505,1189.0
33.310145043,1154.0
33.343567581,1247.0
33.376990119,1143.0
33.410412657,1166.0
33.443835195,1134.0
33.477257733,1202.0
33.510680271,1145.0
33.544102809,1171.0
33.577525347,1151.0
33.610947885,1222.0
33.644370423,1140.0
33.677792961,1175.0
33.711215499,1125.0
33.744638037,1175.0
33.778060575,1173.0
33.811483112,1140.0
33.844905650,1209.0
33.878328188,1132.0
33.911750726,1202.0
33.945173264,1233.0
33.978595802,1157.0
34.012018340,1136.0
34.045440878,1153.0
34.078863416,1155.0
34.112285954,1152.0
34.145708492,1138.0
34.179131030,1132.0
34.212553568,1138.0
34.245976106,1160.0
34.279398644,1168.0
34.312821182,1145.0
34.346243720,1123.0
34.379666258,1120.0
34.413088796,1180.0
34.446511334,1205.0
34.479933872,1257.0
34.513356410,1156.0
34.546778948,1175.0
34.580201485,1195.0
34.613624023,1233.0
34.647046561,1097.0
34.680469099,1182.0
34.713891637,1170.0
34.747314175,1126.0
34.780736713,1142.0
34.814159251,1157.0
34.847581789,1175.0
34.881004327,1128.0
34.914426865,1111.0
34.947849403,1205.0
34.981271941,1240.0
35.014694479,1146.0
35.048117017,1202.0
35.081539555,1262.0
35.114962093,1260.0
35.148384631,1255.0
35.181807169,1193.0
35.215229707,1353.0
35.248652245,1379.0
35.282074783,1411.0
35.315497320,1502.0
35.348919858,1597.0
35.382342396,1574.0
35.415764934,1767.0
35.449187472,1843.0
35.482610010,1972.0
35.516032548,1981.0
35.549455086,2102.0
35.582877624,2040.0
35.616300162,1987.0
35.649722700,1973.0
35.683145238,1880.0
35.716567776,1888.0
35.749990314,1656.0
35.783412852,1610.0
35.816835390,1539.0
35.850257928,1451.0
35.883680466,1450.0
35.917103004,1314.0
35.950525542,1307.0
35.983948080,1278.0
36.017370618,1217.0
36.050793156,1205.0
36.084215693,1231.0
36.117638231,1129.0
36.151060769,1172.0
36.184483307,1158.0
36.217905845,1067.0
36.251328383,1119.0
36.284750921,1115.0
36.318173459,1060.0
36.351595997,1154.0
36.385018535,1056.0
36.418441073,1055.0
36.451863611,1082.0
36.485286149,1061.0
36.518708687,1086.0
36.552131225,1091.0
36.585553763,1078.0
36.618976301,1025.0
36.652398839,1030.0
36.685821377,1101.0
36.719243915,1046.0
36.752666453,1053.0
36.786088991,1063.0
36.819511529,1045.0
36.852934066,1026.0
36.886356604,999.0
36.919779142,1031.0
36.953201680,1013.0
36.986624218,1012.0
37.020046756,1011.0
37.053469294,1086.0
37.086891832,1050.0
37.120314370,1008.0
37.153736908,1020.0
37.187159446,1023.0
37.220581984,982.0
37.254004522,1041.0
37.287427060,971.0
37.320849598,1057.0
37.354272136,1017.0
37.387694674,1082.0
37.421117212,1064.0
37.454539750,1077.0
37.487962288,1016.0
37.521384826,1048.0
37.554807364,991.0
37.588229902,981.0
37.621652439,1008.0
37.655074977,1058.0
37.688497515,981.0
37.721920053,997.0
37.755342591,1031.0
37.788765129,1005.0
37.822187667,1021.0
37.855610205,1020.0
37.889032743,1049.0
37.922455281,1043.0
37.955877819,1060.0
37.989300357,1085.0
38.022722895,1020.0
38.056145433,1025.0
38.089567971,1137.0
38.122990509,1090.0
38.156413047,1095.0
38.189835585,1097.0
38.223258123,1062.0
38.256680661,1195.0
38.290103199,1196.0
38.323525737,1179.0
38.356948275,1238.0
38.390370812,1248.0
38.423793350,1221.0
38.457215888,1283.0
38.490638426,1334.0
38.524060964,1363.0
38.557483502,1446.0
38.590906040,1472.0
38.624328578,1567.0
38.657751116,1588.0
38.691173654,1666.0
38.724596192,1781.0
38.758018730,1709.0
38.791441268,1735.0
38.824863806,1634.0
38.858286344,1626.0
38.891708882,1546.0
38.925131420,1581.0
38.958553958,1488.0
38.991976496,1487.0
39.025399034,1417.0
39.058821572,1290.0
39.092244110,1225.0
39.125666647,1237.0
39.159089185,1158.0
39.192511723,1236.0
39.225934261,1098.0
39.259356799,1072.0
39.292779337,1112.0
39.326201875,1025.0
39.359624413,1031.0
39.393046951,1002.0
39.426469489,966.0
39.459892027,970.0
39.493314565,967.0
39.526737103,965.0
39.560159641,970.0
39.593582179,951.0
39.627004717,921.0
39.660427255,905.0
39.693849793,891.0
39.727272331,943.0
39.760694869,936.0
39.794117407,959.0
39.827539945,861.0
39.860962483,861.0
39.894385020,889.0
39.927807558,891.0
39.961230096,823.0
39.994652634,862.0
40.028075172,866.0
40.061497710,865.0
40.094920248,855.0
40.128342786,841.0
40.161765324,874.0
40.195187862,837.0
40.228610400,839.0
40.262032938,828.0
40.295455476,841.0
40.328878014,836.0
40.362300552,859.0
40.395723090,865.0
40.429145628,904.0
40.462568166,846.0
40.495990704,897.0
40.529413242,910.0
40.562835780,874.0
40.596258318,853.0
40.629680856,870.0
40.663103393,855.0
40.696525931,905.0
40.729948469,832.0
40.763371007,807.0
40.796793545,847.0
40.830216083,836.0
40.863638621,847.0
40.897061159,805.0
40.930483697,898.0
40.963906235,846.0
40.997328773,794.0
41.030751311,810.0
41.064173849,795.0
41.097596387,814.0
41.131018925,834.0
41.164441463,905.0
41.197864001,848.0
41.231286539,819.0
41.264709077,833.0
41.298131615,873.0
41.331554153,843.0
41.364976691,817.0
41.398399229,795.0
41.431821766,856.0
41.465244304,837.0
41.498666842,828.0
41.532089380,820.0
41.565511918,891.0
41.598934456,867.0
41.632356994,849.0
41.665779532,786.0
41.699202070,833.0
41.732624608,869.0
41.766047146,807.0
41.799469684,825.0
41.832892222,832.0
41.866314760,807.0
41.899737298,812.0
41.933159836,838.0
41.966582374,814.0
42.000004912,867.0
42.033427450,804.0
42.066849988,826.0
42.100272526,824.0
42.133695064,833.0
42.167117602,863.0
42.200540139,866.0
42.233962677,881.0
42.267385215,854.0
42.300807753,909.0
42.334230291,771.0
42.367652829,829.0
42.401075367,842.0
42.434497905,828.0
42.467920443,778.0
42.501342981,776.0
42.534765519,767.0
42.568188057,738.0
42.601610595,791.0
42.635033133,851.0
42.668455671,819.0
42.701878209,825.0
42.735300747,779.0
42.768723285,863.0
42.802145823,809.0
42.835568361,832.0
42.868990899,812.0
42.902413437,781.0
42.935835974,766.0
42.969258512,807.0
43.002681050,782.0
43.036103588,813.0
43.069526126,876.0
43.102948664,855.0
43.136371202,826.0
43.169793740,839.0
43.203216278,819.0
43.236638816,777.0
43.270061354,809.0
43.303483892,811.0
43.336906430,804.0
43.370328968,801.0
43.403751506,824.0
43.437174044,815.0
43.470596582,826.0
43.504019120,834.0
43.537441658,808.0
43.570864196,862.0
43.604286734,834.0
43.637709272,759.0
43.671131810,855.0
43.704554347,802.0
43.737976885,814.0
43.771399423,888.0
43.804821961,815.0
43.838244499,785.0
43.871667037,787.0
43.905089575,791.0
43.938512113,787.0
43.971934651,729.0
44.005357189,829.0
44.038779727,798.0
44.072202265,807.0
44.105624803,781.0
44.139047341,788.0
44.172469879,824.0
44.205892417,847.0
44.239314955,769.0
44.272737493,784.0
44.306160031,798.0
44.339582569,809.0
44.373005107,784.0
44.406427645,742.0
44.439850183,777.0
44.473272720,773.0
44.506695258,787.0
44.540117796,833.0
44.573540334,807.0
44.606962872,779.0
44.640385410,815.0
44.673807948,799.0
44.707230486,799.0
44.740653024,822.0
44.774075562,783.0
44.807498100,812.0
44.840920638,788.0
44.874343176,792.0
44.907765714,804.0
44.941188252,806.0
44.974610790,731.0
45.008033328,822.0
45.041455866,808.0
45.074878404,817.0
45.108300942,774.0
45.141723480,787.0
45.175146018,812.0
45.208568556,845.0
45.241991093,762.0
45.275413631,831.0
45.308836169,798.0
45.342258707,770.0
45.375681245,764.0
45.409103783,790.0
45.442526321,776.0
45.475948859,798.0
45.509371397,805.0
45.542793935,802.0
45.576216473,798.0
45.609639011,851.0
45.643061549,860.0
45.676484087,852.0
45.709906625,751.0
45.743329163,813.0
45.776751701,825.0
45.810174239,791.0
45.843596777,783.0
45.877019315,795.0
45.910441853,806.0
45.943864391,772.0
45.977286929,782.0
46.010709466,753.0
46.044132004,786.0
46.077554542,779.0
46.110977080,745.0
46.144399618,774.0
46.177822156,798.0
46.211244694,834.0
46.244667232,776.0
46.278089770,846.0
46.311512308,786.0
46.344934846,765.0
46.378357384,755.0
46.411779922,804.0
46.445202460,837.0
46.478624998,828.0
46.512047536,802.0
46.545470074,799.0
46.578892612,810.0
46.612315150,786.0
46.645737688,780.0
46.679160226,857.0
46.712582764,743.0
46.746005301,755.0
46.779427839,756.0
46.812850377,729.0
46.846272915,732.0
46.879695453,780.0
46.913117991,762.0
46.946540529,741.0
46.979963067,848.0
47.013385605,737.0
47.046808143,800.0
47.080230681,758.0
47.113653219,764.0
47.147075757,774.0
47.180498295,742.0
47.213920833,760.0
47.247343371,788.0
47.280765909,790.0
47.314188447,772.0
47.347610985,770.0
47.381033523,742.0
47.414456061,741.0
47.447878599,772.0
47.481301137,780.0
47.514723674,769.0
47.548146212,776.0
47.581568750,787.0
47.614991288,815.0
47.648413826,807.0
47.681836364,772.0
47.715258902,700.0
47.748681440,752.0
47.782103978,794.0
47.815526516,736.0
47.848949054,759.0
47.882371592,750.0
47.915794130,791.0
47.949216668,753.0
47.982639206,760.0
48.016061744,762.0
48.049484282,781.0
48.082906820,739.0
48.116329358,770.0
48.149751896,773.0
48.183174434,805.0
48.216596972,768.0
48.250019510,756.0
48.283442047,749.0
48.316864585,807.0
48.350287123,752.0
48.383709661,794.0
48.417132199,757.0
48.450554737,792.0
48.483977275,815.0
48.517399813,832.0
48.550822351,813.0
48.584244889,811.0
48.617667427,838.0
48.651089965,800.0
48.684512503,793.0
48.717935041,862.0
48.751357579,860.0
48.784780117,905.0
48.818202655,901.0
48.851625193,856.0
48.885047731,914.0
48.918470269,884.0
48.951892807,922.0
48.985315345,887.0
49.018737883,914.0
49.052160420,923.0
49.085582958,879.0
49.119005496,892.0
49.152428034,821.0
49.185850572,838.0
49.219273110,795.0
49.252695648,843.0
49.286118186,788.0
49.319540724,781.0
49.352963262,819.0
49.386385800,812.0
49.419808338,810.0
49.453230876,726.0
49.486653414,795.0
49.520075952,811.0
49.553498490,795.0
49.586921028,729.0
49.620343566,737.0
49.653766104,772.0
49.687188642,769.0
49.720611180,742.0
49.754033718,755.0
49.787456256,757.0
49.820878793,767.0
49.854301331,760.0
49.887723869,725.0
49.921146407,713.0
49.954568945,698.0
49.987991483,728.0
50.021414021,782.0
50.054836559,740.0
50.088259097,723.0
50.121681635,762.0
50.155104173,699.0
50.188526711,797.0
50.221949249,798.0
50.255371787,769.0
50.288794325,735.0
50.322216863,729.0
50.355639401,721.0
50.389061939,714.0
50.422484477,712.0
50.455907015,757.0
50.489329553,702.0
50.522752091,781.0
50.556174628,699.0
50.589597166,707.0
50.623019704,699.0
50.656442242,699.0
50.689864780,736.0
50.723287318,686.0
50.756709856,718.0
50.790132394,754.0
50.823554932,741.0
50.856977470,712.0
50.890400008,661.0
50.923822546,672.0
50.957245084,726.0
50.990667622,696.0
51.024090160,736.0
51.057512698,758.0
51.090935236,779.0
51.124357774,734.0
51.157780312,676.0
51.191202850,741.0
51.224625388,680.0
51.258047926,739.0
51.291470464,734.0
51.324893001,685.0
51.358315539,705.0
51.391738077,727.0
51.425160615,713.0
51.458583153,675.0
51.492005691,714.0
51.525428229,674.0
51.558850767,697.0
51.592273305,652.0
51.625695843,687.0
51.659118381,751.0
51.692540919,722.0
51.725963457,698.0
51.759385995,697.0
51.792808533,738.0
51.826231071,738.0
51.859653609,708.0
51.893076147,707.0
51.926498685,661.0
51.959921223,755.0
51.993343761,728.0
52.026766299,710.0
52.060188837,735.0
52.093611374,736.0
52.127033912,743.0
52.160456450,689.0
52.193878988,705.0
52.227301526,673.0
52.260724064,659.0
52.294146602,680.0
52.327569140,679.0
52.360991678,729.0
52.394414216,735.0
52.427836754,748.0
52.461259292,765.0
52.494681830,737.0
52.528104368,696.0
52.561526906,715.0
52.594949444,707.0
52.628371982,718.0
52.661794520,680.0
52.695217058,694.0
52.728639596,662.0
52.762062134,681.0
52.795484672,728.0
52.828907210,701.0
52.862329747,732.0
52.895752285,717.0
52.929174823,698.0
52.962597361,677.0
52.996019899,713.0
53.029442437,753.0
53.062864975,737.0
53.096287513,712.0
53.129710051,709.0
53.163132589,756.0
53.196555127,718.0
53.229977665,741.0
53.263400203,713.0
53.296822741,671.0
53.330245279,738.0
53.363667817,701.0
53.397090355,770.0
53.430512893,739.0
53.463935431,731.0
53.497357969,700.0
53.530780507,726.0
53.564203045,766.0
53.597625583,702.0
53.631048120,701.0
53.664470658,711.0
53.697893196,716.0
53.731315734,723.0
53.764738272,709.0
53.798160810,770.0
53.831583348,778.0
53.865005886,712.0
53.898428424,724.0
53.931850962,667.0
53.965273500,714.0
53.998696038,718.0
54.032118576,691.0
54.065541114,736.0
54.098963652,710.0
54.132386190,666.0
54.165808728,672.0
54.199231266,753.0
54.232653804,672.0
54.266076342,663.0
54.299498880,684.0
54.332921418,707.0
54.366343955,716.0
54.399766493,709.0
54.433189031,698.0
54.466611569,695.0
54.500034107,651.0
54.533456645,734.0
54.566879183,731.0
54.600301721,726.0
54.633724259,726.0
54.667146797,726.0
54.700569335,675.0
54.733991873,707.0
54.767414411,713.0
54.800836949,679.0
54.834259487,748.0
54.867682025,716.0
54.901104563,653.0
54.934527101,714.0
54.967949639,714.0
55.001372177,673.0
55.034794715,715.0
55.068217253,697.0
55.101639791,713.0
55.135062328,703.0
55.168484866,652.0
55.201907404,675.0
55.235329942,707.0
55.268752480,655.0
55.302175018,697.0
55.335597556,655.0
55.369020094,696.0
55.402442632,744.0
55.435865170,696.0
55.469287708,657.0
55.502710246,681.0
55.536132784,680.0
55.569555322,698.0
55.602977860,659.0
55.636400398,743.0
55.669822936,687.0
55.703245474,695.0
55.736668012,714.0
55.770090550,672.0
55.803513088,666.0
55.836935626,645.0
55.870358164,687.0
55.903780701,673.0
55.937203239,712.0
55.970625777,725.0
56.004048315,640.0
56.037470853,693.0
56.070893391,705.0
56.104315929,710.0
56.137738467,711.0
56.171161005,647.0
56.204583543,630.0
56.238006081,704.0
56.271428619,657.0
56.304851157,670.0
56.338273695,676.0
56.371696233,690.0
56.405118771,671.0
56.438541309,689.0
56.471963847,682.0
56.505386385,683.0
56.538808923,696.0
56.572231461,682.0
56.605653999,645.0
56.639076537,704.0
56.672499074,694.0
56.705921612,716.0
56.739344150,735.0
56.772766688,739.0
56.806189226,710.0
56.839611764,699.0
56.873034302,715.0
56.906456840,659.0
56.939879378,690.0
56.973301916,745.0
57.006724454,651.0
57.040146992,660.0
57.073569530,693.0
57.106992068,705.0
57.140414606,685.0
57.173837144,693.0
57.207259682,674.0
57.240682220,710.0
57.274104758,713.0
57.307527296,666.0
57.340949834,667.0
57.374372372,720.0
57.407794910,673.0
57.441217447,740.0
57.474639985,669.0
57.508062523,700.0
57.541485061,667.0
57.574907599,668.0
57.608330137,639.0
57.641752675,697.0
57.675175213,708.0
57.708597751,673.0
57.742020289,713.0
57.775442827,690.0
57.808865365,691.0
57.842287903,696.0
57.875710441,691.0
57.909132979,792.0
57.942555517,752.0
57.975978055,736.0
58.009400593,752.0
58.042823131,723.0
58.076245669,729.0
58.109668207,724.0
58.143090745,770.0
58.176513283,685.0
58.209935820,689.0
58.243358358,737.0
58.276780896,727.0
58.310203434,758.0
58.343625972,756.0
58.377048510,723.0
58.410471048,737.0
58.443893586,686.0
58.477316124,755.0
58.510738662,736.0
58.544161200,716.0
58.577583738,709.0
58.611006276,695.0
58.644428814,748.0
58.677851352,726.0
58.711273890,721.0
58.744696428,694.0
58.778118966,679.0
58.811541504,663.0
58.844964042,699.0
58.878386580,731.0
58.911809118,683.0
58.945231655,694.0
58.978654193,687.0
59.012076731,672.0
59.045499269,688.0
59.078921807,746.0
59.112344345,701.0
59.145766883,727.0
59.179189421,684.0
59.212611959,707.0
59.246034497,693.0
59.279457035,729.0
59.312879573,651.0
59.346302111,705.0
59.379724649,672.0
59.413147187,712.0
59.446569725,714.0
59.479992263,721.0
59.513414801,696.0
59.546837339,662.0
59.580259877,659.0
59.613682415,672.0
59.647104953,649.0
59.680527491,668.0
59.713950028,666.0
59.747372566,707.0
59.780795104,705.0
59.814217642,699.0
59.847640180,674.0
59.881062718,624.0
59.914485256,660.0
59.947907794,684.0
59.981330332,676.0
60.014752870,710.0
60.048175408,714.0
60.081597946,653.0
60.115020484,689.0
60.148443022,672.0
60.181865560,639.0
60.215288098,666.0
60.248710636,695.0
60.282133174,693.0
60.315555712,663.0
60.348978250,628.0
60.382400788,710.0
60.415823326,682.0
60.449245864,716.0
60.482668401,628.0
60.516090939,727.0
60.549513477,712.0
60.582936015,640.0
60.616358553,718.0
60.649781091,682.0
60.683203629,711.0
60.716626167,709.0
60.750048705,726.0
60.783471243,714.0
60.816893781,695.0
60.850316319,742.0
60.883738857,693.0
60.917161395,684.0
60.950583933,745.0
60.984006471,710.0
61.017429009,743.0
61.050851547,724.0
61.084274085,710.0
61.117696623,717.0
61.151119161,717.0
61.184541699,702.0
61.217964237,728.0
61.251386774,727.0
61.284809312,687.0
61.318231850,727.0
61.351654388,707.0
61.385076926,770.0
61.418499464,701.0
61.451922002,739.0
61.485344540,713.0
61.518767078,815.0
61.552189616,734.0
61.585612154,766.0
61.619034692,736.0
61.652457230,791.0
61.685879768,790.0
61.719302306,776.0
61.752724844,837.0
61.786147382,767.0
61.819569920,734.0
61.852992458,813.0
61.886414996,750.0
61.919837534,715.0
61.953260072,738.0
61.986682610,752.0
62.020105147,701.0
62.053527685,729.0
62.086950223,694.0
62.120372761,652.0
62.153795299,726.0
62.187217837,694.0
62.220640375,727.0
62.254062913,718.0
62.287485451,707.0
62.320907989,693.0
62.354330527,712.0
62.387753065,700.0
62.421175603,729.0
62.454598141,693.0
62.488020679,701.0
62.521443217,680.0
62.554865755,713.0
62.588288293,655.0
62.621710831,700.0
62.655133369,734.0
62.688555907,713.0
62.721978445,730.0
62.755400982,668.0
62.788823520,726.0
62.822246058,725.0
62.855668596,749.0
62.889091134,730.0
62.922513672,656.0
62.955936210,698.0
62.989358748,658.0
63.022781286,708.0
63.056203824,720.0
63.089626362,697.0
63.123048900,688.0
63.156471438,667.0
63.189893976,663.0
63.223316514,687.0
63.256739052,673.0
63.290161590,669.0
63.323584128,666.0
63.357006666,718.0
63.390429204,654.0
63.423851742,648.0
63.457274280,662.0
63.490696818,641.0
63.524119355,715.0
63.557541893,748.0
63.590964431,690.0
63.624386969,691.0
63.657809507,729.0
63.691232045,712.0
63.724654583,675.0
63.758077121,708.0
63.791499659,738.0
63.824922197,713.0
63.858344735,689.0
63.891767273,686.0
63.925189811,665.0
63.958612349,673.0
63.992034887,657.0
64.025457425,721.0
64.058879963,686.0
64.092302501,671.0
64.125725039,705.0
64.159147577,651.0
64.192570115,679.0
64.225992653,697.0
64.259415191,704.0
64.292837728,694.0
64.326260266,709.0
64.359682804,674.0
64.393105342,667.0
64.426527880,732.0
64.459950418,698.0
64.493372956,688.0
64.526795494,699.0
64.560218032,711.0
64.593640570,695.0
64.627063108,699.0
64.660485646,714.0
64.693908184,760.0
64.727330722,713.0
64.760753260,662.0
64.794175798,667.0
64.827598336,638.0
64.861020874,676.0
64.894443412,723.0
64.927865950,675.0
64.961288488,622.0
64.994711026,704.0
65.028133564,681.0
65.061556101,690.0
65.094978639,684.0
65.128401177,683.0
65.161823715,696.0
65.195246253,696.0
65.228668791,729.0
65.262091329,646.0
65.295513867,751.0
65.328936405,711.0
65.362358943,694.0
65.395781481,669.0
65.429204019,714.0
65.462626557,718.0
65.496049095,691.0
65.529471633,711.0
65.562894171,711.0
65.596316709,714.0
65.629739247,665.0
65.663161785,723.0
65.696584323,701.0
65.730006861,726.0
65.763429399,731.0
65.796851937,743.0
65.830274474,700.0
65.863697012,804.0
65.897119550,745.0
65.930542088,751.0
65.963964626,720.0
65.997387164,758.0
66.030809702,767.0
66.064232240,745.0
66.097654778,763.0
66.131077316,720.0
66.164499854,727.0
66.197922392,708.0
66.231344930,718.0
66.264767468,655.0
66.298190006,736.0
66.331612544,745.0
66.365035082,738.0
66.398457620,714.0
66.431880158,756.0
66.465302696,767.0
66.498725234,688.0
66.532147772,726.0
66.565570309,725.0
66.598992847,705.0
66.632415385,759.0
66.665837923,685.0
66.699260461,748.0
66.732682999,742.0
66.766105537,723.0
66.799528075,689.0
66.832950613,686.0
66.866373151,680.0
66.899795689,683.0
66.933218227,737.0
66.966640765,710.0
67.000063303,677.0
67.033485841,697.0
67.066908379,785.0
67.100330917,727.0
67.133753455,697.0
67.167175993,680.0
67.200598531,701.0
67.234021069,654.0
67.267443607,701.0
67.300866145,672.0
67.334288682,667.0
67.367711220,695.0
67.401133758,691.0
67.434556296,698.0
67.467978834,687.0
67.501401372,728.0
67.534823910,647.0
67.568246448,705.0
67.601668986,700.0
67.635091524,720.0
67.668514062,682.0
67.701936600,702.0
67.735359138,732.0
67.768781676,727.0
67.802204214,675.0
67.835626752,729.0
67.869049290,744.0
67.902471828,711.0
67.935894366,712.0
67.969316904,732.0
68.002739442,726.0
68.036161980,764.0
68.069584518,703.0
68.103007055,710.0
68.136429593,670.0
68.169852131,774.0
68.203274669,697.0
68.236697207,720.0
68.270119745,708.0
68.303542283,754.0
68.336964821,727.0
68.370387359,695.0
68.403809897,658.0
68.437232435,673.0
68.470654973,673.0
68.504077511,714.0
68.537500049,697.0
68.570922587,649.0
68.604345125,660.0
68.637767663,645.0
68.671190201,679.0
68.704612739,646.0
68.738035277,704.0
68.771457815,635.0
68.804880353,703.0
68.838302891,631.0
68.871725428,690.0
68.905147966,644.0
68.938570504,683.0
68.971993042,649.0
69.005415580,648.0
69.038838118,629.0
69.072260656,604.0
69.105683194,683.0
69.139105732,619.0
69.172528270,671.0
69.205950808,669.0
69.239373346,653.0
69.272795884,647.0
69.306218422,680.0
69.339640960,616.0
69.373063498,645.0
69.406486036,660.0
69.439908574,677.0
69.473331112,648.0
69.506753650,638.0
69.540176188,649.0
69.573598726,651.0
69.607021264,647.0
69.640443801,619.0
69.673866339,632.0
69.707288877,583.0
69.740711415,652.0
69.774133953,645.0
69.807556491,598.0
69.840979029,654.0
69.874401567,646.0
69.907824105,644.0
69.941246643,657.0
69.974669181,628.0
69.991380450,602.0